model
size = 27 18 23, scale = 0.05, origin = -y
material 
  colors = A:#84492C B:#000 C:#A17A43 D:#FEEA41 E:#A9523A F:#94453E G:#FFF H:#8E695F I:#1E1729
voxels
--------------------------- --------------------------- --------------------------- --------------------------- --------------------------- --------------------------- --------------------------- --------------------------- --------------------------- --------------------------- --------------------------- --------------------------- -------------AA------------ --------------------------- --------------------------- --------------------------- --------------------------- --------------------------- 
--------------------------- --------------------------- --------------------------- --------------------------- --------------------------- --------------------------- --------------------------- --------------------------- --------------------------- -------------AA------------ -------------AA------------ ------------AAA------------ ------------A--A----------- --------------------------- --------------------------- --------------------------- --------------------------- --------------------------- 
--------------------------- --------------------------- --------------------------- --------------------------- --------------------------- --------------------------- --------------------------- --------------------------- -------------BB------------ ----------BBBAA------------ ----------BBBAABBBBBBBBBB-- ------BBBBBBBAAB----------- ------BBBBBBBAAA----------- -------BBBBBA-A------------ -------BBBB-B-------------- --------B---B-------------- ---------BBB--------------- ---------B----------------- 
--------------------------- --------------------------- --------------------------- --------------------------- --------------------------- ---------------B-B--------- ------BBBBBBBBBBBB--------- -----BBBBBBBBBBBBB--------- -----BBBBBBBBBBBBB--------- ------BBBBBBAAAAABBBB------ -----BBBBBBBAAAAAAAAA------ -----BAAAAAAAAAAAAAAA------ -----BAAAABAAAAAAAAAA------ ------BAAB-AAAA----AA------ -------BBB-BBBB-----A------ --------BB-B--------------- -----------B--------------- ---------BB---------------- 
--------------------------- --------------------------- --------------------------- --------------------------- ----------------BBBB------- ------BBBBBBBBBBBBBBBBBBBBB -----BAAAAAAAAAAAABBBBBBB-- ----BAAAAAAAAAAAAABB------- ----BAAAAAAAAAAAAABBB------ ---BBBABBBBBBBBBCAAAABBBBB- ---BBBABBBBBBBBBCCCCCA----- -----BAAAAAAAAAACCCCCA----- -----BAAAAAAAAAAAAAACA----- ------AAAAAAAAAAAAAAFA----- ------AAAABAABB----AAA----- -------AAABAB-B------------ --------BBBB--------------- --------BBB---------------- 
--------------------------- --------------------------- -------------B------------- -----------BBBBBBBBB------- --------BBBBBBBBAAAABBB---- -----BBBAAAAAAAAAAAA-B----- ----BAAAAAAAAAAAAAAA------- ---BAAAAAAAAAAAAAAAA------- ---BAAAAAAAAAAAAAAAA------- --BABAABBBBBBBBBCCAAAA----- --BABAABBBBBBBBBCCCAAA----- ---BBAADDDDDDDDDCCCAAA----- ---BBAADDDDDDDAAAAAAAA----- ----BAAGGGGGGAAAAAAAAA----- -----AAGA--AAAB--AAAAAA---- ------AAAAAAAB-----AAA----- -------AAGGGB-------------- --------BBBBB-------------- 
--------------------------- --------------------------- -----------BBBBBBB--------- ---------BBAAAAAAABBB------ -------BBAAAAAA-AAAAAB----- -----BBAAAAAAAAAAAAAAABBBBB ---BBAAAAAAAAAAAAAAAAA----- --BAAAAAAAAAAAAAAAAAAA----- --BAAAAAAAAAAAAAAAAAAA----- ---BBBBBBBBBBBBBCCCAAAA---- ---BBBBBBBBBBBBBCCCCCAA---- --BEE-DDDDDDDDDHCCCCCAAA--- --BAAAAAAAAAAAAAAACCCA----- ---BAAAAAAAAAAAAAAAAFA----- ----BAAAAAAAAAB-AAAAAAA---- ------AAAFAAAB---AAAAAA---- -------AABBGB-------------- --------B-BB--------------- 
--------------------------- -----------BBBBBB---------- ----------BAAAAAABBB------- --------BBAAAAAAAAAAB------ ------BBAAAAAAA-AAAAAB----- -----BBAAAAAAAAAAAAAAA----- ---BBAAAAAAAAAAAAAAAAA----- --BAAAAAAAAAAAAAAAAAAA----- --BAAAAAAAAAAAAAAAAAAA----- ---BBBBBBBBBBBBBCCCCAAAA--- ---BBBBBBBBBBBBBCCCCCAAA--- --BEEEDDDDDDDDDHCCCCCAAA--- --BAAAAAAAAAAAAACCCCCAAA--- ---BAAAAAAAAAAAAAAAFFAAA--- ----BAAAAAFAAAAAAAAAAAA---- ------AAAA-AABBBAAABAAA---- --------ABBGB-------------- --------B-BB--------------- 
--------------------------- -----------BBBBBB---------- --------BBBAAAAAABBB------- --------BBAAAAAAAAAAB------ -----BBBAAAAAAA-AAAAAB----- -----BBAAAAAAAAAAAAAAA----- ---BBAAAAAAAAAAAAAAAAA----- --BAAAAAAAAAAAAAAAAAAA----- -BAAAAAAAAAAAAAAAAAAAA----- --BBBBBBBBBBBBBBCCCCCAAA--- --BBBBBBBBBBBBBBCCCCCAAA--- --BEEEEDDDDDDDHHCCCCCAAA--- --BAAAAAAAAAAAAACCCCCAAA--- ---BAAAAAAAAAAAAAAAFFAAA--- ----BAAAAAAAAAAAAAAAAAAA--- -----BAAAAAAABBBAAAAAAAA--- --------AGGGB-----BBAAAA--- --------BBBB--------------- 
------------B-------------- -----------BBBBBB---------- --------BBBAAAAAABBB------- -------BBBAAAAAAAAAAB------ -------BAAAAAAA-AAAAAB----- -----BBAAAAAAAAAAAAAAA----- ---BBAAAAAAAAAAAAAAAAA----- --BAAAAAAAAAAAAAAAAAAAA---- -BAAAAAAAAAAAAAAAAAAAAA---- -BBBBBBBBBBBBBBBCCCCCAAAA-- ---BBBBBBBBBBBBBCCCCCAAAA-- --BEEEEDDDDDDDHHCCCCCAAAA-- -BAAAAAAAAAAAAAACCCCCAAAAA- --BBAAAAAAAAAAAAAAAFFAAAA-- ----BBAAAAAAAAAAAAAAAAAAA-- -----B---AAAB-BBAAHFFFFAA-- ---------BBB-BB--ABAAAFAA-- ---------BBBBB-------AA---- 
--------------BB----------- -----------BBBAAB---------- --------BBBAAAAAABBB------- --------BBAAAAAAAAAAB------ -------BAAAAAAA-AAAAAB----- -----BBAAAAAAAAAAAAAAA----- ---BBAAAAAAAAAAAAAAAAA----- --BAAAAAAAAAAAAAAAAAAAA---- -BAAAAAAAAAAAAAAAAAAAAA---- BBBBBBBBBBBBBBBBCCCC-AAAA-- -BBBBBBBBBBBBBBBCCCCCAAAA-- -BEEEEEEDDDDDDHHCCCCCAAAAA- BAAAAAAAAAAAAAAACCCCCAAAA-- -BBBAAAAAAAAAAAAAAAFFAAAA-- ---BBB---AAAAAAAAAAAAAAAA-- -----B---BBBBAAAAHHFFFFAA-- ----------BBBAAAAABAAAAAA-- ----------BBBBB-----A-AA--- 
--------------BB----------- ---------B-BBBAAB---------- --------BBBAAAAAABBB------- --------BBAAAAAAAAAAB------ -------BAAAAAAA-AAAAAB----- -----BBAAAAAAAAAAAAAAA----- ---BBAAAAAAAAAAAAAAAAA----- --BAAAAAAAAAAAAAAAAAAAA---- -BAAAAAAAAAAAAAAAAAAAAA---- BBBBBBBBBBBBBBBBCCCC-AAAA-- BEBBBBBBBBBBBBBBCCCCCAAAAA- -BEEEEEEDDDDDDHHCCCCCAAAAA- BAAAAAAAAAAAAAAACCCCCAAAAA- -BBBAAAAAAAAAAAAAAAFFAAAAA- ---BBB-----AAAAAAAAAAAAAAA- ----BB---BB-BDDDDHHFFFAAAB- ---------BBBBAAAAABAAA-AB-- ---------BBBBBAAA---A--A--- 
--------------BB----------- ---------B-BBBAAB---------- --------BBBAAAAAABBB------- --------BBAAAAAAAAAAB------ -------BAAAAAAA-AAAAAB----- -----BBAAAAAAAAAAAAAAA----- ---BBAAAAAAAAAAAAAAAAA----- --BAAAAAAAAAAAAAAAAAAAA---- -BAAAAAAAAAAAAAAAAAAAAA---- BBBBBBBBBBBBBBBBCCCCCAAAA-- -BBBBBBBBBBBBBBBCCCCCAAAAA- -BEEEEEEDDDDDDHHCCCCCAAAAA- BAAAAAAAAAAAAAAACCCCCAAAAA- -BBBAAAAAAAAAAAAAAAFFAAAAA- ---BBB-----AAAAAAAAAAAAAAA- ----BB---BBBBDDAAAHFFAAAAB- ---------BB-BAAAAABAAA-AB-- ---------BBB-BAAA---A--A--- 
--------------------------- -----------BBBBBB---------- --------BBBAAAAAABBB------- --------BBAAAAAAAAAAB------ -------BAAAAAAA-AAAAAB----- -----BBAAAAAAAAAAAAAAA----- ---BBAAAAAAAAAAAAAAAAA----- --BAAAAAAAAAAAAAAAAAAAA---- -BAAAAAAAAAAAAAAAAAAAAA---- BBBBBBBBBBBBBBBBCCCA-AAAA-- -BBBBBBBBBBBBBBBCCCC-AAAAA- -BEEEEEEDDDDDDHHCCCC-AAAAA- BAAAAAAAAAAAAAAACCCC-AAAAA- -BBBAAAAAAAAAAAAAAAF-AAAAA- ---BBB--AAAAA--AAAAA-AAAAA- ----B-----BBBAAAAAAF-AAAA-- ---------BBBBAAAAABAAAAAA-- ---------BBBBBB-----A-AA--- 
--------------------------- -----------BBBBBB---------- --------BBBAAAAAABBB------- --------BBAAAAAAAAAAB------ -------BAAAAAAA-AAAAAB----- -----BBAAAAAAAAAAAAAAA----- ---BBAAAAAAAAAAAAAAAAA----- --BAAAAAAAAAAAAAAAAAAA----- -BAAAAAAAAAAAAAAAAAAAA----- -BBBBBBBBBBBBBBBCAAA-A----- -BBBBBBBBBBBBBBBCCCCAAAAA-- -BEEEEEEDDDDDDHHCCCCAAAAAA- BAAAAAAAAAAAAAAACCCCAAAAAA- -BBBAAAAAAAAAAAAAAAFAAAAA-- ---BBB--AAA--AABAAAAAAAAA-- ---------AAA---BAAAAAAAA--- ---------BBBBBB--ABAAAAA--- ---------BBBBBB------AA---- 
--------------------------- -----------BBBBBB---------- ---------BBAAAAAABBB------- --------BBAAAAAAAAAAB------ -------BBAAAAAA-AAAAAB----- -----BBAAAAAAAAAAAAAAABBBBB ----BAAAAAAAAAAAAAAAAA----- --BBAAAAAAAAAAAAAAAAAA----- -BAAAAAAAAAAAAAAAAAAAA----- --BBBBBBBBBBBBBBCAAA-A----- -BBBBBBBBBBBBBBBCCCCAAAAA-- -BEEEEEEDDDDDDHHCCCCAAAAA-- -BAAAAAAAAAAAAAACCCCAAAAA-- --BBAAAAAAAAAAAAAAAAAAAAA-- ----BAAAAAA--AAAAAAAAAAA--- -----BAAAAGGA--BAAAAAAAA--- --------AGGG--BB--BBAAAA--- --------BBBBBB------------- 
--------------------------- --------------------------- ---------B-BBBBBBB--------- --------BBBAAAAAAABBB------ -------BBAAAAAA-AAAAABB---- -----BBAAAAAAAAAAAAAAABBBBB ----BAAAAAAAAAAAAAAAAA----- ---BBAAAAAAAAAAAAAAAAA----- --BAAAAAAAA----AAAAAAA----- --BBBBBBBBBBBBBBAAAAAA----- -BBBBBBBBBBBBBBBCCCCCA----- -BEEEEEEDDDDDDDHCCCCCA----- --BAAAAAAAAAAAAACCCCCA----- ---BAAAAAAAAAAAAAAAAAA----- ----BAAAAAA--AABAAAAAAAA--- ------AAAAFGAB-BAAABAAA---- --------ABBG-BB------------ --------BB-BB-------------- 
--------------------------- --------------------------- --------------------------- --------BB-BBBBBBBBBBBB---- --------BBBBBBBBAAAABBB---- ------BBAAABBBAAAAAABB----- -----BAAAAAAAAAAAAAABB----- ---BBAAAAAAAAAAAAAAABB----- --BAAAAAAAA---AAAAAABBB---- --BBBBBBBBBBBBBBAAAAAAAB--- --BBBBBBBBBBBBBBCCCCCCAB--- --B-EEEDDDDDDDDHCCCCCCAB--- --BAAAAAAAAAAAAACCCCCCCA--- ---BAAAAAAAAAAAAAAAAAAAA--- ----BAAAAAAA-AABAAAAAAAA--- ------AAAAFGABBB-AAAAAA---- -------AABBGB-------------- --------BBBBBB------------- 
--------------------------- --------------------------- --------------------------- ---------B-------B-B------- --------BB---BBBBBBB------- ------BBBBBBBBAAABBBBBBBBBB -----BAAAAAAAABBBBBB------- ----BAAAAAAAAABBBBBB------- ---BAAAAAAA---AA-BBBBBB---- ---BBBBBBBBBBBBAAAAAAAABBBB ---BBBBBBBBBBBBBBABBBBABB-- --BEEEEDDDDDDDDDDHHFFFABB-- --BAAAAAAAAAAAAAAAAFFFAB--- ---BAAAAAAAAAAAAAAAAAAAA--- ----BAAAAAAAAAB--AAAAAA---- ------AAAAGGAB------------- -------AAGGGB-------------- --------BBBB--------------- 
--------------------------- --------------------------- --------------------------- --------------------------- --------BB----B---B-------- ------BBBBBBBBBBBB--------- -----BAAAAAAAAB------------ ----BAAAAAAAAAB------------ ----BAAAAAAAAAABBBBBBBB---- ---BBBBBBBBBBBBAAAAAAAAB--- ---BBBBBBBBBBBBBBABBBBAB--- ---BEEAADDDDDDDDDHHFFFAB--- ---BAAAADDDDDDAAAHHFFFA---- ---BAAAAGGGGGAAAAAAAAAA---- ----BBAAAAAAABB----AA------ -------AAAAAB-------------- --------BBBB--------------- --------BB----------------- 
--------------------------- --------------------------- --------------------------- --------------------------- --------------------------- ------------B-------------- ------BBBBBBBB------------- -----BBBBBBBBB------------- ----BBABBBABBBBBBB--------- ---BAABAAABAAAAAAABBBBB---- ---BAAAAAAAAAAAAAAAAAA-B--- ---BAAAAAAAAAAAAAAAAAA-BBBB ---BAAAAAAAAAAAAAAAAAA----- ----BBAAAAAAAAA----AAA----- -------AAAABBBB-----A------ --------BBBB--------------- --------------------------- --------------------------- 
--------------------------- --------------------------- --------------------------- --------------------------- --------------------------- --------------------------- --------------------------- --------------------------- ------B-BBB---------------- ----BBABAAABBBBBBBBBBBBBBB- ----BBBBBBIBAAAA----------- --------IBBBA--A----------- --------BBBBA--A----------- --------BBBB--------------- --------BBB---------------- --------BBBB--------------- --------------------------- --------------------------- 
--------------------------- --------------------------- --------------------------- --------------------------- --------------------------- --------------------------- --------------------------- --------------------------- --------------------------- ------B-BBB---------------- ----------B---------------- --------B-B---------------- -------------AA------------ --------------------------- ----------B---------------- ----------B---------------- --------------------------- --------------------------- 
