model
size = 32, scale = 0.05, origin = -y
material 
  colors = A:#EEE B:#111 C:#633 D:#010 E:#888 F:#FCF G:#F6C H:#E00 I:#555 J:#444 K:#AAA
voxels
396-A6-A24-ABI2JIBA4(24-IJI2JIJI)20-HA4-4B4-AH16-2(AH)A-4B-2(AH)A16-3(HA)-2B-3(AH)16-3(AH)-2B-3(HA)16-3(HA)-2B-3(AH)17-2(HA)H-2B-2(HA)H18-2(AH)A-2B-2(AH)A19-2(AH)-2B-2(HA)21-AHA-2B-AHA26-2B540-6B24-10B20-14B18-14B17-16B16-16B15-2(A16BA14-H16BH14-)A16BA15-A14BA16-H14BH17-H12BH18-AH10BHA20-10B24-6B505-8B22-12B18-16B16-16B15-18B14-18B13-2(H18BH12-A18BA12-)H18BH13-A16BA14-H16BH15-A14BA16-H14BH18-12B22-8B116-4D8-4D16-4D8-4D340-8B22-12B18-16B16-16B15-18B14-18B13-20B2(12-H18BH12-A18BA)13-H16BH14-A16BA15-H14BH16-A14BA18-12B22-8B24-I2-2B2-I24-I6-I20-5I6-5I2(16-4D8-4D)340-8B22-12B18-16B16-16B15-18B14-18B13-20B2(12-A18BA12-H18BH)13-A16BA14-H16BH15-A14BA16-H14BH18-12B22-8B27-2B55-I14-I2(16-4D8-4D)17-2D10-2D2(18-2A10-2A)2(18-CA10-2A)2(18-2A10-2A)2(18-CA10-CA)18-C7A5CA18-11A2CA18-14A17-4(B14AB16-)B14AB15-2B14A2B15-3(B14AB16-)B14AB17-14B19-2(12B20-)12B21-B2-4B2-B83-I14-I2(16-4D8-4D)17-2D10-2D2(2(18-2A10-2A)2(18-CA10-2A))18-C7A4C2A2(18-14A)17-9(B14AB16-)B14AB17-B4A4B4AB19-5B2-5B20-B-8B-B21-10B23-8B25-B4-B85-4D8-4D16-4D8-4D305-C7A4C2A18-C13A18-14A17-16A15-6(B16AB14-)B16AB15-B14AB16-B14AB17-B4A4B4AB19-B2A6B2AB19-2(4B-)4B19-2B-6B-2B21-2(B-)2B2(-B)437-2A8-CA19-C7A3C3A18-C13A18-14A17-16A16-16A14-4(B18AB12-)B18AB13-B16AB15-2(B14AB16-)2B4A4B4A2B18-B2A6B2AB20-3B-4B-3B21-B2-4B2-B25-4B440-2A8-2A19-C7A2C4A18-C13A18-14A17-16A16-16A15-18A2(14-17AC)2(14-18A)15-16A17-14A18-14A17-2B4A4B4A2B18-B2A6B2AB19-14B19-12B21-3B-2B-3B405-12A20-8A2C2A19-2(C13A18-)14A17-16A16-16A15-4(17AC14-)18A15-16A17-2(14A18-)B4A4B4AB19-B2A-4B-2AB20-12B21-3B-2B-3B23-B6-B376-8F22-12A20-12A19-14A2(18-C13A)17-16A16-15AC15-4(17AC14-)18A15-16A17-14A18-14A19-4AB2-B4A21-2AB-2B-B2A22-2B-4B-2B24-B4-B378-6G25-8F22-12A20-12A19-14A18-C13A18-14A17-C15A16-15AC15-4(17AC14-)17AC15-16A17-14A18-14A19-4AB2-B4A21-2A6B2A22-2B-4B-2B26-2B285-2(G2-G28-)G2-G27-6G25-8F22-12A20-12A19-14A18-C13A18-14A17-C15A16-C14AC15-4(17AC14-)17AC15-16A17-14A18-14A19-4A4B4A21-2A6B2A23-B-4B-B409-6G25-8F22-12A20-12A19-2(14A18-)14A17-15AC16-15AC15-4(17AC14-)17AC15-16A17-14A18-14A19-4A4B4A21-2A6B2A23-B-4B-B314-2(G2-G28-)G2-G27-6G25-8F22-12A20-12A19-2(14A18-)13AC17-15AC16-15AC15-4(17AC14-)18A15-16A17-14A18-14A19-4A4B4A22-8B26-4B411-6G25-8F22-12A20-12A19-14A2(18-13AC)17-15AC16-15AC15-2(17AC14-)2(18A14-)18A15-16A17-14A18-14A10-11E8B11E15-4B28-4B411-6G25-8F22-12A20-12A19-14A2(18-13AC)17-15AC16-15AC15-17AC4(14-18A)15-16A17-14A18-14A9-12E8B12E14-4B28-4B316-2(G2-G28-)G2-G27-6G25-8F22-12A20-12A19-14A2(18-13AC)17-15AC16-15AC15-17AC4(14-18A)15-16A17-14A18-14A9-11E10B11E12-B-4B-B26-4B411-6G25-8F22-12A20-12A19-14A2(18-13AC)17-15AC16-15AC15-17AC4(14-18A)15-16A17-14A18-14A9-2E9K10B9K2E12-B-4B-B26-4B316-2(G2-G28-)G2-G27-6G25-8F22-12A20-12A19-2(14A18-)C12AC17-15AC16-15AC15-17AC14-C17A14-18A14-17AC14-18A15-16A17-14A18-14A9-11E10B11E12-8B25-6B410-6G25-8F22-12A20-12A19-2(14A18-)C13A17-C15A16-C15A15-3(C17A14-)C16AC14-17AC15-16A17-14A18-14A10-10E10B10E14-6B27-4B442-8F22-12A20-12A19-2(14A18-)C13A17-C15A16-C15A15-2(C17A14-)2(C16AC14-)17AC15-15AC17-14A18-14A19-12B25-2B505-12A20-2AC9A19-2(13AC18-)C13A17-5(C15A16-)C14A2(C16-15A)C17-14A18-14A595-AC8-2A19-3A2C8AC18-13AC6(18-C13A)2(18-C12AC)18-13AC3(18-14A)563-AC8-2A19-3A2C8A2(C18-13A)C11(18-14A)19-5A2-5A210-4D8-4D16-4D8-4D305-2A3C8A3(C18-13A)C2(18-14A)17-6(16A16-)16A17-14A19-5A2-5A21-3A4-3A179-4D8-4D16-4D8-4D17-2D10-2D3(18-2A10-2A)2(18-2A10-AC)3(18-2A10-2A)18-2A3C8A3(C18-13A)C2(18-14A)17-6(16A16-)16A17-14A19-4CA2-5A210-4D8-4D16-4D8-4D17-2D10-2D3(18-2A10-2A)18-CA10-2A2(18-CA10-AC)18-CA10-2A18-2C10-2A18-2A4C7AC18-2A5C2A2C2AC18-4A3C3A2C2A18-5A2C3A2C2A18-10A3CA18-8A2C4A3(18-14A)4(18-C13A)18-5C9A24-2A2(30-2C)30-3A2CA26-5AC83-4D8-4D16-4D8-4D498-5A4C3A2(20-5A2C5A)3(20-C11A)20-3C9A274-4D8-4D16-4D8-4D531-4A2-2C2A22-4A2-C3A22-4A2-4A22-C3A2-4A22-2C2A2-4A919-2A4-CA2(24-2A4-2A)332-
