model
size = 20 28 29, scale = 0.05, origin = -y
material 
  colors = A:#003 B:#960 C:#300 D:#FF0 E:#C30 F:#EEE G:#630
voxels
-------------------- -------------------- -------------------- -------------------- -------------------- -------------------- -------------------- -------------------- -------------------- -------------------- -------------------- -------------------- -------------------- -------------------- -------------------- -------------------- -------------------- -AAAAAAAAAAAAAAAAAA- -------------------- -------------------- -------------------- -------------------- -------------------- -------------------- -------------------- -------------------- -------------------- -------------------- 
-------------------- -------------------- -------------------- -------------------- -------------------- -------------------- -------------------- -------------------- -------------------- -------------------- -------------------- -------------------- -------------------- -------------------- -------------------- -------------------- -------------------- -AAAAAAAAAAAAAAAAAA- -AAAAAAAAAAAAAAAAAA- -------------------- -------------------- -------------------- -------------------- -------------------- -------------------- -------------------- -------------------- -------------------- 
-------------------- -------------------- -------------------- -------------------- -------------------- -------------------- -------------------- -------------------- -------------------- -------------------- -------------------- -------------------- -------------------- -------------------- -------------------- -------------------- -------------------- -AAAAAAAAAAAAAAAAAA- -AAAAAAAAAAAAAAAAAA- -------------------- -------------------- -------------------- -------------------- -------------------- -------------------- -------------------- -------------------- -------------------- 
-------------------- -------------------- -------------------- -------------------- -------------------- -------------------- -------------------- -------------------- -------------------- -------------------- -------------------- -------------------- -------------------- -------------------- -------------------- -------------------- -------------------- -AAAAAAAAAAAAAAAAAA- -AAAAAAAAAAAAAAAAAA- -------------------- -------------------- -------------------- -------------------- -------------------- -------------------- -------------------- -------------------- -------------------- 
-------------------- -------------------- -------------------- -------------------- -------------------- -------------------- -------------------- -------------------- ---------BBB-------- ---------BBB-------- ---------BBB-------- ---------BBB-------- -------------------- -------------------- -------------------- -------------------- -------------------- -AAAAAAAAAAAAAAAAAA- -AAAAAAAAAAAAAAAAAA- -AAAAAAAAAAAAAAAAAA- -------------------- -------------------- -------------------- -------------------- -------------------- -------------------- -------------------- -------------------- 
-------------------- -------------------- -------------------- -------------------- -------------------- -------------------- -------------------- -------------------- --------BBBBB------- --------BAAAB------- ---------BAB-------- ---------BBB-------- -------------------- -------------------- -------------------- -------------------- -------------------- -AAAAAAAAAAAAAAAAAA- -AAAAAAAAAAAAAAAAAA- -AAAAAAAAAAAAAAAAAA- -------------------- -------------------- -------------------- -------------------- -------------------- -------------------- -------------------- -------------------- 
-------------------- -------------------- -------------------- -------------------- -------------------- -------------------- -------------------- -------------------- --------B-B-B------- --------BAAAB------- ---------BAB-------- ---------BBB-------- -------------------- -------------------- -------------------- -------------------- -------------------- -AAAAAAAAAAAAAAAAAA- -AAAAAAAAAAAAAAAAAA- -AAAAAAAAAAAAAAAAAA- -AAAAAAAAAAAAAAAAAA- -------------------- -------------------- -------------------- -------------------- -------------------- -------------------- -------------------- 
-------------------- -------------------- -------------------- -------BBBBBBB------ --------BBBBB------- -------------------- -------------------- -------------------- --------BBBBB------- -DDDDDDDAAAAADDDDDD- -DEEEEEDDAAADDEEEED- -DEEEEEEDAAADEEEEED- -DEEFEEEEDDDEEFEEED- -DEFEEEEEDDDEFEEEED- -DEEEEEEEDDDEEEEEED- -DDDDDDDDDDDDDDDDDD- -------------------- -AAAAAAAAAAAAAAAAAA- -AAAAAAAAAAAAAAAAAA- -AAAAAAAAAAAAAAAAAA- -AAAAAAAAAAAAAAAAAA- -------------------- -------------------- -------------------- -------------------- -------------------- -------------------- -------------------- 
-------BBBBBBB------ ------BBBBBBBBB----- ---BBBBBBBBBBBBBB--- --BBBBBAAAAAAABBBB-- --BBBBBBAAAAABBBBB-- --BBBBBBBBBBBBBBBB-- --BBBBBBBBBBBBBBBB-- --BBBBBBBBBBBBBBBB-- --BBBBBBAAAAABBBBB-- --BBAAAAAAAAAAAAAB-- --BBAAAAAAAAAAAAAB-- --BBAAAAAAAAAAAAAB-- -DDAAAAAAAAAAAAAAAD- -DAAAAAAAAAAAAAAAAD- -DDAAAAAAAAAAAAAAAD- -DDBBBBBBBBBBBBBBBD- ---BBBBBBBBBBBBBBB-- -AAAAAAAAAAAAAAAAAA- -AAAAAAAAAAAAAAAAAA- -AAAAAAAAAAAAAAAAAA- -AAAAAAAAAAAAAAAAAA- -AAAAAFFFFAFFFFAAAA- -AAAAAFAAFAFAAFAAAA- -AAAAAFFAFAFFFFAAAA- -AAAAAAAAFAFAAAAAAA- -AAAAAAAAAAAAAAAAAA- -------------------- -------------------- 
-------BBBBBBB------ ------BBAAAAABB----- ---BBBBAAAAAAABBB--- --BBBBAAAAAAAAAABB-- --BBAAAAAAAAAAAAAB-- --BBAAAAAAAAAAAAAB-- --BBAAAAAAAAAAAAAB-- --BBAAAAAAAAAAAAAB-- --BBAAAAAAAAAAAAAB-- --BBAAAAAAAAAAAAAB-- --BBAAAAAAAAAAAAAB-- --BBAAAAAAAAAAAAAB-- -DDBAAAAAAAAAAAAAAD- -DDAAAAAAAAAAAAAAAD- -DDAAAAAAAAAAAAAAAD- -DDBAAAAAAAAAAAAABD- ---BAAAAAAAAAAAAAB-- -AAAAAAAAAAAAAAAAAA- -AAAAAAAAAAAAAAAAAA- -AAAAAAAAAAAAAAAAAA- -AAAAAAAAAAAAAAAAAA- -AAAAAAAAAAAAAAAAAA- -AAAAAAAAAAAAAAAAAA- -AAAAAAAAAAAAAAAAAA- -AAAAAAAAAAAAAAAAAA- -AAAAAAAAAAAAAAAAAA- -AAAAAAAAAAAAAAAAAA- -------------------- 
-------BBBBBBB------ ------BBBBBBBBB----- ---BBBBBAAAAABBBB--- --BBBBAAAAAAAAABBB-- --BBAAAAAAAAAAAAAB-- --BBAAAAAAAAAAAAAB-- --BBAAAAAAAAAAAAAB-- --BBAAAAAAAAAAAAAB-- --BBAAAAAAAAAAAAAB-- --BBAAAAAAAAAAAAAB-- --BBAAAAAAAAAAAAAB-- --BBAAAAAAAAAAAAAB-- --BBAAAAAAAAAAAAAB-- -DDAAAAAAAAAAAAAAAD- -DDAAAAAAAAAAAAAAAD- -DDBAAAAAAAAAAAAABD- ---BAAAAAAAAAAAAAB-- -AAAAAAAAAAAAAAAAAA- -AAAAAAAAAAAAAAAAAA- -AAAAAAAAAAAAAAAAAA- -AAAAAAAAAAAAAAAAAA- -AAAAAAAAAAAAAAAAAA- -AAAAAAAAAAAAAAAAAA- -AAAAAAAAAAAAAAAAAA- -AAAAAAAAAAAAAAAAAA- -AAAAAAAAAAAAAAAAAA- -AAAAAAAAAAAAAAAAAA- -------------------- 
-------BBBBBBB------ ------BBBBBBBBB----- ---BBBBBAAAAABBBB--- --BBBBAAAAAAAAABBB-- --BBAAAAAAAAAAAAAB-- --BBAAAAAAAAAAAAAB-- --BBAAAAAAAAAAAAAB-- --BBAAAAAAAAAAAAAB-- --BBAAAAAAAAAAAAAB-- --BBAAAAAAAAAAAAAB-- --BBAAAAAAAAAAAAAB-- --BBAAAAAAAAAAAAAB-- --BBAAAAAAAAAAAAAB-- -DDAAAAAAAAAAAAAAAD- -DDAAAAAAAAAAAAAAAD- -DDBAAAAAAAAAAAAABD- ---BAAAAAAAAAAAAAB-- -AAAAAAAAAAAAAAAAAA- -AAAAAAAAAAAAAAAAAA- -AAAAAAAAAAAAAAAAAA- -AAAAAAAAAAAAAAAAAA- -AAAAAAAAAAAAAAAAAA- -AAAAAAAAAAAAAAAAAA- -AAAAAAAAAAAAAAAAAA- -AAAAAAAAAAAAAAAAAA- -AAAAAAAAAAAAAAAAAA- -AAAAAAAAAAAAAAAAAA- -------------------- 
-------BBBBBBB------ ------BBBBBBBBB----- ---BBBBBAAAAABBBB--- --BBBBAAAAAAAAABBB-- --BBAAAAAAAAAAAAAB-- --BBAAAAAAAAAAAAAB-- --BBAAAAAAAAAAAAAB-- --BBAAAAAAAAAAAAAB-- --BBAAAAAAAAAAAAAB-- --BBAAAAAAAAAAAAAB-- --BBAAAAAAAAAAAAAB-- --BBAAAAAAAAAAAAAB-- --BBAAAAAAAAAAAAAB-- -DDAAAAAAAAAAAAAAAD- -DDAAAAAAAAAAAAAAAD- -DDBAAAAAAAAAAAAABD- ---BAAAAAAAAAAAAAB-- -AAAAAAAAAAAAAAAAAA- -AAAAAAAAAAAAAAAAAA- -AAAAAAAAAAAAAAAAAA- -AAAAAAAAAAAAAAAAAA- -AAAAAAAAAAAAAAAAAA- -AAAAAAAAAAAAAAAAAA- -AAAAAAAAAAAAAAAAAA- -AAAAAAAAAAAAAAAAAA- -AAAAAAAAAAAAAAAAAA- -AAAAAAAAAAAAAAAAAA- -------------------- 
-------BBBBBBB------ ------BBBBBBBBB----- ---BBBBBAAAAABBBB--- --BBBBAAAAAAAAABBB-- --BBAAAAAAAAAAAAAB-- --BBAAAAAAAAAAAAAB-- --BBAAAAAAAAAAAAAB-- --BBAAAAAAAAAAAAAB-- --BBAAAAAAAAAAAAAB-- --BBAAAAAAAAAAAAAB-- --BBAAAAAAAAAAAAAB-- --BBAAAAAAAAAAAAAB-- --BBAAAAAAAAAAAAAB-- -DDAAAAAAAAAAAAAAAD- -DDAAAAAAAAAAAAAAAD- -DDBAAAAAAAAAAAAABD- ---BAAAAAAAAAAAAAB-- -AAAAAAAAAAAAAAAAAA- -AAAAAAAAAAAAAAAAAA- -AAAAAAAAAAAAAAAAAA- -AAAAAAAAAAAAAAAAAA- -AAAAAAAAAAAAAAAAAA- -AAAAAAAAAAAAAAAAAA- -AAAAAAAAAAAAAAAAAA- -AAAAAAAAAAAAAAAAAA- -AAAAAAAAAAAAAAAAAA- -AAAAAAAAAAAAAAAAAA- -------------------- 
-------BBBBBBB------ ------BBBBBBBBB----- ---BBBBBAAAAABBBB--- --BBBBAAAAAAAAABBB-- --BBAAAAAAAAAAAAAB-- --BBAAAAAAAAAAAAAB-- --BBAAAAAAAAAAAAAB-- --BBAAAAAAAAAAAAAB-- --BBAAAAAAAAAAAAAB-- --GGGAAAAAAAAAAAAB-- --BBAAAAAAAAAAAAAB-- --BBAAAAAAAAAAAAAB-- --BBAAAAAAAAAAAAAB-- -DDAAAAAAAAAAAAAAAD- -DDAAAAAAAAAAAAAAAD- -DDBAAAAAAAAAAAAABD- ---BAAAAAAAAAAAAAB-- -AAAAAAAAAAAAAAAAAA- -AAAAAAAAAAAAAAAAAA- -AAAAAAAAAAAAAAAAAA- -AAAAAAAAAAAAAAAAAA- -AAAAAAAAAAAAAAAAAA- -AAAAAAAAAAAAAAAAAA- -AAAAAAAAAAAAAAAAAA- -AAAAAAAAAAAAAAAAAA- -AAAAAAAAAAAAAAAAAA- -AAAAAAAAAAAAAAAAAA- -------------------- 
-------BBBBBBB------ ------BBBBBBBBB----- ----BBBBAAAAABBBB--- --BBBBAAAAAAAAABBB-- --BBAAAAAAAAAAAAAB-- --BBAAAAAAAAAAAAAB-- --BBAAAAAAAAAAAAAB-- --BBAAAAAAAAAAAAAB-- --BBAAAAAAAAAAAAAB-- --BBAAAAAAAAAAAAAB-- --GGGAAAAAAAAAAAAB-- --BBAAAAAAAAAAAAAB-- --BBAAAAAAAAAAAAAB-- -DDAAAAAAAAAAAAAAAD- -DDAAAAAAAAAAAAAAAD- -DDBAAAAAAAAAAAAABD- ---BAAAAAAAAAAAAAB-- -AAAAAAAAAAAAAAAAAA- -AAAAAAAAAAAAAAAAAA- -AAAAAAAAAAAAAAAAAA- -AAAAAAAAAAAAAAAAAA- -AAAAAAAAAAAAAAAAAA- -AAAAAAAAAAAAAAAAAA- -AAAAAAAAAAAAAAAAAA- -AAAAAAAAAAAAAAAAAA- -AAAAAAAAAAAAAAAAAA- -AAAAAAAAAAAAAAAAAA- ---------AAA-------- 
-------BBBBBBB------ ------BBBBBBBBB----- ----BBBBAAAAABBBB--- ----BBAAAAAAAAABBB-- ----BAAAAAAAAAAAAB-- --BBAAAAAAAAAAAAAB-- --BBAAAAAAAAAAAAAB-- --BBAAAAAAAAAAAAAB-- --BBAAAAAAAAAAAAAB-- --BBAAAAAAAAAAAAAB-- --BBAAAAAAAAAAAAAG-- --BBAAAAAAAAAAAAAB-- --BBAAAAAAAAAAAAAB-- -DDAAAAAAAAAAAAAAAD- -DDAAAAAAAAAAAAAAAD- -DDBAAAAAAAAAAAAABD- ---BAAAAAAAAAAAAAC-- -AAAAAAAAAAAAAAAAAA- -AAAAAAAAAAAAAAAAAA- -AAAAAAAAAAAAAAAAAA- -AAAAAAAAAAAAAAAAAA- -AAAAAAAAAAAAAAAAAA- -AAAAAAAAAAAAAAAAAA- -AAAAAAAAAAAAAAAAAA- -AAAAAAAAAAAAAAAAAA- -AAAAAAAAAAAAAAAAAA- -AAAAAAAAAAAAAAAAAA- ---------AAA-------- 
-------BBBBBBB------ ------BBBBBBBBB----- ----BBBBAAAAABBBB--- ----BBAAAAAAAAABB--- ----BAAAAAAAAAAAB--- ----BAAAAAAAAAAAAB-- --BBAAAAAAAAAAAAAB-- --BBAAAAAAAAAAAAAB-- --BBAAAAAAAAAAAAAB-- --BBAAAAAAAAAAAAAB-- --BBAAAAAAAAAAAAAB-- --BBAAAAAAAAAAAAAG-- --BBAAAAAAAAAAAAAB-- -DDAAAAAAAAAAAAAAAD- -DDAAAAAAAAAAAAAAAD- -DDBAAAAAAAAAAAAACD- ---BAAAAAAAAAAAAAC-- -AAAAAAAAAAAAAAAAAA- -AAAAAAAAAAAAAAAAAA- -AAAAAAAAAAAAAAAAAA- -AAAAAAAAAAAAAAAAAA- -AAAAAAAAAAAAAAAAAA- -AAAAAAAAAAAAAAAAAA- -AAAAAAAAAAAAAAAAAA- -AAAAAAAAAAAAAAAAAA- -AAAAAAAAAAAAAAAAAA- -AAAAAAAAAAAAAAAAAA- -------------------- 
-------BBBBBBB------ ------BBBBBBBBB----- ----BBBBBBBBBBBBB--- ----BAAAAAAAAAAAB--- ----BAAAAAAAAAAAB--- ----BAAAAAAAAAAAB--- ----BAAAAAAAAAAAAB-- ----BAAAAAAAAAAAAB-- ----BAAAAAAAAAAAAB-- BBBBAAAAAAAAAAAAAB-- BBBAAAAAAAAAAAAAAB-- --BAAAAAAAAAAAAAAB-- BBBAAAAAAAAAAAAAAB-- BAAAAAAAAAAAAAAAAAD- BDDAAAAAAAAAAAAAAAD- -DDBAAAAAAAAAAAAACD- ---BAAAAAAAAAAAAAAA- -AAAAAAAAAAAAAAAAAA- -AAAAAAAAAAAAAAAAAA- -AAAAAAAAAAAAAAAAAA- -AAAAAAAAAAAAAAAAAA- -AAAAAAAAAAAAAAAAAA- -AAAAAAAAAAAAAAAAAA- -AAAAAAAAAAAAAAAAAA- -AAAAAAAAAAAAAAAAAA- -AAAAAAAAAAAAAAAAAA- -AAAAAAAAAAAAAAAAAA- -------------------- 
-------BBBBBBB------ ------BBBBBBBBB----- ----BBBBBBBBBBBBB--- ----BAAAAAAAAAAAB--- ----BAAAAAAAAAAAB--- ----BAAAAAAAAAAAB--- ----BAAAAAAAAAAAB--- ----BAAAAAAAAAAAB--- ----BAAAAAAAAAAAB--- BBBBAAAAAAAAAAAAABBB BBAAAAAAAAAAAAAAAABB --BAAAAAAAAAAAAAAB-- -BBAAAAAAAAAAAAAAABB -BAAAAAAAAAAAAAAAAAB BDDAAAAAAAAAAAAAAAAB -DDBAAAAAAAAAAAAACD- ---BAAAAAAAAAAAAAAA- -AAAAAAAAAAAAAAAAAA- -AAAAAAAAAAAAAAAAAA- -AAAAAAAAAAAAAAAAAA- -AAAAAAAAAAAAAAAAAA- -AAAAAAAAAAAAAAAAAA- -AAAAAAAAAAAAAAAAAA- -AAAAAAAAAAAAAAAAAA- -AAAAAAAAAAAAAAAAAA- -AAAAAAAAAAAAAAAAAA- -AAAAAAAAAAAAAAAAAA- -------------------- 
-------BBBBBBB------ ------BBBBBBBBB----- ----BBBBBBBBBBBBB--- ----BAAAAAAAAAAAB--- ----BAAAAAAAAAAAB--- ----BAAAAAAAAAAAB--- ----BAAAAAAAAAAAB--- ----BAAAAAAAAAAAB--- ----BAAAAAAAAAAAB--- BBB-BAAAAAAAAAAAABBB BBBBAAAAAAAAAAAAAABB -BBAAAAAAAAAAAAAAB-- BBBAAAAAAAAAAAAAAB-- -BBAAAAAAAAAAAAAAABB BBBAAAAAAAAAAAAAAABB -DDBAAAAAAAAAAAAAAA- ---BAAAAAAAAAAAAAAA- -AAAAAAAAAAAAAAAAAA- -AAAAAAAAAAAAAAAAAA- -AAAAAAAAAAAAAAAAAA- -AAAAAAAAAAAAAAAAAA- -AAAAAAAAAAAAAAAAAA- -AAAAAAAAAAAAAAAAAA- -AAAAAAAAAAAAAAAAAA- -AAAAAAAAAAAAAAAAAA- -AAAAAAAAAAAAAAAAAA- -AAAAAAAAAAAAAAAAAA- -------------------- 
-------------------- -------------------- -------------------- ----BBBBBBBBBBBBB--- ----BAAAAAAAAAAAB--- ----BAAAAAAAAAAAB--- ----BAAAAAAAAAAAB--- ----BAAAAAAAAAAAB--- ----BAAAAAAAAAAAB--- --CCAAAAAAAAAAAAABBB BBCAAAAAAAAAAAAAAABB BBCAAAAAAAAAAAAAAABB BBC-AAAAAAAAAAAAAABB --BAAAAAAAAAAAAAAABB BBDAAAAAAAAAAAAAAABB -AAAAAAAAAAAAAAAAAA- -AAAAAAAAAAAAAAAAAA- -AAAAAAAAAAAAAAAAAA- -AAAAAAAAAAAAAAAAAA- -AAAAAAAAAAAAAAAAAA- -AAAAAAAAAAAAAAAAAA- -AAAAAAAAAAAAAAAAAA- -AAAAAAAAAAAAAAAAAA- -AAAAAAAAAAAAAAAAAA- -AAAAAAAAAAAAAAAAAA- -AAAAAAAAAAAAAAAAAA- -AAAAAAAAAAAAAAAAAA- -------------------- 
-------------------- -------------------- -------------------- ----BBBBBBBBBBBBB--- ----BBAAAAAAAAAAB--- ----BBAAAAAAAAAAB--- ----BAAAAAAAAAAAB--- ----BAAAAAAAAAAAB--- ---CAAAAAAAAAAAAB--- --CAAAAAAAAAAAAAB--- --CAAAAAAAAAAAAAABBB BBCAAAAAAAAAAAAAAABB BBCAAAAAAAAAAAAAAAG- BBBAAAAAAAAAAAAAAAAB BAAAAAAAAAAAAAAAAABB -AAAAAAAAAAAAAAAAAA- -AAAAAAAAAAAAAAAAAA- -AAAAAAAAAAAAAAAAAA- -AAAAAAAAAAAAAAAAAA- -AAAAAAAAAAAAAAAAAA- -AAAAAAAAAAAAAAAAAA- -AAAAAAAAAAAAAAAAAA- -AAAAAAAAAAAAAAAAAA- -AAAAAAAAAAAAAAAAAA- -AAAAAAAAAAAAAAAAAA- -AAAAAAAAAAAAAAAAAA- -AAAAAAAAAAAAAAAAAA- -------------------- 
-------------------- -------------------- -------------------- ----BBBBBBBBBBBBB--- ----BBAAAAAAAAAAB--- ----BBAAAAAAAAAAB--- ----BAAAAAAAAAAAB--- ---CAAAAAAAAAAAAB--- ---CAAAAAAAAAAAAB--- --CAAAAAAAAAAAAAAC-- --CAAAAAAAAAAAAAAAB- --CAAAAAAAAAAAAAAABB --CAAAAAAAAAAAAAAABB ---CAAAAAAAAAAAAAABB -AAAAAAAAAAAAAAAAAD- -AAAAAAAAAAAAAAAAAA- -AAAAAAAAAAAAAAAAAA- -AAAAAAAAAAAAAAAAAA- -AAAAAAAAAAAAAAAAAA- -AAAAAAAAAAAAAAAAAA- -AAAAAAAAAAAAAAAAAA- -AAAAAAAAAAAAAAAAAA- -AAAAAAAAAAAAAAAAAA- -AAAAAAAAAAAAAAAAAA- -AAAAAAAAAAAAAAAAAA- -AAAAAAAAAAAAAAAAAA- -AAAAAAAAAAAAAAAAAA- -------------------- 
-------------------- -------------------- -------------------- -------------------- ----BBBBBBBBBBBBB--- ----BAAAAAAAAAAAB--- ---CAAAAAAAAAAAAB--- ---CAAAAAAAAAAAAB--- ---CAAAAAAAAAAAAACC- --CAAAAAAAAAAAAAAAC- --CAAAAAAAAAAAAAAAC- --C-AAAAAAAAAAAAAAC- --CAAAAAAAAAAAAAAAC- ---CAAAAAAAAAAAAAC-- -AAAAAAAAAAAAAAAAAA- -AAAAAAAAAAAAAAAAAA- -AAAAAAAAAAAAAAAAAA- -AAAAAAAAAAAAAAAAAA- -AAAAAAAAAAAAAAAAAA- -AAAAAAAAAAAAAAAAAA- -AAAAAAAAAAAAAAAAAA- -AAAAAAAAAAAAAAAAAA- -AAAAAAAAAAAAAAAAAA- -AAAAAAAAAAAAAAAAAA- -AAAAAAAAAAAAAAAAAA- -AAAAAAAAAAAAAAAAAA- -------------------- -------------------- 
-------------------- -------------------- -------------------- -------------------- ----BBBBCCCCBBBBB--- ----BBCCCCCCCCCBB--- ---CAAAAAAAAAAAAB--- ---CAAAAAAAAAAAAACC- ---CAAAAAAAAAAAAAAC- --CAAAAAAAAAAAAAAAC- --CAAAAAAAAAAAAAAAC- --C-AAAAAAAAAAAAAAC- --CAAAAAAAAAAAAAAAC- ---CAAAAAAAAAAAAAC-- -AAAAAAAAAAAAAAAAAA- -AAAAAAAAAAAAAAAAAA- -AAAAAAAAAAAAAAAAAA- -AAAAAAAAAAAAAAAAAA- -AAAAAAAAAAAAAAAAAA- -AAAAAAAAAAAAAAAAAA- -AAAAAAAAAAAAAAAAAA- -AAAAAAAAAAAAAAAAAA- -AAAAAAAAAAAAAAAAAA- -AAAAAAAAAAAAAAAAAA- -AAAAAAAAAAAAAAAAAA- -------------------- -------------------- -------------------- 
-------------------- -------------------- -------------------- -------------------- -------------------- -------------------- ---CCCCCCCCCCCCCCC-- ---CCCCCCCCCCCCCCCC- ---CCCCCCCCCCCCCCCC- --CAAAAAAAAAAAAAAAC- --CAAAAAAAAAAAAAAAC- --CAAAAAAAAAAAAAAAC- --CAAAAAAAAAAAAAAAC- ---CAAAAAAAAAAAAAC-- -AAAAAAAAAAAAAAAAAA- -AAAAAAAAAAAAAAAAAA- -AAAAAAAAAAAAAAAAAA- -AAAAAAAAAAAAAAAAAA- -AAAAAAAAAAAAAAAAAA- -AAAAAAAAAAAAAAAAAA- -AAAAAAAAAAAAAAAAAA- -AAAAAAAAAAAAAAAAAA- -AAAAAAAAAAAAAAAAAA- -AAAAAAAAAAAAAAAAAA- -------------------- -------------------- -------------------- -------------------- 
-------------------- -------------------- -------------------- -------------------- -------------------- -------------------- -------------------- -------------------- -------------------- --CCCCCCCCCCCCCCCCC- --CAAAAAAAAAAAAAAAC- --CAAAAAAAAAAAAAAAC- --CAAAAAAAAAAAAAAAC- ---CCCCCCCCCCCCCCC-- -AAAAAAAAAAAAAAAAAA- -AAAAAAAAAAAAAAAAAA- -AAAAAAAAAAAAAAAAAA- -AAAAAAAAAAAAAAAAAA- -AAAAAAAAAAAAAAAAAA- -AAAAAAAAAAAAAAAAAA- -AAAAAAAAAAAAAAAAAA- -------------------- -------------------- -------------------- -------------------- -------------------- -------------------- -------------------- 
-------------------- -------------------- -------------------- -------------------- -------------------- -------------------- -------------------- -------------------- -------------------- -------------------- --CCCCCCCCCCCCCCCCC- --CCCCCCCCCCCCCCCCC- --CCCCCCCCCCCCCCCCC- -------------------- -AAAAAAAAAAAAAAAAAA- -AAAAAAAAAAAAAAAAAA- -AAAAAAAAAAAAAAAAAA- -AAAAAAAAAAAAAAAAAA- -------------------- -------------------- -------------------- -------------------- -------------------- -------------------- -------------------- -------------------- -------------------- -------------------- 
