model
size = 14 32 24, scale = 0.05, origin = -y
material 
  colors = A:#EEE B:#AAA C:#0CF D:#555 E:#111
voxels
32-C13-C433-2(A13-)A419-4(A13-)A391-AC12-A13-2(AC12-)2(A13-)A363-3(AC12-A13-)2(A13-)A335-A13-2(AC12-)A13-AC12-5(A13-)A307-12(A13-)A279-4(2A12-)10(A13-)A223-2D25-5(4A10-)4A11-2(2A12-)8(A13-)A194-4D11-2D10-13(6A8-)4(5A9-)5(4A10-)4A11-A13-A82-6D9-4D8-4(A7B6-)A7B5-9B7-10(A4BC8-)A4BC6-7B2(C8-A4B)C2(8-A3B2E)8-A3BE9-4AE10-4A10-3A2(12-2A)37-8D7-6D8-A4B2A5C2-A4BA5C3-A4BA4C4-A4BA3C5-4(A4BAC7-)12(A4BA8-)3(A3B2E8-)2(3ABE9-)5A2(10-4A)11-2A12-2C9-8D7-6D8-A4B2A5C2-A4BA5C3-A4BA4C4-A4BA3C5-4(A4BAC7-)12(A4BA8-)3(A3B2E8-)2(3ABE9-)5A2(10-4A)11-2A12-2C10-6D9-4D8-4(A7B6-)A7B5-9B7-10(A4BC8-)A4BC6-7B2(C8-A4B)C2(8-A3B2E)8-A3BE9-4AE10-4A10-3A2(12-2A)39-4D11-2D10-6(AB4A8-)7(6A8-)4(5A9-)5(4A10-)4A11-A13-A84-2D25-5(4A10-)4A11-2(2A12-)8(A13-)A223-4(2A12-)10(A13-)A251-12(A13-)A279-5(AC12-)5(A13-)A307-A13-2(AC12-)A13-AC12-3(A13-)A335-2(AC12-2(A13-))A363-4(A13-)A391-2(A13-)A419-C13-C401-
