model
size = 18 31 15, scale = 0.05, origin = -y
material 
  colors = A:#EEE B:#111 C:#444 D:#FC0 E:#C66
voxels
-----------AA----- -----------AA----- ----------AAA----- ----------AAA----- ----------AB------ ---------BBB------ --------BBB------- --------BB-------- --------BB-------- ------------------ ------------------ ------------------ ------------------ ------------------ ------------------ ------------------ ------------------ ------------------ ------------------ ------------------ ------------------ ------------------ ------------------ ------------------ ------------------ ------------------ ------------------ ------------------ ------------------ ------------------ ------------------ 
-----------AA----- -----------AA----- ----------AAA----- ----------AAB----- ----------AB------ ---------BAB------ --------BBB------- --------BB-------- --------BB-------- --------BB-------- ------------------ ------------------ ------------------ ------------------ ------------------ ------------------ ------------------ ------------------ ------------------ ------------------ ------------------ ------------------ ------------------ ------------------ ------------------ ------------------ ------------------ ------------------ ------------------ ------------------ ------------------ 
------------------ ------------------ ------------------ ------------------ ------------------ ------------------ ------------------ ------------------ --------BB-------- --------BB-------- ------------------ ------------------ ------------------ ------------------ ------------------ ------------------ ------------------ ------------------ ------------------ ------------------ ------------------ ------------------ ------------------ ------------------ ------------------ ------------------ ------------------ ------------------ ------------------ ------------------ ------------------ 
------------------ ------------------ ------------------ ------------------ ------------------ ------------------ ------------------ ------------------ --------BB-------- --------BB-------- ------------------ ------------------ ------------------ ------------------ ------------------ ------------------ ------------------ ------------------ ------------------ ------------------ ------------------ ------------------ ------------------ ------------------ ------------------ ------------------ ------------------ ------------------ ------------------ ------------------ ------------------ 
------------------ ------------------ ------------------ ------------------ ------------------ ------------------ ------------------ ------------------ ------BBBBBB------ ------ABAABB------ ------BBBBBB------ ------BBBBBB------ ------------------ ------------------ ------------------ ------------------ ------------------ ------------------ ------------------ ------------------ ------------------ ------------------ ------------------ ------------------ ------------------ ------------------ ------------------ ------------------ ------------------ ------------------ ------------------ 
------------------ ------------------ ------------------ ------------------ ------------------ ------------------ ------------------ ------------------ ------BBBBBB------ ------AAAAAB------ -----AAAAAAAB----- -----AAAAAAAB----- -----ABBBBBBB----- -----BBBBBBBB----- ------------------ ------------------ ------------------ ------------------ ------------------ ------------------ ------------------ ------------------ ------------------ ------------------ ------------------ ------------------ ------------------ ------------------ ------------------ ------------------ ------------------ 
------------------ ------------------ ------------------ ------------------ ------------------ ------------------ ------------------ ------------------ -----BBBAAAAA----- ----AAAAAAAAAA---- ----AAAAAAAAAA---- ----AAAAAAAAAA---- ----AAAAAAAAAA---- -----AAAAAAAA----- -----BBBBBBBB----- ------BBBBBB------ ------BBBBBB------ -------BBBB------- ------------------ ------------------ ------------------ ------------------ ------------------ ------------------ ------------------ ------------------ ------------------ ------------------ ------------------ ------------------ ------------------ 
------------------ ------------------ ------------------ ------------------ ------------------ ------------------ ------------------ ------------------ ----AAAAAAAAAA---- ----AAAAAAAAAA---- ----AAAAAAAAAA---- ----AAAAAAAAAA---- ----AAAAAAAAAA---- ----AAAAAAAAAA---- -----AAAAAAAA----- -----BAAAAAAB----- -----BAAAAAAB----- ------BBBBBB------ ------------------ ------------------ ------------------ ------------------ ------------------ ------------------ ------------------ ------------------ ------------------ ------------------ ------------------ ------------------ ------------------ 
------------------ ------------------ ------------------ ------------------ ------------------ ------------------ ------------------ ------------------ ----AAAAAAAAAA---- ----AAAAAAAAAA---- -----AAAAAAAA----- ----AAAAAAAAAA---- ----AAAAAAAAAA---- ----AAAAAAAAAA---- -----AAAAAAAA----- -----AAABBBAA----- -----AABBBBBA----- -----BBBBBBBB----- -----BBBBBBBB----- ------BBBBBB------ -------BBBB------- -------BBBB------- ------------------ -------AAAA------- ------AAAAAB------ ------AAAAAB------ ------ABBBBB------ ------------------ ------------------ ------------------ ------------------ 
------------------ ------------------ ------------------ ------------------ ------------------ ------------------ ------------------ ------------------ ----AAAAAAAAAA---- -----AAAAAAAA----- -----AAAAAAAA----- -----AAAAAAAA----- -----AAAAAAAA----- -----AAAAAAAA----- -----AAAAAAAA----- -----AAABBAAA----- -----AAAAAAAA----- -----AAAAAAAA----- -----AAAAAAAA----- -----AAAAAAAA----- -----AAAAAAAA----- ------AAAAAA------ ------ABBBBA------ ------AAAAAA------ ------AAAAAB------ ------AAAAAB------ ------AAAAAB------ ------ABBBBB------ ------A----B------ ------------------ ------------------ 
------------------ ------------------ ------------------ ------------------ ------------------ ------------------ ------------------ ------------------ ----AA------AA---- ------------------ ------------------ ------------------ ------------------ ------------------ ------------------ ------------------ -----AAABAAAA----- -----AAAAAAAA----- -----AAAAAAAA----- -----AAAAAAAA----- -----AAAAAAAA----- -----AAAAAAAA----- ------AAAAAA------ ------AAAAAA------ ------AAAAAB------ ------AAAAAB------ ------AAAAAB------ -----AABBBBAB----- -----AA----BB----- -----AA----BB----- ------A----B------ 
------------------ ------------------ ------------------ ------------------ ------------------ ------------------ ------------------ ------------------ -----BB----AA----- -----BB----AA----- -----BB----AA----- -----BB----AA----- -----BB----AB----- -----BB----BB----- -----BB----BB----- -----BB----BA----- -----BB----AA----- -----BAAAAAAA----- -----AAAAAAAA----- -----AAAAAAAA----- -----AAAAAAAA----- -----AAAAAAAA----- ------AAAAAA------ ------AAAAAA------ ------AAAAAB------ ------AAAAAB------ ------AAAAAB------ ------ABBBBB------ ------------------ ------------------ ------------------ 
------------------ ------------------ ------------------ ------------------ ------------------ ------------------ ------------------ ------------------ -----BB----AA----- -----BB----AA----- -----BB----AA----- -----BB----BA----- -----BB----BB----- -----BB----BB----- -----BB----BB----- -----BB----BA----- -----BB----AA----- -----BBBBBAAA----- -----BBBBBBAA----- ------BBBBBA------ ------BBBBBA------ -------AAAA------- ------------------ ------AAAAAA------ ------AAAAAB------ ------AAAAAB------ -----DDDAADDD----- -----D-DBBD-D----- -----DDD--DDD----- ------------------ ------------------ 
------------------ ------------------ ------------------ ------------------ ------------------ ------------------ ------------------ ------------------ -----BB----AA----- ------------------ ------------------ ------------------ ------------------ ------------------ ------------------ ------------------ ------------------ ------------------ ------------------ ------------------ ------------------ ------------------ ------------------ ------AAAAAA------ ------AAAAAB------ CCCCCCAAAABBCCCCCC --------AB-------- ------B-BB-B------ ------------------ ------------------ ------------------ 
------------------ ------------------ ------------------ ------------------ ------------------ ------------------ ------------------ ------------------ -----BB----AA----- ------------------ ------------------ ------------------ ------------------ ------------------ ------------------ ------------------ ------------------ ------------------ ------------------ ------------------ ------------------ ------------------ ------------------ -CCCCCCAAAACCCCCC- -------AAAA------- --------EE-------- --------EE-------- ------------------ ------------------ ------------------ ------------------ 
