model
size = 21 31 21, scale = 0.05, origin = -y
material 
  colors = A:#001 B:#B00 C:#E00
voxels
--------------------- --------------------- --------------------- --------------------- --------------------- --------------------- --------------------- --------------------- --------------------- --------------------- --------------------- --------------------- --------------------- --------------------- --------------------- --------------------- --------------------- ------AAAACCAAA------ ------ACCAACCAC------ ------ACCAACCAA------ ------ACAAACAAC------ ------AACCCAAAA------ ------AAAAAAAAA------ ------AAABBBAAA------ ------AAAAAAAAA------ --------------------- --------------------- --------------------- --------------------- --------------------- --------------------- 
--------------------- --------------------- --------------------- --------------------- --------------------- --------------------- --------------------- --------------------- --------------------- --------------------- --------------------- -------AAAAAAA------- -------AAAAAAA------- -------AAAAAAA------- -------ACAAAAA------- -------AACAAAA------- -------AAACAAA------- ----AAA-------AA----- ----AA--------AA----- ----AA--------AA----- ----AA--------AA----- ----AA--------AA----- ----AAAA-----AAA----- ----AAAA-BBB-AAA----- ----AAABBBBBBBAA----- --------------------- --------------------- --------------------- --------------------- --------------------- --------------------- 
--------------------- --------------------- --------------------- --------------------- --------CCCAA-------- --------CCCAA-------- --------AACAA-------- --------AACAA-------- --------AACAA-------- --------AACAC-------- --------AACCA-------- -----AAB-----BAA----- -----CC-------AC----- -----AA-------AB----- -----BA-------AA----- -----AA-------AA----- -----CA-------AA----- ---AA-----------A---- ---A------------A---- ---A------------A---- ---A------------A---- ---A------------A---- ---A------------A---- ---AAAAA-----AAAA---- ---AAAAA-----AAAA---- ---AAAABBBBBBBAAA---- ---AAAAAAAAAAAAA----- --------------------- --------------------- --------------------- --------------------- 
--------BBBBB-------- --------BBBBB-------- --------AAAAA-------- --------AAAAA-------- ------AA-----AA------ ------AA-----AA------ ------AA-----AA------ ------AA-----AA------ ------CA-----AA------ ------AA-----AA------ ------CC-----AC------ ----AB---------BB---- ----B-----------C---- ----A-----------A---- ----C-----------C---- ----A-----------A---- ----C-----------C---- --AA-------------A--- --A--------------A--- --A--------------A--- --A--------------A--- --A--------------A--- --A--------------A--- --AAAAAA-----A---A--- --AAAAAA-----A---A--- --AAAAAA-----A---A--- --AAAAAA-----A--AA--- ---AAAABBBBBBBAAAA--- --------------------- --------------------- --------------------- 
------BB-----BB------ ------BB-----BB------ ------AA-----AA------ ------AA-----AA------ ----AA---------AA---- ----AA---------AA---- ----AA---------AA---- ----AA---------AA---- ----CC---------CC---- ----AA---------AA---- ----CC---------CC---- ---A-------------A--- ---C-------------C--- ---A-------------A--- ---C-------------C--- ---A-------------A--- ---C-------------C--- -AA---------------A-- -A----------------A-- -A----------------A-- -A----------------A-- -A----------------A-- -B----------------A-- -BA----------A----A-- -BA----------A----A-- -BA----------A----A-- -BA----------A----A-- -BA----------A----A-- -BAAAAAAAAAAAAAAAAA-- --------------------- --------------------- 
-----B---------B----- -----B---------B----- -----A---------A----- -----A---------A----- ----A-----------A---- ----A-----------A---- ----A-----------A---- ----A-----------A---- ----C-----------C---- ----A-----------A---- ----C-----------C---- --AB-------------AA-- --B---------------C-- --A---------------B-- --C---------------C-- --A---------------A-- --C---------------C-- -A-----------------A- -A-----------------A- -A-----------------A- -A-----------------A- -B-----------------A- ------------------A-- -------------AAAAAA-- -------------AAAAAA-- -------------AAAAAA-- -------------AAAAAA-- -------------AAAAAA-- -BAAAAABBBBBBBAAAAA-- --------------------- --------------------- 
----B-----------B---- ----B-----------B---- ----A-----------A---- ----A-----------A---- ---A-------------A--- ---A-------------A--- ---A-------------A--- ---A-------------A--- ---C-------------C--- ---A-------------A--- ---C-------------C--- --A---------------A-- --C---------------C-- --A---------------A-- --C---------------C-- --A---------------A-- --C---------------C-- -A-----------------A- -A-----------------A- -A-----------------A- -A-----------------A- -B-----------------A- -------------------B- -------------------B- -------------------B- -------------------B- -------------------B- -------------------B- -------------------B- -BAAAAABBBBBBBAAAAABB --------------------- 
----B-----------B---- ----B-----------B---- ----A-----------A---- ----A-----------A---- ---A-------------A--- ---A-------------A--- ---A-------------A--- ---A-------------A--- ---C-------------C--- ---B-------------A--- ---C-------------C--- -AB---------------BA- -C-----------------C- -A-----------------A- -C-----------------C- -A-----------------B- -C-----------------C- A-------------------A A-------------------A A-------------------A A-------------------A B-------------------B --------------------- --------------------- --------------------- --------------------- --------------------- --------------------- --------------------- -BAAAAB-------BAAAAB- --------------------- 
---B-------------B--- ---B-------------B--- ---A-------------A--- ---A-------------A--- --A---------------A-- --A---------------A-- --A---------------A-- --A---------------A-- --C---------------C-- --A---------------A-- --C---------------C-- -A-----------------B- -C-----------------C- -A-----------------A- -C-----------------C- -A-----------------A- -C-----------------C- A-------------------A A-------------------A A-------------------A B-------------------B --------------------- --------------------- --------------------- --------------------- --------------------- --------------------- --------------------- --------------------- --------------------- -BAAAB---------BAAAB- 
---B-------------B--- ---B-------------B--- ---A-------------A--- ---A-------------A--- --A---------------A-- --A---------------A-- --A---------------A-- --A---------------A-- --C---------------C-- --A---------------A-- --C---------------C-- -B-----------------A- -B-----------------C- -A-----------------A- -C-----------------C- -A-----------------A- -C-----------------C- A-------------------A A-------------------A B-------------------B --------------------- --------------------- --------------------- --------------------- --------------------- --------------------- --------------------- --------------------- --------------------- --------------------- -BAAB-----------BAAB- 
---B-------------B--- ---B-------------B--- ---A-------------A--- ---A-------------A--- --A---------------A-- --A---------------A-- --A---------------A-- --A---------------A-- --C---------------C-- --A---------------A-- --C---------------C-- -A-----------------A- -C-----------------C- -A-----------------B- -C-----------------C- -A-----------------A- -C-----------------C- A-------------------A B-------------------B --------------------- --------------------- --------------------- --------------------- --------------------- --------------------- --------------------- --------------------- --------------------- --------------------- --------------------- -BAAB-----------BAAB- 
---B-------------B--- ---B-------------B--- ---A-------------A--- ---A-------------A--- --A---------------A-- --A---------------A-- --A---------------A-- --A---------------A-- --C---------------C-- --A---------------A-- --C---------------C-- -A-----------------A- -C-----------------C- -B-----------------A- -C-----------------C- -A-----------------A- -C-----------------C- A-------------------A A-------------------A B-------------------B --------------------- --------------------- --------------------- --------------------- --------------------- --------------------- --------------------- --------------------- --------------------- --------------------- -BAAB-----------BAAB- 
---B-------------B--- ---B-------------B--- ---A-------------A--- ---A-------------A--- --A---------------A-- --A---------------A-- --A---------------A-- --A---------------A-- --C---------------C-- --A---------------A-- --C---------------C-- -A-----------------B- -C-----------------C- -A-----------------A- -C-----------------C- -A-----------------A- -C-----------------C- A-------------------A A-------------------A A-------------------A B-------------------B --------------------- --------------------- --------------------- --------------------- --------------------- --------------------- --------------------- --------------------- --------------------- -BAAAB---------BAAAB- 
----B-----------B---- ----B-----------B---- ----A-----------A---- ----A-----------A---- ---A-------------A--- ---A-------------A--- ---A-------------A--- ---A-------------A--- ---C-------------C--- ---A-------------A--- ---C-------------C--- -AB---------------BA- -C-----------------C- -A-----------------A- -C-----------------C- -B-----------------A- -C-----------------C- A-------------------A A-------------------A A-------------------A A-------------------A B-------------------B --------------------- --------------------- --------------------- --------------------- --------------------- --------------------- --------------------- -BAAABB-------BBAAAB- --------------------- 
----B-----------B---- ----B-----------B---- ----A-----------A---- ----A-----------A---- ---A-------------A--- ---A-------------A--- ---A-------------A--- ---A-------------A--- ---C-------------C--- ---A-------------A--- ---C-------------C--- --A---------------B-- --C---------------C-- --A---------------A-- --C---------------C-- --A---------------A-- --C---------------C-- -A-----------------A- -A-----------------A- -A-----------------A- -A-----------------A- -B-----------------B- --------------------- --------------------- --------------------- --------------------- --------------------- --------------------- --------------------- -BAAAAABBBBBBBAAAAAB- --------------------- 
-----B---------B----- -----B---------B----- -----A---------A----- -----A---------A----- ----A-----------A---- ----A-----------A---- ----A-----------A---- ----A-----------A---- ----C-----------C---- ----A-----------A---- ----C-----------C---- --AB-------------AA-- --C---------------C-- --A---------------B-- --B---------------C-- --A---------------A-- --C---------------C-- -A-----------------A- -A-----------------A- -A-----------------A- -A-----------------A- -A-----------------A- -B-----------------B- -B-----------------B- -B-----------------B- -B-----------------B- -B-----------------B- -B-----------------B- -BAAAAABBBBBBBAAAAAB- --------------------- --------------------- 
------BB-----BB------ ------BB-----BB------ ------AA-----AA------ ------AA-----AA------ ----AA---------AA---- ----AA---------AA---- ----AA---------AA---- ----AA---------AA---- ----CC---------AA---- ----AA---------AA---- ----CC---------AA---- ---A-------------A--- ---C-------------C--- ---A-------------A--- ---C-------------C--- ---A-------------A--- ---C-------------C--- -AA---------------A-- -AA---------------A-- -AA---------------A-- -AA---------------A-- -AA---------------A-- -AA---------------A-- -AA---------------A-- -AA---------------A-- -AA---------------A-- -AA---------------A-- -AA---------------AB- -AAAAAAAAAAAAAAAAAAB- --------------------- --------------------- 
--------BBBBB-------- --------BBBBB-------- --------AAAAA-------- --------AAAAA-------- ------AA-----AA------ ------AA-----AA------ ------AA-----AA------ ------AA-----AA------ ------CA-----CA------ ------AA-----CA------ ------CA-----CA------ ----AB---------BA---- ----C-----------C---- ----A-----------A---- ----C-----------C---- ----B-----------A---- ----C-----------A---- ---AA------------A--- ---AA------------A--- ---AA------------A--- ---AA------------A--- ---AA------------A--- ---AA------------A--- ---AAAAA-----AAAAA--- ---AAAAA-----AAAAA--- ---AAAAA-----AAAAA--- ---AAAAA-----AAAAA--- --AAAAABBBBBBBAAAAA-- --------------------- --------------------- --------------------- 
--------------------- --------------------- --------------------- --------------------- --------AAAAA-------- --------AAAAA-------- --------AAAAA-------- --------AAAAA-------- --------AAACC-------- --------AAACC-------- --------AAACC-------- -----AAB-----BAA----- -----CA-------AA----- -----AA-------AA----- -----CA-------AA----- -----AA-------AA----- -----CA-------AA----- -----A----------A---- -----A----------A---- -----A----------A---- -----A----------A---- -----A----------A---- -----AB---------A---- -----AAA-----AAAA---- ----AAAA-----AAAA---- ----AAABBBBBBBAAAA--- ----AAAAAAAAAAAAAA--- --------------------- --------------------- --------------------- --------------------- 
--------------------- --------------------- --------------------- --------------------- --------------------- --------------------- --------------------- --------------------- --------------------- --------------------- --------------------- -------AAAACAA------- -------AACACAA------- -------AAACCAA------- -------ACAACAA------- -------AACCCAA------- -------AAAAAAA------- -----AAAAAAAAAAA----- -----AAAAAAAAAAA----- -----AAAAAAAAAAA----- -----AAAAAAAAAAA----- -----AAAAAAAAAAA----- -----AAAAAAAAAAA----- -----AAAABBBAAAA----- -----AABBBBBBBAA----- --------------------- --------------------- --------------------- --------------------- --------------------- --------------------- 
--------------------- --------------------- --------------------- --------------------- --------------------- --------------------- --------------------- --------------------- --------------------- --------------------- --------------------- --------------------- --------------------- --------------------- --------------------- --------------------- --------------------- ------AAAACCCA------- ------AAAACCCA------- ------AAAACAAA------- ------AACACAAA------- ------AAACCAAA------- ------AAAAAAAA------- ------AAA---AA------- ------AAAAAAAA------- --------------------- --------------------- --------------------- --------------------- --------------------- --------------------- 
