model
size = 30 6 30, scale = 0.05, origin = -y
material 
  colors = A:#E00 B:#DDD C:#B00 D:#EEE E:#700
voxels
-----------C------------------ -----------A------------------ -----------A------------------ ------------------------------ ------------------------------ ------------------------------ 
------------------------------ -----------AA----------------- -----------AA----------------- ------------------------------ ------------------------------ ------------------------------ 
------------C----------------- -----------AA----------------- -----------AA----------------- ------------------------------ ------------------------------ ------------------------------ 
------------------------------ -----------AA----------------- -----------AA----------------- ------------------------------ ------------------------------ ------------------------------ 
-----------C-C---------------- -----------ABA---------------- -----------AA----------------- ------------------------------ ------------------------------ ------------------------------ 
------------------------------ -----------ABAA--------------- -----------AAA---------------- ------------------------------ ------------------------------ ------------------------------ 
------------C-C--------------- ------------AAA--------------- ------------AAA--------------- ------------------------------ ------------------------------ ------------------------------ 
-----------------------------C ------------ABAA------------AA ------------AAA--------------- ------------------------------ ------------------------------ ------------------------------ 
-----------C----C--------C-C-- -----------AABAAA--------AAAA- ------------AAAAA------------- -------------AAA-------------- ------------------------------ ------------------------------ 
------------------------------ ------------AABAA-------AAAA-- ------------AAAAA------------- -------------AAA-------------- ------------------------------ ------------------------------ 
------------C---C----C-A--A--- ------------AABAA----AAAABA--- ------------AAAAA-----AAAA---- -------------AAA-------------- ------------------------------ ------------------------------ 
-------------------C---------- ------------AABAAAAAAAAABA---- ------------AAAAAA-AAAAAAA---- -------------AAAAA------------ ----------------A------------- ------------------------------ 
------------C------------C---- ------------AABAAAAAAABBAA---- -------------AAAAAAAAAAAA----- -------------AAAAA--AAA------- ---------------AA------------- ------------------------------ 
-----------------------C------ ------------AAABAAAABBAA------ -------------AAAAAAAAAA------- -------------DDAADDAAAA------- ------------------------------ ------------------------------ 
---------C-C------------------ --------AAAAAAABAABBAAA------- ---------AAAAAAAAAAAAAA------- ------------AEDAAADAAAA------- ---------------AAE------------ ------------------------------ 
----C--C--------------C------- ----AAAAAAAAAAABBBAAAAA------- ------AAAAAAAAAAAAAAAAA------- ---------AAAAAAAAAAAA--------- -------------A-AAAAA---------- -------------AA--------------- 
C----------------------------- AAAAABBBBBBBBBBB-BAAA--------- ----AAAAAAAAAAAADAAAA--------- --------AAAAAAAAAAAAA--------- -----------AAA-AAA-A---------- -------------AA--------------- 
---C-C---------------C-------- ---AAAAAAAAAAAABBBBAAA-------- -----AAAAAAAAAAAAAAAAA-------- ---------AAAAAAAAAAA---------- -----------AAAAAAA------------ -------------AA--------------- 
-------C--C------------------- -------AAAAAAAABAAABAA-------- --------AAAAAAAAAAAAAA-------- -----------AAAAAAAAAA--------- -----------AAAA-AA------------ -------------AA--------------- 
------------------------------ -----------AAAABAAAABBAC------ ------------AAAAAAAAAA-------- -------------AAAAAAAA--------- ------------------------------ ------------------------------ 
-----------------C------------ -----------AAABAAAAAAABA------ -----------AAAAA-AAAAAAA------ ------------AAAA--AAAA-------- ------------------------------ ------------------------------ 
-----------C-------C-C--C----- -----------AAABAA-AAAAABA----- -----------AAAAAA-AA-AAA------ -----------AAAAA---A---------- ------------------------------ ------------------------------ 
----------------C------------- ------------ABAAA----AAAAAC--- -------------AAAA----AAA------ -------------A---------------- ------------------------------ ------------------------------ 
--------------C-------C-C----- -----------AABA------AAAAAA--- -----------AAAA----------AA--- -------------A---------------- ------------------------------ ------------------------------ 
-----------C--------------C--- ----------AABAA-----------AA-- -----------AAA------------A--- ------------A----------------- ------------------------------ ------------------------------ 
----------C---C------------C-- ----------AABAA-----------AA-- ------------AAA--------------- -------------A---------------- ------------------------------ ------------------------------ 
-------------C---------------- ----------AAAA---------------- -----------A------------------ ------------------------------ ------------------------------ ------------------------------ 
----------C------------------- ----------AAA----------------- ----------A-A----------------- ------------------------------ ------------------------------ ------------------------------ 
------------C----------------- ----------AAA----------------- -----------A------------------ ------------------------------ ------------------------------ ------------------------------ 
----------C------------------- ----------A------------------- ------------------------------ ------------------------------ ------------------------------ ------------------------------ 
