model
size = 16 17 30, scale = 0.05, origin = -y
material 
  colors = A:#FF0 B:#001 C:#309 D:#EEE E:#222 F:#111 G:#333 H:#DDD
voxels
----A----------- ----AAAAA------- ---------------- ---------------- ---------------- ---------------- ---------------- ---------------- ---------------- ---------------- ---------------- ---------------- ---------------- ---------------- ---------------- ---------------- ---------------- 
--AA---AA------- ---AA---A------- ---------------- ---------------- ---------------- -----AAA-------- ----A---AAA----- ---A------AAA--- --AA--------AAA- -AA-----------A- AA------------AA AA------------A- -A-----------A-- --A---------A--- ---A-------A---- ----A----AA----- -----AAAA------- 
-A-----AA------- -AAA----AA------ ---------------- ---------------- ---------------- -----AAA-------- ----AAAAAAA----- ---AA-----AAA--- ---AA-------A--- -AA----------AA- AA-----------AAA AA------------A- -A-----------A-- --A-A-------A--- ---AA------A---- ----A----AA----- -----AAAA------- 
-A-----AA------- AAA-----AA------ -A-------------- ---------------- ---------------- ------AA-------- ------AAAAA----- ----AA----AAA--- ---AA------AAA-- --A---------AA-- -AA----------AAA -A------------A- -AA----------A-- --A---------A--- ---A-------A---- ----A----AA----- -----AAAA------- 
-A-----AA------- AAA-----AA------ -A-------------- ---------------- ---------------- ------AA-------- ------AAAAA----- -----A----A----- ---AA----------- ---A--------AA-- --A-----------A- -A-----------A-- --A----------A-- --A---------A--- ---A-------A---- ----A----AA----- -----AAAA------- 
-A-----AA------- AAA-----AA------ -A-------------- ---------------- ---------------- ------AA-A------ -----AAAAAA----- ---AA-----AA---- --AEA-------A--- --AA--------AA-- -A------------A- -A-----------A-- -A-----------A-- --A---------A--- --A-----AAAA---- ---A-----EA----- ----AAAAAA------ 
-A-----AA------- AAA-----AA------ -A-------------- ---------------- ---------------- ------A-AA------ ------AA-AA----- -----AA-AA-A---- ---AAA----AAA--- ---AA-----AA-A-- --A-----------A- -AA----------A-- --A--------AA--- --AA-------A---- --AA-----AA----- ---AA----A------ -----AAAA------- 
-A-----AA------- AAA-----AA------ -A-------------- ---------------- ---------------- --------AA------ -------A--A----- ------AA---A---- -----AAA-A--A--- ----A--------A-- --AA---------AA- -AAA---------A-- --A---------A--- --A--------A---- ---A------A----- ----A---AA------ -----AAAA------- 
-A-----AA------- AAA-----AA------ -A-------------- ---------------- ---------------- --------AA------ -------AA-A----- ------AA---A---- -----AAAAAA-A--- ----A-------A--- --AA-----AA--AA- -AAAAA-------AA- --AA--------AA-- ---A-------AA--- ----AA----AA---- -----AAAAAA----- -------AAA------ 
-A-----AA------- AAA-----AA------ -A-------------- ---------------- ---------------- -------AAA------ -------AAAA----- -----A--AA-A---- -----AAAAAAAA--- ----AAAAAA--AA-- ----AAAAABA--A-- --AAABA--AA-AA-- --AA-AA--AAAA--- ---A----AAAA---- ----AA--AAA----- -----AAAAA------ ---------------- 
-A-----AA------- AAA-----AA------ -A-------------- ---------------- ---------------- ---------------- -------AA------- -----A--A------- -----AAAAA------ ----ABBBBBAAA--- ----ABBBBBAAA--- ----ABBAAAAA---- ---AABA-ABA----- ---AAAAABA------ -----AAAAA------ -------A-------- ---------------- 
-A-----AA------- AAA-----AA------ -A-------------- ---------------- ---------------- ---------------- -------AA------- ------AAA------- ----AA-B-A------ ----ABBBBBA----- ----ABBBBBA----- ---ABBBBAABA---- ----ABAAA-A----- ----ABBABBA----- -----AABAA------ -------A-------- ---------------- 
-A-----AA------- AAA-----AA------ -A-------------- ---------------- ---------------- ---------------- -------A-------- -------AA------- -----AAAAA------ ----ABBBBBA----- ----ABBBBBA----- ----ABBBABA----- ----ABBBABA----- -----AB-BA------ ------AAA------- ---------------- ---------------- 
-A-----AA------- AAA-----AA------ -A-------------- ---------------- ---------------- ---------------- -------A-------- -------A-------- -----AAAA------- -----ABBBA------ ----ABBBBBA----- ----ABBBBBA----- -----ABBBA------ ------A-A------- -------AA------- ---------------- ---------------- 
-A-----AA------- AAA-----AA------ -A-------------- ---------------- ---------------- ---------------- ---------------- -------A-------- -------A-------- -----AAAA------- -----A-CAA------ ----AACBCA------ -----AACA------- -------A-------- ---------------- ---------------- ---------------- 
-AAAAAAAA------- AAAAAAAAAA------ -A-------------- ---------------- ---------------- ---------------- ---------------- ---------------- -------A-------- ------AA-------- -----AACA------- ----AACBCA------ -----AACA------- -------A-------- ---------------- ---------------- ---------------- 
-A------A------- AA------AA------ -A-------------- ---------------- ---------------- ---------------- ---------------- ---------------- -------A-------- ------AA-------- ------ACA------- ----AACBCA------ -----AACA------- -------A-------- ---------------- ---------------- ---------------- 
-A------A------- AA------AA------ -A------AA------ ---------------- ---------------- ---------------- ---------------- ---------------- -------A-------- ------AA-------- ------ACA------- ----AACBCA------ -----AACA------- -------A-------- ---------------- ---------------- ---------------- 
-A----AAA------- AA-------A------ -A-----AAA------ --------A------- --------A------- ---------------- ---------------- ---------------- ------AAA------- ------AAA------- ------ACA------- ----AACBCA------ -----AACA------- -------A-------- ---------------- ---------------- ---------------- 
-A-----AA------- AAAAAAAEEA------ -A-----AAA------ -------AAA------ -------AA------- -------AA------- -------AA------- -------AA------- ------A-EA------ ------AGEA------ ------ACAA------ ----AACBAA------ -----AACA------- -------A-------- ---------------- ---------------- ---------------- 
-A-------------- ADAAAAAAA------- -A-----AA------- -------AA------- --------A------- --------A------- --------A------- --------A------- -------AA------- ------AAA------- ------AFA------- ----AACBCA------ -----AACA------- -------A-------- ---------------- ---------------- ---------------- 
---------------- -D-----A-------- -------A-------- -------AA------- ---------------- ---------------- ---------------- ---------------- ---------------- ------AA-------- ------ACA------- ----AACBCA------ -----AACA------- -------A-------- ---------------- ---------------- ---------------- 
---------------- -D-------------- -------A-------- -------AA------- ---------------- ---------------- ---------------- ---------------- ---------------- ------AA-------- ------ACA------- ----AACBCA------ -----AACA------- -------A-------- ---------------- ---------------- ---------------- 
-H-------------- D-D------------- -D-----A-------- -------AA------- ---------------- ---------------- ---------------- ---------------- ---------------- ------AA-------- ------ACA------- ----AACBCA------ -----AACA------- -------A-------- ---------------- ---------------- ---------------- 
---------------- ---------------- -------A-------- -------AA------- ---------------- ---------------- ---------------- ---------------- ---------------- ------AA-------- ------ACA------- ----AACBCA------ -----AACA------- -------A-------- ---------------- ---------------- ---------------- 
---------------- ---------------- -------A-------- -------AA------- -------A-------- -------A-------- -------A-------- -------A-------- -------A-------- ------AAA------- ------ACA------- ----AACBCA------ -----AACA------- -------A-------- ---------------- ---------------- ---------------- 
---------------- ---------------- -------A-------- -------AA------- ---------------- ---------------- ---------------- ---------------- ---------------- ------AA-------- ------AA-------- -----AABA------- -------A-------- -------A-------- ---------------- ---------------- ---------------- 
---------------- ---------------- ---------------- -------AA------- ---------------- ---------------- ---------------- ---------------- ---------------- -------A-------- ------AA-------- ------AAA------- -------A-------- ---------------- ---------------- ---------------- ---------------- 
---------------- ---------------- ---------------- -------A-------- -------A-------- ---------------- ---------------- ---------------- -------A-------- -------A-------- ------AAA------- -------A-------- ---------------- ---------------- ---------------- ---------------- ---------------- 
---------------- ---------------- ---------------- ---------------- -------A-------- -------A-------- -------A-------- -------A-------- -------A-------- -------A-------- ---------------- ---------------- ---------------- ---------------- ---------------- ---------------- ---------------- 
