model
size = 21 32 7, scale = 0.05, origin = -y
material 
  colors = A:#FF3 B:#F96 C:#FC6 D:#FC9 E:#FFE122 F:#0FF G:#FFF H:#FF0 I:#FFC J:#DDD K:#FF6 L:#001
voxels
549-2F19-2F533-C19-EC18-2(DHCA17-)2(CA)17-EAC10-2F6-AH11-LF6-H124-6A13-8A13-2A5-2E12-2A5-AE12-3A-2J2-EA12-3A2J2-AE13-2A5-2(EA19-)2(2A19-)2A17-4A15-4A17-CA18-CE19-CE18-DEA18-DC2A17-DCHA6-2G9-DC2A8-K8-D4A7-G6-2D5A7-G7-D5A8-A6-C5A8-G6-E4A9-G2A4-H2AC11-A3C2-3A14-A2CA2H17-2A63-6B13-2B6A2B9-2B8AB11-B2A5-2AB9-2B2A2-2B-2AB10-B3AB2JB-2A2B9-B3A2JB-2AB9-B-B2A2B3-2AB11-2B5-2A2B10-B6-2(2AB18-)2A2B15-H3AB14-CH2A2B15-CA2B2-B13-CAB17-D2A2B15-D3AB16-D4A2B14-D4AB5-2I8-D4AB7-I6-CD5A2B5-I6-7AB6-I6-C6AB7-I5-C6A2B6-I5-C5AB8-I2A4-4AB10-3AH2-3AB-B9-B-6AB14-2B2A2B-B13-B-2B-B18-B42-2A3CA13-6A2C13-2A5-2C12-2A5-AC12-3A-2A2-2A12-5A2-2A13-2A5-2(2C19-)2(CD19-)2D17-ACDA15-2C2A17-2C18-2C19-CA18-DCA18-CE2A17-2C2A6-2G9-D3A8-K8-D4A7-G6-CE5A7-G7-6A8-G6-E5A8-G6-D4A9-G2A4-D3A11-3AH2-3A14-6A17-2A465-A19-DA18-2D2(A17-DED)A17-3DA18-DA11-2F6-H12-2F649-2F19-LF100-
