model
size = 27 24 32, scale = 0.05, origin = -y
material 
  colors = A:#6F6 B:#FF0 C:#F93 D:#F06 E:#3FF F:#F0F G:#66F H:#9CF
voxels
C25-C607-C13-2D23-4D23-2D553-D26-D13-3F2(21-6F)21-3F472-F25-3F24-3F25-F14-2G21-2G-5G17-9G19-4G-3G6-2G3-2G6-3G11-G5-G72-G9-G15-2G9-2G15-G9-G72-G5-G20-2G3-2G131-G25-3(3G24-)3G41-2E19-2E3-7E11-7E2-6E3-3E-3E3-6E2-5E3-9E3-5E3-3E2(3-4E)3-3E5-2E2-3E8-E3-2E10-2E9-2E13-2(3E9-3E12-)3E9-3E13-2E9-2E15-2E7-2E17-3E3-3E18-9E19-3E-3E50-E25-3E23-5E22-5E23-E-E24-3E68-3A17-3A4-23A3-2A2-17A-3A2-2A-18A-3A3-11A-11A2(5-8A)8-5A7-5A11-3A9-3A11-2A-A9-4A11-3A9-3A12-4A7-4A13-4A5-4A15-5A-5A16-2A-8A17-9A19-7A20-7A21-5A22-A3-A22-A2-2A22-5A23-3A69-2B17-2B6-21B5-3B-4B7-4B-3B4-2B3-3B-5B-3B3-2B4-2B2-14B3-2B5-2B-6B3-9B7-7B5-7B9-5B7-5B2(10-2B-2B7-2B-2B)11-5B5-2B-2B12-2B-3B3-6B13-2B-7B-2B14-2(3B2-)3B15-11B17-9B19-2B3-2B21-2(B3-B22-)5B22-5B101-9C13-19C2(7-3C-3C)6-2C2-3C7-3C2-2C5-2(3C-)6C2-3C-3C5-2C3H-2H6C-3C-2C7-C3H-2HC3-3C-4C9-2C2-2C5-2C2-2C9-2C3-2C5-2C3-2C9-C3-2C5-2C2-2C10-2C2-3C3-3C2-2C11-2C2-7C2-2C12-2C3-5C3-2C13-2C9-2C14-2C-10C15-11C17-3C3-3C19-2C3-2C21-5C22-5C127-11D13-4D8-5D9-5D8-6D8-5D9-5D7-5D10-6D6-2(5D3-)5D8-2D3-7D2-3D9-3D3-7D3-3D8-D5-3D-3D4-2D8-2D4-7D4-2D9-2D3-7D3-2D10-2D4-5D4-2(2D11-)2D12-2D10-2D14-2D9-2D15-11D16-11D18-7D21-5D154-11F14-3F9-3F12-3F9-3F11-2(4F9-)4F11-4F9-2F12-3F9-3F13-3F8-2F6-3F6-2F8-F7-3F7-F8-2F6-3F6-2F8-2F15-2F9-2F13-2F11-F2(12-2F)11-2F13-2F9-2F14-2F-7F-2F15-11F18-7F180-11G15-2G9-2G13-2G11-2G12-2(2G11-)2G13-2G10-G14-2G9-2G15-2G8-G17-G7-2G17-2G7-G16-2G8-2G15-2G9-2G13-2G10-2G13-G12-2G11-2G13-G11-G14-2G9-2G15-11G205-11E15-E10-2E13-2E11-2E12-E12-2E11-2E13-2E10-E15-E9-2E15-2E8-E17-E7-2E17-2E7-E17-E8-2E15-2E9-E14-2E10-2E13-E12-2E11-2E13-E11-E14-2E9-2E15-11E205-11A15-2A9-2A13-2A11-2A12-A12-2A11-2A13-2A10-A15-A9-2A15-2A8-A17-A7-2A17-2A7-A17-A8-2A15-2A9-A14-2A10-2A13-A12-2A11-2A13-A11-A14-2A9-2A15-11A205-11B15-2B9-2B13-2B11-2B12-B12-HB11-2B13-2B10-B15-B9-2B15-2B8-B17-B7-2B17-2B7-B17-B8-2B15-2B9-B14-2B10-2B13-B12-2B11-2B13-B11-B14-2B9-2B15-11B205-11C15-2C9-2C13-2C11-2C12-C12-2C11-2C13-2C10-C14-2C9-2C15-2C8-C17-C7-2C17-2C7-C16-2C8-2C15-2C9-C14-2C10-2C13-C12-2C11-2C13-C11-C14-2C9-2C15-11C205-11D15-2D9-2D13-2D11-2D12-2(2D11-)2D13-2D10-D14-2D9-2D15-2D2(8-D17-D)8-D16-2D8-2D15-2D9-2D13-2D10-2D13-D12-2D11-2D13-D10-2D14-2D9-2D15-11D205-11F15-2F9-2F14-F10-2F13-2(2F11-)2F13-2F10-2F13-2F9-2F15-2F8-F16-2F8-F17-F2(8-2F15-2F)9-2F13-2F11-F2(12-2F)11-2F13-F10-2F15-F9-F16-11F205-11G15-2G9-2G14-2G9-2G13-2G11-2G12-G12-2G11-2G13-2G10-G15-G9-2G15-2G8-G17-G8-2G15-2G9-G14-2G10-2G13-2(2G11-)2G12-2G11-2G13-2G9-2G15-G8-2G16-11G205-11E16-E8-2E15-2E9-2E13-2E11-2E12-2(2E11-)2E13-2E10-E14-2E9-2(2E15-2E8-)2E15-2E9-2E13-2E10-2E13-2(2E11-)2E13-E10-2E14-2E9-2E15-11E17-9E207-9A17-11A15-2A9-2A14-2A9-2A13-2(2A11-)2A12-2A11-2A13-2A10-A15-A9-2A15-2A9-A14-2A10-2A13-2(2A11-)2A12-2A11-2A13-2A9-2A15-A9-A16-11A234-7B18-11B16-B8-2B15-2B9-2B13-2B10-3B12-2(2B11-)2(2B13-2B10-)B15-B10-2B13-2B10-2B12-3B2(11-2B)13-B10-2B14-2B9-2B15-2B7-2B16-11B235-5C19-11C16-2C7-2C15-2C9-2C14-2C9-2C13-2C11-2C12-2(2C11-)2(2C13-2C10-)2C13-2(2C11-)2C12-2C10-3C13-2C9-2C14-2C8-3C15-2C7-2C17-9C261-9D17-11D16-2D7-2D15-2D9-2D14-2D9-2D13-2D11-2D12-D12-2D11-2D13-2(2D11-)2D12-2D11-2D13-2D9-2D14-2D8-3D15-2D7-2D16-11D17-9D263-5F20-9F17-2F7-2F16-2F7-2F15-2F9-2F14-2F9-2F13-2(2F11-2F12-)2F11-2F13-2F9-2F14-2F9-2F15-2F7-2F16-2F6-3F17-9F316-7G19-2G5-2G17-2G7-2G16-2G7-2G15-2G9-2G14-G10-2G13-2G11-2G13-2G9-2G14-2G9-2G15-2G7-2G16-2G6-3G17-9G19-7G318-5E21-7E19-2E5-2E17-2E6-3E16-2E7-2E15-2(2E9-2E14-)2E8-3E15-2E7-2E16-3E5-3E17-2E5-2E19-7E372-5A21-7A19-2A5-2A17-3A5-3A3(16-2A7-2A)16-3A5-3A17-2A4-3A19-7A21-5A400-5B21-7B19-3B3-3B18-2B5-2B17-3B5-3B17-2B5-2B18-3B3-3B19-7B21-5B454-5C21-7C20-2C3-2C19-3C3-3C19-2C3-2C20-7C21-5C508-5D22-5D21-3D-3D21-5D22-5D563-2(3F24-)3F619-G418-
