model
size = 32 4 32, scale = 0.05, origin = -y
material 
  colors = A:#800 B:#FF3 C:#111 D:#00B E:#EEE F:#06F G:#00A H:#FF9 I:#DDD J:#069 K:#500 L:#A00 M:#D00 N:#039 O:#FC0 P:#AAA Q:#09F R:#B00 S:#FF0
voxels
HO29BH16(-B)2-7(B3-)B2-32BH2B11AK12A2BH2B62-2B30-3BH5AK6AM13AH2(2B31-)B30-3BAH24AHAO2B63-B30-2B23AL6AB24-3B4-B32-B30-2B13ALAM14A2B10-8C6-B37-2B30-2B30AB11-C2IC3FNC5-B5-2B31-B30-2B3AMK5AR2AK16A2B9-C2EC2FN3FC4-B38-B30-BH26AL3AB10-C2IC2F2C2FC3-2B5-B32-B30-2B30A2B8-C2EC2FC2GCNFC3-B37-2B30-2B30AB8-CEI2C2FC2GC3FC8-2B31-B30-2B21AK8AHB6-CI2EC2F2CG2DC2FC41-B30-2B30AH7-C2EC3FC-CD2GCNFC7-B32-B30-2B14AL13ALA2B5-C3EC2FC3-2C2DCFNC38-2B30-2B13AK16AB6-C2ECJFC5-CGDCJFJC5-2B31-B30-2B6AK23A2B4-C2EC3FC5-2CDGCFJC38-B30-2B30AB5-C2ECQJC8-C2DCJNC4-B32-B30-2B6ALM22A2B3-C2ECFJC10-C2DCFJC35-2B30-BH8AM21AB4-C2ECJQC10-C3DCNJC2-2B31-B30-2B11AL3AK14A2B2-C2ECQJC12-C3DCJFC34-B30-2B30AB2-2C2E18C3DCJC-B32-B30-2B30A2B-C8EI6E2(2IP)C3D2C33-2B30-2B4AR8AK11AK4AB2-C2E2I9E2I2EIP2IPC3DC-2B31-B30-2B30A2B-24C2D2C34-B30-BO30AB3-C5G2D3G2DG11DC2-B32-B30-2B22AL3AM3AHB2-2C3GD2G2(DG)4DG7DC35-2B30-2B12AL17AB4-24C3-2B31-B30-BS24AK5AOB63-B30-3BAH10AM13AHA2B31-B32-B30-3BH12AK13AH3B62-2B30-2BH2B24A2BHB31-2B31-B30-BH30BH15(B-)B2-7(B3-)B2-32B
