model
size = 20 3 30, scale = 0.05, origin = -y
material 
  colors = A:#996 B:#03C C:#EEE D:#6FF E:#C69 F:#303 G:#E00 H:#FC6 I:#3F3 J:#111 K:#C09 L:#FF0 M:#6F6
voxels
-------------------- ---EE--------------- -------------------- 
-------------------- ---EEE--------C----- -------------------- 
-------------------- ---EEE--------C----- ----E--------------- 
-------------------- ----EE-------CC----- ----EE-------------- 
------E------C------ ----EE------CCC----- ----EE--------C----- 
------E------CC----- ----EE------CCC----- ----E-------CC------ 
------------CC------ ----EEE-----CC------ -----------CCC------ 
------E-----C------- ------E-----C------- -----------C-------- 
------EE----C------- ------E-----C------- -----------C-------- 
------EA----C------- -------A----C------- --------A--C-------- 
------EAAAAAC------- ------EAAAAAC------- --------AAAA-------- 
-----AAAADDDDDD----- -----AAAADDDDDD----- -----AAAADDDDDD----- 
----KAA------DDD---- ----KAA------DDD---- ----KAA------DDD---- 
---KK----------DD--- ---KK----------DD--- ---KK----------DD--- 
--KK------------JJ-- --KK------------JJ-- --KK------------JJ-- 
-KK--------------JJ- -KK--------------JJ- -KK--------------JJ- 
-HH--------------JJ- -HH--------------JJ- -HH--------------JJ- 
HH----------------JJ -H----------------JJ -H----------------J- 
HH----------------LM HH----------------LM HH----------------MM 
HH----------------LM HH----------------LM HH----------------MM 
HH----------------LM HH----------------LM HH----------------MM 
II----------------GG II----------------GG II----------------GG 
II----------------GG II----------------GG -I----------------G- 
-II--------------GG- -II--------------GG- -II--------------GG- 
-II--------------GG- -II--------------GG- -II--------------GG- 
--IF------------GG-- --IF------------GG-- --IF------------GG-- 
---FF----------LL--- ---FF----------LL--- ---FF----------LL--- 
----FFF------BLL---- ----FFF------BLL---- ----FFF------BLL---- 
-----FFFBBBBBBL----- -----FFFBBBBBBL----- -----FFFBBBBBBL----- 
-------FBBBBB------- -------FBBBBB------- --------BBBB-------- 
