model
size = 23 31 17, scale = 0.05, origin = -y
material 
  colors = A:#FC0000 B:#2500DF C:#DF0082 D:#54FC00 E:#005049 F:#00DFCD G:#FCD200 H:#00897E I:#8200DF J:#00DF70 K:#FC6900 L:#006C63 M:#EFEFEF
voxels
----------------------- ----------------------- ----------------------- ----------------------- ----------------------- ----------------------- ----------------------- ----------------------- ----------------------- ----------AAA---------- ----------AFA---------- ----------AFA---------- ----------AFA---------- ----------AAA---------- ----------------------- ----------------------- ----------------------- ----------------------- ----------------------- ----------------------- ----------------------- ----------------------- ----------------------- ----------------------- ----------------------- ----------------------- ----------------------- ----------------------- ----------------------- ----------------------- ----------------------- 
----------------------- ----------------------- ----------------------- ----------------------- ----------------------- ----------------------- ----------------------- ----------------------- ----------------------- ----------------------- --------AA---AA-------- --------FA---AF-------- --------AA---AA-------- ----------III---------- -------II-III-II------- -------FIFFFFFIF------- -------IIIIFIIII------- -------IIFIIIFII------- --------I-----I-------- ----------------------- ----------------------- ----------------------- ----------------------- ----------------------- ----------------------- ----------------------- ----------------------- ----------------------- ----------------------- ----------------------- ----------------------- 
----------------------- ----------------------- ----------------------- ----------------------- ----------------------- ----------------------- ----------------------- ----------------------- ----------------------- ----------------------- -------A-------A------- ----------------------- -------A-------A------- ----------GGG---------- ----------GGG---------- ------I---GGG---I------ -----II---GGG---II----- ------F--GGGGG--F------ ---------GEGEG--------- -------F-GEGEG-F------- ---------GEGEG--------- --------GGEGEGG-------- --------GEEGEEG-------- --------GEEGEEG-------- --------EEEGEEE-------- --------EEEGEEE-------- --------EEEGEEE-------- --------AAAGAAA-------- --------AAAGAAA-------- --------GLGGGLG-------- ---------MGGGM--------- 
----------------------- ----------------------- ----------------------- ----------------------- ----------------------- ----------------------- ----------------------- ----------------------- ----------------------- ----------------------- ------A---------A------ ------F---------F------ ------A---------A------ --------ED---DE-------- --------ED---DE-------- --------ED---DE-------- --------DD---DD-------- --------DD---DD-------- --------DD---DD-------- ------I-DD---DD-I------ --------DD---DD-------- --------DD---DD-------- --------DD---DD-------- --------DD---DD-------- --------DD---DD-------- --------DD---DD-------- --------DD---DD-------- --------DD---DD-------- ----------------------- ----------------------- ----------------------- 
-----F-----------F----- -----F-----------F----- ----------------------- ----------------------- ----------------------- ----------------------- -----F-----------F----- -----F-----------F----- ----------------------- ----------------------- ------A---------A------ ------A---------A------ ------A---------A------ -------D-------D------- -------E-------E------- -------E-------E------- -------E-------E------- -------D-------D------- -----F-E-------E-F----- -------E-------E------- -------E-------E------- -------E-------E------- -------D-------D------- -------D-------D------- -------A-------A------- -------A-------A------- -------D-------D------- -------D-------D------- ----------------------- ----------------------- ----------------------- 
----------------------- -----A-----------A----- -----A-----------A----- -----A-----------A----- -----A-----------A----- -----A-----------A----- -----A-----------A----- -----A-----------A----- -----A-----------A----- -----A-----------A----- -----A-----------A----- -----A-----------A----- -----A-----------A----- -----A--C-----C--A----- --------C-----C-------- --------C-----C-------- --------C-----C-------- ------D-C-----C-D------ ------D-C-----C-D------ ------D-C-----C-D------ ------E-C-----C-E------ ------E-C-----C-E------ ------E-C-----C-E------ ------E---------E------ ------A---------A------ ------A---------A------ ------L---------L------ ------M---------M------ ----------------------- ----------------------- ----------------------- 
----------------------- -----F-----------F----- ----------------------- -----A-----------A----- -----F-----------F----- ----------------------- -----F-----------F----- -----A-----------A----- -----A-----------A----- -----F-----------F----- -----F-----------F----- -----F-----------F----- -----F-----------F----- -----A-C-------C-A----- -------C-------C------- -------C-------C------- -------C-------C------- -------C-------C------- -------C-------C------- -------C-------C------- -------C-------C------- -----D-C-------C-D----- -----E-C-------C-E----- -----E-----------E----- -----A-----------A----- -----A-----------A----- -----D-----------D----- ----------------------- ----------------------- ----------------------- ----------------------- 
----------------------- ----------------------- -----F-----------F----- -----A-----------A----- -----A-----------A----- -----A-----------A----- -----A-----------A----- -----A-----------A----- -----A-----------A----- -----A-----------A----- -----A-----------A----- -----A-----------A----- -----A-----------A----- -----AC---------CA----- ------C---------C------ ------C---------C------ ------C---------C------ ------C---------C------ ------C---------C------ ------C---------C------ ------C---------C------ ------C---------C------ ------C---------C------ ----------------------- ----------------------- ----------------------- ----------------------- ----------------------- ----------------------- ----------------------- ----------------------- 
----------------------- ----------------------- ----------------------- ----------------------- -----F-----------F----- -----F-----------F----- ----------------------- ----------------------- ----------------------- ----------------------- ------A---------A------ ------A---------A------ ------A---------A------ -------B-------B------- -------B-------B------- -------B-------B------- -------B-------B------- -------B-------B------- ----------------------- -----K-----------K----- -----C-----------C----- -----C-----------C----- -----K-----------K----- ----------------------- ----------------------- ----------------------- ----------------------- ----------------------- ----------------------- ----------------------- ----------------------- 
----------------------- ----------------------- ----------------------- ----------------------- ----------------------- ----------------------- ----------------------- ----------------------- ----------------------- ----------------------- ------A---------A------ ------F---------F------ ------A---------A------ -------B-------B------- -------B-------B------- -------B-------B------- -------B-------B------- -------B-------B------- ----K--B-------B--K---- ----C-------------C---- ----K-------------K---- ----K-------------K---- ----C-------------C---- ----K-------------K---- ----------------------- ----------------------- ----------------------- ----------------------- ----------------------- ----------------------- ----------------------- 
----------------------- ----------------------- ----------------------- ----------------------- ----------------------- ----------------------- ----------------------- ----------------------- ----------------------- ----------------------- -------A-------A------- ----------------------- -------A-------A------- --------J-----J-------- ------B---------B------ ---K--B--J---J--B--K--- ------B--J---J--B------ ---K--B--B---B--B--K--- ------B--J---J--B------ ---C--B--J---J--B--C--- ---C---------------C--- ---C---------------C--- ---C---------------C--- ----------------------- ---K---------------K--- ----------------------- ---K---------------K--- ----------------------- ----------------------- ----------------------- ----------------------- 
----------------------- ----------------------- ----------------------- ----------------------- ----------------------- ----------------------- ----------------------- ----------------------- ----------------------- ----------------------- --------AA---AA-------- --------FA---AF-------- --------AA---AA-------- ----------JJJ---------- -----B----JBJ----B----- -----B----JBJ----B----- --K--B----JBJ----B--K-- -----B----JJJ----B----- -----B-----B-----B----- --K--B-----------B--K-- --K-----J-----J-----K-- --K-----------------K-- --K-----------------K-- ----------------------- ----------------------- --K-----------------K-- ----------------------- ----------------------- ----------------------- ----------------------- ----------------------- 
----------------------- ----------------------- ----B-------------B---- ----B-------------B---- ----B-------------B---- ----B-------------B---- ----B-------------B---- ----B-------------B---- ----B-------------B---- ----B-----AAA-----B---- ----B-----AFA-----B---- ----B-----AFA-----B---- ----B-----AFA-----B---- ----B-----AAA-----B---- ----B-------------B---- ----B-------------B---- ----B-------------B---- ----B--J-------J--B---- ----B-------------B---- -----------J----------- -------J-------J------- ----------------------- ----------------------- ----------------------- ----------------------- ----------------------- ----------------------- ----------------------- ----------------------- ----------------------- ----------------------- 
----------------------- ---B---------------B--- ---B---------------B--- ---H---------------H--- ---H---------------H--- ---H---------------H--- ---H---------------H--- ---H---------------H--- ---H---------------H--- ---H---------------H--- ---H---------------H--- ---H---------------H--- ---H---------------H--- ---H---------------H--- ---H---------------H--- ---H---------------H--- ---H---------------H--- ---B---------------B--- ---B--J---------J--B--- ------J---------J------ -----------J----------- ----------------------- ----------------------- ----------------------- ----------------------- ----------------------- ----------------------- ----------------------- ----------------------- ----------------------- ----------------------- 
----------------------- --B-----------------B-- --B-----------------B-- --B-----------------B-- --B-----------------B-- --B-----------------B-- --B-----------------B-- --B-----------------B-- --B-----------------B-- --B-----------------B-- --B-----------------B-- --B-----------------B-- --B-----------------B-- --B-----------------B-- --B-----------------B-- --B-----------------B-- --B-----------------B-- --B--------J--------B-- ----------------------- -----------J----------- ----------------------- ----------------------- ----------------------- ----------------------- ----------------------- ----------------------- ----------------------- ----------------------- ----------------------- ----------------------- ----------------------- 
----------------------- -H-------------------H- ----------------------- -B-------------------B- ----------------------- -H-------------------H- ----------------------- -B-------------------B- ----------------------- ----------------------- ----------------------- ----------------------- -H-------------------H- ----------------------- -B-------------------B- ----------------------- -H-------------------H- ----------------------- -----------J----------- ----------------------- ----------------------- ----------------------- ----------------------- ----------------------- ----------------------- ----------------------- ----------------------- ----------------------- ----------------------- ----------------------- ----------------------- 
----------------------- B---------------------B ----------------------- H---------------------H ----------------------- B---------------------B ----------------------- H--------------------BH ----------------------- ----------------------- ----------------------- ----------------------- B---------------------B ----------------------- H---------------------H ----------------------- B---------------------B ----------------------- ----------------------- ----------------------- ----------------------- ----------------------- ----------------------- ----------------------- ----------------------- ----------------------- ----------------------- ----------------------- ----------------------- ----------------------- ----------------------- 
