model
size = 31 5 31, scale = 0.05, origin = -y
material 
  colors = A:#630 B:#FF3 C:#200 D:#500 E:#FC3 F:#600 G:#960 H:#888 I:#555 J:#FF0 K:#AAA L:#777 M:#444 N:#700 O:#963
voxels
------------------------------- ------------------------------- --------------BJB-------------- ------------------------------- ------------------------------- 
------------------------------- ------------------------------- ------------EBBKEBB------------ ------------------------------- ------------------------------- 
------------------------------- ------------------------------- ---------BBBHDDDDDHEBB--------- ------------------------------- ------------------------------- 
------------------------------- ------------------------------- -------EEHCCCCCCCCCCCKEB------- ------------------------------- ------------------------------- 
------------------------------- ------------------------------- ------BAAAGAAAAAAAAAAGAAB------ ------------------------------- ------------------------------- 
------------------------------- ------------------------------- -----EBAAAAGAAAAAAAAGAGAEB----- ------------------------------- ------------------------------- 
------------------------------- ------------------------------- ----BBKEAAAAAAGAAAAAAAABMEE---- ------------------------------- ------------------------------- 
------------------------------- ------------------------------- ---BBCBEECCCCCCCCCCCCCBEECCE--- ------------------------------- ------------------------------- 
------------------------------- ------------------------------- ---BDDDJIBDDDDODDDDDDEHBDDDB--- ------------------------------- ------------------------------- 
------------------------------- ------------------------------- --EIDDDDJEBDDDDAADDDBBBDDDDME-- ------------------------------- ------------------------------- 
------------------------------- ------------------------------- --JDDDDDDBHBDDDDDDDBIBDDDADDB-- ------------------------------- ------------------------------- 
------------------------------- ------------------------------- --ECCCCCCCBBBCCCCCEBBCCCCCCCB-- ------------------------------- ------------------------------- 
------------------------------- ------------------------------- -BMFAAAANAABHBAAABHBAAGAAAAAKB- ------------------------------- ------------------------------- 
------------------------------- ------------------------------- -BAAAGAAAAAAEJJ-BEBAAAAAAAAAAE- ---------------B--------------- ------------------------------- 
------------------------------- ------------------------------- BBAAGAGAAAAAAB---BAFAAAAAAAAAEE --------------B-B-------------- ---------------B--------------- 
----------FFFAAAAAFFF---------- --FFFFFFFFFFF-----FFFFFFFFFFF-- JKCCCCCCCCCCB-----BCCCCCCCCCCLB -------------B---B------------- --------------BBB-------------- 
------------------------------- ------------------------------- JBANAAAAAAAAAE---BAAAAAAAAAAGEB --------------B-B-------------- ---------------B--------------- 
------------------------------- ------------------------------- -EAAAAAAAAAAEBB-BBBAAAAGAAAAGB- ---------------B--------------- ------------------------------- 
------------------------------- ------------------------------- -BLAGAFAAAABIBAAAEMEAAAAAAGAHB- ------------------------------- ------------------------------- 
------------------------------- ------------------------------- --BCCCCCCCBBECCCCCBBBCCCCCCCB-- ------------------------------- ------------------------------- 
------------------------------- ------------------------------- --BDDDDDDELBDDDDDDDBKBDDDDDAB-- ------------------------------- ------------------------------- 
------------------------------- ------------------------------- --BIDDADBBBDDDADDDDDEBBDDADMB-- ------------------------------- ------------------------------- 
------------------------------- ------------------------------- ---BDDDBLEDDDDDDAADDDBIBDDDB--- ------------------------------- ------------------------------- 
------------------------------- ------------------------------- ---BCCBEECCCCCCCCCCCCCBBBCCB--- ------------------------------- ------------------------------- 
------------------------------- ------------------------------- ----BEKBAANAAAAAFAAAAAABLEB---- ------------------------------- ------------------------------- 
------------------------------- ------------------------------- -----BEANAAAAAAAAGAAAGAABE----- ------------------------------- ------------------------------- 
------------------------------- ------------------------------- ------ECCCCCCCCCCCCCCCCCB------ ------------------------------- ------------------------------- 
------------------------------- ------------------------------- -------BBIDDDDDDDDDDDIBE------- ------------------------------- ------------------------------- 
------------------------------- ------------------------------- ---------BBBBDDDDDLBBE--------- ------------------------------- ------------------------------- 
------------------------------- ------------------------------- ------------BEBLEBE------------ ------------------------------- ------------------------------- 
------------------------------- ------------------------------- --------------EBB-------------- ------------------------------- ------------------------------- 
