model
size = 32 14 28, scale = 0.05, origin = -y
material 
  colors = A:#004198 B:#562B00 C:#482701 D:#508AC1 E:#0B366F F:#282828
voxels
361-A3-F4-F3-A18-A3-F4-F3-A370-A3-6F3-A17-CBC3B4C4B-B16-2(3BC)BC2B2C2B17-A3-6F3-A14-12(6A10-)7A8-7A10-9A4-9A10-2E18A2E12-E16AE15-E14AE13-C2B16A2BC10-CBC16A3B13-16A12-12(8A8-)AD9A2-9ADA8-A2D18A2DA8-E3D16A3DE9-3D16A3D10-3D16A3D9-C22AB8-C22AB9-22A8-5A4-A6-A4-5A6-5A3-2A6-2A3-3(5A6-5A4-A6-A4-)5A6-5A2(4-2A)4-5A6-AD2(4A5-)4ADA6-AD4A14-4ADA6-ED4A14-4ADE7-D4A14-4AD8-D4A14-4AD7-B5A14-5AB6-C5A14-5AC7-5A14-5A7-A9-A4-A9-A6-A8-2A4-2A8-A6-A9-A4-A9-A6-2A8-A4-A8-2A6-2A8-2A2-2A8-2A6-3A8-4A8-3A5-3(AD3A18-3ADA4-)ED3A18-3ADE5-D3A18-3AD5-C4A18-4AB4-C4A18-4AB5-4A18-4A6-A9-A4-A9-A6-A8-3A2-3A8-A6-A10-A2-A10-A5-2A10-4A10-2A4-2(2A11-)2A4-ADA22-3A4(4-4A20-4A)4-E3A20-3AE3-B4A20-4AB2-B4A20-4AB3-4A20-4A4-2A10-A2-A10-2A4-2A9-6A9-2A4-2(2A11-)3(2A4-2A24-)2A4(4-3A22-3A)3-4A22-4A-AB3A22-3AB2AB3A22-3ABA-4A22-4A3-2A10-A2-A10-2A4-2A9-6A9-4(2A4-2A24-)2A5(4-3A22-3A)3-B3A22-3AB2-B3A22-3AC3-3A22-3A4-2(2A11-)2A4-2A10-4A10-9(2A4-2A24-)2A3-B2A24-2AB2-C2A24-2AB3-2A24-2A4-2(2A11-)2A4-2A10-4A10-9(2A4-2A24-)2A3-C2A24-2AC2-C2A24-2AC3-2A24-2A4-2(2A11-)2A4-2A10-4A10-9(2A4-2A24-)2A3-C2A24-2AB2-B2A24-2AC3-2A24-2A4-2(2A11-)2A4-2A10-4A10-9(2A4-2A24-)2A3-C2A24-2AC2-C2A24-2AC3-2A24-2A4-2(2A11-)2A4-2A10-4A10-9(2A4-2A24-)2A3-B2A24-2AC2-C2A24-2AB3-2A24-2A4-2(2A11-)2A4-2A10-4A10-9(2A4-2A24-)2A3-C2A24-2AC2-B2A24-2AB3-2A24-2A4-2(2A11-)2A4-2A10-4A10-9(2A4-2A24-)2A3-B2A24-2AB2-C2A24-2AC3-2A24-2A4-2(2A11-)2A4-2A10-4A10-9(2A4-2A24-)2A3-C2A24-2AB2-C2A24-2AC3-2A24-2A4-2(2A11-)2A4-2A10-4A10-9(2A4-2A24-)2A3-B2A24-2AB2-B2A24-2AB3-2A24-2A5-A11-2A11-A6-A10-4A10-3(A6-A24-)A5-5(2A24-2A4-)2A24-2A3-B2A24-2AC2-B2A24-2AB3-2A24-2A6-A10-2A10-A8-A9-4A9-A8-A10-2A10-A7-2(A24-A6-)A24-A5-3(2A24-2A4-)2A24-2A3-3A24-3A-AB2A24-2(2AB)2A24-2ABA-3A24-3A6-A8-4A8-A10-E7-6A7-A10-E8-4A8-A9-AE21-A7-3(2A22-2A6-)2A22-2A5-2(3A22-3A4-)3A22-3A3-C3A22-3AB2-B3A22-3AB3-3A22-3A8-3A4-6A4-3A12-3E3-8A3-3A12-3A4-6A4-3A11-E20-A9-AE20-2A8-AE20-2A7-2AE20-3A6-2AD3(20-3A6-3A)20-3A5-C3A20-3AC4-C3A20-3AB5-3A20-3A12-15A17-5E10A17-4AE10A2(14-3A)11-EA18-2A10-EA18-2A9-3A18-3A8-2AD3(18-3A8-3A)18-3A7-B3A18-3AB6-B3A18-3AC7-3A18-3A108-5AE10A14-2A16-2A12-2A16-2A11-E2A16-3A10-A-D3(16-3A10-3A)16-3A9-C3A16-3AB8-C3A16-3AB9-3A16-3A141-5AE10A16-5AE10A14-2E5AE12A14-6D12A3(12-20A)11-C20AC10-B20AB11-20A206-6E10A22-10A3(16-16A)14-2C16ABC12-BC16A2B14-16A337-A12-A17-3BC2B2CB2C2BC2B16-5BCBC2B3C2BC17-A12-A370-A12-A18-A12-A41-
