model
size = 22 17 23, scale = 0.05, origin = -y
material 
  colors = A:#002 B:#F0C C:#DC00B3 D:#F93 E:#004 F:#009 G:#007 H:#EEE I:#FFB648 J:#F60 K:#00B L:#E00
voxels
---------AAAAA-------- ---------------------- ---------------------- ---------------------- ---------------------- ---------------------- ---------------------- ---------------------- ---------------------- ---------------------- ---------------------- ---------------------- ---------------------- ---------------------- ---------------------- ---------------------- ---------------------- 
-------AAAAAAAAAA----- ---------------------- ---------------------- ---------------------- ---------------------- ---------------------- ---------------------- ---------------------- ---------------------- ---------------------- ---------------------- ---------------------- ---------------------- ---------------------- ---------------------- ---------------------- ---------------------- 
-----AAAAAAAAAAAAA---- ---------------------- ---------------------- ---------------------- ---------------------- ---------------------- ---------------------- ---------------------- ---------------------- ---------------------- ---------------------- ---------------------- ---------------------- ---------------------- ---------------------- ---------------------- ---------------------- 
----AAAAAAAAAAAAAAA--- ---------DDDD--------- ---------DDDD--------- ---------AAAA--------- ---------AAAA--------- ---------AAAA--------- ---------AAAA--------- ---------AAAA--------- ---------AAAA--------- ---------AAAA--------- ---------AAAA--------- ---------AAAA--------- ---------AAAA--------- ---------AAAA--------- ---------AAAA--------- ---------AAAA--------- ---------AAAA--------- 
---AAAAAAAAAAAAAAAAG-- -------DDAAAADDD------ -------DDAAAADDD------ -------AAAAAAAAA------ -------AAAAAAAAA------ -------AAAAAAAAA------ -------AAAAAAAAA------ -------AAAAAAAAA------ -------AAAAAAAAA------ -------AAAAAAAAA------ -------AAAAAAAAA------ -------AAAAAAAAA------ -------AAAAAAAAA------ -------AAAAAAAAA------ -------AAAAAAAAA------ -------AAAAAAAAA------ -------AAAAAAAAE------ 
--AAAAACCCCCCCCAAAAAK- ------DCCCCCCCCAI----- ------DAAAAAAAAAI----- ------AAAAAAAAAAG----- ------AAAAAAAAAAG----- ------AAAAAAAAAAG----- ------AAAAAAAAAAG----- ------AAAAAAAAAAG----- ------AAAAAAAAAAG----- ------AAAAAAAAAAG----- ------AAAAAAAAAAG----- ------AAAAAAAAAAG----- ------AAAAAAAAAAG----- ------AAAAAAAAAAG----- ------AAAAAAAAAAG----- ------AAAAAAAAAAG----- ------AAAAAAAAAAG----- 
--AAAABC-------CAAAAK- -----DAC------CAAI---- -----DABBCCCCCAAAI---- -----AABBCCCCCAAAF---- -----AABBCCCCCAAAF---- -----ACCBCCCCCAAAF---- -----AAAA----CAAAF---- -----AAAAAAAAAAAAF---- -----AAAAAAAAAAAAF---- -----AAAAAAAAAAAAF---- -----AAAAAAAAAAAAF---- -----AAAAAAAAAAAAF---- -----AAAAAAAAAAAAF---- -----AAAAAAAAAAAAF---- -----AAAAAAAAAAAAF---- -----AAAAAAAAAAAAF---- -----AAAAAAAAAAAAF---- 
-AAAAB---------BCAAAAA ----DAC-------CBCD---- ----DAAB------BBAD---- ----AAAB------BAAA---- ----AAAC------BAAA---- ----AAC-BCCCC-BAAA---- ----AAACCCCCCCAAAA---- ----AAABBBBBAAAAAA---- ----AAAAAAAAAAAAAA---- ----AAAAAAAAAAAAAA---- ----AAAAAAAAAAAAAA---- ----AAAAAAAAAAAAAA---- ----AAAAAAAAAAAAAA---- ----AAAAAAAAAAAAAA---- ----AAAAAAAAAAAAAA---- ----AAAAAAAAAAAAAA---- ----AAAAAAAAAAAAAF---- 
-AAAAB----------CAAAAA ----DAC---------CAD--- ----DAB--------BAAD--- ----AAB-------BBAAA--- ----AAB-------B-AAA--- ----AAB-------BAAAA--- ----AA-C-----CAAAAA--- ----AAABBBBBBAAAAAA--- ----AAAAAAAAAAAAAAA--- ----AAAAAAAAAAAAAAA--- ----AAAAAAAAAAAAAAA--- ----AAAAAAAAAAAAAAA--- ----AAAAAAAAAAAAAAA--- ----AAAAAAAAAAAAAAA--- ----AAAAAAAAAAAAAAA--- ----AAAAAAAAAAAAAAA--- ----AAAAAAAAAAAAAAE--- 
AAAAB-----------CCAAAA ---DABB---------CAD--- ---DABB--------BAAD--- ---AABB--------BAAA--- ---AAAB--------BAAA--- ---AAAB--------BAAA--- ---AABB-------BAAAA--- ---AAABBBBBBBBBAAAA--- ---AAAAAAAAAAAAAAAA--- ---AAAAAAAAAAAAAAAH--- ---AAAAAAAAAAAAAAAH--- ---AAAAAAAAAAAAAAAA--- ---AAAAAAAAAAAAAAAA--- ---AAAAAAAAAAAAAAAA--- ---AAAAAAAAAAAAAAAA--- ---AAAAAAAAAAAAAAAA--- ---AAAAAAAAAAAAAAAA--- 
AAAAB-----------BCAAAA ---DAB----------BAD--- ---DAB----------BAD--- ---AAB----------BAA--- ---AAB---------CBAA--- ---AAB---------CAAA--- ---AABB--------BAAA--- ---AAABBBBBBBBCCAAH--- ---AAAAAAAAAAAAAAAL--- ---AAAAAAAAAAAAAAAH--- ---AAAAAAAAAAAAAAAH--- ---AAAAAAAAAAAAAAAA--- ---AAAAAAAAAAAAAAAA--- ---AAAAAAAAAAAAAAAA--- ---AAAAAAAAAAAAAAAA--- ---AAAAAAAAAAAAAAAA--- ---AAAAAAAAAAAAAAAA--- 
AAAAB-----------BCAAAA ---DAB----------BAD--- ---DAB----------BAD--- ---AAB----------BAA--- ---AAB---------CBAA--- ---AAB---------CAAA--- ---AABB---------AAH--- ---AAABBBBBBBBCCAAH--- ---AAAAAAAAAAAAAAAH--- ---AAAAAAAAAAAAAAAH--- ---AAAAAAAAAAAAAAAA--- ---AAAAAAAAAAAAAAAA--- ---AAAAAAAAAAAAAAAA--- ---AAAAAAAAAAAAAAAA--- ---AAAAAAAAAAAAAAAA--- ---AAAAAAAAAAAAAAAA--- ---AAAAAAAAAAAAAAAG--- 
AAAAB-----------BCAAAA ---DAB----------BAD--- ---DAB----------BAD--- ---AAB----------BAA--- ---AAB---------CBAA--- ---AAB---------CAAA--- ---AABB---------AAA--- ---AAABBBBBBBBCCAAH--- ---AAAAAAAAAAAAAAAL--- ---AAAAAAAAAAAAAAAH--- ---AAAAAAAAAAAAAAAH--- ---AAAAAAAAAAAAAAAA--- ---AAAAAAAAAAAAAAAA--- ---AAAAAAAAAAAAAAAA--- ---AAAAAAAAAAAAAAAA--- ---AAAAAAAAAAAAAAAA--- ---AAAAAAAAAAAAAAAF--- 
AAAACC----------BCAAAA ----DB----------BAD--- ----DB----------BAD--- ----AB----------BAA--- ----AB---------CBAA--- ----AB---------CAAA--- ----ABB---------AAA--- ----AABBBBBBBBCCAAA--- ----AAAAAAAAAAAAAAA--- ----AAAAAAAAAAAAAAH--- ----AAAAAAAAAAAAAAH--- ----AAAAAAAAAAAAAAA--- ----AAAAAAAAAAAAAAA--- ----AAAAAAAAAAAAAAA--- ----AAAAAAAAAAAAAAA--- ----AAAAAAAAAAAAAAA--- ----AAAAAAAAAAAAAGF--- 
-AAAAC----------CCAAAA ----DC----------BAD--- ----DC----------BAD--- ----AC----------BAA--- ----AC---------CBAA--- ----AAB--------CAAA--- ----AAB--------CAAA--- ----AAABBBBBBBCCAAA--- ----AAAAAAAAAAAAAAA--- ----AAAAAAAAAAAAAAA--- ----AAAAAAAAAAAAAAA--- ----AAAAAAAAAAAAAAA--- ----AAAAAAAAAAAAAAA--- ----AAAAAAAAAAAAAAA--- ----AAAAAAAAAAAAAAA--- ----AAAAAAAAAAAAAAA--- ----AAAAAAAAAEEEEGF--- 
-AAAACB--------CEEEEEE ----IAC--------BAD---- ----IAC--------BAD---- ----FAC--------CAA---- ----FAC--------CAA---- ----FAC--------CAA---- ----FAAB------CCAA---- ----FAAABBBBBBCCAA---- ----FAAAAAAAAAAAAA---- ----FAAAAAAAAAAAAA---- ----FAAAAAAAAAAAAA---- ----FAAAAAAAAAAAAA---- ----FAAAAAAAAAAAAA---- ----FAAAAAAAAAAAAA---- ----FAAAAAAAAAAAAA---- ----FAAAAAAAAAAAAA---- ----FAAAAAAAAEEEEG---- 
-AAAAACB-------CEEEEEE -----IACCCCCCCCCJ----- -----IACBBBBBBBBJ----- -----FACBCCCCCCCA----- -----FACB-----CCA----- -----FAB-------CA----- -----FAAB------CA----- -----FAAABBBBBCCA----- -----FAAAAAAAAAAA----- -----FAAAAAAAAAAA----- -----FAAAAAAAAAAA----- -----FAAAAAAAAAAA----- -----FAAAAAAAAAAA----- -----FAAAAAAAAAAA----- -----FAAAAAAAAAAA----- -----FAAAAAAAAAAA----- -----FAAAAAAAEEEG----- 
--AAAAAACCCCCCCAEEEEE- ------DDC-----CJ------ ------DDABBBBBAJ------ ------AAABBBBBAA------ ------AAACCCCCCA------ ------AAACCCCCCA------ ------AAACCCCCCA------ ------AAAAAAAAAA------ ------AAAAAAAAAA------ ------AAAAAAAAAA------ ------AAAAAAAAAA------ ------AAAAAAAAAA------ ------AAAAAAAAAA------ ------AAAAAAAAAA------ ------AAAAAAAAAA------ ------AAAAAAAAAA------ ------EEEEEEEEEG------ 
---AAAAAAAAAAAAAEEEE-- --------DDDDDDD------- --------DDDDDDD------- --------AAAAAAA------- --------AAAAAAA------- --------AAAAAAA------- --------AAAAAAA------- --------AAAAAAA------- --------AAAAAAA------- --------AAAAAAA------- --------AAAAAAA------- --------AAAAAAA------- --------AAAAAAA------- --------AAAAAAA------- --------AAAAAAA------- --------AAAAAAA------- --------EEEEEEE------- 
----AAAAAAAAAAAAEEE--- ---------------------- ---------------------- ---------------------- ---------------------- ---------------------- ---------------------- ---------------------- ---------------------- ---------------------- ---------------------- ---------------------- ---------------------- ---------------------- ---------------------- ---------------------- ---------------------- 
-----AAAAAAAAAAAEE---- ---------------------- ---------------------- ---------------------- ---------------------- ---------------------- ---------------------- ---------------------- ---------------------- ---------------------- ---------------------- ---------------------- ---------------------- ---------------------- ---------------------- ---------------------- ---------------------- 
-------AAAAAAAAAE----- ---------------------- ---------------------- ---------------------- ---------------------- ---------------------- ---------------------- ---------------------- ---------------------- ---------------------- ---------------------- ---------------------- ---------------------- ---------------------- ---------------------- ---------------------- ---------------------- 
---------AAAAA-------- ---------------------- ---------------------- ---------------------- ---------------------- ---------------------- ---------------------- ---------------------- ---------------------- ---------------------- ---------------------- ---------------------- ---------------------- ---------------------- ---------------------- ---------------------- ---------------------- 
