model
size = 31 32 32, scale = 0.05, origin = -y
material 
  colors = A:#FC0 B:#FFF C:#111 D:#FF3 E:#F90 F:#444 G:#222 H:#F60 I:#FF6 J:#FC3 K:#AAA L:#777 M:#FF0 N:#888 O:#F63 P:#555 Q:#D00 R:#DDD S:#BBB T:#F93 U:#A00 V:#E00 W:#B00 X:#FF9 Y:#C30 Z:#F00 Aa:#800
voxels
424-2B28-B2CB26-BCVWCB25-BCWYCB25-2B2C2B26-4B28-2B30-B17-13B47-12B2(49-11B)49-12B48-10B406-3CG3C-2C21-I3AEA2-2B21-2A2DAJ-B2CB19-2I2DAHCBCQVCB18-ADIDAHCBCVQCBC17-A2D2ADC2B2C2BG17-3AEIAC5BC19-H2AEG5BC17-7C6BC16-13BC19-11BC15-14BC20-10BC15-14BC19-10BC15-13B2C20-9BC15-13B2C20-7B2C16-10B3C400-G2C6-G3C-C16-EIA6-2G2BG17-2AE6-GB2UBG16-I2A6-3BUBC16-E2A6-3B19-AEA6-B2E19-E2A6-AEA19-3A6-2A21-9A20-11B25-5B19-14B2(47-13B)47-12B48-10B402-C11-2G2C15-I11-BA17-E11-3BCA14-I11-A3BC13-2A11-A3C14-IA11-AEA16-A11-2A17-A11-2A18-5A4-3A20-2B8AO19-3AE7A25-3BA27-2A200-10B233-5(C30-)C11-2C14-FGC12-2A14-2A13-EA14-2BD12-2A14-2BJ12-EA14-AC13-EA14-2A13-IA14-AI13-2(2A14-)D3A9-3A16-4A7-3A17-6A2-6A18-12A20-9A24-5AD348-C30-G30-C29-ACI28-ACD28-ACA28-ACI28-OCD9-C18-C11-C18-J3(11-A18-C)11-E18-C11-A18-A11-E18-A12-4A11-3A13-D6A8-3A14-5A6-5A16-5A2-6AE18-12A19-10AE22-7A287-C30-C29-GA29-OA29-AC29-AG3(29-AC)8-C20-CG2(8-C20-CA)8-A20-CH8-A20-CE8-2(A20-C9-)A20-A10-3A15-2A11-4A13-2AD12-E2A12-3A14-3A10-3A15-AD2A7-4AD17-2A-A5-3A19-H3A2-5A22-4A2OA194-3(C30-)I30-H30-I30-G131-C22-C2(7-C22-E)7-M22-A7-A22-H7-A22-AT6-E22-C7-A22-C8-3A17-2A9-E3A14-3AH10-D2A14-3A12-EA13-3A13-2A12-4A14-DA11-3A17-A9-AD19-11A23-HAD2AI132-C30-I30-H30-D30-H2(30-J)30-C130-C23-C6-K23-X7-L22-A7-C22-A6-CA22-T6-2A22-H7-A22-AH6-E22-C7-3A19-AC8-3A17-2A9-E2A15-4A10-DA15-2AE11-DA14-3AE12-D2A12-2AD14-DA11-3A17-12A20-3A3D2AE131-C30-A30-I30-A30-J30-D30-I30-C129-C24-C5-K24-A5-FC23-E5-FC23-J5-FA23-A6-C23-T6-A23-H6-E23-2A6-3A19-AC7-3A18-2AC7-3A17-3AD8-EA17-3A10-DA16-2A12-DA14-2A2(14-A)16-14A18-O5AD3AJD129-C30-E30-H30-A30-D2(30-J)30-C128-C26-C3-F26-E3-K26-E3-L26-J3-P26-J2(3-FC25-A)4-C25-H5-3A21-AC5-3A20-AC6-M2A19-2AC7-3A18-2AE8-2A17-3A9-D3A15-2AI10-D2A14-2AE12-E16AE15-12AED20-2AO3AD132-2(C30-)D30-A30-E30-D30-C128-C26-C3-K26-D3-K26-E3-K26-D3-L26-J3-K26-D3-K26-J3-F26-D4-C3A21-AC5-M2A20-2AI5-3A19-2AC7-3A18-2AC7-D2A17-3AD8-DA17-3A10-DA16-2A12-D17A14-E11AE3A18-9A162-2(C30-)2(A30-)D30-C128-C26-G2(3-C26-E)2-BA26-AX-BA26-AJ-LA26-AJ-KA26-AJ2-K26-C3-F2A24-AD3-C2A21-2AC5-2A20-2AC6-3A19-2AG7-3A18-2AG8-DA17-3A9-H2A16-3A10-2D17AH13-D14AD17-AH9A24-EDJA164-C2(30-D)30-M30-G3C124-C28-C-L28-E-B28-E-L28-C-K28-G-R28-G-B28-C-K28-AT-K2A24-C3-FC2A21-2AC5-C2A19-2AG6-3A19-2AG7-3A18-3AAa6-M2A17-3AG8-2A18-AC10-19AC12-14AE3A16-11A23-AJEDAD163-2(C30-)2(A2-C27-)C2DS3(30-C)30-2C28-C-B28-C-G28-C-N28-C-P28-AIR28-G-P28-AIK28-C2-K2A24-F3-L3A21-2AG3-FC3A19-3AC5-C2A2(19-3AQ6-CA)18-3AGZ7-CA18-AC10-C18AL12-3C12A3C16-2C7A2CF21-7C197-C27-C2-S2(27-C2-K)2(30-N)30-P30-NC29-PL29-2N29-SN29-2P29-FL29-PB28-F-R28-G2-K2A24-K3-L2A22-2AG3-F4A20-2AQ4-L3A19-3AU4-2F2A19-3AV5-F2A18-4AQ6-F2A18-AFCW7-L19AF11-F15AFLF13-3F9A2FK19-CF6AF24-2FN2FK167-C27-C2-K2(27-C2-S)30-F30-S30-N30-PC29-NB29-FN29-PL29-FP29-NR29-NB28-F-R28-F2-N2A24-L3-L2A22-2AC3-L3A20-3AW4-F3A19-3AQ4-KC2A19-3AV5-F2A18-4AU6-F2A18-AFCQ7-F19AF11-F15ASFK13-3F9ARFS19-FR6AF24-RLF2NF133-2(C30-)H2-C27-A2-C26-CH2DS3(30-C)30-2C28-GC2(L28-C-)P28-G-K28-AIR28-C-K28-AIC28-C2-N2A24-S3-L2A22-2AG3-FC2A20-3AC5-C2A19-3AQ6-CA18-4AQ6-CA18-3AGQ7-CA18-AC10-C18AN12-3C12A3C16-2C7A2CF21-7C132-F30-C30-H30-D30-M30-4C124-C28-C-L28-D-N28-E-K28-C-P28-C-R28-C-K28-C-R28-CH-K2A24-C3-FCA22-2AC5-CA20-2AG6-H2A18-3AG7-3A17-4AW6-I2A17-3AG8-IA17-2AC10-19AC12-14ACADA16-11A23-2AE2AD132-F30-C30-J2(30-I)30-C128-C26-C2(3-K26-E)3-K26-2A3(2-K26-AJ)2-K26-C3-FCA23-ACH4-CJA20-AC6-3A19-2AC2(7-3A17-3AG)8-2A16-4A10-A17-AE12-I17A14-14ADA18-3A2DHD2A25-J2DJ102-2(C30-)2(D30-)J30-I30-C128-C26-C3-B26-D3-N26-X3-B26-J3-C26-J3-B26-J3-N26-A3-FC25-A5-J23-C6-E22-2AI5-3A19-2AC7-D2A16-4AC8-DA-A13-5A9-4A14-4A10-I2A14-3A12-17AE15-H11AEA20-A5DH101-C30-E30-D30-H30-J30-D30-J30-G129-C24-C2(5-B24-E)4-CA24-AJ3-BA24-2A2(3-FC24-AT)5-C23-H6-E22-2AC5-2A-A19-AC7-D2A17-3AC7-D2A15-6A8-3A14-4AD10-D2A13-4A12-2(2A14-)16A16-A2H8AD2A22-4A102-C3(30-I)2(30-J)30-D30-C129-C24-C5-N24-E5-B24-A5-B24-J5-F24-T6-C23-T6-M23-H6-M23-AH6-A21-AC7-4A18-AC7-D4A14-5A8-4A14-4A10-D2A13-4A12-DA12-3AI14-A12-3A16-14A18-3AD4AE2AD129-C30-E2(30-H)30-D30-I30-J30-C130-C23-G6-B23-A6-F23-E6-F23-T5-FC23-A6-C23-H6-J23-2A5-J23-C7-DA19-2AC8-4A16-2A9-5A13-4A10-4A12-3AH11-D3A11-5A12-4A9-5A14-E2A9-3AD17-12A20-E3A3D2A162-3(C30-)H30-D30-J30-C130-CG22-G6-KC22-E7-L22-X2(7-C22-H)7-A22-AH6-A22-C7-A22-C8-EA18-2A9-6A13-3A10-M5A9-4AE12-5A9-4A13-D5A7-4AI14-6A5-5A17-5A3-4A19-11A23-E2A2DA256-C30-A29-AI5(29-AC)8-G20-CG8-C20-2A8-C20-CD8-A20-CA8-H20-CH8-A20-C9-H20-C9-A20-A10-2A2-A13-2A11-6A10-3AE12-6A6-5AE14-D7A3-4AI15-16A17-12A19-E8AEA22-3AE3A287-C29-2C28-2OA28-AOD2(28-AOI)28-AOM28-AOI9-C18-C11-C18-A11-A18-2A10-A18-A11-A18-C11-H18-C11-A18-A11-H18-A2(12-3A)13-D5A7-3A2E14-5A-A-2A-5A16-D13A18-11AD19-9AEA22-5ADE347-6(C30-)C12-3G11-3CG13-3A11-3CAJA11-ADA11-2BGCA12-E2A11-2ABC13-2EA11-A2BC13-A2E11-4A13-3A11-3AD13-3A11-4A14-2D3A6-5A16-11AE2A17-14A18-3A5D3AD20-A2D6A24-3AH2A27-C552-FCG6-2C2G18-O2A6-2C3GJ16-E2A6-3BC18-AIA6-B2CBC17-3A6-CA3B17-E2A6-CAB-C17-AIA6-3A19-3A6-2A21-9A-B21-3AH3A-BC23-3AHB-B30-B227-10B405-C5GL3G22-5A2G2BG21-D3AHC4B20-2AD3A2B2C2B19-5ACBCVYCB19-5ACBCQUCBC18-2(AI)AC2B2C2BC19-AI4A4BC17-8C5BC16-13B2C22-7BC15-6B2-B-4B2C19-4B-5BC15-14BC29-C15-14BC27-B2C15-13B2C27-2C16-10B3C403-2C2(FC)25-MO3M26-M2JMA26-JM2JC26-2MOJ28-3M63-C2-2B26-5B17-13B21-10B16-15B20-10B16-14B20-10B16-12B23-7B18-13B22-7B18-10B681-13B47-13B3(48-12B)48-10B21-
