model
size = 24 29 25, scale = 0.05, origin = -y
material 
  colors = A:#C0F B:#603 C:#EEE D:#001
voxels
------------------------ -----------B------------ -----------B------------ -----------B------------ ----------B------------- ------------------------ ------------------------ ------------------------ ------------------------ ------------------------ ------------------------ ------------------------ ------------------------ ------------------------ ------------------------ ------------------------ ------------------------ ------------------------ ------------------------ ------------------------ ------------------------ ------------------------ ------------------------ ------------------------ ------------------------ ------------------------ ------------------------ ------------------------ ------------------------ 
------------------------ ------------------------ ------------------------ ------------------------ ---------B-------------- ------------------------ ------------------------ ------------------------ ------------------------ ------------------------ ------------------------ ------------------------ ------------------------ ------------------------ ------------------------ ------------------------ ------------------------ ------------------------ ------------------------ --------AAAAAAA--------- --------AAAAAAA--------- ------------------------ ------------------------ ------------------------ ------------------------ ------------------------ ------------------------ ------------------------ ------------------------ 
------------------------ ------------------------ ------------------------ ------------------------ ------B----------------- ------B--B-------------- -----B---B-------------- ---------B-------------- ------------------------ -B---------------------- -B---------------------- ------------------------ ------------------------ ------------------------ ------------------------ ------------------------ ---------B-B-B---------- ---------B-B-B---------- --------AAAAAAA--------- ------AAAAAAAAAAA------- ------AAAAAAAAAAA------- --------AAAAAAA--------- --------AAAAAAA--------- ------------------------ ------------------------ ------------------------ ------------------------ ------------------------ ------------------------ 
------------------------ ------------------------ ------------------------ ------------------------ ------------------------ ------------------------ ----B------------------- ------------------------ -B-------B-------------- ------------------------ ------------------------ -BB--------------------- ---B-------------------- ---B-------------------- ------------------------ ------------------------ -------B-------B-------- -------BAAAAAAAB-------- ------AAAAAAAAAAA------- ----AAAAAAAAAAAAAAA----- ----AAAAAAAAAAAAAAA----- ------AAAAAAAAAAA------- ------AAAAAAAAAAA------- --------AAAAAAA--------- --------AAAAAAA--------- ------------------------ ------------------------ ------------------------ ------------------------ 
------------------------ ------------------------ ------------------------ ------------------------ -------------AA--------- -------------AA--------- -------------AA--------- ----B------------------- --BB-------------------- ---------B-------------- ---------B-------------- ------------------------ ------------------------ ------------------------ ---B-------------------- ------------------------ -----B-----------B------ -----BAAAAAAAAAAAB------ -----AAAAAAAAAAAAA------ ---AAAAAAAAAAAAAAAAA---- ---AAAAAAAAAAAAAAAAA---- -----AAAAAAAAAAAAA--CCC- -----AAAAAAAAAAAAA--CCC- ------AAAAAAAAAAA------- ------AAAAAAAAAAA------- ---------AAAAA---------- ------------------------ ------------------------ ------------------------ 
------------------------ ------------------------ ------------------------ ------------------------ -------------AA--------- -------------AA--------- -------------AA--------- -------------AA--------- ------------------------ ------------------------ ------------------------ ---------B-------------- ------------------------ ------------------------ ---B-------------------- ------------------------ ------------------------ -----AAAAAAAAAAAAA------ ----AAAAAAAAAAAAAAA----- --AAAAAAAAAAAAAAAAAAA--- --AAAAAAAAAAAAAAAAAAACC- ----AAAAAAAAAAAAAAA-CCC- ----AAAAAAAAAAAAAAA-CCC- -----AAAAAAAAAAAAA--CCC- -----AAAAAAAAAAAAA------ -------AAAAAAAAA-------- ---------AAAAA---------- ------------------------ ------------------------ 
------------------------ ------------------------ ------------------------ -----AA----------------- ----AAA-------------B--- ----AA--------------B--- --------------------B--- -------------AA----B---- -------------AA--------- ------------------------ ------------------------ ------------------------ ---------B---AA--------- ---------B---AA--------- ----BB---B---AA--------- ------B--B---AA--------- ---B--B--B---AA----B---- ---BAAAAAAAAAAAAAAAB---- ---AAAAAAAAAAAAAAAAA---- --AAAAAAAAAAAAAAAAAAACC- --AAAAAAAAAAAAAAAAAAACC- ---AAAAAAAAAAAAAAAAACCCD ---AAAAAAAAAAAAAAAAACCCD ----AAAAAAAAAAAAAAA-CCC- ----AAAAAAAAAAAAAAA-CCC- -----AAAAAAAAAAAAA------ -------AAAAAAAAA-------- ------------------------ ------------------------ 
------------------------ ------------------------ ------------------------ -----AA-------------B--- ----AAA----------------- ----AA------------------ ----AA------------------ -------------AA---B----- -------------AA--------- -------------AA--------- -------------AA--------- -------------AA--------- -------------AA--------- -------------AA--------- -------------AA--------- -------------AA--------- -------------AA--------- ---AAAAAAAAAAAAAAAAA---- --AAAAAAAAAAAAAAAAAAA--- -AAAAAAAAAAAAAAAAAAAAAC- -AAAAAAAAAAAAAAAAAAAAAC- --AAAAAAAAAAAAAAAAAAACCD --AAAAAAAAAAAAAAAAAAACCD ---AAAAAAAAAAAAAAAAACCC- ---AAAAAAAAAAAAAAAAACCC- -----AAAAAAAAAAAAA------ ------AAAAAAAAAAA------- ---------AAAAA---------- ------------------------ 
------------------------ --------------------B--- --------------------B--- ------------------------ ------------------------ ------------------------ ----AA------------------ ----AA------------------ ---AA--------AA---B----- ---AA--------AA---B----- ---AA--------AA---B----- ---AA--------AA--B------ ---AA-----------B------- ----AA------------------ -----AAA---------------- ------AA---------------- --B---AA------------B--- --BAAAAAAAAAAAAAAAAAB--- --AAAAAAAAAAAAAAAAAAA--- -AAAAAAAAAAAAAAAAAAAAA-- -AAAAAAAAAAAAAAAAAAAAAC- --AAAAAAAAAAAAAAAAAAACC- --AAAAAAAAAAAAAAAAAAACC- ---AAAAAAAAAAAAAAAAACCC- ---AAAAAAAAAAAAAAAAA---- ----AAAAAAAAAAAAAAA----- -----AAAAAAAAAAAAA------ --------AAAAAAA--------- ------------------------ 
------------------------ ------------------------ ------------------------ ------------------------ ------------------------ ------------------------ ------------------------ ----AA------------------ ---AA------------------- ---AA------------------- ---AA------------------- ---AA------------------- ---AA------------------- ----AA----------B------- -----AAA---------------- ------AA---------------- ------AA---------------- --AAAAAAAAAAAAAAAAAAA--- -AAAAAAAAAAAAAAAAAAAAA-- AAAAAAAAAAAAAAAAAAAAAAA- AAAAAAAAAAAAAAAAAAAAAAA- -AAAAAAAAAAAAAAAAAAAAAC- -AAAAAAAAAAAAAAAAAAAAAC- --AAAAAAAAAAAAAAAAAAA--- --AAAAAAAAAAAAAAAAAAA--- ----AAAAAAAAAAAAAAA----- -----AAAAAAAAAAAAA------ -------AAAAAAAAA-------- ------------------------ 
------------------------ ------------------------ ------------------------ -------B---------------- -------B---------------- --------B--------------- ---------B-------------- ---------B-------------- ---------B-------------- ------------------------ ------------------------ ------------------------ ------------------------ ------------------------ ----------------B------- ----------------B------- -B--------------B----B-- -BAAAAAAAAAAAAAAAAAAAB-- -AAAAAAAAAAAAAAAAAAAAA-- AAAAAAAAAAAAAAAAAAAAAAA- AAAAAAAAAAAAAAAAAAAAAAA- -AAAAAAAAAAAAAAAAAAAAA-- -AAAAAAAAAAAAAAAAAAAAA-- --AAAAAAAAAAAAAAAAAAA--- --AAAAAAAAAAAAAAAAAAA--- ---AAAAAAAAAAAAAAAAA---- ----AAAAAAAAAAAAAAA----- ------AAAAAAAAAAA------- ----------AAA----------- 
------------------------ ------------------------ -------B---------------- ------------------------ ------------------------ ------------------------ ------------------------ ------------------------ ------------------------ ---------B-------------- ------------------------ ------------------------ ------------------------ ------------------------ ------------------------ ------------------------ ------------------------ --AAAAAAAAAAAAAAAAAAA--- -AAAAAAAAAAAAAAAAAAAAA-- AAAAAAAAAAAAAAAAAAAAAAA- AAAAAAAAAAAAAAAAAAAAAAA- -AAAAAAAAAAAAAAAAAAAAA-- -AAAAAAAAAAAAAAAAAAAAA-- --AAAAAAAAAAAAAAAAAAA--- --AAAAAAAAAAAAAAAAAAA--- ---AAAAAAAAAAAAAAAAA---- ----AAAAAAAAAAAAAAA----- ------AAAAAAAAAAA------- ---------AAAAA---------- 
-------B---------------- -------B---------------- ------------------------ ------------------------ ------------------------ ------------------------ ------------------------ ------------------------ ------------------------ ------------------------ ---------B-------------- ----------B------------- ----------B------------- ----------B------------- ---------BB------------- ----B---B--------------- -B--B---B------------B-- -BAAAAAAAAA-AAAAAAAAAB-- -AAAAAAAAAAAAAAAAAAAAA-- AAAAAAAAAAAAAAAAAAAAAAA- AAAAAAAAAAAAAAAAAAAAAAA- -AAAAAAAAAAAAAAAAAAAAA-- -AAAAAAAAAAAAAAAAAAAAA-- --AAAAAAAAAAAAAAAAAAA--- --AAAAAAAAAAAAAAAAAAA--- ---AAAAAAAAAAAAAAAAA---- ----AAAAAAAAAAAAAAA----- ------AAAAAAAAAAA------- ---------AAAAA---------- 
------------------------ ------------------------ ------------------------ ------------------------ ------------------------ ------AA-----------AA--- ------AAA----------AA--- -------AA----------AA--- -------AA--------------- ------------------------ ------------------------ ------------------------ ------------------------ ------------------------ ----B-----------AA------ ----------------AA------ ----------------AA------ --AAAAAAAAAAAAAAAAAAA--- -AAAAAAAAAAAAAAAAAAAAA-- AAAAAAAAAAAAAAAAAAAAAAA- AAAAAAAAAAAAAAAAAAAAAAA- -AAAAAAAAAAAAAAAAAAAAA-- -AAAAAAAAAAAAAAAAAAAAA-- --AAAAAAAAAAAAAAAAAAA--- --AAAAAAAAAAAAAAAAAAA--- ---AAAAAAAAAAAAAAAAA---- ----AAAAAAAAAAAAAAA----- ------AAAAAAAAAAA------- ---------AAAAA---------- 
------------------------ ------------------------ ------------------------ ------------------------ ------AA-----------AA--- ------AA-----------AA--- ------AAA----------AA--- -------AA----------AA--- -------AA----------AA--- -------AA---------AAA--- -------AA--------AA----- ----------------AA------ ----------------AA------ ------------B---AA------ ----B-------B---AA------ ------------B---AA------ -B----------B---AA---B-- -BAAAAAAAAAAAAAAAAAAAB-- -AAAAAAAAAAAAAAAAAAAAA-- AAAAAAAAAAAAAAAAAAAAAAA- AAAAAAAAAAAAAAAAAAAAAAA- -AAAAAAAAAAAAAAAAAAAAA-- -AAAAAAAAAAAAAAAAAAAAA-- --AAAAAAAAAAAAAAAAAAA--- --AAAAAAAAAAAAAAAAAAA--- ---AAAAAAAAAAAAAAAAA---- ----AAAAAAAAAAAAAAA----- ------AAAAAAAAAAA------- ----------AAA----------- 
------------------------ ------------------------ -B---------------------- -B-----------------AA--- --B---AA-----------AA--- ---B-------------------- ---B-------------------- ---B-------------------- --B----------------AA--- -------AA---------AAA--- -------AA--------AA----- --BB------------AA------ ----B-------B---AA------ ----B-----------AA------ ----------------AA------ ------------------------ ------------------------ --AAAAAAAAAAAAAAAAAAA--- -AAAAAAAAAAAAAAAAAAAAA-- AAAAAAAAAAAAAAAAAAAAAAA- AAAAAAAAAAAAAAAAAAAAAAA- -AAAAAAAAAAAAAAAAAAAAAC- -AAAAAAAAAAAAAAAAAAAAAC- --AAAAAAAAAAAAAAAAAAA--- --AAAAAAAAAAAAAAAAAAA--- ----AAAAAAAAAAAAAAA----- -----AAAAAAAAAAAAA------ -------AAAAAAAAA-------- ------------------------ 
------------------------ ------------------------ ------------------------ -------------------AA--- ------------------------ ------------------------ ------------------------ ------------------------ -B---------------------- -------AA--------------- -------AA--------------- -B---------------------- -----------B------------ ------------------------ ---------------B-------- --------------B--------- --B-----------B-----B--- --BAAAAAAAAAAAAAAAAAB--- --AAAAAAAAAAAAAAAAAAA--- -AAAAAAAAAAAAAAAAAAAAA-- -AAAAAAAAAAAAAAAAAAAAAC- --AAAAAAAAAAAAAAAAAAACC- --AAAAAAAAAAAAAAAAAAACC- ---AAAAAAAAAAAAAAAAACCC- ---AAAAAAAAAAAAAAAAA---- ----AAAAAAAAAAAAAAA----- -----AAAAAAAAAAAAA------ --------AAAAAAA--------- ------------------------ 
------------------------ ------------------------ ------------------------ ------------------------ ------------------------ ------------------------ ------------------------ ------------------------ ------------------------ -B---------------------- -B-----AA--------------- -------AA--------------- -------AA-B------------- ------------AA---------- ------------AA--B------- ------------AA---------- ------------AA---------- ---AAAAAAAAAAAAAAAAA---- --AAAAAAAAAAAAAAAAAAA--- -AAAAAAAAAAAAAAAAAAAAAC- -AAAAAAAAAAAAAAAAAAAAAC- --AAAAAAAAAAAAAAAAAAACCD --AAAAAAAAAAAAAAAAAAACCD ---AAAAAAAAAAAAAAAAACCC- ---AAAAAAAAAAAAAAAAACCC- -----AAAAAAAAAAAAA------ ------AAAAAAAAAAA------- ---------AAAAA---------- ------------------------ 
------------------------ ------------------------ ------------------------ ------------------------ ------------------------ ------------------------ ------------------------ ---------B-------------- ----------B------------- ----------B------------- -------AA-B------------- -------AA-B-----B------- -------AA---AA--B------- -------AA---AA--B------- -------AA---AA---------- -------AA---AA---------- ---B---AA---AA-----B---- ---BAAAAAAAAAAAAAAAB---- ---AAAAAAAAAAAAAAAAA---- --AAAAAAAAAAAAAAAAAAACC- --AAAAAAAAAAAAAAAAAAACC- ---AAAAAAAAAAAAAAAAACCCD ---AAAAAAAAAAAAAAAAACCCD ----AAAAAAAAAAAAAAA-CCC- ----AAAAAAAAAAAAAAA-CCC- -----AAAAAAAAAAAAA------ -------AAAAAAAAA-------- ------------------------ ------------------------ 
------------------------ ------------------------ ------------------------ ------------------------ ------------------------ ------------------------ ------------------------ --------B--------------- ------------------------ ------------------------ ----------------B------- ------------------------ ------------AA---------- -------AA---AA---------- -------AA--------------- -------AA--------------- -------AA--------------- -----AAAAAAAAAAAAA------ ----AAAAAAAAAAAAAAA----- --AAAAAAAAAAAAAAAAAAA--- --AAAAAAAAAAAAAAAAAAACC- ----AAAAAAAAAAAAAAA-CCC- ----AAAAAAAAAAAAAAA-CCC- -----AAAAAAAAAAAAA--CCC- -----AAAAAAAAAAAAA------ -------AAAAAAAAA-------- ---------AAAAA---------- ------------------------ ------------------------ 
------------------------ ------B----------------- ------B----------------- -------B---------------- --------B--------------- --------B--------------- --------B--------B------ ------------------B----- ------------------B----- ------------------B----- -----------------B------ ------------------------ ------------AA---------- ------------AA---------- ------------------------ ------------------------ -----B-----------B------ -----BAAAAAAAAAAAB------ -----AAAAAAAAAAAAA------ ---AAAAAAAAAAAAAAAAA---- ---AAAAAAAAAAAAAAAAA---- -----AAAAAAAAAAAAA--CCC- -----AAAAAAAAAAAAA--CCC- ------AAAAAAAAAAA------- ------AAAAAAAAAAA------- ---------AAAAA---------- ------------------------ ------------------------ ------------------------ 
------------------------ ------------------------ ------------------------ ------------------------ ------------------------ ------------------------ ----------------B------- ------------------------ ------------------------ ------------------------ ------------------------ ------------AA---------- ------------AA---------- ------------------------ ------------------------ ------------------------ -------B-------B-------- -------BAAAAAAAB-------- ------AAAAAAAAAAA------- ----AAAAAAAAAAAAAAA----- ----AAAAAAAAAAAAAAA----- ------AAAAAAAAAAA------- ------AAAAAAAAAAA------- --------AAAAAAA--------- --------AAAAAAA--------- ------------------------ ------------------------ ------------------------ ------------------------ 
------------------------ ------------------------ ------------------------ ----------------B------- ----------------B------- ----------------B------- ------------AA---------- ------------------------ ------------------------ ------------------------ ------------------------ ------------AA---------- ------------AA---------- ------------------------ ------------------------ ------------------------ ---------B-B-B---------- ---------B-B-B---------- --------AAAAAAA--------- ------AAAAAAAAAAA------- ------AAAAAAAAAAA------- --------AAAAAAA--------- --------AAAAAAA--------- ------------------------ ------------------------ ------------------------ ------------------------ ------------------------ ------------------------ 
------------------------ ------------------------ ------------------------ ------------------------ ------------------------ ------------------------ ------------AA---------- ------------AA---------- ------------AA---------- ------------AA---------- ------------AA---------- ------------AA---------- ------------------------ ------------------------ ------------------------ ------------------------ ------------------------ ------------------------ ------------------------ --------AAAAAAA--------- --------AAAAAAA--------- ------------------------ ------------------------ ------------------------ ------------------------ ------------------------ ------------------------ ------------------------ ------------------------ 
------------------------ ------------------------ ------------------------ ------------------------ ------------------------ ------------------------ ------------------------ ------------AA---------- ------------AA---------- ------------AA---------- ------------AA---------- ------------AA---------- ------------------------ ------------------------ ------------------------ ------------------------ ------------------------ ------------------------ ------------------------ ------------------------ ------------------------ ------------------------ ------------------------ ------------------------ ------------------------ ------------------------ ------------------------ ------------------------ ------------------------ 
