model
size = 28 17 28, scale = 0.05, origin = -y
material 
  colors = A:#FC3 B:#E00 C:#FC0 D:#00D E:#0D0 F:#EEE G:#BBB H:#9CF I:#CC0 J:#0E0
voxels
-----------AAAAAA----------- ---------------------------- ---------------------------- ---------------------------- ---------------------------- ---------------------------- ---------------------------- ---------------------------- ---------------------------- -------------DD------------- -------------DD------------- ---------------------------- ---------------------------- ---------------------------- ---------------------------- ---------------------------- ---------------------------- 
--------AAAAAAAAAAAA-------- ----------AAAACAAA---------- -----------CCACCC----------- -----------CC--AC----------- -----------CA--AC----------- -----------CCAAAC----------- -----------A----C----------- -----------AAAAAC----------- -----------AADDAC----------- -----------ADAADC----------- -----------ADAADA----------- -----------CADDAC----------- -----------ACAAAA----------- ------------A--A------------ ------------CCCA------------ -------------CC------------- -------------CA------------- 
------AAAAABBBBBBBAAAA------ -------CCAHBBBBBBBCCC------- --------CCCAAAAAACCC-------- --------CAAAAFFAACAC-------- --------C-AAAFFAAC-C-------- --------C-AAAAAAAC-C-------- --------C-AA----AC-C-------- --------C-AAAAAAAC-A-------- --------CAAAAAAAAAAA-------- --------A-AAAAAAAA-A-------- --------A-AAAAAAAA-A-------- -----------AAAAAA----------- ------------AAAA------------ ------------A--A------------ -------------AA------------- -------------AA------------- ---------------------------- 
-----AAAABBBBBBBBBBBAAA----- ------CAGBBBBBBBBBBBHC------ -------CAAA--BBB-AAAC------- --------AAA--AA--AAA-------- -------EA-A--AA--A-AE------- -------EA-A------A-AE------- -------EA-A------A-AE------- --------A-A------A-A-------- -------AAAA------AAAA------- -------AA-A------A-AA------- -------AA-----------A------- -------A------------A------- -------A------------A------- ---------------------------- ---------------------------- ---------------------------- ---------------------------- 
----AAAABBB-------BBBAAA---- -----AAABBBB-----BBBBHC----- ------CAABBBBBBBBBB-AC------ -------IA--BBBBBBB--C------- -------AA---BBBBB---C------- -------AA-----A-----A------- -------AA-----------C------- -------AA-----------A------- -------AA-----------A------- -------AA-----------AA------ ------AA------------AA------ ------AA------------AA------ ------AA-------------A------ ------A--------------A------ -----CA--------------AC----- -----C----------------C----- -----A----------------C----- 
---AAABBB-----------BBAAA--- ----AHBBBB---------BBBHC---- -----AAABBB-------BBBAA----- -------ABBBBBBBBBBBB-------- -------A--BBBBBBBBB--------- -------A---BBBBBBB---------- -------A------A------------- -------A-------------------- -------A-------------------- -------A-------------------- -------A-------------------- -------A-------------------- -----AA--------------AA----- -----BA--------------AB----- ----AA----------------AC---- ----CA----------------AC---- ----C------------------A---- 
--AAABBB-------------BBAAA-- ---AHBBB-------------BBHA--- ----AA-BB-----------BBAA---- --------BBB-------BBB------- --------BBBBBBBBBBBBB------- ---------BBBBBBBBBBB-------- -----------BBBBBBB---------- --------------A------------- ---------------------------- -----------------------A---- ----A------------------A---- ----A------------------A---- ----AA----------------AA---- ----AA----------------AA---- ----A------------------A---- ---------------------------- ---------------------------- 
--AAABB---------------BBAA-- --AGABB---------------BBHA-- ---AA-BB-------------BBAA--- ----A--BB-----------BB-A---- ---EA--BBBB-------BBBB-AE--- ---EA---BBBBBBBBBBBBB--AE--- ---EA----BBBBBBBBBBB---AE--- ----A------BBBBBBB-----A---- ---AA---------A--------AA--- ---AA------------------AA--- ---AA------------------AA--- ---AA------------------AA--- ---A--------------------A--- ---------------------------- ---------------------------- ---------------------------- ---------------------------- 
-AAABB-----------------BBAA- --AGBBB---------------BBBC-- --AAA-B---------------BAAC-- --AAA-BB-------------BBAAC-- --AAA--BBB---------BBB-AAC-- --AAA--BBBBB-----BBBBB-AAC-- --AAA---BBBBBBBBBBBBB--AAC-- --AAA-----BBBBBBBBB----AAA-- --AAA-------BBBBB------AAA-- --AAA---------A--------AAA-- --AA--------------------AA-- ---------------------------- ---------------------------- ---------------------------- ---------------------------- ---------------------------- ---------------------------- 
-AAABB-----------------BBAA- --CABB-----------------BBA-- --AAABB---------------BBAC-- --AAA-BB-------------BBAAA-- ------BBB-----------BBB----- -------BBBB-------BBBB------ --------BBBBBBBBBBBBB------- ---------BBBBBBBBBBB-------- --AA-------BBBBBBB------AA-- --------------A------------- ---------------------------- ---------------------------- ---------------------------- ---------------------------- ---------------------------- ---------------------------- ---------------------------- 
-AABB-------------------BBA- -CGBBB-----------------BBBA- --CA-B-----------------BAA-- --CA-BB---------------BBAA-- --CA--BB-------------BB-AA-- --CA--BBBB---------BBBB-AA-- --CA---BBBBBB---BBBBBB--AA-- --CA-----BBBB---BBBBB---AA-- --CA------BBB---BBB-----AA-- --AA---------BBB--------AA-- --A-----------A----------A-- ---------------------------- ---------------------------- ---------------------------- ---------------------------- ---------------------------- ---------------------------- 
AABBB-------------------BBAA -CBBB-------------------BBC- -CA--B-----------------B-AC- -CA--BB---------------BB-AC- -CA--BBB-------------BBB-AC- -CA---BBB-----------BBB--AC- -CA----BBBBB-----BBBBB---AC- -CA-----BBBB-----BBBB----AC- -CA------BBB-----BBB-----AC- -AA---------BBBBB--------AA- -AA-----------A----------AA- -AA----------------------AA- -A------------------------A- ---------------------------- ---------------------------- ---------------------------- ---------------------------- 
AABBB-------------------BBAA -ABBB-------------------BBC- -AA-BB-----------------BBAA- -CA--BB---------------BB-AA- -AA--BBB-------------BBB-AA- -AA---BBB-----------BBB--AA- -------BBBB-------BBBB------ -AA-----BBB-------BBB----AA- -AA------BB-------BB-----AA- -DA--------BBBBBBB-------AD- -DA----------BBB---------AD- -AA-----------A----------AA- -AA----------------------AA- -AA----------------------AA- -A------------------------A- ---------------------------- ---------------------------- 
AABBB-------------------BBAA -ABBB-------------------BBA- -AA-BB-----------------BBAA- --FAABB---------------BBAF-- --FA-BBB-------------BBBAF-- -AA--ABBB-----------BBBA-AA- ------ABBBB-------BBBBA----- -AA----ABBB-------BBBA---AA- -DA-----ABB-------BBA----AD- DAA------AABBBBBBBAA-----AAD DAA--------AABJBAA-------AAD -DA----------A-A---------AD- -AA----------------------AA- ---------------------------- -CA----------------------AA- -CA----------------------AC- -A------------------------C- 
AABBB-------------------BBAA -ABBB-------------------BBA- -AA-BB-----------------BBAA- --FA-BB---------------BBAF-- --FA-BBB-------------BBBAF-- -AA---BBB-----------BBB--AA- -------BBBB-------BBBB------ -AA-----BBB-------BBB----AA- -DA------BB-------BB-----AD- DAA--------BBBBBBB-------AAD DAA----------BBB---------AAD -DA-----------A----------AD- -AA----------------------AA- ---------------------------- -CA----------------------AC- -CA----------------------AC- -C------------------------A- 
AABBB-------------------BBAA -CBBB-------------------BBA- -AA--B-----------------B-AA- -AA--BB---------------BB-AA- -AA--BBB-------------BBB-AA- -AA---BBB-----------BBB--AA- -------BBBBB-----BBBBB------ -AA-----BBBB-----BBBB----AA- -CA------BBB-----BBB-----AA- -DA---------BBBBB--------AD- -DA-----------A----------AD- -AA----------------------AA- -AA----------------------AA- -AA----------------------AA- -A------------------------A- ---------------------------- ---------------------------- 
AABBB-------------------BBAA -CBBBB-----------------BBBA- -CA--B-----------------B-AC- -CA--BB---------------BB-AC- -CA---BB-------------BB--AC- -CA---BBBB---------BBBB--AC- -CA----BBBBBB---BBBBBB---AC- -CA-----BBBBB---BBBBB----AA- -CA-------BBB---BBB------AA- -AA----------BBB---------AA- -AA-----------A----------AA- -AA----------------------AA- -A------------------------A- ---------------------------- ---------------------------- ---------------------------- ---------------------------- 
-AABBB-----------------BBAA- -AGBBB-----------------BBHC- --AA-BB---------------BBAC-- --AA--BB-------------BB-AA-- --AA--BBB-----------BBB-AA-- --AA---BBBB-------BBBB--AA-- --AA----BBBBBBBBBBBBB---AC-- --AA-----BBBBBBBBBBB----AC-- --AA-------BBBBBBB------AA-- --AA----------A---------AA-- --A----------------------A-- ---------------------------- ---------------------------- ---------------------------- ---------------------------- ---------------------------- ---------------------------- 
-AABBB-----------------BBAA- --ABBBB---------------BBBC-- --CAA-B---------------BAAC-- --AAA-BB-------------BBAAC-- -------BBB---------BBB------ -------BBBBB-----BBBBB------ --------BBBBBBBBBBBBB------- ----------BBBBBBBBB--------- --AA--------BBBBB-------AA-- --------------A------------- ---------------------------- ---------------------------- ---------------------------- ---------------------------- ---------------------------- ---------------------------- ---------------------------- 
-AAABBB---------------BBAAA- --AABBB---------------BBAC-- --CAA-BB-------------BBAAC-- --CAA--BB-----------BB-AAA-- --CAA--BBBB-------BBBB-AAA-- --CAA---BBBBBBBBBBBBB--AAA-- --CAA----BBBBBBBBBBB---AAA-- --CAA------BBBBBBB-----AAA-- --AAA---------A--------AAA-- --AAA------------------AAA-- --AA--------------------AA-- ---------------------------- ---------------------------- ---------------------------- ---------------------------- ---------------------------- ---------------------------- 
--AABBBB-------------BBBAA-- --AABBBB-------------BBBAC-- ---CA-BBB-----------BB-AA--- ----A---BBB-------BBB--A---- ---EA---BBBBBBBBBBBBB--AE--- ---EA----BBBBBBBBBBB---AE--- ---EA------BBBBBBB-----AE--- ----A---------A--------A---- ---AA------------------AA--- ---AA------------------AA--- ---AA------------------AA--- ---AA------------------AA--- ---A--------------------A--- ---------------------------- ---------------------------- ---------------------------- ---------------------------- 
--AAABBBB-----------BBBAAA-- ---CABBBBB---------BBBBHA--- ----AA--BBB-------BBB-AA---- ---------BBBBBBBBBBB-------- ----------BBBBBBBBB--------- -----------BBBBBBB---------- --------------A------------- ---------------------------- ---------------------------- ----A------------------A---- ----A------------------A---- ----A------------------A---- ----AA----------------AA---- ----AA----------------AA---- ----A------------------A---- ---------------------------- ---------------------------- 
---AAABBBBB-------BBBBAAA--- ----CGBBBBBB-----BBBBBHA---- -----CA---BBBBBBBBB--AA----- -----------BBBBBBB---------- ------------BBBBB----------- --------------A------------- ---------------------------- ---------------------------- ---------------------------- ---------------------------- ---------------------------- ---------------------------- -----AA--------------AA----- -----BA--------------AB----- ----CA----------------AC---- ----C-----------------AC---- ----A------------------C---- 
----AAAABBBBBBBBBBBBBAAA---- -----CGABBBBBBBBBBBBBGA----- ------CAAA---BBB--AAAA------ -------CAA----A---AAA------- -------CA----------AA------- -------CA----------AA------- -------CA----------AA------- -------CA----------AA------- -------CA----------AA------- ------AAA----------AAA------ ------AA------------AC------ ------AA------------AA------ ------A--------------A------ ------A--------------C------ -----CA--------------AC----- -----C----------------C----- -----C----------------C----- 
-----AAAABBBBBBBBBBAAAA----- ------AGGBBBBBBBBBBAHA------ -------CAAA---A--AAAA------- --------CAA--AA--AAA-------- -------EA-A--AA--A-AE------- -------EA-A------A-AE------- -------EA-A------A-AE------- --------A-A------A-A-------- -------AAAA------AAAA------- -------AA-A------A-AA------- -------AA----------AA------- -------A------------A------- -------A------------A------- ---------------------------- ---------------------------- ---------------------------- ---------------------------- 
------AAAAABBBBBBAAAAA------ -------AAAGBBBBBBGAAA------- --------CCCAAAAAAACA-------- --------CAAAAFFAACCC-------- --------C-AAAFFAAA-A-------- --------C-AAAAAAAA-A-------- --------C-AA----AA-A-------- --------C-AAAAAAAA-A-------- --------CAAAAAAAAAAA-------- --------A-AAAAAAAA-A-------- --------A-AAAAAAAA-A-------- -----------AAAAAA----------- ------------AAAA------------ ------------A--A------------ -------------AA------------- -------------AA------------- ---------------------------- 
--------AAAAAAAAAAAA-------- ----------AAAAACAA---------- -----------CAAACC----------- -----------CA--AC----------- -----------CA--AC----------- -----------CAAAAC----------- -----------C----C----------- -----------CAAACC----------- -----------CADDAA----------- -----------ADAADA----------- -----------ADAADA----------- -----------AADDAA----------- -----------AAAAAA----------- ------------A--A------------ ------------AAAA------------ -------------CC------------- -------------AC------------- 
-----------AAAAAA----------- ---------------------------- ---------------------------- ---------------------------- ---------------------------- ---------------------------- ---------------------------- ---------------------------- ---------------------------- -------------DD------------- -------------DD------------- ---------------------------- ---------------------------- ---------------------------- ---------------------------- ---------------------------- ---------------------------- 
