model
size = 26 32 14, scale = 0.05, origin = -y
material 
  colors = A:#700 B:#EEE
voxels
37-A26-A-A48-A26-A23-A51-2A25-A595-7B21-4A22-A-2A21-2A-2A22-2A-A21-3A22-4A22-2(3A24-)A24-A2-A22-A2-A540-B7AB19-3A-A17-A2-6A21-2(A-)3A18-4A3-A18-2(4A22-)4A23-3A-A21-5A21-A-2A21-2A2-A25-A151-A360-2B7A-A2B15-9A14-6A-2A-4A15-2(A-)2A-3A17-4A3-A19-3A3-A18-4A22-4A-A20-6A20-A-4A20-6A20-2A-3A20-2A-2A25-A47-2A2-A22-A-2A22-A24-2A25-2A26-A304-BA-8A-2A2B13-13A10-5A2-8A11-6A-7A13-A-3A-2A2-2A15-A-3A-A2-A16-2(A-)3A-2A18-6A20-3A-2A20-A-4A19-7A19-8A18-2A2-3A20-A-4A20-A2-3A20-2A-3A20-5A22-2A-A2(21-5A)22-A-3A23-A26-2(A25-)A198-B11A-4AB9-2A2-13A9-A-4A-8A-A11-4A-8A13-4A2-2(5A15-3A-A-)4A16-3A-A-3A-A15-3A-A-3A17-3(A-)3A17-A-A3-3A17-A-A2-4A3(17-9A)19-A-4A20-6A20-7A19-6A19-7A17-9A18-A4-3A23-3A21-A-2A22-A-3A21-A-3A170-B18AB6-18A9-7A-2A-6A12-4A2(-2A)2-4A10-3A3-A-3A4-A10-3A-A3-2A16-2A2-A2-3A6-A9-2A5-3A16-3A4-3A-A2-3A9-3A3-4A16-3A3-A-2A5-A9-4A3-A-A6-A12-A3-3A18-2A-A-3A17-3A3-3A17-3A-5A18-2A2-4A18-2A3(-5A17-3A)-4A19-7A18-8A18-7A21-2(2A-3A20-)2A-3A2(21-A2-2A)21-A-2A22-3A41-B2A-3A6B8A2B7-3A6-3A3-2A6-6A6-8A7-5A6-8A8-4A6-6A-A8-4A6-3A2-A-A8-4A6-3A3-3A8-3A6-3A3-A-A8-3A6-5A-3A9-2A6-4A-4A8-3A6-6A-2A8-3A6-2A-3A-A9-4A5-A2-A13-A-2A4-2A18-2A2(4-3A16-3A)4-2A18-2A2(4-2A17-3A)3-4A16-3A3-4A17-2A-A-2A19-8A18-4A-3A18-4A-2A18-9A17-A-3(7A19-)6A20-6A23-A15-B5AB6-B3AB4AB3-2A-3A8-9A3-2A2-2A8-9A7-2A8-8A8-2A8-A-6A7-3A8-8A7-3A8-9A4-5A8-6A-A4-6A8-A-6A5-5A8-7A6-5A8-8A7-3A8-A2(-5A9-3A6-2A)-4A10-2A7-2A2-A-A10-3A6-2A2-A13-2A6-2A3-A12-4(2A6-2A16-)3A3-4A17-2A3-3A18-2A3-4A17-2A5-2A16-4A-A-3A16-4A3-2A17-5A3-A18-6A-2A17-9A17-8A19-2A-3A12-B2AB3AB6-B3A6B2-A-5A8-3A2(-2A)2-7A8-3A-2A-3A3-5A8-3A2(-2A)4-5A8-9A4-4A9-8A3-6A9-8A4-5A9-9A3-5A9-8A3-6A9-8A3-7A8-9A4-4A9-8A7-A-A8-A-6A7-A10-A-4A8-2A10-6A8-3A2(9-6A9-2A)9-3A-2(2A9-)3A-2A10-2A8-3A12-3A8-5A10-4A2(6-2A15-3A)2(6-2A16-2A)5-3A16-2A6-2A15-3A2(6-2A16-2A)5-3A16-10A18-A16-B3ABA2B8-3B3-BAB-4A-A17-2A3-2A-A17-2(3A-)A12-A2-A-3A-5A12-A4-3A-5A12-4A-2A2-5A12-3A2-2A2-5A12-6A4-2A14-3A2-A3-2A17-5A2-4A15-5A2-4A16-4A4-3A11-A2-4A5-3A11-2(A-)3A5-2A13-5A6-3A13-A-A7-3A13-A-2A6-2A12-5A7-3A10-7A6-3A9-7A6-3A11-A-4A7-2A11-6A7-3A10-6A8-3A9-A-4A7-2(4A9-)5A8-3A12-2(3A8-2A13-)3A8-A14-3A8-3A13-11A16-A2-4B-A10-2BAB-B17-2B3-2A19-2A3-2A19-A3-3A19-2A2-3A19-3A2-2A19-2A3-2A19-A4-3A18-A4-A20-A2-3A19-2A2(2-3A20-A)3-3A17-4A3-A19-3A4-A18-2A5-A18-2A3-3A17-A5-3A17-2A5-2A16-2(2A6-3A15-)A8-2A14-3A7-3A13-3A7-2A-A10-5A6-5A9-6A7-5A8-6A6-6A3(8-5A)9-4A8-4A11-3A8-2A14-4A4-4A15-A-2B2-2B12-BAB24-2A20-A3-2A19-A3-3(3A19-2A2-)3A19-A3-2A20-A4-A20-2A3-A19-2A4-A20-A3-2A24-2(2A20-A3-)2A24-2A20-A3-2A105-A15-A9-A15-2A8-2(A15-A9-)A13-3A9-3A12-3A7-4A11-3A9-3A11-A-A9-A-A11-2A12-2A25-2A6-A38-B829-
