model
size = 7 32 7, scale = 0.05, origin = -y
material 
  colors = A:#FC0 B:#FC3 C:#E00 D:#00B
voxels
171-B5-BCB5-B55-A34-B110-3B3-B2ABA2-5A2-AB2AB3-2BA40-A5-BAB5-3(B6-)B5-2AB5-2(A3(6-B)6-)B2(6-A)3(6-B)5-A2B3-5A2-5A-7A-5A2-2BABA11-B6-B13-B5-ACA3-B3AB3-3(BAB4-)BAB3-5A3-2(B2A4-)7(BAB4-)2(B2A4-)BA2(B4-2A)B4-3A3-5A-7AC5ACB5AB-2B2AB4-B2(6-D)6-A13-A5-B2A5-3(B6-)B5-3A5-11(B6-)2(A6-)A5-2BA3-5A2-5A-B5AB-B4A2-2B2AB11-A6-A27-A34-B110-A2B3-2(B3AB2-)B3AB3-3A201-A5-ACA5-A38-
