model
size = 27 14 26, scale = 0.05, origin = -y
material 
  colors = A:#09F B:#FC0 C:#CFF D:#EEE E:#FF0 F:#9CF G:#69C H:#FFC
voxels
-----BBBBBBBBBBBBBBBBB----- -----BBBBBBBBBBBBBBBBB----- -----BBBBBBBBBBBBBBBBB----- ------B-------------------- ------B-------------------- ------B-------------------- --------------------------- --------------------------- --------------------------- --------------------------- --------------------------- --------------------------- --------------------------- --------------------------- 
----BBBBBBBBBBBBBBBBBBB---- ----BADAAAAAAAAAAAAAABB---- ----BADAAAAAAAAAAAAAABB---- -----EDEEEEEEEEEEEEEEB----- -----EDEEEEEEEEEEEEEEB----- ------BB-------------B----- -------B------------------- -------B------------------- --------------------------- --------------------------- --------------------------- --------------------------- --------------------------- --------------------------- 
---BBBBBBBBBBBBBBBBBBBBB--- ---BAAADAAAAAAAAAAAADABB--- ---BAAADAAAAAAAAAAAADABB--- ----EAADAAAAAAAAAAAADE----- ----EAADAAAAAAAAAAAADE----- -----EADEEEEEEEEEEEEB------ -----EEDEEEEEEEEEEEEB------ -----BBBBBBBBBBBBBBBB------ --------------------------- --------------------------- --------------------------- --------------------------- --------------------------- --------------------------- 
--BBBBBBBBBBBBBBBBBBBBBBB-- --BAAAAADAAAAAAAAAADAAADB-- --BAAAAADAAAAAAAAAADAAABB-- ---EAAAADAAAAAAAAAADAAE---- ---EAAAADAAAAAAAAAADAAE---- ----EAAADAAAAAAAAAADAE----- ----EEEEDAAAAAAAAAADAE----- ----B---BEEEEEEEEEEDEB----- --------B----------B------- --------------------------- --------------------------- --------------------------- --------------------------- --------------------------- 
-BBBBBBBBBBBBBBBBBBBBBBBBB- -BADAAAAADAAAAAAAADAAAAADB- -BADAAAAADAAAAAAAADAAAAADB- --BDAAAAADAAAAAAAADAAAAEB-- --BDAAAAADAAAAAAAADAAAAEB-- --BBAAAAADAAAAAAAADAAAE-B-- ---BEEEEEDAAAAAAAADAAAE---- ---B-----BAAAAAAAADAEEB---- ---------BEEEEEEEEBE------- ---------B--------B-------- ------------------B-------- --------------------------- --------------------------- --------------------------- 
BBBBBBBBBBBBBBBBBBBBBBBBBBB BAAADAAAADDDDDDDDDAAAABBBBB BAAADAAAADDDDDDDDDAAAABBBBB -EAADAAAADDDDDDDDDAAAAADE-- -EAADAAAADDDDDDDDDAAAAADE-- --EADAAAADDDDDDDDDAAAAAB--- --EADAAAADDDDDDDDDAAAAAB--- ---BBEEEEDDDDDDDDDAAAAEB--- ----BEEEEDDDDDDDDDAAEE----- ----B----BEEEEEEEBAE------- ---------BEEEEEEEBEE------- -----------------B--------- --------------------------- --------------------------- 
BBBBBBBBBBBBBBBBBBBBBBBBBBB BAAAADAADFCCCCCCFFDAAABBBBB BAAAADAADFCCCCCCFFDAAABBBBB -EAAADAADFCCCCCCFFDAAADAAE- -EAAADAADFCCCCCCFFDAAADAAE- --EAADAADFCCCCCCFFDAAADAE-- --EAADAADFCCCCCCFFDAAADAE-- ---BADAADFCCCCCCFFDAAADBB-- ----EDAADFCCCCCCFFDAAEB---- -----BEEEFCCCCCCFFDAE-B---- -----BEEEFCCCCCCFFDEE------ ---------BBBBBBBBBB-------- --------------------------- --------------------------- 
BBBBBBBBBBBBBBBBBBBBBBBBBBB BAAAAADDFFCCCCCCCFFDADBBBBB BAAAAADDFFCCCCCCCFFDADBBBBB -EAAAADDFFCCCCCCCFFDADAAAE- -EAAAADDFFCCCCCCCFFDADAAAE- --EAAADDFFCCCCCCCFFDADAAE-- --EAAADDFFCCCCCCCFFDADAAE-- ---BAADDFFCCCCCCCFFDADAAB-- ----EADDFFCCCCCCCFFDADEE--- -----EDDFFCCCCCCCFFDAB----- -----EDDFFCCCCCCCFFDEB----- ------BBBECCCCCCFEBB------- ----------EEEEEEE---------- --------------------------- 
BBBBBBBBBBBBBBBBBBBBBBBBBBB BAAAAAADFCCCCCCCCCFDDABBBBB BAAAAAADFCCCCCCCCCFDDABBBBB -EAAAAADFCCCCCCCCCFDDAAAAE- -EAAAAADFCCCCCCCCCFDDAAAAE- --EAAAADFCCCCCCCCCFDDAAAE-- --EAAAADFCCCCCCCCCFDDAAAE-- ---BAAADFCCCCCCCCCFDDAAAB-- ----EAADFCCCCCCCCCFDDAEE--- -----EADFCCCCCCCCCFDDE----- -----EEDFCCCCCCCCCFDDE----- -------BFCCCCCCCCFEBB------ --------EECCCCCCEE--------- ----------EEEEEE----------- 
BBBBBBBBBBBBBBBBBBBBBBBBBBB BAAAAAGDCCCCCCCCCCCDAABBBBB BAAAAAGDCCCCCCCCCCCDAABBBBB -EAAAAGDCCCCCCCCCCCDAAAAAE- -EAAAAGDCCCCCCCCCCCDAAAAAE- --EAAAGDCCCCCCCCCCCDAAAAE-- --EAAAGDCCCCCCCCCCCDAAAAE-- ---BAAGDCCCCCCCCCCCDAAAAB-- ----EAGDCCCCCCCCCCCDAAEE--- -----EGDCCCCCCCCCCCDAE----- -----EEDCCCCCCCCCCCDEE----- -------BCCCCCCCCCCCB------- --------ECCCCCCCCEE-------- ---------EEEEEEEE---------- 
BBBBBBBBBBBBBBBBBBBBBBBBBBB BAAAAAADCCCCDDDDCCCDAABBBBB BAAAAAADCCCCFFFFCCCDAABBBBB -EAAAAADCCCCFFFFCCCDAAAAAE- -EAAAAADCCCCFFFFCCCDAAAAAE- --EAAAADCCCCFFFFCCCDAAAAE-- --EAAAADCCCCFFFFCCCDAAAAE-- ---BAAADCCCCFFFFCCCDAAAAB-- ----EAADCCCCFFFFCCCDAAEE--- -----EADCCCCFFFFCCCDAE----- -----EEDCCCCFFFFCCCDEE----- -------BCCCCFFFFCCCB------- --------ECCCFFFFCCE-------- ---------EEEEHHEEE--------- 
BBBBBBBBBBBBBBBBBBBBBBBBBBB BAAAAAADCCCDDDDDCCCDAABBBBB BAAAAAADCCCFFFFFCCCDAABBBBB -EAAAAADCCCFFFFFCCCDAAAAAE- -EAAAAADCCCFFFFFCCCDAAAAAE- --EAAAADCCCFFFFFCCCDAAAAE-- --EAAAADCCCFFFFFCCCDAAAAE-- ---BAAADCCCFFFFFCCCDAAAAB-- ----EAADCCCFFFFFCCCDAAEE--- -----EADCCCFFFFFCCCDAE----- -----EEDCCCFFFFFCCCDEE----- -------BCCCFFFFFCCCB------- --------ECCFFFFFCCE-------- ---------EEEHHHEEE--------- 
BBBBBBBBBBBBBBBBBBBBBBBBBBB BAAAAAADCCBDDDDDCCCDAABBBBB BAAAAAADCCCFFFFFCCCDAABBBBB -EAAAAADCCCFFFFFCCCDAAAAAE- -EAAAAADCCCFFFFFCCCDAAAAAE- --EAAAADCCCFFFFFCCCDAAAAE-- --EAAAADCCCFFFFFCCCDAAAAE-- ---BAAADCCCFFFFFCCCDAAAAB-- ----EAADCCCFFFFFCCCDAAEE--- -----EADCCCFFFFFCCCDAE----- -----EEDCCCFFFFFCCCDEE----- -------BCCCFFFFFCCCB------- --------ECCFFFFFCCE-------- ---------EEEEHEEEE--------- 
BBBBBBBBBBBBBBBBBBBBBBBBBBB BAAAAAADCCBDDDDDCCCDAABBBBB BAAAAAADCCCFFFFFCCCDAABBBBB -EAAAAADCCCFFFFFCCCDAAAAAE- -EAAAAADCCCFFFFFCCCDAAAAAE- --EAAAADCCCFFFFFCCCDAAAAE-- --EAAAADCCCFFFFFCCCDAAAAE-- ---BAAADCCCFFFFFCCCDAAAAB-- ----EAADCCCFFFFFCCCDAAEE--- -----EADCCCFFFFFCCCDAE----- -----EEDCCCFFFFFCCCDEE----- -------BCCCFFFFFCCCB------- --------ECCFFFFFCCE-------- ---------EEEEEEEEE--------- 
BBBBBBBBBBBBBBBBBBBBBBBBBBB BAAAAAADCCCCCCCCCCCDAABBBBB BAAAAAADCCCCCCCCCCCDAABBBBB -EAAAAADCCCCCCCCCCCDAAAAAE- -EAAAAADCCCCCCCCCCCDAAAAAE- --EAAAADCCCCCCCCCCCDAAAAE-- --EAAAADCCCCCCCCCCCDAAAAE-- ---BAAADCCCCCCCCCCCDAAAAB-- ----EAADCCCCCCCCCCCDAAEE--- -----EADCCCCCCCCCCCDAE----- -----EEDCCCCCCCCCCCDEE----- -------BCCCCCCCCCCCB------- --------ECCCCCCCCCE-------- ---------EEEEEEEEE--------- 
BBBBBBBBBBBBBBBBBBBBBBBBBBB BAAAAAADFCCCCCCCCCCDAABBBBB BAAAAAADFCCCCCCCCCCDAABBBBB -EAAAAADFCCCCCCCCCCDAAAAAE- -EAAAAADFCCCCCCCCCCDAAAAAE- --EAAAADFCCCCCCCCCCDAAAAE-- --EAAAADFCCCCCCCCCCDAAAAE-- ---BAAADFCCCCCCCCCCDAAAAB-- ----EAADFCCCCCCCCCCDAAEE--- -----EADFCCCCCCCCCCDAE----- -----EEDFCCCCCCCCCCDEE----- -------BFCCCCCCCCCCB------- --------ECCCCCCCCCE-------- ---------EEEEEEEEE--------- 
BBBBBBBBBBBBBBBBBBBBBBBBBBB BAAAAAADFFCCCCCCCCFDAABBBBB BAAAAAADFFCCCCCCCCFDAABBBBB -EAAAAADFFCCCCCCCCFDAAAAAE- -EAAAAADFFCCCCCCCCFDAAAAAE- --EAAAADFFCCCCCCCCFDAAAAE-- --EAAAADFFCCCCCCCCFDAAAAE-- ---BAAADFFCCCCCCCCFDAAAAB-- ----EAADFFCCCCCCCCFDAAEE--- -----EADFFCCCCCCCCFDAE----- -----EEDFFCCCCCCCCFDEE----- -------BFFCCCCCCCCFB------- --------EEECCCCCCEE-------- -----------EEEEEE---------- 
BBBBBBBBBBBBBBBBBBBBBBBBBBB BAAAAAADDFFCCCCCCFDDDDBBBBB BAAAAAADDFFCCCCCCFDDDDBBBBB -EAAAAADDFFCCCCCCFDDDDAAAE- -EAAAAADDFFCCCCCCFDDDDAAAE- --EAAAADDFFCCCCCCFDDDDAAE-- --EAAAADDFFCCCCCCFDDDDAAE-- ---BAAADDFFCCCCCCFDDDDAAB-- ----EAADDFFCCCCCCFDDDDEE--- -----EADDFFCCCCCCFDDDB----- -----EEDDFFCCCCCCFDDDB----- -------BBEFCCCCCCFBBB------ ----------EEEEEEEE--------- --------------------------- 
BBBBBBBBBBBBBBBBBBBBBBBBBBB BBAAAABBBBBBBBBBBBBBBABBBBB BBAAAABBBBBBBBBBBBBBBABBBBB -EAAAADAADDDDDDDDDDAAADAAE- -EAAAADAADDDDDDDDDDAAADAAE- --EAAADAADDDDDDDDDDAAADAE-- --EAAADAADDDDDDDDDDAAADAE-- ---BAADAADDDDDDDDDDAAADB--- ----EADAADDDDDDDDDDAAEB---- -----EDAADDDDDDDDDDAE-B---- -----EBEEDDDDDDDDDDEE------ ------B--BBBBBBBBBB-------- --------------------------- --------------------------- 
BBBBBBBBBBBBBBBBBBBBBBBBBBB BBABADBBBBBBBBBBBBBBBABBBBB BBABADBBBBBBBBBBBBBBBABBBBB --EAADAAAADAAAAAGADAAAADAE- --EAADAAAADAAAAAGADAAAADEE- ---EADAAAADAAAAAGADAAAAB--- ---EADAAAADAAAAAGADAAAAB--- ---BADAAAADAAAAAGADAAABB--- ----EDAAAADAAAAAGADAAE----- -----BEEAADAAAAAGADAE------ --------EEDEEEEEEEDEE------ ----------B-------B-------- --------------------------- --------------------------- 
-BBBBBBBBBBBBBBBBBBBBBBBBB- -BDBDABBBBBBBBBBBBBBBAAADB- -BBBDABBBBBBBBBBBBBBBAAADB- ---EDAAAADAAAAAAAAADAAAAB-- ---EDAAAADAAAAAAAAADAAAEB-- ---BBAAAADAAAAAAAAADAAE-B-- ---BBAAAADAAAAAAAAADAAE---- ---BBAAAADAAAAAAAAADAAB---- ----BEEAADAAAAAAAAADEE----- ----B--EABEEEEEEEEEB------- --------EBEEEEEEEEEB------- --------------------------- --------------------------- --------------------------- 
--BBBBBBBBBBBBBBBBBBBBBBB-- --BBABBBBBBBBBBBBBBBBAAAB-- --BBABBBBBBBBBBBBBBBBAAAB-- ---BEBAADAAAAAAAAAAADAAE--- ---BEBAADAAAAAAAAAAADAAE--- ---B-EAADAAAAAAAAAAADAE---- -----EAADAAAAAAAAAAADAE---- -----BAADAAAAAAAAAAADBB---- ------EEDEEEEEEEEEEEB------ --------B-----------B------ --------------------------- --------------------------- --------------------------- --------------------------- 
---BBBBBBBBBBBBBBBBBBBBB--- ---BDBBBBBBBBBBBBBBBBDAB--- ---BBBBBBBBBBBBBBBBBBDAB--- -----EADAAAAAAAAAAAAADE---- -----EADAAAAAAAAAAAAADE---- ------EDAAAAAAAAAAAAAB----- ------EDAAAAAAAAAAAAAB----- ------BDAAAAAAAABBBBBB----- -------BEEEEEEEE----------- -------B------------------- --------------------------- --------------------------- --------------------------- --------------------------- 
----BBBBBBBBBBBBBBBBBBB---- ----BBBBBBBBBBBBBBBBBAB---- ----BBBBBBBBBBBBBBBBBAB---- -----EDAAAAAAAAAAAAAAEB---- -----EDAAAAAAAAAAAAAAEB---- ------BEEEEEEEEEEEEEE-B---- ------BEEEEEEEEEEEEEE------ ------BBBBBBBBBBB---------- --------------------------- --------------------------- --------------------------- --------------------------- --------------------------- --------------------------- 
-----BBBBBBBBBBBBBBBBB----- -----BBBBBBBBBBBBBBBBB----- -----BBBBBBBBBBBBBBBBB----- -----BEEEEEEEEEEEEEEE------ -----BEEEEEEEEEEEEEEE------ -----B--------------------- --------------------------- --------------------------- --------------------------- --------------------------- --------------------------- --------------------------- --------------------------- --------------------------- 
------BBBBBBBBBBBBBBB------ ------BBBBBBBBBBBBBBB------ ------BBBBBBBBBBBBBBB------ --------------------------- --------------------------- --------------------------- --------------------------- --------------------------- --------------------------- --------------------------- --------------------------- --------------------------- --------------------------- --------------------------- 
