model
size = 27 14 26, scale = 0.05, origin = -y
material 
  colors = A:#09F B:#FC0 C:#EEE D:#CFF E:#9CF F:#69C G:#BBB
voxels
-----BBBBBBBBBBBBBBBBB----- -----BBBBBBBBBBBBBBBBB----- -----BBBBBBBBBBBBBBBBB----- ------B-------------------- ------B-------------------- ------B-------------------- --------------------------- --------------------------- --------------------------- --------------------------- --------------------------- --------------------------- --------------------------- --------------------------- 
----BBBBBBBBBBBBBBBBBBB---- ----BACAAAAAAAAAAAAAABB---- ----BACAAAAAAAAAAAAAABB---- -----CCCCCCCCCCCCCCCCB----- -----CCCCCCCCCCCCCCCCB----- ------BB-------------B----- -------B------------------- -------B------------------- --------------------------- --------------------------- --------------------------- --------------------------- --------------------------- --------------------------- 
---BBBBBBBBBBBBBBBBBBBBB--- ---BAAACAAAAAAAAAAAACABB--- ---BAAACAAAAAAAAAAAACABB--- ----CAACAAAAAAAAAAAACC----- ----CAACAAAAAAAAAAAACC----- -----CACCCCCCCCCCCCCB------ -----CCCCCCCCCCCCCCCB------ -----BBBBBBBBBBBBBBBB------ --------------------------- --------------------------- --------------------------- --------------------------- --------------------------- --------------------------- 
--BBBBBBBBBBBBBBBBBBBBBBB-- --BAAAAACAAAAAAAAAACAAACB-- --BAAAAACAAAAAAAAAACAAABB-- ---CAAAACAAAAAAAAAACAAC---- ---CAAAACAAAAAAAAAACAAC---- ----CAAACAAAAAAAAAACAC----- ----CCCCCAAAAAAAAAACAC----- ----B---BCCCCCCCCCCCCB----- --------B----------B------- --------------------------- --------------------------- --------------------------- --------------------------- --------------------------- 
-BBBBBBBBBBBBBBBBBBBBBBBBB- -BACAAAAACAAAAAAAACAAAAACB- -BACAAAAACAAAAAAAACAAAAACB- --BCAAAAACAAAAAAAACAAAACB-- --BCAAAAACAAAAAAAACAAAACB-- --BBAAAAACAAAAAAAACAAAC-B-- ---BCCCCCCAAAAAAAACAAAC---- ---B-----BAAAAAAAACACCB---- ---------BCCCCCCCCBC------- ---------B--------B-------- ------------------B-------- --------------------------- --------------------------- --------------------------- 
BBBBBBBBBBBBBBBBBBBBBBBBBBB BAAACAAAACCCCCCCCCAAAABBBBB BAAACAAAACCCCCCCCCAAAABBBBB -CAACAAAACCCCCCCCCAAAAACC-- -CAACAAAACCCCCCCCCAAAAACC-- --CACAAAACCCCCCCCCAAAAAB--- --CACAAAACCCCCCCCCAAAAAB--- ---BBCCCCCCCCCCCCCAAAACB--- ----BCCCCCCCCCCCCCAACC----- ----B----BCCCCCCCBAC------- ---------BCCCCCCCBCC------- -----------------B--------- --------------------------- --------------------------- 
BBBBBBBBBBBBBBBBBBBBBBBBBBB BAAAACAACEDDDDDDEECAAABBBBB BAAAACAACEDDDDDDEECAAABBBBB -CAAACAACEDDDDDDEECAAACAAC- -CAAACAACEDDDDDDEECAAACAAC- --CAACAACEDDDDDDEECAAACAC-- --CAACAACEDDDDDDEECAAACAC-- ---BACAACEDDDDDDEECAAACBB-- ----CCAACEDDDDDDEECAACB---- -----BCCCEDDDDDDEECAC-B---- -----BCCCEDDDDDDEECCC------ ---------BBBBBBBBBB-------- --------------------------- --------------------------- 
BBBBBBBBBBBBBBBBBBBBBBBBBBB BAAAAACCEEDDDDDDDEECACBBBBB BAAAAACCEEDDDDDDDEECACBBBBB -CAAAACCEEDDDDDDDEECACAAAC- -CAAAACCEEDDDDDDDEECACAAAC- --CAAACCEEDDDDDDDEECACAAC-- --CAAACCEEDDDDDDDEECACAAC-- ---BAACCEEDDDDDDDEECACAAB-- ----CACCEEDDDDDDDEECACCC--- -----CCCEEDDDDDDDEECAB----- -----CCCEEDDDDDDDEECCB----- ------BBBCDDDDDDECBB------- ----------CCCCCCC---------- --------------------------- 
BBBBBBBBBBBBBBBBBBBBBBBBBBB BAAAAAACEDDDDDDDDDECCABBBBB BAAAAAACEDDDDDDDDDECCABBBBB -CAAAAACEDDDDDDDDDECCAAAAC- -CAAAAACEDDDDDDDDDECCAAAAC- --CAAAACEDDDDDDDDDECCAAAC-- --CAAAACEDDDDDDDDDECCAAAC-- ---BAAACEDDDDDDDDDECCAAAB-- ----CAACEDDDDDDDDDECCACC--- -----CACEDDDDDDDDDECCC----- -----CCCEDDDDDDDDDECCC----- -------BEDDDDDDDDECBB------ --------CCDDDDDDCC--------- ----------CCCCCC----------- 
BBBBBBBBBBBBBBBBBBBBBBBBBBB BAAAAAFCDDDDDDDDDDDCAABBBBB BAAAAAFCDDDDDDDDDDDCAABBBBB -CAAAAFCDDDDDDDDDDDCAAAAAC- -CAAAAFCDDDDDDDDDDDCAAAAAC- --CAAAFCDDDDDDDDDDDCAAAAC-- --CAAAFCDDDDDDDDDDDCAAAAC-- ---BAAFCDDDDDDDDDDDCAAAAB-- ----CAFCDDDDDDDDDDDCAACC--- -----CFCDDDDDDDDDDDCAC----- -----CCCDDDDDDDDDDDCCC----- -------BDDDDDDDDDDDB------- --------CDDDDDDDDCC-------- ---------CCCCCCCC---------- 
BBBBBBBBBBBBBBBBBBBBBBBBBBB BAAAAAACDDDDCCCCDDDCAABBBBB BAAAAAACDDDDEEEEDDDCAABBBBB -CAAAAACDDDDEEEEDDDCAAAAAC- -CAAAAACDDDDEEEEDDDCAAAAAC- --CAAAACDDDDEEEEDDDCAAAAC-- --CAAAACDDDDEEEEDDDCAAAAC-- ---BAAACDDDDEEEEDDDCAAAAB-- ----CAACDDDDEEEEDDDCAACC--- -----CACDDDDEEEEDDDCAC----- -----CCCDDDDEEEEDDDCCC----- -------BDDDDEEEEDDDB------- --------CDDDEEEEDDC-------- ---------CCCCGGCCC--------- 
BBBBBBBBBBBBBBBBBBBBBBBBBBB BAAAAAACDDDCCCCCDDDCAABBBBB BAAAAAACDDDEEEEEDDDCAABBBBB -CAAAAACDDDEEEEEDDDCAAAAAC- -CAAAAACDDDEEEEEDDDCAAAAAC- --CAAAACDDDEEEEEDDDCAAAAC-- --CAAAACDDDEEEEEDDDCAAAAC-- ---BAAACDDDEEEEEDDDCAAAAB-- ----CAACDDDEEEEEDDDCAACC--- -----CACDDDEEEEEDDDCAC----- -----CCCDDDEEEEEDDDCCC----- -------BDDDEEEEEDDDB------- --------CDDEEEEEDDC-------- ---------CCCGGGCCC--------- 
BBBBBBBBBBBBBBBBBBBBBBBBBBB BAAAAAACDDBCCCCCDDDCAABBBBB BAAAAAACDDDEEEEEDDDCAABBBBB -CAAAAACDDDEEEEEDDDCAAAAAC- -CAAAAACDDDEEEEEDDDCAAAAAC- --CAAAACDDDEEEEEDDDCAAAAC-- --CAAAACDDDEEEEEDDDCAAAAC-- ---BAAACDDDEEEEEDDDCAAAAB-- ----CAACDDDEEEEEDDDCAACC--- -----CACDDDEEEEEDDDCAC----- -----CCCDDDEEEEEDDDCCC----- -------BDDDEEEEEDDDB------- --------CDDEEEEEDDC-------- ---------CCCCGCCCC--------- 
BBBBBBBBBBBBBBBBBBBBBBBBBBB BAAAAAACDDBCCCCCDDDCAABBBBB BAAAAAACDDDEEEEEDDDCAABBBBB -CAAAAACDDDEEEEEDDDCAAAAAC- -CAAAAACDDDEEEEEDDDCAAAAAC- --CAAAACDDDEEEEEDDDCAAAAC-- --CAAAACDDDEEEEEDDDCAAAAC-- ---BAAACDDDEEEEEDDDCAAAAB-- ----CAACDDDEEEEEDDDCAACC--- -----CACDDDEEEEEDDDCAC----- -----CCCDDDEEEEEDDDCCC----- -------BDDDEEEEEDDDB------- --------CDDEEEEEDDC-------- ---------CCCCCCCCC--------- 
BBBBBBBBBBBBBBBBBBBBBBBBBBB BAAAAAACDDDDDDDDDDDCAABBBBB BAAAAAACDDDDDDDDDDDCAABBBBB -CAAAAACDDDDDDDDDDDCAAAAAC- -CAAAAACDDDDDDDDDDDCAAAAAC- --CAAAACDDDDDDDDDDDCAAAAC-- --CAAAACDDDDDDDDDDDCAAAAC-- ---BAAACDDDDDDDDDDDCAAAAB-- ----CAACDDDDDDDDDDDCAACC--- -----CACDDDDDDDDDDDCAC----- -----CCCDDDDDDDDDDDCCC----- -------BDDDDDDDDDDDB------- --------CDDDDDDDDDC-------- ---------CCCCCCCCC--------- 
BBBBBBBBBBBBBBBBBBBBBBBBBBB BAAAAAACEDDDDDDDDDDCAABBBBB BAAAAAACEDDDDDDDDDDCAABBBBB -CAAAAACEDDDDDDDDDDCAAAAAC- -CAAAAACEDDDDDDDDDDCAAAAAC- --CAAAACEDDDDDDDDDDCAAAAC-- --CAAAACEDDDDDDDDDDCAAAAC-- ---BAAACEDDDDDDDDDDCAAAAB-- ----CAACEDDDDDDDDDDCAACC--- -----CACEDDDDDDDDDDCAC----- -----CCCEDDDDDDDDDDCCC----- -------BEDDDDDDDDDDB------- --------CDDDDDDDDDC-------- ---------CCCCCCCCC--------- 
BBBBBBBBBBBBBBBBBBBBBBBBBBB BAAAAAACEEDDDDDDDDECAABBBBB BAAAAAACEEDDDDDDDDECAABBBBB -CAAAAACEEDDDDDDDDECAAAAAC- -CAAAAACEEDDDDDDDDECAAAAAC- --CAAAACEEDDDDDDDDECAAAAC-- --CAAAACEEDDDDDDDDECAAAAC-- ---BAAACEEDDDDDDDDECAAAAB-- ----CAACEEDDDDDDDDECAACC--- -----CACEEDDDDDDDDECAC----- -----CCCEEDDDDDDDDECCC----- -------BEEDDDDDDDDEB------- --------CCCDDDDDDCC-------- -----------CCCCCC---------- 
BBBBBBBBBBBBBBBBBBBBBBBBBBB BAAAAAACCEEDDDDDDECCCCBBBBB BAAAAAACCEEDDDDDDECCCCBBBBB -CAAAAACCEEDDDDDDECCCCAAAC- -CAAAAACCEEDDDDDDECCCCAAAC- --CAAAACCEEDDDDDDECCCCAAC-- --CAAAACCEEDDDDDDECCCCAAC-- ---BAAACCEEDDDDDDECCCCAAB-- ----CAACCEEDDDDDDECCCCCC--- -----CACCEEDDDDDDECCCB----- -----CCCCEEDDDDDDECCCB----- -------BBCEDDDDDDEBBB------ ----------CCCCCCCC--------- --------------------------- 
BBBBBBBBBBBBBBBBBBBBBBBBBBB BBAAAABBBBBBBBBBBBBBBABBBBB BBAAAABBBBBBBBBBBBBBBABBBBB -CAAAACAACCCCCCCCCCAAACAAC- -CAAAACAACCCCCCCCCCAAACAAC- --CAAACAACCCCCCCCCCAAACAC-- --CAAACAACCCCCCCCCCAAACAC-- ---BAACAACCCCCCCCCCAAACB--- ----CACAACCCCCCCCCCAACB---- -----CCAACCCCCCCCCCAC-B---- -----CBCCCCCCCCCCCCCC------ ------B--BBBBBBBBBB-------- --------------------------- --------------------------- 
BBBBBBBBBBBBBBBBBBBBBBBBBBB BBABACBBBBBBBBBBBBBBBABBBBB BBABACBBBBBBBBBBBBBBBABBBBB --CAACAAAACAAAAAFACAAAACAC- --CAACAAAACAAAAAFACAAAACCC- ---CACAAAACAAAAAFACAAAAB--- ---CACAAAACAAAAAFACAAAAB--- ---BACAAAACAAAAAFACAAABB--- ----CCAAAACAAAAAFACAAC----- -----BCCAACAAAAAFACAC------ --------CCCCCCCCCCCCC------ ----------B-------B-------- --------------------------- --------------------------- 
-BBBBBBBBBBBBBBBBBBBBBBBBB- -BCBCABBBBBBBBBBBBBBBAAACB- -BBBCABBBBBBBBBBBBBBBAAACB- ---CCAAAACAAAAAAAAACAAAAB-- ---CCAAAACAAAAAAAAACAAACB-- ---BBAAAACAAAAAAAAACAAC-B-- ---BBAAAACAAAAAAAAACAAC---- ---BBAAAACAAAAAAAAACAAB---- ----BCCAACAAAAAAAAACCC----- ----B--CABCCCCCCCCCB------- --------CBCCCCCCCCCB------- --------------------------- --------------------------- --------------------------- 
--BBBBBBBBBBBBBBBBBBBBBBB-- --BBABBBBBBBBBBBBBBBBAAAB-- --BBABBBBBBBBBBBBBBBBAAAB-- ---BCBAACAAAAAAAAAAACAAC--- ---BCBAACAAAAAAAAAAACAAC--- ---B-CAACAAAAAAAAAAACAC---- -----CAACAAAAAAAAAAACAC---- -----BAACAAAAAAAAAAACBB---- ------CCCCCCCCCCCCCCB------ --------B-----------B------ --------------------------- --------------------------- --------------------------- --------------------------- 
---BBBBBBBBBBBBBBBBBBBBB--- ---BCBBBBBBBBBBBBBBBBCAB--- ---BBBBBBBBBBBBBBBBBBCAB--- -----CACAAAAAAAAAAAAACC---- -----CACAAAAAAAAAAAAACC---- ------CCAAAAAAAAAAAAAB----- ------CCAAAAAAAAAAAAAB----- ------BCAAAAAAAABBBBBB----- -------BCCCCCCCC----------- -------B------------------- --------------------------- --------------------------- --------------------------- --------------------------- 
----BBBBBBBBBBBBBBBBBBB---- ----BBBBBBBBBBBBBBBBBAB---- ----BBBBBBBBBBBBBBBBBAB---- -----CCAAAAAAAAAAAAAACB---- -----CCAAAAAAAAAAAAAACB---- ------BCCCCCCCCCCCCCC-B---- ------BCCCCCCCCCCCCCC------ ------BBBBBBBBBBB---------- --------------------------- --------------------------- --------------------------- --------------------------- --------------------------- --------------------------- 
-----BBBBBBBBBBBBBBBBB----- -----BBBBBBBBBBBBBBBBB----- -----BBBBBBBBBBBBBBBBB----- -----BCCCCCCCCCCCCCCC------ -----BCCCCCCCCCCCCCCC------ -----B--------------------- --------------------------- --------------------------- --------------------------- --------------------------- --------------------------- --------------------------- --------------------------- --------------------------- 
------BBBBBBBBBBBBBBB------ ------BBBBBBBBBBBBBBB------ ------BBBBBBBBBBBBBBB------ --------------------------- --------------------------- --------------------------- --------------------------- --------------------------- --------------------------- --------------------------- --------------------------- --------------------------- --------------------------- --------------------------- 
