model
size = 8 32 8, scale = 0.05, origin = -y
material 
  colors = A:#630 B:#222 C:#633 D:#DDD E:#EEE F:#BBB G:#111
voxels
3-3C2(5-C2A)9(5-3A)5-2AC5-A2C8(5-3A)5-3C76-5C3-A-C11(-A3-A-B)-C3(3-A-B-A)2(3-C-B-A)4(3-A-B-A)3-C-B-C5-3(B7-)B6-DBD4-2FB2F3-2DB2D3-2FB2F5-B4-7C4(-A5-A)2(-C5-A)15(-A5-A)-C5-C44-2(E7-)E12-7C-A-G-B4(2(-A)2(-B))-A-C15(2(-B)2(-A))2(-B)-A-C2(-B)-C3-B-B5-B-B4-2B-B4-B2-B4-B-DBD3-B2DB2E2-2(B2D)2-B2DB2E2(2-B)3-7C4(-A5-A)2(-A5-C)11(-A5-A)-C5-A2(-A5-C)-A5-A-C5-C33-D2-D4-E2-E4-D2-D4-E2-E13-5C10(3-A-B-A)2(3-A-B-C)5(3-A-B-A)2(3-C-B-A)2(3-A-B-A)3-C-B-C5-4(B7-)B3-E3-B3-D3-B3-E3-B7-B6-3C5(5-3A)5-2C2(A5-AC)A10(5-3A)5-2AC2(5-3A)5-3C38-E7-D7-E7-D239-E7-D7-E11-
