model
size = 31 3 9, scale = 0.05, origin = -y
material 
  colors = A:#630 B:#633 C:#111
voxels
A-----------------------------A CCCCCCCCCCCCCCCCCCCCCCCCCCCCCCC A-----------------------------A 
-AA-------------------------AA- BAA-------------------------AAA -AA-------------------------AA- 
-AA-------------------------BA- -BA-------------------------BA- -AB-------------------------AA- 
--AAA---------------------AAA-- --AAB---------------------ABB-- --ABB---------------------BAB-- 
---ABAB-----------------BAAA--- ---BBBA-----------------AAAB--- ---AAAB-----------------ABAA--- 
-----AABB-------------BBAA----- -----BAAA-------------AAAA----- -----AAAA-------------AAAA----- 
-------AAAAA-------AAABB------- -------BAAAA-------BBBAB------- -------BBAAA-------AAAAA------- 
---------AAAA-A-A-AAAA--------- ---------BAAAABBAAABAA--------- ---------AAAA-B-A-ABAA--------- 
------------A-B-A-A------------ ------------ABBAABB------------ ------------A-A-A-B------------ 
