model
size = 12 32 19, scale = 0.05, origin = -y
material 
  colors = A:#FC0 B:#FC6 C:#009 D:#E00
voxels
177-3(A11-)A347-2(A11-)AB10-A11-A35-2(B11-)B47-B11-B10-B204-A11-AB10-AD10-AB9-3A9-A-A9-ABA10-A23-A10-ABA9-A-A9-ABA10-2(A9-)2ABA8-B-A9-2A181-BAB10-B11-AB10-A11-A35-2(B11-)B47-B11-B6-B3-B7-A11-B112-3(A11-)A22-B-B10-3(A11-)A137-B9-A13-B113-2(A11-)2A10-A10-BAB195-2B8-ABA11-2B17-5(A11-)A35-A11-2A10-AC10-BA10-A206-A-A30-A11-2A10-3A9-2A10-A11-A34-BAB10-B11-2A10-A11-A206-ABA30-2A10-ACA9-ADC9-ACA9-2A10-A11-A10-B-B10-3(A11-)A207-B11-A11-B19-3A9-ADC9-AD10-ADC9-3A9-B10-BAB266-B23-B19-2A10-ACA9-ADC9-ACA9-2A10-A11-A10-B-B10-3(A11-)A207-B11-A11-B19-A11-2A10-3A9-2A10-A11-A34-BAB10-B11-2A10-A11-A206-ABA30-5(A11-)A35-A11-2A10-AC10-BA10-A206-A-A126-2(A11-)2A10-A10-BAB195-2B8-ABA11-2B113-3(A11-)A22-B-B10-3(A11-)A137-B9-A13-B184-BAB10-B11-AB10-A11-A35-2(B11-)B47-B11-B6-B3-B7-A11-B184-A11-AB10-AD10-AB9-3A9-A-A9-ABA10-A23-A10-ABA9-A-A9-ABA10-2(A9-)2ABA8-B-A9-2A182-2(A11-)AB10-A11-A35-2(B11-)B47-B11-B10-B204-3(A11-)A170-
