model
size = 32 6 11, scale = 0.05, origin = -y
material 
  colors = A:#FC0 B:#BBB C:#EEE D:#C00 E:#DDD
voxels
33-3(A7-A23-)A7-A87-A7-A22-10A22-3A5D2A23-9A55-A7-A23-9A2(22-10A)23-9A2(23-A7-A)4(22-10A)2(23-A7-A)22-3A5D2A22-D9C13B9-D9CB11E5B5-3A5DAC19B4-A7-A23-A7-A22-ACA5DA15C8-D9C13B5C4-D9C17B3C2-ACA5DAC19B3C-A7-A23-A7-A22-3A5D2A22-D9C13B9-D9CB11E5B5-3A5DAC19B4-A7-A23-A7-A4(22-10A)2(23-A7-A)23-9A2(22-10A)23-9A23-A7-A55-A7-A22-10A22-3A5D2A23-9A87-3(A7-A23-)A7-A54-
