model
size = 6 29 21, scale = 0.05, origin = -y
material 
  colors = A:#CB2929 B:#E82C2C C:#AE2A2A
voxels
------ ------ ------ ------ ------ ------ ------ ------ ------ ------ ------ ------ --AA-- ------ ------ ------ ------ ------ ------ ------ ------ ------ ------ ------ ------ ------ ------ ------ ------ 
------ ------ ------ ------ ------ ------ ------ ------ ------ ------ ------ ------ -AAAA- --BB-- --BB-- --BB-- --BB-- --BB-- --BB-- --BB-- --BB-- --BB-- --BB-- --BB-- --BB-- --BB-- --BB-- --BB-- --BB-- 
------ ------ ------ ------ ------ ------ ------ ------ ------ ------ ------ ------ ------ AAAAAA -BAAB- -BAAB- -BAAB- -BAAB- -BAAB- -BAAB- -BAAB- -BAAB- -BAAB- -BAAB- -BAAB- -BAAB- --AA-- ------ ------ 
------ ------ ------ ------ ------ ------ ------ ------ ------ ------ ------ ------ ------ AAAAAA -AAAA- -CAAC- -CAAC- -CAAC- -CAAC- -CAAC- -CAAC- -CAAC- -CAAC- -CAAC- -AAAA- --AA-- ------ ------ ------ 
------ ------ ------ ------ ------ ------ ------ ------ ------ ------ ------ ------ ------ -AAAA- AAAAAA -AAAA- -AAAA- -BAAB- -AAAA- -AAAA- -AAAA- --AA-- -AAAA- -AAAA- --AA-- ------ ------ ------ ------ 
------ ------ ------ ------ ------ ------ ------ ------ ------ ------ ------ ------ ------ ------ AAAAAA AAAAAA -BAAB- --AA-- -BAAB- -BAAB- --AA-- --AA-- -AAAA- --AA-- ------ ------ ------ ------ ------ 
------ ------ ------ ------ ------ ------ ------ ------ ------ ------ ------ ------ ------ ------ AAAAAA AAAAAA -BAAB- -BAAB- -BAAB- -BAAB- -BAAB- -AAAA- -AAAA- ------ ------ ------ ------ ------ ------ 
------ ------ ------ ------ ------ ------ ------ ------ ------ ------ ------ ------ ------ ------ AAAAAA AAAAAA -BAAB- -BAAB- -BAAB- -BAAB- -BAAB- -BAAB- --AA-- ------ ------ ------ ------ ------ ------ 
------ ------ ------ ------ ------ ------ ------ ------ ------ ------ ------ ------ ------ ------ AAAAAA AAAAAA -CAAC- -BAAB- -AAAA- --AA-- -BAAB- -AAAA- ------ ------ ------ ------ ------ ------ ------ 
------ ------ ------ ------ ------ ------ ------ ------ ------ ------ ------ ------ ------ ------ AAAAAA -BAAB- -BAAB- -CAAC- -AAAA- -BAAB- -AAAA- -AAAA- ------ ------ ------ ------ ------ ------ ------ 
------ ------ ------ ------ ------ ------ ------ ------ ------ ------ ------ ------ ------ ------ AAAAAA -CAAC- -BAAB- -BAAB- -CAAC- -BAAB- -AAAA- --AA-- ------ ------ ------ ------ ------ ------ ------ 
------ ------ ------ ------ ------ ------ ------ ------ ------ ------ ------ ------ ------ AAAAAA -BAAB- -BAAB- -CAAC- -BAAB- -BAAB- -CAAC- -AAAA- ------ ------ ------ ------ ------ ------ ------ ------ 
------ ------ ------ ------ ------ ------ ------ ------ ------ ------ ------ ------ ------ ABAABA -BAAB- -BAAB- -BAAB- -CAAC- -BAAB- -BAAB- -AAAA- ------ ------ ------ ------ ------ ------ ------ ------ 
------ ------ ------ ------ ------ ------ ------ ------ ------ ------ ------ ------ ABAABA -BAAB- -BAAB- -BAAB- -BAAB- -BAAB- -CAAC- -AAAA- --AA-- ------ ------ ------ ------ ------ ------ ------ ------ 
------ ------ ------ ------ ------ ------ ------ ------ ------ ------ ------ ABAABA -BAAB- -BAAB- -BAAB- --AA-- --AA-- -BAAB- -AAAA- -AAAA- ------ ------ ------ ------ ------ ------ ------ ------ ------ 
--AA-- -AAAA- AAAAAA ------ ------ ------ ------ ------ ------ AAAAAA ACAACA -CAAC- -CAAC- -CAAC- -BAAB- -BAAB- -BAAB- --AA-- -AAAA- --AA-- ------ ------ ------ ------ ------ ------ ------ ------ ------ 
--AA-- -AAAA- -AAAA- AAAAAA AAAAAA AAAAAA AAAAAA AAAAAA AAAAAA -CAAC- -BAAB- -BAAB- -BAAB- -BAAB- -CAAC- -BAAB- --AA-- -AAAA- -AAAA- ------ ------ ------ ------ ------ ------ ------ ------ ------ ------ 
------ --AA-- -AAAA- -AAAA- -BAAB- -BAAB- -BAAB- -BAAB- -BAAB- -BAAB- -CAAC- -CAAC- -CAAC- -CAAC- -BAAB- -CAAC- -AAAA- -AAAA- --AA-- ------ ------ ------ ------ ------ ------ ------ ------ ------ ------ 
------ ------ ------ --AA-- -AAAA- -AAAA- -AAAA- -AAAA- -CAAC- -CAAC- -BAAB- -BAAB- -BAAB- -BAAB- -CAAC- -AAAA- -AAAA- --AA-- ------ ------ ------ ------ ------ ------ ------ ------ ------ ------ ------ 
------ ------ ------ ------ ------ --AA-- -AAAA- -AAAA- -AAAA- --AA-- --AA-- --AA-- -AAAA- -AAAA- -AAAA- --AA-- ------ ------ ------ ------ ------ ------ ------ ------ ------ ------ ------ ------ ------ 
------ ------ ------ ------ ------ ------ ------ --AA-- -AAAA- -AAAA- -AAAA- -AAAA- -AAAA- --AA-- ------ ------ ------ ------ ------ ------ ------ ------ ------ ------ ------ ------ ------ ------ ------ 
