model
size = 12 28 24, scale = 0.05, origin = -y
material 
  colors = A:#FFF B:#9300FF C:#FF00E9 D:#FFFEFE E:#000 F:#FFF300 G:#F00
voxels
------------ ------------ ------------ ------------ -----------A -----------A -----------A -----------A -----------A -----------A -----------A -----------A -----------A ------------ ------------ ------------ ------------ ------------ ------------ ------------ ------------ ------------ ------------ ------------ ------------ ------------ ------------ ------------ 
------------ ------------ ------------ ------------ -----------A -----------A -----------A -----------A -----------A -----------A -----------A -----------A -----------A ------------ ------------ ------------ ------------ ------------ ------------ ------------ ------------ ------------ ------------ ------------ ------------ ------------ ------------ ------------ 
------------ ------------ ------------ ------------ -----------A -----------A -----------A -----------A -----------A -----------A -----------A -----------A -----------A ------------ ------------ ------------ ------------ ------------ ------------ ------------ ------------ ------------ ------------ ------------ ------------ ------------ ------------ ------------ 
------------ ------------ ------------ ------------ -----------A -----------A -----------A -----------A -----------E -----------A -----------A -----------A -----------A ------------ ------------ ------------ ------------ ------------ ------------ ------------ ------------ ------------ ------------ ------------ ------------ ------------ ------------ ------------ 
------------ ------------ ------------ ------------ -----------A -----------A -----------A -----------E -----------E -----------E -----------A -----------A -----------A ------------ ------------ ------------ ------------ ------------ ------------ ------------ ------------ ------------ ------------ ------------ ------------ ------------ ------------ ------------ 
------------ ------------ ------------ ------------ -----------A -----------A -----------E -----------E -----------E -----------E -----------E -----------A -----------A ------------ ------------ ------------ ------------ ------------ ------------ ------------ ------------ ------------ ------------ ------------ ------------ ------------ ------------ ------------ 
------------ ------------ ------------ ------------ -----------A -----------E -----------E -----------A -----------E -----------A -----------E -----------E -----------A ------------ ------------ ------------ ------------ ------------ ------------ ------------ ------------ ------------ ------------ ------------ ------------ ------------ ------------ ------------ 
------------ ------------ ------------ ------------ -----------A -----------E -----------A -----------A -----------E -----------A -----------A -----------E -----------A ------------ ------------ ------------ ------------ ------------ ------------ ------------ ------------ ------------ ------------ ------------ ------------ ------------ ------------ ------------ 
------------ ------------ ------------ ------------ -----------A -----------A -----------A -----------A -----------E -----------A -----------A -----------A -----------A ------------ ------------ ------------ ------------ ------------ ------------ ------------ ------------ ------------ ------------ ------------ ------------ ------------ ------------ ------------ 
--DDD------- --DDD------- --DDD------- ---D-------- ---D-------A -----------A -----------A -----------A -----------E -----------A -----------A -----------A -----------A ------------ ------------ ------------ ------------ ------------ ------------ ------------ ------------ ------------ ------------ ------------ ------------ ------------ ------------ ------------ 
-B---B------ -B---B------ -B---B------ -BBBBB------ -BBBBB-----A -BBBBB-----A --BBB------A --BBB------A --BBB------E --BBB------A --BBB------A --BBB------A ---B-------A ---B-------- ------------ ------------ ------------ ------------ ------------ ------------ ------------ ------------ ------------ ------------ ------------ ------------ ------------ ------------ 
D-----D----- D-----D----- D-----D----- -B---B------ -B---B-----A -B---B-----A -B---B-----A -B---B-----A -B---B-----E -B---B-----A -B---B-----A -B---B-----A --CCC------A --CCC------- --CCC------- --CCC------- --CCC------- --CCC------- --CCC------- ---C-------- ---C-------- ---C-------- ---C-------- ------------ ------------ ------------ ------------ ------------ 
D-----D----- D-----D----- D-----D----- DB---BD----- DB---BD----A -B---B-----A -B---B-----A -B---B-----A -B---B-----E -B---B-----A -B---B-----A -B---B-----A -BC-CB-----A -BC-CB-----G --C-C------G --C-C------F --C-C------F --C-C------F --C-C------F --C-C------F --C-C------F --C-C------F --C-C------F ---C-------F ---C------F- ---F-----F-- ---F----F--- ---FFFFF---- 
D-----D----- D-----D----- D-----D----- -B---B------ -B---B-----A -B---B-----A -B---B-----A -B---B-----A -B---B-----E -B---B-----A -B---B-----A -B---B-----A --CCC------A --CCC------- --CCC------- --CCC------- --CCC------- --CCC------- --CCC------- ---C-------- ---C-------- ---C-------- ---C-------- ------------ ------------ ------------ ------------ ------------ 
-B---B------ -B---B------ -B---B------ -BBBBB------ -BBBBB-----A -BBBBB-----A --BBB------A --BBB------A --BBB------E --BBB------A --BBB------A --BBB------A ---B-------A ---B-------- ------------ ------------ ------------ ------------ ------------ ------------ ------------ ------------ ------------ ------------ ------------ ------------ ------------ ------------ 
--DDD------- --DDD------- --DDD------- ---D-------- ---D-------A -----------A -----------A -----------A -----------E -----------A -----------A -----------A -----------A ------------ ------------ ------------ ------------ ------------ ------------ ------------ ------------ ------------ ------------ ------------ ------------ ------------ ------------ ------------ 
------------ ------------ ------------ ------------ -----------A -----------E -----------A -----------A -----------E -----------A -----------A -----------E -----------A ------------ ------------ ------------ ------------ ------------ ------------ ------------ ------------ ------------ ------------ ------------ ------------ ------------ ------------ ------------ 
------------ ------------ ------------ ------------ -----------A -----------E -----------E -----------A -----------E -----------A -----------E -----------E -----------A ------------ ------------ ------------ ------------ ------------ ------------ ------------ ------------ ------------ ------------ ------------ ------------ ------------ ------------ ------------ 
------------ ------------ ------------ ------------ -----------A -----------A -----------E -----------E -----------E -----------E -----------E -----------A -----------A ------------ ------------ ------------ ------------ ------------ ------------ ------------ ------------ ------------ ------------ ------------ ------------ ------------ ------------ ------------ 
------------ ------------ ------------ ------------ -----------A -----------A -----------A -----------E -----------E -----------E -----------A -----------A -----------A ------------ ------------ ------------ ------------ ------------ ------------ ------------ ------------ ------------ ------------ ------------ ------------ ------------ ------------ ------------ 
------------ ------------ ------------ ------------ -----------A -----------A -----------A -----------A -----------E -----------A -----------A -----------A -----------A ------------ ------------ ------------ ------------ ------------ ------------ ------------ ------------ ------------ ------------ ------------ ------------ ------------ ------------ ------------ 
------------ ------------ ------------ ------------ -----------A -----------A -----------A -----------A -----------A -----------A -----------A -----------A -----------A ------------ ------------ ------------ ------------ ------------ ------------ ------------ ------------ ------------ ------------ ------------ ------------ ------------ ------------ ------------ 
------------ ------------ ------------ ------------ -----------A -----------A -----------A -----------A -----------A -----------A -----------A -----------A -----------A ------------ ------------ ------------ ------------ ------------ ------------ ------------ ------------ ------------ ------------ ------------ ------------ ------------ ------------ ------------ 
------------ ------------ ------------ ------------ -----------A -----------A -----------A -----------A -----------A -----------A -----------A -----------A -----------A ------------ ------------ ------------ ------------ ------------ ------------ ------------ ------------ ------------ ------------ ------------ ------------ ------------ ------------ ------------ 
