model
size = 14 30 9, scale = 0.05, origin = -y
material 
  colors = A:#FFF B:#000 C:#847E87
voxels
-------------- -BBBBBBBBBBBB- CCCCCCCCCCCCCC CBCBBBBBBBBCBC CBCBBBBBBBBCBC CBCBBBBBBBBCBC CBCBBBBBBBBCBC CBCBBBBBBBBCBC CBCBBBBBBBBCBC CBCBBBBBBBBCBC CBCBBBAABBBCBC CBCBBBBBBBBCBC CBCCCCCCCCCCBC CBCCCCCCCCCCBC CBBBBBBBBBBBBC CBBBBBBBBBBBBC CBBBBBBBBBBBBC -CBBBBBBBBBBC- --CCCCCCCCCC-- -------------- -------------- -------------- -------------- -------------- -------------- -------------- -------------- -------------- -------------- -------------- 
-C----------C- BABBBBBBBBBBAB CAAAAAAAAAAAAC BAAAAAAAAAAAAB BAAAAAAAAAAAAB BAAAAAAAAAAAAB BAAAAAAAAAAAAB BAAAAAAAAAAAAB BAAAAAAAAAAAAB BAAAAAAAAAAAAB BAAAAAAAAAAAAB BAAAAAAAAAAAAB BAAAAAAAAAAAAB BAAAAAAAAAAAAB BAAAAAAAAAAAAB BAAAAAAAAAAAAB BAAAAAAAAAAABB -BAAAAAAAAAAB- --BBBBBBBBBB-- -------------- -------------- -------------- -------------- -------------- -------------- -------------- -------------- -------------- -------------- -------------- 
-------------- BBBBBBBBBBBBBB CAAAAAAAAAAAAC BAAAAAAAAAAAAB BAAAAAAAAAAAAB BAAAAAAAAAAAAB BAAAAAAAAAAAAB BAAAAAAAAAAAAB BAAAAAAAAAAAAB BAAAAAAAAAAAAB BAAAAAAAAAAAAB BAAAAAAAAAAAAB BAAAAAAAAAAAAB BAAAAAAAAAAAAB BAAAAAAAAAAAAB BAAAAAAAAAAAAB BAAAAAAAAAAAAB BAAAAAAAAAAABB -BAAAAAAAAABB- --BBBBBBBBBB-- -------------- -------------- -------------- -------------- -------------- -------------- -------------- -------------- -------------- -------------- 
-------------- BBBBBBBBBBBBBB CAAAAAAAAAAAAC BAAAAAAAAAAAAB BAAAAAAAAAAAAB BAAAAAAAAAAAAB BAAAAAAAAAAAAB BAAAAAAAAAAAAB BAAAAAAAAAAAAB BAAAAAAAAAAAAB BAAAAAAAAAAAAB BAAAAAAAAAAAAB BAAAAAAAAAAAAB BAAAAAAAAAAAAB BAAAAAAAAAAAAB BAAAAAAAAAAAAB BAAAAAAAAAAAAB BAAAAAAAAAAABB -BAAAAAAAAAAB- --BBBBBBBBBB-- -------------- -------------- -------------- -------------- -------------- -------------- -------------- -------------- -------------- -------------- 
-------------- BBBBBBBBBBBBBB CAAAAAAAAAAAAC AAAAAAAAAAAAAA BAAAAAAAAAAAAA AAAAAAAAAAAAAA AAAAAAAAAAAAAA AAAAAAAAAAAAAA AAAAAAAAAAAAAA AAAAAAAAAAAAAA AAAAAAAAAAAAAA AAAAAAAAAAAAAA AAAAAAAAAAAAAA AAAAAAAAAAAAAA AAAAAAAAAAAAAA AAAAAAAAAAAAAA AAAAAAAAAAAAAA AAAAAAAAAAAAAA -AAAAAAAAAAAA- --AAAAAAAAAA-- -------------- -------------- -------------- -------------- -------------- -------------- -------------- -------------- -------------- -------------- 
-------------- BBBBBBBBBBBBBB CAAAAAAAAAAAAC BAAAAAAAAAAAAB BAAAAAAAAAAAAB BAAAAAAAAAAAAB BAAAAAAAAAAAAB BAAAAAAAAAAAAB BAAAAAAAAAAAAB BAAAAAAAAAAAAB BAAAAAAAAAAAAB BAAAAAAAAAAAAB BAAAAAAAAAAAAB BAAAAAAAAAAAAB BAAAAAAAAAAAAB BAAAAAAAAAAAAB BAAAAAAAAAAAAB BAAAAAAAAAAABB -BAAAAAAAAABB- --BBBBBBBBBB-- -------------- -------------- -------------- -------------- -------------- -------------- -------------- -------------- -------------- -------------- 
-------------- BBBBBBBBBBBBBB CAAAAAAAAAAAAC BAAAAAAAAAAAAB BAAAAAAAAAAAAB BAAAAAAAAAAAAB BAAAAAAAAAAAAB BAAAAAAAAAAAAB BAAAAAAAAAAAAB BAAAAAAAAAAAAB BAAAAAAAAAAAAB BAAAAAAAAAAAAB BAAAAAAAAAAAAB BAAAAAAAAAAAAB BAAAAAAAAAAAAB BAAAAAAAAAAAAB BAAAAAAAAAAAAB BAAAAAAAAAAABB -BBAAAAAAAABB- --BBBBBBBBBB-- -------------- -------------- -------------- -------------- -------------- -------------- -------------- -------------- -------------- -------------- 
-------------- BBBBBBBBBBBBBB CAAAAAAAAAAAAC BAAAAAAAAAAAAB BAAAAAAAAAAAAB BAAAAAAAAAAAAB BAAAAAAAAAAAAB BAAAAAAAAAAAAB BAAAAAAAAAAAAB BAAAAAAAAAAAAB BAAAAAAAAAAAAB BAAAAAAAAAAAAB BAAAAAAAAAAAAB BAAAAAAAAAAAAB BAAAAAAAAAAAAB BAAAAAAAAAAAAB BAAAAAAAAAAAAB BABAAAAAAAAAAB -BBBBBBBBBBBB- --BBBBBBBBBB-- -------------- -------------- -------------- -------------- -------------- -------------- -------------- -------------- -------------- -------------- 
-C----------C- -BBBBBBBBBBBB- BCCCCCCCCCCCCB CBBBBBBBBBBBBC CBBBBBBBBBBBBC CBBBBBBBBBBBBC CBBBBBBBBBBBBC CBBBBBBBBBBBBC CBBBBBBBBBBBBC CBBBBBBBBBBBBC CBBBBBBBBBBBBC CBBBBBBBBBBBBC CBBBBBBBBBBBBC CBBBBBBBBBBBBC CBBBBBBBBBBBBC CBBBBBBBBBBBBC CBBBBBBBBBBBBC CBBBBBBBBBBBBC BCCCCCCCCCCCCB CB----------BC C------------C C------------C B------------B B------------B B------------B B------------B B------------B B------------B BB----------BB -BBBBBBBBBBBB- 
