model
size = 14 30 9, scale = 0.05, origin = -y
material 
  colors = A:#FFF B:#AC3232 C:#000 D:#847E87
voxels
-------------- -BBBBBBBBBBBB- BCCCCCCCCCCCCB CBCBBBBBBBBCBC CBCBBBBBBBBCBC CBCBBBBBBBBCBC CBCBBBBBBBBCBC CBCBBBBBBBBCBC CBCBBBBBBBBCBC CBCBBBBBBBBCBC CBCBBBAABBBCBC CBCBBBBBBBBCBC CBCCCCCCCCCCBC CBCCCCCCCCCCBC CBBBBBBBBBBBBC CBBBBBBBBBBBBC CBBBBBBBBBBBBC -CBBBBBBBBBBC- --CCCCCCCCCC-- -------------- -------------- -------------- -------------- -------------- -------------- -------------- -------------- -------------- -------------- -------------- 
-C----------C- BABBBBBBBBBBAB CAAAAAAAAAAAAC BAAAAAAAAAAAAB BAAAAAAAAAAAAB BAAAAAAAAAAAAB BAAAAAAAAAAAAB BAAAAAAAAAAAAB BAAAAAAAAAAAAB BAAAAAAAAAAAAB BAAAAAAAAAAAAB BAAAAAAAAAAAAB BAAAAAAAAAAAAB BAAAAAAAAAAAAB BAAAAAAAAAAAAB BAAAAAAAAAAAAB BAAAAAAAAAAABB BBAAAAAAAAAABB --BBBBBBBBBB-- -------------- -------------- -------------- -------------- -------------- -------------- -------------- -------------- -------------- -------------- -------------- 
-------------- BBBBBBBBBBBBBB CAAAAAAAAAAAAC BAAAAAAAAAAAAB BAAAAAAAAAAAAB BAAAAAAAAAAAAB BAAAAAAAAAAAAB BAAAAAAAAAAAAB BAAAAAAAAAAAAB BAAAAAAAAAAAAB BAAAAAAAAAAAAB BAAAAAAAAAAAAB BAAAAAAAAAAAAB BAAAAAAAAAAAAB BAAAAAAAAAAAAB BAAAAAAAAAAAAB BAAAAAAAAAAAAB BAAAAAAAAAAABB -BAAAAAAAAABB- --BBBBBBBBBB-- -------------- -------------- -------------- -------------- -------------- -------------- -------------- -------------- -------------- -------------- 
-------------- BBBBBBBBBBBBBB CAAAAAAAAAAAAC BAAAAAAAAAAAAB BAAAAAAAAAAAAB BAAAAAAAAAAAAB BAAAAAAAAAAAAB BAAAAAAAAAAAAB BAAAAAAAAAAAAB BAAAAAAAAAAAAB BAAAAAAAAAAAAB BAAAAAAAAAAAAB BAAAAAAAAAAAAB BAAAAAAAAAAAAB BAAAAAAAAAAAAB BAAAAAAAAAAAAB BAAAAAAAAAAAAB BAAAAAAAAAAABB -BAAAAAAAAABB- --BBBBBBBBBB-- -------------- -------------- -------------- -------------- -------------- -------------- -------------- -------------- -------------- -------------- 
-------------- BBBBBBBBBBBBBB CAAAAAAAAAAAAC AAAAAAAAAAAAAA CAAAAAAAAAAAAA AAAAAAAAAAAAAA AAAAAAAAAAAAAA AAAAAAAAAAAAAA AAAAAAAAAAAAAA AAAAAAAAAAAAAA AAAAAAAAAAAAAA AAAAAAAAAAAAAA AAAAAAAAAAAAAA AAAAAAAAAAAAAA AAAAAAAAAAAAAA AAAAAAAAAAAAAA AAAAAAAAAAAAAA AAAAAAAAAAAAAA -AAAAAAAAAAAA- --AAAAAAAAAA-- -------------- -------------- -------------- -------------- -------------- -------------- -------------- -------------- -------------- -------------- 
-------------- BBBBBBBBBBBBBB CAAAAAAAAAAAAC BAAAAAAAAAAAAB BAAAAAAAAAAAAB BAAAAAAAAAAAAB BAAAAAAAAAAAAB BAAAAAAAAAAAAB BAAAAAAAAAAAAB BAAAAAAAAAAAAB BAAAAAAAAAAAAB BAAAAAAAAAAAAB BAAAAAAAAAAAAB BAAAAAAAAAAAAB BAAAAAAAAAAAAB BAAAAAAAAAAAAB BAAAAAAAAAAAAB BAAAAAAAAAAABB -BAAAAAAAAACB- --BBBBBBBBBB-- -------------- -------------- -------------- -------------- -------------- -------------- -------------- -------------- -------------- -------------- 
-------------- BBBBBBBBBBBBBB CAAAAAAAAAAAAC BAAAAAAAAAAAAB BAAAAAAAAAAAAB BAAAAAAAAAAAAB BAAAAAAAAAAAAB BAAAAAAAAAAAAB BAAAAAAAAAAAAB BAAAAAAAAAAAAB BAAAAAAAAAAAAB BAAAAAAAAAAAAB BAAAAAAAAAAAAB BAAAAAAAAAAAAB BAAAAAAAAAAAAB BAAAAAAAAAAAAB BAAAAAAAAAAAAB BAAAAAAAAAAABB -BCAAAAAAAACB- --BBBBBBBBBB-- -------------- -------------- -------------- -------------- -------------- -------------- -------------- -------------- -------------- -------------- 
-------------- BBBBBBBBBBBBBB CAAAAAAAAAAAAC BAAAAAAAAAAAAB BAAAAAAAAAAAAB BAAAAAAAAAAAAB BAAAAAAAAAAAAB BAAAAAAAAAAAAB BAAAAAAAAAAAAB BAAAAAAAAAAAAB BAAAAAAAAAAAAB BAAAAAAAAAAAAB BAAAAAAAAAAAAB BAAAAAAAAAAAAB BAAAAAAAAAAAAB BAAAAAAAAAAAAB BAAAAAAAAAAAAB BACAAAAAAAAABB -BCCCCCCCCCCB- --BBBBBBBBBB-- -------------- -------------- -------------- -------------- -------------- -------------- -------------- -------------- -------------- -------------- 
-C----------C- -BBBBBBBBBBBB- BCCCCCCCCCCCCB CBBBBBBBBBBBBC CBBBBBBBBBBBBC CBBBBBBBBBBBBC CBBBBBBBBBBBBC CBBBBBBBBBBBBC CBBBBBBBBBBBBC CBBBBBBBBBBBBC CBBBBBBBBBBBBC CBBBBBBBBBBBBC CBBBBBBBBBBBBC CBBBBBBBBBBBBC CBBBBBBBBBBBBC CBBBBBBBBBBBBC CBBBBBBBBBBBBC CBBBBBBBBBBBBC DCCCCCCCCCCCCD D------------D D------------D D------------D C------------C C------------C C------------C C------------C C------------C C------------C CC----------CC -CCCCCCCCCCCC- 
