model
size = 14 30 9, scale = 0.05, origin = -y
material 
  colors = A:#FFF B:#000 C:#847E87 D:#595652 E:#AC3232
voxels
-------------- -AAAAAAAAAAAA- ABBBBBBBBBBBBA BABAAAAAAAABAB BABAAAAAAAABAB BABAAAAAAAABAB BABAAAAAAAABAB BABAAAAAAAABAB BABAAAAAAAABAB BABAAAAAAAABAB BABAAADDAAABAB BABAAAAAAAABAB BABBBBBBBBBBAB BABBBBBBBBBBAB BAAAAAAAAAAAAB BAAAAAAAAAAAAB BAAAAAAAAAAAAB -BAAAAAAAAAAB- --BBBBBBBBBB-- -------------- -------------- -------------- -------------- -------------- -------------- -------------- -------------- -------------- -------------- -------------- 
-B----------B- AAAAAAAAAAAAAA BAAAAAAAAAAAAB AAAAAAAAAAAAAA AAAAAAAAAAAAAA AAAAAAAAAAAAAA AAAAAAAAAAAAAA AAAAAAAAAAAAAA AAAAAAAAAAAAAA AAAAAAAAAAAAAA AAAAAAAAAAAAAA AAAAAAAAAAAAAA AAAAAAAAAAAAAA AAAAAAAAAAAAAA AAAAAAAAAAAAAA AAAAAAAAAAAAAA AAAAAAAAAAAAEA AAAAAAAAAAAAAA --AAAAAAAAAA-- -------------- -------------- -------------- -------------- -------------- -------------- -------------- -------------- -------------- -------------- -------------- 
-------------- AAAAAAAAAAAAAA BAAAAAAAAAAAAB AAAAAAAAAAAAAA AAAAAAAAAAAAAA AAAAAAAAAAAAAA AAAAAAAAAAAAAA AAAAAAAAAAAAAA AAAAAAAAAAAAAA AAAAAAAAAAAAAA AAAAAAAAAAAAAA AAAAAAAAAAAAAA AAAAAAAAAAAAAA AAAAAAAAAAAAAA AAAAAAAAAAAAAA AAAAAAAAAAAAAA AAAAAAAAAAAAAA AAAAAAAAAAAAEA -AAAAAAAAAAEA- --AAAAAAAAAA-- -------------- -------------- -------------- -------------- -------------- -------------- -------------- -------------- -------------- -------------- 
-------------- AAAAAAAAAAAAAA BAAAAAAAAAAAAB AAAAAAAAAAAAAA AAAAAAAAAAAAAA AAAAAAAAAAAAAA AAAAAAAAAAAAAA AAAAAAAAAAAAAA AAAAAAAAAAAAAA AAAAAAAAAAAAAA AAAAAAAAAAAAAA AAAAAAAAAAAAAA AAAAAAAAAAAAAA AAAAAAAAAAAAAA AAAAAAAAAAAAAA AAAAAAAAAAAAAA AAAAAAAAAAAAAA AAAAAAAAAAAAEA -AAAAAAAAAAEA- --AAAAAAAAAA-- -------------- -------------- -------------- -------------- -------------- -------------- -------------- -------------- -------------- -------------- 
-------------- AAAAAAAAAAAAAA BAAAAAAAAAAAAB CAAAAAAAAAAAAC BAAAAAAAAAAAAC CAAAAAAAAAAAAC CAAAAAAAAAAAAC CAAAAAAAAAAAAC CAAAAAAAAAAAAC CAAAAAAAAAAAAC CAAAAAAAAAAAAC CAAAAAAAAAAAAC CAAAAAAAAAAAAC CAAAAAAAAAAAAC CAAAAAAAAAAAAC CAAAAAAAAAAAAC CAAAAAAAAAAAAC CAAAAAAAAAAAAC -CAAAAAAAAAAC- --CCCCCCCCCC-- -------------- -------------- -------------- -------------- -------------- -------------- -------------- -------------- -------------- -------------- 
-------------- AAAAAAAAAAAAAA BAAAAAAAAAAAAB AAAAAAAAAAAAAA AAAAAAAAAAAAAA AAAAAAAAAAAAAA AAAAAAAAAAAAAA AAAAAAAAAAAAAA AAAAAAAAAAAAAA AAAAAAAAAAAAAA AAAAAAAAAAAAAA AAAAAAAAAAAAAA AAAAAAAAAAAAAA AAAAAAAAAAAAAA AAAAAAAAAAAAAA AAAAAAAAAAAAAA AAAAAAAAAAAAAA AAAAAAAAAAAAAA -AAAAAAAAAABA- --AAAAAAAAAA-- -------------- -------------- -------------- -------------- -------------- -------------- -------------- -------------- -------------- -------------- 
-------------- AAAAAAAAAAAAAA BAAAAAAAAAAAAB AAAAAAAAAAAAAA AAAAAAAAAAAAAA AAAAAAAAAAAAAA AAAAAAAAAAAAAA AAAAAAAAAAAAAA AAAAAAAAAAAAAA AAAAAAAAAAAAAA AAAAAAAAAAAAAA AAAAAAAAAAAAAA AAAAAAAAAAAAAA AAAAAAAAAAAAAA AAAAAAAAAAAAAA AAAAAAAAAAAAAA AAAAAAAAAAAAAA AAAAAAAAAAAAAA -ABAAAAAAAABA- --AAAAAAAAAA-- -------------- -------------- -------------- -------------- -------------- -------------- -------------- -------------- -------------- -------------- 
-------------- AAAAAAAAAAAAAA BAAAAAAAAAAAAB AAAAAAAAAAAAAA AAAAAAAAAAAAAA AAAAAAAAAAAAAA AAAAAAAAAAAAAA AAAAAAAAAAAAAA AAAAAAAAAAAAAA AAAAAAAAAAAAAA AAAAAAAAAAAAAA AAAAAAAAAAAAAA AAAAAAAAAAAAAA AAAAAAAAAAAAAA AAAAAAAAAAAAAA AAAAAAAAAAAAAA AAAAAAAAAAAAAA AABAAAAAAAAAEA -ABBBBBBBBBBA- --AAAAAAAAAA-- -------------- -------------- -------------- -------------- -------------- -------------- -------------- -------------- -------------- -------------- 
-B----------B- -AAAAAAAAAAAA- ABBBBBBBBBBBBA BAAAAAAAAAAAAB BAAAAAAAAAAAAB BAAAAAAAAAAAAB BAAAAAAAAAAAAB BAAAAAAAAAAAAB BAAAAAAAAAAAAB BAAAAAAAAAAAAB BAAAAAAAAAAAAB BAAAAAAAAAAAAB BAAAAAAAAAAAAB BAAAAAAAAAAAAB BAAAAAAAAAAAAB BAAAAAAAAAAAAB BAAAAAAAAAAAAB BAAAAAAAAAAAAB DBBBBBBBBBBBBD D------------D D------------D D------------D B------------B B------------B B------------B B------------B B------------B B------------B BB----------BB -BBBBBBBBBBBB- 
