model
size = 8 35 35, scale = 0.05, origin = -y
material 
  colors = A:#000
voxels
93-A5-3A2(4-4A)4-5A3(2-6A)2-5A3-5A2(4-4A)5-2A166-3A4-4A4-3A-A2-2A3-A2-2(A4-2A-)4(A5-A-)4(A4-A2-)2(2A2-)5A5-2A135-2A4-4A4-A3-A2-A4-2A2(-A5-A)-A5-8(2A6-)2A5-2(A2-A4-)A2(2-2A)2-5A5-2A109-4A4-2A2(2-A)4-2A2(-A5-A)-A5-12(2A6-)2A5-A-A5-A2-A4-A2-2A2-A5-2A94-3A4-A3-A2-11(A5-A-)A5-6(2A6-)2A5-A-A5-A2-A4-A2(2-2A)3-3A77-4A4-A3-A2-10(A5-A-)4(A4-A2-)A4-A-A5(6-2A)5-A-A5-A2-A4-A2-A3-A4-3A62-3A4-A3-A2-8(A5-A-)A4-A2(2-2A)5(3-5A)2-2A-3A2(2-A4-A)-A5-A-A3(6-2A)5-A-A5-A2-A4-A2-A3-A4-3A48-A4-3A-A2-7(A5-A-)A4-A3-A-3A3-5A4-2A46-A6-4A4-A-3A2-A4-A-A5-A-A3(6-2A)5-A-A5-A2-A4-A2-2A2-A5-2A37-5A2(3-A)2-5(A5-A-)A5-A2-2(A3-)5A4-A79-A6-4A3-A4-2(A-A5-)A-A2(6-2A)5-A-A5-A2-A4-A2-5A30-2A4-2A2(2-A)5(5-A-A)5-A2-A3-A4-4A107-4A3-A4-A-A5-A-A2(6-2A)2(5-A-A)5-A2-2A2-A5-2A21-4A4-A3-2A5(-A5-A)2-A3-A4-4A123-4A2(3-A)2-4(A5-A-)A5-A2-A3-2A2-4A16-A4-3A-A2-5(A5-A-)2A4-A3-4A138-5A2-5(A5-A-)A5-A2-3A-2(A6-)3A4-A3-2A5(-A5-A)2-A2-2A4-2A141-2A5-A2-2A2-4(A5-A-)A5-A2-2A2-A5-2A5-5A2-5(A5-A-)2A4-A3-4A155-4A2-2A4-4(A-A5-)A2-A3-2A3-3A5-5A2-4(A5-A-)A5-A2-A3-A4-3A156-3A4-A3-A2-4(A5-A-)A5-A2-5A4-5A2-4(A5-A-)A5-A2-5A163-2A5-A2-2A4(2-4(A5-A-)A5-A2-5A4-5A2-4(A5-A-)A5-A2-5A170-5A)2-4(A5-A-)A5-A2-5A4-5A2-4(A5-A-)A5-A2-A3-A4-3A156-3A4-A3-A2-4(A5-A-)A5-A2-5A4-4A3-A4-2A4(-A5-A)-2A3-A4-4A155-4A2-2A4-4(A-A5-)A-2(2A3-)3A6-3A4-A3-A2-4(A5-A-)A5-A2-A-3A4-A142-2A5-A2-2A2-4(A5-A-)A5-A2-A3-A4-3A8-A4-3A-A2-5(A5-A-)A4-A3-5A138-5A2-5(A5-A-)A5-A2-3A-A6-A13-4A3-A4-2A5(-A5-A)2-A3-A4-4A123-4A2(3-A)2-4(A5-A-)A5-A2-A3-2A2-4A23-2A4-2A2(2-A)5(5-A-A)4-A2-2A3-A4-4A107-4A2(3-A)2-5(A5-A-)A5-A2-2A2-A5-2A29-5A2-6(A5-A-)A4-A2-2A3-A3-5A4-A79-A5-5A2(3-A)2-5(A5-A-)A5-A2-A3-2A2-4A39-2A4-2A2(2-A)7(5-A-A)4-A3-A-3A3-5A4-2A45-3A5-4A3-2A-2A2-7(A5-A-)A5-A2-3A-A6-A46-3A4-A3-A2-A5-A-A5-2(2A6-)4(A-A5-)A-A4-A2(2-2A)2(3-5A)3-4A4-4A3-5A3-A3-2A-2A4-2(A-A5-)A-A6-2A4(5-A-A)5-A2-A3-A4-3A61-4A4-A3-A2-A5-A-A5-4(2A6-)3(A-A5-)A-3(A4-A2-)A4-3(A-A5-)A-A3(6-2A)3(5-A-A)5-A2-A3-A4-3A78-3A4-A3-A2-A5-A-A5-15(2A6-)2A3(5-A-A)5-A2-A3-A4-3A94-3A4-2A-2A2-A4-2A-A5-A-A5-11(2A6-)2A3(5-A-A)5-A2-A4-A2-3A-A4-3A111-A5-4A3-3A-2A2-A4-A2-A5-A-A5-6(2A6-)2A3(5-A-A)5-2(A2-A4-)A2-2A2-A3-5A6-A135-A5-4A3-3A-2A2-2A3-9(A2-A4-)A2-A3-2A2-3A-A3-5A5-2A167-A6-3A4-4A3(3-5A)3-2(6A2-)2(5A3-)5A4-3A7-A91-
