model
size = 13 32 25, scale = 0.05, origin = -y
material 
  colors = A:#444 B:#555 C:#888 D:#630 E:#300 F:#111 G:#777 H:#500 I:#AAA J:#700 K:#200 L:#400 M:#D00 N:#DDD O:#800 P:#643C13 Q:#222 R:#391E04 S:#552108 T:#402900 U:#A00 V:#773900
voxels
276-7(7A6-)7A304-9(9A4-)9A277-9A3-2(11A2-)2(4ABAB4A2-3A5B3A2-)4ABAB4A3(2-11A)3-9A264-9A3-11A-5A4B7AG6B6A6BG6A6BC6AC5B7A7B7A5BC12AC3A-4A3B4A3-9A264-9A3-4ABGB4A-4A5B7AC5BI6AG6B6A6BN6A7B6AC5BC8A4BC7AB3-BC3A-2(4A3-)9A264-9A3-4A2BG4A-4A5B7AC5BI6A6BN6AG6B6AI5BC6AI5BG8A4BC7AB3-BC3A-4AB2-4A3-9A264-9A3-5AQ5A-4A5B7AC6B6A6BC6AG5BQ7A5BC6AC5BC8A4BC7A2B2-BC3A-4AB2-4A3-9A264-9A3-5AB5A-4A5B7AC5BC6AC5BQ7A2B-2BI6AC2B-2BC6AI5BG8A4BC7AB-3BC3A-4A3B4A3-9A264-9A3-6AB4A-4A5B7A2B2-2BG6AC2(B-)BC6AC2B-2BI6AN2B-2BI6AC2(B-)BC8A4BC7A5BC3A-4A3B4A3-9A264-9A3-4AG2B4A-4A5B7ACB2-2B7AC2(B-)BC7A5BC6AC5B7AC2(B-)BC8A4BC7AB-3BC3A-4A3B4A3-9A264-9A3-4A3B4A-4A5B8AB2-2BC6AC2(B-)2B2(6AC5BC)6AI2(B-)2B8A4BC7AB-3BC3A-4ABDB4A3-9A7-2(3A10-)FOK10-KFJ10-3E10-JLH10-2FK10-JEF10-EFH10-LEJ10-FJK10-JFK10-HEF10-E2H10-H2E10-FJL10-J2F10-2EO10-3E10-3F7-4AE4A3-4ASDR4A-4AB2DRB8AB3M2B6AC5BC7A5B7AC5BC6AC2BD2BC8A4BC7AB-3BC3A-4ADPD4A3-3ADPD3A6-5A9-3A10-KDE10-JDK10-HDF10-FDE10-ODK10-HDF10-EDK10-UNL10-FNK10-LDH10-EDF10-LDE10-ODL10-FDE10-EDE10-LDF10-LDE10-FDF7-4AD4A3-4A2DS4A-4ABT2DB7A2BMDM2B6AI5BC6AC5BC6A7B6AC2BD2BC8A4BC7AB-3BC3A-4ADPD4A3-3ADPD3A6-5A9-3A10-2EJ10-HEK10-JHF10-2FE10-H2E10-EJK10-J2F10-F2H10-LHJ10-LEK10-LHO10-O2F10-F2E10-2EH10-L2E10-EHO10-JKF10-3F7-4AE4A3-4AT2D4A-4ABDVPB8AB3MBC6AC5BC6AI5BG6AC5BC6AG2BD2B9A4BC7AB-3BC3A-4ADPD4A3-3ADPD3A6-5A253-9A3-4A3B4A-4A5B7A6BC6AC2(B-)2B6AC5BI6AC5BC6AG2(B-)2B8A4BC7AB-3BC3A-4ABDB4A3-9A7-3A254-9A3-4AGBG4A-4A5B7AC5BC6AG2(B-)BC6AN5BC6AC5BI6A2B2(-B)G8A4BC7AB-3BC3A-4A3B4A3-9A264-9A3-4ABG5A-4A5B7AC6B6A2B2(-B)C6AC5BC6AN5BC7A2(B-)2B8A4BC7AB-3BC3A-4A3B4A3-9A264-9A3-4AQG5A-4A5B7AN6B6AC2B-2BC6AG2B-2BC6AC2B-2BI6A3B-3B8A4BC7A5BC3A-4A3B4A3-9A264-9A3-6AQ4A-4A5B7AC2B-2BG6AC2B-3B6AG2B-2BC6AC2B-3B6A3B-2BI8A4BC7A3B-BC3A-4AB2-4A3-9A264-9A3-6AB4A-4A5B7A3B-2BC6AC2B-2B7A3B-2BC6AI2B-3B6AG2B-2BI8A4BC7A5BC3A-4AB-B4A3-9A264-9A3-4ABGB4A-4A5B7A6BC6A7B6AC5B7AC5BC6AC5BQ8A4BC7A5BC3A-4A3B4A3-9A264-9A3-11A-5A3B8AC6B6A2B2(AB)C6A7B6AC5BC6A7B7AC4BC12AC3A-11A3-9A264-9A3-2(11A2-)2(4ABAB4A2-3A5B3A2-)4ABAB4A3(2-11A)3-9A277-9(9A4-)9A304-7(7A6-)7A42-
