model
size = 3 3 31, scale = 0.05, origin = -y
material 
  colors = A:#222 B:#630 C:#933 D:#700 E:#555 F:#500 G:#633 H:#400 I:#800
voxels
--- EEE --- 
--- E-E --- 
--- E-E --- 
EEE EEE EEE 
AAA ACA AAA 
BBB BCB BGB 
AAA ACA AAA 
BBB BAB BBB 
AAA AAA AAA 
BGB BAB BBB 
BBB BCB BBB 
BBG BCB BBB 
BBB BCB BBB 
BBB BCB BBB 
BBB BCB BBB 
BBB BCB BBG 
BBB BCB BBB 
GGB BCB BBB 
AAA ACA AAA 
FAD ACA FAF 
AFA FCD ADA 
FAH ACA DAH 
ADA FCD ADA 
IAD ACA HAF 
AFA FCD ADA 
DAD ACA DAD 
AFA ICD AHA 
FAF ACA DAF 
AHA FCI ADA 
DAD ACA HAD 
AAA AAA AAA 
