model
size = 3 3 31, scale = 0.05, origin = -y
material 
  colors = A:#222 B:#630 C:#050 D:#933 E:#555 F:#040 G:#633 H:#080
voxels
--- EEE --- 
--- E-E --- 
--- E-E --- 
EEE EEE EEE 
AAA ADA AAA 
BBB BDB BGB 
AAA ADA AAA 
BBB BAB BBB 
AAA AAA AAA 
BGB BAB BBB 
BBB BDB BBB 
BBG BDB BBB 
BBB BDB BBB 
BBB BDB BBB 
BBB BDB BBB 
BBB BDB BBG 
BBB BDB BBB 
GGB BDB BBB 
AAA ADA AAA 
CAC ADA CAF 
AFA FDC ACA 
HAC ADA FAF 
AFA CDC ACA 
CAF ADA CAH 
ACA FDC ACA 
FAC ADA CAF 
AHA CDC ACA 
FAF ADA HAC 
AFA CDF FCA 
CAC ADA CAC 
AAA AAA AAA 
