model
size = 25 30 20, scale = 0.05, origin = -y
material 
  colors = A:#F60 B:#111 C:#888 D:#222 E:#777 F:#AAA G:#555 H:#A00 I:#DDD J:#080
voxels
------BBBBBBBBBBBBBBBB--- ----BBB---AAAAAAAAAAAAA-- ---BBB----AABBAAABAABAB-- --BB------ABAABAABBABAB-- -BB-------ABBABAABBBBAB-- BB--------AAAABAABABBAB-- BB--------ABBBAAABAABAB-- BB--------AAAAAAAAAAAAB-- BB--------ABAABAAABBAAB-- BB--------ABAABAABAABAB-- BB--------ABBBBAABBABAB-- BB--------ABAABAAAAABAB-- BB--------AABBAAABBBAAB-- BB--------AAAAACFAAAAAB-- BB--------AAAACCFFAAAAB-- BB--------AAACCCFFFAAAB-- BB--------AAACCCFFFAAAA-- BB--------AACCAAAAFFAAA-- BB--------ACAAAGCAAAFAB-- BB--------AAAGGGCCCAAAB-- BB--------AGGGGGCCCCCAB-- BB--------AACGGGCCCFAAB-- BB--------AAACCGCFFAAAB-- BB--------AAACCCFFFAAAB-- BB--------AAAACCFFAAAAB-- BB--------AAAACCFFAAAAB-- BB--------AAAAACFAAAAAB-- BB--------AAAAACFADAAAB-- -BBBBBBBBBBAAAAAAADAAA--- --BBBBBBBB--------------- 
------BBBBBAAAAAAAAAAB--- ----BBB---BAAAAAAAAAAAB-- ---BBB----BAAAAAAAAAAAA-- --BB------BAAAAAAAAAAAA-- -BB-------BAAAAAAAAAAAA-- BB--------BAAAAAAAAAAAA-- BB--------BAAAAAAAAAAAA-- BB--------BAAAAAAAAAAAA-- BB--------BAAAAAAAAAAAA-- BB--------BAAAAAAAAAAAA-- BB--------BAAAAAAAAAAAA-- BB--------BAAAAAAAAAAAA-- BB--------BAAAAAAAAAAAA-- BB--------BAAAAAAAAAAAA-- BB--------BAAAAAAAAAAAA-- BB--------BAAAAAAAAAAAA-- BB--------BAAAAAAAAAAAA-- BB--------BAAAAAAAAAAAA-- BB--------BAAAAAAAAAAAAA- BB--------BAAAAAAAAAAAAA- BB--------BAAAAAAAAAAAAA- BB--------BAAAAAAAAAAAAA- BB--------BAAAAAAAAAAAAA- BB--------BAAAAAAAAAAAAA- BB--------BAAAAAAAAAAAAA- BB--------BAAAAAAAAAAAAD- BB--------BAAAAAAAAAAAAA- BB--------BAAAAAAAAAAAA-- -BBBBBBBBBBBAAAAAADAAB--- --BBBBBBBB--------------- 
------BBBBBAAAAAAAAAAB--- ----BBB---AAAAAAAAAAAAB-- ---BBB----AAAAAAAAAAAAA-- --BB------AAAAAAAAAAAAAA- -BB-------AAAAAAAAAAAAAA- BB--------AAAAAAAAAAAAAA- BB--------AAAAAAAAAAAAAA- BB--------AAAAAAAAAAAAAA- BB--------AAAAAAAAAAAAAA- BB--------AAAAAAAAAAAAAA- BB--------AAAAAAAAAAAAAA- BB--------AAAAAAAAAAAAAA- BB--------AAAAAAAAAAAAAA- BB--------AAAAAAAAAAAAAA- BB--------AAAAAAAAAAAAAD- BB--------AAAAAAAAAAAAAA- BB--------AAAAAAAAAAAAA-- BB--------AAAAAAAAAAAAA-- BB--------AAAAAAAAAAAAAA- BB--------AAAAAAAAAAAAAA- BB--------AAAAAAAAAAAAAA- BB--------AAAAAAAAAAAAAA- BB--------AAAAAAAAAAAAAA- BB--------AAAAAAAAAAAAAA- BB--------AAAAAAAAAAAAAA- BB--------AAAAAAAAAAAAAB- BB--------AAAAAAAAAAAAAA- BB--------BAAAAAAAAAAAA-- -BBBBBBBBBBBAAAAAADAAB--- --BBBBBBBB--------------- 
----------BAAAAAAAAAAB--- ----------AAAAAAAAAAAAB-- ----------AAAAAAAAAAAAA-- ----------AAAAAAAAAAAAAA- ----------AAAAAAAAAAAAAA- ----------AAAAAAAAAAAAAA- ----------AAAAAAAAAAAAAB- ----------AAAAAAAAAAAAAB- ----------AAAAAAAAAAAAAB- ----------AAAAAAAAAAAAAB- ----------AAAAAAAAAAAAAB- ----------AAAAAAAAAAAAAA- ----------AAAAAAAAAAAAAA- ----------AAAAAAAAAAAAAA- ----------AAAAAAAAAAAAAD- ----------AAAAAAAAAAAAAA- ----------AAAAAAAAAAAAA-- ----------AAAAAAAAAAAAA-- ----------AAAAAAAAAAAAAA- ----------AAAAAAAAAAAAAA- ----------AAAAAAAAAAAAAEE ----------AAAAAAAAAAAAAEE ----------AAAAAAAAAAAAAEE ----------AAAAAAAAAAAAAA- ----------AAAAAAAAAAAAAB- ----------AAAAAAAAAAAAAD- ----------AAAAAAAAAAAAAA- ----------BAAAAAAAAAAAA-- ----------ABAAAAAADAAB--- ------------------------- 
----------BAAAAAAAAAAB--- ----------AAAAAAAAAAAAB-- ----------AAAAAAAAAAAAA-- ----------AAAAAAAAAAAAAA- ----------AAAAAAAAAAAAAA- ----------AAAAAAAAAAAAAB- ----------AAAAAAAAAAAAAB- ----------AAAAAAAAAAAAAB- ----------AAAAAAAAAAAAAB- ----------AAAAAAAAAAAAAB- ----------AAAAAAAAAAAAAB- ----------AAAAAAAAAAAAAB- ----------AAAAAAAAAAAAAA- ----------AAAAAAAAAAAAAA- ----------AAAAAAAAAAAAAD- ----------AAAAAAAAAAAAAA- ----------AAAAAAAAAAAAA-- ----------AAAAAAAAAAAAA-- ----------AAAAAAAAAAAAAA- ----------AAAAAAAAAAAAAEE ----------AAAAAAAAAAAAAB- ----------AAAAAAAAAAAAAB- ----------AAAAAAAAAAAAAB- ----------AAAAAAAAAAAAAEE ----------AAAAAAAAAAAAAA- ----------AAAAAAAAAAAAAD- ----------AAAAAAAAAAAAAA- ----------BAAAAAAAAAAAA-- ----------ABAAAAAADAAB--- ------------------------- 
----------BAAAAAAAAAAB--- ----------AAAAAAAAAAAAB-- ----------AAAAAAAAAAAAA-- ----------AAAAAAAAAAAAAA- ----------AAAAAAAAAAAAAB- ----------AAAAAAAAAAAAAB- ----------AAAAAAAAAAAAAB- ----------AAAAAAAAAAAAAB- ----------AAAAAAAAAAAAAB- ----------AAAAAAAAAAAAAB- ----------AAAAAAAAAAAAAB- ----------AAAAAAAAAAAAAB- ----------AAAAAAAAAAAAAB- ----------AAAAAAAAAAAAAA- ----------AAAAAAAAAAAAAD- ----------AAAAAAAAAAAAAA- ----------AAAAAAAAAAAAA-- ----------AAAAAAAAAAAAA-- ----------AAAAAAAAAAAAAA- ----------AAAAAAAAAAAAAEE ----------AAAAAAAAAAAAAB- ----------AAAAAAAAAAAAAB- ----------AAAAAAAAAAAAAB- ----------AAAAAAAAAAAAAEE ----------AAAAAAAAAAAAAA- ----------AAAAAAAAAAAAAD- ----------AAAAAAAAAAAAAA- ----------BAAAAAAAAAAAA-- ----------ABAAAAAADAAB--- ------------------------- 
----------BAAAAAAAAAAB--- ----------AAAAAAAAAAAAB-- ----------AAAAAAAAAAAAA-- ----------AAAAAAAAAAAAAA- ----------AAAAAAAAAAAAAB- ----------AAAAAAAAAAAAAB- ----------AAAAAAAAAAAAAB- ----------AAAAAAAAAAAAAH- ----------AAAAAAAAAAAAAH- ----------AAAAAAAAAAAAAH- ----------AAAAAAAAAAAAAB- ----------AAAAAAAAAAAAAB- ----------AAAAAAAAAAAAAB- ----------AAAAAAAAAAAAAA- ----------AAAAAAAAAAAAAD- ----------AAAAAAAAAAAAAA- ----------AAAAAAAAAAAAA-- ----------AAAAAAAAAAAAA-- ----------AAAAAAAAAAAAAA- ----------AAAAAAAAAAAAAEE ----------AAAAAAAAAAAAAB- ----------AAAAAAAAAAAAAB- ----------AAAAAAAAAAAAAB- ----------AAAAAAAAAAAAAEE ----------AAAAAAAAAAAAAA- ----------AAAAAAAAAAAAAD- ----------AAAAAAAAAAAAAA- ----------BAAAAAAAAAAAA-- ----------ABAAAAAADAAB--- ------------------------- 
----------BAAAAAAAAAAB--- ----------AAAAAAAAAAAAB-- ----------AAAAAAAAAAAAA-- ----------AAAAAAAAAAAAAA- ----------AAAAAAAAAAAAAB- ----------AAAAAAAAAAAAAB- ----------AAAAAAAAAAAAAB- ----------AAAAAAAAAAAAAH- ----------AAAAAAAAAAAAAHI ----------AAAAAAAAAAAAAH- ----------AAAAAAAAAAAAAB- ----------AAAAAAAAAAAAAB- ----------AAAAAAAAAAAAAB- ----------AAAAAAAAAAAAAA- ----------AAAAAAAAAAAAAD- ----------AAAAAAAAAAAAAA- ----------AAAAAAAAAAAAA-- ----------AAAAAAAAAAAAA-- ----------AAAAAAAAAAAAAA- ----------AAAAAAAAAAAAAA- ----------AAAAAAAAAAAAAEE ----------AAAAAAAAAAAAAEE ----------AAAAAAAAAAAAAEE ----------AAAAAAAAAAAAAA- ----------AAAAAAAAAAAAAA- ----------AAAAAAAAAAAAAD- ----------AAAAAAAAAAAAAA- ----------BAAAAAAAAAAAA-- ----------ABAAAAAADAAB--- ---------------B--------- 
----------BAAAAAAAAAAB--- ----------AAAAAAAAAAAAB-- ----------AAAAAAAAAAAAA-- ----------AAAAAAAAAAAAAA- ----------AAAAAAAAAAAAAB- ----------AAAAAAAAAAAAAB- ----------AAAAAAAAAAAAAB- ----------AAAAAAAAAAAAAH- ----------AAAAAAAAAAAAAH- ----------AAAAAAAAAAAAAH- ----------AAAAAAAAAAAAAB- ----------AAAAAAAAAAAAAB- ----------AAAAAAAAAAAAAB- ----------AAAAAAAAAAAAAA- ----------AAAAAAAAAAAAAD- ----------AAAAAAAAAAAAAA- ----------AAAAAAAAAAAAA-- ----------AAAAAAAAAAAAA-- ----------AAAAAAAAAAAAAA- ----------AAAAAAAAAAAAAA- ----------AAAAAAAAAAAAAA- ----------AAAAAAAAAAAAAA- ----------AAAAAAAAAAAAAA- ----------AAAAAAAAAAAAAA- ----------AAAAAAAAAAAAAA- ----------AAAAAAAAAAAAAD- ----------AAAAAAAAAAAAAA- ----------BAAAAAAAAAAAA-- ----------ABAAAAAADAAB--- ---------------B--------- 
----------BAAAAAAAAAAB--- ----------AAAAAAAAAAAAB-- ----------AAAAAAAAAAAAA-- ----------AAAAAAAAAAAAAA- ----------AAAAAAAAAAAAAB- ----------AAAAAAAAAAAAAB- ----------AAAAAAAAAAAAAB- ----------AAAAAAAAAAAAAB- ----------AAAAAAAAAAAAABD ----------AAAAAAAAAAAAAB- ----------AAAAAAAAAAAAAB- ----------AAAAAAAAAAAAAB- ----------AAAAAAAAAAAAAB- ----------AAAAAAAAAAAAAA- ----------AAAAAAAAAAAAAD- ----------AAAAAAAAAAAAAA- ----------AAAAAAAAAAAAA-- ----------AAAAAAAAAAAAA-- ----------AAAAAAAAAAAAAA- ----------AAAAAAAAAAAAAA- ----------AAAAAAAAAAAAAA- ----------AAAAAAAAAAAAAA- ----------AAAAAAAAAAAAAA- ----------AAAAAAAAAAAAAA- ----------AAAAAAAAAAAAAA- ----------AAAAAAAAAAAAAD- ----------AAAAAAAAAAAAAA- ----------BAAAAAAAAAAAA-- ----------ABAAAAAADAAB--- ---------------B--------- 
----------BAAAAAAAAAAB--- ----------AAAAAAAAAAAAB-- ----------AAAAAAAAAAAAA-- ----------AAAAAAAAAAAAAA- ----------AAAAAAAAAAAAAA- ----------AAAAAAAAAAAAAB- ----------AAAAAAAAAAAAAB- ----------AAAAAAAAAAAAABE ----------AAAAAAAAAAAAAB- ----------AAAAAAAAAAAAAB- ----------AAAAAAAAAAAAAB- ----------AAAAAAAAAAAAAB- ----------AAAAAAAAAAAAAA- ----------AAAAAAAAAAAAAA- ----------AAAAAAAAAAAAAD- ----------AAAAAAAAAAAAAA- ----------AAAAAAAAAAAAA-- ----------AAAAAAAAAAAAA-- ----------AAAAAAAAAAAAAA- ----------AAAAAAAAAAAAAA- ----------AAAAAAAAAAAAAA- ----------AAAAAAAAAAAAAA- ----------AAAAAAAAAAAAAA- ----------AAAAAAAAAAAAAA- ----------AAAAAAAAAAAAAA- ----------AAAAAAAAAAAAAD- ----------AAAAAAAAAAAAAA- ----------BAAAAAAAAAAAA-- ----------ABAAAAAADAAB--- ---------------B--------- 
----------BAAAAAAAAAAB--- ----------AAAAAAAAAAAAB-- ----------AAAAAAAAAAAAA-- ----------AAAAAAAAAAAAAA- ----------AAAAAAAAAAAAAA- ----------AAAAAAAAAAAAAA- ----------AAAAAAAAAAAAABE ----------AAAAAAAAAAAAAB- ----------AAAAAAAAAAAAAB- ----------AAAAAAAAAAAAAB- ----------AAAAAAAAAAAAAB- ----------AAAAAAAAAAAAAA- ----------AAAAAAAAAAAAAA- ----------AAAAAAAAAAAAAA- ----------AAAAAAAAAAAAAD- ----------AAAAAAAAAAAAAA- ----------AAAAAAAAAAAAA-- ----------AAAAAAAAAAAAA-- ----------AAAAAAAAAAAAAA- ----------AAAAAAAAAAAAAA- ----------AAAAAAAAAAAAAA- ----------AAAAAAAAAAAAAA- ----------AAAAAAAAAAAAAA- ----------AAAAAAAAAAAAAA- ----------AAAAAAAAAAAAAA- ----------AAAAAAAAAAAAAD- ----------AAAAAAAAAAAAAA- ----------BAAAAAAAAAAAA-- ----------ABAAAAAADAAB--- ---------------B--------- 
----------BAAAAAAAAAAB--- ----------AAAAAAAAAAAAB-- ----------AAAAAAAAAAAAA-- ----------AAAAAAAAAAAAAA- ----------AAAAAAAAAAAAAA- ----------AAAAAAAAAAAAAAE ----------AAAAAAAAAAAAAA- ----------AAAAAAAAAAAAAA- ----------AAAAAAAAAAAAAA- ----------AAAAAAAAAAAAAA- ----------AAAAAAAAAAAAAA- ----------AAAAAAAAAAAAAA- ----------AAAAAAAAAAAAAA- ----------AAAAAAAAAAAAAA- ----------AAAAAAAAAAAAAD- ----------AAAAAAAAAAAAAA- ----------AAAAAAAAAAAAA-- ----------AAAAAAAAAAAAA-- ----------AAAAAAAAAAAAAA- ----------AAAAAAAAAAAAAA- ----------AAAAAAAAAAAAAEE ----------AAAAAAAAAAAAAEE ----------AAAAAAAAAAAAAEE ----------AAAAAAAAAAAAAA- ----------AAAAAAAAAAAAAA- ----------AAAAAAAAAAAAAD- ----------AAAAAAAAAAAAAA- ----------BAAAAAAAAAAAA-- ----------ABAAAAAADAAB--- ---------------B--------- 
----------BAAAAAAAAAAB--- ----------AAAAAAAAAAAAB-- ----------AAAAAAAAAAAAA-- ----------AAAAAAAAAAAAAA- ----------AAAAAAAAAAAAAAD ----------AAAAAAAAAAAAAAD ----------AAAAAAAAAAAAAA- ----------AAAAAAAAAAAAAA- ----------AAAAAAAAAAAAAAD ----------AAAAAAAAAAAAAE- ----------AAAAAAAAAAAAAE- ----------AAAAAAAAAAAAAA- ----------AAAAAAAAAAAAAA- ----------AAAAAAAAAAAAAA- ----------AAAAAAAAAAAAAD- ----------AAAAAAAAAAAAAA- ----------AAAAAAAAAAAAA-- ----------AAAAAAAAAAAAA-- ----------AAAAAAAAAAAAAA- ----------AAAAAAAAAAAAAEE ----------AAAAAAAAAAAAAB- ----------AAAAAAAAAAAAAB- ----------AAAAAAAAAAAAAB- ----------AAAAAAAAAAAAAEE ----------AAAAAAAAAAAAAA- ----------AAAAAAAAAAAAAD- ----------AAAAAAAAAAAAAA- ----------BAAAAAAAAAAAA-- ----------ABAAAAAADAAB--- ------------------------- 
----------BAAAAAAAAAAB--- ----------AAAAAAAAAAAAB-- ----------AAAAAAAAAAAAA-- ----------AAAAAAAAAAAAAA- ----------AAAAAAAAAAAAAA- ----------AAAAAAAAAAAAAA- ----------AAAAAAAAAAAAAA- ----------AAAAAAAAAAAAAA- ----------AAAAAAAAAAAAAA- ----------AAAAAAAAAAAAAA- ----------AAAAAAAAAAAAAA- ----------AAAAAAAAAAAAAA- ----------AAAAAAAAAAAAAA- ----------AAAAAAAAAAAAAA- ----------AAAAAAAAAAAAAB- ----------AAAAAAAAAAAAAA- ----------AAAAAAAAAAAAA-- ----------AAAAAAAAAAAAA-- ----------AAAAAAAAAAAAAA- ----------AAAAAAAAAAAAAEE ----------AAAAAAAAAAAAAB- ----------AAAAAAAAAAAAAB- ----------AAAAAAAAAAAAAB- ----------AAAAAAAAAAAAAEE ----------AAAAAAAAAAAAAA- ----------AAAAAAAAAAAAAD- ----------AAAAAAAAAAAAAA- ----------BAAAAAAAAAAAA-- ----------ABAAAAAADAAB--- ------------------------- 
----------BAAAAAAAAAAB--- ----------AAAAAAAAAAAAB-- ----------AAAAAAAAAAAAA-- ----------AAAAAAAAAAAAAA- ----------AAAAAAAAAAAAAA- ----------AAAAAAAAAAAAAA- ----------AAAAAAAAAAAAAA- ----------AAAAAAAAAAAAAA- ----------AAAAAAAAAAAAAE- ----------AAAAAAAAAAAAAAD ----------AAAAAAAAAAAAAE- ----------AAAAAAAAAAAAAA- ----------AAAAAAAAAAAAAA- ----------AAAAAAAAAAAAAB- ----------AAAAAAAAAAAAAD- ----------AAAAAAAAAAAAAA- ----------AAAAAAAAAAAAA-- ----------AAAAAAAAAAAAA-- ----------AAAAAAAAAAAAAA- ----------AAAAAAAAAAAAAEE ----------AAAAAAAAAAAAAB- ----------AAAAAAAAAAAAAB- ----------AAAAAAAAAAAAAB- ----------AAAAAAAAAAAAAEE ----------AAAAAAAAAAAAAA- ----------AAAAAAAAAAAAAD- ----------AAAAAAAAAAAAAA- ----------BAAAAAAAAAAAA-- ----------ABAAAAAADAAB--- ------------------------- 
----------BAAAAAAAAAAB--- ----------AAAAAAAAAAAAB-- ----------AAAAAAAAAAAAA-- ----------AAAAAAAAAAAAAA- ----------AAAAAAAAAAAAAA- ----------AAAAAAAAAAAAAAJ ----------AAAAAAAAAAAAAA- ----------AAAAAAAAAAAAAA- ----------AAAAAAAAAAAAAA- ----------AAAAAAAAAAAAAA- ----------AAAAAAAAAAAAAA- ----------AAAAAAAAAAAAAA- ----------AAAAAAAAAAAAAA- ----------AAAAAAAAAAAAAA- ----------AAAAAAAAAAAAAD- ----------AAAAAAAAAAAAAA- ----------AAAAAAAAAAAAA-- ----------AAAAAAAAAAAAA-- ----------AAAAAAAAAAAAAA- ----------AAAAAAAAAAAAAA- ----------AAAAAAAAAAAAAEE ----------AAAAAAAAAAAAAEE ----------AAAAAAAAAAAAAEE ----------AAAAAAAAAAAAAA- ----------AAAAAAAAAAAAAA- ----------AAAAAAAAAAAAAD- ----------AAAAAAAAAAAAAA- ----------BAAAAAAAAAAAA-- ----------ABAAAAAADAAB--- ------------------------- 
------BBBBBAAAAAAAAAAB--- ----BBB---AAAAAAAAAAAAB-- ---BBB----AAAAAAAAAAAAA-- --BB------AAAAAAAAAAAAAA- -BB-------AAAAAAAAAAAAAA- BB--------AAAAAAAAAAAAAA- BB--------AAAAAAAAAAAAAA- BB--------AAAAAAAAAAAAAA- BB--------AAAAAAAAAAAAAA- BB--------AAAAAAAAAAAAAA- BB--------AAAAAAAAAAAAAA- BB--------AAAAAAAAAAAAAA- BB--------AAAAAAAAAAAAAA- BB--------AAAAAAAAAAAAAA- BB--------AAAAAAAAAAAAAD- BB--------AAAAAAAAAAAAAA- BB--------AAAAAAAAAAAAA-- BB--------AAAAAAAAAAAAA-- BB--------AAAAAAAAAAAAAA- BB--------AAAAAAAAAAAAAA- BB--------AAAAAAAAAAAAAA- BB--------AAAAAAAAAAAAAA- BB--------AAAAAAAAAAAAAA- BB--------AAAAAAAAAAAAAA- BB--------AAAAAAAAAAAAAA- BB--------AAAAAAAAAAAAAD- BB--------AAAAAAAAAAAAAA- BB--------BAAAAAAAAAAAA-- -BBBBBBBBBBBAAAAAADAAB--- --BBBBBBBB--------------- 
------BBBBBAAAAAAAAAAB--- ----BBB---BAAAAAAAAAAAB-- ---BBB----BAAAAAAAAAAAA-- --BB------BAAAAAAAAAAAA-- -BB-------BAAAAAAAAAAAA-- BB--------BAAAAAAAAAAAA-- BB--------BAAAAAAAAAAAA-- BB--------BAAAAAAAAAAAA-- BB--------BAAAAAAAAAAAA-- BB--------BAAAAAAAAAAAA-- BB--------BAAAAAAAAAAAA-- BB--------BAAAAAAAAAAAA-- BB--------BAAAAAAAAAAAA-- BB--------BAAAAAAAAAAAA-- BB--------BAAAAAAAAAAAA-- BB--------BAAAAAAAAAAAA-- BB--------BAAAAAAAAAAAA-- BB--------BAAAAAAAAAAAA-- BB--------BAAAAAAAAAAAAA- BB--------BAAAAAAAAAAAAA- BB--------BAAAAAAAAAAAAA- BB--------BAAAAAAAAAAAAA- BB--------BAAAAAAAAAAAAA- BB--------BAAAAAAAAAAAAA- BB--------BAAAAAAAAAAAAA- BB--------BAAAAAAAAAAAAD- BB--------BAAAAAAAAAAAAA- BB--------BAAAAAAAAAAAA-- -BBBBBBBBBBBAAAAAADAAB--- --BBBBBBBB--------------- 
------BBBBBBBBBBBBBBBB--- ----BBB---AAAAAAAAAAAAA-- ---BBB----AABBAAABAABAB-- --BB------ABAABAABBABAB-- -BB-------ABBABAABBBBAB-- BB--------AAAABAABABBAB-- BB--------ABBBAAABAABAB-- BB--------AAAAAAAAAAAAB-- BB--------ABAABAAABBAAB-- BB--------ABAABAABAABAB-- BB--------ABBBBAABBABAB-- BB--------ABAABAAAAABAB-- BB--------AABBAAABBBAAB-- BB--------AAAAACFAAAAAB-- BB--------AAAACCFFAAAAB-- BB--------AAACCCFFFAAAB-- BB--------AAACCCFFFAAAA-- BB--------AACCAAAAFFAAA-- BB--------ACAAAGCAAAFAB-- BB--------AAAGGGCCCAAAB-- BB--------AGGGGGCCCCCAB-- BB--------AACGGGCCCFAAB-- BB--------AAACCGCFFAAAB-- BB--------AAACCCFFFAAAB-- BB--------AAAACCFFAAAAB-- BB--------AAAACCFFAAAAB-- BB--------AAAAACFAAAAAB-- BB--------AAAAACFADAAAB-- -BBBBBBBBBBAAAAAAADAAA--- --BBBBBBBB-----------E--- 
