model
size = 17 8 13, scale = 0.05, origin = -y
material 
  colors = A:#111 B:#69F
voxels
--------B-------- -------BBB------- ------BBBBB------ ----------------- -----BBBBBBB----- ------BBBBB------ -------BBB------- --------B-------- 
----------------- ----------------- ----------------- ----------------- ---AAAAAAAAAAA--- ----------------- ----------------- ----------------- 
----------------- ----------------- ----------------- ----------------- --A-----------A-- ----------------- ----------------- ----------------- 
----------------- ----------------- ----------------- ----------------- -A-------------A- ----------------- ----------------- ----------------- 
----------------- ----------------- ----------------- ----------------- A---------------A ----------------- ----------------- ----------------- 
----------------- ----------------- ----------------- ----------------- A---------------A ----------------- ----------------- ----------------- 
----------------- ----------------- ----------------- ----------------- A---------------A ----------------- ----------------- ----------------- 
----------------- ----------------- ----------------- ----------------- A---------------A ----------------- ----------------- ----------------- 
----------------- ----------------- ----------------- ----------------- A---------------A ----------------- ----------------- ----------------- 
----------------- ----------------- ----------------- ----------------- -A-------------A- ----------------- ----------------- ----------------- 
----------------- ----------------- ----------------- ----------------- --A-----------A-- ----------------- ----------------- ----------------- 
----------------- ----------------- ----------------- ----------------- ---A---------A--- ----------------- ----------------- ----------------- 
----------------- ----------------- ----------------- ----------------- ----AAAAAAAAA---- ----------------- ----------------- ----------------- 
