model
size = 15 25 29, scale = 0.05, origin = -y
material 
  colors = A:#DDD B:#111 C:#C0F D:#EEE E:#E00 F:#00F G:#FF0
voxels
--AAAAAAAAAAA-- --AAAAAAAAAAA-- --------------- --------------- --------------- --------------- --------------- --------------- --------------- --------------- --------------- --------------- --------------- --------------- --------------- --------------- --------------- --------------- --------------- --------------- --------------- --------------- --------------- --------------- --------------- 
--AAAAAAAAAAA-- --AAAAAAAAAAA-- --CCCCFGECCCC-- --------------- --------------- --------------- --------------- --------------- --------------- --------------- --------------- --------------- --------------- --------------- --------------- --------------- --------------- --------------- --------------- --------------- --------------- --------------- --------------- --------------- --------------- 
--AAAAAAAAAAA-- --AAAAAAAAAAA-- --CCCCFGECCCC-- ------DDD------ ------D-D------ ------DDD------ --------------- --------------- --------------- --------------- --------------- --------------- --------------- --------------- --------------- --------------- --------------- --------------- --------------- --------------- --------------- --------------- --------------- --------------- --------------- 
--AAAAAAAAAAA-- --AAAAAAAAAAA-- --CCCCFGECCCC-- ------BBB------ ------BBB------ ------BBB------ --------------- --------------- --------------- --------------- --------------- --------------- --------------- --------------- --------------- --------------- --------------- --------------- --------------- --------------- --------------- --------------- --------------- --------------- --------------- 
--AAAAAAAAAAA-- --AAAAAAAAAAA-- --CDDDDDDDDDC-- --CECCDDDCCCC-- --CCCCDDDCCBC-- BBCCCCCCCCCCCBB --------------- --------------- --------------- --------------- --------------- --------------- --------------- --------------- --------------- --------------- --------------- --------------- --------------- --------------- --------------- --------------- --------------- --------------- --------------- 
--AAAAAAAAAAA-- --AAAAAAAAAAA-- --AAAAAAAAAAA-- --AAAAAAAAAAA-- --AAAAAAAAAAA-- B-AAAAAAAAAAA-B --------------- --------------- --------------- --------------- --------------- --------------- --------------- --------------- --------------- --------------- --------------- --------------- --------------- --------------- --------------- --------------- --------------- --------------- --------------- 
--AAAAAAAAAAA-- --AAAAAAAAAAA-- --AAAAAAAAAAA-- --AAAAAAAAAAA-- --AAAAAAAAAAA-- --AAAAAAAAAAA-- B-------------B --------------- --------------- --------------- --------------- --------------- --------------- --------------- --------------- --------------- --------------- --------------- --------------- --------------- --------------- --------------- --------------- --------------- --------------- 
--AAAAAAAAAAA-- --AAAAAAAAAAA-- --AAAAAAAAAAA-- ----AAAAAA----- ---AAAAAAA-AA-- ---AAAAAAAAAA-- --------------- B-------------B --------------- --------------- --------------- --------------- --------------- --------------- --------------- --------------- --------------- --------------- --------------- --------------- --------------- --------------- --------------- --------------- --------------- 
--AAAAAAAAAAA-- --AAAAAAAAAAA-- --AAAAAAAAAAA-- ----AAAAAA----- ----AAAAAA-AA-- ----AAAAAA-AA-- --------------- --------------- B-------------B --------------- --------------- --------------- --------------- --------------- --------------- --------------- --------------- --------------- --------------- --------------- --------------- --------------- --------------- --------------- --------------- 
--AAAAAAAAAAA-- --AAAAAAAAAAA-- --AAAAAAAAAAA-- ----AAAAAA----- -----------AA-- -----------AA-- --------------- --------------- --------------- B-------------B --------------- --------------- --------------- --------------- --------------- --------------- --------------- --------------- --------------- --------------- --------------- --------------- --------------- --------------- --------------- 
--AAAAAAAAAAA-- --AAAAAAAAAAA-- --AAAAAAAAAAA-- --------------- -----------AA-- -----------AA-- --------------- --------------- --------------- --------------- B-------------B --------------- --------------- --------------- --------------- --------------- --------------- --------------- --------------- --------------- --------------- --------------- --------------- --------------- --------------- 
--------------- --------------- --------------- --------------- -----------BB-- -----------BB-- --------------- --------------- --------------- --------------- --------------- B-------------B --------------- --------------- --------------- --------------- --------------- --------------- --------------- --------------- --------------- --------------- --------------- --------------- --------------- 
--------------- --------------- --------------- --------------- --------------- --------------- --------------- --------------- --------------- --------------- --------------- --------------- B-------------B B-------------B --------------- --------------- --------------- --------------- --------------- --------------- --------------- --------------- --------------- --------------- --------------- 
--------------- --------------- --------------- --------------- --------------- --------------- --------------- --------------- --------------- --------------- --------------- --------------- --------------- --------------- B-------------B B-------------B --------------- --------------- --------------- --------------- --------------- --------------- --------------- --------------- --------------- 
--------------- --------------- --------------- --------------- --------------- --------------- --------------- --------------- --------------- --------------- --------------- --------------- --------------- --------------- --------------- --------------- B-------------B B-------------B --------------- --------------- --------------- --------------- --------------- --------------- --------------- 
--------------- --------------- --------------- --------------- --------------- --------------- --------------- --------------- --------------- --------------- --------------- --------------- --------------- --------------- --------------- --------------- --------------- --------------- B-------------B B-------------B --------------- --------------- --------------- --------------- --------------- 
--------------- --------------- --------------- --------------- --------------- --------------- --------------- --------------- --------------- --------------- --------------- --------------- --------------- --------------- --------------- --------------- --------------- --------------- --------------- --------------- B-------------B B-------------B --------------- --------------- --------------- 
--------------- --------------- --------------- --------------- --------------- --------------- --------------- --------------- --------------- --------------- --------------- --------------- --------------- --------------- --------------- --------------- --------------- --------------- --------------- --------------- --------------- --------------- B-------------B B-------------B --------------- 
--------------- --------------- --------------- --------------- --------------- --------------- --------------- --------------- --------------- --------------- --------------- --------------- --------------- --------------- --------------- --------------- --------------- --------------- --------------- --------------- --------------- --------------- --------------- --------------- B-------------B 
--------------- --------------- --------------- --------------- --------------- --------------- --------------- --------------- --------------- --------------- --------------- --------------- --------------- --------------- --------------- --------------- --------------- --------------- --------------- --------------- --------------- --------------- --------------- --------------- B-------------B 
--------------- --------------- --------------- --------------- --------------- --------------- --------------- --------------- --------------- --------------- --------------- --------------- --------------- --------------- --------------- --------------- --------------- --------------- --------------- --------------- --------------- --------------- --------------- --------------- B-------------B 
--------------- --------------- --------------- --------------- --------------- --------------- --------------- --------------- --------------- --------------- --------------- --------------- --------------- --------------- --------------- --------------- --------------- --------------- --------------- --------------- --------------- --------------- --------------- --------------- B-------------B 
--------------- --------------- --------------- --------------- --------------- --------------- --------------- --------------- --------------- --------------- --------------- --------------- --------------- --------------- --------------- --------------- --------------- --------------- --------------- --------------- --------------- --------------- --------------- --------------- B-------------B 
--------------- --------------- --------------- --------------- --------------- --------------- --------------- --------------- --------------- --------------- --------------- --------------- --------------- --------------- --------------- --------------- --------------- --------------- --------------- --------------- --------------- --------------- --------------- --------------- B-------------B 
--------------- --------------- --------------- --------------- --------------- --------------- --------------- --------------- --------------- --------------- --------------- --------------- --------------- --------------- --------------- --------------- --------------- --------------- --------------- --------------- --------------- --------------- --------------- --------------- B-------------B 
--------------- --------------- --------------- --------------- --------------- --------------- --------------- --------------- --------------- --------------- --------------- --------------- --------------- --------------- --------------- --------------- --------------- --------------- --------------- --------------- --------------- --------------- --------------- --------------- B-------------B 
--------------- --------------- --------------- --------------- --------------- --------------- --------------- --------------- --------------- --------------- --------------- --------------- --------------- --------------- --------------- --------------- --------------- --------------- --------------- --------------- --------------- --------------- --------------- --------------- BB-----------BB 
--------------- --------------- --------------- --------------- --------------- --------------- --------------- --------------- --------------- --------------- --------------- --------------- --------------- --------------- --------------- --------------- --------------- --------------- --------------- --------------- --------------- --------------- --------------- --------------- --B---------B-- 
--------------- --------------- --------------- --------------- --------------- --------------- --------------- --------------- --------------- --------------- --------------- --------------- --------------- --------------- --------------- --------------- --------------- --------------- --------------- --------------- --------------- --------------- --------------- --------------- ---BBBBBBBBB--- 
