model
size = 15 25 29, scale = 0.05, origin = -y
material 
  colors = A:#111 B:#EEE C:#E00 D:#00F E:#FF0
voxels
--AAAAAAAAAAA-- --AAAAAAAAAAA-- --------------- --------------- --------------- --------------- --------------- --------------- --------------- --------------- --------------- --------------- --------------- --------------- --------------- --------------- --------------- --------------- --------------- --------------- --------------- --------------- --------------- --------------- --------------- 
--AAAAAAAAAAA-- --AAAAAAAAAAA-- --BBBBDECBBBB-- --------------- --------------- --------------- --------------- --------------- --------------- --------------- --------------- --------------- --------------- --------------- --------------- --------------- --------------- --------------- --------------- --------------- --------------- --------------- --------------- --------------- --------------- 
--AAAAAAAAAAA-- --AAAAAAAAAAA-- --BBBBDECBBBB-- ------BBB------ ------B-B------ ------BBB------ --------------- --------------- --------------- --------------- --------------- --------------- --------------- --------------- --------------- --------------- --------------- --------------- --------------- --------------- --------------- --------------- --------------- --------------- --------------- 
--AAAAAAAAAAA-- --AAAAAAAAAAA-- --BBBBDECBBBB-- ------AAA------ ------AAA------ ------AAA------ --------------- --------------- --------------- --------------- --------------- --------------- --------------- --------------- --------------- --------------- --------------- --------------- --------------- --------------- --------------- --------------- --------------- --------------- --------------- 
--AAAAAAAAAAA-- --AAAAAAAAAAA-- --BBBBBBBBBBB-- --BCBBBBBBBBB-- --BBBBBBBBBAB-- AABBBBBBBBBBBAA --------------- --------------- --------------- --------------- --------------- --------------- --------------- --------------- --------------- --------------- --------------- --------------- --------------- --------------- --------------- --------------- --------------- --------------- --------------- 
--AAAAAAAAAAA-- --AAAAAAAAAAA-- --AAAAAAAAAAA-- --AAAAAAAAAAA-- --AAAAAAAAAAA-- A-AAAAAAAAAAA-A --------------- --------------- --------------- --------------- --------------- --------------- --------------- --------------- --------------- --------------- --------------- --------------- --------------- --------------- --------------- --------------- --------------- --------------- --------------- 
--AAAAAAAAAAA-- --AAAAAAAAAAA-- --AAAAAAAAAAA-- --AAAAAAAAAAA-- --AAAAAAAAAAA-- --AAAAAAAAAAA-- A-------------A --------------- --------------- --------------- --------------- --------------- --------------- --------------- --------------- --------------- --------------- --------------- --------------- --------------- --------------- --------------- --------------- --------------- --------------- 
--AAAAAAAAAAA-- --AAAAAAAAAAA-- --AAAAAAAAAAA-- ----ABBBBA----- ---AABBBBA-AA-- ---AAAAAAAAAA-- --------------- A-------------A --------------- --------------- --------------- --------------- --------------- --------------- --------------- --------------- --------------- --------------- --------------- --------------- --------------- --------------- --------------- --------------- --------------- 
--AAAAAAAAAAA-- --AAAAAAAAAAA-- --AAAAAABAAAA-- ----AAAAAA----- ----AAAAAA-AA-- ----AAAAAA-AA-- --------------- --------------- A-------------A --------------- --------------- --------------- --------------- --------------- --------------- --------------- --------------- --------------- --------------- --------------- --------------- --------------- --------------- --------------- --------------- 
--AAAAAAAAAAA-- --AAAAAAAAAAA-- --AAAAAABAAAA-- ----AAAAAA----- -----------AA-- -----------AA-- --------------- --------------- --------------- A-------------A --------------- --------------- --------------- --------------- --------------- --------------- --------------- --------------- --------------- --------------- --------------- --------------- --------------- --------------- --------------- 
--AAAAAAAAAAA-- --AAAAAAAAAAA-- --AAAAAAAAAAA-- --------------- -----------AA-- -----------AA-- --------------- --------------- --------------- --------------- A-------------A --------------- --------------- --------------- --------------- --------------- --------------- --------------- --------------- --------------- --------------- --------------- --------------- --------------- --------------- 
--------------- --------------- --------------- --------------- -----------AA-- -----------AA-- --------------- --------------- --------------- --------------- --------------- A-------------A --------------- --------------- --------------- --------------- --------------- --------------- --------------- --------------- --------------- --------------- --------------- --------------- --------------- 
--------------- --------------- --------------- --------------- --------------- --------------- --------------- --------------- --------------- --------------- --------------- --------------- A-------------A A-------------A --------------- --------------- --------------- --------------- --------------- --------------- --------------- --------------- --------------- --------------- --------------- 
--------------- --------------- --------------- --------------- --------------- --------------- --------------- --------------- --------------- --------------- --------------- --------------- --------------- --------------- A-------------A A-------------A --------------- --------------- --------------- --------------- --------------- --------------- --------------- --------------- --------------- 
--------------- --------------- --------------- --------------- --------------- --------------- --------------- --------------- --------------- --------------- --------------- --------------- --------------- --------------- --------------- --------------- A-------------A A-------------A --------------- --------------- --------------- --------------- --------------- --------------- --------------- 
--------------- --------------- --------------- --------------- --------------- --------------- --------------- --------------- --------------- --------------- --------------- --------------- --------------- --------------- --------------- --------------- --------------- --------------- A-------------A A-------------A --------------- --------------- --------------- --------------- --------------- 
--------------- --------------- --------------- --------------- --------------- --------------- --------------- --------------- --------------- --------------- --------------- --------------- --------------- --------------- --------------- --------------- --------------- --------------- --------------- --------------- A-------------A A-------------A --------------- --------------- --------------- 
--------------- --------------- --------------- --------------- --------------- --------------- --------------- --------------- --------------- --------------- --------------- --------------- --------------- --------------- --------------- --------------- --------------- --------------- --------------- --------------- --------------- --------------- A-------------A A-------------A --------------- 
--------------- --------------- --------------- --------------- --------------- --------------- --------------- --------------- --------------- --------------- --------------- --------------- --------------- --------------- --------------- --------------- --------------- --------------- --------------- --------------- --------------- --------------- --------------- --------------- A-------------A 
--------------- --------------- --------------- --------------- --------------- --------------- --------------- --------------- --------------- --------------- --------------- --------------- --------------- --------------- --------------- --------------- --------------- --------------- --------------- --------------- --------------- --------------- --------------- --------------- A-------------A 
--------------- --------------- --------------- --------------- --------------- --------------- --------------- --------------- --------------- --------------- --------------- --------------- --------------- --------------- --------------- --------------- --------------- --------------- --------------- --------------- --------------- --------------- --------------- --------------- A-------------A 
--------------- --------------- --------------- --------------- --------------- --------------- --------------- --------------- --------------- --------------- --------------- --------------- --------------- --------------- --------------- --------------- --------------- --------------- --------------- --------------- --------------- --------------- --------------- --------------- A-------------A 
--------------- --------------- --------------- --------------- --------------- --------------- --------------- --------------- --------------- --------------- --------------- --------------- --------------- --------------- --------------- --------------- --------------- --------------- --------------- --------------- --------------- --------------- --------------- --------------- A-------------A 
--------------- --------------- --------------- --------------- --------------- --------------- --------------- --------------- --------------- --------------- --------------- --------------- --------------- --------------- --------------- --------------- --------------- --------------- --------------- --------------- --------------- --------------- --------------- --------------- A-------------A 
--------------- --------------- --------------- --------------- --------------- --------------- --------------- --------------- --------------- --------------- --------------- --------------- --------------- --------------- --------------- --------------- --------------- --------------- --------------- --------------- --------------- --------------- --------------- --------------- A-------------A 
--------------- --------------- --------------- --------------- --------------- --------------- --------------- --------------- --------------- --------------- --------------- --------------- --------------- --------------- --------------- --------------- --------------- --------------- --------------- --------------- --------------- --------------- --------------- --------------- A-------------A 
--------------- --------------- --------------- --------------- --------------- --------------- --------------- --------------- --------------- --------------- --------------- --------------- --------------- --------------- --------------- --------------- --------------- --------------- --------------- --------------- --------------- --------------- --------------- --------------- AA-----------AA 
--------------- --------------- --------------- --------------- --------------- --------------- --------------- --------------- --------------- --------------- --------------- --------------- --------------- --------------- --------------- --------------- --------------- --------------- --------------- --------------- --------------- --------------- --------------- --------------- --A---------A-- 
--------------- --------------- --------------- --------------- --------------- --------------- --------------- --------------- --------------- --------------- --------------- --------------- --------------- --------------- --------------- --------------- --------------- --------------- --------------- --------------- --------------- --------------- --------------- --------------- ---AAAAAAAAA--- 
