model
size = 17 22 11, scale = 0.05, origin = -y
material 
  colors = A:#F2E3CF B:#FCEACD C:#E7C8BC D:#EEE E:#4D2A0A F:#FFF G:#FE5C7D
voxels
----------------- ----------------- ----------------- ----------------- ----------------- ----------------- ----------------- ACCAAAAAACCA----- ACCAAAAAACCA----- AEEAFFFFAEEA----- AEEAFFFFAEEA----- AAAAAGGAAAAA----- AAAAAAAAAAAA----- AAAAAAAAAAAA----- AAAAAAAAAAAA----- AAAAAAAAAAAA----- AAAAAAAAAAAA----- AAAAAAAAAAAA----- ----------------- ----------------- ----------------- ----------------- 
----------------- ----------------- ----------------- ----------------- ----------------- ----------------- ----------------- AAAAAAAAAAAA----- AAAAAAAAAAAA----- AAAAAAAAAA-A----- AAAAAAAAAA-A----- AAAAAAAAAAAA----- A---------AA----- A----------A----- A----------A----- A----------A----- AAAAAAAAAAAA----- AAAAAAAAAAAA----- ----------------- ----------------- ----------------- ----------------- 
--AA-------AAAA-- --AABBBBBBBAAAA-- --AABBBBBBBAAAA-- --AAAAAAAAAAAAA-- --AAAAAAAAAAAAA-- --AAAAAAAAAAAAA-- --AAAAAAAAAAAAA-- AAAAAAAAAAAAAAA-- AAAAAAAAAAAA----- AAAAAAAAAAAA----- AAAAAAAAAAAA----- AAAAAAAAAAAA----- A---------AA----- A----------A----- A----------A----- A----------A----- AAAAAAAAAAAA----- AAAAAAAAAAAA----- ----------------- ----------------- ----------------- ----------------- 
--AA-------AAAA-- --AABBBBBBBBBAA-- --AABBBBBBBBBAA-- --AAAAAAAAAAAAA-- --AAAAAAAAAAAAA-- --AAAAAAAAAAAAA-- --AAAAAAAAAAAAA-- AAAAAAAAAAAAAAA-- AAAAAAAAAAAA----- AAAAAAAAAAAA----- AAAAAAAAAAAA----- AAAAAAAAAAAA----- A---------AA----- A----------A----- A----------A----- A----------A----- AAAAAAAAAAAA----- AAAAAAAAAAAA----- ----------------- ----------------- ----------------- ----------------- 
----------------- --BBBBBBBBBBBBB-- --BBBBBBBBBBBBB-- --BAAAAAAAAAAAB-- --BAAAAAAAAAAAA-- --BAAAAAAAAAAAA-- --BAAAAAAAAAAAA-- AAAAAAAAAAAAAAA-- AAAAAAAAAAAA----- AAAAAAAAAAAA----- AAAAAAAAAAAA----- AAAAAAAAAAAA----- AAAAAAAAA-AA----- AAAAAAAAA-AA----- A----------A----- A----------A----- AAAAAAAAAAAA----- AAAAAAAAAAAA----- ----------CA----- ----------CA----- ----------AA----- ----------AA----- 
----------------- --BBBBBBBBBBBBB-- --BBBBBBBBBBBBB-- --BAAAAAAAAAAAB-- --BAAAAAAAAAAAA-- --BAAAAAAAAAAAA-- --BAAAAAAAAAAAA-- AAAAAAAAAAAAAAADD AAAAAAAAAAAA---DD AAAAAAAAAAAA---DD AAAAAAAAAAAA----- AAAAAAAAAAAA----- AAAAAAAAA-AA----- AAAAAAAAA-AA----- A----------A----- A----------A----- AAAAAAAAAAAA----- AAAAAAAAAAAA----- ----------AA----- ----------AA----- ----------AA----- ----------AA----- 
----------------- --BBBBBBBBBBBBB-- --BBBBBBBBBBBBB-- --BAAAAAAAAAAAB-- --BAAAAAAAAAAAA-- --BAAAAAAAAAAAA-- --BAAAAAAAAAAAA-- AAAAAAAAAAAAAAADD AAAAAAAAAAAA---DD AAAAAAAAAAAA---DD AAAAAAAAAAAA----- AAAAAAAAAAAA----- AAAAAAAAA-AA----- AAAAAAAAAAAA----- AAAAAAAAAAAA----- AAAAAAAAAAAA----- AAAAAAAAAAAA----- AAAAAAAAAAAA----- AC--------------- AC--------------- AA--------------- AA--------------- 
----------------- --BBBBBBBBBBBBB-- --BBBBBBBBBBBBB-- --BAAAAAAAAAAAB-- --BAAAAAAAAAAAA-- --BAAAAAAAAAAAA-- --BAAAAAAAAAAAA-- AAAAAAAAAAAAAAA-- AAAAAAAAAAAA----- AAAAAAAAAAAA----- AAAAAAAAAAAA----- AAAAAAAAAAAA----- AAAAAAAAA-AA----- AAAAAAAAAAAA----- AAAAAAAAAAAA----- AAAAAAAAAAAA----- AAAAAAAAAAAA----- AAAAAAAAAAAA----- AA--------------- AA--------------- AA--------------- AA--------------- 
-----AA--AAAA---- --AAAAABBAAAAAA-- --AAABABBBBAAAA-- --ABBAAAAAAAAAA-- --AAAAAAAAAAAAA-- --AAAAAAAAAAAAA-- --AAAAAAAAAAAAA-- AAAAAAAAAAAAAAA-- AAAAAAAAAAAA----- AAAAAAAAAAAA----- AAAAAAAAAAAA----- AAAAAAAAAAAA----- AAAAAAAAA-AA----- AAAAAAAAAAAA----- AAAAAAAAAAAA----- AAAAAAAAAAAA----- AAAAAAAAAAAA----- AAAAAAAAAAAA----- ----------------- ----------------- ----------------- ----------------- 
-----AA--AAAA---- --AAAAABBAAAAAA-- --AAAAABBAAAAAA-- --AAAAAAAAAAAAA-- --AAAAAAAAAAAAA-- --AAAAAAAAAAAAA-- --AAAAAAAAAAAAA-- AAAAAAAAAAAAAAA-- AAAAAAAAAAAA----- AAAAAAAAAAAA----- AAAAAAAAAAAA----- AAAAAAAAAA-A----- AAAAAAAAA-AA----- AAAAAAAAAAAA----- AAAAAAAAAAAA----- AAAAAAAAAAAA----- AAAAAAAAAAAA----- AAAAAAAAAAAA----- ----------------- ----------------- ----------------- ----------------- 
----------------- ----------------- ----------------- ----------------- ----------------- ----------------- ----------------- AAAAAAAAAAAA----- AAAAAAAAAAAA----- AAAAAAAAAAAA----- AAAAAAAAAAAA----- AAAAAAAAAAAA----- AAAAAAAAAAAA----- AAAAAAAAAAAA----- AAAAAAAAAAAA----- AAAAAAAAAAAA----- AAAAAAAAAAAA----- AAAAAAAAAAAA----- ----------------- ----------------- ----------------- ----------------- 
