model
size = 31, scale = 0.05, origin = -y
material 
  colors = A:#42602D B:#3C2F41 C:#C99833 D:#533D5B E:#E8B647 F:#AF5F3C G:#FB966E H:#2EA9DF I:#0B1013 J:#724938 K:#B47157 L:#51A8DD M:#0F2540 N:#00AA90 O:#F7C242 P:#DB4D6D Q:#0F4C3A R:#D0104C S:#FEDFE1 T:#DDA52D U:#8F77B5 V:#8A6BBE W:#E87A90 X:#0D5661 Y:#336774 Z:#9F353A Aa:#9E7A7A Ab:#D05A6E Ac:#B5495B Ad:#F9BF45 Ae:#69B0AC Af:#20604F Ag:#77428D Ah:#B28FCE Ai:#BA9132 Aj:#0C4842 Ak:#81C7D4 Al:#ED784A Am:#7B90D2 An:#F05E1C Ao:#08192D Ap:#005CAF Aq:#0B346E Ar:#00896C As:#90B44B At:#096148 Au:#986DB2 Av:#6A4C9C Aw:#DCB879 Ax:#0089A7 Ay:#D19826 Az:#33A6B8 Ba:#4F726C Bb:#111
voxels
- - - - - - - - - - - - AlAlAlAlAlAlAl- - - - - - - - - - - -   - - - - - - - - - - - - - - - - - - - - - - - - - - - - - - -   - - - - - - - - - - - - - - - - - - - - - - - - - - - - - - -   - - - - - - - - - - - - - - - - - - - - - - - - - - - - - - -   - - - - - - - - - - - - - - - - - - - - - - - - - - - - - - -   - - - - - - - - - - - - - - - - - - - - - - - - - - - - - - -   - - - - - - - - - - - - - - - - - - - - - - - - - - - - - - -   - - - - - - - - - - - - - - - - - - - - - - - - - - - - - - -   - - - - - - - - - - - - - - - - - - - - - - - - - - - - - - -   - - - - - - - - - - - - - - - - - - - - - - - - - - - - - - -   - - - - - - - - - - - - - - - - - - - - - - - - - - - - - - -   - - - - - - - - - - - - - - - - - - - - - - - - - - - - - - -   - - - - - - - - - - - - Ai- - Aw- - Ad- - - - - - - - - - - -   - - - - - - - - - - - - - BbBbAwBbBb- - - - - - - - - - - - -   - - - - - - - - - - - - - - BbBbBb- - - - - - - - - - - - - -   - - - - - - - - - - - - E E E BbC C C - - - - - - - - - - - -   - - - - - - - - - - - - - - O BbT - - - - - - - - - - - - - -   - - - - - - - - - - - - - O - Ay- T - - - - - - - - - - - - -   - - - - - - - - - - - - O - - Ay- - T - - - - - - - - - - - -   - - - - - - - - - - - - - - - - - - - - - - - - - - - - - - -   - - - - - - - - - - - - - - - - - - - - - - - - - - - - - - -   - - - - - - - - - - - - - - - - - - - - - - - - - - - - - - -   - - - - - - - - - - - - - - - - - - - - - - - - - - - - - - -   - - - - - - - - - - - - - - - - - - - - - - - - - - - - - - -   - - - - - - - - - - - - - - - - - - - - - - - - - - - - - - -   - - - - - - - - - - - - - - - - - - - - - - - - - - - - - - -   - - - - - - - - - - - - - - - - - - - - - - - - - - - - - - -   - - - - - - - - - - - - - - - - - - - - - - - - - - - - - - -   - - - - - - - - - - - - - - - - - - - - - - - - - - - - - - -   - - - - - - - - - - - - - - - - - - - - - - - - - - - - - - -   - - - - - - - - - - - - AoAoAoAoAoAoAo- - - - - - - - - - - -   
- - - - - - - - - - - - - - - - - - - - - - - - - - - - - - -   - - - - - - - - - AlAlAlAlAlAlAlAlAlAlAlAlAl- - - - - - - - -   - - - - - - - - - - - - - - - - - - - - - - - - - - - - - - -   - - - - - - - - - - - - - - - - - - - - - - - - - - - - - - -   - - - - - - - - - - - - - - - - - - - - - - - - - - - - - - -   - - - - - - - - - - - - - - - - - - - - - - - - - - - - - - -   - - - - - - - - - - - - - - - - - - - - - - - - - - - - - - -   - - - - - - - - - - - - - - - - - - - - - - - - - - - - - - -   - - - - - - - - - - - - - - - - - - - - - - - - - - - - - - -   - - - - - - - - - Ai- - - - - Aw- - - - - Ad- - - - - - - - -   - - - - - - - - - - Ai- - - - Aw- - - - Ad- - - - - - - - - -   - - - - - - - - - - - Ai- - - Aw- - - Ad- - - - - - - - - - -   - - - - - - - - - - - - Ai- - Aw- - Ad- - - - - - - - - - - -   - - - - - - - - - - - - - Ai- Aw- Ad- - - - - - - - - - - - -   - - - - - - - - - - - - - - AiA Ad- - - - - - - - - - - - - -   - - - - - - - - - E E E E E A BbA C C C C C - - - - - - - - -   - - - - - - - - - - - - - - O A T - - - - - - - - - - - - - -   - - - - - - - - - - - - - O - Ay- T - - - - - - - - - - - - -   - - - - - - - - - - - - O - - Ay- - T - - - - - - - - - - - -   - - - - - - - - - - - O - - - Ay- - - T - - - - - - - - - - -   - - - - - - - - - - O - - - - Ay- - - - T - - - - - - - - - -   - - - - - - - - - O - - - - - Ay- - - - - T - - - - - - - - -   - - - - - - - - - - - - - - - - - - - - - - - - - - - - - - -   - - - - - - - - - - - - - - - - - - - - - - - - - - - - - - -   - - - - - - - - - - - - - - - - - - - - - - - - - - - - - - -   - - - - - - - - - - - - - - - - - - - - - - - - - - - - - - -   - - - - - - - - - - - - - - - - - - - - - - - - - - - - - - -   - - - - - - - - - - - - - - - - - - - - - - - - - - - - - - -   - - - - - - - - - - - - - - - - - - - - - - - - - - - - - - -   - - - - - - - - - AoAoAoAoAoAoAoAoAoAoAoAoAo- - - - - - - - -   - - - - - - - - - - - - - - - - - - - - - - - - - - - - - - -   
- - - - - - - - - - - - - - - - - - - - - - - - - - - - - - -   - - - - - - - - - - - - - - - - - - - - - - - - - - - - - - -   - - - - - - - AlAlAlAlAlAlAlAlAlAlAlAlAlAlAlAlAl- - - - - - -   - - - - - - - - - - - - - - - - - - - - - - - - - - - - - - -   - - - - - - - - - - - - - - - - - - - - - - - - - - - - - - -   - - - - - - - - - - - - - - - - - - - - - - - - - - - - - - -   - - - - - - - - - - - - - - - - - - - - - - - - - - - - - - -   - - - - - - - Ai- - - - - - - Aw- - - - - - - Ad- - - - - - -   - - - - - - - - Ai- - - - - - Aw- - - - - - Ad- - - - - - - -   - - - - - - - - - Ai- - - - - Aw- - - - - Ad- - - - - - - - -   - - - - - - - - - - Ai- - - - Aw- - - - Ad- - - - - - - - - -   - - - - - - - - - - - Ai- - - Aw- - - Ad- - - - - - - - - - -   - - - - - - - - - - - - Ai- - Aw- - Ad- - - - - - - - - - - -   - - - - - - - - - - - - - Ai- Aw- Ad- - - - - - - - - - - - -   - - - - - - - - - - - - - - AiA Ad- - - - - - - - - - - - - -   - - - - - - - E E E E E E E A A A C C C C C C C - - - - - - -   - - - - - - - - - - - - - - O A T - - - - - - - - - - - - - -   - - - - - - - - - - - - - O - Ay- T - - - - - - - - - - - - -   - - - - - - - - - - - - O - - Ay- - T - - - - - - - - - - - -   - - - - - - - - - - - O - - - Ay- - - T - - - - - - - - - - -   - - - - - - - - - - O - - - - Ay- - - - T - - - - - - - - - -   - - - - - - - - - O - - - - - Ay- - - - - T - - - - - - - - -   - - - - - - - - O - - - - - - Ay- - - - - - T - - - - - - - -   - - - - - - - O - - - - - - - Ay- - - - - - - T - - - - - - -   - - - - - - - - - - - - - - - - - - - - - - - - - - - - - - -   - - - - - - - - - - - - - - - - - - - - - - - - - - - - - - -   - - - - - - - - - - - - - - - - - - - - - - - - - - - - - - -   - - - - - - - - - - - - - - - - - - - - - - - - - - - - - - -   - - - - - - - AoAoAoAoAoAoAoAoAoAoAoAoAoAoAoAoAo- - - - - - -   - - - - - - - - - - - - - - - - - - - - - - - - - - - - - - -   - - - - - - - - - - - - - - - - - - - - - - - - - - - - - - -   
- - - - - - - - - - - - - - - - - - - - - - - - - - - - - - -   - - - - - - - - - - - - - - - - - - - - - - - - - - - - - - -   - - - - - - - - - - - - - - - - - - - - - - - - - - - - - - -   - - - - - - AlAlAlAlAlAlAlAlAlAlAlAlAlAlAlAlAlAlAl- - - - - -   - - - - - - - - - - - - - - - - - - - - - - - - - - - - - - -   - - - - - - - - - - - - - - - - - - - - - - - - - - - - - - -   - - - - - - Ai- - - - - - - - Aw- - - - - - - - Ad- - - - - -   - - - - - - - Ai- - - - - - - Aw- - - - - - - Ad- - - - - - -   - - - - - - - - Ai- - - - - - Aw- - - - - - Ad- - - - - - - -   - - - - - - - - - Ai- - - - - Aw- - - - - Ad- - - - - - - - -   - - - - - - - - - - Ai- - - - Aw- - - - Ad- - - - - - - - - -   - - - - - - - - - - - Ai- - - Aw- - - Ad- - - - - - - - - - -   - - - - - - - - - - - - Ai- - Aw- - Ad- - - - - - - - - - - -   - - - - - - - - - - - - - Ai- Aw- Ad- - - - - - - - - - - - -   - - - - - - - - - - - - - - AiA Ad- - - - - - - - - - - - - -   - - - - - - E E E E E E E E A A A C C C C C C C C - - - - - -   - - - - - - - - - - - - - - O A T - - - - - - - - - - - - - -   - - - - - - - - - - - - - O - Ay- T - - - - - - - - - - - - -   - - - - - - - - - - - - O - - Ay- - T - - - - - - - - - - - -   - - - - - - - - - - - O - - - Ay- - - T - - - - - - - - - - -   - - - - - - - - - - O - - - - Ay- - - - T - - - - - - - - - -   - - - - - - - - - O - - - - - Ay- - - - - T - - - - - - - - -   - - - - - - - - O - - - - - - Ay- - - - - - T - - - - - - - -   - - - - - - - O - - - - - - - Ay- - - - - - - T - - - - - - -   - - - - - - O - - - - - - - - Ay- - - - - - - - T - - - - - -   - - - - - - - - - - - - - - - - - - - - - - - - - - - - - - -   - - - - - - - - - - - - - - - - - - - - - - - - - - - - - - -   - - - - - - AoAoAoAoAoAoAoAoAoAoAoAoAoAoAoAoAoAoAo- - - - - -   - - - - - - - - - - - - - - - - - - - - - - - - - - - - - - -   - - - - - - - - - - - - - - - - - - - - - - - - - - - - - - -   - - - - - - - - - - - - - - - - - - - - - - - - - - - - - - -   
- - - - - - - - - - - - - - - - - - - - - - - - - - - - - - -   - - - - - - - - - - - - - - - - - - - - - - - - - - - - - - -   - - - - - - - - - - - - - - - - - - - - - - - - - - - - - - -   - - - - - - - - - - - - - - - - - - - - - - - - - - - - - - -   - - - - - AlAlAlAlAlAlAlAlAlAlAlAlAlAlAlAlAlAlAlAlAl- - - - -   - - - - - Ai- - - - - - - - - Aw- - - - - - - - - Ad- - - - -   - - - - - - Ai- - - - - - - - Aw- - - - - - - - Ad- - - - - -   - - - - - - - Ai- - - - - - - Aw- - - - - - - Ad- - - - - - -   - - - - - - - - Ai- - - - - - Aw- - - - - - Ad- - - - - - - -   - - - - - - - - - Ai- - - - - Aw- - - - - Ad- - - - - - - - -   - - - - - - - - - - Ai- - - - Aw- - - - Ad- - - - - - - - - -   - - - - - - - - - - - Ai- - - Aw- - - Ad- - - - - - - - - - -   - - - - - - - - - - - - Ai- - Aw- - Ad- - - - - - - - - - - -   - - - - - - - - - - - - - Ai- Aw- Ad- - - - - - - - - - - - -   - - - - - - - - - - - - - - AiA Ad- - - - - - - - - - - - - -   - - - - - E E E E E E E E E A A A C C C C C C C C C - - - - -   - - - - - - - - - - - - - - O A T - - - - - - - - - - - - - -   - - - - - - - - - - - - - O - Ay- T - - - - - - - - - - - - -   - - - - - - - - - - - - O - - Ay- - T - - - - - - - - - - - -   - - - - - - - - - - - O - - - Ay- - - T - - - - - - - - - - -   - - - - - - - - - - O - - - - Ay- - - - T - - - - - - - - - -   - - - - - - - - - O - - - - - Ay- - - - - T - - - - - - - - -   - - - - - - - - O - - - - - - Ay- - - - - - T - - - - - - - -   - - - - - - - O - - - - - - - Ay- - - - - - - T - - - - - - -   - - - - - - O - - - - - - - - Ay- - - - - - - - T - - - - - -   - - - - - O - - - - - - - - - Ay- - - - - - - - - T - - - - -   - - - - - AoAoAoAoAoAoAoAoAoAoAoAoAoAoAoAoAoAoAoAoAo- - - - -   - - - - - - - - - - - - - - - - - - - - - - - - - - - - - - -   - - - - - - - - - - - - - - - - - - - - - - - - - - - - - - -   - - - - - - - - - - - - - - - - - - - - - - - - - - - - - - -   - - - - - - - - - - - - - - - - - - - - - - - - - - - - - - -   
- - - - - - - - - - - - - - - - - - - - - - - - - - - - - - -   - - - - - - - - - - - - - - - - - - - - - - - - - - - - - - -   - - - - - - - - - - - - - - - - - - - - - - - - - - - - - - -   - - - - - - - - - - - - - - - - - - - - - - - - - - - - - - -   - - - - As- - - - - - - - - - Ab- - - - - - - - - - An- - - -   - - - - X J J J J J J J J J J A G G G G G G G G G G N - - - -   - - - - - - Ai- - - - - - - - Aw- - - - - - - - Ad- - - - - -   - - - - - - - Ai- - - - - - - Aw- - - - - - - Ad- - - - - - -   - - - - - - - - Ai- - - - - - Aw- - - - - - Ad- - - - - - - -   - - - - - - - - - Ai- - - - - Aw- - - - - Ad- - - - - - - - -   - - - - - - - - - - Ai- - - - Aw- - - - Ad- - - - - - - - - -   - - - - - - - - - - - Ai- - - Aw- - - Ad- - - - - - - - - - -   - - - - - - - - - - - - Ai- - Aw- - Ad- - - - - - - - - - - -   - - - - - - - - - - - - - Ai- Aw- Ad- - - - - - - - - - - - -   - - - - - - - - - - - - - - AiA Ad- - - - - - - - - - - - - -   - - - - E E E E E E E E E E A A A C C C C C C C C C C - - - -   - - - - - - - - - - - - - - O A T - - - - - - - - - - - - - -   - - - - - - - - - - - - - O - Ay- T - - - - - - - - - - - - -   - - - - - - - - - - - - O - - Ay- - T - - - - - - - - - - - -   - - - - - - - - - - - O - - - Ay- - - T - - - - - - - - - - -   - - - - - - - - - - O - - - - Ay- - - - T - - - - - - - - - -   - - - - - - - - - O - - - - - Ay- - - - - T - - - - - - - - -   - - - - - - - - O - - - - - - Ay- - - - - - T - - - - - - - -   - - - - - - - O - - - - - - - Ay- - - - - - - T - - - - - - -   - - - - - - O - - - - - - - - Ay- - - - - - - - T - - - - - -   - - - - AjL L L L L L L L L L A H H H H H H H H H H Ae- - - -   - - - - Am- - - - - - - - - - Aa- - - - - - - - - - Ap- - - -   - - - - - - - - - - - - - - - - - - - - - - - - - - - - - - -   - - - - - - - - - - - - - - - - - - - - - - - - - - - - - - -   - - - - - - - - - - - - - - - - - - - - - - - - - - - - - - -   - - - - - - - - - - - - - - - - - - - - - - - - - - - - - - -   
- - - - - - - - - - - - - - - - - - - - - - - - - - - - - - -   - - - - - - - - - - - - - - - - - - - - - - - - - - - - - - -   - - - - - - - - - - - - - - - - - - - - - - - - - - - - - - -   - - - As- - - - - - - - - - - Ab- - - - - - - - - - - An- - -   - - - - As- - - - - - - - - - Ab- - - - - - - - - - An- - - -   - - - - - J - - - - - - - - - Ab- - - - - - - - - G - - - - -   - - - X X X J J J J J J J J J A G G G G G G G G G N N N - - -   - - - - - - - Ai- - - - - - - Aw- - - - - - - Ad- - - - - - -   - - - - - - - - Ai- - - - - - Aw- - - - - - Ad- - - - - - - -   - - - - - - - - - Ai- - - - - Aw- - - - - Ad- - - - - - - - -   - - - - - - - - - - Ai- - - - Aw- - - - Ad- - - - - - - - - -   - - - - - - - - - - - Ai- - - Aw- - - Ad- - - - - - - - - - -   - - - - - - - - - - - - Ai- - Aw- - Ad- - - - - - - - - - - -   - - - - - - - - - - - - - Ai- Aw- Ad- - - - - - - - - - - - -   - - - - - - - - - - - - - - AiA Ad- - - - - - - - - - - - - -   - - - E E E E E E E E E E E A A A C C C C C C C C C C C - - -   - - - - - - - - - - - - - - O A T - - - - - - - - - - - - - -   - - - - - - - - - - - - - O - Ay- T - - - - - - - - - - - - -   - - - - - - - - - - - - O - - Ay- - T - - - - - - - - - - - -   - - - - - - - - - - - O - - - Ay- - - T - - - - - - - - - - -   - - - - - - - - - - O - - - - Ay- - - - T - - - - - - - - - -   - - - - - - - - - O - - - - - Ay- - - - - T - - - - - - - - -   - - - - - - - - O - - - - - - Ay- - - - - - T - - - - - - - -   - - - - - - - O - - - - - - - Ay- - - - - - - T - - - - - - -   - - - AjAjAjL L L L L L L L L A H H H H H H H H H AeAeAe- - -   - - - - - L - - - - - - - - - Aa- - - - - - - - - H - - - - -   - - - - Am- - - - - - - - - - Aa- - - - - - - - - - Ap- - - -   - - - Am- - - - - - - - - - - Aa- - - - - - - - - - - Ap- - -   - - - - - - - - - - - - - - - - - - - - - - - - - - - - - - -   - - - - - - - - - - - - - - - - - - - - - - - - - - - - - - -   - - - - - - - - - - - - - - - - - - - - - - - - - - - - - - -   
- - - - - - - - - - - - - - - - - - - - - - - - - - - - - - -   - - - - - - - - - - - - - - - - - - - - - - - - - - - - - - -   - - As- - - - - - - - - - - - Ab- - - - - - - - - - - - An- -   - - - As- - - - - - - - - - - Ab- - - - - - - - - - - An- - -   - - - - As- - - - - - - - - - Ab- - - - - - - - - - An- - - -   - - - - - J - - - - - - - - - Ab- - - - - - - - - G - - - - -   - - - - - - J - - - - - - - - Ab- - - - - - - - G - - - - - -   - - X X X X X J J J J J J J J A G G G G G G G G N N N N N - -   - - - - - - - - Ai- - - - - - Aw- - - - - - Ad- - - - - - - -   - - - - - - - - - Ai- - - - - Aw- - - - - Ad- - - - - - - - -   - - - - - - - - - - Ai- - - - Aw- - - - Ad- - - - - - - - - -   - - - - - - - - - - - Ai- - - Aw- - - Ad- - - - - - - - - - -   - - - - - - - - - - - - Ai- - Aw- - Ad- - - - - - - - - - - -   - - - - - - - - - - - - - Ai- Aw- Ad- - - - - - - - - - - - -   - - - - - - - - - - - - - - AiA Ad- - - - - - - - - - - - - -   - - E E E E E E E E E E E E A A A C C C C C C C C C C C C - -   - - - - - - - - - - - - - - O A T - - - - - - - - - - - - - -   - - - - - - - - - - - - - O - Ay- T - - - - - - - - - - - - -   - - - - - - - - - - - - O - - Ay- - T - - - - - - - - - - - -   - - - - - - - - - - - O - - - Ay- - - T - - - - - - - - - - -   - - - - - - - - - - O - - - - Ay- - - - T - - - - - - - - - -   - - - - - - - - - O - - - - - Ay- - - - - T - - - - - - - - -   - - - - - - - - O - - - - - - Ay- - - - - - T - - - - - - - -   - - AjAjAjAjAjL L L L L L L L A H H H H H H H H AeAeAeAeAe- -   - - - - - - L - - - - - - - - Aa- - - - - - - - H - - - - - -   - - - - - L - - - - - - - - - Aa- - - - - - - - - H - - - - -   - - - - Am- - - - - - - - - - Aa- - - - - - - - - - Ap- - - -   - - - Am- - - - - - - - - - - Aa- - - - - - - - - - - Ap- - -   - - Am- - - - - - - - - - - - Aa- - - - - - - - - - - - Ap- -   - - - - - - - - - - - - - - - - - - - - - - - - - - - - - - -   - - - - - - - - - - - - - - - - - - - - - - - - - - - - - - -   
- - - - - - - - - - - - - - - - - - - - - - - - - - - - - - -   - - - - - - - - - - - - - - - - - - - - - - - - - - - - - - -   - - As- - - - - - - - - - - - Ab- - - - - - - - - - - - An- -   - - - As- - - - - - - - - - - Ab- - - - - - - - - - - An- - -   - - - - As- - - - - - - - - - Ab- - - - - - - - - - An- - - -   - - - - - J - - - - - - - - - Ab- - - - - - - - - G - - - - -   - - - - - - J - - - - - - - - Ab- - - - - - - - G - - - - - -   - - - - - - - J - - - - - - - Ab- - - - - - - G - - - - - - -   - - X X X X X X J J J J J J J A G G G G G G G N N N N N N - -   - - - - - - - - - Ai- - - - - Aw- - - - - Ad- - - - - - - - -   - - - - - - - - - - Ai- - - - Aw- - - - Ad- - - - - - - - - -   - - - - - - - - - - - Ai- - - Aw- - - Ad- - - - - - - - - - -   - - - - - - - - - - - - Ai- - Aw- - Ad- - - - - - - - - - - -   - - - - - - - - - - - - - Ai- Aw- Ad- - - - - - - - - - - - -   - - - - - - - - - - - - - - AiA Ad- - - - - - - - - - - - - -   - - E E E E E E E E E E E E A A A C C C C C C C C C C C C - -   - - - - - - - - - - - - - - O A T - - - - - - - - - - - - - -   - - - - - - - - - - - - - O - Ay- T - - - - - - - - - - - - -   - - - - - - - - - - - - O - - Ay- - T - - - - - - - - - - - -   - - - - - - - - - - - O - - - Ay- - - T - - - - - - - - - - -   - - - - - - - - - - O - - - - Ay- - - - T - - - - - - - - - -   - - - - - - - - - O - - - - - Ay- - - - - T - - - - - - - - -   - - AjAjAjAjAjAjL L L L L L L A H H H H H H H AeAeAeAeAeAe- -   - - - - - - - L - - - - - - - Aa- - - - - - - H - - - - - - -   - - - - - - L - - - - - - - - Aa- - - - - - - - H - - - - - -   - - - - - L - - - - - - - - - Aa- - - - - - - - - H - - - - -   - - - - Am- - - - - - - - - - Aa- - - - - - - - - - Ap- - - -   - - - Am- - - - - - - - - - - Aa- - - - - - - - - - - Ap- - -   - - Am- - - - - - - - - - - - Aa- - - - - - - - - - - - Ap- -   - - - - - - - - - - - - - - - - - - - - - - - - - - - - - - -   - - - - - - - - - - - - - - - - - - - - - - - - - - - - - - -   
- - - - - - - - - - - - - - - - - - - - - - - - - - - - - - -   - As- - - - - - - - - - - - - Ab- - - - - - - - - - - - - An-   - - As- - - - - - - - - - - - Ab- - - - - - - - - - - - An- -   - - - As- - - - - - - - - - - Ab- - - - - - - - - - - An- - -   - - - - As- - - - - - - - - - Ab- - - - - - - - - - An- - - -   - - - - - J - - - - - - - - - Ab- - - - - - - - - G - - - - -   - - - - - - J - - - - - - - - Ab- - - - - - - - G - - - - - -   - - - - - - - J - - - - - - - Ab- - - - - - - G - - - - - - -   - - - - - - - - J - - - - - - Ab- - - - - - G - - - - - - - -   - X X X X X X X X J J J J J J A G G G G G G N N N N N N N N -   - - - - - - - - - - Ai- - - - Aw- - - - Ad- - - - - - - - - -   - - - - - - - - - - - Ai- - - Aw- - - Ad- - - - - - - - - - -   - - - - - - - - - - - - Ai- - Aw- - Ad- - - - - - - - - - - -   - - - - - - - - - - - - - Ai- Aw- Ad- - - - - - - - - - - - -   - - - - - - - - - - - - - - AiA Ad- - - - - - - - - - - - - -   - E E E E E E E E E E E E E A A A C C C C C C C C C C C C C -   - - - - - - - - - - - - - - O A T - - - - - - - - - - - - - -   - - - - - - - - - - - - - O - Ay- T - - - - - - - - - - - - -   - - - - - - - - - - - - O - - Ay- - T - - - - - - - - - - - -   - - - - - - - - - - - O - - - Ay- - - T - - - - - - - - - - -   - - - - - - - - - - O - - - - Ay- - - - T - - - - - - - - - -   - AjAjAjAjAjAjAjAjL L L L L L A H H H H H H AeAeAeAeAeAeAeAe-   - - - - - - - - L - - - - - - Aa- - - - - - H - - - - - - - -   - - - - - - - L - - - - - - - Aa- - - - - - - H - - - - - - -   - - - - - - L - - - - - - - - Aa- - - - - - - - H - - - - - -   - - - - - L - - - - - - - - - Aa- - - - - - - - - H - - - - -   - - - - Am- - - - - - - - - - Aa- - - - - - - - - - Ap- - - -   - - - Am- - - - - - - - - - - Aa- - - - - - - - - - - Ap- - -   - - Am- - - - - - - - - - - - Aa- - - - - - - - - - - - Ap- -   - Am- - - - - - - - - - - - - Aa- - - - - - - - - - - - - Ap-   - - - - - - - - - - - - - - - - - - - - - - - - - - - - - - -   
- - - - - - - - - - - - - - - - - - - - - - - - - - - - - - -   - As- - - - - - - - - - - - - Ab- - - - - - - - - - - - - An-   - - As- - - - - - - - - - - - Ab- - - - - - - - - - - - An- -   - - - As- - - - - - - - - - - Ab- - - - - - - - - - - An- - -   - - - - As- - - - - - - - - - Ab- - - - - - - - - - An- - - -   - - - - - J - - - - - - - - - Ab- - - - - - - - - G - - - - -   - - - - - - J - - - - - - - - Ab- - - - - - - - G - - - - - -   - - - - - - - J - - - - - - - Ab- - - - - - - G - - - - - - -   - - - - - - - - J - - - - - - Ab- - - - - - G - - - - - - - -   - - - - - - - - - J - - - - - Ab- - - - - G - - - - - - - - -   - X X X X X X X X X J J J J J A G G G G G N N N N N N N N N -   - - - - - - - - - - - Ai- - - Aw- - - Ad- - - - - - - - - - -   - - - - - - - - - - - - Ai- - Aw- - Ad- - - - - - - - - - - -   - - - - - - - - - - - - - Ai- Aw- Ad- - - - - - - - - - - - -   - - - - - - - - - - - - - - AiA Ad- - - - - - - - - - - - - -   - E E E E E E E E E E E E E A A A C C C C C C C C C C C C C -   - - - - - - - - - - - - - - O A T - - - - - - - - - - - - - -   - - - - - - - - - - - - - O - Ay- T - - - - - - - - - - - - -   - - - - - - - - - - - - O - - Ay- - T - - - - - - - - - - - -   - - - - - - - - - - - O - - - Ay- - - T - - - - - - - - - - -   - AjAjAjAjAjAjAjAjAjL L L L L A H H H H H AeAeAeAeAeAeAeAeAe-   - - - - - - - - - L - - - - - Aa- - - - - H - - - - - - - - -   - - - - - - - - L - - - - - - Aa- - - - - - H - - - - - - - -   - - - - - - - L - - - - - - - Aa- - - - - - - H - - - - - - -   - - - - - - L - - - - - - - - Aa- - - - - - - - H - - - - - -   - - - - - L - - - - - - - - - Aa- - - - - - - - - H - - - - -   - - - - Am- - - - - - - - - - Aa- - - - - - - - - - Ap- - - -   - - - Am- - - - - - - - - - - Aa- - - - - - - - - - - Ap- - -   - - Am- - - - - - - - - - - - Aa- - - - - - - - - - - - Ap- -   - Am- - - - - - - - - - - - - Aa- - - - - - - - - - - - - Ap-   - - - - - - - - - - - - - - - - - - - - - - - - - - - - - - -   
- - - - - - - - - - - - - - - - - - - - - - - - - - - - - - -   - As- - - - - - - - - - - - - Ab- - - - - - - - - - - - - An-   - - As- - - - - - - - - - - - Ab- - - - - - - - - - - - An- -   - - - As- - - - - - - - - - - Ab- - - - - - - - - - - An- - -   - - - - As- - - - - - - - - - Ab- - - - - - - - - - An- - - -   - - - - - J - - - - - - - - - Ab- - - - - - - - - G - - - - -   - - - - - - J - - - - - - - - Ab- - - - - - - - G - - - - - -   - - - - - - - J - - - - - - - Ab- - - - - - - G - - - - - - -   - - - - - - - - J - - - - - - Ab- - - - - - G - - - - - - - -   - - - - - - - - - J - - - - - Ab- - - - - G - - - - - - - - -   - - - - - - - - - - J - - - - Ab- - - - G - - - - - - - - - -   - X X X X X X X X X X J J J J A G G G G N N N N N N N N N N -   - - - - - - - - - - - - Ai- - Aw- - Ad- - - - - - - - - - - -   - - - - - - - - - - - - - Ai- Aw- Ad- - - - - - - - - - - - -   - - - - - - - - - - - - - - AiA Ad- - - - - - - - - - - - - -   - E E E E E E E E E E E E E A A A C C C C C C C C C C C C C -   - - - - - - - - - - - - - - O A T - - - - - - - - - - - - - -   - - - - - - - - - - - - - O - Ay- T - - - - - - - - - - - - -   - - - - - - - - - - - - O - - Ay- - T - - - - - - - - - - - -   - AjAjAjAjAjAjAjAjAjAjL L L L A H H H H AeAeAeAeAeAeAeAeAeAe-   - - - - - - - - - - L - - - - Aa- - - - H - - - - - - - - - -   - - - - - - - - - L - - - - - Aa- - - - - H - - - - - - - - -   - - - - - - - - L - - - - - - Aa- - - - - - H - - - - - - - -   - - - - - - - L - - - - - - - Aa- - - - - - - H - - - - - - -   - - - - - - L - - - - - - - - Aa- - - - - - - - H - - - - - -   - - - - - L - - - - - - - - - Aa- - - - - - - - - H - - - - -   - - - - Am- - - - - - - - - - Aa- - - - - - - - - - Ap- - - -   - - - Am- - - - - - - - - - - Aa- - - - - - - - - - - Ap- - -   - - Am- - - - - - - - - - - - Aa- - - - - - - - - - - - Ap- -   - Am- - - - - - - - - - - - - Aa- - - - - - - - - - - - - Ap-   - - - - - - - - - - - - - - - - - - - - - - - - - - - - - - -   
As- - - - - - - - - - - - - - Ab- - - - - - - - - - - - - - An  - As- - - - - - - - - - - - - Ab- - - - - - - - - - - - - An-   - - As- - - - - - - - - - - - Ab- - - - - - - - - - - - An- -   - - - As- - - - - - - - - - - Ab- - - - - - - - - - - An- - -   - - - - As- - - - - - - - - - Ab- - - - - - - - - - An- - - -   - - - - - J - - - - - - - - - Ab- - - - - - - - - G - - - - -   - - - - - - J - - - - - - - - Ab- - - - - - - - G - - - - - -   - - - - - - - J - - - - - - - Ab- - - - - - - G - - - - - - -   - - - - - - - - J - - - - - - Ab- - - - - - G - - - - - - - -   - - - - - - - - - J - - - - - Ab- - - - - G - - - - - - - - -   - - - - - - - - - - J - - - - Ab- - - - G - - - - - - - - - -   - - - - - - - - - - - J - - - Ab- - - G - - - - - - - - - - -   X X X X X X X X X X X X J J J A G G G N N N N N N N N N N N N   - - - - - - - - - - - - - Ai- Aw- Ad- - - - - - - - - - - - -   - - - - - - - - - - - - - - AiA Ad- - - - - - - - - - - - - -   E E E E E E E E E E E E E E A A A C C C C C C C C C C C C C C   - - - - - - - - - - - - - - O A T - - - - - - - - - - - - - -   - - - - - - - - - - - - - O - Ay- T - - - - - - - - - - - - -   AjAjAjAjAjAjAjAjAjAjAjAjL L L A H H H AeAeAeAeAeAeAeAeAeAeAeAe  - - - - - - - - - - - L - - - Aa- - - H - - - - - - - - - - -   - - - - - - - - - - L - - - - Aa- - - - H - - - - - - - - - -   - - - - - - - - - L - - - - - Aa- - - - - H - - - - - - - - -   - - - - - - - - L - - - - - - Aa- - - - - - H - - - - - - - -   - - - - - - - L - - - - - - - Aa- - - - - - - H - - - - - - -   - - - - - - L - - - - - - - - Aa- - - - - - - - H - - - - - -   - - - - - L - - - - - - - - - Aa- - - - - - - - - H - - - - -   - - - - Am- - - - - - - - - - Aa- - - - - - - - - - Ap- - - -   - - - Am- - - - - - - - - - - Aa- - - - - - - - - - - Ap- - -   - - Am- - - - - - - - - - - - Aa- - - - - - - - - - - - Ap- -   - Am- - - - - - - - - - - - - Aa- - - - - - - - - - - - - Ap-   Am- - - - - - - - - - - - - - Aa- - - - - - - - - - - - - - Ap  
As- - - - - - - - - - - - - - Ab- - - - - - - - - - - - - - An  - As- - - - - - - - - - - - - Ab- - - - - - - - - - - - - An-   - - As- - - - - - - - - - - - Ab- - - - - - - - - - - - An- -   - - - As- - - - - - - - - - - Ab- - - - - - - - - - - An- - -   - - - - As- - - - - - - - - - Ab- - - - - - - - - - An- - - -   - - - - - J - - - - - - - - - Ab- - - - - - - - - G - - - - -   - - - - - - J - - - - - - - - Ab- - - - - - - - G - - - - - -   - - - - - - - J - - - - - - - Ab- - - - - - - G - - - - - - -   - - - - - - - - J - - - - - - Ab- - - - - - G - - - - - - - -   - - - - - - - - - J - - - - - Ab- - - - - G - - - - - - - - -   - - - - - - - - - - J - - - - Ab- - - - G - - - - - - - - - -   - - - - - - - - - - - J - - - Ab- - - G - - - - - - - - - - -   - - - - - - - - - - - - J - - Ab- - G - - - - - - - - - - - -   X X X X X X X X X X X X X J J A G G N N N N N N N N N N N N N   - - - - - - - - - - - - - - AiA Ad- - - - - - - - - - - - - -   E E E E E E E E E E E E E E A A A C C C C C C C C C C C C C C   - - - - - - - - - - - - - - O A T - - - - - - - - - - - - - -   BbAjAjAjAjAjAjAjAjAjAjAjAjL L A H H AeAeAeAeAeAeAeAeAeAeAeAeBb  - - - - - - - - - - - - L - - Aa- - H - - - - - - - - - - - -   - - - - - - - - - - - L - - - Aa- - - H - - - - - - - - - - -   - - - - - - - - - - L - - - - Aa- - - - H - - - - - - - - - -   - - - - - - - - - L - - - - - Aa- - - - - H - - - - - - - - -   - - - - - - - - L - - - - - - Aa- - - - - - H - - - - - - - -   - - - - - - - L - - - - - - - Aa- - - - - - - H - - - - - - -   - - - - - - L - - - - - - - - Aa- - - - - - - - H - - - - - -   - - - - - L - - - - - - - - - Aa- - - - - - - - - H - - - - -   - - - - Am- - - - - - - - - - Aa- - - - - - - - - - Ap- - - -   - - - Am- - - - - - - - - - - Aa- - - - - - - - - - - Ap- - -   - - Am- - - - - - - - - - - - Aa- - - - - - - - - - - - Ap- -   - Am- - - - - - - - - - - - - Aa- - - - - - - - - - - - - Ap-   Am- - - - - - - - - - - - - - Aa- - - - - - - - - - - - - - Ap  
As- - - - - - - - - - - - - - O - - - - - - - - - - - - - - An  - As- - - - - - - - - - - - - Ab- - - - - - - - - - - - - An-   - - As- - - - - - - - - - - - Ab- - - - - - - - - - - - An- -   - - - As- - - - - - - - - - - Ab- - - - - - - - - - - An- - -   - - - - As- - - - - - - - - - Ab- - - - - - - - - - An- - - -   - - - - - J - - - - - - - - - Ab- - - - - - - - - G - - - - -   - - - - - - J - - - - - - - - Ab- - - - - - - - G - - - - - -   - - - - - - - J - - - - - - - Ab- - - - - - - G - - - - - - -   - - - - - - - - J - - - - - - Ab- - - - - - G - - - - - - - -   - - - - - - - - - J - - - - - Ab- - - - - G - - - - - - - - -   - - - - - - - - - - J - - - - Ab- - - - G - - - - - - - - - -   - - - - - - - - - - - J - - - Ab- - - G - - - - - - - - - - -   - - - - - - - - - - - - J - - Ab- - G - - - - - - - - - - - -   - - - - - - - - - - - - - J - Ab- G - - - - - - - - - - - - -   X X X X X X X X X X X X X X J A G N N N N N N N N N N N N N N   E A A A A A A A A A A A A A A A A A A A A A A A A A A A A A C   BbAjAjAjAjAjAjAjAjAjAjAjAjAjL A H AeAeAeAeAeAeAeAeAeAeAeAeAeBb  Bb- - - - - - - - - - - - L - Aa- H - - - - - - - - - - - - Bb  - - - - - - - - - - - - L - - Aa- - H - - - - - - - - - - - -   - - - - - - - - - - - L - - - Aa- - - H - - - - - - - - - - -   - - - - - - - - - - L - - - - Aa- - - - H - - - - - - - - - -   - - - - - - - - - L - - - - - Aa- - - - - H - - - - - - - - -   - - - - - - - - L - - - - - - Aa- - - - - - H - - - - - - - -   - - - - - - - L - - - - - - - Aa- - - - - - - H - - - - - - -   - - - - - - L - - - - - - - - Aa- - - - - - - - H - - - - - -   - - - - - L - - - - - - - - - Aa- - - - - - - - - H - - - - -   - - - - Am- - - - - - - - - - Aa- - - - - - - - - - Ap- - - -   - - - Am- - - - - - - - - - - Aa- - - - - - - - - - - Ap- - -   - - Am- - - - - - - - - - - - Aa- - - - - - - - - - - - Ap- -   - Am- - - - - - - - - - - - - Aa- - - - - - - - - - - - - Ap-   Am- - - - - - - - - - - - - - N - - - - - - - - - - - - - - Ap  
As- - - - - - - - - - - W W W O P P P - - - - - - - - - - - An  - As- - - - - - - W W W W W W BbP P P P P P - - - - - - - An-   - - As- - - - W W W W W W W W A P P P P P P P P - - - - An- -   - - - As- - W W W W W W W W W A P P P P P P P P P - - An- - -   - - - - AsW W W W W W W W W W A P P P P P P P P P P An- - - -   - - - - AxA W W W W W W W W W A P P P P P P P P P A Ba- - - -   - - - AxAxAxA W W W W W W W W A P P P P P P P P A BaBaBa- - -   - - AxAxAxAxAxA W W W W W W W A P P P P P P P A BaBaBaBaBa- -   - - AxAxAxAxAxAxA W W W W W W A P P P P P P A BaBaBaBaBaBa- -   - AxAxAxAxAxAxAxAxA W W W W W A P P P P P A BaBaBaBaBaBaBaBa-   - AxAxAxAxAxAxAxAxAxA W W W W A P P P P A BaBaBaBaBaBaBaBaBa-   - AxAxAxAxAxAxAxAxAxAxA W W W A P P P A BaBaBaBaBaBaBaBaBaBa-   AxAxAxAxAxAxAxAxAxAxAxAxA W W A P P A BaBaBaBaBaBaBaBaBaBaBaBa  AxAxAxAxAxAxAxAxAxAxAxAxAxA W A P A - BaBaBaBaBaBaBaBaBaBaBaBa  BbA A A A A A A A A A A A A A A F - - A A A A A A A A A A A Bb  BbBbA A A A A A A A A A A A A - A B B A A A A A A A A A A BbBb  BbA A A A A A A A A A A A A A A A A A A A A A A A A A A A A Bb  AzAzAzAzAzAzAzAzAzAzAzAzAzA S A R A AtAtAtAtAtAtAtAtAtAtAtAtAt  AzAzAzAzAzAzAzAzAzAzAzAzA S S A R R A AtAtAtAtAtAtAtAtAtAtAtAt  - AzAzAzAzAzAzAzAzAzAzA S S S A R R R A AtAtAtAtAtAtAtAtAtAt-   - AzAzAzAzAzAzAzAzAzA S S S S A R R R R A AtAtAtAtAtAtAtAtAt-   - AzAzAzAzAzAzAzAzA S S S S S A R R R R R A AtAtAtAtAtAtAtAt-   - - AzAzAzAzAzAzA S S S S S S A R R R R R R A AtAtAtAtAtAt- -   - - AzAzAzAzAzA S S S S S S S A R R R R R R R A AtAtAtAtAt- -   - - - AzAzAzA S S S S S S S S A R R R R R R R R A AtAtAt- - -   - - - - AzA S S S S S S S S S A R R R R R R R R R A At- - - -   - - - - AmS S S S S S S S S S A R R R R R R R R R R Ap- - - -   - - - Am- - S S S S S S S S S A R R R R R R R R R - - Ap- - -   - - Am- - - - S S S S S S S S A R R R R R R R R - - - - Ap- -   - Am- - - - - - - S S S S S S BbR R R R R R - - - - - - - Ap-   Am- - - - - - - - - - - S S S N R R R - - - - - - - - - - - Ap  
As- - - - - - - - - - - - - O O O - - - - - - - - - - - - - An  - As- - - - - - - - - - - - - Ac- - - - - - - - - - - - - An-   - - As- - - - - - - - - - - - Ac- - - - - - - - - - - - An- -   - - - As- - - - - - - - - - - Ac- - - - - - - - - - - An- - -   - - - - As- - - - - - - - - - Ac- - - - - - - - - - An- - - -   - - - - - K - - - - - - - - - Ac- - - - - - - - - F - - - - -   - - - - - - K - - - - - - - - Ac- - - - - - - - F - - - - - -   - - - - - - - K - - - - - - - Ac- - - - - - - F - - - - - - -   - - - - - - - - K - - - - - - Ac- - - - - - F - - - - - - - -   - - - - - - - - - K - - - - - Ac- - - - - F - - - - - - - - -   - - - - - - - - - - K - - - - Ac- - - - F - - - - - - - - - -   - - - - - - - - - - - K - - - Ac- - - F - - - - - - - - - - -   - - - - - - - - - - - - K - - Ac- - F - - - - - - - - - - - -   - - - - - - - - - - - - - K - Ac- F - - - - - - - - - - - - -   Y Y Y Y Y Y Y Y Y Y Y Y Y Y K A F Q Q Q Q Q Q Q Q Q Q Q Q Q Q   D A A A A A A A A A A A A A A A A B B A A A A A A A A A A A B   BbAkAkAkAkAkAkAkAkAkAkAkAkAkM A I AfAfAfAfAfAfAfAfAfAfAfAfAfBb  Bb- - - - - - - - - - - - M - Z - I - - - - - - - - - - - - Bb  - - - - - - - - - - - - M - - Z - - I - - - - - - - - - - - -   - - - - - - - - - - - M - - - Z - - - I - - - - - - - - - - -   - - - - - - - - - - M - - - - Z - - - - I - - - - - - - - - -   - - - - - - - - - M - - - - - Z - - - - - I - - - - - - - - -   - - - - - - - - M - - - - - - Z - - - - - - I - - - - - - - -   - - - - - - - M - - - - - - - Z - - - - - - - I - - - - - - -   - - - - - - M - - - - - - - - Z - - - - - - - - I - - - - - -   - - - - - M - - - - - - - - - Z - - - - - - - - - I - - - - -   - - - - Am- - - - - - - - - - Z - - - - - - - - - - Ap- - - -   - - - Am- - - - - - - - - - - Z - - - - - - - - - - - Ap- - -   - - Am- - - - - - - - - - - - Z - - - - - - - - - - - - Ap- -   - Am- - - - - - - - - - - - - Z - - - - - - - - - - - - - Ap-   Am- - - - - - - - - - - - - N N N - - - - - - - - - - - - - Ap  
As- - - - - - - - - - - - O O AcO O - - - - - - - - - - - - An  - As- - - - - - - - - - - - - Ac- - - - - - - - - - - - - An-   - - As- - - - - - - - - - - - Ac- - - - - - - - - - - - An- -   - - - As- - - - - - - - - - - Ac- - - - - - - - - - - An- - -   - - - - As- - - - - - - - - - Ac- - - - - - - - - - An- - - -   - - - - - K - - - - - - - - - Ac- - - - - - - - - F - - - - -   - - - - - - K - - - - - - - - Ac- - - - - - - - F - - - - - -   - - - - - - - K - - - - - - - Ac- - - - - - - F - - - - - - -   - - - - - - - - K - - - - - - Ac- - - - - - F - - - - - - - -   - - - - - - - - - K - - - - - Ac- - - - - F - - - - - - - - -   - - - - - - - - - - K - - - - Ac- - - - F - - - - - - - - - -   - - - - - - - - - - - K - - - Ac- - - F - - - - - - - - - - -   - - - - - - - - - - - - K - - Ac- - F - - - - - - - - - - - -   Y Y Y Y Y Y Y Y Y Y Y Y Y K K A F F Q Q Q Q Q Q Q Q Q Q Q Q Q   - - - - - - - - - - - - - - AhA Ag- - - - - - - - - - - - - -   D D D D D D D D D D D D D D A A A B B B B B B B B B B B B B B   - - - - - - - - - - - - - - U A V - - - - - - - - - - - - - -   BbAkAkAkAkAkAkAkAkAkAkAkAkM M A I I AfAfAfAfAfAfAfAfAfAfAfAfBb  - - - - - - - - - - - - M - - Z - - I - - - - - - - - - - - -   - - - - - - - - - - - M - - - Z - - - I - - - - - - - - - - -   - - - - - - - - - - M - - - - Z - - - - I - - - - - - - - - -   - - - - - - - - - M - - - - - Z - - - - - I - - - - - - - - -   - - - - - - - - M - - - - - - Z - - - - - - I - - - - - - - -   - - - - - - - M - - - - - - - Z - - - - - - - I - - - - - - -   - - - - - - M - - - - - - - - Z - - - - - - - - I - - - - - -   - - - - - M - - - - - - - - - Z - - - - - - - - - I - - - - -   - - - - Am- - - - - - - - - - Z - - - - - - - - - - Ap- - - -   - - - Am- - - - - - - - - - - Z - - - - - - - - - - - Ap- - -   - - Am- - - - - - - - - - - - Z - - - - - - - - - - - - Ap- -   - Am- - - - - - - - - - - - - Z - - - - - - - - - - - - - Ap-   Am- - - - - - - - - - - - N N Z N N - - - - - - - - - - - - Ap  
As- - - - - - - - - - - - - - Ac- - - - - - - - - - - - - - An  - As- - - - - - - - - - - - - Ac- - - - - - - - - - - - - An-   - - As- - - - - - - - - - - - Ac- - - - - - - - - - - - An- -   - - - As- - - - - - - - - - - Ac- - - - - - - - - - - An- - -   - - - - As- - - - - - - - - - Ac- - - - - - - - - - An- - - -   - - - - - K - - - - - - - - - Ac- - - - - - - - - F - - - - -   - - - - - - K - - - - - - - - Ac- - - - - - - - F - - - - - -   - - - - - - - K - - - - - - - Ac- - - - - - - F - - - - - - -   - - - - - - - - K - - - - - - Ac- - - - - - F - - - - - - - -   - - - - - - - - - K - - - - - Ac- - - - - F - - - - - - - - -   - - - - - - - - - - K - - - - Ac- - - - F - - - - - - - - - -   - - - - - - - - - - - K - - - Ac- - - F - - - - - - - - - - -   Y Y Y Y Y Y Y Y Y Y Y Y K K K A F F F Q Q Q Q Q Q Q Q Q Q Q Q   - - - - - - - - - - - - - Ah- Au- Ag- - - - - - - - - - - - -   - - - - - - - - - - - - - - AhA Ag- - - - - - - - - - - - - -   D D D D D D D D D D D D D D A A A B B B B B B B B B B B B B B   - - - - - - - - - - - - - - U A V - - - - - - - - - - - - - -   - - - - - - - - - - - - - U - Av- V - - - - - - - - - - - - -   AkAkAkAkAkAkAkAkAkAkAkAkM M M A I I I AfAfAfAfAfAfAfAfAfAfAfAf  - - - - - - - - - - - M - - - Z - - - I - - - - - - - - - - -   - - - - - - - - - - M - - - - Z - - - - I - - - - - - - - - -   - - - - - - - - - M - - - - - Z - - - - - I - - - - - - - - -   - - - - - - - - M - - - - - - Z - - - - - - I - - - - - - - -   - - - - - - - M - - - - - - - Z - - - - - - - I - - - - - - -   - - - - - - M - - - - - - - - Z - - - - - - - - I - - - - - -   - - - - - M - - - - - - - - - Z - - - - - - - - - I - - - - -   - - - - Am- - - - - - - - - - Z - - - - - - - - - - Ap- - - -   - - - Am- - - - - - - - - - - Z - - - - - - - - - - - Ap- - -   - - Am- - - - - - - - - - - - Z - - - - - - - - - - - - Ap- -   - Am- - - - - - - - - - - - - Z - - - - - - - - - - - - - Ap-   Am- - - - - - - - - - - - - - Z - - - - - - - - - - - - - - Ap  
- - - - - - - - - - - - - - - - - - - - - - - - - - - - - - -   - As- - - - - - - - - - - - - Ac- - - - - - - - - - - - - An-   - - As- - - - - - - - - - - - Ac- - - - - - - - - - - - An- -   - - - As- - - - - - - - - - - Ac- - - - - - - - - - - An- - -   - - - - As- - - - - - - - - - Ac- - - - - - - - - - An- - - -   - - - - - K - - - - - - - - - Ac- - - - - - - - - F - - - - -   - - - - - - K - - - - - - - - Ac- - - - - - - - F - - - - - -   - - - - - - - K - - - - - - - Ac- - - - - - - F - - - - - - -   - - - - - - - - K - - - - - - Ac- - - - - - F - - - - - - - -   - - - - - - - - - K - - - - - Ac- - - - - F - - - - - - - - -   - - - - - - - - - - K - - - - Ac- - - - F - - - - - - - - - -   - Y Y Y Y Y Y Y Y Y Y K K K K A F F F F Q Q Q Q Q Q Q Q Q Q -   - - - - - - - - - - - - Ah- - Au- - Ag- - - - - - - - - - - -   - - - - - - - - - - - - - Ah- Au- Ag- - - - - - - - - - - - -   - - - - - - - - - - - - - - AhA Ag- - - - - - - - - - - - - -   - D D D D D D D D D D D D D A A A B B B B B B B B B B B B B -   - - - - - - - - - - - - - - U A V - - - - - - - - - - - - - -   - - - - - - - - - - - - - U - Av- V - - - - - - - - - - - - -   - - - - - - - - - - - - U - - Av- - V - - - - - - - - - - - -   - AkAkAkAkAkAkAkAkAkAkM M M M A I I I I AfAfAfAfAfAfAfAfAfAf-   - - - - - - - - - - M - - - - Z - - - - I - - - - - - - - - -   - - - - - - - - - M - - - - - Z - - - - - I - - - - - - - - -   - - - - - - - - M - - - - - - Z - - - - - - I - - - - - - - -   - - - - - - - M - - - - - - - Z - - - - - - - I - - - - - - -   - - - - - - M - - - - - - - - Z - - - - - - - - I - - - - - -   - - - - - M - - - - - - - - - Z - - - - - - - - - I - - - - -   - - - - Am- - - - - - - - - - Z - - - - - - - - - - Ap- - - -   - - - Am- - - - - - - - - - - Z - - - - - - - - - - - Ap- - -   - - Am- - - - - - - - - - - - Z - - - - - - - - - - - - Ap- -   - Am- - - - - - - - - - - - - Z - - - - - - - - - - - - - Ap-   - - - - - - - - - - - - - - - - - - - - - - - - - - - - - - -   
- - - - - - - - - - - - - - - - - - - - - - - - - - - - - - -   - As- - - - - - - - - - - - - Ac- - - - - - - - - - - - - An-   - - As- - - - - - - - - - - - Ac- - - - - - - - - - - - An- -   - - - As- - - - - - - - - - - Ac- - - - - - - - - - - An- - -   - - - - As- - - - - - - - - - Ac- - - - - - - - - - An- - - -   - - - - - K - - - - - - - - - Ac- - - - - - - - - F - - - - -   - - - - - - K - - - - - - - - Ac- - - - - - - - F - - - - - -   - - - - - - - K - - - - - - - Ac- - - - - - - F - - - - - - -   - - - - - - - - K - - - - - - Ac- - - - - - F - - - - - - - -   - - - - - - - - - K - - - - - Ac- - - - - F - - - - - - - - -   - Y Y Y Y Y Y Y Y Y K K K K K A F F F F F Q Q Q Q Q Q Q Q Q -   - - - - - - - - - - - Ah- - - Au- - - Ag- - - - - - - - - - -   - - - - - - - - - - - - Ah- - Au- - Ag- - - - - - - - - - - -   - - - - - - - - - - - - - Ah- Au- Ag- - - - - - - - - - - - -   - - - - - - - - - - - - - - AhA Ag- - - - - - - - - - - - - -   - D D D D D D D D D D D D D A A A B B B B B B B B B B B B B -   - - - - - - - - - - - - - - U A V - - - - - - - - - - - - - -   - - - - - - - - - - - - - U - Av- V - - - - - - - - - - - - -   - - - - - - - - - - - - U - - Av- - V - - - - - - - - - - - -   - - - - - - - - - - - U - - - Av- - - V - - - - - - - - - - -   - AkAkAkAkAkAkAkAkAkM M M M M A I I I I I AfAfAfAfAfAfAfAfAf-   - - - - - - - - - M - - - - - Z - - - - - I - - - - - - - - -   - - - - - - - - M - - - - - - Z - - - - - - I - - - - - - - -   - - - - - - - M - - - - - - - Z - - - - - - - I - - - - - - -   - - - - - - M - - - - - - - - Z - - - - - - - - I - - - - - -   - - - - - M - - - - - - - - - Z - - - - - - - - - I - - - - -   - - - - Am- - - - - - - - - - Z - - - - - - - - - - Ap- - - -   - - - Am- - - - - - - - - - - Z - - - - - - - - - - - Ap- - -   - - Am- - - - - - - - - - - - Z - - - - - - - - - - - - Ap- -   - Am- - - - - - - - - - - - - Z - - - - - - - - - - - - - Ap-   - - - - - - - - - - - - - - - - - - - - - - - - - - - - - - -   
- - - - - - - - - - - - - - - - - - - - - - - - - - - - - - -   - As- - - - - - - - - - - - - Ac- - - - - - - - - - - - - An-   - - As- - - - - - - - - - - - Ac- - - - - - - - - - - - An- -   - - - As- - - - - - - - - - - Ac- - - - - - - - - - - An- - -   - - - - As- - - - - - - - - - Ac- - - - - - - - - - An- - - -   - - - - - K - - - - - - - - - Ac- - - - - - - - - F - - - - -   - - - - - - K - - - - - - - - Ac- - - - - - - - F - - - - - -   - - - - - - - K - - - - - - - Ac- - - - - - - F - - - - - - -   - - - - - - - - K - - - - - - Ac- - - - - - F - - - - - - - -   - Y Y Y Y Y Y Y Y K K K K K K A F F F F F F Q Q Q Q Q Q Q Q -   - - - - - - - - - - Ah- - - - Au- - - - Ag- - - - - - - - - -   - - - - - - - - - - - Ah- - - Au- - - Ag- - - - - - - - - - -   - - - - - - - - - - - - Ah- - Au- - Ag- - - - - - - - - - - -   - - - - - - - - - - - - - Ah- Au- Ag- - - - - - - - - - - - -   - - - - - - - - - - - - - - AhA Ag- - - - - - - - - - - - - -   - D D D D D D D D D D D D D A A A B B B B B B B B B B B B B -   - - - - - - - - - - - - - - U A V - - - - - - - - - - - - - -   - - - - - - - - - - - - - U - Av- V - - - - - - - - - - - - -   - - - - - - - - - - - - U - - Av- - V - - - - - - - - - - - -   - - - - - - - - - - - U - - - Av- - - V - - - - - - - - - - -   - - - - - - - - - - U - - - - Av- - - - V - - - - - - - - - -   - AkAkAkAkAkAkAkAkM M M M M M A I I I I I I AfAfAfAfAfAfAfAf-   - - - - - - - - M - - - - - - Z - - - - - - I - - - - - - - -   - - - - - - - M - - - - - - - Z - - - - - - - I - - - - - - -   - - - - - - M - - - - - - - - Z - - - - - - - - I - - - - - -   - - - - - M - - - - - - - - - Z - - - - - - - - - I - - - - -   - - - - Am- - - - - - - - - - Z - - - - - - - - - - Ap- - - -   - - - Am- - - - - - - - - - - Z - - - - - - - - - - - Ap- - -   - - Am- - - - - - - - - - - - Z - - - - - - - - - - - - Ap- -   - Am- - - - - - - - - - - - - Z - - - - - - - - - - - - - Ap-   - - - - - - - - - - - - - - - - - - - - - - - - - - - - - - -   
- - - - - - - - - - - - - - - - - - - - - - - - - - - - - - -   - - - - - - - - - - - - - - - - - - - - - - - - - - - - - - -   - - As- - - - - - - - - - - - Ac- - - - - - - - - - - - An- -   - - - As- - - - - - - - - - - Ac- - - - - - - - - - - An- - -   - - - - As- - - - - - - - - - Ac- - - - - - - - - - An- - - -   - - - - - K - - - - - - - - - Ac- - - - - - - - - F - - - - -   - - - - - - K - - - - - - - - Ac- - - - - - - - F - - - - - -   - - - - - - - K - - - - - - - Ac- - - - - - - F - - - - - - -   - - Y Y Y Y Y Y K K K K K K K A F F F F F F F Q Q Q Q Q Q - -   - - - - - - - - - Ah- - - - - Au- - - - - Ag- - - - - - - - -   - - - - - - - - - - Ah- - - - Au- - - - Ag- - - - - - - - - -   - - - - - - - - - - - Ah- - - Au- - - Ag- - - - - - - - - - -   - - - - - - - - - - - - Ah- - Au- - Ag- - - - - - - - - - - -   - - - - - - - - - - - - - Ah- Au- Ag- - - - - - - - - - - - -   - - - - - - - - - - - - - - AhA Ag- - - - - - - - - - - - - -   - - D D D D D D D D D D D D A A A B B B B B B B B B B B B - -   - - - - - - - - - - - - - - U A V - - - - - - - - - - - - - -   - - - - - - - - - - - - - U - Av- V - - - - - - - - - - - - -   - - - - - - - - - - - - U - - Av- - V - - - - - - - - - - - -   - - - - - - - - - - - U - - - Av- - - V - - - - - - - - - - -   - - - - - - - - - - U - - - - Av- - - - V - - - - - - - - - -   - - - - - - - - - U - - - - - Av- - - - - V - - - - - - - - -   - - AkAkAkAkAkAkM M M M M M M A I I I I I I I AfAfAfAfAfAf- -   - - - - - - - M - - - - - - - Z - - - - - - - I - - - - - - -   - - - - - - M - - - - - - - - Z - - - - - - - - I - - - - - -   - - - - - M - - - - - - - - - Z - - - - - - - - - I - - - - -   - - - - Am- - - - - - - - - - Z - - - - - - - - - - Ap- - - -   - - - Am- - - - - - - - - - - Z - - - - - - - - - - - Ap- - -   - - Am- - - - - - - - - - - - Z - - - - - - - - - - - - Ap- -   - - - - - - - - - - - - - - - - - - - - - - - - - - - - - - -   - - - - - - - - - - - - - - - - - - - - - - - - - - - - - - -   
- - - - - - - - - - - - - - - - - - - - - - - - - - - - - - -   - - - - - - - - - - - - - - - - - - - - - - - - - - - - - - -   - - As- - - - - - - - - - - - Ac- - - - - - - - - - - - An- -   - - - As- - - - - - - - - - - Ac- - - - - - - - - - - An- - -   - - - - As- - - - - - - - - - Ac- - - - - - - - - - An- - - -   - - - - - K - - - - - - - - - Ac- - - - - - - - - F - - - - -   - - - - - - K - - - - - - - - Ac- - - - - - - - F - - - - - -   - - Y Y Y Y Y K K K K K K K K A F F F F F F F F Q Q Q Q Q - -   - - - - - - - - Ah- - - - - - Au- - - - - - Ag- - - - - - - -   - - - - - - - - - Ah- - - - - Au- - - - - Ag- - - - - - - - -   - - - - - - - - - - Ah- - - - Au- - - - Ag- - - - - - - - - -   - - - - - - - - - - - Ah- - - Au- - - Ag- - - - - - - - - - -   - - - - - - - - - - - - Ah- - Au- - Ag- - - - - - - - - - - -   - - - - - - - - - - - - - Ah- Au- Ag- - - - - - - - - - - - -   - - - - - - - - - - - - - - AhA Ag- - - - - - - - - - - - - -   - - D D D D D D D D D D D D A A A B B B B B B B B B B B B - -   - - - - - - - - - - - - - - U A V - - - - - - - - - - - - - -   - - - - - - - - - - - - - U - Av- V - - - - - - - - - - - - -   - - - - - - - - - - - - U - - Av- - V - - - - - - - - - - - -   - - - - - - - - - - - U - - - Av- - - V - - - - - - - - - - -   - - - - - - - - - - U - - - - Av- - - - V - - - - - - - - - -   - - - - - - - - - U - - - - - Av- - - - - V - - - - - - - - -   - - - - - - - - U - - - - - - Av- - - - - - V - - - - - - - -   - - AkAkAkAkAkM M M M M M M M A I I I I I I I I AfAfAfAfAf- -   - - - - - - M - - - - - - - - Z - - - - - - - - I - - - - - -   - - - - - M - - - - - - - - - Z - - - - - - - - - I - - - - -   - - - - Am- - - - - - - - - - Z - - - - - - - - - - Ap- - - -   - - - Am- - - - - - - - - - - Z - - - - - - - - - - - Ap- - -   - - Am- - - - - - - - - - - - Z - - - - - - - - - - - - Ap- -   - - - - - - - - - - - - - - - - - - - - - - - - - - - - - - -   - - - - - - - - - - - - - - - - - - - - - - - - - - - - - - -   
- - - - - - - - - - - - - - - - - - - - - - - - - - - - - - -   - - - - - - - - - - - - - - - - - - - - - - - - - - - - - - -   - - - - - - - - - - - - - - - - - - - - - - - - - - - - - - -   - - - As- - - - - - - - - - - Ac- - - - - - - - - - - An- - -   - - - - As- - - - - - - - - - Ac- - - - - - - - - - An- - - -   - - - - - K - - - - - - - - - Ac- - - - - - - - - F - - - - -   - - - Y Y Y K K K K K K K K K A F F F F F F F F F Q Q Q - - -   - - - - - - - Ah- - - - - - - Au- - - - - - - Ag- - - - - - -   - - - - - - - - Ah- - - - - - Au- - - - - - Ag- - - - - - - -   - - - - - - - - - Ah- - - - - Au- - - - - Ag- - - - - - - - -   - - - - - - - - - - Ah- - - - Au- - - - Ag- - - - - - - - - -   - - - - - - - - - - - Ah- - - Au- - - Ag- - - - - - - - - - -   - - - - - - - - - - - - Ah- - Au- - Ag- - - - - - - - - - - -   - - - - - - - - - - - - - Ah- Au- Ag- - - - - - - - - - - - -   - - - - - - - - - - - - - - AhA Ag- - - - - - - - - - - - - -   - - - D D D D D D D D D D D A A A B B B B B B B B B B B - - -   - - - - - - - - - - - - - - U A V - - - - - - - - - - - - - -   - - - - - - - - - - - - - U - Av- V - - - - - - - - - - - - -   - - - - - - - - - - - - U - - Av- - V - - - - - - - - - - - -   - - - - - - - - - - - U - - - Av- - - V - - - - - - - - - - -   - - - - - - - - - - U - - - - Av- - - - V - - - - - - - - - -   - - - - - - - - - U - - - - - Av- - - - - V - - - - - - - - -   - - - - - - - - U - - - - - - Av- - - - - - V - - - - - - - -   - - - - - - - U - - - - - - - Av- - - - - - - V - - - - - - -   - - - AkAkAkM M M M M M M M M A I I I I I I I I I AfAfAf- - -   - - - - - M - - - - - - - - - Z - - - - - - - - - I - - - - -   - - - - Am- - - - - - - - - - Z - - - - - - - - - - Ap- - - -   - - - Am- - - - - - - - - - - Z - - - - - - - - - - - Ap- - -   - - - - - - - - - - - - - - - - - - - - - - - - - - - - - - -   - - - - - - - - - - - - - - - - - - - - - - - - - - - - - - -   - - - - - - - - - - - - - - - - - - - - - - - - - - - - - - -   
- - - - - - - - - - - - - - - - - - - - - - - - - - - - - - -   - - - - - - - - - - - - - - - - - - - - - - - - - - - - - - -   - - - - - - - - - - - - - - - - - - - - - - - - - - - - - - -   - - - - - - - - - - - - - - - - - - - - - - - - - - - - - - -   - - - - As- - - - - - - - - - Ac- - - - - - - - - - An- - - -   - - - - Y K K K K K K K K K K A F F F F F F F F F F Q - - - -   - - - - - - Ah- - - - - - - - Au- - - - - - - - Ag- - - - - -   - - - - - - - Ah- - - - - - - Au- - - - - - - Ag- - - - - - -   - - - - - - - - Ah- - - - - - Au- - - - - - Ag- - - - - - - -   - - - - - - - - - Ah- - - - - Au- - - - - Ag- - - - - - - - -   - - - - - - - - - - Ah- - - - Au- - - - Ag- - - - - - - - - -   - - - - - - - - - - - Ah- - - Au- - - Ag- - - - - - - - - - -   - - - - - - - - - - - - Ah- - Au- - Ag- - - - - - - - - - - -   - - - - - - - - - - - - - Ah- Au- Ag- - - - - - - - - - - - -   - - - - - - - - - - - - - - AhA Ag- - - - - - - - - - - - - -   - - - - D D D D D D D D D D A A A B B B B B B B B B B - - - -   - - - - - - - - - - - - - - U A V - - - - - - - - - - - - - -   - - - - - - - - - - - - - U - Av- V - - - - - - - - - - - - -   - - - - - - - - - - - - U - - Av- - V - - - - - - - - - - - -   - - - - - - - - - - - U - - - Av- - - V - - - - - - - - - - -   - - - - - - - - - - U - - - - Av- - - - V - - - - - - - - - -   - - - - - - - - - U - - - - - Av- - - - - V - - - - - - - - -   - - - - - - - - U - - - - - - Av- - - - - - V - - - - - - - -   - - - - - - - U - - - - - - - Av- - - - - - - V - - - - - - -   - - - - - - U - - - - - - - - Av- - - - - - - - V - - - - - -   - - - - AkM M M M M M M M M M A I I I I I I I I I I Af- - - -   - - - - Am- - - - - - - - - - Z - - - - - - - - - - Ap- - - -   - - - - - - - - - - - - - - - - - - - - - - - - - - - - - - -   - - - - - - - - - - - - - - - - - - - - - - - - - - - - - - -   - - - - - - - - - - - - - - - - - - - - - - - - - - - - - - -   - - - - - - - - - - - - - - - - - - - - - - - - - - - - - - -   
- - - - - - - - - - - - - - - - - - - - - - - - - - - - - - -   - - - - - - - - - - - - - - - - - - - - - - - - - - - - - - -   - - - - - - - - - - - - - - - - - - - - - - - - - - - - - - -   - - - - - - - - - - - - - - - - - - - - - - - - - - - - - - -   - - - - - ArArArArArArArArArArArArArArArArArArArArAr- - - - -   - - - - - Ah- - - - - - - - - Au- - - - - - - - - Ag- - - - -   - - - - - - Ah- - - - - - - - Au- - - - - - - - Ag- - - - - -   - - - - - - - Ah- - - - - - - Au- - - - - - - Ag- - - - - - -   - - - - - - - - Ah- - - - - - Au- - - - - - Ag- - - - - - - -   - - - - - - - - - Ah- - - - - Au- - - - - Ag- - - - - - - - -   - - - - - - - - - - Ah- - - - Au- - - - Ag- - - - - - - - - -   - - - - - - - - - - - Ah- - - Au- - - Ag- - - - - - - - - - -   - - - - - - - - - - - - Ah- - Au- - Ag- - - - - - - - - - - -   - - - - - - - - - - - - - Ah- Au- Ag- - - - - - - - - - - - -   - - - - - - - - - - - - - - AhA Ag- - - - - - - - - - - - - -   - - - - - D D D D D D D D D A A A B B B B B B B B B - - - - -   - - - - - - - - - - - - - - U A V - - - - - - - - - - - - - -   - - - - - - - - - - - - - U - Av- V - - - - - - - - - - - - -   - - - - - - - - - - - - U - - Av- - V - - - - - - - - - - - -   - - - - - - - - - - - U - - - Av- - - V - - - - - - - - - - -   - - - - - - - - - - U - - - - Av- - - - V - - - - - - - - - -   - - - - - - - - - U - - - - - Av- - - - - V - - - - - - - - -   - - - - - - - - U - - - - - - Av- - - - - - V - - - - - - - -   - - - - - - - U - - - - - - - Av- - - - - - - V - - - - - - -   - - - - - - U - - - - - - - - Av- - - - - - - - V - - - - - -   - - - - - U - - - - - - - - - Av- - - - - - - - - V - - - - -   - - - - - AqAqAqAqAqAqAqAqAqAqAqAqAqAqAqAqAqAqAqAqAq- - - - -   - - - - - - - - - - - - - - - - - - - - - - - - - - - - - - -   - - - - - - - - - - - - - - - - - - - - - - - - - - - - - - -   - - - - - - - - - - - - - - - - - - - - - - - - - - - - - - -   - - - - - - - - - - - - - - - - - - - - - - - - - - - - - - -   
- - - - - - - - - - - - - - - - - - - - - - - - - - - - - - -   - - - - - - - - - - - - - - - - - - - - - - - - - - - - - - -   - - - - - - - - - - - - - - - - - - - - - - - - - - - - - - -   - - - - - - ArArArArArArArArArArArArArArArArArArAr- - - - - -   - - - - - - - - - - - - - - - - - - - - - - - - - - - - - - -   - - - - - - - - - - - - - - - - - - - - - - - - - - - - - - -   - - - - - - Ah- - - - - - - - Au- - - - - - - - Ag- - - - - -   - - - - - - - Ah- - - - - - - Au- - - - - - - Ag- - - - - - -   - - - - - - - - Ah- - - - - - Au- - - - - - Ag- - - - - - - -   - - - - - - - - - Ah- - - - - Au- - - - - Ag- - - - - - - - -   - - - - - - - - - - Ah- - - - Au- - - - Ag- - - - - - - - - -   - - - - - - - - - - - Ah- - - Au- - - Ag- - - - - - - - - - -   - - - - - - - - - - - - Ah- - Au- - Ag- - - - - - - - - - - -   - - - - - - - - - - - - - Ah- Au- Ag- - - - - - - - - - - - -   - - - - - - - - - - - - - - AhA Ag- - - - - - - - - - - - - -   - - - - - - D D D D D D D D A A A B B B B B B B B - - - - - -   - - - - - - - - - - - - - - U A V - - - - - - - - - - - - - -   - - - - - - - - - - - - - U - Av- V - - - - - - - - - - - - -   - - - - - - - - - - - - U - - Av- - V - - - - - - - - - - - -   - - - - - - - - - - - U - - - Av- - - V - - - - - - - - - - -   - - - - - - - - - - U - - - - Av- - - - V - - - - - - - - - -   - - - - - - - - - U - - - - - Av- - - - - V - - - - - - - - -   - - - - - - - - U - - - - - - Av- - - - - - V - - - - - - - -   - - - - - - - U - - - - - - - Av- - - - - - - V - - - - - - -   - - - - - - U - - - - - - - - Av- - - - - - - - V - - - - - -   - - - - - - - - - - - - - - - - - - - - - - - - - - - - - - -   - - - - - - - - - - - - - - - - - - - - - - - - - - - - - - -   - - - - - - AqAqAqAqAqAqAqAqAqAqAqAqAqAqAqAqAqAqAq- - - - - -   - - - - - - - - - - - - - - - - - - - - - - - - - - - - - - -   - - - - - - - - - - - - - - - - - - - - - - - - - - - - - - -   - - - - - - - - - - - - - - - - - - - - - - - - - - - - - - -   
- - - - - - - - - - - - - - - - - - - - - - - - - - - - - - -   - - - - - - - - - - - - - - - - - - - - - - - - - - - - - - -   - - - - - - - ArArArArArArArArArArArArArArArArAr- - - - - - -   - - - - - - - - - - - - - - - - - - - - - - - - - - - - - - -   - - - - - - - - - - - - - - - - - - - - - - - - - - - - - - -   - - - - - - - - - - - - - - - - - - - - - - - - - - - - - - -   - - - - - - - - - - - - - - - - - - - - - - - - - - - - - - -   - - - - - - - Ah- - - - - - - Au- - - - - - - Ag- - - - - - -   - - - - - - - - Ah- - - - - - Au- - - - - - Ag- - - - - - - -   - - - - - - - - - Ah- - - - - Au- - - - - Ag- - - - - - - - -   - - - - - - - - - - Ah- - - - Au- - - - Ag- - - - - - - - - -   - - - - - - - - - - - Ah- - - Au- - - Ag- - - - - - - - - - -   - - - - - - - - - - - - Ah- - Au- - Ag- - - - - - - - - - - -   - - - - - - - - - - - - - Ah- Au- Ag- - - - - - - - - - - - -   - - - - - - - - - - - - - - AhA Ag- - - - - - - - - - - - - -   - - - - - - - D D D D D D D A A A B B B B B B B - - - - - - -   - - - - - - - - - - - - - - U A V - - - - - - - - - - - - - -   - - - - - - - - - - - - - U - Av- V - - - - - - - - - - - - -   - - - - - - - - - - - - U - - Av- - V - - - - - - - - - - - -   - - - - - - - - - - - U - - - Av- - - V - - - - - - - - - - -   - - - - - - - - - - U - - - - Av- - - - V - - - - - - - - - -   - - - - - - - - - U - - - - - Av- - - - - V - - - - - - - - -   - - - - - - - - U - - - - - - Av- - - - - - V - - - - - - - -   - - - - - - - U - - - - - - - Av- - - - - - - V - - - - - - -   - - - - - - - - - - - - - - - - - - - - - - - - - - - - - - -   - - - - - - - - - - - - - - - - - - - - - - - - - - - - - - -   - - - - - - - - - - - - - - - - - - - - - - - - - - - - - - -   - - - - - - - - - - - - - - - - - - - - - - - - - - - - - - -   - - - - - - - AqAqAqAqAqAqAqAqAqAqAqAqAqAqAqAqAq- - - - - - -   - - - - - - - - - - - - - - - - - - - - - - - - - - - - - - -   - - - - - - - - - - - - - - - - - - - - - - - - - - - - - - -   
- - - - - - - - - - - - - - - - - - - - - - - - - - - - - - -   - - - - - - - - - ArArArArArArArArArArArArAr- - - - - - - - -   - - - - - - - - - - - - - - - - - - - - - - - - - - - - - - -   - - - - - - - - - - - - - - - - - - - - - - - - - - - - - - -   - - - - - - - - - - - - - - - - - - - - - - - - - - - - - - -   - - - - - - - - - - - - - - - - - - - - - - - - - - - - - - -   - - - - - - - - - - - - - - - - - - - - - - - - - - - - - - -   - - - - - - - - - - - - - - - - - - - - - - - - - - - - - - -   - - - - - - - - - - - - - - - - - - - - - - - - - - - - - - -   - - - - - - - - - Ah- - - - - Au- - - - - Ag- - - - - - - - -   - - - - - - - - - - Ah- - - - Au- - - - Ag- - - - - - - - - -   - - - - - - - - - - - Ah- - - Au- - - Ag- - - - - - - - - - -   - - - - - - - - - - - - Ah- - Au- - Ag- - - - - - - - - - - -   - - - - - - - - - - - - - Ah- Au- Ag- - - - - - - - - - - - -   - - - - - - - - - - - - - - AhA Ag- - - - - - - - - - - - - -   - - - - - - - - - D D D D D A BbA B B B B B - - - - - - - - -   - - - - - - - - - - - - - - U A V - - - - - - - - - - - - - -   - - - - - - - - - - - - - U - Av- V - - - - - - - - - - - - -   - - - - - - - - - - - - U - - Av- - V - - - - - - - - - - - -   - - - - - - - - - - - U - - - Av- - - V - - - - - - - - - - -   - - - - - - - - - - U - - - - Av- - - - V - - - - - - - - - -   - - - - - - - - - U - - - - - Av- - - - - V - - - - - - - - -   - - - - - - - - - - - - - - - - - - - - - - - - - - - - - - -   - - - - - - - - - - - - - - - - - - - - - - - - - - - - - - -   - - - - - - - - - - - - - - - - - - - - - - - - - - - - - - -   - - - - - - - - - - - - - - - - - - - - - - - - - - - - - - -   - - - - - - - - - - - - - - - - - - - - - - - - - - - - - - -   - - - - - - - - - - - - - - - - - - - - - - - - - - - - - - -   - - - - - - - - - - - - - - - - - - - - - - - - - - - - - - -   - - - - - - - - - AqAqAqAqAqAqAqAqAqAqAqAqAq- - - - - - - - -   - - - - - - - - - - - - - - - - - - - - - - - - - - - - - - -   
- - - - - - - - - - - - ArArArArArArAr- - - - - - - - - - - -   - - - - - - - - - - - - - - - - - - - - - - - - - - - - - - -   - - - - - - - - - - - - - - - - - - - - - - - - - - - - - - -   - - - - - - - - - - - - - - - - - - - - - - - - - - - - - - -   - - - - - - - - - - - - - - - - - - - - - - - - - - - - - - -   - - - - - - - - - - - - - - - - - - - - - - - - - - - - - - -   - - - - - - - - - - - - - - - - - - - - - - - - - - - - - - -   - - - - - - - - - - - - - - - - - - - - - - - - - - - - - - -   - - - - - - - - - - - - - - - - - - - - - - - - - - - - - - -   - - - - - - - - - - - - - - - - - - - - - - - - - - - - - - -   - - - - - - - - - - - - - - - - - - - - - - - - - - - - - - -   - - - - - - - - - - - - - - - - - - - - - - - - - - - - - - -   - - - - - - - - - - - - Ah- - Au- - Ag- - - - - - - - - - - -   - - - - - - - - - - - - - BbBbAuBbBb- - - - - - - - - - - - -   - - - - - - - - - - - - - - BbBbBb- - - - - - - - - - - - - -   - - - - - - - - - - - - D D D BbB B B - - - - - - - - - - - -   - - - - - - - - - - - - - - U BbV - - - - - - - - - - - - - -   - - - - - - - - - - - - - U - Av- V - - - - - - - - - - - - -   - - - - - - - - - - - - U - - Av- - V - - - - - - - - - - - -   - - - - - - - - - - - - - - - - - - - - - - - - - - - - - - -   - - - - - - - - - - - - - - - - - - - - - - - - - - - - - - -   - - - - - - - - - - - - - - - - - - - - - - - - - - - - - - -   - - - - - - - - - - - - - - - - - - - - - - - - - - - - - - -   - - - - - - - - - - - - - - - - - - - - - - - - - - - - - - -   - - - - - - - - - - - - - - - - - - - - - - - - - - - - - - -   - - - - - - - - - - - - - - - - - - - - - - - - - - - - - - -   - - - - - - - - - - - - - - - - - - - - - - - - - - - - - - -   - - - - - - - - - - - - - - - - - - - - - - - - - - - - - - -   - - - - - - - - - - - - - - - - - - - - - - - - - - - - - - -   - - - - - - - - - - - - - - - - - - - - - - - - - - - - - - -   - - - - - - - - - - - - AqAqAqAqAqAqAq- - - - - - - - - - - -   
