model
size = 32 31 18, scale = 0.05, origin = -y
material 
  colors = A:#FFC408 B:#E81B00 C:#FFCC24 D:#FFB200 E:#111 F:#DDD23B G:#F9BF45 H:#EFBB24
voxels
614-2C3A2CA5-2C2ACAC11-2(CA)2CA3C2-3CA2C2(AC)9-A6C2(AC)2-CA2CACA2C2A8-5A2C3AC2-2(3CA)2CA8-2A2(3CA)4-A8CA8-9A6-8AC589-2(C2A)2-2ACA2C17-A2(C2A)2-5ACA48-3CAC2A2-2ACA2CA15-2ACA3CA2-2(AC)2A2C43-D2A2CACA2C2A4CACA4CD8-D22CD8-DC7A5C8ACD8-DC8A4C8ACD8-D22AD8-D10A2-10AD8-DCAC2A2CA6-2A2(2CA)D8-4D2E3D6-4D2E3D2(11-E2BE)13-E2BE11-E2BE14-2E13-2E274-A3C2-2ACA21-2C3A2-A2C2A52-2CACA2-2A2CA19-C2A2CA2-4A2C47-D6AC4AC7A11-D7ACA2CAC7AD10-DCA2CA3C5A7CD10-D9A2CAC7AD9-DC20AD9-D9CA2CA8CAD8-C2A4C8AC8A8-2A21-C8-A22-C104-A22-A8-D16-6AD9-2E4BD8-DCA2BAE12-C2BF11-C2BC14-2B13-DE15-2B13-2B179-8D23-D3A2C3AD21-DAC8AD18-2D3ACA2C3ACA2D15-D5C5A7C14-C5ACA2CAC4A2CD12-D6AC4AC5A2C12-D6C2A2C2A7C12-20AD10-D20-A10-C20-A9-DA20-C9-3A20-D8-CA21-A8-CA21-C8-CA21-A200-E6A9-7AE9-DC4BD8-DFA2BC2D10-AE2BED8-DCE2BE-D12-2B13-2B15-2B13-2B239-2(D14-A)16-AD12-DA16-CA12-2A16-2A12-3A15-2AD10-D2A17-2C10-C20-C9-DC20-AD8-2C20-AD8-3A20-2(A8-2A21-)C8-CA21-A198-2EA22-A3E5-A19-2A-3D7-D3A14-3AE2D9-E4BE8-DE4B14-2B13-2B239-A14-AD14-D2(16-2A12-2A)16-2AD10-D2A16-C2A10-3A17-AC9-DA20-AD2(8-2C20-AC)8-C2A20-A3(8-2A21-C)197-E3A22-3ACE2-D2A22-2A2D4-D5A15-4AD7-2DE4BE8-E5BED12-2B13-2B239-A14-AD14-D16-2A12-2A16-CAD10-D2A16-2AC10-3A16-G2A9-DC2A17-2AD8-2C2(20-AC8-CA)20-AC8-C2A20-2(C8-CA21-)A8-CA21-C196-E4A22-4AE-2D2A22-2A2D4-D5A15-4AD7-2DE4BE8-E5BED12-2B13-2B239-A14-CD14-D16-CA12-2A16-2AD10-DAC16-2AC10-2AC16-C2A9-DC2A17-2AD2(8-2C20-AC)8-CA20-2C8-C2A20-C8-2A21-A8-CA21-C8-2A21-C196-E4A22-4AE-2D2A22-2A2D4-D5A15-4AD7-2DE4BE8-E5BED12-2B12-3B239-A14-AD14-D2(16-CA12-2A)16-2AD10-DAC16-3A10-C2A17-2A9-DC20-AD8-2C20-AC8-2C20-2C8-C2A20-C8-CA21-A8-CA21-C8-2A21-C192-A4-E3A22-2A2E3-D2A22-A2D5-D4A16-2ACAD7-2DE4BE8-E5BED12-2B12-3B239-D2A10-3AD14-A16-2A12-DC16-2A2(12-AC16-CA)D11-DA17-AC10-C20-C9-DA20-AD8-CA20-AC8-C2A20-2(C8-2A21-)A8-2A21-C8-A183-A5-2E8A8-7A2E6-D3AC4A8-6ACD8-DE5BE8-E5BE2(12-3B)-E27-3B178-CAC4ACAC21-A3C2(AD)ACAF18-EB4AD3ADCA2FCD14-CE4AD5ADC2FCD14-CE11A2C-2CD12-DEB14AHCD12-DE17AD12-G18ACD11-D2AG12AG3AD10-C16AGABAD9-DCAG17AB2A8-DCG21A8-ADC21A8-AGC21A8-C13A-9A8-C2A20-A8-2A30-2(A31-)A22-A8-7A8-A7-D8-ED7A6-7AE10-E5BE8-E5BE2(12-3B)29-3B29-B182-2A2C2A-E21-2B2C3B3CF21-2BC5B2AF20-2BC6B2AF20-BC8ABA20-BC11A18-BC10AB2AH15-E2CB9AB2AEA13-E2C14AEAC12-E2(BC)2A2-6ABAEAC12-E17AECD11-E9A-7AECD10-2E17AECD9-E6A-7A-A-5AD8-AC12A-7ABC8-23AC3(8-C23A)8-E23A8-2E16A2C3AD8-E7BEA4-AE6BE10-6B11-3B14-4B11-3B29-2B213-8B22-10BE19-12BE20-2B-8BE20-12BE18-4B4AC4BE18-3B5A2C3BE17-4B6AC4B16-4B8AC3B17-3B9A3B16-BAB2C8ACBAB15-2B12AC2B15-2B11A2C2B13-3BC10A4C2BEC9-EBAB2AC7A-3CACBECD8-E2BCB10ABA2CA2BED8-E2BAC11ACA3CBEC8-EB3C11A6CEC8-EB2A3C10A5CEC9-B2A2B2AC5AC4A2CAE10-8B6E7BE10-6B8-B2-3B12-6B10-4B14-4B11-2B87-2B-B28-B2-2B27-5B27-6B24-4B-3B22-10B20-12B21-11B20-13B19-13B18-6B2A6B18-3B-2B2A7B17-6B2(3AC5B16-6BC)3A2C4B17-4BC6AC3B16-6B2CB3AC3B16-4BC2ABCACB2C3B14-5B2CBAB2CA2C3B14-4B3C2BACB-B2C2B14-5BAB2CBA4BC2B14-3B2CACA3C2A4C2B13-B5C4A2C2A5CB12-BC2B4C3A2CA5CB11-6B2F2B7F4B11-20B12-6B8-6B13-5B9-4B15-4B10-2B84-B2(4-B-B23-2B)3-2B2-B22-2B-3B3-B22-8B-B22-11B3(20-12B)20-3(13B19-)13B18-15B2(16-16B)17-15B15-18B14-18B2(15-17B)15-18B13-2(20B12-)2(19B13-)6B7-5B14-5B9-4B29-2B180-B3-B27-B3-B-B25-B3-2B3-B20-B-B4-B3-2(B20-4B3-2B2-)B20-5B2-2B2-3(B20-5B2-3B-)B20-6B-3B-B20-6B-5B19-7B-4B-B18-7B-6B17-15B17-4(16B16-)4(17B15-)5B7-5B28-3B212-4(B31-)B30-3B4-B23-4B4-B23-2(2B-B4-2B22-)2B-2B2(3-2B22-2B2-B)3-3B21-2B2-B3-3B21-3B-2B2-3B21-3B2-B2-3B20-2(4B2-B2-4B19-)4B3-B-5B18-5B2-B-5B18-6B-B-5B17-2B-3B2-7B17-2B-4B2-7B16-2B-B6-6B29-4B569-2(B31-)2(3(2B30-)2B31-)2(2B30-)2B171-
