model
size = 28 35 28, scale = 0.05, origin = -y
material 
  colors = A:#F06
voxels
684-4A22-7A21-8A21-5A863-5A21-3A4-3A17-2A7-3A15-3A8-2A16-3A5-4A17-8A832-9A17-2A9-2A14-2A12-2(A13-)2(2A12-)2A13-14A234-3A25-4A23-6A22-6A21-7A22-4A449-12A15-A12-2A12-A15-A11-A16-A9-2A16-A10-2A6-9A12-7A187-2A24-2A2-A22-2A4-3(A21-A5-)A21-2A3-2A23-3A421-11A15-2A11-3A11-A16-2A9-2(A18-A8-)A7-12A9-7A186-5A22-A5-2A20-A6-2(A19-A7-)A20-A6-A20-A5-A22-5A419-7A19-2A7-7A11-A10-5A-3A8-A10-4A5-A7-A9-6A5-A6-A7-3A4-3A3-A7-A4-2A10-4A7-5A136-3A22-3A2-2A20-A7-4(A18-A8-)A19-A6-A21-2A3-A24-3A391-4A22-2A4-3A18-A8-2A5-3A9-A8-2A4-3A-2A6-A8-2A6-2A3-A5-A8-A7-2A3-A6-A5-2A10-2A2-A6-5A14-2A118-6A21-A6-A19-A8-4(A17-A9-)A18-A7-A19-2A3-3A22-3A391-3A23-2A3-3A19-A7-2A18-A8-A9-2A2(7-A)10-4A5-A7-A10-A3-A4-A6-A11-2A2-A5-6A14-3A117-7A20-A7-A18-A9-2(A16-A10-)A16-2(A9-A17-)2A7-A20-A-5A22-A419-6A21-A6-A20-A7-A18-A8-A12-A5-A7-A12-4A4-A6-A12-A2-A4-3A2-2A14-A2-A6-2A17-3A88-7A20-A7-A18-5(A9-A17-)2A7-A20-7A441-5A21-2A5-A20-3(A7-A19-)A6-A14-3A4-2A3-A16-A-A5-3A17-A-A26-2A27-A32-8A19-A7-A18-A9-A17-3(A10-A16-)A10-A17-A8-A19-8A439-6A21-4(A6-A20-)A6-A21-A4-A16-3A4-4A17-3A26-A-A25-A-A26-2A4-7A19-2A7-A18-5(A9-A17-)2A8-A19-4A2-2A24-2A412-6A21-A5-A21-A6-A20-A6-A19-A7-A20-A6-A21-A4-A23-4A19-A26-3A25-A-A25-3A4-7A20-A7-A18-A9-A17-3(A10-A16-)A10-A17-A9-A18-3A4-2A22-4A384-A26-A-3A22-A5-A21-A6-2(A19-A7-)A20-A5-A21-2A3-2A23-3A76-2A26-2A5-7A20-A6-A19-A8-A18-3(A9-A17-)A9-A18-A8-A19-A6-2A20-4A-A26-A356-2A24-2A2-2A22-A5-A20-2(A7-A19-)A7-A20-A5-A21-A4-2A22-4A112-6A20-2A6-A18-A8-A18-A9-A17-2(A10-A16-)A9-A18-A8-A19-A7-A20-2A4-2A22-4A355-3A23-2A3-2A21-A5-A20-2(A7-A19-)A7-A20-A5-A21-2A3-2A23-3A113-3A23-2A3-3A19-A7-A19-A8-A18-2(A9-A17-)A9-2(A18-A8-)A19-A7-A20-2A3-2A23-3A326-6A21-A5-A21-A6-3(A19-A7-)A20-A5-A21-2A3-2A23-3A114-A25-2A-4A20-A6-A20-A7-A19-A8-2(A17-A9-)2(A18-A8-)A19-A7-A20-A6-A20-3A2-2A24-2A271-3A24-A3-2A21-A6-A20-A6-3(A19-A7-)A20-A5-A21-3A2-2A24-2A141-4A23-A4-2A20-A7-A19-2(A8-A18-)A9-A17-A8-A18-A8-A19-A7-2(A20-A6-)A20-3A2-2A23-4A25-2A188-2A25-A2-3A21-A5-A20-A6-A20-A7-A18-A8-A18-A7-A20-A6-A20-A5-2A21-3A-A26-A143-A25-2A-3A21-A6-A19-2(A8-A18-)2(A9-A17-)A9-A18-A8-A18-A7-2(A20-A6-)A20-2A4-2A20-3A2-2A22-5A23-4A25-2A26-2A25-2A23-5A22-A-4A21-A5-A19-2A6-A19-A7-2A18-A7-A19-A7-A18-A8-A19-A6-A20-A5-2A21-5A197-4A23-A4-2A20-A6-A20-2(A7-A19-)4(A8-A18-)4(A7-A19-)2A5-A20-2A4-2A20-3A2-2A21-2(3A2-2A20-)A5-2A19-A6-A19-A7-A18-A8-2A17-2(A8-A18-)2(A7-A19-)A6-A21-2A3-A24-3A225-5A21-2A5-A20-3(A7-A19-)4(A8-A18-)4(A7-A19-)A6-2(A19-A7-)A18-A7-A19-A7-A17-2A7-2A2(17-A8-A18-A8-A)18-A8-A18-A7-A20-A5-A21-3A-2A25-A228-A25-2A-2A22-A5-A21-A6-A19-A7-A19-4(A8-A18-)A8-A17-A9-A17-3(A8-A18-)A7-A18-A8-A17-A9-2(A17-A8-A18-A8-)A18-A8-A17-A8-A18-A8-A19-A6-A20-A4-2A22-4A283-A25-2A-3A21-2A4-A21-A6-A20-A6-A19-A7-A19-2(A8-A18-)A8-A17-A9-A17-2(A8-A18-)A8-2(A17-A8-A18-A8-A17-A9-)A17-2(A8-A18-)A7-A19-A7-A20-A4-2A21-5A338-A26-4A22-2A3-2A21-A6-A20-A6-4(A19-A7-)3(A18-A8-)2(A17-A9-A17-A8-A18-A8-)A17-A8-A18-A8-A19-A6-A20-A5-A21-6A26-A393-3A24-2A-3A21-2A4-2A20-A6-4(A19-A7-)2(A18-A8-)A18-A7-3(A18-A8-)A17-2(A8-A18-)A7-A19-A6-A21-A4-A22-5A477-A26-4A23-2A-3A21-2A3-2A20-2A5-3(A20-A6-)3(A19-A7-)A18-2(A7-A19-)2(A6-A20-)A5-A21-7A22-5A560-A26-3A24-5A22-2A-4A21-2A2-2(3A20-2A3-)2A21-A5-A2(20-2A4-2A)20-2A4-A21-2A2-3A21-6A22-6A698-A27-2A2(25-3A)24-5A23-3(4A24-)2A383-
