model
size = 10 35 31, scale = 0.05, origin = -y
material 
  colors = A:#F06
voxels
212-3A7-5(4A6-)3A8-A258-3A6-5A5-A3-2A11(4-A)3-2A4-2A-2A6-4A7-2A227-4A5-A3-A4-5(A5-A3-)A5-9(A4-)2A2-A6-3A207-4A5-A3-A4-8(A5-A3-)A5-7(A4-)A3-A6-4A186-3A6-A3-A4-10(A5-A3-)A5-7(A4-)2A-2A7-A177-5A4-5(A5-A3-)A5-10(A4-)2(A3-A5-)6(A4-)A5-4A37-A9-2(3A7-)2A97-4A5-A3-A4-4(A5-A3-)A5-3(A4-)5A5-5A2(6-4A)5-2A2-2A10(4-A)4-2A2-A7-2A18-3A6-A-3A2(5-A3-A)5-2A-2A7-A86-5A4-4(A5-A3-)A5-3(A4-)5A47-2A7-A2-A5-9(A4-)A5-4A16-5A3(4-A)5-A3-3(A4-)A5-4A85-5A4-4(A5-A3-)A5-A4-2A2-A7-2A58-2A6-2A2-2A8(4-A)5-4A7-2A7-A2-2A4-3(A5-A3-)A4-2A4-4A76-2A7-A2-2A4-4(A5-A3-)A5-A4-5A76-4A5-7(A4-)A5-4A7-4A4-2A3-A4-3(A5-A3-)A5-A4-5A75-3A5-2A3-A4-4(A5-A3-)A4-2A4-4A78-2A7-A2-2A6(4-A)5-4A6-5A4-4(A5-A3-)A5-A4-5A74-5A3(4-A)3(5-A3-A)5-A3-2A3-A6-3A79-A7-2A-2A6(4-A)5-4A6-5A4-A5-A3-A6-A2-2(A5-A3-)A5-A4-5A74-5A3(4-A)3(5-A3-A)5-A3-3A2-A7-2A87-4A5-5(A4-)A5-4A6-6A3-A5-A3-3(A6-A2-)A5-A4-5A74-5A4-4(A5-A3-)A5-A4-2A2-A7-2A87-4A6-A3-2(A4-)A5-A3-A5-4A6-6A3-A5-A3-3(A6-A2-)A5-2A3-5A74-5A4-4(A5-A3-)A5-A4-5A96-4A6-3(A3-A5-)4A6-6A3-4(A6-A2-)A6-A3-6A73-5A4-4(A5-A3-)A5-A4-5A97-4A3(5-A3-A)6-3A6-6A3-3(A6-A2-)A6-A3-A5-A3-3A2-A7-2A55-2A7-A2-2A4-4(A5-A3-)A5-A4-5A97-4A3(5-A3-A)6-3A7-5A2(4-A)3-3(A6-A2-)A6-A3-A4-2A4-4A55-3A6-A3-2A3-A5-A3-A6-A2-2(A5-A3-)A5-A4-5A89-A7-2A-A5-A3-A6-A2-A6-4A16-5A3(4-A)5-3(A2-A6-)A3-A5-A4-3A-A8-A45-4A4-2A4-A3-2(A6-A2-)A5-A3-A5-3(A4-)5A88-3A3(6-A2-A)7-3A17-3A5-2A3-A4-A5-A3-A5-2(A2-A6-)2(A3-A5-)A4-3A-A8-A26-2A6-2A2-2A3-A5-A3-3(A6-A2-)A5-A4-A3-2A5-3A89-3A2(6-A2-A)6-4A36-5A4-5(A5-A3-)A5-3(A4-)3A-A6-3A6-4A5-A2-2A4-A5-4(A2-A6-)A2-A5-2A3-3A-A8-A80-2A3(7-A-A)8-A37-5A3(4-A)6(5-A3-A)5-A2(3-2A)3-A4-3(A3-A5-)3(A2-A6-)A3-A4-A5-4A79-2A3(7-A-A)7-3A47-A8-A-3A4-2(A5-A3-)2(A6-A2-)3(A5-A3-)A5-3(A2-A6-)A2-A5-2(A2-A6-)A3-A5-A3-A4-A5-4A79-3A7-A-A7-2A8-2A67-3A6-A3-A4-2(A5-A3-)2(A6-A2-)A5-A3-A5-5(A2-A6-)A2-2(A5-A3-)A5-A4-5A79-2A7-A-A7-3A7-2A87-3A6-A3-A4-5(A5-A3-)A5-4(A2-A6-)A2-A5-A3-A5-A4-5A79-2(2A8-)2A116-3A6-A-3A4-2A4-5(A3-A5-)2(A2-A6-)A2-A5-3(A4-)5A6-3A71-A2(8-2A)136-A9-4A5-5A5-A2-2A4-2A3-7(A4-)A3-2A4-A-4A5-4A90-2A8-A176-2A8-3A6-2(5A5-)4A6-3A7-A94-2A7-3A338-2A8-A339-2A349-A110-
