model
size = 13 35 35, scale = 0.05, origin = -y
material 
  colors = A:#F06 B:#EEE C:#111
voxels
184-A2(11-2A)11-2(3A10-)2A-5B6-2A6B6-A6B7-3B294-A-2B8-2A11-3A9-4A9-2A-2(A9-A2-)A9-2(A3-A8-)A2-A-6B2-2A8-B2-3A5-3B2-4A4B6-2A261-3B7-3A5B4-2A-A2-3B4-A2-2A3B5-7(A3-A8-)A4-7B-A6-B3-B-A5-5B2-A4-2B6-A2-2A8-4A10-3A218-3A9-4A4B5-A7-2B3-A8-B3-A4-5B2(3-A)6(8-A3-A)8-A3-2B2-5BA4-2(2B-)B-A4-B3-2B2-A4-B7-3(A3-A8-)4A10-3A179-3A9-A2-A9-A3-4B5-A7-2B3-A9-B2-A4-6B2-2(A3-A8-)A2-A9-2A-A3(9-4A)9-2A-A6-3BA2-2A5-3B5(A3-A8-)A3-5B4-A3-5B5-2A6B8-3B137-3A9-3(A3-A8-)A4-A4B3-A3-2A2B2-B2-A3-A2-AB-B2-2A-A5-2B2-C3A9-C2A10-C-A10-3(C12-)C-A8-2BC2A8-2B2(4A9-)3(A3-A8-)A4-5B3-A8-B3-A7-2B4-2A5B123-3A9-5(A3-A8-)2A-A4-3B2-C3A4-B2-B-C-A6-3B-6(C12-)C11-B3(C12-)C3A9-2A-A9-2(A3-)3B2-A4-3B2-B2-A5-2B-2B2-A5-3B4-A3-3B7-3A101-2A10-A2-A9-4(A3-A8-)4A9-C-A7-B2-C8-2(B-)C8-3B-11(C12-)C-A7-B2-4A5-2(B-)2(A3-)3B2-A4-B2-2B3-A4-B7-A3-A8-A3-A9-3A76-A10-2A-A9-4(A3-A8-)4A9-2(C12-)3(C9-2B-)10(C12-)2(C9-2B-)C3A6-B2-4(A3-A8-)2A-A11-A63-3A9-4(A3-A8-)4A9-4(C12-)2(C9-2B-)10(C12-)C9-2B-C9-B2-C12-C3A9-3(A3-A8-)A3-A9-3A50-A5B5-2A2-5B4-A4-5B2(3-A)2-3B2(3-A)8-2A-A9-C-A10-5(C12-)C10-B-13(C12-)C-A10-2A-2A3(8-A3-A)8-2A-2A10-A27-2B8-2AB2-3B4-A8-B3-A4-2B3-B2-A3-A2(2-B)2-2(A3-)3B2-C3A5-2B2-21(C12-)C3A9-3(A3-A8-)A3-A9-3A35-3A6B4-A6-3B3-A4-6B2-A3-A2-4B2-C3A4-B-B2-C8-2(B-)C9-2B-21(C12-)C4A3(8-A3-A)9-4A23-A10-2A-3B7-A4-2B6-A4-B7-A3-A8-C3A5-2B2-C8-3B-C9-2B-C10-B-20(C12-)C3A9-3(A3-A8-)2A-2A10-A11-3A9-3(A3-A8-)2A-2A8-C-A10-23(C12-)C-A6-2B2-2A-2A3-3B2-A3-A-4B3-A4-5B3-2A2-5B6-2A-2B7-3A9-3(A3-A8-)C3A9-21(C12-)2(C9-B2-)2(C8-2B2-)C4A3-B-B2-A4-5B3-A8-B3-A7-2B4-3A4B6-3A9-3(A3-A8-)C3A9-22(C12-)C9-B2(2-C8-2B)2-C4A3-3B2-A4-5B3-A6-3B3-A6-2B5-3A4B6-3A9-3(A3-A8-)C3A9-25(C12-)C3A9-A3-A8-A4-2B6-A4-2B7-4AB8-3A9-3(A3-A8-)C3A9-25(C12-)C4A3(8-A3-A)9-3A10-3A9-3(A3-A8-)C4A8-4(C12-)C8-2B2-C8-B3-19(C12-)C4A3(8-A3-A)9-3A10-3A9-2(A3-A8-)2(A3-)2B3-C4A3-3B2-C7-3B2-3(C8-3B-)C8-2B2-20(C12-)C4A3(8-A3-A)9-3A11-A-2B7-2A-B-4B4-A4-5B3-A4-3B2-B3-A-2A2(2-B)2-C-A5-B2-B-C8-2(B-)2(C8-3B-)15(C12-)2(C9-B2-)3(C12-)C-2A10-A2-2(A8-A3-)A9-A2-A10-2A12-4B6-3A4-2B4-A8-B3-A2(4-B)2-A3-A-2B2-B2-C3A4-B-B2-C8-2B2-18(C12-)2(C9-2B-)2(C12-)C3A9-2(A3-A8-)A3-A9-4A24-4B7-2A4-2B4-A7-2B3-A4-B-3B2(3-A)-4B3-CA-2A4-B3-C-A10-18(C12-)C9-2B-C8-2(B-)C8-3B-C-2A5-2B2-CA2-3(A8-A3-)A9-4A36-2A3B6-2A3-3B5-A4-2B6-2(A3-A8-)C4A8-2(6(C12-)C9-B2-)5(C12-)C8-3B-C7-B2-B-C4A3-B-B3-2(A2-)4B2-2(A3-)B4-A3-A9-A2-A10-2A49-4A3(8-A3-A)9-A2-A8-C3A9-4(C12-)2(C8-2B2-)6(C12-)C9-2B-6(C12-)C3A4-3B3-A2-A-2B2-B2-A4-2B3-B2-A4-3B-B3-A4-4B5-4A62-2A10-A2-3(A8-A3-)A8-CA2-A8-C-2A9-2(C12-)C7-3B2-C7-B-B2-C8-2B2-6(C12-)2(C9-2B-)4(C12-)C-2A9-CA2-A3-2B2(3-A)2(-2B)2-A2(4-B)2-A8-B4-A4-3B6-3AB73-4A4(8-A3-A)8-CA2-A8-C3A9-C7-2B3-2(C7-B-B2-)C8-2B2-6(C12-)2(C9-2B-)3(C12-)C3A9-CA2-A8-A3-A8-A4-A3B4-A7-2B4-A6-B5-3A5B84-A11-A-2A4(8-A3-A)9-A2-A-3B4-C4A-2B-B3-C-A4-2(B2-)C6-4B2-7(C12-)C8-3B-C8-2(B-)C9-B2-C-A10-C4A9-A2-3(A8-A3-)A9-A3-3B6-A2-4B7-2A3B99-A11-A-2A2(8-A3-A)8-A4-3B5-A4-B2-2B3-A4-2(B3-)CA-2A3B-B3-C3A4-2B3-C-A10-6(C12-)C8-3B-C8-2(B-)C-2A5-3B-CA-2A9-A2-3(A8-A3-)A9-A2-A9-A-2A10-2A128-A11-A-2A9-A2-B8-A4-3B5-A7-B4-A8-B3-A4-5B4-A2-A9-A-2A2(8-C4A)8-2(C-2A9-)2(C3A9-)C4A3-4B2-4A3-2(B2-)A2-A3-4B-3(A3-A8-)A3-A9-A2-A9-A-2A10-A155-A11-2A2B9-A3-2B6-2(A6-2B4-)A4-4B4-2(A3-A8-)A3-5(A9-A2-)A8-A3-A2-4B2-A4-3B3-B-A4-3B2-B2-A3-A2-3B2(3-A)8-A3-A9-A2-A9-4A10-A194-A2B9-A-4B7-A2-A2B6-9(A3-A8-)A4-6B2(2-A9-B)2-A4-5B4-A2-A9-A-2A10-2A232-A12-2A10-4A4(9-A2-A)3(8-A3-A)9-A2-A9-A3-5B2(4-A7-B)4-2A2-4B5-4A10-A285-2A11-2A10-3A10-5(4A9-)2A5B7-A6B6-A6B7-5B148-
