model
size = 20 22 22, scale = 0.05, origin = -y
material 
  colors = A:#DDD B:#900 C:#EEE D:#BBB E:#400 F:#111 G:#300 H:#500 I:#AAA J:#444 K:#800 L:#B00 M:#FF6 N:#222 O:#600
voxels
-------------------- -------------------- -------------------- -------------------- -------------------- -------------------- -------------------- -------------------- -------------------- -------------------- ----EE--------EE---- -BBBBBBBBBBBBBBBBBB- BBBGHGEGGGHEEGGHGBBB BBGGGEGGHEGEGHGGEEBB BBBGHOGGGGGGGEEHGBBB -KBBBBBBBBBBBBBBBBB- ----HH--------HH---- -------------------- -------------------- -------------------- -------------------- -------------------- 
-------------------- -------------------- -------------------- -------------------- -------------------- -------------------- -------------------- -------------------- -------------------- -------------------- ---BBBBB----BBBBB--- -BBAAAAABHHBAAAAABB- BAAAAAAAABBAAAAAAAAK EAAAAAAAAAAAAAAAAAAE BAAAAAAAAAAAAAAAAAAB -BAAAAAAAAAAAAAAAAB- --BBBKBBBBKBBBEBEB-- -------------------- -------------------- -------------------- -------------------- -------------------- 
-------------------- -------------------- -------------------- -------------------- -------------------- -------------------- --------C--C-------- --------C--C-------- ----CC--C--C--CC---- ----CC---CC---CC---- ---BBBBBHCCHBBBBB--- -KBAAAAABHHBAAAAABB- BAAAAAAAAHHAAAAAAAAB EAAAAAAAAAAAAAAAAAAE BAAAAAAAAAAAAAAAAAAB -BAAAAAAAAAAAAAAAAB- --BBBBBEBBBBBBBBBB-- -------------------- -------------------- -------------------- -------------------- -------------------- 
---------AA--------- --------AAAA-------- -------------------- -------------------- -------------------- --------AAAA-------- --------A--A-------- ----AAA-A--A-AAA---- ---CCAACA--ACAAAC--- ---CAAACCAACCAAAC--- ---GAAAADAADAAAAB--- -BBAAAAAAHHAAAAAABB- BAAAAAAAAHHAAAAAAAAB EAAAAAAAAAAAAAAAAAAE LAAAAAAAAAAAAAAAAAAL -BAAAAAAAAAAAAAAAAB- --BBBBBBBBBBBEBBBE-- -------------------- -------------------- -------------------- -------------------- -------------------- 
-------AAAAAA------- ------CACACACA------ ------C-C-C-C------- ------C-C-C-C------- -------C-C-C-A------ -------AAAAAAA------ ---AAAAAJ--JAAAAA--- ---AAAADJ--JDAAAA--- ---AAAADJ--JDAAAA--- ---AAAADDJJDDAAAA--- ---AAAAADAADAAAAA--- -BHBAAAAAAAAAAAAABB- BBBBBAAAAAAAAAAAABBB GBBBBAAAAAAAAAABBBBH BBBBBAAAAAAAACCBBBBB -BBBBBAAAAAAAABBBBB- --EBBBBBBBBBBBBBBB-- -------------------- -------------------- -------------------- -------------------- -------------------- 
----------AA-------- -----ACDCDCMDCA----- ------ADCDCMDC------ ------CDCDCMDC------ ------DAAAAAAD------ ----AAADADDADAAA---- ---AAAAAAFFAAAAAA--- --AAAAAAAFFAAAAAAC-- --AAAAAAAFFAAAAAAA-- --AAAAAADAADAAAAAA-- ---AAAAAAAAAAAAAA--- ---FDAAAAAAAAAAAN--- B-JFFDAAAAAAAADFFF-B E-FFFDAAAAAAAADFFF-E B-FFFDAAAAAAAADFFF-B --NFFJAAAAAAAAFNF--- ------AAAAAAAA------ --------AAAA-------- -------------------- -------------------- -------------------- -------------------- 
-------------------- -----CAAAAAAAAC----- -----CAAAAAAAAC----- ------AAAAAAAA------ ------AAAAAAAA------ ----AAAAAAAAAAAA---- ---AAAAAAAAAAAAAD--- --AAAAAAAAAAAAAAAA-- --AAAAAAAAAAAAAAAA-- --AAAAAAAAAAAAAAAA-- ---AAAAAAAAAAAAAA--- ----AAAAAAAAAAAA---- B---AAAAAAAAAAAA---B H---AAAAAAAAAAAA---G B---AAAAAAAAAAAA---B ----AAAAAAAAAAAA---- -----AAAAAAAAAA----- ------AAAAAACC------ -------AAAAAC------- -------------------- -------------------- -------------------- 
-------------------- -----CAAAAAAAAC----- -----CAAAAAAAAC----- ------AAAAAAAA------ ------AAAAAAAA------ ----CAAAAAAAAAAA---- ---DAAAAAAAAAAAAA--- --AAAAAAAAAAAAAAAD-- --AAAAAAAAAAAAAAAA-- --AAAAAAAAAAAAAAAA-- ---AAAAAAAAAAAAAA--- ---AAAAAAAAAAAAAA--- B--AAAAAAAAAAAAAA--B E--AAAAAAAAAAAAAA--E B--AAAAAAAAAAAAAA--B ---AAAAAAAAAAAAAA--- ----AAAAAAAAAAAA---- ----AAAAAAAAAAAA---- -----AAAAAAAAAC----- -------AAAAAA------- -------------------- -------------------- 
-------------------- -----CAAAAAAAAC----- -----CAAAAAAAAC----- ------AAAAAAAA------ ------AAAAAAAA------ ------DAAAAAAD------ ---AAAAAAAAAAAAAA--- ---AAAAAAAAAAAAAA--- ---AAAAAAAAAAAAAA--- ---AAAAAAAAAAAAAA--- ---AAAAAAAAAAAAAA--- --AAAAAAAAAAAAAAAA-- B-AAAAAAAAAAAAAAAA-B E-AAAAAAAAAAAAAAAA-E B-AAAAAAAAAAAAAAAA-B ---AAAAAAAAAAAAAA--- ---AAAAAAAAAAAAAA--- ----AAAAAAAAAAAA---- ----AAAAAAAAAAAA---- ------AAAAAAAA------ --------AAAA-------- -------------------- 
-------------------- -----CAAAAAAAAC----- -----CAAAAAAAAC----- -----CAAAAAAAA------ -----CAAAAAAAA------ -----CDAAAAAAD------ -----DAAAAAAAAD----- ----DAAAAAAAAAAD---- ---AAAAAAAAAAAAAD--- --AAAAAAAAAAAAAAAA-- --AAAAAAAAAAAAAAAA-- --AAAAAAAAAAAAAAAA-- B-AAAAAAAAAAAAAAAA-B G-AAAAAAAAAAAAAAAA-E B-AAAAAAAAAAAAAAAA-B --AAAAAAAAAAAAAAAA-- --AAAAAAAAAAAAAAAA-- ---AAAAAAAAAAAAAA--- ----AAAAAAAAAAAA---- -----AAAAAAAAAA----- ------AAAAAAAA------ -------------------- 
-------------------- -----CCAAAAAACC----- -----CCAAAAAACC----- -------FAAAAACC----- -------FAAAAICC----- ------FAAAAAADC----- ----AAAAAAAAAAAA---- ---AAAAAAAAAAAAAA--- ---AAAAAAAAAAAAAD--- --AAAAAAAAAAAAAAAA-- --AAAAAAAAAAAAAAAA-- -AAAAAAAAAAAAAAAAAA- BAAAAAAAAAAAAAAAAAAB BAAAAAAAAAAAAAAAAAAG BAAAAAAAAAAAAAAAAAAB --AAAAAAAAAAAAAAAA-- --AAAAAAAAAAAAAAAA-- ---AAAAAAAAAAAAAA--- ---AAAAAAAAAAAAAA--- ----ACAAAAAAAAAA---- ------CAAAAAAA------ --------AACA-------- 
-------------------- ------CAAAAAA------- -----CCAAAAAACC----- -----CCAAAAAF------- -----CCAAAAAF------- ----CAAAAAAAAFF----- ----AAAAAAAAAAAA---- ---CAAAAAAAAAAAAA--- --AAAAAAAAAAAAAAAD-- --AAAAAAAAAAAAAAAA-- -AAAAAAAAAAAAAAAAAA- LAAAAAAAAAAAAAAAAAA- BAAAAAAAAAAAAAAAAAAB BAAAAAAAAAAAAAAAAAAB BAAAAAAAAAAAAAAAAAAB KAAAAAAAAAAAAAAAAAA- --AAAAAAAAAAAAAAAA-- --AAAAAAAAAAAAAAAA-- ---AAAAAAAAAAAAAA--- ----AAAAAAAAAAAA---- -----AAAAAAAAAA----- -------AAAAAA------- 
-------------------- -------AAAAAD------- -------AAAAAACC----- -------AAAAADCC----- -------IAAAAACC----- -----AAAAAAAAADC---- ----AAAAAAAAAAAA---- ---DAAAAAAAAAAAAA--- --AAAAAAAAAAAAAAAA-- --AAAAAAAAAAAAAAAA-- -AAAAAAAAAAAAAAAAAA- BAAAAAAAAAAAAAAAAAAB BAAAAAAAAAAAAAAAAAAL EAAAAAAAAAAAAAAAAAAB EAAAAAAAAAAAAAAAAAAB BAAAAAAAAAAAAAAAAAAB --AAAAAAAAAAAAAAAA-- --AAAAAAAAAAAAAAAA-- ---AAAAAAAAAAAAAA--- ----AAAAAAAAAAAA---- -----AAAAAAAAAA----- -------AAAAAA------- 
-------------------- -------AAAAAA------- -------AAAAAA------- -------AAAAAA------- -------IAAAAD------- -----AAAAAAAAAA----- ----AAAAAAAAAAAA---- ---AAAAAAAAAAAAAA--- --AAAAAAAAAAAAAAAC-- --CAAAAAAAAAAAAAAA-- -AAAAAAAAAAAAAAAAAA- BAAAAAAAAAAAAAAAAAAB EAAAAAAAAAAAAAAAAAAB EAAAAAAAAAAAAAAAAAAH HAAAAAAAAAAAAAAAAAAE BAAAAAAAAAAAAAAAAAAK --AAAAAAAAAAAAAAAA-- --AAAAAAAAAAAAAAAA-- ---AAAAAAAAAAAAAA--- ----AAAAAAAAAAAA---- -----AAAAAAAAAA----- -------AAAAAA------- 
-------------------- -------------------- -------AAAADA------- -------AAAAAA------- -------AAAAIA------- -----AAAAAAAAAA----- ----AAAAAAAAAAAA---- ---AAAAAAAAAAAAAD--- --AAAAAAAAAAAAAAAA-- --AAAAAAAAAAAAAAAA-- -AAAAAAAAAAAAAAAAAA- BAAAAAAAAAAAAAAAAAAB BAAAAAAAAAAAAAAAAAAE EAAAAAAAAAAAAAAAAAAE BAAAAAAAAAAAAAAAAAAE BAAAAAAAAAAAAAAAAAAB --AAAAAAAAAAAAAAAA-- --AAAAAAAAAAAAAAAA-- ---AAAAAAAAAAAAAC--- ----AAAAAAAAAAAA---- -----AAAAAAAAAA----- -------AAAAAA------- 
-------------------- -------------------- -------------------- -------------------- -------------------- ------AAAIIIAA------ ----AAAAAAAAAAAA---- ---AAAAAAAAAAAAAD--- ---AAAAAAAAAAAAAA--- --AAAAAAAAAAAAAAAA-- --AAAAAAAAAAAAAAAA-- -AAAAAAAAAAAAAAAAAAB BAAAAAAAAAAAAAAAAAAB BAAAAAAAAAAAAAAAAAAE BAAAAAAAAAAAAAAAAAAB --AAAAAAAAAAAAAAAA-B --AAAAAAAAAAAAAAAA-- ---CAAAAAAAAAAAAA--- ---AAAAAAAAAAAAAA--- ----AAAAAAAAAAAA---- ------AAAAAAAA------ --------AAAA-------- 
-------------------- -------------------- -------------------- -------------------- -------------------- ------AAAIAIAA------ -----AAAAAAAAAA----- ----AAAAAAAAAAAA---- ---AAAAAAAAAAAAAA--- --AAAAAAAAAAAAAAAA-- --AAAAAAAAAAAAAAAA-- --AAAAAAAAAAAAAAAA-- --AAAAAAAAAAAAAAAA-B --AAAAAAAAAAAAAAAA-B --AAAAAAAAAAAAAAAA-B --AAAAAAAAAAAAAAAA-- --AAAAAAAAAAAAAAAA-- ---DAAAAAAAAAAAAA--- ----AAAAAAAAAAAA---- -----AAAAAAAAAA----- ------AAAAAAAA------ -------------------- 
-------------------- -------------------- -------------------- -------------------- -------------------- ------AADAIAAA------ ------AAAAAAAA------ ----AAAAAAAAAAAC---- ----AAAAAAAAAAAA---- ---AAAAAAAAAAAAAA--- ---AAAAAAAAAAAAAA--- --AAAAAAAAAAAAAAAA-- --AAAAAAAAAAAAAAAA-- --AAAAAAAAAAAAAAAA-- --AAAAAAAAAAAAAAAA-- ---AAAAAAAAAAAAAA--- ---CAAAAAAAAAAAAA--- ----AAAAAAAAAAAA---- ----ACAAAAAAAAAA---- ------AAAAAAAD------ --------ADAA-------- -------------------- 
-------------------- -------------------- -------------------- -------------------- -------------------- -------------------- ------AAAAADDA------ -----AAAAAAAAAA----- ----ADAAAAAAAAAA---- ----AAAAAAAAAAAA---- ---AAAAAAAAAAAAAA--- ---AAAAAAAAAAAAAC--- ---AAAAAAAAAAAAAA--- ---DAAAAAAAAAAAAA--- ---AAAAAAAAAAAAAA--- ---CAAAAAAAAAAAAA--- ----AAAAAAAAAAAA---- ----ACAAAAAAAAAA---- -----AAAAAAAAAA----- -------AAAAAD------- -------------------- -------------------- 
-------------------- -------------------- -------------------- -------------------- -------------------- -------------------- -------------------- ------AAAAAAAA------ ------AAAAAAAA------ -----AAAAAAAAAA----- ----CAAAAAAAAAAA---- ----AAAAAAAAAAAA---- ----AAAAAAAAAAAA---- ----AAAAAAAAAAAA---- ----AAAAAAAAAAAA---- ----CCAAAAAAAAAA---- -----DAAAAAAAAA----- ------AAAAAAAA------ -------AAAAAA------- -------------------- -------------------- -------------------- 
-------------------- -------------------- -------------------- -------------------- -------------------- -------------------- -------------------- -------------------- --------AAAA-------- ------AAAAAAAA------ ------AAAAAAAA------ -----ACAAAAAAAD----- -----CCAAAAAAAD----- -----AAAAAAAAAA----- -----AAAAAAAAAA----- ------AAAAAAAA------ ------AAAAAAAC------ --------AAAA-------- -------------------- -------------------- -------------------- -------------------- 
-------------------- -------------------- -------------------- -------------------- -------------------- -------------------- -------------------- -------------------- -------------------- -------------------- --------AAAA-------- -------AAAAAA------- -------AACAAA------- -------AACAAA------- -------AAAAAA------- --------AAAA-------- -------------------- -------------------- -------------------- -------------------- -------------------- -------------------- 
