model
size = 30 26 17, scale = 0.05, origin = -y
material 
  colors = A:#9CF B:#00D C:#444 D:#DDD E:#00B F:#222 G:#930 H:#B00 I:#002 J:#00A K:#963 L:#EEE M:#06F N:#0CC O:#BBB P:#111 Q:#800 R:#00E S:#555 T:#888 U:#FC3 V:#F60 W:#F90 X:#960 Y:#D00 Z:#777 Aa:#966 Ab:#FC0 Ac:#FF3 Ad:#933 Ae:#700 Af:#0CF Ag:#AAA Ah:#0C9 Ai:#0FF Aj:#0FC Ak:#0C0 Al:#A00
voxels
- - - - - - - - - - - - - - - - - - - - - - - - - - - - - -   - - - - - - - - - - - - - - - - - - - - - - - - - - - - - -   - - - - - - - - - - - - - - - - - - - - - - - - - - - - - -   - - - - - - - - - - - - - - - - - - - - - - - - - - - - - -   - - - - - - - - - - - - - - - - - - - - - - - - - - - - - -   - - - - - - - - - - - - - - - - - - - - - - - - - - - - - -   - - - - - - - - - - - - - - - - - - - - - - - - - - - - - -   - - - - - - - - - - - - - - - - - - - - - - - - - - - - - -   - - - - - - - - - - - - - - - - - - - - - - - - - - - - - -   - - - - - - - - - - - - - - - - - - - - - - - - - - - - - -   - - - - - - - - - - - - G G X X G G - - - - - - - - - - - -   - - - - - - - - - - G G G X G G X G G G - - - - - - - - - -   - - - - - - - - - - G G - - - - - - G G - - - - - - - - - -   - - - - - - - - - - AdG - - - - - - G G - - - - - - - - - -   - - - - - - - - - - X G - - - - - - G X - - - - - - - - - -   - - - - - - - - - - G X - - - - - - X G - - - - - - - - - -   - - - - - - - - - - G G - - - - - - G Ad- - - - - - - - - -   - - - - - - - - - - AaG - - - - - - G G - - - - - - - - - -   - - - - - - - - - - G G - - - - - - G G - - - - - - - - - -   - - - - - - - - - - AdG - - - - - - G G - - - - - - - - - -   - - - - - - - - - - G G - - - - - - G G - - - - - - - - - -   - - - - - - - - - - G G - - - - - - G G - - - - - - - - - -   - - - - - - - - - - - - - - - - - - - - - - - - - - - - - -   - - - - - - - - - - - - - - - - - - - - - - - - - - - - - -   - - - - - - - - - - - - - - - - - - - - - - - - - - - - - -   - - - - - - - - - - - - - - - - - - - - - - - - - - - - - -   
- - - - - - - - - - - - - - - - - - - - - - - - - - - - - -   - - - - - - - - - - - - - - - - - - - - - - - - - - - - - -   - - - - - - - - - - - - - - - - - - - - - - - - - - - - - -   - - - - - - - - - - - - - - - - - - - - - - - - - - - - - -   - - - - - - - - - - - - - - - - - - - - - - - - - - - - - -   - - - - - - - - - - - - - - - - - - - - - - - - - - - - - -   - - - - - - - - - - - - - - - - - - - - - - - - - - - - - -   - - - - - - - - - - - - - - - - - - - - - - - - - - - - - -   - - - - - - - - - - - - - - - - - - - - - - - - - - - - - -   - - - - - - - - - - - - - - - - - - - - - - - - - - - - - -   - - - - - - - - - - - - G G G G G G - - - - - - - - - - - -   - - - - - - - - - - G G G G G G G G G G - - - - - - - - - -   - - - - - - - - - - G G - - - - - - G G - - - - - - - - - -   - - - - - - - - - - - - - - - - - - - - - - - - - - - - - -   - - - - - - - - - - - - - - - - - - - - - - - - - - - - - -   - - - - - - - - - - - - - - - - - - - - - - - - - - - - - -   - - - - - - - - - - - - - - - - - - - - - - - - - - - - - -   - - - - - - - - - - - - - - - - - - - - - - - - - - - - - -   - - - - - - - - - - - - - - - - - - - - - - - - - - - - - -   - - - - - - - - - - - - - - - - - - - - - - - - - - - - - -   - - - - - - - - - - - - - - - - - - - - - - - - - - - - - -   - - - - - - - - - - G G - - - - - - G Aa- - - - - - - - - -   - - - - - - - - - - - - - - - - - - - - - - - - - - - - - -   - - - - - - - - - - - - - - - - - - - - - - - - - - - - - -   - - - - - - - - - - - - - - - - - - - - - - - - - - - - - -   - - - - - - - - - - - - - - - - - - - - - - - - - - - - - -   
- - - - - - - - - - - - - - - - - - - - - - - - - - - - - -   - - - - - - - - - - - - - - - - - - - - - - - - - - - - - -   - - - - - - - - - - - - - - - - - - - - - - - - - - - - - -   - - - - - - - - - - - - - - - - - - - - - - - - - - - - - -   - - - - - - - - - - - - - - - - - - - - - - - - - - - - - -   - - - - - - - - - - - - - - - - - - - - - - - - - - - - - -   - - - - - - - - - - - - - - - - - - - - - - - - - - - - - -   - - - - - - - - - - - - - - - - - - - - - - - - - - - - - -   - - - - - - - - - - - - - - - - - - - - - - - - - - - - - -   - - - - - - - - - - - - - - - - - - - - - - - - - - - - - -   - - - - - - - - - - - G G - - - - G G - - - - - - - - - - -   - - - - - - - - - - - G G - - - - G G - - - - - - - - - - -   - - - - - - - - - - - - - - - - - - - - - - - - - - - - - -   - - - - - - - - - - - - - - - - - - - - - - - - - - - - - -   - - - - - - - - - - - - - - - - - - - - - - - - - - - - - -   - - - - - - - - - - - - - - - - - - - - - - - - - - - - - -   - - - - - - - - - - - - - - - - - - - - - - - - - - - - - -   - - - - - - - - - - - - - - - - - - - - - - - - - - - - - -   - - - - - - - - - - - - - - - - - - - - - - - - - - - - - -   - - - - - - - - - - - - - - - - - - - - - - - - - - - - - -   - - - - - - - - - - - - - - - - - - - - - - - - - - - - - -   - - - - - - - - - - G G - - - - - - G G - - - - - - - - - -   - - - - - - - - - - G Ad- - - - - - G G - - - - - - - - - -   - - - - - - - - - - - - - - - - - - - - - - - - - - - - - -   - - - - - - - - - - - - - - - - - - - - - - - - - - - - - -   - - - - - - - - - - - - - - - - - - - - - - - - - - - - - -   
- - - - - - - - - - - - - - - - - - - - - - - - - - - - - -   - - - - - - I I I - - - - - - - - - - - - I I I - - - - - -   - - - - - - B B B - - - - - - - - - - - - B B B - - - - - -   - - - - - - B B B - - - - - - - - - - - - B B B - - - - - -   - - - - - - M B B - - - - - - - - - - - - E B B - - - - - -   - - - - - - B R B - - - - - - - - - - - - B B R - - - - - -   - - - - - - B B B - - - - - - - - - - - - B B E - - - - - -   - - - - - - B B B - - - - - - - - - - - - B B B - - - - - -   - - - - - - R E B - - - - - - - - - - - - B B B - - - - - -   - - - - - - B B B - - - - - - - - - - - - B B B - - - - - -   - - - - - - B B B - G G - - - - - - G G - B B B - - - - - -   - - - - - - B E B - G G - - - - - - G G - B B M - - - - - -   - - - - - - B B B - - - - - - - - - - - - B B B - - - - - -   - - - - - - B B B - - - - - - - - - - - - B B B - - - - - -   - - - - - - B B B - - - - - - - - - - - - B E B - - - - - -   - - - - - - B R M - - - - - - - - - - - - B B B - - - - - -   - - - - - - B R B - - - - - - - - - - - - B M B - - - - - -   - - - - - - B B B - - - - - - - - - - - - B M B - - - - - -   - - - - - - B B B - - - - - - - - - - - - B M B - - - - - -   - - - - - - B E B - - - - - - - - - - - - B M B - - - - - -   - - - - - - B R B - - - - - - - - - - - - B B B - - - - - -   - - - - - - M B B - - - - - - - - - - - - B B B - - - - - -   - - - - - - I I I - G Aa- - - - - - G G - I I I - - - - - -   - - - - - - H H H - - - - - - - - - - - - H H Y - - - - - -   - - - - - - - - - - - - - - - - - - - - - - - - - - - - - -   - - - - - - - - - - - - - - - - - - - - - - - - - - - - - -   
- - - - - - D D D - - - - - - - - - - - - D O D - - - - - -   - - - - - I A A A I - - - - - - - - - - I A A A I - - - - -   - - - - - B A A A E - - - - - - - - - - E A A A B - - - - -   - - - - - B A A A E - - - - - - - - - - E A A A B - - - - -   - - - - - R A A A E - - - - - - - - - - E A A A B - - - - -   - - - - - E A A A E - - - - - - - - - - E A A A B - - - - -   - - - - - B A A A E - - - - - - - - - - E A A A B - - - - -   - - - - - B A A A E - - - - - - - - - - E A A A E - - - - -   - - - - - B A A A E - - - - - - - - - - E A A A B - - - - -   - - - - - B A A A E - - - - - - - - - - E A A A B - - - - -   - - - - - B A A A E G - - - - - - - - G E A A A B - - - - -   - - - - - B A A A E G - - - - - - - - G E A A A B - - - - -   - - - - - B A A A E - - - - - - - - - - E A A A B - - - - -   - - - - - B A A A E - - - - - - - - - - E A A A B - - - - -   - - - - - B A A A E - - - - - - - - - - E A A A B - - - - -   - - - - - B A A A E - - - - - - - - - - E A A A B - - - - -   - - - - - E A A A E - - - - - - - - - - E A A A B - - - - -   - - - - - B A A A E - - - - - - - - - - E A A A B - - - - -   - - - - - B A A A E - - - - - - - - - - E A A A E - - - - -   - - - - - B A A A E - - - - - - - - - - E A A A B - - - - -   - - - - - B A A A E - - - - - - - - - - E A A A B - - - - -   - - - - - B A A A E - - - - - - - - - - E A A A B - - - - -   - - - - - I A A A I AaG - - - - - - AaG I A A A I - - - - -   - - - - - H A A A H - - - - - - - - - - H A A A H - - - - -   - - - - - - Y H H - - - - - - - - - - - - H H H - - - - - -   - - - - - - - - - - - - - - - - - - - - - - - - - - - - - -   
- - - - - D D D D D - - - - - - - - - - D D D D D - - - - -   - - - - I A A A A A I - - - - - - - - I A A A A A I - - - -   - - - - B A A A A E - - - - - - - - - - E A A A A B - - - -   - - - - R A A A A J - - - - - - - - - - J A A A A B - - - -   - - - - B A A A A J - - - - - - - - - - J A A A A M - - - -   - - - - B A A A A J - - - - - - - - - - J A A A A B - - - -   - - - - B A A A A J - - - - - - - - - - J A A A A B - - - -   - - - - B A A A A E - - - - - - - - - - E A A A A B - - - -   - - - - B A A A A E - - - F F F F - - - E A A A A B - - - -   - - - - B A A A A A C C C C C C C C C C A A A A A B - - - -   - - - - B A A A A A C C F F F F F F C C A A A A A B - - - -   - - - - B A A A A A C C F F F F F F C C A A A A A B - - - -   - - - - R A A A A A C C F F F F F F C C A A A A A B - - - -   - - - - B A A A A A C F F F F F F F F C A A A A A B - - - -   - - - - M A A A A A C F F F F F F F F C A A A A A B - - - -   - - - - M A A A A A C F F F F F F F F C A A A A A B - - - -   - - - - M A A A A A C F F F F F F F F C A A A A A B - - - -   - - - - B A A A A A C F F F F F F F F C A A A A A B - - - -   - - - - B A A A A A C F F F F F F F F C A A A A A B - - - -   - - - - B A A A A A C F F F F F F F F C A A A A A B - - - -   - - - - B A A A A A C F F F F F F F F C A A A A A R - - - -   - - - - B A A A A A C F F F F F F F F C A A A A A B - - - -   - - - - I A A A A A C C C C S S C C C C A A A A A I - - - -   - - - - H A A A A A C C C C C C C C C C A A A A A H - - - -   - - - - - H H H H H - - - - - - - - - - H H H H H - - - - -   - - - - - - - - - - - - - - - - - - - - - - - - - - - - - -   
- - - - O D - - - D - - - - - - - - - - D - - - D D - - - -   - - - I A AbU V U A I - - - - - - - - I A U V U AbA I - - -   - - - B A A A A A A F F F P P P P F F F A A A A A A B - - -   - - - B A A A A A J - - - - D D - - - - J A A A A A B - - -   - - - B A A A A A J - - - - D D - - - - J A A A A A B - - -   - - - B A A A A A J - - - - D D - - - - J A A A A A B - - -   - - - B A A A A A J - - - - D D - - - - J A A A A A B - - -   - - - B A A A A A E - - - - D D - - - - E A A A A A B - - -   - - - B A A A A A A C C F F A A F F C C A A A A A A B - - -   - - - B A A A A A A A A A A A A A A A A A A A A A A R - - -   - - - B A A A A A A A A A A A A A A A A A A A A A A M - - -   - - - B A A A A A A A A A A A A A A A A A A A A A A B - - -   - - - B A A A A A A A A A A A A A A A A A A A A A A B - - -   - - - B A A A A A A A A A A A A A A A A A A A A A A B - - -   - - - B A A A A A A A A A A A A A A A A A A A A A A B - - -   - - - B A A A A A A A A A A A A A A A A A A A A A A B - - -   - - - B A A A A A A A A A A A A A A A A A A A A A A B - - -   - - - B A A A A A A A A A A A A A A A A A A A A A A B - - -   - - - B A A A A A A A A A A A A A A A A A A A A A A B - - -   - - - B A A A A A A A A A A A A A A A A A A A A A A B - - -   - - - B A A A A A A A A A A A A A A A A A A A A A A B - - -   - - - B A A A A A A A A A A A A A A A A A A A A A A B - - -   - - - - I A A A A A A A A A A A A A A A A A A A A I - - - -   - - - - H A A A A A C C C C C C C C C C A A A A A Q - - - -   - - - - - H H A H H - C C C C C C C C - H H A H H - - - - -   - - - - - - - Ae- - - - - - - - - - - - - - Q - - - - - - -   
- - - - D - - - - D - - - - - - - - - - D - - - - D - - - -   - - - I A W AcU W A I F F P Z Z P F F I A W U AcW A I - - -   - - - B A A A A A A F F P A A A A P F F A A A A A A B - - -   - - - B A A A A A J - - - D N N D - - - J A A A A A B - - -   - - - B A A A A A J - - - D N N D - - - J A A A A A B - - -   - - - B A A A A A J - - - D N N D - - - J A A A A A B - - -   - - - B A A A A A J - - - D N N D - - - J A A A A A B - - -   - - - B A A A A A A C C - D A A D - C C A A A A A A B - - -   - - - B A A A A A A A A F A A A A F A A A A A A A A B - - -   - - - B A A A A A A A A A A A A A A A A A A A A A A B - - -   - - - B A A A A A A A A A A A A A A A A A A A A A A B - - -   - - - B A A A A A A A A A A A A A A A A A A A A A A B - - -   - - - B A A A A A A A A A A A A A A A A A A A A A A B - - -   - - - B A A A A A A A A A A A A A A A A A A A A A A B - - -   - - - B A A A A A A A A A A A A A A A A A A A A A A M - - -   - - - B A A A A A A A A A A A A A A A A A A A A A A B - - -   - - - B A A A A A A A A A A A A A A A A A A A A A A B - - -   - - - B A A A A A A A A A A A A A A A A A A A A A A B - - -   - - - B A A A A A A A A A A A A A A A A A A A A A A E - - -   - - - B A A A A A A A A A A A A A A A A A A A A A A B - - -   - - - R A A A A A A A A A A A A A A A A A A A A A A B - - -   - - - B A A A A A A A A A A A A A A A A A A A A A A B - - -   - - - - I A A A A A A A A A A A A A A A A A A A A I - - - -   - - - - H A A A A A C C C C C C C C C C A A A A A H - - - -   - - - - - Q A A A H - C C C C C C C C - H A A A H - - - - -   - - - - - - Q Q Q - - - C C C C C C - - - Q Q Q - - - - - -   
D - - - D - - - - D - - - - - - - - - - D - - - - D - - - D   D D - I A V U AcV A I F F P Z Z P F F I A V AcU V A I - D O   O D D A A A A A A A F F P A A A A P F F A A A A A A A D D D   L D D A A A A A A J - - - D N N D - - - J A A A A A A D D L   - D D A A A A A A J - - - D N N D - - - J A A A A A A O D -   - D D A A A A A A J - - - D N N D - - - J A A A A A A D D -   - - O A A A A A A J - - - D N N D - - - J A A A A A A D - -   - - L A A A A A A A C C - D A A D - C C A A A A A A A L - -   - - - B A A A A A A A C - D A A D - C A A A A A A A B - - -   - - - R A A A A A A A A F A A A A F A A A A A A A A B - - -   - - - B A A A A A A A A A A A A A A A A A A A A A A B - - -   - - - B A A A A A A A A A A A A A A A A A A A A A A B - - -   - - - B A A A A A A A A A A A A A A A A A A A A A A B - - -   - - - B A A A A A A A A A A A A A A A A A A A A A A B - - -   - - - B A A A A A A A A A A A A A A A A A A A A A A B - - -   - - - B A A A A A A A A A A A A A A A A A A A A A A B - - -   - - - B A A A A A A A A A A A A A A A A A A A A A A B - - -   - - - B A A A A A A A A A A A A A A A A A A A A A A B - - -   - - - B A A A A A A A A A A A A A A A A A A A A A A B - - -   - - - B A A A A A A A A A A A A A A A A A A A A A A B - - -   - - - B A A A A A A A A A A A A A A A A A A A A A A B - - -   - - - B A A A A A A A A A A A A A A A A A A A A A A B - - -   - - - - I A A A A A A A A A A A A A A A A A A A A I - - - -   - - - - H A A A A A C C C C C C C C C C A A A A A H - - - -   - - - - - H A A A H - C C C C C C C C - H A A A H - - - - -   - - - - - - Q Q Ae- - - C C C C C C - - - Q AeAe- - - - - -   
- - - - D D - - - D - - - - - - - - - - D - - - D D - - - -   - - - I A AbW V W A I - - - - - - - - I A W V W AbA I - - -   - - - B A A A A A A F F F P P P P F F F A A A A A A B - - -   - - - B A A A A A J - - - - L D - - - - J A A A A A B - - -   - - - B A A A A A J - - - - L D - - - - J A A A A A B - - -   - - - B A A A A A J - - - - L D - - - - J A A A A A B - - -   - - - B A A A A A J - - - - D D - - - - J A A A A A B - - -   - - - B A A A A A E - - - - L D - - - - E A A A A A B - - -   - - - B A A A A A A C C - - D D - - C C A A A A A A B - - -   - - - B A A A A A A A A F F A A F F A A A A A A A A B - - -   - - - B A A A A A A A A A A A A A A A A A A A A A A B - - -   - - - B A A A A A A A A A A A A A A A A A A A A A A B - - -   - - - B A A A A A A A A A A A A A A A A A A A A A A R - - -   - - - E A A A A A A A A A A A A A A A A A A A A A A B - - -   - - - B A A A A A A A A A A A A A A A A A A A A A A B - - -   - - - B A A A A A A A A A A A A A A A A A A A A A A B - - -   - - - B A A A A A A A A A A A A A A A A A A A A A A B - - -   - - - B A A A A A A A A A A A A A A A A A A A A A A B - - -   - - - B A A A A A A A A A A A A A A A A A A A A A A B - - -   - - - B A A A A A A A A A A A A A A A A A A A A A A B - - -   - - - B A A A A A A A A A A A A A A A A A A A A A A B - - -   - - - B A A A A A A A A A A A A A A A A A A A A A A B - - -   - - - - I A A A A A A A A A A A A A A A A A A A A I - - - -   - - - - H A A A A A C C C C C C C C C C A A A A A H - - - -   - - - - - H H A H H - C C C C C C C C - H H A H H - - - - -   - - - - - - - Q - - - - C C C S C C - - - - Q - - - - - - -   
- - - - - D D D D D - - - - - - - - - - D D D D D - - - - -   - - - - I A A A A A I - - - - - - - - I A A A A A I - - - -   - - - - E A A A A E - - - - - - - - - - E A A A A E - - - -   - - - - E A A A A J - - - - - - - - - - J A A A A E - - - -   - - - - E A A A A J - - - - - - - - - - J A A A A E - - - -   - - - - E A A A A J - - - - - - - - - - J A A A A E - - - -   - - - - E A A A A J - - - - - - - - - - J A A A A E - - - -   - - - - E A A A A E - - - - - - - - - - E A A A A E - - - -   - - - - E A A A A E - - - - - - - - - - E A A A A E - - - -   - - - - E A A A A A C C C F F F F C C C A A A A A E - - - -   - - - - E A A A A A A A A A A A A A A A A A A A A E - - - -   - - - - E A A A A A A A A A A A A A A A A A A A A E - - - -   - - - - E A A A A A A A A A A A A A A A A A A A A E - - - -   - - - - E A A A A A A A A A A A A A A A A A A A A E - - - -   - - - - E A A A A A A A A A A A A A A A A A A A A E - - - -   - - - - E A A A A A A A A A A A A A A A A A A A A E - - - -   - - - - E A A A A A A A A A A A A A A A A A A A A E - - - -   - - - - E A A A A A A A A A A A A A A A A A A A A E - - - -   - - - - E A A A A A A A A A A A A A A A A A A A A E - - - -   - - - - E A A A A A A A A A A A A A A A A A A A A E - - - -   - - - - E A A A A A A A A A A A A A A A A A A A A E - - - -   - - - - E A A A A A A A A A A A A A A A A A A A A E - - - -   - - - - I A A A A A A A A A A A A A A A A A A A A I - - - -   - - - - Q A A A A A C C C C C C C C C C A A A A A Y - - - -   - - - - - H H H H H - C S C C C C C C - H Y H H H - - - - -   - - - - - - - - - - - - - - - - - - - - - - - - - - - - - -   
- - - - - - O D D - - - - - - - - - - - - O D D - - - - - -   - - - - - I A A A I I - - - - - - - - I I A A A I - - - - -   - - - - - B A A A E - - - - - - - - - - E A A A B - - - - -   - - - - - B A A A E - - - - - - - - - - E A A A B - - - - -   - - - - - B A A A E - - - - - - - - - - E A A A B - - - - -   - - - - - B A A A E - - - - - - - - - - E A A A B - - - - -   - - - - - B A A A E - - - - - - - - - - E A A A B - - - - -   - - - - - B A A A E - - - - - - - - - - E A A A B - - - - -   - - - - - B A A A E - - - - - - - - - - E A A A B - - - - -   - - - - - B A A A E C S C - - - - C S C E A A A B - - - - -   - - - - - B A A A E C C C C C C C C C C E A A A E - - - - -   - - - - - B A A A E C K K K K K K K K C E A A A B - - - - -   - - - - - B A A A E K C C C C C C C C K E A A A B - - - - -   - - - - - E A A A E C C C C C C C C C S E A A A B - - - - -   - - - - - B A A A E C C K C C K C K C C E A A A E - - - - -   - - - - - M A A A E C K AgK C K C K C C E A A A M - - - - -   - - - - - M A A A E C C K C C K C K C C E A A A M - - - - -   - - - - - M A A A E C S C C C C S C S C E A A A M - - - - -   - - - - - M A A A E C C C C C C C C C C E A A A M - - - - -   - - - - - M A A A E C K C C K K K K K C E A A A M - - - - -   - - - - - B A A A E C C C S K L Z L K C E A A A B - - - - -   - - - - - B A A A E C C C C K L L L K C E A A A B - - - - -   - - - - - I A A A I C K C C K K K K K C I A A A I - - - - -   - - - - - Y A A A H C C C C C C C S C T H A A A H - - - - -   - - - - - - H H H Y - - - - - - - - - - H H H Q - - - - - -   - - - - - - - - - - - - - - - - - - - - - - - - - - - - - -   
- - - - - - - - - - - - - - - - - - - - - - - - - - - - - -   - - - - - - I I I - - - - - - - - - - - - I I I - - - - - -   - - - - - - E B B - - - - - - - - - - - - B B E - - - - - -   - - - - - - E A B - - - - - - - - - - - - B A E - - - - - -   - - - - - - E A B - - - - - - - - - - - - B A E - - - - - -   - - - - - - E A B - - - - - - - - - - - - B A E - - - - - -   - - - - - - E A B - - - - - - - - - - - - B A E - - - - - -   - - - - - - E A B - - - - - - - - - - - - B A E - - - - - -   - - - - - - E A B - - - - - - - - - - - - B A E - - - - - -   - - - - - - E A B - - - - - - - - - - - - B A E - - - - - -   - - - - - - E A B - - - - - - - - - - - - B A E - - - - - -   - - - - - - E A B - - T T T T T T T T - - B A E - - - - - -   - - - - - - E A B - T - - - - - - - - T - B A E - - - - - -   - - - - - - E A B - - - - - - - - - - - - B A E - - - - - -   - - - - - - E A B - - - F - - N - Af- - - B A E - - - - - -   - - - - - - E A B - - F - F - Ah- Ai- - - B A E - - - - - -   - - - - - - E A B - - - F - - Af- Aj- - - B A E - - - - - -   - - - - - - E A B - - - - - - - - - - - - B A E - - - - - -   - - - - - - E A B - - - - - - - - - - - - B A E - - - - - -   - - - - - - E A B - - Ak- - F F F F F - - B A E - - - - - -   - - - - - - E A B - - - - - F - - - F - - B A E - - - - - -   - - - - - - E A B - - - - - F - - - F - - B A E - - - - - -   - - - - - - I A I - - Al- - F F F F F - - I A I - - - - - -   - - - - - - H A H - - - - - - - - - - - - H A H - - - - - -   - - - - - - - H H - - - - - - - - - - - - H H - - - - - - -   - - - - - - - - - - - - - - - - - - - - - - - - - - - - - -   
- - - - - - - - - - - - - - - - - - - - - - - - - - - - - -   - - - - - - - - - - - - - - - - - - - - - - - - - - - - - -   - - - - - - - - - - - - - - - - - - - - - - - - - - - - - -   - - - - - - - D - - - - - - - - - - - - - - D - - - - - - -   - - - - - - - D - - - - - - - - - - - - - - D - - - - - - -   - - - - - - - D - - - - - - - - - - - - - - D - - - - - - -   - - - - - - - D - - - - - - - - - - - - - - D - - - - - - -   - - - - - - - D - - - - - - - - - - - - - - D - - - - - - -   - - - - - - - D - - - - - - - - - - - - - - D - - - - - - -   - - - - - - - D - - - - - - - - - - - - - - D - - - - - - -   - - - - - - - D - - - - - - - - - - - - - - D - - - - - - -   - - - - - - - D - - - - - - - - - - - - - - D - - - - - - -   - - - - - - - D - - - - - - - - - - - - - - D - - - - - - -   - - - - - - - D - - - - - - - - - - - - - - D - - - - - - -   - - - - - - - D - - - - - - - - - - - - - - D - - - - - - -   - - - - - - - D - - - - - - - - - - - - - - D - - - - - - -   - - - - - - - D - - - - - - - - - - - - - - D - - - - - - -   - - - - - - - D - - - - - - - - - - - - - - D - - - - - - -   - - - - - - - D - - - - - - - - - - - - - - D - - - - - - -   - - - - - - - D - - - - - - - - - - - - - - D - - - - - - -   - - - - - - - D - - - - - - - - - - - - - - D - - - - - - -   - - - - - - - O - - - - - - - - - - - - - - D - - - - - - -   - - - - - - - D - - - - - - - - - - - - - - D - - - - - - -   - - - - - - - L - - - - - - - - - - - - - - L - - - - - - -   - - - - - - - - - - - - - - - - - - - - - - - - - - - - - -   - - - - - - - - - - - - - - - - - - - - - - - - - - - - - -   
- - - - - - - - - - - - - - - - - - - - - - - - - - - - - -   - - - - - - - - - - - - - - - - - - - - - - - - - - - - - -   - - - - - - - - - - - - - - - - - - - - - - - - - - - - - -   - - - - - - - D - - - - - - - - - - - - - - D - - - - - - -   - - - - - - - O - - - - - - - - - - - - - - D - - - - - - -   - - - - - - - D - - - - - - - - - - - - - - O - - - - - - -   - - - - - - - D - - - - - - - - - - - - - - D - - - - - - -   - - - - - - - D - - - - - - - - - - - - - - D - - - - - - -   - - - - - - - D - - - - - - - - - - - - - - D - - - - - - -   - - - - - - - - - - - - - - - - - - - - - - - - - - - - - -   - - - - - - - D - - - - - - - - - - - - - - D - - - - - - -   - - - - - - - D - - - - - - - - - - - - - - D - - - - - - -   - - - - - - - D - - - - - - - - - - - - - - O - - - - - - -   - - - - - - - O - - - - - - - - - - - - - - D - - - - - - -   - - - - - - - D - - - - - - - - - - - - - - D - - - - - - -   - - - - - - - D - - - - - - - - - - - - - - D - - - - - - -   - - - - - - - D - - - - - - - - - - - - - - D - - - - - - -   - - - - - - - D - - - - - - - - - - - - - - D - - - - - - -   - - - - - - - L - - - - - - - - - - - - - - D - - - - - - -   - - - - - - - D - - - - - - - - - - - - - - O - - - - - - -   - - - - - - - D - - - - - - - - - - - - - - D - - - - - - -   - - - - - - - D - - - - - - - - - - - - - - D - - - - - - -   - - - - - - - - - - - - - - - - - - - - - - - - - - - - - -   - - - - - - - - - - - - - - - - - - - - - - - - - - - - - -   - - - - - - - - - - - - - - - - - - - - - - - - - - - - - -   - - - - - - - - - - - - - - - - - - - - - - - - - - - - - -   
- - - - - - - - - - - - - - - - - - - - - - - - - - - - - -   - - - - - - - - - - - - - - - - - - - - - - - - - - - - - -   - - - - - - - D - - - - - - - - - - - - - - D - - - - - - -   - - - - - - - D - - - - - - - - - - - - - - D - - - - - - -   - - - - - - - D - - - - - - - - - - - - - - D - - - - - - -   - - - - - - - D - - - - - - - - - - - - - - D - - - - - - -   - - - - - - - - - - - - - - - - - - - - - - - - - - - - - -   - - - - - - - D - - - - - - - - - - - - - - D - - - - - - -   - - - - - - - D - - - - - - - - - - - - - - D - - - - - - -   - - - - - - - D - - - - - - - - - - - - - - O - - - - - - -   - - - - - - - D - - - - - - - - - - - - - - D - - - - - - -   - - - - - - - - - - - - - - - - - - - - - - - - - - - - - -   - - - - - - - D - - - - - - - - - - - - - - D - - - - - - -   - - - - - - - D - - - - - - - - - - - - - - D - - - - - - -   - - - - - - - D - - - - - - - - - - - - - - D - - - - - - -   - - - - - - - D - - - - - - - - - - - - - - D - - - - - - -   - - - - - - - O - - - - - - - - - - - - - - D - - - - - - -   - - - - - - - - - - - - - - - - - - - - - - - - - - - - - -   - - - - - - - - - - - - - - - - - - - - - - - - - - - - - -   - - - - - - - - - - - - - - - - - - - - - - - - - - - - - -   - - - - - - - - - - - - - - - - - - - - - - - - - - - - - -   - - - - - - - - - - - - - - - - - - - - - - - - - - - - - -   - - - - - - - - - - - - - - - - - - - - - - - - - - - - - -   - - - - - - - - - - - - - - - - - - - - - - - - - - - - - -   - - - - - - - - - - - - - - - - - - - - - - - - - - - - - -   - - - - - - - - - - - - - - - - - - - - - - - - - - - - - -   
- - - - - - - D - - - - - - - - - - - - - - D - - - - - - -   - - - - - - - L - - - - - - - - - - - - - - D - - - - - - -   - - - - - - - L - - - - - - - - - - - - - - D - - - - - - -   - - - - - - - L - - - - - - - - - - - - - - D - - - - - - -   - - - - - - - L - - - - - - - - - - - - - - L - - - - - - -   - - - - - - - L - - - - - - - - - - - - - - L - - - - - - -   - - - - - - - L - - - - - - - - - - - - - - L - - - - - - -   - - - - - - - L - - - - - - - - - - - - - - L - - - - - - -   - - - - - - - L - - - - - - - - - - - - - - L - - - - - - -   - - - - - - - D - - - - - - - - - - - - - - L - - - - - - -   - - - - - - - L - - - - - - - - - - - - - - L - - - - - - -   - - - - - - - D - - - - - - - - - - - - - - L - - - - - - -   - - - - - - - D - - - - - - - - - - - - - - D - - - - - - -   - - - - - - - - - - - - - - - - - - - - - - - - - - - - - -   - - - - - - - - - - - - - - - - - - - - - - - - - - - - - -   - - - - - - - - - - - - - - - - - - - - - - - - - - - - - -   - - - - - - - - - - - - - - - - - - - - - - - - - - - - - -   - - - - - - - - - - - - - - - - - - - - - - - - - - - - - -   - - - - - - - - - - - - - - - - - - - - - - - - - - - - - -   - - - - - - - - - - - - - - - - - - - - - - - - - - - - - -   - - - - - - - - - - - - - - - - - - - - - - - - - - - - - -   - - - - - - - - - - - - - - - - - - - - - - - - - - - - - -   - - - - - - - - - - - - - - - - - - - - - - - - - - - - - -   - - - - - - - - - - - - - - - - - - - - - - - - - - - - - -   - - - - - - - - - - - - - - - - - - - - - - - - - - - - - -   - - - - - - - - - - - - - - - - - - - - - - - - - - - - - -   
