model
size = 32 10 9, scale = 0.05, origin = -y
material 
  colors = A:#434242 B:#757474 C:#9F9E9E
voxels
109-2(B4-B26-)C4-C26-C4-C24-2C6-2C152-B4-B25-2B4-2B24-2B4-2B23-2B6-2B20-4B6-4B18-3C8-3C18-C12-C54-A4-A25-2A4-2A24-2A4-2A22-4A4-4A20-4A4-4A19-4A6-4A18-3AB6-B3A17-B2CB8-B2CB14-5C10-5C13-2C14-2C19-2A4-2A23-3A4-3A21-4A4-4A20-4A4-4A19-4A6-4A17-5A6-5A15-4AB8-B4A13-3BCB10-BC3B10-6C12-6C8-5C14-5C47-2A6-2A19-5A6-5A2(16-4A8-4A)14-6A8-6A12-5A10-5A8-8B12-8B4-7C14-7C5-4C18-4C2(12-A)17-3A10-3A15-4A10-4A13-5A10-5A11-6A10-6A9-6A12-6A5-8A14-8A2-7B16-7B3-5C18-5C43-A12-A17-2A12-2A13-5A12-5A10-4A14-4A9-5A14-5A4-8A16-8A-6A18-6A2-C4B20-4BC102-A20-A2(10-2A18-2A)5-2A2-2A20-2A2-2AB4A22-4A5B24-4B224-B30-B160-
