model
size = 31 30 26, scale = 0.05, origin = -y
material 
  colors = A:#D00 B:#E00 C:#777 D:#555 E:#EEE F:#500 G:#B00 H:#400 I:#A00 J:#800 K:#700 L:#222 M:#111 N:#444 O:#888
voxels
------------------------------- ------------------------------- ------------------------------- ------------------------------- ------------------------------- -------------L-L-L------------- --------------LLL-------------- ---------------L--------------- ------------------------------- ------------------------------- ------------------------------- ------------------------------- ------------------------------- ------------------------------- ------------------------------- ------------------------------- ------------------------------- ------------------------------- ------------------------------- ------------------------------- ------------------------------- ------------------------------- ------------------------------- ------------------------------- ------------------------------- ------------------------------- ------------------------------- ------------------------------- ------------------------------- ------------------------------- 
------------------------------- ------------------------------- ------------------------------- ------------------------------- ------------------------------- -------------LLLLL------------- --------------LLL-------------- ---------------L--------------- ------------------------------- ------------------------------- ------------------------------- ------------------------------- ------------------------------- ------------------------------- ------------------------------- ------------------------------- ------------------------------- ------------------------------- ------------------------------- ------------------------------- ------------------------------- ------------------------------- ------------------------------- ------------------------------- ------------------------------- ------------------------------- ------------------------------- ------------------------------- ------------------------------- ------------------------------- 
----------CCBBBBBBBCC---------- ----------CDDBBBBBDDC---------- ----------CCDDDDDDDCC---------- ----------CCCCCDCCCCC---------- ----------EEEEEDEEEEE---------- ----------EEELLLLLEEE---------- ----------EEEELLLEEEE---------- ----------EEEEELEEEEE---------- -----------BBBEEEBBB----------- ------------MBEEEBM------------ -----------C-------C----------- -----------C-------C----------- ------------MBEEEBM------------ -----------BBBEEEBBB----------- ----------EEEEELEEEEE---------- ----------EEEELLLEEEE---------- ----------EEELLLLLEEE---------- ----------EEEEDDDEEEE---------- ----------DDDDDDDDDDD---------- ----------DDDDDDDDDDD---------- ------------AAAAIII------------ -------------AAAIJ------------- --------------KKH-------------- ------------------------------- ------------------------------- ------------------------------- ------------------------------- ------------------------------- ------------------------------- ------------------------------- 
--------CCCCCCCCCCCCCCC-------- --------CCCDDDDDDDDDCCC-------- --------CCCCCCCDCCCCCCC-------- --------CDCCCCCDCCCCCDC-------- --------EEEEEEEDEEEEEEE-------- --------EEEEEEEDEEEEEEE-------- --------EEEEEEEDEEEEEEE-------- ---------EBBBBEDEEEEEE--------- ---------BBBBBEEEBBBBB--------- ----------MMBBEEEBBMM---------- ----------MOMBEEEBMOM---------- ----------MOMBEEEBMOM---------- ----------MMBBEEEBBMM---------- ---------BBBBBEEEBBBBB--------- ---------EEEEEEDEBBBBE--------- --------EEEEEEEDEEEEEEE-------- --------EEEEEEEDEEEEEEE-------- --------EEEEEEEDEEEEEEE-------- --------CCCCCCCDCCCCCCC-------- --------CCCCCCCDCCCCCCC-------- ----------AAAAAAAAAAA---------- ----------AAAAAAAAJJJ---------- -----------AAGGAHHGG----------- -----------AAGGAHHAK----------- -------------KGHAA------------- ------------------------------- ------------------------------- ------------------------------- ------------------------------- ------------------------------- 
-------CCCCC-------CCCCC------- -------CCCCD-------DCCCC------- -------CCCCC-------CCCCC------- -------CCCCC-------CCCCC------- -------EEEEE-------BBBBE------- -------EEEEE-------BBBBE------- -------EBBBB-------BBBBE------- -------EEBBB-------BBEEE------- --------EMBB-------BBME-------- --------EBBB-------BBBE-------- ---------BMMM-----MMMB--------- ---------BMBM-----MBMB--------- --------EBBBB-----BBBBE-------- --------EMBB-------BBME-------- -------EEEBB-------BBBEE------- -------EBBBB-------BBBBE------- -------EBBBB-------EEEEE------- -------EBBBB-------EEEEE------- -------CCCCC-------CCCCC------- -------CCCCC-------CCCCC------- --------AAAAAAAAAAAGGGG-------- ---------AAAAAAAAAAGGG--------- ---------HAAAAAAAAAGGG--------- ----------AAAAAAAAAGG---------- ----------IIKKAHAAAGG---------- ------------AAAHAAH------------ --------------AAA-------------- ------------------------------- ------------------------------- ------------------------------- 
------CCCC-----------CCCC------ ------CCCC-----------CCCC------ ------CCCC-----------BBBC------ ------CCCC-----------BBBC------ ------CDBB-----------BBEC------ ------CEBB-----------BBEC------ ------CEBB-----------BBEC------ ------CEBB-----------EEEC------ -------EBM-----------MEE------- -------EBM-----------BEE------- --------EB-----------BE-------- --------EB-----------ME-------- -------EEB-----------MBE------- -------EEM-----------MBE------- ------CEEE-----------BBEC------ ------CEBB-----------BBEC------ ------CEBB-----------BBEC------ ------CEBB-----------BBDC------ ------CBBC-----------CCCC------ ------CBBB-----------CCCC------ -------AAAAAAAAAAAAAAAAA------- -------AAAAAAAAAAAAAAAAA------- --------AAAAAAAAAAAAAAH-------- --------JJAAAAAAAAAAAAH-------- ---------JGAAAAAAAAAAF--------- ----------AAAAAAAAHAA---------- -----------AHAAAAIHA----------- -------------KAAAI------------- ------------------------------- ------------------------------- 
-----C----------------CCCC----- -----C----------------CCCC----- -----DBBB-------------BBCD----- -----DCBB-------------BBCD----- -----DCDB-------------BECD----- -----DCEB-------------BECD----- -----DCEB-------------BECD----- ------CEB-------------EEC------ ------CEB-------------EEC------ ------CEB-------------EEC------ -------EE-------------EE------- -------EE-------------BE------- ------CEE-------------BEC------ ------CEE-------------BEC------ ------CEE-------------BEC------ -----DCEB-------------BECD----- -----DCEB-------------BECD----- -----DCEB-------------BDCD----- -----DCBB-------------BBCD----- -----DCBB-------------BBBD----- ------AAAAAAAAAAAAAAAAAAA------ -------AAAAAAAAAAAAAAAAA------- -------IAAAAAAAAAAAAAAAA------- -------HHJAAAAAAAAAAAAAA------- --------HJAAAAAAAAAAAFF-------- ---------AAAAAAAAAAAKF--------- ----------AAAAAAAIAAK---------- -----------KKKAAAIAA----------- --------------HHH-------------- ------------------------------- 
-----C------------------CC----- -----C------------------CC----- -----DB-----------------CD----- -----DC-----------------CD----- -----DC-----------------CD----- -----DC-----------------CD----- -----DC-----------------CD----- -----DC-----------------CD----- -----DC-----------------CD----- ------C-----------------C------ ------C-----------------C------ ------C-----------------C------ ------C-----------------C------ -----DC-----------------CD----- -----DC-----------------CD----- -----DC-----------------CD----- -----DC-----------------CD----- -----DC-----------------CD----- -----DC-----------------CD----- -----DC-----------------BD----- ------AAAAAAAAAAAAAAAAAAA------ ------AAAAAAAAAAAAAAAAAAH------ ------IIAAAAAAAAAAAAAAAAI------ -------IAAAAAAAAAAAAAAAA------- -------AAAAAAAAAAAAAAFFF------- --------AAAAAAAAAAAAKFF-------- ---------AAAAAAAAAAAKF--------- ----------AKKKGGGGGGK---------- ------------KKHHHHH------------ ------------------------------- 
----CC------------------CCC---- ----CC------------------CCC---- ----DDB-----------------CDD---- ----DDC-----------------CDD---- ----DDC-----------------CDD---- ----DDC-----------------CDD---- ----DDC-----------------CDD---- ----DDC-----------------CDD---- -----DC-----------------CD----- -----DC-----------------CD----- ------C-----------------C------ ------C-----------------C------ -----DC-----------------CD----- -----DC-----------------CD----- ----DDC-----------------CDD---- ----DDC-----------------CDD---- ----DDC-----------------CDD---- ----DDC-----------------CDD---- ----DDC-----------------CDD---- ----DDC-----------------BDD---- -----AAAAAAAAAAAAAAAAAAAGG----- -----AAAAAAAAAAAAAAAAAAAHH----- ------AAAAAAAAAAAAAAAAAAG------ ------AAAAAAAAAAAAAAAAAAG------ ------HAAAAAAAAAAAAAAFFFF------ -------AAAAAAAAAAAAAAFFF------- --------AAAAAAAAAAAAAFF-------- ---------HAKKKGGGGGGGF--------- ----------AKKKHHHHHHG---------- -------------KHHHH------------- 
----CC------------------CCC---- ----CC------------------CCC---- ----DDB-----------------CDD---- ----DDC-----------------CDD---- ----DDC-----------------CDD---- ----DDC-----------------CDD---- ----DDC-----------------CDD---- ----DDC-----------------CDD---- ----DDC-----------------CDD---- -----DC-----------------CD----- -----DC-----------------CD----- -----DC-----------------CD----- -----DC-----------------CD----- ----DDC-----------------CDD---- ----DDC-----------------CDD---- ----DDC-----------------CDD---- ----DDC-----------------CDD---- ----DDC-----------------CDD---- ----DDC-----------------CDD---- ----DDC-----------------BDD---- -----AAAAAAAAAAAAAAAAAAAGG----- -----FAAAAAAAAAAAAAAAAAAGG----- -----AAAAAAAAAAAAAAAAAAAGG----- -----AAAAAAAAAAAAAAAAAAAGG----- ------AAAAAAAAAAAAAAAFFFF------ -------AAAAAAAAAAAAAAFFF------- -------GAAAAAAAAAAAAAFFH------- --------AAAKKKAAAAAAAFF-------- ----------JKKKHHHHHHA---------- -----------KKKHHHHHH----------- 
----CC-------------------CC---- ----CC-------------------CC---- ----DB-------------------BD---- ---HDB-------------------BBH--- ---HDB-------------------BBH--- ---HDB-------------------BBH--- ----DB-------------------BD---- ----DB-------------------BD---- ----DB-------------------DD---- ----DBD------------------DD---- -----DD------------------D----- -----DD------------------D----- ----DDDD-----------------BD---- ----DD-D-----------------BD---- ----DB-------------------BD---- ----DB-------------------BD---- ---HBB-------------------BDH--- ---HBB-------------------BDH--- ---HBB-------------------BDH--- ----DB-------------------BD---- ----AAAAAAAAAAAAAAAAAAAAGGG---- -----FAAAAAAAAAAAAAAAAAAGG----- -----AAAAAAAAAAAAAAAAAAAGG----- -----AAAAAAAAAAAAAAAAAAAGH----- ------AAAAAAAAAAAAAAAFFFF------ ------AAAAAAAAAAAAAAAFFFF------ -------IIAAAAAAAAAAAAFFF------- --------IAAAAAAAAAAAAFF-------- ---------JJJJAAAIIIIIF--------- -----------JJAAAIIII----------- 
----CC-------------------CC---- ----CC-------------------CC---- ---HDB-------------------BBH--- --GHDB-------------------BBHG-- --GHDB-------------------BBHG-- --GHDB-------------------BBHG-- ---HDB-------------------BBH--- ----DB-------------------BD---- ----DB-------------------DD---- ----DB-------------------DD---- -----D-------------------D----- -----D-------------------D----- ----DDD------------------BD---- ----DD-------------------BD---- ----DB-------------------BD---- ---HBB-------------------BDH--- --GHBB-------------------BDHG-- --GHBB-------------------BDHG-- --GHBB-------------------BDHG-- ---HBB-------------------BDH--- ----AAAAAAAAAAAAAAAAAAAAAAA---- ----AAAAAAAAAAAAAAAAAAAAAAA---- -----AAAAAAAAAAAAAAAAAAAAA----- -----HAAAAAAAAAAAAAAAAAAAA----- -----AAAAAAAAAAAAAAAAFFFFA----- ------AAAAAAAAAAAAAAAFFFF------ -------GAAAAAAAAAAAAAFFF------- -------GAAAAAAAAAAAAAFFF------- ---------GAAAAAAIIIIIF--------- ----------IIIAGGIIIIJ---------- 
----CC-------------------CC---- ----CC-------------------CC---- ---HBB-------------------BBH--- --GHBB-------------------BBHG-- GGIHBB-------------------BBHIGG G-GHBB-------------------BBHG-G G--HBB-------------------BBH--G G--HBB-------------------BBH--G G---DB-------------------DD---G G---DB-------------------DD---G G----D-------------------D----G G----D-------------------D----G G---DDD------------------BD---G G---DD-------------------BD---G G--HBB-------------------BBH--G G--HBB-------------------BBH--G G-GHBB-------------------BBHG-G GGIHBB-------------------BBHIGG --GHBB-------------------BBHG-- ---HBB-------------------BBH--- ----AAAAAAAAAAAAAAAAAAAAAAA---- ----AAAAAAAAAAAAAAAAAAAAAAA---- ----AAAAAAAAAAAAAAAAAAAAAAA---- -----HAAAAAAAAAAAAAAAAAAAA----- -----AAAAAAAAAAAAAAAAFFFFA----- ------AAAAAAAAAAAAAAAFFFF------ ------AAAAAAAAAAAAAAAFFFF------ -------AAAAAAAAAAAAAAFFH------- --------AGGAAAAAIIIIIFF-------- ----------IIIAGGIIIIJ---------- 
----CC-------------------CC---- ----CC-------------------CC---- ---HAA-------------------BBH--- GGGHAA-------------------BBHGGG IIIHAA-------------------BBHIII IGGHAA-------------------BBHGGI I--HBB-------------------BBH--I I--HBB-------------------BBH--I I---DB-------------------DD---I I---DB-------------------DD---I I----D-------------------D----I I----D-------------------D----I I---DDD------------------BD---I I---DD-------------------BD---I I--HBB-------------------BBH--I I--HBB-------------------BBH--I IGGHBB-------------------AAHGGI IIIHBB-------------------AAHIII GGGHBB-------------------AAHGGG ---HBB-------------------AAH--- ----AAAAAAAAAAAAAAAAAAAAAAA---- ----AAAAAAAAAAAAAAAAAAAAAAA---- ----AAAAAAAAAAAAAAAAAAAAAAA---- -----AAAAAAAAAAAAAAAAAAAAA----- -----JAAAAAAAAAAAAAAAFFFFH----- ------AAAAAAAAAAAAAAAFFFF------ ------AAAAAAAAAAAAAAAFFFF------ -------AAAAAAAAAAAAAAFFF------- --------AAAAAAAAIIIIIFF-------- ----------IIIAAAIIIII---------- 
----CC-------------------CC---- ----CC-------------------CC---- ---HBB-------------------BBH--- --GHBB-------------------BBHG-- GGIHBB-------------------BBHIGG G-GHBB-------------------BBHG-G G--HBB-------------------BBH--G G--HBB-------------------BBH--G G---DB-------------------DD---G G---DB-------------------DD---G G----D-------------------D----G G----D-------------------D----G G---DDD------------------BD---G G---DD-------------------BD---G G--HBB-------------------BBH--G G--HBB-------------------BBH--G G-GHBB-------------------BBHG-G GGIHBB-------------------BBHIGG --GHBB-------------------BBHG-- ---HBB-------------------BBH--- ----AAAAAAAAAAAAAAAAAAAAAAA---- ----AAAAAAAAAAAAAAAAAAAAAAA---- ----AAAAAAAAAAAAAAAAAAAAAAA---- -----AAAAAAAAAAAAAAAAAAAAA----- -----JAAAAAAAAAAAAAAAFFFFH----- ------FAAAAAAAAAAAAAAFFFF------ ------FAAAAAAAAAAAAAAFFFF------ -------AAAAAAAAAAAAAAFFF------- --------FFAAAAAAAAAAAFF-------- ----------JJJAAJJJJJI---------- 
----CC-------------------CC---- ----CC-------------------CC---- ---HBB-------------------BBH--- --GHBB-------------------BBHG-- --GHBB-------------------BBHG-- --GHBB-------------------BBHG-- ---HBB-------------------BBH--- ----DB-------------------BD---- ----DB-------------------DD---- ----DB-------------------DD---- -----D-------------------D----- -----D-------------------D----- ----DDD------------------BD---- ----DD-------------------BD---- ----DB-------------------BD---- ---HBB-------------------BBH--- --GHBB-------------------BBHG-- --GHBB-------------------BBHG-- --GHBB-------------------BBHG-- ---HBB-------------------BBH--- ----AAAAAAAAAAAAAAAAAAAAAAA---- ----AAAAAAAAAAAAAAAAAAAAAAA---- -----AAAAAAAAAAAAAAAAAAAAA----- -----IIAAAAAAAAAAAAAAAAAAA----- -----KIAAAAAAAAAAAAAGGGGGG----- ------FAAAAAAAAAAAAAGGIII------ -------AAAAAAAAAAAAAAAII------- -------AAAAAAAAAAAAAAKKK------- ---------FAAAAAAAAAAAK--------- ----------HJJKKKKJJJA---------- 
----CC-------------------C----- ----CC-------------------C----- ----DB-------------------BD---- ---HBB-------------------BBH--- ---HBB-------------------BBH--- ---HBB-------------------BBH--- ----DB-------------------BD---- ----DB-------------------BD---- ----DB-------------------DD---- ----DBD------------------DD---- -----FD------------------D----- -----DK------------------F----- ----DDK------------------BD---- ----DD-I-----------------BD---- ----DB-------------------BD---- ----DB-------------------BD---- ---HBB-------------------BBH--- ---HBB-------------------BBH--- ---HBB-------------------BBH--- ----DB-------------------BD---- ----AAAAAAAAAAAAAAAAAAAAAAA---- -----AAAAAAAAAAAAAAAAAAAAA----- -----FFFAAAAAAAAAAAAAAAAAA----- -----FFFAAAAAAAAAAAAAAAAAA----- ------FFAAAAAAAAAAAAGGGGG------ ------FFAAAAAAAAAAAAGGIII------ -------AAAAAAAAAAAAAAAII------- --------AAAAAAAAAAAAAJI-------- ---------FAAAAAAAAAAAJ--------- -----------AAKKKKJJJ----------- 
----CCC------------------C----- ----CCC------------------C----- ----DBB------------------BD---- ----DBB------------------BD---- ----DBB------------------BD---- ----DBB------------------BD---- ----DBB------------------BD---- ----DBB------------------BD---- ----DBB------------------BD---- -----FBJ-----------------F----- -----FK------------------F----- -----FB------------------F----- -----FBJ-----------------F----- ----DBB------------------BD---- ----DBB------------------BD---- ----DBB------------------BD---- ----DBB------------------BD---- ----DBB------------------BD---- ----DBB------------------BD---- ----DBB------------------BD---- -----AAAAAAAAAAAAAAAAAAAAA----- -----AAAAAAAAAAAAAAAAAAAAA----- -----FFFAAAAAAAAAAAAAAAAAH----- -----FFFAAAAAAAAAAAAAAAAAA----- ------FFAAAAAAAAAAAAGGGGG------ -------FAAAAAAAAAAAAGGGG------- -------AAAAAAAAAAAAAAAAA------- --------AAAAAAAAAAAAAJA-------- ----------AAAAAAAAAAJ---------- -----------AAAAJJJJJ----------- 
----CCC------------------C----- ----CCC------------------C----- ----DBB------------------BD---- ----DBB------------------BD---- ----DBB------------------BD---- ----DBB------------------BD---- ----DBB------------------BD---- ----DBB------------------BD---- -----FB------------------F----- -----FBJ-----------------F----- ------K------------------H----- ------K------------------H----- -----FBJ-----------------F----- -----FB------------------F----- ----DBB------------------BD---- ----DBB------------------BD---- ----DBB------------------BD---- ----DBB------------------BD---- ----DBB------------------BD---- ----DBB------------------BD---- -----AAAAAAAAAAAAAAAAAAAAA----- -----AAAAAAAAAAAAAAAAAAAAA----- ------AAAAAAAAAAAAAAAAAAA------ ------AAAAAAAAAAAAAAAAAAA------ ------AAAAAAAAAAAAAAGGGGG------ -------AAAAAAAAAAAAAGGGG------- --------HAAAAAAAAAAAAAA-------- ---------AAAAGGGAAAAAJ--------- ----------FAAGIGAAAAJ---------- -------------GIKAG------------- 
------C-----------------C------ ------C-----------------C------ -----FB-----------------BF----- -----FB-----------------BF----- -----FB-----------------BF----- -----FB-----------------BF----- -----FB-----------------BF----- -----FB-----------------BF----- -----FB-----------------BN----- ------KB----------------K------ ------ND----------------K------ ------KB----------------H------ ------KB----------------H------ -----NBB-----------------F----- -----FBB-----------------F----- -----FBB-----------------F----- -----FBB-----------------F----- -----FBB-----------------F----- -----FBB-----------------F----- -----FBB-----------------F----- ------AAAAAAAAAAAAAAAAAAA------ ------AAAAAAAAAAAAAAAAAAA------ ------IIAAAAAAAAAAAAAAAAA------ -------IAAAAAAAAAAAAAAAA------- -------AAAAAAAAAAAAAGGGG------- --------AAAAAAAAAAAAGGG-------- ---------AAAAAAAAAAAAA--------- ----------AAAGGGAAAAA---------- ------------AGIGAAA------------ ------------------------------- 
------C----------------CC------ ------C----------------CC------ -----FB----------------BBF----- -----FB----------------BBF----- -----FB----------------BBF----- -----FB----------------BBF----- -----FB----------------BBF----- ------K----------------BK------ ------K----------------BK------ ------KB---------------CK------ -------JI--------------C------- -------CB--------------J------- ------KCBA-------------BK------ ------KBB--------------BK------ ------KBB--------------BK------ -----FBBB--------------BBF----- -----FBBB--------------BBF----- -----FBBB--------------BBF----- -----FBBB--------------BBF----- -----FBBB--------------BBF----- ------AAAAAAAAAAAAAAAAAAA------ -------AAAAAAAAAAAAAAAAA------- -------AAAAAAAAAAAAAAAAA------- -------AAAAAAAAAAAAAAAAA------- --------AAAAAAAAAAAAGGG-------- ---------AAAAAAAAAAAGG--------- ----------AAAAAAAAAAA---------- -----------AAGGGAAAA----------- --------------GGA-------------- ------------------------------- 
------D--------------CCC------- ------D--------------CCC------- ------K--------------BBBK------ ------K--------------BBBK------ ------K--------------BBBK------ ------N--------------BBBD------ ------K--------------BBBD------ ------C--------------BBBC------ -------J-------------BBJ------- -------J-------------BBC------- --------IA-----------AI-------- --------IB-----------BI-------- -------CBB-----------BBJ------- -------JBB-----------BBJ------- ------CBBB-----------BBBC------ ------DBBB-----------BBBK------ ------DBBB-----------BBBN------ ------KBBB-----------BBBK------ ------KBBB-----------BBBK------ ------KBBB-----------BBBK------ -------AAAAAAAAAAAAAAAAA------- -------AAAAAAAAAAAAAAAAA------- --------AAAAAAAAAAAAAAA-------- --------AAAAAAAAAAAAAFA-------- ---------AAJJJFAAAAAGF--------- ----------AJJJFAAAAAF---------- -----------JJJFAAAAA----------- -------------GFGAA------------- ------------------------------- ------------------------------- 
-------DC----------CCCC-------- -------DC----------CCCC-------- -------HB----------BBBBH------- -------HB----------BBBBH------- -------HB----------BBBBN------- -------HB----------BBBBH------- -------HB----------BBBBL------- -------HCCC--------BBBHH------- --------HBB--------BBBH-------- --------HHBBHHCCHHHBBHH-------- ---------HHH-------HHH--------- ---------HHB-------BHH--------- --------HHBBHHHCCHHBBHH-------- --------HBBB-------BBBH-------- -------HHBBB-------BCCCH------- -------LBB---------BBBBH------- -------HBB---------BBBBH------- -------NBB---------BBBBH------- -------HBB---------BBBBH------- -------HBB---------BBBBH------- --------AAAAAAAAAAAAAAA-------- ---------KKKKKAAAAAAAA--------- ---------AAAAAAAAAAAAA--------- ----------AAAAAAAAIAA---------- ----------AJKKFAAFFAA---------- ------------KKFAAAA------------ --------------FAA-------------- ------------------------------- ------------------------------- ------------------------------- 
--------DDCC-------CC---------- --------DDCC-------CC---------- --------FFBBBBBBBBBBBFF-------- --------FFBBBBBBBBBBBDF-------- --------FFBBBBBBBBBBBFF-------- --------FFBBBBBBBBBBBFN-------- --------FFBBBBBBBBBBBFF-------- ---------CCBBBBBBBBBBD--------- ---------FFBBBBBBBBBFF--------- ----------DFBBBBBBBFF---------- -----------FDFFFLFFF----------- -----------FDFFFFFFF----------- ----------FFBBBBBBBFD---------- ---------FFBBBBBBBBBFF--------- ---------DBBBBBBBBBBCC--------- --------FFBBBBBBBBBBBFF-------- --------NFBBBBBBBBBBBFF-------- --------FFBBBBBBBBBBBFF-------- --------FDCCCCCBBBBBBFF-------- --------FFCCBBBBBBBBBFF-------- ----------AAAAAAAAAAA---------- ----------KKKKAAAAAAA---------- -----------AAGGGAAGJ----------- -----------AAGGGAAIJ----------- -------------FFFFF------------- ------------------------------- ------------------------------- ------------------------------- ------------------------------- ------------------------------- 
----------DDDCCCCCDDD---------- ----------DDDCCCCCDDD---------- ----------CCCBBBBBJJJ---------- ----------JJBBBBBBBCC---------- ----------JJBBBBBBBCC---------- ----------LLLBBBBBBJJ---------- ----------LJDBBBBCCJJ---------- ----------NJJJBBBCCJJ---------- -----------JJJCCCCCJ----------- ------------JLCCCJJ------------ ------------------------------- ------------------------------- ------------JJCCCLJ------------ -----------JCCCCCJJJ----------- ----------JJCCBBBJJJN---------- ----------JJCCBBBBDJL---------- ----------JJBBBBBBLLL---------- ----------CCBBBBBBBJJ---------- ----------CCCCCBBBBJJ---------- ----------CCJBBBBBCCC---------- ------------AAAAAAA------------ -------------KAAAA------------- --------------GGI-------------- ------------------------------- ------------------------------- ------------------------------- ------------------------------- ------------------------------- ------------------------------- ------------------------------- 
------------------------------- ------------------------------- -------------IIICI------------- ------------IIIIIII------------ ------------IDINIII------------ ------------LIIINNI------------ -------------NINNC------------- --------------III-------------- ------------------------------- ------------------------------- ------------------------------- ------------------------------- ------------------------------- ------------------------------- --------------III-------------- -------------CNNIN------------- ------------INNIIIL------------ ------------IIINIDI------------ ------------CCCIIII------------ -------------ICIII------------- ------------------------------- ------------------------------- ------------------------------- ------------------------------- ------------------------------- ------------------------------- ------------------------------- ------------------------------- ------------------------------- ------------------------------- 
