model
size = 3 31 16, scale = 0.05, origin = -y
material 
  colors = A:#630 B:#555 C:#C00 D:#200 E:#AAA
voxels
--- --- --- --- --- --- --- --- --- --- --- --- --- --- --- --- --- --- --- --- --- --- --- --- --- --- --- BBB BBB --- --- 
--- --- --- --- --- --- --- --- --- --- --- --- --- --- --- --- --- --- --- --- --- --- --- --- --- --- BBB BBB BBB BBB --- 
--- --- --- --- --- --- --- --- --- --- --- --- --- --- --- --- --- --- --- AAA AAA AAA AAA AAA AAA AAA BBB BBB BBB BBB -A- 
AAA CCC DCD CDC DCD CDC DCD CDC DCD CDC DCD CDC CCC AAA AAA AAA AAA AAA AAA AAA AAA AAA AAA AAA AAA AAA BBB BBB BBB BBB -A- 
AAA CAC CAC DAD CAC DAD CAC DAD CAC DAD CAC DAD CAC AAA AAA AAA AAA AAA AAA AAA AAA AAA AAA AAA AAA AAA BBB BBB BBB BBB -A- 
AAA CCC DCD CDC DCD CDC DCD CDC DCD CDC DCD CDC CCC AAA AAA AAA AAA AAA AAA AAA AAA AAA AAA AAA AAA AAA BBB BBB BBB BBB -A- 
--- --- --- --- --- --- --- --- --- --- --- --- --- --- --- --- --- --- --- --- --- --- --- --- --- --- BBB BBB BBB BBB --- 
--- --- --- --- --- --- --- --- --- --- --- --- --- --- --- --- --- --- --- --- --- --- --- --- --- --- -B- BBB BBB -B- --- 
--- --- --- --- --- --- --- --- --- --- --- --- --- --- --- --- --- --- --- --- --- --- --- --- --- --- -B- -B- -B- -B- --- 
--- --- --- --- --- --- --- --- --- --- --- --- --- --- --- --- --- --- --- --- --- --- --- --- --- --- -B- -B- -B- -B- --- 
--- --- --- --- --- --- --- --- --- --- --- --- --- --- --- --- --- --- --- --- --- --- --- --- --- --- -B- -B- -B- -B- --- 
--- --- --- --- --- --- --- --- --- --- --- --- --- --- --- --- --- --- --- --- --- --- --- --- --- --- -B- -B- -B- -B- --- 
--- --- --- --- --- --- --- --- --- --- --- --- --- --- --- --- --- --- --- --- --- --- --- --- --- -B- -B- -B- -B- -B- --- 
--- --- --- --- --- --- --- --- --- --- --- --- --- --- --- --- --- --- --- --- --- -B- -B- -B- -B- -B- -B- -B- -B- -B- --- 
--- --- --- --- --- --- --- --- --- --- --- --- --- --- --- --- --- --- --- --- --- -B- -B- -B- -B- -B- -B- -B- -B- -B- --- 
--- --- --- --- --- --- --- --- --- --- --- --- --- --- --- --- --- --- --- --- --- -E- -E- -E- -E- -E- -E- -E- -E- -E- --- 
