model
size = 24 32 6, scale = 0.05, origin = -y
material 
  colors = A:#888 B:#400 C:#444 D:#222 E:#200 F:#111
voxels
59-AB21-2A2B19-3A3B18-3A3B17-2(4A4B16-)4A4B15-2(5A5B14-)5A5B13-2(6A6B12-)6A6B11-2(7B7A10-)7B7A9-2(8B8A8-)8B8A7-5(9B9A6-)9B9A5-10B10A10-4B4A19-BA94-CE21-C2AE19-C4AE17-C6AE16-C6AE15-2(C8AE14-)C8AE13-2(C10AE12-)C10AE11-2(C12AE10-)C12AE9-2(E14AC8-)E14AC7-2(E16AC6-)E16AC5-5(E18AC4-)E18AC3-E20AC2-7E8A7C9-3E2A3C19-EC46-2D21-D2AD19-D4AD17-D6AD15-D8AD14-D8AD13-2(D10AD12-)D10AD11-2(D12AD10-)D12AD9-2(D14AD8-)D3AC10AD7-D3AC12A2(D6-D16A)D5-2(D18AD4-)D18AD3-D20AD2-D15AC4AD2-D14AC5A3(D2-D20A)D-D22A2D22A9D8A8D8-3D2A3D19-2D46-2C21-C2-C19-C4-C17-C6-C16-C6-C15-2(C8-C14-)C8-C13-2(C10-C12-)C10-C11-2(C12-C10-)C3-F8-C9-C3-F10-C8-C2-F11-C8-C14-C7-2(C16-C6-)C16-C5-C4-F9-F3-2(C4-)2F7-F2(4-C)5-2F5-F5-C4-C6-2F10-2(C4-C18-)C3-C20-C2-7C8-7C9-3C2-3C19-2C380-2(F22-)F119-F9-2(F22-)F18-F526-C22-3C3(20-5C)20-6C20-5C14-F5-5C13-2F5-3C15-2F5-C17-2F181-
