model
size = 32 7 32, scale = 0.05, origin = -y
material 
  colors = A:#630 B:#555 C:#996 D:#888 E:#111 F:#444 G:#BBB
voxels
116-2(D31-)E160-D31-D30-E161-D31-D29-2(E162-D31-D28-)2(E163-D31-D27-)3(E164-D31-D26-)E165-D31-D57-E71-B31-B29-D-B29-D57-E70-B-B29-2(B-B28-D)57-E36-2B28-2B2(2-B)22-2B4-B2-B22-2B3-DB2-B24-2B-D30-2B25-E13-B2A17-5A6-2B3A14-3A2C3A3-B-2B6A8-4A2C5A3-B-2B18A2C3ACA3-B-2B25A6-B23AB25-2(E12-2B3A8-G7-6A4-A5CA3-2F2-G5-2A5CA3-BA6C2A-6F-3A7CA3-BA6C3A2C3AC12A3-BA6C2A2CAB2-A17-2B9AB2-A28-B7-)E13-B2A17-5A6-2B3A14-3A2C3A3-B-2B6A8-4A2C5A3-B-2B18A2C3ACA3-B-2B25A6-B23AB25-E36-2B28-2B2(2-B)22-2B4-B2-B22-2B3-DB2-B24-2B-DB29-2B25-E70-B-B29-2(B-B28-D)57-E71-B31-B29-D-B29-D57-E133-D31-D57-E132-2(D31-D26-E164-)D31-D26-2(E163-D31-D27-)2(E162-D31-D28-)E161-D31-D29-E160-D31-D30-E159-2(D31-)E43-
