model
size = 23 21 23, scale = 0.05, origin = -y
material 
  colors = A:#242424 B:#B700FF C:#FFC700 D:#2C2C2C E:#444 F:#FFE700 G:#E1A500 H:#343434 I:#C18A00 J:#FFF56A K:#7800FF L:#282828 M:#202020 N:#5800FF O:#7000FF
voxels
----------------------- ----------------------- ----------------------- ----------------------- ----------------------- ----------------------- ----------------------- ----------------------- ----------------------- ----------------------- ----------------------- ----------------------- ----------------------- ----------------------- ----------------------- ----------------------- ----------------------- ----------------------- C---------------------- C---------------------- CCC-------------------- 
----------------------- ----------------------- ----------------------- ----------------------- ----------------------- ----------------------- ----------------------- ----------------------- ----------------------- ----------------------- ----------------------- ----------------------- ----------------------- ----------------------- ----------------------- ----------------------- ----------------------- C---------------------- C---------------------- GE--------------------- FAGC------------------- 
----------------------- ----------------------- ----------------------- ----------------------- ----------------------- ----------------------- ----------------------- ----------------------- ----------------------- ----------------------- ----------------------- ----------------------- ----------------------- ----------------------- ----------------------- ----------------------- C---------------------- G---------------------- AE--------------------- CAE-------------------- FCAGC------------------ 
----------------------- ----------------------- ----------------------- ----------------------- ----------------------- ----------------------- ----------------------- ----------------------- ----------------------- ----------------------- ----------------------- ----------------------- ----------------------- ----------------------- ----------------------- C---------------------- G---------------------- E---------------------- AE--------------------- FAE-------------------- -FAAGC----------------- 
----------------------- ----------------------- ----------------------- ----------------------- ----------------------- ----------------------- ----------------------- ----------------------- ----------------------- ----------------------- ----------------------- ----------------------- ----------------------- ----------------------- C---------------------- G---------------------- A---------------------- AE--------------------- IA--------------------- FAAE------------------- -FAAAGC---------------- 
----------------------- ----------------------- ----------------------- ----------------------- ----------------------- ----------------------- ----------------------- ----------------------- ----------------------- ----------------------- ----------------------- ----------------------- ----------------------- C---------------------- G---------------------- A---------------------- AE--------------------- AM--------------------- GD--------------------- FADAE------------------ -FCAAAGC--------------- 
----------------------- ----------------------- ----------------------- ----------------------- ----------------------- ----------------------- ----------------------- ----------------------- ----------------------- ----------------------- ----------------------- ----------------------- C---------------------- G---------------------- E---------------------- AE--------------------- AA--------------------- AM--------------------- CD--------------------- F-DDAE----------------- --FALAACC-------------- 
----------------------- ----------------------- ----------------------- ----------------------- ----------------------- ----------------------- ----------------------- ----------------------- ----------------------- ----------------------- ----------------------- C---------------------- G---------------------- H---------------------- HE--------------------- AA--------------------- AD--------------------- AAD-------------------- F-DD------------------- --AADAE---------------- --FALAAAGC------------- 
----------------------- ----------------------- ----------------------- ----------------------- ----------------------- ----------------------- ----------------------- ----------------------- ----------------------- ----------------------- C---------------------- G---------------------- A---------------------- HE--------------------- HA--------------------- AA--------------------- AA--------------------- AAD-------------------- F--D------------------- ---ADAAEE-------------- --FILAAAAGC------------ 
----------------------- ----------------------- ----------------------- ----------------------- ----------------------- ----------------------- ----------------------- ----------------------- ----------------------- C---------------------- G---------------------- A---------------------- HE--------------------- HA--------------------- HA--------------------- AANB------------------- AAAKB------------------ I-DNKB----------------- F--DNK----------------- ----AAAAAE------------- --JFALALAACC----------- 
----------------------- ----------------------- ----------------------- ----------------------- ----------------------- ----------------------- ----------------------- ----------------------- C---------------------- G---------------------- A---------------------- AE--------------------- HA--------------------- HAK-------------------- AAOB------------------- AADBB------------------ AA-AAB----------------- G--DABB---------------- F---DABB--------------- ----AAAABAE------------ ---FILLAAAAGC---------- 
----------------------- ----------------------- ----------------------- ----------------------- ----------------------- ----------------------- ----------------------- C---------------------- G---------------------- A---------------------- AE--------------------- AA--------------------- HAB-------------------- AAB-------------------- AABB------------------- AADAB------------------ I--AAB----------------- C--DAAB---------------- ----DAAB--------------- -----AAABBE------------ ---JFAAAAAAAGC--------- 
----------------------- ----------------------- ----------------------- ----------------------- ----------------------- ----------------------- C---------------------- G---------------------- A---------------------- AE--------------------- AA--------------------- AA--------------------- AAB-------------------- AABB------------------- AADB------------------- A--DBB----------------- C--AABB---------------- F--DAAAB--------------- -----DAAB-------------- ------AABBAEE---------- ----FIAAAAAAACC-------- 
----------------------- ----------------------- ----------------------- ----------------------- ----------------------- C---------------------- G---------------------- A---------------------- AE--------------------- AA--------------------- AA--------------------- AAB-------------------- AAB-------------------- AABB------------------- A-DAB------------------ I--DBB----------------- F--AAAB---------------- ----DAAB--------------- -----DAAB-------------- ------AABBBAAE--------- ----JFAAAAAAAAGC------- 
----------------------- ----------------------- ----------------------- ----------------------- C---------------------- C---------------------- A---------------------- AE--------------------- AA--------------------- AA--------------------- AAB-------------------- AAB-------------------- AAB-------------------- A-AB------------------- A-DBB------------------ C--DBB----------------- J--AAAB---------------- ----DAABB-------------- ------DABB------------- -------ABBBB-AE-------- -----FIDAAAAAAAGC------ 
----------------------- ----------------------- ----------------------- C---------------------- C---------------------- A---------------------- AE--------------------- AA--------------------- AA--------------------- AAB-------------------- AAB-------------------- AAB-------------------- A-AB------------------- A-AB------------------- C-DBBB----------------- F--DBBB---------------- ---AAABB--------------- -----DABBBB------------ ------DABBBBK---------- --------ABAAAAE-------- -----JFIAAAAAAADGC----- 
----------------------- ----------------------- C---------------------- C---------------------- A---------------------- AE--------------------- AA--------------------- AA--------------------- AAK-------------------- AAB-------------------- AAB-------------------- AAB-------------------- I-ABB------------------ C-ABBB----------------- J-DABBB---------------- ---DBBBBB-------------- ----AABBBBBB----------- -----ADAABBBBB--------- -------DABAAAAA-------- ---------AAAAAAE------- ------FCDDAAAAAADCC---- 
----------------------- C---------------------- C---------------------- A---------------------- AE--------------------- AA--------------------- AA--------------------- AAK-------------------- AAB-------------------- AAB-------------------- AABB------------------- C-ABBB----------------- C-ABBBB---------------- J-DABBBB--------------- ---ABBBBBB------------- ---AABBBBBBB----------- ----AAABBBBBBB--------- ------ADAAAAAAK-------- --------DDAAAAA-------- ----------AAAAAAE------ -------FCIDAADAAADCC--- 
----------------------- C---------------------- I---------------------- AE--------------------- AA--------------------- AA--------------------- AA--------------------- AAB-------------------- AABB------------------- I-ABBB----------------- C-ABBBB---------------- C-ABBBBB--------------- --DBBBBBB-------------- ---ABBBBBB------------- ---AABBBBBBB----------- ----ABBBBBBBBB--------- -----AAAAAAAAAB-------- -------ADDAAAAB-------- ----------AAAAAA------- -----------AAAAAAE----- --------FCIDDDDAAAECC-- 
C---------------------- I---------------------- AE--------------------- AA--------------------- AA--------------------- AA--------------------- AAA-------------------- IAAK------------------- C-ABBBB---------------- C-ABBBBB--------------- --ABBBBBB-------------- ---ABBBBBB------------- ---ABBBBBBB------------ ---ABBBBBABBB---------- ----AAAAAAAABB--------- -----AAAAAAAAAB-------- ------AAAAAAAAB-------- ---------AAAAABK------- -----------AAAAA------- -------------AAAAAA---- ----------CCIDDAAAAACC- 
G---------------------- A---------------------- AA--------------------- AA--------------------- IA--------------------- CAA-------------------- C--M------------------- C--AK------------------ ---ABBB---------------- ---ABBBBB-------------- ---AABBBBB------------- ---AABBBBBB------------ ----AABBBAAB----------- ----AAAAAAAAB---------- -----AAAAAAAAB--------- ------AAAAAAAAB-------- ---------AAAAAAK------- -----------AAAAB------- --------------AAA------ ---------------AAAA---- ------------CCCGIAAAAGC 
C---------------------- C---------------------- CA--------------------- CA--------------------- CA--------------------- -A--------------------- --A-------------------- ---AN------------------ ----AAA---------------- ----AAAA--------------- -----AABAA------------- -----AAAAAA------------ ------AAAAAA----------- -------AAAAAA---------- --------AAAAAA--------- ---------AAAAAA-------- -----------AAAAA------- ---------------AA------ ---------------AA------ ---------------AAAA---- ----------------CGIAAAC 
-CCC------------------- -CACC------------------ -CAACC----------------- -CAAACC---------------- -CAAAACC--------------- -CAAAAACC-------------- -CIAAAAACC------------- --CAAHAHHCC------------ --CAAAHHHHCC----------- --CAAAHAAAACC---------- --CIAAAAAAAACC--------- ---CAAAAAMAAACC-------- ---FCAAAAAAAAACC------- ----FIAAAAAAAAACC------ ----JCIAAAAAHHHACC----- -----JCIAAAHHHHHACC---- ------JFCAAAAAHHHACC--- --------JCCIAAAAAAACC-- ----------JCCCCAAAAACC- --------------CCCCCCCC- ------------------CCCCC 
