model
size = 15 11 10, scale = 0.05, origin = -y
material 
  colors = A:#111
voxels
------AAA------ ----AAAAAAA---- ---AAAAAAAAA--- --AAAAAAAAAAA-- -AAAAAAAAAAAAA- AAAAAAAAAAAAAAA AAAAAAAAAAAAAAA AAAAAAAAAAAAAAA -AAAAAAAAAAAAA- --AAAAAAAAAAA-- ---AAAAAAAAA--- 
--------------- -------A------- --------------- --------------- --------------- A-------------A A-------------A A-------------A -A-----------A- --------------- --------------- 
--------------- -------A------- --------------- --------------- --------------- A-------------A A-------------A A-------------A -A-----------A- --------------- --------------- 
--------------- -------A------- --------------- --------------- --------------- A-------------A A-------------A A-------------A -A-----------A- --------------- --------------- 
--------------- -------A------- --------------- --------------- --------------- A-------------A A-------------A A-------------A -A-----------A- --------------- --------------- 
--------------- -------A------- --------------- --------------- --------------- A-------------A A-------------A A-------------A -A-----------A- --------------- --------------- 
--------------- -------A------- --------------- --------------- --------------- A-------------A A-------------A A-------------A -A-----------A- --------------- --------------- 
--------------- -------A------- --------------- --------------- --------------- A-------------A A-------------A A-------------A -A-----------A- --------------- --------------- 
--------------- -------A------- --------------- --------------- --------------- A-------------A A-------------A A-------------A -A-----------A- --------------- --------------- 
------AAA------ ----AAAAAAA---- ---AAAAAAAAA--- --AAAAAAAAAAA-- -AAAAAAAAAAAAA- AAAAAAAAAAAAAAA AAAAAAAAAAAAAAA AAAAAAAAAAAAAAA -AAAAAAAAAAAAA- --AAAAAAAAAAA-- ---AAAAAAAAA--- 
