model
size = 27 4 25, scale = 0.05, origin = -y
material 
  colors = A:#EEE B:#111 C:#777
voxels
---------BAAABAC----------- ---------BABABAC----------- ---------BABABAA----------- ---------BABABAB----------- 
-------AA-------AB--------- -------AA-------AB--------- -------AA-------AA--------- -------AA-------AB--------- 
-----AA-----------AACCC---- -----AA-----------AACCC---- -----AA-----------AACCC---- -----AA-----------BACCC---- 
----A---------------ACCAAA- ----A---------------ACCAA-- ----A---------------ACCAAA- ----A---------------ACCAAAA 
---A-----------------A----- ---A-----------------A----- ---A-----------------A----- ---A-----------------A----- 
--A-------------------A---- --A-------------------A---- --A-------------------A---- --A-------------------A---- 
--A-------------------A---- --A-------------------A---- --A-------------------A---- --B-------------------A---- 
-B---------------------A--- -B---------------------A--- -A---------------------A--- -B---------------------A--- 
-A---------------------A--- -A---------------------A--- -A---------------------A--- -A---------------------A--- 
C-----------------------B-- C-----------------------B-- A-----------------------B-- B-----------------------B-- 
A-----------------------A-- A-----------------------A-- A-----------------------A-- A-----------------------A-- 
B-----------------------A-- B-----------------------B-- B-----------------------B-- B-----------------------B-- 
A-----------------------A-- A-----------------------A-- A-----------------------A-- A-----------------------A-- 
A-----------------------B-- B-----------------------B-- B-----------------------B-- B-----------------------B-- 
A-----------------------A-- A-----------------------A-- A-----------------------A-- A-----------------------A-- 
B-----------------------C-- B-----------------------C-- B-----------------------A-- B-----------------------B-- 
-A---------------------A--- -A---------------------A--- -A---------------------A--- -A---------------------A--- 
-A---------------------B--- -A---------------------B--- -A---------------------A--- -A---------------------B--- 
--A-------------------A---- --A-------------------A---- --A-------------------A---- --A-------------------B---- 
--AA------------------A---- --AA------------------A---- --AA------------------A---- --AA------------------A---- 
---A-----------------A----- ---A-----------------A----- ---A-----------------A----- ---A-----------------A----- 
----A---------------A------ ----A---------------A------ ----A---------------A------ ----A---------------A------ 
-----AA-----------AA------- -----AA-----------AA------- -----AA-----------AA------- -----AB-----------AA------- 
-------BA-------AA--------- -------BA-------AA--------- -------AA-------AA--------- -------BA-------AA--------- 
---------CABAAAB----------- ---------CABABAB----------- ---------AABABAB----------- ---------BABABAB----------- 
