model
size = 12 32 12, scale = 0.05, origin = -y
material 
  colors = A:#F93 B:#600 C:#100 D:#FF0 E:#EEE
voxels
385A3(10B2A)3(10BA-)25(10B2A)10C4(2AB8-B)3(A-B8-B)4(2AB8-B)2(EAB8-B)C2(AB8-BE)A15(B8-B2A)10B2AC8AC4(2AB8-B)3(A-B8-B)4(2AB8-B)3(EAB8-B)CAB8-BEA15(B8-B2A)10B2AC8AC4(2AB8-B)3(A-B8-B)4(2AB8-B)5(CAB8-B)11(2AB8-B)2A2(B10-A)B8-B2A10B2AC8AC4(2AB8-B)3(A-B8-B)4(2AB8-B)3(EAB8-B)CAB8-BEA12(B8-B2A)2(B10-A)B8-B2A10B2A10C4(2AB8-B)3(A-B8-B)4(2AB8-B)2(EAB8-B)C2(AB8-BE)A4(B8-B2A)7(B8-BAD)B8-B2A2(B10-A)B8-B2A10B2A10C4(2AB8-B)3(A-B8-B)13(2AB8-B)5(ADB8-B)ACB8-BADB8-B2A2(B10-A)B8-B2A10B2AC8AC4(2AB8-B)3(A-B8-B)13(2AB8-B)ADB8-BAC3(B8-BAD)B8-BACB8-BAD4(B8-B2A)10B2AC8AC4(2AB8-B)3(A-B8-B)13(2AB8-B)3(ADB8-BACB8-B)AD4(B8-B2A)10B2AC8AC4(2A10B)3(A-10B)13(2A10B)7(AD10B)4(2A10B)2A10C385A
