model
size = 22 15 30, scale = 0.05, origin = -y
material 
  colors = A:#FF0 B:#100 C:#EEE D:#C30 E:#FFF
voxels
---------------------- ---------BBBB--------- --------ABEEBA-------- --------ABAABA-------- --------ABAABA-------- --------ABAABA-------- --------ABAABA-------- --------ABAABA-------- ---------------------- ---------------------- ---------------------- ---------------------- ---------------------- ---------------------- ---------------------- 
-BBBB------------BBBB- CCCCCC--BBAABB--CCCCCC --------AAAAAA-------- --------AAAAAA-------- --------AAAAAA-------- --------AAAAAA-------- --------ABAABA-------- --------ABAABA-------- --------ABAABA-------- ---------------------- ---------------------- ---------------------- ---------------------- ---------------------- ---------------------- 
BBBBBB----------BBBBBB CCCCCC--BAAAAB--CCCCCC -CCCCC-BBAAAA-B-CCCCC- -------B-AAAAAB------- -------BAAAAAAB------- -------BAAAAAAB------- -------BAAAAAAB------- --------AAAAAA-------- --------AAAAAA-------- ---------------------- ---------------------- ---------------------- ---------------------- ---------------------- ---------------------- 
BBBBBB----------BBBBBB CCCCCC-AAAAAAAA-CCCCCC -BBCCCADDDDDDDDACCCBB- ------ADDDDDDDDA------ ------ADDDDDDDDA------ ------ADDDDDDDDA------ ------ABBBBBBBBA------ --------A----A-------- --------A----A-------- ---------------------- ---------------------- ---------------------- ---------------------- ---------------------- ---------------------- 
BBBBBB----------BBBBBB CCCCCCA--------ACCCCCC -CCCCCAD------DACCCCC- ------AD------DA------ -----BAD------DAB----- -----BADDDDDDDDAB----- ------ABBBBBBBBA------ --------A----A-------- --------A----A-------- ---------------------- ---------------------- ---------------------- ---------------------- ---------------------- ---------------------- 
BBBBBB----------BBBBBB CCCCCCA--------ACCCCCC -BBCCCAD------DACCCBB- ------AD------DA------ -----BAD------DAB----- -----BADDDDDDDDAB----- ------ABAAAAAABA------ --------BDDDDB-------- --------BDDDDB-------- --------BDDDDB-------- --------BBDDBB-------- ---------BBBB--------- ---------------------- ---------------------- ---------------------- 
BBBBBB----------BBBBBB CCCCCCA--------ACCCCCC -CCCCCAD------DACCCCC- ------AD------DA------ -----BAD------DAB----- -----BADD----DDAB----- ------ABA----ABA------ ---------------------- ---------------------- ---------------------- ---------------------- ---------------------- ---------------------- ---------------------- ---------------------- 
-BBBB------------BBBB- CCCCCCA--------ACCCCCC ------AD------DA------ ------AD------DA------ -----BAD------DAB----- -----BADD----DDAB----- ------ABA----ABA------ ---------------------- ---------------------- ---------------------- ---------------------- ---------------------- ---------------------- ---------------------- ---------------------- 
---------------------- ------A--------A------ ------AD------DA------ ------AD------DA------ -----BAD------DAB----- -----BADD----DDAB----- ------ABA----ABA------ ---------------------- ---------------------- ---------------------- ---------------------- ---------------------- ---------------------- ---------------------- ---------------------- 
---------------------- ------A--------A------ ------AD------DA------ ------AD------DA------ -----BAD------DAB----- -----BADD----DDAB----- ------ABA----ABA------ ---------------------- ---------------------- ---------------------- ---------------------- ---------------------- ---------------------- ---------------------- ---------------------- 
---------------------- ------A--------A------ ------AD------DA------ ------AD------DA------ -----BAD------DAB----- -----BADDDDDDDDAB----- ------ABAAAAAABA------ ---------------------- ---------------------- ---------------------- ---------------------- ---------------------- ---------------------- ---------------------- ---------------------- 
---------------------- ------A--------A------ ------AD------DA------ ------AD------DA------ -----BAD------DAB----- -----BADDDDDDDDAB----- ------ABBBBBBBBA------ ---------------------- ---------------------- ---------------------- ---------------------- ---------------------- ---------------------- ---------------------- ---------------------- 
-BBBB------------BBBB- CCCCCCA--------ACCCCCC ------AD------DA------ ------AD------DA------ -----BAD------DAB----- -----BADDDDDDDDAB----- ------ABAAAAAABA------ ---------------------- ---------------------- ---------------------- ---------------------- ---------------------- ---------------------- ---------------------- ---------------------- 
BBBBBB----------BBBBBB CCCCCCA--------ACCCCCC -CCCCCAD------DACCCCC- ------AD------DA------ -----BAD------DAB----- -----BADDDDDDDDAB----- ------ABAAAAAABA------ ---------------------- ---------------------- ---------------------- ---------------------- ---------------------- ---------------------- ---------------------- ---------------------- 
BBBBBB----------BBBBBB CCCCCCA--------ACCCCCC -BBCCCAD------DACCCBB- ------AD------DA------ -----BAD------DAB----- -----BADDDDDDDDAB----- ------ABBBAABBBA------ ---------------------- ---------------------- ---------------------- ---------------------- ---------------------- ---------------------- ---------------------- ---------------------- 
BBBBBB----------BBBBBB CCCCCCA--------ACCCCCC -CCCCCAD------DACCCCC- ------AD------DA------ -----BAD------DAB----- -----BADDDDDDDDAB----- ------ABBBBBBBBA------ ---------B--B--------- ---------------------- ---------------------- ---------------------- ---------------------- ---------------------- ---------------------- ---------------------- 
BBBBBB----------BBBBBB CCCCCCA--------ACCCCCC -BBCCCADDDDDDDDACCCBB- ------ADDDDDDDDA------ ------ADDDDDDDDA------ ------ADDDDDDDDA------ -------BBBBBBBBA------ ---------BAAB--------- ----------AA---------- ---------------------- ---------------------- ---------------------- ---------------------- ---------------------- ---------------------- 
BBBBBB----------BBBBBB CCCCCCAAAAAAAAAACCCCCC -CCCCCAAAAAAAAAACCCCC- -------AAAAAAAAA------ -------AAAAAAAAA------ -------AAAAAAAAA------ --------BBBBBBB------- ---------BAAB--------- ----------AA---------- ----------AA---------- ---------------------- ---------------------- ---------------------- ---------------------- ---------------------- 
-BBBB------------BBBB- CCCCCC-BBBBBBBB-CCCCCC -------BBBEEBBB------- -------BBBBBBBB------- -------BBBBBBBB------- ---------------------- ----------BB---------- ---------BAAB--------- ----------AA---------- ----------AA---------- ---------BAAB--------- ---------------------- ---------------------- ---------------------- ---------------------- 
---------------------- ---------------------- ---------------------- ---------------------- ---------------------- ---------------------- ---------------------- ---------------------- ----------AA---------- ----------AA---------- ---------B--B--------- ---------B--B--------- ---------BAAB--------- ----------AA---------- ---------------------- 
---------------------- ---------------------- ---------------------- ---------------------- ---------------------- ---------------------- ---------------------- ---------------------- ---------------------- ---------------------- ---------------------- ----------AA---------- ---------BAAB--------- ----------AA---------- ----------AA---------- 
---------------------- ---------------------- ---------------------- ---------------------- ---------------------- ---------------------- ---------------------- ---------------------- ---------------------- ---------------------- ---------------------- ---------------------- ----------AA---------- ----------AA---------- ----------AA---------- 
---------------------- ---------------------- ---------------------- ---------------------- ---------------------- ---------------------- ---------------------- ---------------------- ---------------------- ---------------------- ---------------------- ---------------------- ---------------------- ----------AA---------- ---------BAAB--------- 
---------------------- ---------------------- ---------------------- ---------------------- --------B-B-BB-------- ---------------------- ---------------------- ---------------------- ---------------------- ---------------------- ---------------------- ---------------------- ------------B--------- ---------B--B--------- ---------B--B--------- 
---------------------- ---------------------- ---------------------- ---------------------- --------AAAAAA-------- --------ABBBBA-------- ---------------------- ---------------------- ---------------------- ---------------------- ---------------------- ---------------------- ------------B--------- ---------BAA---------- ----------AA---------- 
---------------------- ---------------------- ---------------------- ---------------------- --------AAAAAA-------- --------ABBBBA-------- --------AB------------ ---------------------- ---------------------- ---------------------- ---------------------- ---------------------- ---------------------- ----------AA---------- ----------AA---------- 
---------------------- ---------------------- ---------------------- ---------------------- --------AAAAAA-------- --------ABBBBA-------- --------AB--BA-------- --------AB--BA-------- ---------------------- ---------------------- ---------------------- ---------------------- ----------AA---------- ----------AA---------- ----------AA---------- 
---------------------- ---------------------- ---------------------- ---------------------- --------AAAAAA-------- --------ABBBBA-------- --------AB--BA-------- --------AB--BA-------- --------AAAAAA-------- ---------------------- ---------B--B--------- ---------BAAB--------- ----------AA---------- ----------AA---------- ----------AA---------- 
---------------------- ---------------------- ---------------------- ---------------------- ---------AAAA--------- --------ABBBBA-------- --------ABBBBA-------- --------ABBBBA-------- --------AAAAAA-------- ---------BAAB--------- ---------B--B--------- ----------AA---------- ----------AA---------- ----------AA---------- ---------------------- 
---------------------- ---------------------- ---------------------- ---------------------- ---------------------- ---------AAAA--------- ---------AAAA--------- ---------AAAA--------- ---------------------- ---------------------- ---------------------- ----------AA---------- ----------AA---------- ---------------------- ---------------------- 
