model
size = 9 14 19, scale = 0.05, origin = -y
material 
  colors = A:#111 B:#FF3 C:#BBB
voxels
--------- --------- --------- --------- --------- --------- --------- --------- ---BBB--- --------- ---BBB--- --------- ---BBB--- --------- 
---CCC--- ---AAA--- ---AAA--- ---AAA--- ---AAA--- ---AAA--- ---AAA--- ---AAA--- --BBBBB-- ---AAA--- --BBBBB-- ---AAA--- --BBBBB-- ---AAA--- 
--CCCCC-- --AAAAA-- --AAAAA-- --AAAAA-- --AAAAA-- --AAAAA-- --AAAAA-- --AAAAA-- -BBBBBBB- --AAAAA-- -BBBBBBB- --AAAAA-- -BBBBBBB- --AAAAA-- 
--CCCCC-- --AAAAA-- --AAAAA-- --AAAAA-- --AAAAA-- --AAAAA-- --AAAAA-- --AAAAA-- -BBBBBBB- --AAAAA-- -BBBBBBB- --AAAAA-- -BBBBBBB- --AAAAA-- 
-CCCCCCC- -AAAAAAA- -AAAAAAA- -AAAAAAA- -AAAAAAA- -AAAAAAA- -AAAAAAA- -AAAAAAA- BBBBBBBBB -AAAAAAA- BBBBBBBBB -AAAAAAA- BBBBBBBBB -AAAAAAA- 
-CCCCCCC- -AAAAAAA- -AAAAAAA- -AAAAAAA- -AAAAAAA- -AAAAAAA- -AAAAAAA- -AAAAAAA- BBBBBBBBB -AAAAAAA- BBBBBBBBB -AAAAAAA- BBBBBBBBB -AAAAAAA- 
CCCCCCCCC AAAAAAAAA AAAAAAAAA -AAAAAAA- -AAAAAAA- -AAAAAAA- -AAAAAAA- -AAAAAA-- -BBBBBBB- --AAAAA-- -BBBBBBB- --AAAAA-- --BBBBBB- --AAAAA-- 
CCCCCCCCC AAAAAAAAA AAAAAAAAA -AAAAAAA- -AAAAAAA- -AAAAAAA- --AAAAA-- --AAAAA-- --BBBBB-- ---AAA--- --BBBBB-- ---AAA--- ---BBBB-- ---AAA--- 
CCCCCCCCC AAAAAAAAA AAAAAAAAA -AAAAAAA- -AAAAAAA- --AAAAA-- --AAAAA-- ---AAA--- ---BBB--- --------- ---BBB--- --------- ---BBB--- --------- 
CCCCCCCCC AAAAAAAAA AAAAAAAAA -AAAAAAA- -AAAAAAA- --AAAAA-- ---AAA--- --------- --------- --------- --------- --------- --------- --------- 
CCCCCCCCC AAAAAAAAA AAAAAAAAA -AAAAAAA- -AAAAAAA- --AAAAA-- --------- --------- --------- --------- --------- --------- --------- --------- 
CCCCCCCCC BBBBBBBBB BBBBBBBBB -BBBBBBB- -BBBBBBB- --BBBBB-- --BB-BB-- ---BBB--- ----B---- --------- --------- --------- --------- --------- 
CCCCCCCCC AAAAAAAAA AAAAAAAAA -AAAAAAA- -AAAAAAA- --AAAAA-- --------- --------- --------- --------- --------- --------- --------- --------- 
CCCCCCCCC BBBBBBBBB BBBBBBBBB -BBBBBBB- -BBBBBBB- --BBBBB-- --BB-BB-- ---BBB--- ----B---- --------- --------- --------- --------- --------- 
CCCCCCCCC AAAAAAAAA AAAAAAAAA -AAAAAAA- -AAAAAAA- --AAAAA-- --------- --------- --------- --------- --------- --------- --------- --------- 
CCCCCCCCC BBBBBBBBB BBBBBBBBB -BBBBBBB- -BBBBBBB- --BBBBB-- --BB-BB-- ---BBB--- ----B---- --------- --------- --------- --------- --------- 
-CCCCCCC- -AAAAAAA- -AAAAAAA- -AAAAAAA- -AAAAAAA- --AAAAA-- --------- --------- --------- --------- --------- --------- --------- --------- 
-CCCCCCC- -AAAAAAA- -AAAAAAA- --AAAAA-- --AAAAA-- ---AAA--- --------- --------- --------- --------- --------- --------- --------- --------- 
--CCCCC-- --AAAAA-- --AAAAA-- ---AAA--- ---AAA--- --------- --------- --------- --------- --------- --------- --------- --------- --------- 
