model
size = 19 14 9, scale = 0.05, origin = -y
material 
  colors = A:#F9F B:#EEE C:#FCF D:#111
voxels
-----AAAAAAAAAA---- -----BBBBBBAAAA---- ---------BBAAAA---- ---------BBAAAA---- ------------------- ------------------- ------------------- ------------------- ------------------- -------------BB---- -------------BC---- -------------BC---- -------------BC---- -------------BC---- 
-AAAAAAAAAAAAAAAA-- -BBBB----------AA-- ---------------AA-- ---------------A--- ----------BAAAA---- ------------------- ------------------- -------------BB---- -------------BC---- -------------BC---- -------------BC---- -------------BC---- -------------BC---- -------------BB---- 
AAAAAAAAAAAAAAAAAA- B---------------AA- ----------------AA- ---------------AA-- ---------------AA-- ----------BAAAAA--- -------------BB---- -------------BC---- -------------BB---- ------------------- ------------------- ------------------- ------------------- ------------------- 
AAAAAAAAAAAAAAAAAAB B----------------AB ----------------AA- ---------------AD-- ---------------AD-- ----------BAAAAA--- -------------BC---- -------------BB---- ------------------- ------------------- ------------------- ------------------- ------------------- ------------------- 
AAAAAAAAAAAAAAAAAAA B----------------AB ----------------AA- ---------------AA-- ---------------AA-- ----------BAAAAA--- ------------------- ------------------- ------------------- ------------------- ------------------- ------------------- ------------------- ------------------- 
AAAAAAAAAAAAAAAAAAB B----------------AB ----------------AA- ---------------AD-- ---------------AD-- ----------BAAAAA--- -------------BC---- -------------BB---- ------------------- ------------------- ------------------- ------------------- ------------------- ------------------- 
AAAAAAAAAAAAAAAAAA- B---------------AA- ----------------AA- ---------------AA-- ---------------AA-- ----------BAAAAA--- -------------BB---- -------------BC---- -------------BB---- ------------------- ------------------- ------------------- ------------------- ------------------- 
-AAAAAAAAAAAAAAAA-- -BBBB----------AA-- ---------------AA-- ---------------A--- ----------BAAAA---- ------------------- ------------------- -------------BB---- -------------BC---- -------------BC---- -------------BC---- -------------BC---- -------------BC---- -------------BB---- 
-----AAAAAAAAAA---- -----BBBBBBAAAA---- ----------BAAAA---- ----------BAAAA---- ------------------- ------------------- ------------------- ------------------- ------------------- -------------BB---- -------------BC---- -------------BC---- -------------BC---- -------------BC---- 
