model
size = 28 18 31, scale = 0.05, origin = -y
material 
  colors = A:#FFCE0C B:#272727 C:#EEE
voxels
---------------------------- ---------------------------- ---------------------------- ---------------------------- -----------AAAAAA----------- ---------------------------- ---------------------------- ---------------------------- ---------------------------- ---------------------------- ---------------------------- ---------------------------- ---------------------------- ---------------------------- ---------------------------- ---------------------------- ---------------------------- ---------------------------- 
---------------------------- ---------------------------- ---------------------------- ---------------------------- ---------AAAAAAAAAA--------- ------------AAAA------------ ---------------------------- ---------------------------- ---------------------------- ---------------------------- ---------------------------- ---------------------------- ---------------------------- ---------------------------- ---------------------------- ---------------------------- ---------------------------- ---------------------------- 
---------------------------- ---------------------------- ---------------------------- ---------------------------- -------AAAAAAAAAAAAAA------- -----------AAAAAA----------- ------------AAAA------------ -------------AA------------- ---------------------------- ---------------------------- ---------------------------- ---------------------------- ---------------------------- ---------------------------- ---------------------------- ---------------------------- ---------------------------- ---------------------------- 
---------------------------- ---------------------------- ---------------------------- ---------------------------- ------AAAAAAAAAAAAAAAA------ ---------AAAAAAAAAA--------- ----------AAAAAAAA---------- -----------AAAAAA----------- ------------AAAAA----------- -------------AA------------- ---------------------------- ---------------------------- ---------------------------- ---------------------------- ---------------------------- ---------------------------- ---------------------------- ---------------------------- 
---------------------------- ---------------------------- ---------------------------- ---------------------------- -----AAAAABBBBBBBBAAAAA----- --------AAAAAAAAAAAA-------- ---------AAAAAAAAAA--------- ---------AAAAAAAAAA--------- ----------AAAAAAAA---------- ----------AAAAAAAA---------- -----------AAAAAA----------- ---------------------------- ---------------------------- ---------------------------- ---------------------------- ---------------------------- ---------------------------- ---------------------------- 
---------------------------- ---------------------------- ---------------------------- ---------------------------- ----AAAABB--------BBAAAA---- -------AAA--------AAA------- --------AAAAAAAAAAAA-------- --------AAAAAAAAAAAA-------- ---------AAAAAAAAAA--------- ----------AAAAAAAA---------- ----------AAAAAAAA---------- -----------AAAAAA----------- ------------AAAA------------ ---------------------------- ---------------------------- ---------------------------- ---------------------------- ---------------------------- 
---------------------------- ---------------------------- ---------------------------- ---------------------------- ---AAABB------------BBAAA--- ------AA------------AA------ ------AAAA--------AAAA------ -------AAA--------AAA------- -------AAA--------AAA------- --------AAAAAAAAAAAA-------- ---------AAAAAAAAAA--------- ----------AAAAAAAA---------- ------------AAAA------------ ------------AAAA------------ ---------------------------- ---------------------------- ---------------------------- ---------------------------- 
---------------------------- ---------------------------- ---------------------------- ---------------------------- ---AAB----------------BAA--- ----AA----------------A----- ----AAAA------------AAA----- -----AAA------------AAA----- ------AA------------AA------ ------AAAA--------AAAA------ -------AAA--------AAA------- --------AAAAAAAAAAAA-------- ---------AAAAAAAAAA--------- -----------AAAAAA----------- ------------AAAA------------ ---------------------------- ---------------------------- ---------------------------- 
---------------------------- ---------------------------- ---------------------------- ---------------------------- --AAB------------------BAA-- ---AABB--------------BBA---- ---AAAA--------------AAA---- ----AAA--------------AAA---- -----AA--------------AA----- -----AAA------------AAA----- ------AA------------AA------ -------AAAA------AAAA------- --------AAAAAAAAAAAA-------- ---------AAAAAAAAAA--------- -----------AAAAAA----------- ------------AAAA------------ ---------------------------- ---------------------------- 
---------------------------- ---------------------------- ---------------------------- ---------------------------- --AB--------------------BA-- ---A--------------------A--- ---AAAB--------------BAAA--- ----AAB--------------BAA---- ----AAB--------------BAA---- ----AAAB------------BAAA---- -----AAB------------BAA----- ------AAA----------AAA------ ------AAAAA------AAAAA------ --------AAAAAAAAAAAA-------- ---------AAAAAAAAAA--------- ------------AAAA------------ ------------AAAA------------ ---------------------------- 
---------------------------- ---------------------------- ---------------------------- ---------------------------- -AAB--------------------BAA- ---A--------------------A--- ---AA------------------AA--- ---AA------------------AA--- ---AA------------------AA--- ----AA----------------AA---- ----AA----------------AA---- -----AABB----------BBAA----- ------AAA----------AAA------ -------AAAAAAAAAAAAAA------- --------AAAAAAAAAAAA-------- ----------AAAAAAAA---------- ------------AAAA------------ ---------------------------- 
---------------------------- ---------------------------- ---------------------------- ---------------------------- -AB----------------------BA- --A----------------------A-- --AA--------------------AA-- --AA--------------------AA-- ---A--------------------A--- ---AA------------------AA--- ----A------------------A---- ----AAA--------------AAA---- -----AAAB----------BAAA----- ------AAAAA------AAAAA------ -------AAAAAAAAAAAAAA------- ---------AAAAAAAAAA--------- -----------AAAAAA----------- ------------AAAA------------ 
---------------------------- ---------------------------- ---------------------------- ---------------------------- -AB----------------------BA- --A----------------------A-- --AA--------------------AA-- --AA--------------------AA-- --AA--------------------AA-- ---AA------------------AA--- ---AA------------------AA--- ----AA----------------AA---- ----AAA--B--------B--AAA---- -----AAAAA--------AAAAA----- ------AAAAA------AAAAA------ --------AAAAAAAAAAAA-------- ----------AAAAAAAA---------- ------------AAAA------------ 
---------------------------- ---------------------------- ---------------------------- ---------------------------- AB------------------------BA -A------------------------A- --A----------------------A-- --A----------------------A-- --A----------------------A-- --AA--------------------AA-- ---A--------------------A--- ---AAA----------------AAA--- ----AAA--------------AAA---- -----AAAAB--------BAAAA----- ------AAAAB------BAAAA------ -------AAAAA----AAAAA------- ---------AAAAAAAAAA--------- ------------AAAA------------ 
---------------------------- ---------------------------- ---------------------------- ---------------------------- AB------------------------BA -A------------------------A- -AA----------------------AA- -AA----------------------AA- --A----------------------A-- --AA--------------------AA-- --AA--------------------AA-- ---AA------------------AA--- ----AA----------------AA---- ----ACAA------------AAAA---- -----AAAA-B------B-AAAA----- -------AAAAB----BAAAA------- --------AAAAAAAAAAAA-------- -----------AAAAAA----------- 
---------------------------- ---------------------------- ---------------------------- ---------------------------- AB------------------------BA -A------------------------A- -AA----------------------AA- -AA----------------------AA- --A----------------------A-- --AA--------------------AA-- --AA--------------------AA-- ---AA------------------AA--- ---AAA----------------AAA--- ----ACAA------------AAAA---- -----AAAA----------AAAA----- ------AAAA--B--B--AAAA------ --------AAAAAAAAAAAA-------- ----------AAAAAAAA---------- 
---------------------------- ---------------------------- ---------------------------- ---------------------------- AB------------------------BA -A------------------------A- -AA----------------------AA- -AA----------------------AA- -AA----------------------AA- -AAA--------------------AAA- -AAA--------------------AAA- --AAA------------------AAA-- --AACA----------------AAAA-- ---AACAA------------AAAAA--- ----AAAAA----------AAAAA---- -----AAAAA---BB---AAAAA----- ------AAAAAAAAAAAAAAAA------ --------AAAAAAAAAAAA-------- 
---------------------------- ---------------------------- ---------------------------- --B----------------------B-- AB------------------------BA -A------------------------A- -AA----------------------AA- -AA----------------------AA- -AA----------------------AA- -AAA--------------------AAA- -AAA--------------------AAA- --AAA------------------AAA-- --AACA----------------AAAA-- ---AACAA------------AAAAA--- ----AAAAA----------AAAAA---- -----AAAAA---BB---AAAAA----- ------AAAAAAAAAAAAAAAA------ --------AAAAAAAAAAAA-------- 
---------------------------- ---------------------------- --B----------------------B-- --B----------------------B-- AB------------------------BA -A------------------------A- -AA----------------------AA- -AA----------------------AA- --A----------------------A-- --AA--------------------AA-- --AA--------------------AA-- ---AA------------------AA--- ---AAA----------------AAA--- ----ACAA------------AAAA---- -----AAAA----------AAAA----- ------AAAA--B--B--AAAA------ --------AAAAAAAAAAAA-------- ----------AAAAAAAA---------- 
---------------------------- ---------------------------- --B----------------------B-- -BB----------------------BB- AB------------------------BA -A------------------------A- -AA----------------------AA- -AA----------------------AA- --A----------------------A-- --AA--------------------AA-- --AA--------------------AA-- ---AA------------------AA--- ----AA----------------AA---- ----ACAA------------AAAA---- -----AAAA-B------B-AAAA----- -------AAAAB----BAAAA------- --------AAAAAAAAAAAA-------- -----------AAAAAA----------- 
---------------------------- --B----------------------B-- --B----------------------B-- -BB----------------------BB- AB------------------------BA -A------------------------A- --A----------------------A-- --A----------------------A-- --A----------------------A-- --AA--------------------AA-- ---A--------------------A--- ---AAA----------------AAA--- ----AAA--------------AAA---- -----AAAAB--------BAAAA----- ------AAAAB------BAAAA------ -------AAAAA----AAAAA------- ---------AAAAAAAAAA--------- ------------AAAA------------ 
---------------------------- --B----------------------B-- --B----------------------B-- -BB----------------------BB- -AB----------------------BA- --A----------------------A-- --AA--------------------AA-- --AA--------------------AA-- --AA--------------------AA-- ---AA------------------AA--- ---AA------------------AA--- ----AA----------------AA---- ----AAA--B--------B--AAA---- -----AAAAA--------AAAAA----- ------AAAAA------AAAAA------ --------AAAAAAAAAAAA-------- ----------AAAAAAAA---------- ------------AAAA------------ 
--B----------------------B-- --B----------------------B-- --B----------------------B-- -AB----------------------BA- -A------------------------A- --A----------------------A-- --AA--------------------AA-- --AA--------------------AA-- ---A--------------------A--- ---AA------------------AA--- ----A------------------A---- ----AAA--------------AAA---- -----AAAB----------BAAA----- ------AAAAA------AAAAA------ -------AAAAAAAAAAAAAA------- ---------AAAAAAAAAA--------- -----------AAAAAA----------- ------------AAAA------------ 
---B--------------------B--- ---B--------------------B--- ---B--------------------B--- --AB--------------------BA-- --A----------------------A-- ---A--------------------A--- ---AA------------------AA--- ---AA------------------AA--- ---AA------------------AA--- ----AA----------------AA---- ----AA----------------AA---- -----AABB----------BBAA----- ------AAA----------AAA------ -------AAAAAAAAAAAAAA------- --------AAAAAAAAAAAA-------- ----------AAAAAAAA---------- ------------AAAA------------ ---------------------------- 
---B--------------------B--- ----B------------------B---- ---B--------------------B--- --AB--------------------BA-- --A----------------------A-- ---A--------------------A--- ---AAAB--------------BAAA--- ----AAB--------------BAA---- ----AAB--------------BAA---- ----AAAB------------BAAA---- -----AAB------------BAA----- ------AAA----------AAA------ ------AAAAA------AAAAA------ --------AAAAAAAAAAAA-------- ---------AAAAAAAAAA--------- ------------AAAA------------ ------------AAAA------------ ---------------------------- 
---BB------------------BB--- ----B------------------B---- ---BB------------------BB--- ---AB------------------BA--- ---A--------------------A--- ----ABB--------------BBA---- ----AAA--------------AAA---- ----AAA--------------AAA---- -----AA--------------AA----- -----AAA------------AAA----- ------AA------------AA------ -------AAAA------AAAA------- --------AAAAAAAAAAAA-------- ---------AAAAAAAAAA--------- -----------AAAAAA----------- ------------AAAA------------ ---------------------------- ---------------------------- 
----BB----------------BB---- -----B----------------B----- ----BB----------------BB---- ----AB----------------BA---- ----AB----------------BA---- -----A----------------A----- -----AAA--A---------AAA----- -----AAA------------AAA----- ------AA------------AA------ ------AAAA--------AAAA------ -------AAA--------AAA------- --------AAAAAAAAAAAA-------- ---------AAAAAAAAAA--------- -----------AAAAAA----------- ------------AAAA------------ ---------------------------- ---------------------------- ---------------------------- 
-----BBB------------BBB----- ------BB------------BB------ -----BBB------------BBB----- -----ABB------------BBA----- -----A----------------A----- ------AA------------AA------ ------AAAAA------AAAAA------ -------AAAA------AAAA------- -------AAAAAAAAAAAAAA------- --------AAAAAAAAAAAA-------- ---------AAAAAAAAAA--------- ----------AAAAAAAA---------- ------------AAAA------------ ------------AAAA------------ ---------------------------- ---------------------------- ---------------------------- ---------------------------- 
------BBBB--------BBBB------ --------BB--------BB-------- ------BBBB--------BBBB------ ------AABB--------BBAA------ ------AA------------AA------ --------AAA------AAA-------- --------AAAAAAAAAAAA-------- --------AAAAAAAAAAAA-------- ---------AAAAAAAAAA--------- ----------AAAAAAAA---------- -----------AAAAAA----------- ------------AAAA------------ ------------AAAA------------ ---------------------------- ---------------------------- ---------------------------- ---------------------------- ---------------------------- 
--------BBBBBBBBBBBB-------- ----------BBBBBBBB---------- --------BBBBBBBBBBBB-------- --------AABBBBBBBBAA-------- --------AA--------AA-------- ---------AAAAAAAAAA--------- ---------AAAAAAAAAA--------- ---------AAAAAAAAAA--------- ----------AAAAAAAA---------- -----------AAAAAA----------- ------------AAAA------------ ---------------------------- ---------------------------- ---------------------------- ---------------------------- ---------------------------- ---------------------------- ---------------------------- 
----------BBBBBBBB---------- ---------------------------- ----------BBBBBBBB---------- ----------AAAAAAAA---------- ----------AAAAAAAA---------- ---------------------------- ---------------------------- ---------------------------- ---------------------------- ---------------------------- ---------------------------- ---------------------------- ---------------------------- ---------------------------- ---------------------------- ---------------------------- ---------------------------- ---------------------------- 
