model
size = 17 32 17, scale = 0.05, origin = -y
material 
  colors = A:#010101
voxels
7-3A15-A16-A506-2A3-2A11-2A-2A2(12-5A)13-3A14-3A15-A16-A419-2(2A7-)2(2A5-2A8-)2A5-2A9-2A3-2A11-A3-A12-2A-2A12-5A13-3A14-3A15-A16-A350-A11-A5-2(A9-A6-)A9-A7-3(2A5-2A8-)2A5-2A10-2(A3-A12-)2A-2A12-5A13-3A14-3A15-A16-A282-3(A11-A4-)A11-A5-A9-A3(6-2A7-2A)7-2A5-2A9-2(A5-A10-)A5-A11-A3-A12-2A-2A2(12-5A)13-3A15-A16-A230-A13-A3-3(A11-A4-)2A9-2A5-2(A9-A6-)A9-2(A7-)3(A8-A7-)A9-A5-A3(10-2A3-2A)11-2A-2A13-2(3A14-)3A15-A16-A179-3(A13-A2-)A13-A3-3(A11-A4-)A11-A5-3(A9-A6-)A9-2(A7-)A3(8-2A5-2A)9-2A3-2A11-2(A3-A12-)A3-A13-A-A3(14-3A)15-A16-A110-A15-A-4(A13-A2-)2A11-2A3-3(A11-A4-)2A9-2A5-3(A9-A6-)2(2A7-)2(A7-A8-)2A3(5-A10-A)5-A11-2(A3-A12-)5A12-5A13-3(3A14-)3A15-A16-A42-A15-2A15-3A13-2A-3(A13-A2-)2A11-2A2-2A11-2A3-2(A11-A4-)2A9-2A4-2A9-2A5-2(A9-A6-)2A7-2A6-2(2A7-)A7-A2(8-2A5-2A)9-2(A5-A10-)2A3-2A11-2A-2A3(12-5A)13-3(3A14-)3A15-A16-A8-A15-A-4(A13-A2-)2A11-2A3-3(A11-A4-)2A9-2A5-3(A9-A6-)2(2A7-)2(A7-A8-)2A5-2A9-2(A5-A10-)A5-A11-2(A3-A12-)5A12-5A13-3(3A14-)3A15-A16-A43-3(A13-A2-)A13-A3-3(A11-A4-)A11-A5-3(A9-A6-)A9-2(A7-)A3(8-2A5-2A)9-2A3-2A11-2(A3-A12-)A3-A13-A-A3(14-3A)15-A16-A111-A13-A3-3(A11-A4-)2A9-2A5-2(A9-A6-)A9-2(A7-)3(A8-A7-)A9-A5-A3(10-2A3-2A)11-2A-2A13-2(3A14-)3A15-A16-A180-3(A11-A4-)A11-A5-A9-A3(6-2A7-2A)7-2A5-2A9-2(A5-A10-)A5-A11-A3-A12-2A-2A2(12-5A)13-3A15-A16-A231-A11-A5-2(A9-A6-)A9-A7-3(2A5-2A8-)2A5-2A10-2(A3-A12-)2A-2A12-5A13-3A14-3A15-A16-A283-2(2A7-)2(2A5-2A8-)2A5-2A9-2A3-2A11-A3-A12-2A-2A12-5A13-3A14-3A15-A16-A353-2A3-2A11-2A-2A2(12-5A)13-3A14-3A15-A16-A423-3A15-A16-A501-
