model
size = 31 31 21, scale = 0.05, origin = -y
material 
  colors = A:#000 B:#FFF
voxels
------------------A------------ -----------------AAA----------- ----------------AAAA----------- ---------------AAAAAA---------- --------------AAAAAAA---------- -------------AAAAAAAAA--------- ------------AAAAAAAAAA--------- -----------AAAAAAAAAAAA-------- ----------AAAAAAAAAAAAA-------- ---------AAAAAAAAAAAAAAA------- --------AAAAAAAABAAAAAAA------- -------AAAAAAAABABAAAAAAA------ ------AAAAAAAABABABAAAAAA------ -----AAAAAAAABAAAAABAAAAAA----- ----AAAAAAAABAABABAABAAAAA----- ---AAAAAAAABABAABAABABAAAAA---- ---AAAAAAABAAAABABAAAABAAAA---- --AAAAAAABABABAABAABABABAAAA--- --AAAAAABAAABAAAAAAABAAABAAA--- -AAAAAABABABABAABAABABABABAAA-- -AAAAABAAAAABAABABAABAAAAABAA-- AAAAABABABAAAABAAAAAAAABABABAA- AAAABAAABAAAABAAAAABAAAABAAABA- AAABABABABAABAAAAAAABAABABABABA AABAAAAABAABAAAABAAAABAABAAAAAB ABABABAAAABAAAABABAAAABAAAABABA BAAABAAAABAAAABAAABAAAABAAAABAA ABABABAABAAAABAAAAABAAAABAABABA AAAABAABAAAABAAAAAAABAAAABAABAA ABAAAABAAAABAAAAAAAAABAAAABAAAA BAAAABAAAABAAAAAAAAAAABAAAABAAA 
------------------------------- ------------------------------- ------------------------------- ------------------------------- ------------------------------- ------------------------------- ------------------------------- ------------------------------- ------------------------------- ------------------------------- ------------------------------- ------------------------------- ------------------------------- ------------------------------- ------------------------------- ------------------------------- ------------------------------- ------------------------------- ------------------------------- ------------------------------- ------------------------------- A----------------------------A- A----------------------------A- A-----------------------------A A-----------------------------A A-----------------------------A A-----------------------------A A-----------------------------A A-----------------------------A A-----------------------------A AA---------------------------AA 
------------------------------- ------------------------------- ------------------------------- ------------------------------- ------------------------------- ------------------------------- ------------------------------- ------------------------------- ------------------------------- ------------------------------- ------------------------------- ------------------------------- ------------------------------- ------------------------------- ------------------------------- ------------------------------- ------------------------------- ------------------------------- ------------------------------- ------------------------------- ------------------------------- ------------------------------- A----------------------------A- A-----------------------------A A-----------------------------A A-----------------------------A A-----------------------------A A-----------------------------A A-----------------------------A A-----------------------------A AA---------------------------AA 
------------------------------- ------------------------------- ------------------------------- ------------------------------- ------------------------------- ------------------------------- ------------------------------- ------------------------------- ------------------------------- ------------------------------- ------------------------------- ------------------------------- ------------------------------- ------------------------------- ------------------------------- ------------------------------- ------------------------------- ------------------------------- ------------------------------- ------------------------------- ------------------------------- ------------------------------- ------------------------------- A-----------------------------A A-----------------------------A A-----------------------------A A-----------------------------A A-----------------------------A A-----------------------------A A-----------------------------A AA---------------------------AA 
------------------------------- ------------------------------- ------------------------------- ------------------------------- ------------------------------- ------------------------------- ------------------------------- ------------------------------- ------------------------------- ------------------------------- ------------------------------- ------------------------------- ------------------------------- ------------------------------- ------------------------------- ------------------------------- ------------------------------- ------------------------------- ------------------------------- ------------------------------- ------------------------------- ------------------------------- ------------------------------- A-----------------------------A A-----------------------------A A-----------------------------A A-----------------------------A A-----------------------------A A-----------------------------A A-----------------------------A AA---------------------------AA 
------------------------------- ------------------------------- ------------------------------- ------------------------------- ------------------------------- ------------------------------- ------------------------------- ------------------------------- ------------------------------- ------------------------------- ------------------------------- ------------------------------- ------------------------------- ------------------------------- ------------------------------- ------------------------------- ------------------------------- ------------------------------- ------------------------------- ------------------------------- ------------------------------- ------------------------------- ------------------------------- A-----------------------------A A-----------------------------A A-----------------------------A A-----------------------------A A-----------------------------A A-----------------------------A A-----------------------------A AA---------------------------AA 
------------------------------- ------------------------------- ------------------------------- ------------------------------- ------------------------------- ------------------------------- ------------------------------- ------------------------------- ------------------------------- ------------------------------- ------------------------------- ------------------------------- ------------------------------- ------------------------------- ------------------------------- ------------------------------- ------------------------------- ------------------------------- ------------------------------- ------------------------------- ------------------------------- ------------------------------- ------------------------------- A-----------------------------A A-----------------------------A A-----------------------------A A-----------------------------A A-----------------------------A A-----------------------------A A-----------------------------A AA---------------------------AA 
------------------------------- ------------------------------- ------------------------------- ------------------------------- ------------------------------- ------------------------------- ------------------------------- ------------------------------- ------------------------------- ------------------------------- ------------------------------- ------------------------------- ------------------------------- ------------------------------- ------------------------------- ------------------------------- ------------------------------- ------------------------------- ------------------------------- ------------------------------- ------------------------------- ------------------------------- ------------------------------- A-----------------------------A A-----------------------------A A-----------------------------A A-----------------------------A A-----------------------------A A-----------------------------A A-----------------------------A AA---------------------------AA 
------------------------------- ------------------------------- ------------------------------- ------------------------------- ------------------------------- ------------------------------- ------------------------------- ------------------------------- ------------------------------- ------------------------------- ------------------------------- ------------------------------- ------------------------------- ------------------------------- ------------------------------- ------------------------------- ------------------------------- ------------------------------- ------------------------------- ------------------------------- ------------------------------- ------------------------------- ------------------------------- ------------------------------- A-----------------------------A A-----------------------------A A-----------------------------A A-----------------------------A A-----------------------------A A-----------------------------A AAA-------------------------AAA 
------------------------------- ------------------------------- ------------------------------- ------------------------------- ------------------------------- ------------------------------- ------------------------------- ------------------------------- ------------------------------- ------------------------------- ------------------------------- ------------------------------- ------------------------------- ------------------------------- ------------------------------- ------------------------------- ------------------------------- ------------------------------- ------------------------------- ------------------------------- ------------------------------- ------------------------------- ------------------------------- ------------------------------- -A---------------------------A- -A---------------------------A- -A---------------------------A- -A---------------------------A- -A---------------------------A- -A---------------------------A- -AAA-----------------------AAA- 
------------------------------- ------------------------------- ------------------------------- ------------------------------- ------------------------------- ------------------------------- ------------------------------- ------------------------------- ------------------------------- ------------------------------- ------------------------------- ------------------------------- ------------------------------- ------------------------------- ------------------------------- ------------------------------- ------------------------------- ------------------------------- ------------------------------- ------------------------------- ------------------------------- ------------------------------- ------------------------------- ------------------------------- --A-------------------------A-- --A-------------------------A-- --A-------------------------A-- --A-------------------------A-- --A-------------------------A-- --A-------------------------A-- --AAA---------------------AAA-- 
------------------------------- ------------------------------- ------------------------------- ------------------------------- ------------------------------- ------------------------------- ------------------------------- ------------------------------- ------------------------------- ------------------------------- ------------------------------- ------------------------------- ------------------------------- ------------------------------- ------------------------------- ------------------------------- ------------------------------- ------------------------------- ------------------------------- ------------------------------- ------------------------------- ------------------------------- ------------------------------- ------------------------------- ---A-----------------------A--- ---A-----------------------A--- ---A-----------------------A--- ---A-----------------------A--- ---A-----------------------A--- ---A-----------------------A--- ---AAA-------------------AAA--- 
------------------------------- ------------------------------- ------------------------------- ------------------------------- ------------------------------- ------------------------------- ------------------------------- ------------------------------- ------------------------------- ------------------------------- ------------------------------- ------------------------------- ------------------------------- ------------------------------- ------------------------------- ------------------------------- ------------------------------- ------------------------------- ------------------------------- ------------------------------- ------------------------------- ------------------------------- ------------------------------- ------------------------------- ----A---------------------A---- ----A---------------------A---- ----A---------------------A---- ----A---------------------A---- ----A---------------------A---- ----A---------------------A---- ----AAA-----------------AAA---- 
------------------------------- ------------------------------- ------------------------------- ------------------------------- ------------------------------- ------------------------------- ------------------------------- ------------------------------- ------------------------------- ------------------------------- ------------------------------- ------------------------------- ------------------------------- ------------------------------- ------------------------------- ------------------------------- ------------------------------- ------------------------------- ------------------------------- ------------------------------- ------------------------------- ------------------------------- ------------------------------- ------------------------------- -----A-------------------A----- -----A-------------------A----- -----A-------------------A----- -----A-------------------A----- -----A-------------------A----- -----A-------------------A----- -----AAA---------------AAA----- 
------------------------------- ------------------------------- ------------------------------- ------------------------------- ------------------------------- ------------------------------- ------------------------------- ------------------------------- ------------------------------- ------------------------------- ------------------------------- ------------------------------- ------------------------------- ------------------------------- ------------------------------- ------------------------------- ------------------------------- ------------------------------- ------------------------------- ------------------------------- ------------------------------- ------------------------------- ------------------------------- ------------------------------- ------------------------------- ------A-----------------A------ ------A-----------------A------ ------A-----------------A------ ------A-----------------A------ ------A-----------------A------ ------AAA-------------AAA------ 
------------------------------- ------------------------------- ------------------------------- ------------------------------- ------------------------------- ------------------------------- ------------------------------- ------------------------------- ------------------------------- ------------------------------- ------------------------------- ------------------------------- ------------------------------- ------------------------------- ------------------------------- ------------------------------- ------------------------------- ------------------------------- ------------------------------- ------------------------------- ------------------------------- ------------------------------- ------------------------------- ------------------------------- ------------------------------- -------A---------------A------- -------A---------------A------- -------A---------------A------- -------A---------------A------- -------A---------------A------- -------AAA-----------AAA------- 
------------------------------- ------------------------------- ------------------------------- ------------------------------- ------------------------------- ------------------------------- ------------------------------- ------------------------------- ------------------------------- ------------------------------- ------------------------------- ------------------------------- ------------------------------- ------------------------------- ------------------------------- ------------------------------- ------------------------------- ------------------------------- ------------------------------- ------------------------------- ------------------------------- ------------------------------- ------------------------------- ------------------------------- ------------------------------- --------A-------------A-------- --------A-------------A-------- --------A-------------A-------- --------A-------------A-------- --------A-------------A-------- --------AAA---------AAA-------- 
------------------------------- ------------------------------- ------------------------------- ------------------------------- ------------------------------- ------------------------------- ------------------------------- ------------------------------- ------------------------------- ------------------------------- ------------------------------- ------------------------------- ------------------------------- ------------------------------- ------------------------------- ------------------------------- ------------------------------- ------------------------------- ------------------------------- ------------------------------- ------------------------------- ------------------------------- ------------------------------- ------------------------------- ------------------------------- ------------------------------- ---------A-----------A--------- ---------A-----------A--------- ---------A-----------A--------- ---------A-----------A--------- ---------AAA-------AAA--------- 
------------------------------- ------------------------------- ------------------------------- ------------------------------- ------------------------------- ------------------------------- ------------------------------- ------------------------------- ------------------------------- ------------------------------- ------------------------------- ------------------------------- ------------------------------- ------------------------------- ------------------------------- ------------------------------- ------------------------------- ------------------------------- ------------------------------- ------------------------------- ------------------------------- ------------------------------- ------------------------------- ------------------------------- ------------------------------- ------------------------------- ----------A---------A---------- ----------A---------A---------- ----------A---------A---------- ----------A---------A---------- ----------AAA-----AAA---------- 
------------------------------- ------------------------------- ------------------------------- ------------------------------- ------------------------------- ------------------------------- ------------------------------- ------------------------------- ------------------------------- ------------------------------- ------------------------------- ------------------------------- ------------------------------- ------------------------------- ------------------------------- ------------------------------- ------------------------------- ------------------------------- ------------------------------- ------------------------------- ------------------------------- ------------------------------- ------------------------------- ------------------------------- ------------------------------- ------------------------------- -----------AA-----AA----------- -----------AA-----AA----------- -----------AA-----AA----------- -----------AA-----AA----------- -----------AAAAAAAAA----------- 
------------------------------- ------------------------------- ------------------------------- ------------------------------- ------------------------------- ------------------------------- ------------------------------- ------------------------------- ------------------------------- ------------------------------- ------------------------------- ------------------------------- ------------------------------- ------------------------------- ------------------------------- ------------------------------- ------------------------------- ------------------------------- ------------------------------- ------------------------------- ------------------------------- ------------------------------- ------------------------------- ------------------------------- ------------------------------- ------------------------------- ------------------------------- -------------AAAAA------------- -------------AAAAA------------- -------------AAAAA------------- -------------AAAAA------------- 
