model
size = 11 28 11, scale = 0.05, origin = -y
material 
  colors = A:#F60 B:#C60 C:#070
voxels
----------- ----------- ----------- ----------- ----------- ----------- ----------- ----------- ----------- ----------- ----------- ----------- ----------- ----------- ----------- ----------- ----------- ----------- ----------- ----------- ----------- ----------- ----------- ----------- ----------- ----------- ----------- C---------C 
----------- ----------- ----------- ----------- ----------- ----------- ----------- ----------- ----------- ----------- ----------- ----------- ----------- ----------- ----------- ----------- ----------- ----------- ----------- ----------- ----------- ----------- ----------- ----------- ----------- ----------- -C-------C- -C-------C- 
----------- ----------- ----------- ----------- ----------- ----------- ----------- ----------- --BBBBBBB-- --AAAAAAA-- --BBBBBBB-- --AAAAAAA-- --BBBBBBB-- ----------- ----------- ----------- ----------- ----------- ----------- ----------- ----------- ----------- ----------- ----------- ---C---C--- --CC---CC-- --C-----C-- ----------- 
----------- ----------- ----------- ---AAAAA--- ---AAAAA--- ---BBBBB--- ---AAAAA--- ---BBBBB--- --BBBBBBB-- --AAAAAAA-- --BAAAAAB-- --AAAAAAA-- --BBBBBBB-- ---BBBBB--- ---AAAAA--- ---BBBBB--- ----------- ----------- ----------- ----------- ----------- ----------- ----------- ---CC-CC--- --CCC-CCC-- --C-----C-- ----------- ----------- 
----AAA---- ----AAA---- ----BBB---- ---AAAAA--- ---AAAAA--- ---BAAAB--- ---AAAAA--- ---BBBBB--- --BBBBBBB-- --AAAAAAA-- --BAAAAAB-- --AAAAAAA-- --BAAAAAB-- ---BAAAB--- ---AAAAA--- ---BAAAB--- ----AAA---- ----AAA---- ----------- ----------- ----------- ----------- ----C-C---- ---CC-CC--- ---C---C--- ----------- ----------- ----------- 
----AAA---- ----AAA---- ----BBB---- ---AAAAA--- ---AAAAA--- ---BAAAB--- ---AAAAA--- ---BBBBB--- --BBBBBBB-- --AAAAAAA-- --BAAAAAB-- --AAAAAAA-- --BAAAAAB-- ---BAAAB--- ---AAAAA--- ---BAAAB--- ----AAA---- ----AAA---- -----C----- -----C----- -----C----- -----C----- ----------- ----------- ----------- ----------- ----------- ----------- 
----AAA---- ----AAA---- ----BBB---- ---AAAAA--- ---AAAAA--- ---BAAAB--- ---AAAAA--- ---BBBBB--- --BBBBBBB-- --AAAAAAA-- --BAAAAAB-- --AAAAAAA-- --BAAAAAB-- ---BAAAB--- ---AAAAA--- ---BAAAB--- ----AAA---- ----AAA---- ----------- ----------- ----------- ----------- ----C-C---- ---CC-CC--- ---C---C--- ----------- ----------- ----------- 
----------- ----------- ----------- ---AAAAA--- ---AAAAA--- ---BBBBB--- ---AAAAA--- ---BBBBB--- --BBBBBBB-- --AAAAAAA-- --BAAAAAB-- --AAAAAAA-- --BAAAAAB-- ---BBBBB--- ---AAAAA--- ---BBBBB--- ----------- ----------- ----------- ----------- ----------- ----------- ----------- ---CC-CC--- --CCC-CCC-- --C-----C-- ----------- ----------- 
----------- ----------- ----------- ----------- ----------- ----------- ----------- ----------- --BBBBBBB-- --AAAAAAA-- --BBBBBBB-- --AAAAAAA-- --BBBBBBB-- ----------- ----------- ----------- ----------- ----------- ----------- ----------- ----------- ----------- ----------- ----------- ---C---C--- --CC---CC-- --C-----C-- ----------- 
----------- ----------- ----------- ----------- ----------- ----------- ----------- ----------- ----------- ----------- ----------- ----------- ----------- ----------- ----------- ----------- ----------- ----------- ----------- ----------- ----------- ----------- ----------- ----------- ----------- ----------- -C-------C- -C-------C- 
----------- ----------- ----------- ----------- ----------- ----------- ----------- ----------- ----------- ----------- ----------- ----------- ----------- ----------- ----------- ----------- ----------- ----------- ----------- ----------- ----------- ----------- ----------- ----------- ----------- ----------- ----------- C---------C 
