model
size = 29 11 28, scale = 0.05, origin = -y
material 
  colors = A:#CF7C00 B:#3FF C:#111 D:#FFF E:#FF0 F:#222 G:#BBB H:#EEE
voxels
----------------------------- ----------------------------- ---E-BBBB-E-------E-BBBB-E--- ----DBBBBB---------DBBBBB---- ---BBDDBBBB-HFFFH-BBDDBBBB--- ---BBDDBBBB-FFFFF-BBDDBBBB--- ---BBBBBDDD-HFFFH-BBBBBDDD--- ----BBBBDD---------BBBBDD---- ---E-BBBD-E-------E-BBBD-E--- ----------------------------- ----------------------------- 
----AAAAAA---------AAAAAA---- ---AAAAAAAA-------AAAAAAAA--- --AAABBBBAAA-----AAABBBBAAA-- -AAABBBBBBAAA---AAABBBBBBAAA- -AABBBBBBBBAA---AABBBBBBBBAA- -AABBBBBBBBAA---AABBBBBBBBAA- -AABBBBBBBBAA---AABBBBBBBBAA- -AAABBBBBBAAA---AAABBBBBBAAA- --AAABBBBAAA-----AAABBBBAAA-- ---AAAAAAAA-------AAAAAAAA--- ----AAAAAA---------AAAAAA---- 
----AAAAAA---------AAAAAA---- ---AAAAAAAA-------AAAAAAAA--- --AAA----AAA-----AAA----AAA-- -AAA------AAA---AAA------AAA- -AA--------AA---AA--------AA- -AA--------AA---AA--------AA- -AA--------AA---AA--------AA- -AAA------AAA---AAA------AAA- --AAA----AAA-----AAA----AAA-- ---AAAAAAAA-------AAAAAAAA--- ----AAAAAA---------AAAAAA---- 
----AAAAAA---------AAAAAA---- ---AAAAAAAA-------AAAAAAAA--- --AAA----AAA-----AAA----AAA-- -AAA------AAA---AAA------AAA- -AA--------AA---AA--------AA- EAA--------AA---AA--------AAE -AA--------AA---AA--------AA- EAAA------AAA---AAA------AAAE --AAA----AAA-----AAA----AAA-- ---AAAAAAAA-------AAAAAAAA--- ----AAAAAA---------AAAAAA---- 
----------------------------- ----------------------------- ----------------------------- ----------------------------- ----------------------------- E---------------------------E ----------------------------- E---------------------------E ----------------------------- ----------------------------- ----------------------------- 
----------------------------- ----------------------------- ----------------------------- -A-------------------------A- -A-------------------------A- EA-------------------------AE -A-------------------------A- EA-------------------------AE ----------------------------- ----------------------------- ----------------------------- 
----------------------------- ----------------------------- ----------------------------- ----------------------------- -A-------------------------A- -A-------------------------A- -A-------------------------A- -A-------------------------A- ----------------------------- ----------------------------- ----------------------------- 
----------------------------- ----------------------------- ----------------------------- ----------------------------- ----------------------------- -A-------------------------A- -A-------------------------A- -A-------------------------A- ----------------------------- ----------------------------- ----------------------------- 
----------------------------- ----------------------------- ----------------------------- ----------------------------- ----------------------------- -A-------------------------A- -A-------------------------A- -A-------------------------A- ----------------------------- ----------------------------- ----------------------------- 
----------------------------- ----------------------------- ----------------------------- ----------------------------- ----------------------------- -A-------------------------A- GA-------------------------AG -A-------------------------A- ----------------------------- ----------------------------- ----------------------------- 
----------------------------- ----------------------------- ----------------------------- ----------------------------- ----------------------------- -C-------------------------C- -C-------------------------C- -C-------------------------C- ----------------------------- ----------------------------- ----------------------------- 
----------------------------- ----------------------------- ----------------------------- ----------------------------- ----------------------------- -C-------------------------C- -C-------------------------C- -C-------------------------C- ----------------------------- ----------------------------- ----------------------------- 
----------------------------- ----------------------------- ----------------------------- ----------------------------- ----------------------------- -C-------------------------C- -C-------------------------C- -C-------------------------C- ----------------------------- ----------------------------- ----------------------------- 
----------------------------- ----------------------------- ----------------------------- ----------------------------- ----------------------------- -C-------------------------C- -C-------------------------C- -C-------------------------C- ----------------------------- ----------------------------- ----------------------------- 
----------------------------- ----------------------------- ----------------------------- ----------------------------- ----------------------------- -C-------------------------C- -C-------------------------C- -C-------------------------C- ----------------------------- ----------------------------- ----------------------------- 
----------------------------- ----------------------------- ----------------------------- ----------------------------- ----------------------------- -C-------------------------C- -C-------------------------C- -C-------------------------C- ----------------------------- ----------------------------- ----------------------------- 
----------------------------- ----------------------------- ----------------------------- ----------------------------- ----------------------------- -C-------------------------C- -C-------------------------C- -C-------------------------C- ----------------------------- ----------------------------- ----------------------------- 
----------------------------- ----------------------------- ----------------------------- ----------------------------- ----------------------------- -C-------------------------C- -C-------------------------C- -C-------------------------C- ----------------------------- ----------------------------- ----------------------------- 
----------------------------- ----------------------------- ----------------------------- ----------------------------- ----------------------------- -C-------------------------C- -C-------------------------C- -C-------------------------C- ----------------------------- ----------------------------- ----------------------------- 
----------------------------- ----------------------------- ----------------------------- ----------------------------- ----------------------------- --C-----------------------C-- --C-----------------------C-- --C-----------------------C-- ----------------------------- ----------------------------- ----------------------------- 
----------------------------- ----------------------------- ----------------------------- ----------------------------- ----------------------------- --C-----------------------C-- --C-----------------------C-- --C-----------------------C-- ----------------------------- ----------------------------- ----------------------------- 
----------------------------- ----------------------------- ----------------------------- ----------------------------- ----------------------------- ---C---------------------C--- ---C---------------------C--- ---C---------------------C--- ----------------------------- ----------------------------- ----------------------------- 
----------------------------- ----------------------------- ----------------------------- ----------------------------- ----------------------------- ----C-------------------C---- ----C-------------------C---- ----C-------------------C---- ----------------------------- ----------------------------- ----------------------------- 
----------------------------- ----------------------------- ----------------------------- ----------------------------- ----------------------------- -----C-----------------C----- -----C-----------------C----- -----C-----------------C----- ----------------------------- ----------------------------- ----------------------------- 
----------------------------- ----------------------------- ----------------------------- ----------------------------- ----------------------------- ------CC-------------CC------ ------CC-------------CC------ ------CC-------------CC------ ----------------------------- ----------------------------- ----------------------------- 
----------------------------- ----------------------------- ----------------------------- ----------------------------- ----------------------------- --------C-----------C-------- --------C-----------C-------- --------C-----------C-------- ----------------------------- ----------------------------- ----------------------------- 
----------------------------- ----------------------------- ----------------------------- ----------------------------- ----------------------------- ---------CCCCCCCCCCC--------- ---------CCCCCCCCCCC--------- ---------CCCCCCCCCCC--------- ----------------------------- ----------------------------- ----------------------------- 
----------------------------- ----------------------------- ----------------------------- ----------------------------- ----------------------------- ----------------------------- ----------G-G-G-G-G---------- ----------------------------- ----------------------------- ----------------------------- ----------------------------- 
