model
size = 14 16 32, scale = 0.05, origin = -y
material 
  colors = A:#FFF B:#111 C:#EEE
voxels
5-4(4A10-)4B10-4B149-4(6A8-)6B8-6B147-3(8A6-)B6AB2(6-8B)145-3(10A4-)B8AB2(4-10B)143-3(12A2-)B10AB2(2-12B)6-5B131-3(12A2-)B2A-7AB2(2-12B)4-8B129-28AB12A2B3A-8A28B3-4B3C3B128-28AB12A2B3A-8A29B-12B5-7B115-28AB12A2B3A-8A29B-12B4-2B5C2B114-28AB12A2B3A-8A29B-12B3-10B8-3B103-28AB12A2B3A-8A29B-12B3-2(3BC)2B8-3C103-28AB12A2B3A-8A29B-12B3-10B6-7B101-28AB12A2B3A-8A13B-5B7-2B2-3B6-3B3-2B-B4-2B6-7C101-2(13A-)B11AB-B3A-7AB-13B2-3B7-2B2-3B6-2B4-2B-B4-2B5-8B7-6B88-2(12A2-)B10AB2-B3A-6AB3-11B3-3B7-B3-3B6-2B4-2B-B4-2B5-C6BC7-6C88-3(12A2-)B3A-6AB3-11B3-3B7-B3-3B6-2B3-3B-B4-2B5-8B6-8B7-6B75-3(11A3-)3A-6AB3-11B3-3B7-B2(3-3B6-2B)5-CB-5B6-2C5BC7-6C75-3(11A3-)3A-6AB3-11B2(3-3B7-B)3-3B6-2B5-2B-5B6-8B7-6B75-3(11A3-)3A-7A3-11B2(3-3B7-B)3-3B6-2B5-CB5-2B5-2C5BC7-6C75-3(11A3-)3A-7A3-11B3(3-3B7-B)5-B6-2B2(5-9B)6-7B60-3(12A2-)3A-8A2-12B3(2-3B7-2B)4-C7-2B4-C7-C5-2C5B2C6-7C60-3(13A-)3A-9A-12BA2(-3B7-3B)-3B2(7-2B4-B)7-B5-B7-B5-8B7-7B8-5B33-3(13A-)3A-9A-12BA2(-3B7-3B)-3B2(7-2B4-B)2(7-B5-B)7-B2(5-2B)6-B5-B7-7B8-5B5-3(13A-)3A-9A-12BA2(-3B7-3B)2-2B7-2B3-2B7-2B4-B3(7-B5-B7-B74-3(12A2-)2A-9A2-A10BA2(2-2B7-3B)2-2(2B7-2B3-)2B)7-B5-B7-B74-3(12A2-)2A-9A2-A10BA2-2B7-3B2-3(2B7-2B3-)2B7-B5-B7-B74-3(11A3-)2A-8A3-A9BA2(3-2B7-2B)3-2B8-B3-2B7-2B4-2(B7-B5-)B7-B61-3(10A4-)A-8A4-A8BA3(4-B7-2B)4-3(B7-B5-)B7-B62-4(8A6-)7BA6(6-8B)6-7B64-4(6A8-)6(6B8-)6B9-4B10-3B47-
