model
size = 14 16 32, scale = 0.05, origin = -y
material 
  colors = A:#FF0 B:#FC0 C:#FF3 D:#100 E:#D00 F:#CF0 G:#993 H:#F63 I:#FC3 J:#F60 K:#FF6
voxels
5-4(4A10-)4D10-HCGC149-4(6A8-)D4BD8-2CJC2B147-3(8A6-)D6AD6-8B6-I2(CB)CFC145-3(10A4-)D8AD4-9BA4-HBG3CBHFC143-3(12A2-)D10AD2-11BC2-IGA7BCF5-BHCBC132-3(12A2-)D7A-2AD2-11BA2-GC8B2F4-CA2(IB)2C129-28AD12ACI8A-3ADI13B-C10BFA2-2CBC2EA2BC128-28AD12ADB8A-3AD13BC14B-11BC4-BCGBCFC116-28AD12ADC8A-3ABG13BH12BH-H11B3-BF5EBC115-28AD12ADC8A-3A2C27B-12B3-H6BGCB7-BCB104-28AD12ADC8A-3ABG12BC14B-G10BC3-GBE3BEGBH7-3E104-28AD12ADG8A-3A2C13BC12BK-C11B3-F8BG5-CBF2BCB102-28AD12ADB8A-3ABG-12B-CB7-3BC-3B6-3B3-2B4-B-2B5-7E103-2(13A-)D11AD-B7A-3AB-12BC-CB7-3B3-CB6-2BC3-GB4-B-2B5-8B7-2(BC)2F90-2(12A2-)D10AD2-D6A-3AD2-11B3-B7-3B3-GB6-3B3-CB4-B-BG5-E6BE7-6E90-3(12A2-)D6A-3AD2-10BD3-H7-2BC3-GB6-3B3-FB4-B-BAB4-8B6-7BA7-GB3CB76-3(11A3-)D6A-3A3-C9BD3-G7-3B3-CB6-3B3-2B6-2BC4-5B-2B6-E5B2E7-6E76-3(11A3-)D6A-3A3-D9BD3-B7-2BA3-H7-2BF3-2B6-3B4-F4B-2B6-8B7-2CFGBC76-3(11A3-)7A-3A3-D9BD3-B7-3B3-B7-2BC3-HB6-2BC3-FB5-2B6-E5B2E7-6E76-3(11A3-)7A-3A3-D9BD3-C7-3B3-B7-3B3-F7-B2C3-2B6-B5-9B6-7B8-CBCGCB61-3(12A2-)8A-3A2-D10BD2-DB7-2BC2-CB7-2BC2-2B7-3B2-AB7-B5-E7-E6-E5BE8-6E60-3(13A-)9A-3A-A11BD-D2B7-2BF-H2B7-3B2-FB7-BCF2-2B7-B5-F7-B5-B7-B6-7B7-CF2BCBF8-BCJBF33-3(13A-)9A-3A-A11BD-D2B7-3B-3B7-2BF2-FB7-2BI2-CB2(7-B5-B7-H5-F)B5-2B6-B5-B7-J2BCBJB8-BCGCB5-3(13A-)9A-3A-A11BD-D2B7-2BD-C2B7-2BI2-2B7-2B3-AB7-BA4-F7-B5-B7-B73-3(12A2-)9A-2A2-A10BA2-D2B7-BD2-G2B7-2B3-AB7-2B3-2B7-2B4-B7-BC4-H7-C73-3(12A2-)9A-2A2-A10BA2-D2B7-BD2-G2B7-2B3-CB7-BC3-2B7-2B4-G7-2B4-F7-B73-3(12A2-)9A-2A2-A10BA2-D2B7-BD2-C2(2B7-2B3-)2B7-BC4-B7-BC4-C7-C73-3(12A2-)9A-2A2-A10BA2-D2B7-BD3-2B7-BC3-FB7-2B3-AB7-2B4-F7-2B4-C7-G74-3(11A3-)8A-2A3-A9BA3-DB7-BD3-FB7-2B3-I8-BA3-CB7-2B4-B7-B5-A7-B5-B7-B60-3(10A4-)8A-A4-A8BA4-DB7-D4-2B7-B4-C2(B7-B5-)C7-B5-B7-B5-H7-H61-4(8A6-)A6BD6-D6BD6-8B6-I7B6-7BC6-C7B6-8B7-6BG63-4(6A8-)6D8-DBCGBF8-H2G2CB8-F3BIB8-GFCBCG8-BCGC2B8-CB3CH9-2BGB11-CBH48-
