model
size = 14 16 32, scale = 0.05, origin = -y
material 
  colors = A:#FF0 B:#FC0 C:#FF3 D:#100 E:#D00 F:#CF0 G:#C90 H:#F63 I:#FC3 J:#F60 K:#FF6
voxels
5-4(4A10-)4D10-CGCH149-4(6A8-)D4BD8-BGCJ2C147-3(8A6-)D6AD6-8B6-CF2(CB)CI145-3(10A4-)D8AD4-A9B4-CFHB3C2BH143-3(12A2-)D10AD2-C11B2-FCG6BABI6-CBCHB131-3(12A2-)D2A-7AD2-A11B2-2F8BCB4-2CBGBIAC129-28AC12A2D3A-8AI13BIAF10BC3-C2BA2ECB2C128-28AD12A2D3A-8ABC27B-C11B5-CFC2BCB115-28AD12ADB3A-8ACG13BH12BH-11BH4-CB5EFB114-28AD12ADC3A-8ACG12BC13BG-12B3-BC6BGH8-BCB103-28AD12ADB3A-8A2C12B2G13B-C11B3-H2GE3BE2B8-3E103-28AD12ADC3A-8AG13BCK12BC-G10BC3-H8BF6-GC2BFBC101-28AD12ADB3A-8A13B-BC3B7-BC2-3B6-3B3-2B-B4-2B6-7E101-2(13A-)D11AD-B3A-7AB-C12B2-3B7-BC2-C2B6-BC4-2B-B4-2B5-8B7-2F2(CB)88-2(12A2-)D10AD2-D3A-6AD3-11B3-G2B7-B3-3B6-BG4-IB-B4-BC5-E6BE7-6E88-3(12A2-)D3A-6AD3-D10B3-C2B7-H3-3B6-BG3-BAB-B4-BF5-8B6-A7B7-B3C2B75-3(11A3-)3A-6AD3-D9BC3-3B7-B3-3B6-BC3-C2B6-2B5-2B-5B6-2E5BE7-6E75-3(11A3-)3A-6AD3-D9BD3-A2B7-B3-F2B7-H3-3B6-2B5-2B-4BF6-8B7-C2BF2C75-3(11A3-)3A-7A3-D9BD3-3B2(7-B3-C2B)6-BH5-2B5-BF5-2E5BE7-6E75-3(11A3-)3A-7A3-D9BD3-3B7-C3-3B7-B3-2CB7-F5-B6-2B5-9B6-7B7-BCFCBC61-3(12A2-)3A-8A2-D10B2(D2-C2B7-B)C2-3B7-2B4-B7-BA4-E7-E6-E5BE7-6E61-3(13A-)3A-9A-D11BA-F2B7-2BD-3B7-2BH-FCB7-BF4-G7-2B4-B7-F5-B7-B6-7B7-FBC2BFC8-FBJCB33-3(13A-)3A-9A-D11BA-3B7-2BD-F2B7-3B-I2B7-BF4-B7-BC4-H7-B5-B7-F5-H7-B5-2B5-BF6-B5-B7-BJBC2BJ8-B3CG5-3(13A-)3A-9A-D11BA-D2B7-2BD-I2B7-2BC2-GB7-2B3-AB7-BA4-B7-F5-B7-B74-3(12A2-)2A-9A2-A10BA2-DB7-2BD2-2B7-3B2-2B7-BA3-2B7-2B3-CB7-B5-C7-H74-3(12A2-)2A-9A2-A10BA2-DB7-2BD2-2B7-3B2-CB7-BC3-2B7-2B3-2B7-B5-B7-F74-3(12A2-)2A-9A2-A10BA2-DB7-2BD2-2B7-2BC2-2B2(7-2B3-CB)7-B5-C7-C74-3(12A2-)2A-9A2-A10BA2-DB7-2BD2-CB7-2B3-2B7-BF3-2B7-BA3-GB7-F5-B7-C74-3(11A3-)2A-8A3-A9BA3-DB7-BD3-2B7-BF3-AB8-I3-2B7-BC4-B7-B5-B7-A5-B7-B61-3(10A4-)A-8A4-A8BA4-D7-BD4-B7-2B4-G7-BC4-B7-B5-B7-C5-G7-B5-H7-H62-4(8A6-)D6BA6-D6BD6-8B6-7BI6-C7B6-7BC6-8B6-G6B64-4(6A8-)6D8-F2BCBD8-BGC2BH8-BIG2BF8-BGBCFB8-2BCICB8-HCGCBC9-3BG10-HBC47-
