model
size = 14 16 32, scale = 0.05, origin = -y
material 
  colors = A:#FFF B:#F6F C:#636
voxels
5-3(4A10-)2(4B10-)4B149-3(6A8-)B4AB2(8-6B)147-3(8A6-)B6AB2(6-8B)145-3(10A4-)B8AB2(4-10B)143-3(12A2-)B10AB2(2-12B)5-5B132-3(12A2-)B7A-2AB2(2-12B)4-8B129-28AB12A2B8A-3A15B-13B2-3B3C4B128-28AB12A2B8A-3A29B-12B4-7B116-28AB12A2B8A-3A29B-12B3-2B5C2B115-28AB12A2B8A-3A29B-12B3-10B7-3B104-28AB12A2B8A-3A29B-12B3-2B2(C3B)7-3C104-28AB12A2B8A-3A29B-12B3-10B5-7B8-5B89-28AB12A2B8A-3A2B-12B-2B7-4B-3B6-3B3-2B4-B-2B5-C5BC8-5C90-2(13A-)B11AB-B7A-3AB-13B-2B7-3B3-2B6-3B3-2B4-B-2B5-8B6-8B89-2(12A2-)B10AB2-B6A-3AB2-11B3-B7-3B3-2B6-3B3-2B4-B-2B5-8B6-8C89-3(12A2-)B6A-3AB2-11B3-B7-3B3-2B6-3B3-2B4-B-3B4-8B6-8B7-6B76-3(11A3-)B6A-3A3-11B3-B7-2(3B3-2B6-)3B4-5B-2B6-C5B2C7-6C76-3(11A3-)B6A-3A3-11B2(3-B7-3B)3-2B6-3B4-5B-2B6-8B7-6B76-3(11A3-)7A-3A3-11B2(3-B7-3B)3-2B6-3B3-2B5-2B6-C5B2C7-6C76-3(11A3-)7A-3A3-11B3(3-B7-3B)3-2B6-B5-9B6-6B8-7B61-3(12A2-)8A-3A2-12B3(2-2B7-3B)2-2B7-B5-C7-C6-C5BC7-7C60-3(13A-)9A-3A-A12B2(-3B7-3B)2-2B7-3B2-2B2(7-B5-B)7-B6-7B7-7B8-5B33-3(13A-)9A-3A-A12B2(-3B7-3B)2-2B7-3B2-2B3(7-B5-B)7-B2(5-2B)6-B5-B7-7B8-5B5-3(13A-)9A-3A-A12B2(-3B7-3B)2-2B7-2B3-2B7-2B4-B7-B5-3(B7-B73-3(12A2-)9A-2A2-A10BA2(2-3B7-2B)2(3-2B7-2B)4-B7-2B4-)B7-B73-3(12A2-)9A-2A2-A10BA2-3B3(7-2B3-2B)2(7-2B4-B)7-B74-3(11A3-)8A-2A3-A9BA4(3-2B7-2B)4-2(B7-B5-)B7-B60-3(10A4-)8A-A4-A8BA3(4-2B7-B)4(5-B7-B)61-4(8A6-)A7B6(6-8B)7-7B63-4(6A8-)6(6B8-)6B9-4B11-3B48-
