model
size = 28 29 19, scale = 0.05, origin = -y
material 
  colors = A:#6C9 B:#FF1AAB C:#09FFEA D:#6F9 E:#CF0 F:#6CF G:#0F0 H:#0D0 I:#FFF J:#6F6 K:#F03 L:#222 M:#888 N:#EEE O:#555
voxels
---------------------------- ---------------------------- ---------------------------- ---------------------------- ---------------------------- ---------------------------- ---------------------------- ---------CCC----BBB--------- ---------CCC----BBB--------- ---------CEEEBBEEEB--------- ---------EE------EE--------- ---------E-EEEEEE-E--------- ---------EE------EE--------- ---------------------------- -----------------M---------- -----------------M---------- ---------------------------- ---------------------------- ---------------------------- ---------------------------- ---------------------------- ---------------------------- ---------------------------- ---------------------------- ---------------------------- ---------------------------- ---------------------------- ---------------------------- ---------------------------- 
---------------------------- ---------------------------- ---------------------------- ---------------------------- ----------AAAAAAAA---------- ---------AAAAAAAAAA--------- --------AAAAAAAAAAAA-------- -------AACCCAAAABBBAA------- ------AAACCCAAAABBBAAA------ ------AAACEEEEEEEEBAAA------ ------AAAEELLLLLLEEAAA------ ------AAAELEEEEEELEAAA------ ------AAAEEAAAAAAEEAAA------ ------AAAAAAAAAAAAAAAA------ ------FFAAAAAAAAAMAAFF------ -------FFLIIIIIIIMLFF------- --------FFAAAAAAAAFF-------- ---------FFFFFFFFFF--------- ---------------------------- ----------AAAAAAAA---------- ----------AAAAAAAA---------- -----------ADDDDA----------- -----------AAAAAA----------- ---------------------------- ---------------------------- ---------------------------- ---------------------------- ---------------------------- ---------------------------- 
---------------------------- ---------------------------- ---------------------------- ---------------------------- ------FFFFAAAAAAAAFFFF------ -----FFAAAAAAAAAAAAAAFF----- -----FAAAAAAAAAAAAAAAAF----- -----FAAAAAAAAAAAAAAAAF----- -----FAAAAAAAAAAAAAAAAF----- -----FAAAAAAAAAAAAAAAAF----- -----FAAAAAAAAAAAAAAAAF----- -----FAAAAAAAAAAAAAAAAF----- -----FAAAAAAAAAAAAAAAAF----- -----FAAAAAAAAAAAAAAAAF----- -----FAAAAAAAAAAAAAAAAF----- -----DDAAAAAAAAAAAAAADD----- ------DDAAAAAAAAAAAADD------ -------DDAAAAAAAAAADD------- --------DAAAAAAAAAAD-------- --------DDAAAAAAAADD-------- ---------DAAAAAAAAD--------- ---------DDAAAAAADD--------- ----------DAAAAAAD---------- ----------DDDDDDDD---------- ---------------------------- ---------------------------- ---------------------------- ---------------------------- ---------------------------- 
---------------------------- ---------------------------- ---------------------------- ----AAAAAAAAAAAAAAAAAAAA---- ----AAAAAAAAAAAAAAAAAAAA---- ----AAAAAAAAAAAAAAAAAAAA---- ----AAAAAAAAAAAAAAAAAAAA---- ----AAAAAAAAAAAAAAAAAAAA---- ----AAAAAAAAAAAAAAAAAAAA---- ----AAAAAAAAAAAAAAAAAAAA---- ----AAAAAAAAAAAAAAAAAAAA---- ----AAAAAAAAAAAAAAAAAAAA---- ----AAAAAAAAAAAAAAAAAAAA---- ----AAAAAAAAAAAAAAAAAAAA---- ----AAAAAAAAAAAAAAAAAAAA---- ----AAAAAAAAAAAAAAAAAAAA---- ----AAAAAAAAAAAAAAAAAAAA---- -----AAAAAAAAAAAAAAAAAA----- ------AAAAAAAAAAAAAAAA------ ------AAAAAAAAAAAAAAAA------ -------AAAAAAAAAAAAAA------- --------AAAAAAAAAAAA-------- --------AAAAAAAAAAAA-------- ---------AAAAAAAAAA--------- ---------AAAAAAAAAA--------- ---------------------------- ---------------------------- ---------------------------- ---------------------------- 
---------------------------- ---------------------------- -------AAAAAAAAAAAAAA------- ----AAAAAAAAAAAAAAAAAAAA---- --AAAAAAAAAAAAAAAAAAAAAAAA-- --AAAAAAAAAAAAAAAAAAAAAAAA-- --AAAAAAAAAAAAAAAAAAAAAAAA-- --AAAAAAAAAAAAAAAAAAAAAAAA-- --AAAAAAAAAAAAAAAAAAAAAAAA-- --AAAAAAAAAAAAAAAAAAAAAAAA-- --DAAAAAAAAAAAAAAAAAAAAAAD-- --DAAAAAAAAAAAAAAAAAAAAAAD-- --DAAAAAAAAAAAAAAAAAAAAAAD-- ----AAAAAAAAAAAAAAAAAAAA---- ----AAAAAAAAAAAAAAAAAAAA---- ----AAAAAAAAAAAAAAAAAAAA---- ----LAAAAAAAAAAAAAAAAAAL---- -----IAAAAAAAAAAAAAAAAI----- ------IAAAAAAAAAAAAAAI------ ------IAAAAAAAAAAAAAAI------ -------IAAAAAAAAAAAAI------- --------IAAAAAAAAAAI-------- --------IAAAAAAAAAAI-------- ---------IAAAAAAAAI--------- ---------IIIIIIMMII--------- ---------------MM----------- ---------------------------- ---------------------------- ---------------------------- 
------AAAAAAAAAAAAAAAA------ ------AAAAAAAAAAAAAAAA------ ---AAAAAAAAAAAAAAAAAAAAAA--- ---AAAAAAAAAAAAAAAAAAAAAA--- --AAAAAAAAAAAAAAAAAAAAAAAA-- --AAAAAAAAAAAAAAAAAAAAAAAA-- --AAAAAAAAAAAAAAAAAAAAAAAA-- --AAAAAAAAAAAAAAAAAAAAAAAA-- --AAAAAAAAAAAAAAAAAAAAAAAA-- --AAAAAAAAAAAAAAAAAAAAAAAA-- ---AAAAAAAAAAAAAAAAAAAAAA--- ---AAAAAAAAAAAAAAAAAAAAAA--- --DAAAAAAAAAAAAAAAAAAAAAAD-- ---AAAAAAAAAAAAAAAAAAAAAA--- ---AAAAAAAAAAAAAAAAAAAAAA--- ---AAAAAAAAAAAAAAAAAAAAAA--- ---AAAAAAAAAAAAAAAAAAAAAA--- ---AAAAAAAAAAAAAAAAAAAAAA--- ----AAAAAAAAAAAAAAAAAAAA---- ----AAAAAAAAAAAAAAAAAAAA---- -----AAAAAAAAAAAAAAAAAA----- ------AAAAAAAAAAAAAAAA------ ------AAAAAAAAAAAAAAAA------ ------AAAAAAAAAAAAAAAA------ -------AAAAAAAAAAAAAA------- --------AAAAAAAAAAAA-------- ---------------------------- ---------------------------- ---------------------------- 
------AAAAAAAAAAAAAAAA------ ------AAAAAAAAAAAAAAAA------ ---AAAAAAAAAAAAAAAAAAAAAA--- ---AAAAAAAAAAAAAAAAAAAAAA--- --AAAAAAAAAAAAAAAAAAAAAAAA-- --AAAAAAAAAAAAAAAAAAAAAAAA-- --AAAAAAAAAAAAAAAAAAAAAAAA-- --AAAAAAAAAAAAAAAAAAAAAAAA-- --AAAAAAAAAAAAAAAAAAAAAAAA-- --AAAAAAAAAAAAAAAAAAAAAAAA-- -FJAAAAAAAAAAAAAAAAAAAAAAJF- -FJAAAAAAAAAAAAAAAAAAAAAAJF- --DAAAAAAAAAAAAAAAAAAAAAAD-- ---BBBBBAAAAAAAAAAAABBBBB--- ---BBBBBAAAAAAAAAAAABBBBB--- ---BBBBBAAAAAAAAAAAABBBBB--- ---BBBBBAAAAAAAAAAAABBBBB--- ---BBBBBAAAAAAAAAAAABBBBB--- ----BBBBAAAAAAAAAAAABBBB---- ----BBBBAAAAAAAAAAAABBBB---- -----BBBAAAAAAAAAAAABBB----- ------BBAAAAAAAAAAAABB------ ------BBAAAAAAAAAAAABB------ ------BBAAAAAAAAAAAABB------ -------BAAAAAAAAAAAAB------- --------AAAAAAAAAAAA-------- ---------A--------A--------- ---------A--------A--------- ---------JBJBJBJBJB--------- 
------AAAAAAAAAAAAAAAA------ ------AAAAAAAAAAAAAAAA------ ---AAAAAAAAAAAAAAAAAAAAAA--- ---AAAAAAAAAAAAAAAAAAAAAA--- --AAAAAAAAAAAAAAAAAAAAAAAA-- --AAAAAAAAAAAAAAAAAAAAAAAA-- --AAAAAAAAAAAAAAAAAAAAAAAA-- --AAAAAAAAAAAAAAAAAAAAAAAA-- --AAAAAAAAAAAAAAAAAAAAAAAA-- --AAAAAAAAAAAAAAAAAAAAAAAA-- IFJAAAAAAAAAAAAAAAAAAAAAAJFI -FJAAAAAAAAAAAAAAAAAAAAAAJF- --DAAAAAAAAAAAAAAAAAAAAAAD-- ---EEEEEAAAAAAAAAAAAEEEEE--- ---EEEEEAAAAAAAAAAAAEEEEE--- ---EEEEEAAAAAAAAAAAAEEEEE--- ---EEEEEAAAAAAAAAAAAEEEEE--- ---EEEEEAAAAAAAAAAAAEEEEE--- ----EEEEAAAAAAAAAAAAEEEE---- ----EEEEAAAAAAAAAAAAEEEE---- -----EEEAAAAAAAAAAAAEEE----- ------EEAAAAAAAAAAAAEE------ ------EEAAAAAAAAAAAAEE------ ------EEAAAAAAAAAAAAEE------ -------EAAAAAAAAAAAAE------- --------AAAAAAAAAAAA-------- ---------A--------A--------- ---------A--------A--------- ---------EJEJEJEJEJ--------- 
------AAAAAAAAAAAAAAAA------ ------AAAAAAAAAAAAAAAA------ ---AAAAAAAAAAAAAAAAAAAAAA--- ---AAAAAAAAAAAAAAAAAAAAAA--- --AAAAAAAAAAAAAAAAAAAAAAAA-- --AAAAAAAAAAAAAAAAAAAAAAAA-- --AAAAAAAAAAAAAAAAAAAAAAAA-- --AAAAAAAAAAAAAAAAAAAAAAAA-- --AAAAAAAAAAAAAAAAAAAAAAAA-- --AAAAAAHHHHHHHHHHHHAAAAAA-- -FJAAAAHHAAAAAAAAAAHHAAAAJF- -FJAAAAHAAAAAAAAAAAAHAAAAJF- --DAAAAHAAAAAAAAAAAAHAAAAD-- ---CCCCHCAAAAAAAAAAAHCCCC--- ---CCCCHCAAAAAAAAAAAHCCCC--- ---CCCCHHAAAAAAAAAAHHCCCC--- ---CCCCOHAAAAAAAAAAHOCCCC--- ---CCCCOHAAAAAAAAAAHOCCCC--- ----CCCCHHAAHHHHAAHHCCCC---- ----CCCCCHHHHAAHHHHACCCC---- -----CCCCAAAAAAAAAAACCC----- ------CCCAAAAAAAAAAACC------ ------CCCAAAAAAAAAAACC------ ------CCCAAAAAAAAAAACC------ -------CCAAAAAAAAAAAC------- --------AAAAAAAAAAAA-------- ---------A--------A--------- ---------A--------A--------- ---------JCJCJCJCJC--------- 
------AAAAAAAAAAAAAAAA------ ------AAAAAAAAAAAAAAAA------ ---AAAAAAAAAAAAAAAAAAAAAA--- ---AAAAAAAAAAAAAAAAAAAAAA--- --AAAAAAAAAAAAAAAAAAAAAAAA-- --AAAAAAAAAAAAAAAAAAAAAAAA-- --AAAAAAAAAAAAAAAAAAAAAAAA-- --AAAAAAAAAAAAAAAAAAAAAAAA-- --AAAAAAAAAAAAAAAAAAAAAAAA-- --AAAAAA------------AAAAAA-- ---AAAA--GGGGGGGGGG--AAAA--- ---AAAA-GGKKKKKKKKGG-AAAA--- --DAAAA-GKKKKKKKKKKG-AAAAD-- ---AAAA-GKGGGGGGGGKG-AAAA--- ---AAAA-GGGGGGGGGGGG-AAAA--- ---AAAA--NLLNGGNLLN--AAAA--- ---AAAAA-NILNGGNILN-AAAAA--- ---AAAAA-GGGGGGGGGG-AAAAA--- ----AAAA--GG----GG--AAAA---- ----AAAAA----AA----AAAAA---- -----AAAAAAAAAAAAAAAAAA----- ------AAAAAAAAAAAAAAAA------ ------AAAAAAAAAAAAAAAA------ ------AAAAAAAAAAAAAAAA------ -------AAAAAAAAAAAAAA------- --------AAAAAAAAAAAA-------- ---------------------------- ---------------------------- ---------------------------- 
---------------------------- ---------------------------- ------DDDDD------DDDDD------ ---------------------------- --AA--------------------AA-- --AA--------------------AA-- --AA--------------------AA-- --AA--------------------AA-- --AA--------------------AA-- --AA--------------------AA-- --DA--------------------AD-- --DA--------------------AD-- --DA--------------------AD-- ---------------------------- ---------------------------- ---------------------------- ---------------------------- ---------------------------- ---------------------------- ---------------------------- ---------------------------- ---------------------------- ---------------------------- ------DDDDD------DDDDD------ ---------------------------- ---------------------------- ---------------------------- ---------------------------- ---------------------------- 
---------------------------- ---------------------------- ------DDDDD------DDDDD------ ---------------------------- ---------------------------- ---------------------------- ---------------------------- ---------------------------- ---------------------------- ---------------------------- ---------------------------- ---------------------------- ---------------------------- ---------------------------- ---------------------------- ---------------------------- ---------------------------- ---------------------------- ---------------------------- ---------------------------- ---------------------------- ---------------------------- ---------------------------- ------DDDDD------DDDDD------ ---------------------------- ---------------------------- ---------------------------- ---------------------------- ---------------------------- 
---------------------------- ---------------------------- ------CCDCC------BBDBB------ ---------------------------- ---------------------------- ---------------------------- ---------------------------- ---------------------------- ---------------------------- ---------------------------- ---------------------------- ---------------------------- ---------------------------- ---------------------------- ---------------------------- ---------------------------- ---------------------------- ---------------------------- ---------------------------- ---------------------------- ---------------------------- ---------------------------- ---------------------------- ------CCDCC------BBDBB------ ---------------------------- ---------------------------- ---------------------------- ---------------------------- ---------------------------- 
---------------------------- ---------------------------- ------CCDCC------BBDBB------ ------CCDCC------BBDBB------ ---------------------------- ---------------------------- ---------------------------- ---------------------------- ---------------------------- ---------------------------- ---------------------------- ---------------------------- ---------------------------- ---------------------------- ---------------------------- ---------------------------- ---------------------------- ---------------------------- ---------------------------- ---------------------------- ---------------------------- ---------------------------- ------CCDCC------BBDBB------ ------CCDCC------BBDBB------ ---------------------------- ---------------------------- ---------------------------- ---------------------------- ---------------------------- 
---------------------------- ---------------------------- ---------------------------- ------CCDCC------BBDBB------ ---------------------------- ---------------------------- ---------------------------- ---------------------------- ---------------------------- ---------------------------- ---------------------------- ---------------------------- ---------------------------- ---------------------------- ---------------------------- ---------------------------- ---------------------------- ---------------------------- ---------------------------- ---------------------------- ---------------------------- ---------------------------- ------CCDCC------BBDBB------ ---------------------------- ---------------------------- ---------------------------- ---------------------------- ---------------------------- ---------------------------- 
---------------------------- ---------------------------- ---------------------------- ------CCDCC------BBDBB------ ---------------------------- ---------------------------- ---------------------------- ---------------------------- ---------------------------- ---------------------------- ---------------------------- ---------------------------- ---------------------------- ---------------------------- ---------------------------- ---------------------------- ---------------------------- ---------------------------- ---------------------------- ---------------------------- ---------------------------- ---------------------------- ------CCDCC------BBDBB------ ---------------------------- ---------------------------- ---------------------------- ---------------------------- ---------------------------- ---------------------------- 
---------------------------- ---------------------------- ---------------------------- ------CCDCC------BBDBB------ ------CCDCC------BBDBB------ ---------------------------- ---------------------------- ---------------------------- ---------------------------- ---------------------------- ---------------------------- ---------------------------- ---------------------------- ---------------------------- ---------------------------- ---------------------------- ---------------------------- ---------------------------- ---------------------------- ---------------------------- ---------------------------- ------CCDCC------BBDBB------ ------CCDCC------BBDBB------ ---------------------------- ---------------------------- ---------------------------- ---------------------------- ---------------------------- ---------------------------- 
---------------------------- ---------------------------- ---------------------------- ---------------------------- ------CCDCC------BBDBB------ ---------------------------- ---------------------------- ---------------------------- ---------------------------- ---------------------------- ---------------------------- ---------------------------- ---------------------------- ---------------------------- ---------------------------- ---------------------------- ---------------------------- ---------------------------- ---------------------------- ---------------------------- ---------------------------- ------CCDCC------BBDBB------ ---------------------------- ---------------------------- ---------------------------- ---------------------------- ---------------------------- ---------------------------- ---------------------------- 
---------------------------- ---------------------------- ---------------------------- ---------------------------- ------CCDCC------BBDBB------ ------CCDCC------BBDBB------ ------CCDCC------BBDBB------ ------CCDCC------BBDBB------ ------CCDCC------BBDBB------ ------CCDCC------BBDBB------ ------CCDCC------BBDBB------ ------CCDCC------BBDBB------ ------CCDCC------BBDBB------ ------CCDCC------BBDBB------ ------CCDCC------BBDBB------ ------CCDCC------BBDBB------ ------CCDCC------BBDBB------ ------CCDCC------BBDBB------ ------CCDCC------BBDBB------ ------CCDCC------BBDBB------ ------CCDCC------BBDBB------ ------CCDCC------BBDBB------ ---------------------------- ---------------------------- ---------------------------- ---------------------------- ---------------------------- ---------------------------- ---------------------------- 
