model
size = 28 29 19, scale = 0.05, origin = -y
material 
  colors = A:#F4A7B9 B:#CB1B45 C:#DB4D6D D:#FFF E:#F8C3CD F:#533D5B G:#FEDFE1 H:#884C3A I:#6A4028 J:#9F353A K:#904840 L:#B9887D M:#986DB2 N:#6A4C9C O:#F19483 P:#9E7A7A Q:#F596AA R:#E03C8A S:#F7D94C T:#64363C U:#854836 V:#994639 W:#AB3B3A X:#B54434 Y:#F75C2F Z:#D7C4BB Aa:#B55D4C Ab:#F17C67 Ac:#CC543A Ad:#B5495B Ae:#D0104C Af:#BF6766 Ag:#9A5034 Ah:#EB7A77 Ai:#724832 Aj:#D75455 Ak:#EEA9A9 Al:#A35E47 Am:#554236 An:#A96360 Ao:#005CAF Ap:#C46243 Aq:#D05A6E Ar:#86473F As:#B19693 At:#8E354A Au:#E16B8C Av:#734338 Aw:#CB4042 Ax:#954A45 Ay:#DC9FB4 Az:#E87A90 Ba:#268785 Bb:#888 Bc:#222 Bd:#C73E3A Be:#E83015
voxels
- - - - - - - - - - - - - - - - - - - - - - - - - - - -   - - - - - - - - - - - - - - - - - - - - - - - - - - - -   - - - - - - - - - - - - - - - - - - - - - - - - - - - -   - - - - - - - - - - - - - - - - - - - - - - - - - - - -   - - - - - - - - - - - - - - - - - - - - - - - - - - - -   - - - - - - - - - - - - - - - - - - - - - - - - - - - -   - - - - - - - - - - - - - F F - - - - - - - - - - - - -   - - - - - - - - - - - - F F F F - - - - - - - - - - - -   - - - - - - - - - - - - F F F F - - - - - - - - - - - -   - - - - - - - - - - - F F - - F F - - - - - - - - - - -   - - - - - - - - - - - F - M M - F - - - - - - - - - - -   - - - - - - - - - - - - M M M M - - - - - - - - - - - -   - - - - - - - - - - - - M M M M - - - - - - - - - - - -   - - - - - - - - - - - - - M M - - - - - - - - - - - - -   - - - - - - - - - - - - - - - - - Bb- - - - - - - - - -   - - - - - - - - - - - - - - - - - Bb- - - - - - - - - -   - - - - - - - - - - - - - - - - - - - - - - - - - - - -   - - - - - - - - - - - - - - - - - - - - - - - - - - - -   - - - - - - - - - - - - - - - - - - - - - - - - - - - -   - - - - - - - - - - - - - - - - - - - - - - - - - - - -   - - - - - - - - - - - - - - - - - - - - - - - - - - - -   - - - - - - - - - - - - C C C C - - - - - - - - - - - -   - - - - - - - - - - - - - - - - - - - - - - - - - - - -   - - - - - - - - - - - - - - - - - - - - - - - - - - - -   - - - - - - - - - - - - - - - - - - - - - - - - - - - -   - - - - - - - - - - - - - - - - - - - - - - - - - - - -   - - - - - - - - - - - - - - - - - - - - - - - - - - - -   - - - - - - - - - - - - - - - - - - - - - - - - - - - -   - - - - - - - - - - - - - - - - - - - - - - - - - - - -   
- - - - - - - - - - - - - - - - - - - - - - - - - - - -   - - - - - - - - - - - - - - - - - - - - - - - - - - - -   - - - - - - - - - - - - - - - - - - - - - - - - - - - -   - - - - - - - - - - - - - - - - - - - - - - - - - - - -   - - - - - - - - - - A A A A A A A A - - - - - - - - - -   - - - - - - - - - A A A A A A A A A A - - - - - - - - -   - - - - - - - - A A A A A A A A A A A A - - - - - - - -   - - - - - - - A A A A A A A A A A A A A A - - - - - - -   - - - - - - A A A A A A A A A A A A A A A A - - - - - -   - - - - - - A A A A A A A A A A A A A A A A - - - - - -   - - - - - - A A A A A A A A A A A A A A A A - - - - - -   - - - - - - A A A A A A A A A A A A A A A A - - - - - -   - - - - - - A A A A A A A A A A A A A A A A - - - - - -   - - - - - - A A A A A A A A A A A A A A A A - - - - - -   - - - - - - A A A A A A A A A A A A A A A A - - - - - -   - - - - - - - A A BcD D D D D D D A BcA A - - - - - - -   - - - - - - - - A A A A A A A A A A A A - - - - - - - -   - - - - - - - - - A A A A A A A A A A - - - - - - - - -   - - - - - - - - - - - - - - - - - - - - - - - - - - - -   - - - - - - - - - - A A A A A A A A - - - - - - - - - -   - - - - - - - - - - A A A A A A A A - - - - - - - - - -   - - - - - - - - - - - A C C C C A - - - - - - - - - - -   - - - - - - - - - - - A A A A A A - - - - - - - - - - -   - - - - - - - - - - - - - - - - - - - - - - - - - - - -   - - - - - - - - - - - - - - - - - - - - - - - - - - - -   - - - - - - - - - - - - - - - - - - - - - - - - - - - -   - - - - - - - - - - - - - - - - - - - - - - - - - - - -   - - - - - - - - - - - - - - - - - - - - - - - - - - - -   - - - - - - - - - - - - - - - - - - - - - - - - - - - -   
- - - - - - - - - - - - - - - - - - - - - - - - - - - -   - - - - - - - - - - - - - - - - - - - - - - - - - - - -   - - - - - - - - - - - - - - - - - - - - - - - - - - - -   - - - - - - - - - - - - - - - - - - - - - - - - - - - -   - - - - - - A A A A A A A A A A A A A A A A - - - - - -   - - - - - A A A A A A A A A A A A A A A A A A - - - - -   - - - - - A A A A A A A A A A A A A A A A A A - - - - -   - - - - - A A A A A A A A A A A A A A A A A A - - - - -   - - - - - A A A A A A A A A A A A A A A A A A - - - - -   - - - - - A A A A A A A A A A A A A A A A A A - - - - -   - - - - - A A A A A A A A A A A A A A A A A A - - - - -   - - - - - A A A A A A A A A A A A A A A A A A - - - - -   - - - - - A A A A A A A A A A A A A A A A A A - - - - -   - - - - - A A A A A A A A A A A A A A A A A A - - - - -   - - - - - A A A A A A A A A A A A A A A A A A - - - - -   - - - - - A A A A A A A A A A A A A A A A A A - - - - -   - - - - - - A A A A A A A A A A A A A A A A - - - - - -   - - - - - - - A A A A A A A A A A A A A A - - - - - - -   - - - - - - - - A A A A A A A A A A A A - - - - - - - -   - - - - - - - - A A A A A A A A A A A A - - - - - - - -   - - - - - - - - - A A A A A A A A A A - - - - - - - - -   - - - - - - - - - A A A A A A A A A A - - - - - - - - -   - - - - - - - - - - A A A A A A A A - - - - - - - - - -   - - - - - - - - - - A A A A A A A A - - - - - - - - - -   - - - - - - - - - - - - - - - - - - - - - - - - - - - -   - - - - - - - - - - - - - - - - - - - - - - - - - - - -   - - - - - - - - - - - - - - - - - - - - - - - - - - - -   - - - - - - - - - - - - - - - - - - - - - - - - - - - -   - - - - - - - - - - - - - - - - - - - - - - - - - - - -   
- - - - - - - - - - - - - - - - - - - - - - - - - - - -   - - - - - - - - - - - - - - - - - - - - - - - - - - - -   - - - - - - - - - - - - - - - - - - - - - - - - - - - -   - - - - G AgC G T AsAxAnL B AhApQ E Y AnL AiP Af- - - -   - - - - O A A A A A A A A A A A A A A A A A A An- - - -   - - - - ArA A A A A A A A A A A A A A A A A A P - - - -   - - - - W A A A A A A A A A A A A A A A A A A G - - - -   - - - - AuA A A A A A A A A A A A A A A A A A H - - - -   - - - - I A A A A A A A A A A A A A A A A A A Q - - - -   - - - - V A A A A A A A A A A A A A A A A A A B - - - -   - - - - E A A A A A A A A A A A A A A A A A A Al- - - -   - - - - T A A A A A A A A A A A A A A A A A A Ai- - - -   - - - - AeA A A A A A A A A A A A A A A A A A Ac- - - -   - - - - AcA A A A A A A A A A A A A A A A A A J - - - -   - - - - Y A A A A A A A A A A A A A A A A A A Ab- - - -   - - - - P A A A A A A A A A A A A A A A A A A P - - - -   - - - - I O A A A A A A A A A A A A A A A A AqAz- - - -   - - - - - W K A A A A A A A A A A A A A A BeAj- - - - -   - - - - - - AwA A A A A A A A A A A A A A Aj- - - - - -   - - - - - - AsAkA A A A A A A A A A A A C Av- - - - - -   - - - - - - - W AdA A A A A A A A A A AxAb- - - - - - -   - - - - - - - - E A A A A A A A A A A Aa- - - - - - - -   - - - - - - - - AaAmA A A A A A A A K P - - - - - - - -   - - - - - - - - - J A A A A A A A A Bd- - - - - - - - -   - - - - - - - - - L L H AjW AhL K E Z - - - - - - - - -   - - - - - - - - - - - - - - - - - - - - - - - - - - - -   - - - - - - - - - - - - - - - - - - - - - - - - - - - -   - - - - - - - - - - - - - - - - - - - - - - - - - - - -   - - - - - - - - - - - - - - - - - - - - - - - - - - - -   
- - - - - - - - - - - - - - - - - - - - - - - - - - - -   - - - - - - - - - - - - - - - - - - - - - - - - - - - -   - - - - - - - A A A A A A A A A A A A A A - - - - - - -   - - - - A A A A A A A A A A A A A A A A A A A A - - - -   - - X A A A A A A A A A A A A A A A A A A A A A A X - -   - - Y A A A A A A A A A A A A A A A A A A A A A A X - -   - - H A A A A A A A A A A A A A A A A A A A A A A U - -   - - Q A A A A A A A A A A A A A A A A A A A A A A I - -   - - AmA A A A A A A A A A A A A A A A A A A A A A A - -   - - A A A A A A A A A A A A A A A A A A A A A A A A - -   - - AgA A A A A A A A A A A A A A A A A A A A A A Aa- -   - - AdA A A A A A A A A A A A A A A A A A A A A A Am- -   - - AtA A A A A A A A A A A A A A A A A A A A A A As- -   - - - - A A A A A A A A A A A A A A A A A A A A - - - -   - - - - A A A A A A A A A A A A A A A A A A A A - - - -   - - - - A A A A A A A A A A A A A A A A A A A A - - - -   - - - - BcA A A A A A A A A A A A A A A A A A Bc- - - -   - - - - - D A A A A A A A A A A A A A A A A D - - - - -   - - - - - - D A A A A A A A A A A A A A A D - - - - - -   - - - - - - D A A A A A A A A A A A A A A D - - - - - -   - - - - - - - D A A A A A A A A A A A A D - - - - - - -   - - - - - - - - D A A A A A A A A A A D - - - - - - - -   - - - - - - - - D A A A A A A A A A A D - - - - - - - -   - - - - - - - - - D A A A A A A A A D - - - - - - - - -   - - - - - - - - - D D D D D D A A D D - - - - - - - - -   - - - - - - - - - - - - - - - BbBb- - - - - - - - - - -   - - - - - - - - - - - - - - - - - - - - - - - - - - - -   - - - - - - - - - - - - - - - - - - - - - - - - - - - -   - - - - - - - - - - - - - - - - - - - - - - - - - - - -   
- - - - - - A A A A A A A A A A A A A A A A - - - - - -   - - - - - - A A A A A A A A A A A A A A A A - - - - - -   - - - A A A A A A A A A A A A A A A A A A A A A A - - -   - - - A A A A A A A A A A A A A A A A A A A A A A - - -   - - V A A A A A A A A A A A A A A A A A A A A A A Aj- -   - - A A A A A A A A A A A A A A A A A A A A A A A A - -   - - A A A A A A A A A A A A A A A A A A A A A A A A - -   - - A A A A A A A A A A A A A A A A A A A A A A A A - -   - - AnA A A A A A A A A A A A A A A A A A A A A A J - -   - - A A A A A A A A A A A A A A A A A A A A A A A A - -   - - A A A A A A A A A A A A A A A A A A A A A A A A - -   - - A A A A A A A A A A A A A A A A A A A A A A A A - -   - - Y A A A A A A A A A A A A A A A A A A A A A A J - -   - - - A A A A A A A A A A A A A A A A A A A A A A - - -   - - - A A A A A A A A A A A A A A A A A A A A A A - - -   - - - A A A A A A A A A A A A A A A A A A A A A A - - -   - - - A A A A A A A A A A A A A A A A A A A A A A - - -   - - - A A A A A A A A A A A A A A A A A A A A A A - - -   - - - - A A A A A A A A A A A A A A A A A A A A - - - -   - - - - A A A A A A A A A A A A A A A A A A A A - - - -   - - - - - A A A A A A A A A A A A A A A A A A - - - - -   - - - - - - A A A A A A A A A A A A A A A A - - - - - -   - - - - - - A A A A A A A A A A A A A A A A - - - - - -   - - - - - - A A A A A A A A A A A A A A A A - - - - - -   - - - - - - - A A A A A A A A A A A A A A - - - - - - -   - - - - - - - - A A A A A A A A A A A A - - - - - - - -   - - - - - - - - - - - - - - - - - - - - - - - - - - - -   - - - - - - - - - - - - - - - - - - - - - - - - - - - -   - - - - - - - - - - - - - - - - - - - - - - - - - - - -   
- - - - - - A A A A A A A A A A A A A A A A - - - - - -   - - - - - - A A A A A A A A A A A A A A A A - - - - - -   - - - A A A A A A A A A A A A A A A A A A A A A A - - -   - - - A A A A A A A A A A A A A A A A A A A A A A - - -   - - H A A A A A A A A A A A A A A A A A A A A A A P - -   - - A A A A A A A A A A A A A A A A A A A A A A A A - -   - - A A A A A A A A A A A A A A A A A A A A A A A A - -   - - A A A A A A A A A A A A A A A A A A A A A A A A - -   - - AyA A A A A A A A A A A A A A A A A A A A A A Ar- -   - - A A A A A A A A A A A A A A A A A A A A A A A A - -   - E A A A A A A A A A A A A A A A A A A A A A A A A E -   - E A A A A A A A A A A A A A A A A A A A A A A A A E -   - - G A A A A A A A A A A A A A A A A A A A A A A At- -   - - - B D Z AxW A A A A A A A A A A A A C C C C B - - -   - - - B A A AaAuA A A A A A A A A A A A C C C C B - - -   - - - B AuAeP I A A A A A A A A A A A A C C C C B - - -   - - - B AlAgArV A A A A A A A A A A A A C C C C B - - -   - - - B Q G AuE A A A A A A A A A A A A C C C C B - - -   - - - - B K G T A A A A A A A A A A A A C C C B - - - -   - - - - B C AeAeA A A A A A A A A A A A C C C B - - - -   - - - - - B V AcA A A A A A A A A A A A C C B - - - - -   - - - - - - B Y A A A A A A A A A A A A C B - - - - - -   - - - - - - B P A A A A A A A A A A A A C B - - - - - -   - - - - - - B I A A A A A A A A A A A A C B - - - - - -   - - - - - - - B A A A A A A A A A A A A B - - - - - - -   - - - - - - - - A A A A A A A A A A A A - - - - - - - -   - - - - - - - - - A - - - - - - - - A - - - - - - - - -   - - - - - - - - - A - - - - - - - - A - - - - - - - - -   - - - - - - - - - A B A B A A B A B A - - - - - - - - -   
- - - - - - A A A A A A A A A A A A A A A A - - - - - -   - - - - - - A A A A A A A A A A A A A A A A - - - - - -   - - - A A A A A A A A A A A A A A A A A A A A A A - - -   - - - A A A A A A A A A A A A A A A A A A A A A A - - -   - - H A A A A A A A A A A A A A A A A A A A A A A Al- -   - - A A A A A A A A A A A A A A A A A A A A A A A A - -   - - A A A A A A A A A A A A A A A A A A A A A A A A - -   - - A A A A A A A A A A A A A A A A A A A A A A A A - -   - - W A A A A A A A A A A A A A A A A A A A A A A U - -   - - A A A A A A A A A A A A A A A A A A A A A A A A - -   D E A A A A A A A A A A A A A A A A A A A A A A A A E D   - E A A A A A A A A A A A A A A A A A A A A A A A A E -   - - E A A A A A A A A A A A A A A A A A A A A A A T - -   - - - A A A A A A A A A A A A A A A A A A A A A A - - -   - - - A A A A A A A A A A A A A A A A A A A A A A - - -   - - - A A A A A A A A A A A A A A A A A A A A A A - - -   - - - A A A A A A A A A A A A A A A A A A A A A A - - -   - - - A A A A A A A A A A A A A A A A A A A A A A - - -   - - - - A A A A A A A A A A A A A A A A A A A A - - - -   - - - - A A A A A A A A A A A A A A A A A A A A - - - -   - - - - - A A A A A A A A A A A A A A A A A A - - - - -   - - - - - - A A A A A A A A A A A A A A A A - - - - - -   - - - - - - A A A A A A A A A A A A A A A A - - - - - -   - - - - - - A A A A A A A A A A A A A A A A - - - - - -   - - - - - - - A A A A A A A A A A A A A A - - - - - - -   - - - - - - - - A A A A A A A A A A A A - - - - - - - -   - - - - - - - - - A - - - - - - - - A - - - - - - - - -   - - - - - - - - - A - - - - - - - - A - - - - - - - - -   - - - - - - - - - A B A B A A B A B A - - - - - - - - -   
- - - - - - A A A A A A A A A A A A A A A A - - - - - -   - - - - - - A A A A A A A A A A A A A A A A - - - - - -   - - - A A A A A A A A A A A A A A A A A A A A A A - - -   - - - A A A A A A A A A A A A A A A A A A A A A A - - -   - - U A A A A A A A A A A A A A A A A A A A A A A J - -   - - A A A A A A A A A A A A A A A A A A A A A A A A - -   - - A A A A A A A A A A A A A A A A A A A A A A A A - -   - - A A A A A A A A A A A A A A A A A A A A A A A A - -   - - AdA A A A A A A A A A A A A A A A A A A A A A O - -   - - A A A A A A A A A A A A A A A A A A A A A A A A - -   - E A A A A A A A A A A A A A A A A A A A A A A A A E -   - E A A A A A A A A A A A A A A A A A A A A A A A A E -   - - H J AwA A A A A A A A A A A A A A A A A A AaAcH - -   - - - B AtA A A A A A A A A A A A A A A A A A L B - - -   - - - B I A A A A A A A A A A A A A A A A A A AsB - - -   - - - B O A A A A A A A A A A A A A A A A A A Y B - - -   - - - B AtK AfE A A A A A A A A A A A A A AcAeJ B - - -   - - - B AmD D W A A A A A A A A A A A A U V V AjB - - -   - - - - B Z G L A A A A A A A A A A A A E AaAkB - - - -   - - - - B A ApAqA A A A A A A A A A A A T Z O B - - - -   - - - - - B AbAvA A A A A A A A A A A A ApAhB - - - - -   - - - - - - B B A A A A A A A A A A A A B B - - - - - -   - - - - - - B B A A A A A A A A A A A A B B - - - - - -   - - - - - - B B A A A A A A A A A A A A B B - - - - - -   - - - - - - - B A A A A A A A A A A A A B - - - - - - -   - - - - - - - - A A A A A A A A A A A A - - - - - - - -   - - - - - - - - - A - - - - - - - - A - - - - - - - - -   - - - - - - - - - A - - - - - - - - A - - - - - - - - -   - - - - - - - - - A B A B A A B A B A - - - - - - - - -   
- - - - - - A A A A A A A A A A A A A A A A - - - - - -   - - - - - - A A A A A A K AyAkQ A A A A A A - - - - - -   - - - A A A A A A A A A AwAbAhX A A A A A A A A A - - -   - - - A A A A A A A A A AsC AnY A A A A A A A A A - - -   - - O A A A A I I AgA A V O AdH A A AvU E A A A A K - -   - - A A A A A AmAzAfA A Z AzAdQ A A K AyT A A A A A - -   - - A A A A A AfX D A A AhX AuAmA A A AiApA A A A A - -   - - A A A A A ArAxG AgAfAnX Y AhAmI AqAzT A A A A A - -   - - H A U AcAgBdAaK Y AhG U AqAyAgBdJ AeAkG K V A At- -   - - A A H - - - - - - - - - - - - - - - - - - AkA A - -   - - A A G AoAoAo- - S S - Ba- N N N - - R R - O A A - -   - - A A O - - Ao- S - S - Ba- N - N - R - R - U A A - -   - - AfA Ar- - Ao- S - S - Ba- N - N - - R R - L A L - -   - - - A W - - Ao- S - S - Ba- N - N - R - R - AlA - - -   - - - A Au- - Ao- - S S - Ba- N - N - - R R - B A - - -   - - - A I - - - - - - - - - - - - - - - - - - AdA - - -   - - - A V AwX AfAsAzX C AaO AiAgAiQ J AqAkAbL Z A - - -   - - - A A A A AnE AeA A AbU B T A A AeAkAvA A A A - - -   - - - - A A A P P ApA A J L AlE A A C AjH A A A - - - -   - - - - A A A G T C A A BeAlAfQ A A AbI AiA A A - - - -   - - - - - A A H I AyA A Z B W AwA A ApAiB A A - - - - -   - - - - - - A A A A A A G AdAdAcA A A A A A - - - - - -   - - - - - - A A A A A A ArZ E K A A A A A A - - - - - -   - - - - - - A A A A A A BeQ J D A A A A A A - - - - - -   - - - - - - - A A A A A A A A A A A A A A - - - - - - -   - - - - - - - - A A A A A A A A A A A A - - - - - - - -   - - - - - - - - - - - - - - - - - - - - - - - - - - - -   - - - - - - - - - - - - - - - - - - - - - - - - - - - -   - - - - - - - - - - - - - - - - - - - - - - - - - - - -   
- - - - - - - - - - - - - - - - - - - - - - - - - - - -   - - - - - - - - - - - - - - - - - - - - - - - - - - - -   - - - - - - B B B B B - - - - - - B B B B B - - - - - -   - - - - - - - - - - - - - - - - - - - - - - - - - - - -   - - G A - - - - - - - - - - - - - - - - - - - - A L - -   - - H A - - - - - - - - - - - - - - - - - - - - A Aq- -   - - Q A - - - - - - - - - - - - - - - - - - - - A Av- -   - - B A - - - - - - - - - - - - - - - - - - - - A K - -   - - AlA - - - - - - - - - - - - - - - - - - - - A A - -   - - A A - - - - - - - - - - - - - - - - - - - - A A - -   - - AcA - - - - - - - - - - - - - - - - - - - - A Aj- -   - - J A - - - - - - - - - - - - - - - - - - - - A At- -   - - AbA - - - - - - - - - - - - - - - - - - - - A Ax- -   - - - - - - - - - - - - - - - - - - - - - - - - - - - -   - - - - - - - - - - - - - - - - - - - - - - - - - - - -   - - - - - - - - - - - - - - - - - - - - - - - - - - - -   - - - - - - - - - - - - - - - - - - - - - - - - - - - -   - - - - - - - - - - - - - - - - - - - - - - - - - - - -   - - - - - - - - - - - - - - - - - - - - - - - - - - - -   - - - - - - - - - - - - - - - - - - - - - - - - - - - -   - - - - - - - - - - - - - - - - - - - - - - - - - - - -   - - - - - - - - - - - - - - - - - - - - - - - - - - - -   - - - - - - - - - - - - - - - - - - - - - - - - - - - -   - - - - - - B B B B B - - - - - - B B B B B - - - - - -   - - - - - - - - - - - - - - - - - - - - - - - - - - - -   - - - - - - - - - - - - - - - - - - - - - - - - - - - -   - - - - - - - - - - - - - - - - - - - - - - - - - - - -   - - - - - - - - - - - - - - - - - - - - - - - - - - - -   - - - - - - - - - - - - - - - - - - - - - - - - - - - -   
- - - - - - - - - - - - - - - - - - - - - - - - - - - -   - - - - - - - - - - - - - - - - - - - - - - - - - - - -   - - - - - - B B B B B - - - - - - B B B B B - - - - - -   - - - - - - - - - - - - - - - - - - - - - - - - - - - -   - - - - - - - - - - - - - - - - - - - - - - - - - - - -   - - - - - - - - - - - - - - - - - - - - - - - - - - - -   - - - - - - - - - - - - - - - - - - - - - - - - - - - -   - - - - - - - - - - - - - - - - - - - - - - - - - - - -   - - - - - - - - - - - - - - - - - - - - - - - - - - - -   - - - - - - - - - - - - - - - - - - - - - - - - - - - -   - - - - - - - - - - - - - - - - - - - - - - - - - - - -   - - - - - - - - - - - - - - - - - - - - - - - - - - - -   - - - - - - - - - - - - - - - - - - - - - - - - - - - -   - - - - - - - - - - - - - - - - - - - - - - - - - - - -   - - - - - - - - - - - - - - - - - - - - - - - - - - - -   - - - - - - - - - - - - - - - - - - - - - - - - - - - -   - - - - - - - - - - - - - - - - - - - - - - - - - - - -   - - - - - - - - - - - - - - - - - - - - - - - - - - - -   - - - - - - - - - - - - - - - - - - - - - - - - - - - -   - - - - - - - - - - - - - - - - - - - - - - - - - - - -   - - - - - - - - - - - - - - - - - - - - - - - - - - - -   - - - - - - - - - - - - - - - - - - - - - - - - - - - -   - - - - - - - - - - - - - - - - - - - - - - - - - - - -   - - - - - - B B B B B - - - - - - B B B B B - - - - - -   - - - - - - - - - - - - - - - - - - - - - - - - - - - -   - - - - - - - - - - - - - - - - - - - - - - - - - - - -   - - - - - - - - - - - - - - - - - - - - - - - - - - - -   - - - - - - - - - - - - - - - - - - - - - - - - - - - -   - - - - - - - - - - - - - - - - - - - - - - - - - - - -   
- - - - - - - - - - - - - - - - - - - - - - - - - - - -   - - - - - - - - - - - - - - - - - - - - - - - - - - - -   - - - - - - A A B A A - - - - - - A A B A A - - - - - -   - - - - - - - - - - - - - - - - - - - - - - - - - - - -   - - - - - - - - - - - - - - - - - - - - - - - - - - - -   - - - - - - - - - - - - - - - - - - - - - - - - - - - -   - - - - - - - - - - - - - - - - - - - - - - - - - - - -   - - - - - - - - - - - - - - - - - - - - - - - - - - - -   - - - - - - - - - - - - - - - - - - - - - - - - - - - -   - - - - - - - - - - - - - - - - - - - - - - - - - - - -   - - - - - - - - - - - - - - - - - - - - - - - - - - - -   - - - - - - - - - - - - - - - - - - - - - - - - - - - -   - - - - - - - - - - - - - - - - - - - - - - - - - - - -   - - - - - - - - - - - - - - - - - - - - - - - - - - - -   - - - - - - - - - - - - - - - - - - - - - - - - - - - -   - - - - - - - - - - - - - - - - - - - - - - - - - - - -   - - - - - - - - - - - - - - - - - - - - - - - - - - - -   - - - - - - - - - - - - - - - - - - - - - - - - - - - -   - - - - - - - - - - - - - - - - - - - - - - - - - - - -   - - - - - - - - - - - - - - - - - - - - - - - - - - - -   - - - - - - - - - - - - - - - - - - - - - - - - - - - -   - - - - - - - - - - - - - - - - - - - - - - - - - - - -   - - - - - - - - - - - - - - - - - - - - - - - - - - - -   - - - - - - A A B A A - - - - - - A A B A A - - - - - -   - - - - - - - - - - - - - - - - - - - - - - - - - - - -   - - - - - - - - - - - - - - - - - - - - - - - - - - - -   - - - - - - - - - - - - - - - - - - - - - - - - - - - -   - - - - - - - - - - - - - - - - - - - - - - - - - - - -   - - - - - - - - - - - - - - - - - - - - - - - - - - - -   
- - - - - - - - - - - - - - - - - - - - - - - - - - - -   - - - - - - - - - - - - - - - - - - - - - - - - - - - -   - - - - - - A A B A A - - - - - - A A B A A - - - - - -   - - - - - - A A B A A - - - - - - A A B A A - - - - - -   - - - - - - - - - - - - - - - - - - - - - - - - - - - -   - - - - - - - - - - - - - - - - - - - - - - - - - - - -   - - - - - - - - - - - - - - - - - - - - - - - - - - - -   - - - - - - - - - - - - - - - - - - - - - - - - - - - -   - - - - - - - - - - - - - - - - - - - - - - - - - - - -   - - - - - - - - - - - - - - - - - - - - - - - - - - - -   - - - - - - - - - - - - - - - - - - - - - - - - - - - -   - - - - - - - - - - - - - - - - - - - - - - - - - - - -   - - - - - - - - - - - - - - - - - - - - - - - - - - - -   - - - - - - - - - - - - - - - - - - - - - - - - - - - -   - - - - - - - - - - - - - - - - - - - - - - - - - - - -   - - - - - - - - - - - - - - - - - - - - - - - - - - - -   - - - - - - - - - - - - - - - - - - - - - - - - - - - -   - - - - - - - - - - - - - - - - - - - - - - - - - - - -   - - - - - - - - - - - - - - - - - - - - - - - - - - - -   - - - - - - - - - - - - - - - - - - - - - - - - - - - -   - - - - - - - - - - - - - - - - - - - - - - - - - - - -   - - - - - - - - - - - - - - - - - - - - - - - - - - - -   - - - - - - A A B A A - - - - - - A A B A A - - - - - -   - - - - - - A A B A A - - - - - - A A B A A - - - - - -   - - - - - - - - - - - - - - - - - - - - - - - - - - - -   - - - - - - - - - - - - - - - - - - - - - - - - - - - -   - - - - - - - - - - - - - - - - - - - - - - - - - - - -   - - - - - - - - - - - - - - - - - - - - - - - - - - - -   - - - - - - - - - - - - - - - - - - - - - - - - - - - -   
- - - - - - - - - - - - - - - - - - - - - - - - - - - -   - - - - - - - - - - - - - - - - - - - - - - - - - - - -   - - - - - - - - - - - - - - - - - - - - - - - - - - - -   - - - - - - A A B A A - - - - - - A A B A A - - - - - -   - - - - - - - - - - - - - - - - - - - - - - - - - - - -   - - - - - - - - - - - - - - - - - - - - - - - - - - - -   - - - - - - - - - - - - - - - - - - - - - - - - - - - -   - - - - - - - - - - - - - - - - - - - - - - - - - - - -   - - - - - - - - - - - - - - - - - - - - - - - - - - - -   - - - - - - - - - - - - - - - - - - - - - - - - - - - -   - - - - - - - - - - - - - - - - - - - - - - - - - - - -   - - - - - - - - - - - - - - - - - - - - - - - - - - - -   - - - - - - - - - - - - - - - - - - - - - - - - - - - -   - - - - - - - - - - - - - - - - - - - - - - - - - - - -   - - - - - - - - - - - - - - - - - - - - - - - - - - - -   - - - - - - - - - - - - - - - - - - - - - - - - - - - -   - - - - - - - - - - - - - - - - - - - - - - - - - - - -   - - - - - - - - - - - - - - - - - - - - - - - - - - - -   - - - - - - - - - - - - - - - - - - - - - - - - - - - -   - - - - - - - - - - - - - - - - - - - - - - - - - - - -   - - - - - - - - - - - - - - - - - - - - - - - - - - - -   - - - - - - - - - - - - - - - - - - - - - - - - - - - -   - - - - - - A A B A A - - - - - - A A B A A - - - - - -   - - - - - - - - - - - - - - - - - - - - - - - - - - - -   - - - - - - - - - - - - - - - - - - - - - - - - - - - -   - - - - - - - - - - - - - - - - - - - - - - - - - - - -   - - - - - - - - - - - - - - - - - - - - - - - - - - - -   - - - - - - - - - - - - - - - - - - - - - - - - - - - -   - - - - - - - - - - - - - - - - - - - - - - - - - - - -   
- - - - - - - - - - - - - - - - - - - - - - - - - - - -   - - - - - - - - - - - - - - - - - - - - - - - - - - - -   - - - - - - - - - - - - - - - - - - - - - - - - - - - -   - - - - - - A A B A A - - - - - - A A B A A - - - - - -   - - - - - - - - - - - - - - - - - - - - - - - - - - - -   - - - - - - - - - - - - - - - - - - - - - - - - - - - -   - - - - - - - - - - - - - - - - - - - - - - - - - - - -   - - - - - - - - - - - - - - - - - - - - - - - - - - - -   - - - - - - - - - - - - - - - - - - - - - - - - - - - -   - - - - - - - - - - - - - - - - - - - - - - - - - - - -   - - - - - - - - - - - - - - - - - - - - - - - - - - - -   - - - - - - - - - - - - - - - - - - - - - - - - - - - -   - - - - - - - - - - - - - - - - - - - - - - - - - - - -   - - - - - - - - - - - - - - - - - - - - - - - - - - - -   - - - - - - - - - - - - - - - - - - - - - - - - - - - -   - - - - - - - - - - - - - - - - - - - - - - - - - - - -   - - - - - - - - - - - - - - - - - - - - - - - - - - - -   - - - - - - - - - - - - - - - - - - - - - - - - - - - -   - - - - - - - - - - - - - - - - - - - - - - - - - - - -   - - - - - - - - - - - - - - - - - - - - - - - - - - - -   - - - - - - - - - - - - - - - - - - - - - - - - - - - -   - - - - - - - - - - - - - - - - - - - - - - - - - - - -   - - - - - - A A B A A - - - - - - A A B A A - - - - - -   - - - - - - - - - - - - - - - - - - - - - - - - - - - -   - - - - - - - - - - - - - - - - - - - - - - - - - - - -   - - - - - - - - - - - - - - - - - - - - - - - - - - - -   - - - - - - - - - - - - - - - - - - - - - - - - - - - -   - - - - - - - - - - - - - - - - - - - - - - - - - - - -   - - - - - - - - - - - - - - - - - - - - - - - - - - - -   
- - - - - - - - - - - - - - - - - - - - - - - - - - - -   - - - - - - - - - - - - - - - - - - - - - - - - - - - -   - - - - - - - - - - - - - - - - - - - - - - - - - - - -   - - - - - - A A B A A - - - - - - A A B A A - - - - - -   - - - - - - A A B A A - - - - - - A A B A A - - - - - -   - - - - - - - - - - - - - - - - - - - - - - - - - - - -   - - - - - - - - - - - - - - - - - - - - - - - - - - - -   - - - - - - - - - - - - - - - - - - - - - - - - - - - -   - - - - - - - - - - - - - - - - - - - - - - - - - - - -   - - - - - - - - - - - - - - - - - - - - - - - - - - - -   - - - - - - - - - - - - - - - - - - - - - - - - - - - -   - - - - - - - - - - - - - - - - - - - - - - - - - - - -   - - - - - - - - - - - - - - - - - - - - - - - - - - - -   - - - - - - - - - - - - - - - - - - - - - - - - - - - -   - - - - - - - - - - - - - - - - - - - - - - - - - - - -   - - - - - - - - - - - - - - - - - - - - - - - - - - - -   - - - - - - - - - - - - - - - - - - - - - - - - - - - -   - - - - - - - - - - - - - - - - - - - - - - - - - - - -   - - - - - - - - - - - - - - - - - - - - - - - - - - - -   - - - - - - - - - - - - - - - - - - - - - - - - - - - -   - - - - - - - - - - - - - - - - - - - - - - - - - - - -   - - - - - - A A B A A - - - - - - A A B A A - - - - - -   - - - - - - A A B A A - - - - - - A A B A A - - - - - -   - - - - - - - - - - - - - - - - - - - - - - - - - - - -   - - - - - - - - - - - - - - - - - - - - - - - - - - - -   - - - - - - - - - - - - - - - - - - - - - - - - - - - -   - - - - - - - - - - - - - - - - - - - - - - - - - - - -   - - - - - - - - - - - - - - - - - - - - - - - - - - - -   - - - - - - - - - - - - - - - - - - - - - - - - - - - -   
- - - - - - - - - - - - - - - - - - - - - - - - - - - -   - - - - - - - - - - - - - - - - - - - - - - - - - - - -   - - - - - - - - - - - - - - - - - - - - - - - - - - - -   - - - - - - - - - - - - - - - - - - - - - - - - - - - -   - - - - - - A A B A A - - - - - - A A B A A - - - - - -   - - - - - - - - - - - - - - - - - - - - - - - - - - - -   - - - - - - - - - - - - - - - - - - - - - - - - - - - -   - - - - - - - - - - - - - - - - - - - - - - - - - - - -   - - - - - - - - - - - - - - - - - - - - - - - - - - - -   - - - - - - - - - - - - - - - - - - - - - - - - - - - -   - - - - - - - - - - - - - - - - - - - - - - - - - - - -   - - - - - - - - - - - - - - - - - - - - - - - - - - - -   - - - - - - - - - - - - - - - - - - - - - - - - - - - -   - - - - - - - - - - - - - - - - - - - - - - - - - - - -   - - - - - - - - - - - - - - - - - - - - - - - - - - - -   - - - - - - - - - - - - - - - - - - - - - - - - - - - -   - - - - - - - - - - - - - - - - - - - - - - - - - - - -   - - - - - - - - - - - - - - - - - - - - - - - - - - - -   - - - - - - - - - - - - - - - - - - - - - - - - - - - -   - - - - - - - - - - - - - - - - - - - - - - - - - - - -   - - - - - - - - - - - - - - - - - - - - - - - - - - - -   - - - - - - A A B A A - - - - - - A A B A A - - - - - -   - - - - - - - - - - - - - - - - - - - - - - - - - - - -   - - - - - - - - - - - - - - - - - - - - - - - - - - - -   - - - - - - - - - - - - - - - - - - - - - - - - - - - -   - - - - - - - - - - - - - - - - - - - - - - - - - - - -   - - - - - - - - - - - - - - - - - - - - - - - - - - - -   - - - - - - - - - - - - - - - - - - - - - - - - - - - -   - - - - - - - - - - - - - - - - - - - - - - - - - - - -   
- - - - - - - - - - - - - - - - - - - - - - - - - - - -   - - - - - - - - - - - - - - - - - - - - - - - - - - - -   - - - - - - - - - - - - - - - - - - - - - - - - - - - -   - - - - - - - - - - - - - - - - - - - - - - - - - - - -   - - - - - - A A B A A - - - - - - A A B A A - - - - - -   - - - - - - A A B A A - - - - - - A A B A A - - - - - -   - - - - - - A A B A A - - - - - - A A B A A - - - - - -   - - - - - - A A B A A - - - - - - A A B A A - - - - - -   - - - - - - A A B A A - - - - - - A A B A A - - - - - -   - - - - - - A A B A A - - - - - - A A B A A - - - - - -   - - - - - - A A B A A - - - - - - A A B A A - - - - - -   - - - - - - A A B A A - - - - - - A A B A A - - - - - -   - - - - - - A A B A A - - - - - - A A B A A - - - - - -   - - - - - - A A B A A - - - - - - A A B A A - - - - - -   - - - - - - A A B A A - - - - - - A A B A A - - - - - -   - - - - - - A A B A A - - - - - - A A B A A - - - - - -   - - - - - - A A B A A - - - - - - A A B A A - - - - - -   - - - - - - A A B A A - - - - - - A A B A A - - - - - -   - - - - - - A A B A A - - - - - - A A B A A - - - - - -   - - - - - - A A B A A - - - - - - A A B A A - - - - - -   - - - - - - A A B A A - - - - - - A A B A A - - - - - -   - - - - - - A A B A A - - - - - - A A B A A - - - - - -   - - - - - - - - - - - - - - - - - - - - - - - - - - - -   - - - - - - - - - - - - - - - - - - - - - - - - - - - -   - - - - - - - - - - - - - - - - - - - - - - - - - - - -   - - - - - - - - - - - - - - - - - - - - - - - - - - - -   - - - - - - - - - - - - - - - - - - - - - - - - - - - -   - - - - - - - - - - - - - - - - - - - - - - - - - - - -   - - - - - - - - - - - - - - - - - - - - - - - - - - - -   
