model
size = 27 11 20, scale = 0.05, origin = -y
material 
  colors = A:#111
voxels
----------AAAAAAAAAA------- --------------AAAAAA------- --------------AAAAAA------- ---------------AAAA-------- --------------------------- --------------------------- --------------------------- --------------------------- --------------------------- --------------------------- --------------------------- 
--------AAAAAAAAAAAAAA----- -------------AAAAAAAAA----- -------------AAAAAAAAA----- -------------AAAAAAAAA----- -------------AAAAAAAA------ --------------AAAAAA------- --------------------------- --------------------------- --------------------------- --------------------------- --------------------------- 
------AAAAAAAA-----AAAAA--- ----------AAAAAAAAAAAAAA--- -----------AAAAAAAAAAAA---- -----------AAAAAAAAAAAA---- -----------AAAAAAAAAAAA---- ------------AAAAAAAAAA----- -------------AAAAAAAA------ ----------------AA--------- --------------------------- --------------------------- --------------------------- 
----AAAAAAAA---------AAAA-- ---------AAAAA-----AAAAAA-- ----------AAAAAAAAAAAAAA--- ----------AAAAAAAAAAAAAA--- ----------AAAAAAAAAAAAAA--- -----------AAAAAAAAAAAA---- ------------AAAAAAAAAA----- -------------AAAAAAAA------ ----------------AA--------- --------------------------- --------------------------- 
---AAAAAAA-------------AA-- ---------AAA---------AAAA-- ---------AAAAA-----AAAAAA-- ---------AAAAA-----AAAAAA-- ---------AAAAA-----AAAAAA-- ----------AAAA-----AAAAA--- -----------AAA-----AAAA---- ------------AAAAAAAAAA----- -------------AAAAAAAA------ --------------------------- --------------------------- 
--AAAAAAAA-------------AAA- --------AAA-----------AAAA- --------AAAA---------AAAAA- --------AAAA---------AAAAA- ---------AAA---------AAAA-- ---------AAA---------AAAA-- ----------AA---------AAA--- -----------AAA-----AAAA---- ------------AAAAAAAAAA----- --------------AAAAAA------- --------------------------- 
-AAAAAAAA---------------AA- --------AA-------------AAA- --------AAA-----------AAAA- --------AAA-----------AAAA- --------AAA-----------AAAA- ---------AA-----------AAA-- ---------AA-----------AAA-- ----------AAA-------AAAA--- -----------AAAAAAAAAAAA---- -------------AAAAAAAA------ --------------------------- 
-AAAAAAAA---------------AAA -------AAA-------------AAAA -------AAAA-----------AAAAA --------AAA-----------AAAA- --------AAA-----------AAAA- --------AAA-----------AAAA- ---------AA-----------AAA-- ----------AA---------AAA--- -----------AAAAAAAAAAAA---- ------------AAAAAAAAAA----- ---------------AAAA-------- 
AAAAAAAA-----------------AA -------AA---------------AAA -------AAA-------------AAAA -------AAA-------------AAAA --------AA-------------AAA- --------AA-------------AAA- ---------A-------------AA-- ----------A-----------AA--- -----------AAAAAAAAAAAA---- ------------AAAAAAAAAA----- --------------AAAAAA------- 
AAAAAAAA-----------------AA -------AA---------------AAA -------AAA-------------AAAA -------AAA-------------AAAA --------AA-------------AAA- --------AA-------------AAA- ---------A-------------AA-- ---------AA-----------AAA-- ----------AAAAAAAAAAAAAA--- ------------AAAAAAAAAA----- --------------AAAAAA------- 
AAAAAAAA-----------------AA -------AA---------------AAA -------AAA-------------AAAA -------AAA-------------AAAA --------AA-------------AAA- --------AA-------------AAA- ---------A-------------AA-- ---------AA-----------AAA-- ----------AAAAAAAAAAAAAA--- ------------AAAAAAAAAA----- --------------AAAAAA------- 
AAAAAAAA-----------------AA -------AA---------------AAA -------AAA-------------AAAA -------AAA-------------AAAA --------AA-------------AAA- --------AA-------------AAA- ---------A-------------AA-- ----------A-----------AA--- -----------AAAAAAAAAAAA---- ------------AAAAAAAAAA----- --------------AAAAAA------- 
-AAAAAAA-----------------AA -------AA---------------AAA -------AAA-------------AAAA --------AA-------------AAA- --------AA-------------AAA- --------AA-------------AAA- ---------A-------------AA-- ----------A-----------AA--- -----------AAAAAAAAAAAA---- ------------AAAAAAAAAA----- ---------------AAAA-------- 
-AAAAAAAA---------------AA- --------AA-------------AAA- --------AAA-----------AAAA- --------AAA-----------AAAA- --------AAA-----------AAAA- ---------AA-----------AAA-- ---------AA-----------AAA-- ----------AA---------AAA--- -----------AAAAAAAAAAAA---- -------------AAAAAAAA------ --------------------------- 
--AAAAAAA---------------AA- --------AA-------------AAA- --------AAA-----------AAAA- --------AAA-----------AAAA- ---------AA-----------AAA-- ---------AA-----------AAA-- ----------A-----------AA--- -----------AA-------AAA---- ------------AAAAAAAAAA----- --------------AAAAAA------- --------------------------- 
---AAAAAAA-------------AA-- ---------AA-----------AAA-- ---------AAA---------AAAA-- ---------AAA---------AAAA-- ---------AAA---------AAAA-- ----------AA---------AAA--- -----------A---------AA---- ------------AA-----AAA----- -------------AAAAAAAA------ --------------------------- --------------------------- 
----AAAAAA-------------AA-- ---------AAA---------AAAA-- ----------AAAA-----AAAAA--- ----------AAAA-----AAAAA--- ----------AAAA-----AAAAA--- -----------AAA-----AAAA---- ------------AA-----AAA----- -------------AAAAAAAA------ ----------------AA--------- --------------------------- --------------------------- 
------AAAAAA---------AAA--- ----------AAAA-----AAAAA--- -----------AAAAAAAAAAAA---- -----------AAAAAAAAAAAA---- -----------AAAAAAAAAAAA---- ------------AAAAAAAAAA----- -------------AAAAAAAA------ ----------------AA--------- --------------------------- --------------------------- --------------------------- 
--------AAAAAA-----AAA----- ------------AAAAAAAAAA----- ------------AAAAAAAAAA----- ------------AAAAAAAAAA----- -------------AAAAAAAA------ --------------AAAAAA------- --------------------------- --------------------------- --------------------------- --------------------------- --------------------------- 
----------AAAAAAAAAA------- --------------AAAAAA------- --------------AAAAAA------- ---------------AAAA-------- --------------------------- --------------------------- --------------------------- --------------------------- --------------------------- --------------------------- --------------------------- 
