model
size = 15 30 10, scale = 0.05, origin = -y
material 
  colors = A:#777 B:#555 C:#888 D:#222 E:#F30 F:#0F0 G:#9F0 H:#F60 I:#F90 J:#444 K:#3F3 L:#B00 M:#6F0
voxels
--------------- --------------- --------------- --------------- --------------- --------------- --------------- BBB-BBB-BBB-BBB BBB-BBB-BBB-BBB BBB-BBB-BBB-BBB --------------- --------------- --------------- --------------- ---AACAAAAAA--- ---AAHEEEEAA--- ---AAHEEEEAA--- ---AAHIEEEAA--- ---AAHEELEAA--- ---AAHEEEEAA--- ---AAHIELEAA--- ---AAHIEEEAA--- ---AAHIELEAA--- ---AAHIEEEAA--- ---AAHIEEEAA--- ---AAHIEEEAA--- ---AACAAAAAA--- --------------- --------------- --------------- 
CAADAAADAAADAAC CAADAAADAAADAAC CAADAAADAAADAAC CAADAAADAAADAAC CAADAAADAAADAAA ACAAAAAAAAAAAAA AAAAAAAAAAAAAAA AAAAAAAAAAAAAAA AAAAAAAAAAAAAAA AAAAAAAAAAAAAAA AACAACAAAAAAAAA ABJBBJBBBBBBBBA ABCAACAAAAAAABA ABCAACAAAAAAABA -BCAAAAAAAAAAB- -BCAAAAAAAAAAB- -BCAAAAAAAAAAB- -ACAAAAAAAAAAC- --------------- -ACAAAAAAAAAAC- -ACAAAAAAAAAAC- -ACAAAAAAAAAAC- -ACAAAAAAAAAAC- -ACAAAAAAAAAAC- --------------- -ACAAAAAAAAAAA- -ACAAAAAAAAAAC- -ACAACAAAAAAAC- -ACAACAAAAAAAC- -BBBBBBBBBBBBB- 
AAADAAADAAADAAA AAAAAAAAAAAAAAA AAAAAAAAAAAAAAA AAAAAAAAAAAAAAA AAAAAAAAAAAAAAA AAAAAAAAAAAAAAA AAAAAAAAAAAAAAA AAAAAAAAAAAAAAA AAAAAAAAAAAAAAA AAAAAAAAAAAAAAA AAAAAAAAAAAAAAA AAAAAAAAAAAAAAA AAAAAAAAAAAAAAA AAAAAAAAAAAAAAA -AAAAAAAAAAAAA- -AAAAAAAAAAAAA- -BAAAAAAAAAAAB- -AAAAAAAAAAAAA- --GGGFAAAAGFF-- -AAAAAAAAAAAAA- -BAAAAAAAAAAAB- -BAAAAAAAAAAAB- -BAAAAAAAAAAAB- -AAAAAAAAAAAAA- --GGGFFFFFFFG-- -AAAAAAAAAAAAA- -AAAAAAAAAAAAA- -AAAAAAAAAAAAA- -AAAAAAAAAAAAA- -BAAAAAAAAAAAB- 
AAADAAADAAADAAA AAAAAAAAAAAAAAA AAAAAAAAAAAAAAA AAAAAAAAAAAAAAA AAAAAAAAAAAAAAA AAAAAAAAAAAAAAA AAAAAAAAAAAAAAA AAAAAAAAAAAAAAA AAAAAAAAAAAAAAA AAAAAAAAAAAAAAA AAAAAAAAAAAAAAA AAAAAAAAAAAAAAA AAAAAAAAAAAAAAA AAAAAAAAAAAAAAA -AAAAAAAAAAAAA- -AAAAAAAAAAAAA- -BA---------AB- -AA---------AA- --F---------G-- -AA---------AA- -BA---------AB- -AA---------AA- -BA---------AB- -AA---------AA- --G---------K-- -AA---------AA- -AA---------AA- -AA---------AA- -AA---------AA- -BA---------AB- 
AAADAAADAAADAAA AAAAAAAAAAAAAAA AAAAAAAAAAAAAAA AAAAAAAAAAAAAAA AAAAAAAAAAAAAAA AAAAAAAAAAAAAAA AAAAAAAAAAAAAAA AAAAAAAAAAAAAAA AAAAAAAAAAAAAAA AAAAAAAAAAAAAAA AAAAAAAAAAAAAAA AAAAAAAAAAAAAAA AAAAAAAAAAAAAAA AAAAAAAAAAAAAAA -AAAAAAAAAAAAA- -AAAAAAAAAAAAA- -BA---------AB- -AA---------AA- --F---------G-- -AA---------AA- -BA---------AB- -AA---------AA- -BA---------AB- -AA---------AA- --G---------G-- -AA---------AA- -AA---------AA- -AA---------AA- -AA---------AA- -BA---------AB- 
AAADAAADAAADAAA AAADAAADAAADAAA AAADAAADAAADAAA AAADAAADAAADAAA AAABAAABAAABAAA AAAAAAAAAAAAAAA AAAAAAAAAAAAAAA AAAAAAAAAAAAAAA AAAAAAAAAAAAAAA AAAAAAAAAAAAAAA AAAAAAAAAAAAAAA AAAAAAAAAAAAAAA AAAAAAAAAAAAAAA AAAAAAAAAAAAAAA -AAAAAAAAAAAAA- -CAAAAAAAAAAAA- -JA---------AB- -AA---------AA- --G---------F-- -AA---------AA- -BA---------AB- -AA---------AA- -BA---------AB- -AA---------AA- --F---------K-- -AA---------AA- -AA---------AA- -AA---------AA- -AA---------AA- -BA---------AB- 
--------------- --------------- --------------- --------------- --------------- --------------- --------------- AAAAAAAAAAAAAAA CAAAAAAAAAAAAAC AAAAAAAAAAAAAAA AAAAAAAAAAAAAAA AAAAAAAAAAAAAAA AAAAAAAAAAAAAAA AAAAAAAAAAAAAAA -CAAAAAAAAAAAC- -AAAAAAAAAAAAC- -BA---------AJ- -AA---------AC- --F---------F-- -AA---------AC- -JA---------AJ- -CA---------AC- -BA---------AJ- -AA---------AC- --F---------M-- -CA---------AC- -CA---------AC- -CA---------AC- -AA---------AC- -BA---------AB- 
--------------- --------------- --------------- --------------- --------------- --------------- --------------- AAAAAAAAAAAAAAA AAAAAAAAAAAAAAA CAAAAAAAAAAAAAC AAAAAAAAAAAAAAA AAAAAAAAAAAAAAA AAAAAAAAAAAAAAA AAAAAAAAAAAAAAA -AAAAAAAAAAAAA- -AAAAAAAAAAAAA- -BAAAAAAAAAAAB- -AAAAAAAAAAAAA- --GFFAAAAAGGF-- -AAAAAAAAAAAAA- -BAAAAAAAAAAAB- -AAAAAAAAAAAAA- -BAAAAAAAAAAAB- -AAAAAAAAAAAAA- --GGFAAAAAFMK-- -AAAAAAAAAAAAA- -AAAAAAAAAAAAA- -AAAAAAAAAAAAA- -AAAAAAAAAAAAA- -BAAAAAAAAAAAB- 
--------------- --------------- --------------- --------------- --------------- --------------- --------------- --------------- AAAAAAAAAAAAAAA AAAAAAAAAAAAAAC CAAAAAAAAAAAAAC CAAAAAAAAAAAAAC CAAAAAAAAAAAAAC AAAAAAAAAAAAAAC -ABBBBBBBBBBBA- -AAAAAAAAAAAAA- -BBBBBBABBBBBB- -AAAAABABAAAAA- -----ABABA----- -AAAAABABAAAAA- -BBBBBBABBBBBB- -AAAAAAAAAAAAA- -BBBBBBABBBBBB- -AAAAABABAAAAA- -----ABABA----- -AAAAABABAAAAA- -AAAAABABAAAAA- -AAAAABABAAAAA- -AAAAABABAAAAA- -BBBBBBBBBBBBB- 
--------------- --------------- --------------- --------------- --------------- --------------- --------------- --------------- --------------- AAAAAAAAAAAAAAA AAAAAAAAAAAAAAA ACAAAAAAAAAAAAA ACAAAAAAAAAAAAA AAAAAAAAAAAAAAA --------------- --------------- --------------- --------------- --------------- --------------- --------------- --------------- --------------- --------------- --------------- --------------- --------------- --------------- --------------- --------------- 
