model
size = 32 32 11, scale = 0.05, origin = -y
material 
  colors = A:#050 B:#FC0 C:#070 D:#080
voxels
498-4A28-2ADA28-AD2A28-4A28-4B184-2B-2B26-BAB-BAB24-BDAB-BADB22-B2AB3-B2AB21-BCB5-BAB22-B7-B23-B7-B477-2(4A28-)4A18-15A17-16A15-B3A2C5A4B2A2B10-3B4AC13A2B7-2B6A2C14A4B3-2B7ACAC6A2C7A3B-2B18A3CAC4A2B2-B5A2C13A3C5A4-4A2C8A-6A2C4A6-12A3-10A8-10A5-8A10-3AC4A6-7A13-4ABA6-2AB3A19-B7-B-CA20-B7-B22-10B22-D2AD6A22-2AD5ADA2(22-10A)21-8AC2A21-3A2D2AC4A2(20-12A)20-AD3ACD5A20-5AC5AD2(20-12A)20-3AD8A20-14A17-15A3(16-16A)15-B16AB14-16AB13-20A13-15A4-2A11-15A2(4-A)2B29AB2-B12A5-11A4-12A5-10A6-C10A5-9A8-10A5-8A11-7A6-7A15-ACBA7-ABACA19-B7-B21-B9-AB20-A9-2A20-2A2(8-2A19-3A)3(8-3A18-3A)2(8-3A18-D2A)4(8-3A18-3A)5(8-4A16-4A)8-4A15-B4A8-4AB14-5A8-4AB13-A13-6A12-A13-A5-A11-6A8-A9-A2B11A8-10AB2-B10A8-10A3-11A8-9A5-AC8A8-9A7-8A8-7AD9-AC6A6-6ADA13-2CABA7-ABACA19-B7-B21-B10-B20-A10-A19-7(2A10-2A18-)2(DA10-2A18-)2A10-2A18-2A10-2A17-5(3A10-3A16-)3A10-3A15-B3A10-3AB14-4A10-3AB13-A14-5A12-A19-A11-5A19-A2B10A10-9AB2-B9A10-9A3-10A10-8AD4-D8A10-8A6-C7A10-7AD8-AC6A6-8A12-A2CABA7-ABAC2A18-B7-B21-B10-B2(20-A10-A)19-3(2A10-2A18-)DA3(10-2A18-2A)2(10-2A18-DA)10-2A18-2A2(10-3A16-3A)10-3A16-D2A3(10-3A16-3A)10-3A15-B3A10-3AB14-4A10-3AB13-A3-A10-5A12-A19-A11-5A19-A2B10A10-9AB2-B9A10-8AD3-D9A10-9A4-9A10-8A6-8A10-7A8-C8A6-8A12-A2CABA7-AB2C2A18-B7-B22-B8-AB3(20-2A8-2A)2(19-3A8-2A)19-7(3A8-3A18-)3A5(8-4A16-4A)8-4A15-B4A8-4AB14-5A8-4AB13-A3-2A8-6A12-A13-A5-A11-6A8-A10-2B11A8-10AB2-B10A8-10A4-10A8-9A5-D9A8-8AD6-9A8-7AD8-C8A6-8A13-ACABA7-AB2CA19-B7-B22-11B21-11A20-D11A20-12A20-9AD2A2(20-12A)20-4AD7A20-D11A3(20-12A)20-13A18-14A18-15A17-3A2-10A3(16-4A7-5A)15-B4A7-5AB14-5A7-5AB13-A3-2A7-7A12-A12-2A5-A11-6A7-2A10-3B10A7-11AB3-B9A7-11A4-10A7-9AD6-2(9A7-)10A6-9A9-8A6-7AD14-ACBA7-ABCA20-B7-B313-AD2A25-5AD4A21-3AD8A20-13A18-14A18-10AD3A18-11AD3A17-7AC4AD2A17-15A2(17-4A6-5A)B13-2B5A6-4AB14-7A6-7A12-A5-A6-2A5-2A4-2B4-7A6-2A5-A3-AB-B11A6-11AB3-11A2(6-10A)6-9A7-10A6-9A8-C8A6-8A12-D5A6-6AD18-B7-B23-B7-B599-8A22-6AC3AD2A2-2B9-2B2-16AC2AB6-3BA-20A3B3-2B9A2C10A2C2AD2B3-4A2C4AC3A4C9ADB3-4AC4A2C17A5-7A2C7A3C6AD6-D6AC17A8-4A2C13AD3A11-2AC5A5-5AD19-2A5-4A21-2B5-B24-2B5-B890-ADA28-2(AD)2A26-D6A26-5B27-5B13-
