model
size = 28 12 28, scale = 0.05, origin = -y
material 
  colors = A:#FC0 B:#E00 C:#D00 D:#A00 E:#00E F:#0A0
voxels
----------AAAAAAAA---------- ---------------------------- ------------AAAA------------ -----------ACCCCA----------- -----------ACCCCA----------- -----------ACCCCA----------- -----------ACCCCA----------- -----------ACDCCA----------- ------------ACDA------------ -------------AA------------- ---------------------------- ---------------------------- 
--------AAAAAAAAAAAA-------- --------A-AAAAAAAA-A-------- ----------AABBBBAA---------- ----------AABBBBAA---------- ----------AABBBBAA---------- ----------AABBBBAA---------- ----------AABBBBAA---------- ----------AABBBBAA---------- ----------AAABBAAA---------- -----------AABBAA----------- ------------AAAA------------ -------------AA------------- 
------AAAA--------AAAA------ ------AFAA--------AAFA------ -------AAA--AAAA--AAA------- ------------AAAA------------ --------AA--AAAA--AA-------- ------------AAAA------------ --------AA--AAAA--AA-------- ------------AAAA------------ -------------AA------------- -------------AA------------- ---------------------------- ---------------------------- 
-----AAAA-----------AAA----- ------AAA-----------AA------ ------AAA-----------AA------ ---------------------------- ------AAA-----------AA------ ---------------------------- ------AAA-----------AA------ ------A--------------A------ ---------------------------- ---------------------------- ---------------------------- ---------------------------- 
----AAA---------------AA---- -----AA---------------A----- -----AA---------------A----- ---------------------------- -----AA---------------A----- ---------------------------- ----AAA---------------AA---- ----EA----------------AE---- ----EA----------------AE---- ---------------------------- ---------------------------- ---------------------------- 
---AAA-----------------AA--- ----AA-----------------A---- ----AA-----------------A---- ---------------------------- ----AA-----------------A---- ---------------------------- ----AA-----------------A---- ----AA----------------AA---- ----AA----------------AA---- -----A----------------A----- ---------------------------- ---------------------------- 
--AAA-------------------AA-- --AAA-------------------AA-- ---AA-------------------A--- ---------------------------- ---AA-------------------A--- ---------------------------- ---AA-------------------A--- ---A--------------------A--- ---------------------------- ---------------------------- ---------------------------- ---------------------------- 
--AA--------------------AA-- --FA--------------------AF-- --AA--------------------AA-- ---------------------------- ---A--------------------A--- ---------------------------- ---A--------------------A--- ---------------------------- ---------------------------- ---------------------------- ---------------------------- ---------------------------- 
-AAA---------------------AA- -AAA---------------------AA- --AA---------------------A-- ---------------------------- --AA---------------------A-- ---------------------------- --AA---------------------A-- ---------------------------- ---------------------------- ---------------------------- ---------------------------- ---------------------------- 
-AA-----------------------A- --A----------------------A-- --A----------------------A-- ---------------------------- --A----------------------A-- ---------------------------- --A----------------------A-- ---------------------------- ---------------------------- ---------------------------- ---------------------------- ---------------------------- 
AA------------------------AA -A------------------------A- -A------------------------A- -A------------------------A- -A------------------------A- -A------------------------A- -A------------------------A- -A------------------------A- -A------------------------A- ---------------------------- ---------------------------- ---------------------------- 
AA------------------------AA -A------------------------A- -A------------------------A- AA------------------------AA AA------------------------AA AA------------------------AA AA------------------------AA AA------------------------AA -A------------------------A- -A------------------------A- ---------------------------- ---------------------------- 
AA------------------------AA -A------------------------A- ABA----------------------ABA BBA----------------------ABB BBA----------------------ABB BBA----------------------ABB BBA----------------------ABB BBA----------------------ABB AA------------------------AA -A------------------------A- -A------------------------A- ---------------------------- 
AA------------------------AA -A------------------------A- ABA----------------------ABA BBA----------------------ABB BBA----------------------ABB BBA----------------------ABB BBA----------------------ABB BBA----------------------ABB BBA----------------------ABD ABA----------------------ABA -A------------------------A- -A------------------------A- 
AA------------------------AA -A------------------------A- ABA----------------------ABA BBA----------------------ABB BBA----------------------ABB BBA----------------------ABB BBA----------------------ABD DBA----------------------ABB DBA----------------------ABB ABA----------------------ABA -A------------------------A- -A------------------------A- 
AA------------------------AA -A------------------------A- ABA----------------------ABA BBA----------------------ABB BBA----------------------ABB BBA----------------------ABB BBA----------------------ABB DBA----------------------ABB AA------------------------AA -A------------------------A- -A------------------------A- ---------------------------- 
AA------------------------AA -A------------------------A- -A------------------------A- AA------------------------AA AA------------------------AA AA------------------------AA AA------------------------AA AA------------------------AA -A------------------------A- -A------------------------A- ---------------------------- ---------------------------- 
AA------------------------AA -A------------------------A- -A------------------------A- -A------------------------A- -A------------------------A- -A------------------------A- -A------------------------A- -A------------------------A- -A------------------------A- ---------------------------- ---------------------------- ---------------------------- 
-AA----------------------AA- --A----------------------A-- --A----------------------A-- ---------------------------- --A----------------------A-- ---------------------------- --A----------------------A-- ---------------------------- ---------------------------- ---------------------------- ---------------------------- ---------------------------- 
-AA---------------------AAA- -AA---------------------AAA- --A---------------------AA-- ---------------------------- --A---------------------AA-- ---------------------------- --A---------------------AA-- ---------------------------- ---------------------------- ---------------------------- ---------------------------- ---------------------------- 
--AA--------------------AA-- --FA--------------------AF-- --AA--------------------AA-- ---------------------------- ---A--------------------A--- ---------------------------- ---A--------------------A--- ---------------------------- ---------------------------- ---------------------------- ---------------------------- ---------------------------- 
--AA-------------------AAA-- --AA-------------------AAA-- ---A-------------------AA--- ---------------------------- ---A-------------------AA--- ---------------------------- ---A-------------------AA--- ---A--------------------A--- ---------------------------- ---------------------------- ---------------------------- ---------------------------- 
---AA-----------------AAA--- ----A-----------------AA---- ----A-----------------AA---- ---------------------------- ----A-----------------AA---- ---------------------------- ----AA----------------AA---- ----AA----------------AA---- ----AA----------------AA---- -----A----------------A----- ---------------------------- ---------------------------- 
----AA---------------AAA---- -----A---------------AA----- -----A---------------AA----- ---------------------------- -----A---------------AA----- ---------------------------- ----AA---------------AAA---- ----EA----------------AE---- ----EA----------------AE---- ---------------------------- ---------------------------- ---------------------------- 
-----AAA-----------AAAA----- ------AA-----------AAA------ ------AA-----------AAA------ ---------------------------- ------AA-----------AAA------ ---------------------------- ------AA-----------AAA------ ------A--------------A------ ---------------------------- ---------------------------- ---------------------------- ---------------------------- 
------AAAA--------AAAA------ ------AFAA--------AAFA------ -------AAA--AAAA--AAA------- ------------AAAA------------ --------AA--AAAA--AA-------- ------------AAAA------------ --------AA--AAAA--AA-------- ------------AAAA------------ -------------AA------------- -------------AA------------- ---------------------------- ---------------------------- 
--------AAAAAAAAAAAA-------- --------A-AAAAAAAA-A-------- ----------AABBBBAA---------- ----------AABBBBAA---------- ----------AABBBBAA---------- ----------AABBBBAA---------- ----------AABBBBAA---------- ----------AABBBBAA---------- ----------AAABBAAA---------- -----------AABBAA----------- ------------AAAA------------ -------------AA------------- 
----------AAAAAAAA---------- ---------------------------- ------------AAAA------------ -----------ABBBBA----------- -----------ABBBBA----------- -----------ABBBBA----------- -----------ABBDBA----------- -----------ABBDBA----------- ------------ABBA------------ -------------AA------------- ---------------------------- ---------------------------- 
