model
size = 14 28 23, scale = 0.05, origin = -y
material 
  colors = A:#888 B:#FF0 C:#FC9 D:#FFC E:#444 F:#DDD G:#EEE H:#EEC2C2 I:#222 J:#00E K:#111 L:#777 M:#F96
voxels
-------------- -------------- -------------- -------------- -------------- -------------- -------------- -------------- ----CC-------- ---CCCC------- --FC---C------ --FC-C-C------ --FC---C------ --FCCCCC------ ---CCCC------- ----CC-------- -------------- -------------- -------------- -------------- -------------- -------------- -------------- -------------- -------------- -------------- -------------- -------------- 
-------------- -------------- -------------- -------------- -------------- -------------- -------------- ----CC-------- ---CAAC------- --FAAAAC------ -GAACCCAC----- -GAACACAC----- -GAACCCAC----- -GAAAAAAC----- --FAAAAC------ ---CAAC------- ----CC-------- -------------- -------------- -------------- -------------- -------------- -------------- -------------- -------------- -------------- -------------- -------------- 
-------------- -------------- -------------- -------------- -------------- -------------- -------------- ---CCCC------- --FAAAAC------ -EAAAAAACBBB-- -EAAAAAAABBB-- -EAAAAAAABBB-- -EAAAAAAABBB-- -EAAAAAAABBB-- -EAAAAAACBBB-- --FAAAACBBBB-- ---CAACBBBBB-- --K----------- -------B------ ---BB--------- ---BB--------- ------BBB----- -------------- -------------- -------------- -------------- -------------- -------------- 
-------------- -------------- -------------- -------------- -------------- -------------- ----CC-------- --FCAACC------ -GAAAAAAC----- -EAAAAAAABBB-- AAAAAAAAAABB-- AAAAAAAAAABB-- AAAAAAAAAABBB- AAAAAAAAAABB-- -EAAAAAAABBB-- -GAAAAAAABBBB- --IAAAAABBBB-- --KBCCBBB----- ---BBBBBB----- ---BBBBBB----- ---BBBBBB----- ---BBBBBB----- ---BBBBBB----- -----BBBB----- -------------- -------------- -------------- -------------- 
-------------- -------------- -------------- -------------- -------------- -------------- ----CC-------- --FCAACC------ -GAAAAAAC----- -EAAAAAAABB--- AAAAAAAAAAB--- JAAAAAAAAAB--- JAAAAAAAAABB-- AAAAAAAAAABB-- -EAAAAAAABBB-- -GAAAAAAABBB-- --IAAAAABBBB-- --KBAABBBBBBB- ---BBBBBBBBB-- ---BBBBBBBBBB- ---BBBBBBBBB-- --BBBBBBBBBB-- --BBBBBBB----- -----BBBB----- -------------- -----B-------- -------------- -------------- 
-------------- -------------- -------------- -------------- ---DCCC------- ---DCCC------- ---DAAC------- --FAAAAC------ -GAAAAAAC----- -EAAAAAAABB--- AAAAAAAAAAB--- JAAAAAAAAAB--- JAAAAAAAAABB-- AAAAAAAAAABBB- -EAAAAAAABBB-- -GAAAAAAABBB-- --IAAAAABBBB-- ---DAAABBBBB-- ---DAAABBBBB-- ---DAAA--BBB-- -BBBBB---BBBB- -BBBBBBBBBBB-- --BBBBBBBB---- ----BBB------- ----BBB------- ---BBBB------- ----BBB------- ----BBB------- 
-------------- -------------- ---DCCC------- ---DCCC------- ---DAAC------- ---DAAC------- ---DAAC------- --FAAAAC------ -GAAAAAAC----- -EAAAAAAABB--- AAAAAAAAAAB--- AAAAAAAAAAB--- AAAAAAAAAAB--- AAAAAAAAAAB--- -EAAAAAAABB--- -GAAAAAAABBB-- --IAAAAAB--B-- ---DAAABBB-B-- ---DAAABBBB--- ---DAAABBBBB-- -BBDAAABBBBB-- -BBDAAABBBBBB- --BBBB-BBBBBB- ----BBBBBBBBB- ----BBB------- ----BBB------- ----BBB------- ----BBB------- 
-------------- ---DCCC------- ---DAAC------- ---DAAC--BB--- ---DAAAC-BB--- ---DAAAC-BB--- ---DAAAC-BB--- ---DAAAC-BB--- --FAAAAC-BB--- -EAAAAAAABBB-- -EAAAAAAABBB-- -EAAAAAAABB--- -EAAAAAAABBB-- -EAAAAAAABBB-- -EAAAAAAABB--- --FAAAAABBBB-- ---DAAAAB--B-- ---DAAAAB--B-- ---DAAAABBB--- ---DAAAA-BBB-- ---DAAA--BBB-- --BDAAABBBBBBB -BBDAAABBBBBB- -BB-BBBBBBBBB- ----BBBB------ ----BBBB------ ----BBB------- ----BBB------- 
-------BB----- ---DCCCBB----- ----HAABB----- ----HAACBBB--- ---DAAAABBBB-- ---DAAAABBB--- ---DAAAABBB--- ---DAAAC-BB--- ---DAAAC-BB--- --FAAAAABBBB-- -GAAAAAAABBB-- -EAAAAAAABB--- -EAAAAAAABB--- -GAAAAAAABB--- --FAAAAABBB--- ---DAAAABBBBBB ---DAAAABB-B-- ---DAAAABB-BB- ---DAAAA-B-BB- ---DAAAA-BBBB- ---DAAAABBBB-- --BDAAABBBBBB- -BBDAAABBBBBB- -BBBBBBBBBBBB- ---BBBBBB----- ---BBBBBBB---- ----BBB------- ----BBB------- 
---DCCCBB----- ----HAABB----- ----HAAAB----- ---DAAAABBB--- ---DAAAABBB--- -CCLAAAABBB--- ---DAAAABBB--- ---DAAAABBB--- ---DAAAABBBB-- ---DAAAABBB--- --FAAAAABBB--- --EAAAAABBBB-- --EEAAAABBB--- --FAAAAABBB--- ---DAAAABBB--- ---DAAAABBBBBB ---DAAAABBBB-- ---DAAAABBBBB- ---DAAAABBBBB- ---DAAAABBBBB- -BBDAAAABBBB-- -BBDAAAABBBB-- -BBDAAABB----- -BBDAAABB----- -BBBBBBBB----- ---BBBBBB----- -----BB------- -------------- 
---DCCCBB----- ----MAABB----- ----HAAAB----- ---DAAAAB----- ---DAAAAB----- -CCLAAAABB---- -CCLAAAABBB--- -CCLAAAABBB--- ---DAAAABBB--- ---DAAAABBB--- ---DAAABBBB--- ---DAAABBBB--- ---EAAABBBB--- ---DAAABBBB--- ---DAAAABBBB-- ---DAAAABBBB-- ---DAAAABBB--- ---DAAAABBBBB- ---DAAAABBBBBB ---DAAAABBBBB- -BBDAAAA-BBBB- -BBDAAAA-BBBB- --BDAAABB----- -BBDAAAB------ -BBBBBBB------ -----BBB------ ----BBB------- -------------- 
---DCCCBB----- ----MAABB----- ----HAAAB----- ---DAAAABB---- ---DAAAABB---- -CCLAAAABB---- ---DAAAABB---- ---DAAAABB---- ---DAAAABB---- ---DAAAABB---- ---DAAABBB---- ---DAAABBB---- ---EAAABBB---- ---DAAABBB---- ---DAAAABBBB-- ---DAAAABBBB-- ---DAAAABB---- ---DAAAA-BBBB- ---DAAAA-BBBB- ---DAAAABBBBB- -BBDAAAABBBBB- -BBDAAAA-BBBB- --BDAAABBB---- --BDAAABB----- ---BBBBBB----- -----BBB------ -----BB------- -------------- 
---DCCC------- ----HAC------- ----HAACBBBB-- ---DAAAABBBB-- ---DAAAABBBB-- ---DAAAABBBB-- ---DAAAABBBB-- ---DAAAABBBB-- ---DAAAABBBB-- ---DAAAABBBB-- --FAAAAABBBB-- --EAAAAABB---- --EAAAAABBB--- --FAAAAABBB--- ---DAAAABBB--- ---DAAAABBB--- ---DAAAABBB--- ---DAAAABBBB-- ---DAAAABBB--- ---DAAAABBBB-- -BBDAAAABBBBB- -BBDAAAABBBBB- BBBDAAABB----- BBBDAAABB----- ---BBBBBB----- ----BBB------- -----BB------- -------------- 
-------------- ---DCCCB------ ----HAC-BBBB-- ----HAACBBBB-- ---DAAAABBBB-- ---DAAAABBBBB- ---DAAAABBBB-- ---DAAAABBBB-- ---DAAAABBBBB- --FAAAAABBBB-- -GAAAAAAABBB-- -EAAAAAAABB--- -EAAAAAAABB--- -GAAAAAAABB--- --FAAAAABBB--- ---DAAAABBBB-- ---DAAAABBB--- ---DAAAABBBB-- ---DAAAABBBB-- ---DAAAABBBB-- ---DAAAABBBBBB -BBDAAABBBB--- BBBDAAABBBBB-- BBBBBBBB------ -----BBB------ -----BB------- -----BB------- -----B-------- 
-------------- ---DCCC------- ---DAAC-BBBB-- ---DAAC-BBBB-- ---DAAACBBBB-- ---DAAACBBBB-- ---DAAACBBBB-- ---DAAAABBBB-- --FAAAAABBBBB- -EAAAAAAABBB-- -EAAAAAAABBB-- -EAAAAAAABB--- -EAAAAAAABB--- -EAAAAAAABB--- -EAAAAAAABB--- --FAAAAABBB--- ---DAAAABBB--- ---DAAAA--BBB- ---DAAAA--BB-- ---DAAAA--BB-- --BDAAABBBBBB- --BDAAABBBB--- -BBDAAABBBB--- -BBBBBBB------ -----BB------- -----BB------- -----BB------- -------------- 
-------------- -------------- ---DCCC------- ---DCAC------- ---DAAC-BBB--- ---DAAC-BBB--- ---DAAC-BBB--- --FAAAACBBB--- -GAAAAAAABB--- -EAAAAAAABB--- AAAAAAAAAABB-- AAAAAAAAAABB-- AAAAAAAAAABB-- AAAAAAAAAAB--- -EAAAAAAABB--- -GAAAAAAABB--- --IAAAAABBB--- ---DAAABBBBBB- ---DAAABBBBB-- ---DAAABBBBB-- --BDAAABBBBB-- --BDAAABBBB--- --BBBBBBBBB--- -----BB------- -----BB------- -----BB------- -----BB------- -------------- 
-------------- -------------- -------------- -----BB------- ---DCAC-BBB--- ---DCAC-BBB--- ---DAAC-BBBBB- --FAAAACBBBBB- -GAAAAAAABBBB- -EAAAAAAABBB-- AAAAAAAAAABB-- JAAAAAAAAABB-- JAAAAAAAAABB-- AAAAAAAAAABB-- -EAAAAAAABBB-- -GAAAAAAAB---- --IAAAAABB---- ---DAAABBBBB-- ---DAAABBBBB-- ---DAAABBBBB-- --BBBBBBBBBB-- --BBBBBBBBB--- --BBBBBBBBBB-- -----B-BBBBB-- -------------- -------------- -------------- -------------- 
-------------- -------------- -------------- -----BB------- -----BB-BBB--- -----BB-BBB--- ----CABBBBBBB- --FCAAAABBBBB- -GAAAAAAABBBB- -EAAAAAAABBB-- AAAAAAAAAABB-- JAAAAAAAAABB-- JAAAAAAAAABBB- AAAAAAAAAABBB- -EAAAAAAABBBB- -GAAAAAAAB---- --IAAAAABB---- --KBAABBBB---- ---BBBBBBB---- ---BBBBBBB---- ----BBBBBBB--- ----BBBBBBB--- ----BBBBBBB--- ----BBBBB----- -------------- -------------- -------------- -------------- 
-------------- -------------- -------------- -------------- -------------- -------------- ----CCBBB----- --FCAAAAB----- -GAAAAAAAB---- -EAAAAAAABBB-- AAAAAAAAAABBB- AAAAAAAAAABB-- AAAAAAAAAABB-- AAAAAAAAAABB-- -EAAAAAAAB---- -GAAAAAAABB--- --IAAAAAB----- --KBAABBBB---- ---BBBBBBB---- ---BBBBBBB---- ----BBBBB----- ----BBBBB----- ---BBBBBB----- ----BBBBB----- -------------- -------------- -------------- -------------- 
-------------- -------------- -------------- -------------- -------------- -------------- ------BBB----- ---CCCABB----- --FAAAAABB---- -EAAAAAAAB---- -EAAAAAAAB---- -EAAAAAAAB---- -EAAAAAAAB---- -EAAAAAAAB---- -EAAAAAAAB---- --FAAAAABBB--- ---CAACBB----- --K-BBBBB----- ---BBBBBB----- ----BBBBB----- ----BBBBB----- ----BBBBB----- ---BBBBBB----- ----BBBBB----- -------------- -------------- -------------- -------------- 
-------------- -------------- -------------- -------------- -------------- -------------- ------BBB----- ----CCBBB----- ---CAACBB----- --FAAAACB----- -GAACCCAAB---- -GAACACAAB---- -GAACCCAABB--- -GAACAAAAB---- --FAAAAABB---- ---CAACBBBB--- ----CC-BBB---- ----BB-------- ----BB-------- ----BB-------- ---BBB-------- ----BB-------- ----BB-------- ----BB-------- -------------- -------------- -------------- -------------- 
-------------- -------------- -------------- -------------- -------------- -------------- -------------- -------------- ----CC-------- ---CCCC------- --FC---CBB---- --FC-C-CBB---- --FC---CBB---- --FCCCCCBB---- ---CCCCBBB---- ----CC-BBB---- -------BBB---- -------------- -------------- -------------- -------------- -------------- -------------- -------------- -------------- -------------- -------------- -------------- 
-------------- -------------- -------------- -------------- -------------- -------------- -------------- -------------- -------------- -------------- --------BB---- --------BB---- --------BB---- --------BB---- --------BB---- -------------- -------------- -------------- -------------- -------------- -------------- -------------- -------------- -------------- -------------- -------------- -------------- -------------- 
