model
size = 32 32 27, scale = 0.05, origin = -y
material 
  colors = A:#F60 B:#F03 C:#FC0 D:#E00 E:#C60 F:#F63 G:#500
voxels
832-2(5(8B24-)8B856-)5(8B24-)8B387-2(3C29-)3C26-2(6A3C23-)6A3C20-3(3E9A3C17-)2(15A3C14-)15A3C11-3(18A14-)3(3A3-9A17-)13AF19-12AF19-11A2F379-2(3C29-)3C26-2(6A3C23-)6A3C20-3(3E9A3C17-)2(15A3C14-)15A3C11-3(18A14-)3(3A3-9A17-)14AF18-13AF18-12A2F378-2(3C29-)3C26-2(6A3C23-)6A3C20-3(3E9A3C17-)2(15A3C14-)15A3C11-3(18A14-)3(3A3-9A17-)15A2(18-14A)2(11(17-15A)3(17-9A3-3A)17-6A9-15A2-2(6A9-5AD11-)3(3A15-12A2-)3(3A18-9A2-)3(3A15-9A5-)3(3A12-3F14-)12A2EF18-11A2EF18-14A)11(17-15A)3(17-9A3-3A)17-6A9-15A2-2(6A9-5AD11-)3(3A15-12A2-)3(3A18-9A2-)3(3A15-9A5-)3(3A12-3F14-)2(12A2EF17-)15A11(17-3A9-3A)17-3(3A12-3A14-)3A15-12A2-2(3A15-2AD11-)2(3A18-9A2-)3A18-11A25-A3-2(3A29-)3A2(18-14A)18-12A2-3(3A12-3G14-)2(12A2EF17-)15A11(17-3A9-3A)17-3(3A12-3A14-)3A15-12A2-2(3A15-2AD11-)2(3A18-9A2-)3A18-11A29-3A2(30-2A)2(18-14A)18-12A2-3(3A12-3G14-)2(12A2EF17-)15A11(17-3A9-3A)17-3(3A12-3A14-)3A15-12A2-2(3A15-2A9D3-)2(3A18-9A2-)3A18-11A29-3A2(30-2A)2(18-14A)18-12A2-3(3A12-3G14-)2(12A2EF17-)15A3(11(17-3A9-3A)17-3(3A12-6A11-)3A18-9A2(2-3A18-9D)2(2A30-)2A2(26-6A26-A2-3A)3(21-3A3-5A)2(15-6A3-3A3-2A)15-6A3-3A5-12A2EF18-11A2EF18-14A)11(17-3A9-3A)17-3(3A12-3A14-)3A15-12A2-2(3A15-2A9D3-)3A18-9A2-4A17-9A2-3A18-11A25-A3-3A2(30-2A)2(18-14A)18-12A2-3(3A12-3G14-)2(12A2EF17-)15A11(17-3A9-3A)17-3(3A12-3A14-)3A15-12A2-2(3A15-2AD11-)3A18-9A2-4A17-9A2-3A18-11A29-3A2(30-2A)2(18-14A)18-12A2-3(3A12-3G14-)2(12A2EF17-)15A11(17-3A9-3A)17-3(3A12-3A14-)3A15-12A2-2(3A15-2AD11-)2(3A18-9A2-)3A18-11A25-A2-4A2(29-3A)2(18-14A)18-12A2-3(3A12-3G14-)2(12A2EF17-)12(15A17-)3(9A3-3A17-)2(6A9-15A2-2(6A9-5AD11-)3(3A15-12A2-)3(3A18-9A2-)3(3A15-9A5-)3(3A12-3A14-)12A2EF18-11A2EF18-14A11(17-15A)3(17-9A3-3A)17-)6A9-15A2-2(6A9-5AD11-)3(3A15-12A2-)3(3A18-9A2-)3(3A15-9A5-)3(3A12-3A14-)3(12A2EF18-11A2EF18-14A378-2(3C29-)3C26-2(6A3C23-)6A3C20-3(12A3C17-)2(15A3C14-)15A3C11-3(18A14-)3(3A3-9A17-))12A2E19-11A2E19-13A848-2(5(8B24-)8B856-)6(8B24-)
