model
size = 7 32 13, scale = 0.05, origin = -y
material 
  colors = A:#FC0 B:#FC3 C:#FF3 D:#FFF E:#EEE F:#700 G:#400 H:#FF6
voxels
38-A223-C202-C6-C13-C195-C20-B6-C5-3B5-B174-A34-C4-B-A-B3-2AB5-B167-H33-3C2-B2-A2-2(B-)A-A3-BAB5-A160-A2(6-G6-F)5-3C2-B2-A2-B2A-A-2A-4AB3-2AB5-A5(6-D)6-E2(6-D)6-E6-D5(6-E)6(6-D)40-3C2-B2-A2-2(B-)A-B3-2AB5-B195-C4-B-A-B3-BAB5-B202-C5-3B5-A209-2(C223-)A185-
