model
size = 19 6 9, scale = 0.05, origin = -y
material 
  colors = A:#111 B:#555 C:#888
voxels
-----AAAAAAAAAA---- -----BBCBBAAAAA---- ----------BAAAA---- ----------BAAAA---- ------------------- ------------------- 
-AAAAAAAAAAAAAAAA-- -BBCB----------AA-- ---------------AA-- ---------------A--- ----------BAAAA---- ------------------- 
AAAAAAAAAAAAAAAAAA- B---------------AA- ----------------AA- ---------------AA-- ---------------A--- ----------BAAAA---- 
AAAAAAAAAAAAAAAAAAA B----------------AA ----------------AA- ---------------AA-- ---------------A--- ----------CAAAA---- 
AAAAAAAAAAAAAAAAAAA B----------------AA ----------------AA- ---------------AA-- ---------------A--- ----------BAAAA---- 
AAAAAAAAAAAAAAAAAAA C----------------AA ----------------AA- ---------------AA-- ---------------A--- ----------BAAAA---- 
AAAAAAAAAAAAAAAAAA- B---------------AA- ----------------AA- ---------------AA-- ---------------A--- ----------CAAAA---- 
-AAAAAAAAAAAAAAAA-- -BCBB----------AA-- ---------------AA-- ---------------A--- ----------CAAAA---- ------------------- 
-----AAAAAAAAAA---- -----BBCBBAAAAA---- ----------BAAAA---- ----------BAAAA---- ------------------- ------------------- 
