model
size = 19 6 9, scale = 0.05, origin = -y
material 
  colors = A:#111 B:#555
voxels
-----AAAAAAAAAA---- -----BBBBBAAAAA---- ----------BAAAA---- ----------BAAAA---- ------------------- ------------------- 
-AAAAAAAAAAAAAAAA-- -BBBB----------AA-- ---------------AA-- ---------------A--- ----------BAAAA---- ------------------- 
AAAAAAAAAAAAAAAAAA- B---------------AA- ----------------AA- ---------------AA-- ---------------A--- ----------BAAAA---- 
AAAAAAAAAAAAAAAAAAA B----------------AA ----------------AA- ---------------AA-- ---------------A--- ----------BAAAA---- 
AAAAAAAAAAAAAAAAAAA B----------------AA ----------------AA- ---------------AA-- ---------------A--- ----------BAAAA---- 
AAAAAAAAAAAAAAAAAAA B----------------AA ----------------AA- ---------------AA-- ---------------A--- ----------BAAAA---- 
AAAAAAAAAAAAAAAAAA- B---------------AA- ----------------AA- ---------------AA-- ---------------A--- ----------BAAAA---- 
-AAAAAAAAAAAAAAAA-- -BBBB----------AA-- ---------------AA-- ---------------A--- ----------BAAAA---- ------------------- 
-----AAAAAAAAAA---- -----BBBBBAAAAA---- ----------BAAAA---- ----------BAAAA---- ------------------- ------------------- 
