model
size = 13 27 13, scale = 0.05, origin = -y
material 
  colors = A:#6FF B:#CFF C:#DDD D:#E00 E:#EEE F:#BBB
voxels
------------- ------------- ------------- ------------- ----AAAAA---- ----AAAAA---- ----AAAAA---- ----BBBBB---- ----BBBBB---- ----AAAAA---- ----AAAAA---- ----AAAAA---- ----AAAAA---- ----BBBBB---- ----BBBBB---- ----AAAAA---- ----AAAAA---- ------------- ------------- ------------- ------------- ------------- ------------- ------------- ------------- ------------- ------------- 
----AAAAA---- ----BBBBB---- ----BBBBB---- ----AAAAA---- --AABAAABAA-- --AABAAABAA-- --AABAAABAA-- --BBBAAABBB-- --BBBAAABBB-- --AAAAAAAAA-- --AAAAAAAAA-- --AAAAAAAAA-- --AAAAAAAAA-- --BBAAAAABB-- --BBAAAAABB-- --AAABBBAAA-- --AAACCCAAA-- -----CCC----- ------------- ------------- ------------- ------------- ------------- ------------- ------------- ------------- ------E------ 
---AAAAAAA--- ---BBBBBBB--- ---BBBBBBB--- ---ABBBBBA--- -AAAAAAAAAAA- -AAAAAAAAABA- -AAAAAAAAABA- -BBBAAAAAABB- -BBBAAAAAABB- -AAAAAAAAAAA- -AAAAAAAAAAA- -AAAAAAAAAAA- -AAAAAAAAAAA- -BBAAAAAABBB- -BBAAAAAABBB- -ABBBBBBBBAA- -AACCCCCCCAA- ---CCCCCCC--- ------------- ------------- ------------- ------------- ------------- ------------- ------------- ------------- ------D------ 
--AAAAAAAAA-- --BAAAAAABB-- --BAAAAAABB-- --AAAAAAAAA-- -AAAAAAAAAAA- -AAAAAAAAAAA- -AAAAAAAAAAA- -BBBAAAAAAAB- -BBBAAAAAAAB- -AAAAAAAAAAA- -AAAAAAAAAAA- -AAAAAAAAAAA- -AAAAAAAAAAA- -BBAAAAAABBB- -BBAAAAAABBB- -ABBBBBBBBBA- -ACCCCCCCCCA- --CCCCCCCCC-- ------F------ ------------- ------------- ------------- ------------- ------------- ------------- ------------- ------E------ 
-AAAAAAAAAAA- -BBAABBBAAAB- -BBAABBBAAAB- -AAAABBBAAAA- ABAAAAAAAAABA ABAAAAAAAAABA ABAAAAAAAAABA BBAAAAAAAAABB BBAAAAAAAAABB ABAAAAAAAAAAA ABAAAAAAAAAAA ABAAAAAAAAAAA ABAAAAAAAAAAA BBAAAAAAAAABB BBAAAAAAAAABB ABBBBBBBBBBAA AACCCCCCCCCAA --CCCCCCCCC-- ------------- ------------- ------------- ------------- ------------- ------------- ------------- ------------- ------D------ 
-AAAAAAAAAAA- -BBAABBBAAAB- -BBAABBBAAAB- -AAAABBBAAAA- ABAAAAAAAAAAA ABAAAAAAAAAAA ABAAAAAAAAAAA BBAAAAAAAAABB BBAAAAAAAAABB ABAAAAAAAAAAA ABAAAAAAAAAAA ABAAAAAAAAAAA ABAAAAAAAAAAA BBAAAAAAAAABB BBAAAAAAAAABB ABBBBBBBBBBBA ACCCCCCCCCCCA -CCCCCCCCCCC- ---F-----F--- ------------- ------------- ------------- ------------- ------------- ------------- ------------- ------E------ 
-AAAAA-AAAAA- -BBAAB-BAAAB- -BBAAB-BAAAB- -AAAABABAAAA- ABAAAA-AAAAAA ABAAAA-AAAAAA ABAAAA-AAAAAA BBAAAA-AAAABB BBAAAA-AAAABB ABAAAA-AAAAAA ABAAAA-AAAAAA ABAAAA-AAAAAA ABAAAA-AAAAAA BBAAAA-AAAABB BBAAAA-AAAABB ABBBBBBBBBBBA ACCCCC-CCCCCA -CCCCC-CCCCC- ------D------ ------E------ ------D------ ------E------ ------D------ ------E------ ------D------ ------E------ ------D------ 
-AAAAAAAAAAA- -BBAABABAAAB- -BBAABABAAAB- -AAAABBBAAAA- ABAAAAAAAAAAA ABAAAAAAAAAAA ABAAAAAAAAAAA BBAAAAAAAAABB BBAAAAAAAAABB ABAAAAAAAAAAA ABAAAAAAAAAAA ABAAAAAAAAAAA ABAAAAAAAAAAA BBAAAAAAAAABB BBAAAAAAAAABB ABBBBBBBBBBBA ACCCCCCCCCCCA -CCCCCCCCCCC- ------------- ------------- ------------- ------------- ------------- ------------- ------------- ------------- ------------- 
-AAAAAAAAAAA- -BBAABBBAAAB- -BBAABBBAAAB- -AAAABBBAAAA- ABAAAAAAAAABA ABAAAAAAAAABA ABAAAAAAAAABA BBAAAAAAAAABB BBAAAAAAAAABB ABAAAAAAAAAAA ABAAAAAAAAAAA ABAAAAAAAAAAA ABAAAAAAAAAAA BBAAAAAAAAABB BBAAAAAAAAABB ABBBBBBBBBBAA AACCCCCCCCCAA --CCCCCCCCC-- ---F-----F--- ------------- ------------- ------------- ------------- ------------- ------------- ------------- ------------- 
--AAAAAAAAA-- --BBABBBBBB-- --BBABBBBBB-- --AAABBBBBA-- -AAAAAAAAAAA- -AAAAAAAAAAA- -AAAAAAAAAAA- -BBBAAAAAAAB- -BBBAAAAAAAB- -AAAAAAAAAAA- -AAAAAAAAAAA- -AAAAAAAAAAA- -AAAAAAAAAAA- -BBAAAAAAAAB- -BBAAAAAAAAB- -ABBBBBBBBBA- -ACCCCCCCCCA- --CCCCCCCCC-- ------------- ------------- ------------- ------------- ------------- ------------- ------------- ------------- ------------- 
---AAAAAAA--- ---BBBBBBB--- ---BBBBBBB--- ---ABBBBBA--- -AAAAAAAA-AA- -AAAAAAAA-AA- -AAAAAAAA-AA- -BBBAAAAA-AB- -BBBAAAAA-AB- -AAAAAAAA-AA- -AAAAAAAA-AA- -AAAAAAAA-AA- -AAAAAAAA-AA- -BBAAAAAA-BB- -BBAAAAAA-BB- -AABBBBBBBAA- -AACCCCCCCAA- ---CCCCCCC--- ------F------ ------------- ------------- ------------- ------------- ------------- ------------- ------------- ------------- 
----AAAAA---- ----BBBBB---- ----BBBBB---- ----AAAAA---- --AAB---BAA-- --AAB---BAA-- --AAB---BAA-- --BBB---BBB-- --BBB---BBB-- --AAA---AAA-- --AAA---AAA-- --AAA---AAA-- --AAA---AAA-- --BBB---BBB-- --BBB---BBB-- --AAABBBAAA-- --AAACCCAAA-- -----CCC----- ------------- ------------- ------------- ------------- ------------- ------------- ------------- ------------- ------------- 
------------- ------------- ------------- ------------- ----AAAAA---- ----AAAAA---- ----AAAAA---- ----BBBBB---- ----BBBBB---- ----AAAAA---- ----AAAAA---- ----AAAAA---- ----AAAAA---- ----BBBBB---- ----BBBBB---- ----AAAAA---- ----AAAAA---- ------------- ------------- ------------- ------------- ------------- ------------- ------------- ------------- ------------- ------------- 
