model
size = 28 27 27, scale = 0.05, origin = -y
material 
  colors = A:#FFF B:#D2D2D2 C:#FEBFC7 D:#990027 E:#CAD2E9 F:#FF7200
voxels
-----A-A-A-A-A-A-A-A-A------ -----AAAAAAAAAAAAAAAAAAA---- -----AAAAAAAAAAAAAAAAAAA---- ------AAAAAAAAAAAAAAAAA----- -------AAAAAAAAAAAAAA------- ---------AAAAAAAAAAA-------- ------------AAAAA----------- ---------------------------- ---------------------------- ---------------------------- ---------------------------- ---------------------------- ---------------------------- ---------------------------- ---------------------------- ---------------------------- ---------------------------- ---------------------------- ---------------------------- ---------------------------- ---------------------------- ---------------------------- ---------------------------- ---------------------------- ---------------------------- ---------------------------- ---------------------------- 
-----AAAAAAAAAAAAAAAAAAA---- -----AAAAAAAAAAAAAAAAAAA---- -----AAAAAAAAAAAAAAAAAAA---- -----AAAAAAAAAAAAAAAAAAA---- ------AAAAAAAAAAAAAAAAAA---- -------AAAAAAAAAAAAAAAA----- ----------AAAAAAAAA--------- ------------AAAAA----------- ---------------------------- ---------------------------- ---------------------------- ---------------------------- ---------------------------- ---------------------------- ---------------------------- ---------------------------- ---------------------------- ---------------------------- ---------------------------- ---------------------------- ---------------------------- ---------------------------- ---------------------------- ---------------------------- ---------------------------- ---------------------------- ---------------------------- 
----ACCCCCCCCCCCCCCCCCCA---- ----ACCCCCCCCCCCCCCCCAAAA--- ----ACCCCCCCCCCCCCAAAAAAA--- -----ACCCCCCCCCCCCAAAAAAA--- -----AACCCCCCCCCCCAAAAAAA--- ------AAAAAAAAAAAAAAAAAA---- ------AAAAAAAAAAAAA--------- ----------AAAAAAAAAA-------- ---------------------------- ---------------------------- ---------------------------- ---------------------------- ---------------------------- ---------------------------- ---------------------------- ---------------------------- ---------------------------- ---------------------------- ---------------------------- -------------AAAA----------- -----------AAAAAAAA--------- ---------------------------- ---------------------------- ---------------------------- ---------------------------- ---------------------------- ---------------------------- 
---AAAAACCCCCCCCCCCCCCCCAA-- ---AAAAACCCCCCCCCCCCCAAAAAA- ----AAAACCCCCCCCCCAAAAAAAAA- ----AAAACCC----C-CAAAAAAAA-- ----AAAACCCCCCCCCCAAAAAAAA-- -----AAAAAAAAAAAAAAAAAAAA--- -----AAAAAAAAAAAAAAAAAAA---- ---------AAAAAAAAAAAAA------ ---------------------------- ---------------------------- ---------------------------- ---------------------------- ---------------------------- ---------------------------- ---------------------------- ---------------------------- ---------------------------- ---------------------------- --------------AA------------ ----------AAAAAAAAAA-------- ---------AAAAAAAAAAAAA------ ---------------------------- ---------------------------- ---------------------------- ---------------------------- ---------------------------- ---------------------------- 
---AAAAACCCCCCCCCCCCCCCCCCA- --AAAAAACCCCCCCCCCCCCAAAACA- ---AAAAACCCCCCCCCCCCCAAAACAA ---AAAAACCC----C-CCCAAAAAAA- ---AAAAACCCCCCCCCCCCAAAAAAA- ----AAAAAAAAAAAAAAAAAAAAAA-- ----AAAAAAAAAAAAAAAAAAAAA--- -------AAAAAAAAAAAAAAAA----- ---------------------------- ---------------------------- ---------------------------- ---------------------------- ---------------------------- ---------------------------- ---------------------------- ---------------------------- ---------------------------- --------------AA------------ ------------AAAAAA---------- --------AAAAAAAAAAAAAA------ -------AAAAAAAAAAAAAAAA----- ---------------------------- ---------------------------- ---------------------------- ---------------------------- ---------------------------- ---------------------------- 
--AAAAAACCCCCCCCCCCCCCCCCE-- --AAAAAACCCCCCCCCCCCCAAAAEA- --AAAAAACCCCCCCCCCBBCAAAAEAA --AAAAAAEEE----B--BBAAAAAAAA --AAAAAAEEEBBBBBBBBBAAAAAAAA ---AAAAAAAAAAAAAAAAAAAAAAA-- ----AAAAAAAAAAAAAAAAAAAAAA-- ------AAAAAAAAAAAAAAAAAA---- ---------------------------- ---------------------------- ---------------------------- ---------------------------- ---------------------------- ---------------------------- ---------------------------- ---------------------------- ---------------------------- ------------AAAAAA---------- ----------AAAAAAAAAA-------- -------AAAAAAAAAAAAAAAA----- ------AAAAAAAAAAAABAABAA---- ---AAAAAAAAAAAAAAAAAABAAAA-- ---AAAAAAAAAAAAAAAAAAAAAAA-- ---AAAAAAAAAAAAAAAAAAAAAAA-- ---A------------------------ ---------------------------- ---------------------------- 
---AAAAACCCCCCCCCCCCCCCCCEA- --AAAAAACCCCCCCCCCCCCAAAAEAA --AAAAAACCCCCCCCCCBBCAAAAEAA --AAAAAAEEE----B--BBBAAAAAAA --AAAAAAEEEBBBBBBBBBBAAAAAAA ---AAAAAEEEBBBBBBBBBBAAAAAA- ---AAAAAAAAAAABBBBBBBAAAAA-- -----AAAAAAAAABBBBBBBAAAA--- --------AAAAAABBBBBBBA------ ---------AAAAABBBBBBB------- ----------AAAABBBBBB-------- ------------AABBBB---------- ---------------------------- ---------------------------- ---------------------------- ---------------------------- ---------------------------- ----------AAAAAABBBA-------- ---------AAAAAAABBBAA------- ---AAAAAAAAAAAABBBBAABAA---- ---AAAAAAAAAAAAAAABAABAAA--- ---AAAAAAAAAAAAAAAAAABAAAA-- --AAAAAAAAAA-------AABAAAA-- --AAAAAAAAAAAAAAAAAAAAAAAA-- --AAAA---------------------- ---------------------------- ---------------------------- 
--ACCCCCCCCCCCCCCCCCCCCCDDCA --AAAAAACCCCCCCCCCCCCAAAAECA --AAAAAACCCCCCCCCCBBCAAAAECA --AAAAAAEEE-------BBBAAAAAAA --AAAAAAEEEBBBBBBBBBBAAAAAAA ---AAAAAEEEBBBBBBBBBBAAAAAA- ---AAAAAAAAAAABBBBBBBAAAAAA- ----AAAAAAAAAABBBBBBBAAAAA-- --------AAAAAABBBBBBBA------ --------AAAAAABBBBBBBA------ ---------AAAAABBBBBBB------- -----------AAABBBBBB-------- --------------AAB----------- ---------------------------- ---------------------------- ---------------------------- ---------------------------- ---------AAAAAAAAAAAA------- --------AAAAAAAAAAAAAB------ --AAAAAAAAAAAAAAAAAAABAAA--- -AAAAAAAAAAAAAAAAAAAABAAA--- AAAAAAAAAAAAAAAAAAAAABAAAA-- AAAAAAAAAAAA-------AABAAAA-- AAAAAAAA---------------AAA-- -AAAAAAAAAAAAAAAAAAAAAAA---- ------------AAAAAAAAAAAA---- ------------AAAAAAAAAAAA---- 
---CCCCCCCCCCCCCCCCCCCCCDAA- --AAAAAACCCCCCCCCCCCCAAAAAAA --AAAAAACCCCCCCCCCDDCAAAAAAA --AAAAAAEEE----B--DDDAAAAAAA --AAAAAAEEEBBBBBBBBBBAAAAAAA ---AAAAAEEEBBBBBBBBBBAAAAAA- ---AAAAAAAABBBBBBBBBBAAAAAA- ----AAAAAAABBBBBBBBBBAAAAA-- --------AAAAAABBBBBBBA------ --------AAAAAABBBBBBBA------ --------AAAAAABBBBBBBA------ ----------AAAABBBBBBB------- ------------AABBBBB--------- ---------------------------- ---------------------------- ---------------------------- ---------------------------- --------AAAAABAAAAAAAA------ -------AAAAAAAAAAAAAABA----- --AAAAAAAAAAAAAAAAAAABAAA--- AAAAAAAAAAAAAAAAAAAAABAAAA-- AAAAAAAAAAAAAAAAAAAAABAAAA-- AAAAAAAAAAAA-------AABAAAA-- AAAAAAA----------------AAA-- AAAAAAAAAAAAAAAAAAAAAACA---- ------------AAAAAAAAAACA---- ------------AAAAAAAAAAAA---- 
--AAAAAAAAAAAAACCCCCCCDDDAAA --AAAAAAAAAAAAACCCCCCCEEEAAA --AAAAAAAAAAAAACCCCCCCEEEAAA --AAAAAAAAAAAAABBBDDDEEEEAAA --AAAAAAAAAAAAABBBBBBEEEEAAA --AAAAAAAAAAAAABBBBBBEEEEAAA ---AAAAAAAAAAAABBBBBBAAAAAA- ----AAAAAAAAAAABBBBBBAAA---- --------AAAAAAABBBBBBA------ --------AAAAAAABBBBBBA------ --------AAAAAAABBBBBBA------ ---------AABBBBBBBBBB------- -----------AABBBBBBB-------- ---------------AAAA--------- ---------------AAA---------- ---------------AAA---------- ---------------AAA---------- -------AAAAAAAAAAAAAAAA----- ------AAAAAAAAAAAAAAAAAA---- --AAAAAAAAAAAAAAAAAAAAAAAA-- AAAAAAAAAAAAAAAAAAAAAAAAAA-- AAAAAAAAAAAAAAAAAAAAAAAAAA-- AAAAAAAAAAAA---AAAAAAAAAAA-- AAAAAAA--------AAAA----AAA-- AAAAAAAAAAAAAAAAAAAAAAAAAA-- ------------AAAAAAAAAAAAAA-- ------------AAAAAAAAAAAAAA-- 
---AAAAAAAAAAAACCCCCCCCBBBB- --AAAAA-AAAAAAACCCCCCCCBBBBA --AAAAA-AAAAAAACCCCCCCCBBBBA --AAAAAAAAAAAAABBBBBBBBBBBBA --AAAAAAAAAAAAABBBBBBBBBBBBA --AAAAAAAAAAAAABBBBBBBBBBBBA --AAAAAAAAAAAAABBBBBBAAAAAAA ---AAAAAAAAAAAABBBBBBAAA--A- --------AAAAAAABBBBBBA------ --------AAAAAAABBBBBBA------ --------AAAAAAABBBBBBA------ --------AAABBBBBBBBBBA------ ----------AAABBBBBAAA------- -----------AAAAABBA--------- ------------AAAACCA--------- ------------AAAACCA--------- ------------AAAACCA--------- -------AAAAAAAAAAAAAAAA----- ------AAAAAAAAAAAAAAAAAA---- --AAAAAAAAAAAAAAAAAAAAAAAA-- AAAAAAAAAAAAAAAAAAAAAAAAAA-- AAAAAAAAAAAAAAAAAAAAAAAAAA-- AAAAAAAAAAAAAAAAAAAAAAAAAA-- AAAAAAA-AAAAAAAAAAA----AAA-- AAAAAAAAAAAAAAAAAAA----AAA-- ------------AAAAAAA----AAA-- ------------AAAAAAAAAAAAAA-- 
--AAAAAAAAAAAAACCCCCCCAAAAAA --AAAAA-AAAAAAACCCCCCCAAAAAA --AAAAA-AAAAAAACCCCCCCAAAAAA --AAAAAAAAAAAAACCCCCCCAAAAAA --AAAAAAAAAAAAACCCCCCCAAAAAA --AAAAAAAAAAAAACCCCCCCAAAAAA --AAAAAAAAAAAAACCCCCCCAAAAAA ---AAAAAAAAAAAABBBBBBBAA--A- --------AAAAAAABBBBBBA------ --------AAAAAAABBBBBBA------ --------AAAAAAABBBBBBA------ --------AAABBBBBBBBBBA------ ----------AABBBBBBAAA------- -----------ABBBBBBAA-------- -----------ACCCBBCA--------- -----------ACCCCCCA--------- -----------ACCCCCCA--------- ------AAAAAAAAAAAAAAAAAA---- -----AAAAAAAAAAAAAAAAAAAA--- --AAAAAAAAAAAAAAAAAAAAAAAA-- -AAAAAAAAAAAAAAAAAAAAAAAAA-- AAAAAAAAAAAAAAAAAAAAAAAAAA-- AAAAAAAAAAAAAAAAAAAAAAAAAA-- AAAAAAA-AAAAAAAAAAA----AAA-- -AAAAAAAAAAAAAAAAAA----AAA-- ------------AAAAAAA----AAA-- ------------AAAAAAAAAAAAAA-- 
---AAAAAAAAAAAACCCCCCCAAAAA- --AAAAA-AAAAAAACCCCCCCAAAAAA --AAAAA-AAAAAAACCCCCCCAAAAAA --AAAAAAAAAAAAACCCCCCCAAAAAA --AAAAAAAAAAAAACCCCCCCAAAAAA --AAAAAAAAAAAAACCCCCCCAAAAAA --AAAAAAAAAAAAACCCCCCCAAAAAA ---AAAAAAAAAAAABBBBBBBAA--A- --------AAAAAAABBBBBBA------ --------AAAAAAABBBBBBA------ --------AAAAAAABBBBBBA------ --------AAAAABBBBBBBBA------ ----------AAABBBBBBAA------- -----------AABBBBBBA-------- -----------ACCBBBBCA-------- -----------ACCCCCCCA-------- -----------ACCCCCCCA-------- ------AAAAAAAAAAAAAAAAAA---- -----AAAAAAAAAAAAAAAAAAAA--- ---A-ABAAAAAAAAAAAAAAAAAAA-- --AA-ABAAAAAAAAAAAAAAAAAAA-- --AA-ABAAAAAAAAAAAAAAAAAAA-- --AAAABAAAAAAAAAAAAAAAAAAA-- --AAAAB-AAAAAAAAAAAA---AAA-- ---AAAAAAAAAAAAAAAAA---AAA-- ------------AAAAAAAA---AAA-- ------------AAAAAAAAAAAAAA-- 
--AAAAAAAAAAAAACCCCCAAAAAAA- --AAAAAAAAAAAAACCCCCAAAAAAA- --AAAAAAAAAAAAACCCCCAAAAAAA- --AAAAAAAAAAAAACCCCCAAAAAAAA --AAAAAAAAAAAAACCCCCAAAAAAAA --AAAAAAAAAAAAACCCCCAAAAAAAA --AAAAAAAAAAAAACCCCCAAAAAAAA --AAAAAAAAAAAAABBBFBAAAA--AA --------AAAAAAABBBFBAA------ --------AAAAAAABBBFBAA------ --------AAAAAAABBBDBAA------ --------AAAAABBBBBDBAA------ ----------AAABBBBBDAA------- -----------AABBBBBDA-------- -----------ACBBBBBBA-------- -----------ACCCCCCCA-------- -----------ACCCCCCCA-------- -----AAAAAAAAAAAAAAAAAAAA--- -----AAAAAAAAAAAAAAAAAAAAA-- -----ABAAAAAAAAAAAAAAAAAAA-- -----ABAAAAAAAAAAAAAAAAAAA-- -----ABAAAAAAAAAAAAAAAAAAA-- -----ABAAAAAAAAAAAAAAAAAAA-- ----AABAAAAAAAAAAAAAAAAAAA-- ----AAAAAAAAAAAAAAAAAAAAAA-- ------------AAAAAAAAAAAAAA-- ---------------------------- 
---AAAAAAAAAAAACCCCCAAAAAAA- --AAAAAAAAAAAAACCCCCAAAAAAAA --AAAAAAAAAAAAACCCCCAAAAAAAA --AAAAAAAAAAAAACCCCCAAAAAAAA --AAAAAAAAAAAAACCCCCAAAAAAAA --AAAAAAAAAAAAACCCCCAAAAAAAA --AAAAAAAAAAAAACCCCCAAAAAAAA --AAAAAAAAAAAAABBBBBAAAA--AA --------AAAAAAABBBBBAA------ --------AAAAAAABBBBBAA------ --------AAAAAAABBBBAAA------ --------AAAAABBBBBBAAA------ ----------AAABBBBBBAA------- -----------AABBBBBBA-------- -----------ACBBBBBBA-------- -----------ACCCCCCCA-------- -----------ACCCCCCCA-------- -----AAAAAAAAAAAAAAAAAAAA--- -----AAAAAAAAAAAAAAAAAAAAA-- -----ABAAAAAAAAAAAAAAAAAAA-- -----ABAAAAAAAAAAAAAAAAAAA-- -----ABAAAAAAAAAAAAAAAAAAA-- -----ABAAAAAAAAAAAAAAAAAAA-- ----AABAAAAAAAAAAAAAAAAAAA-- ----AAAAAAAAAAAAAAAAAAAAAA-- ------------AAAAAAAAAAAAAA-- ---------------------------- 
--AAAAAAAAAAAAACCCCCAAAAAAAA --AAAAAAAAAAAAACCCCCAAAAAAAA --AAAAAAAAAAAAACCCCCAAAAAAAA --AAAAAAAAAAAAACCCCCAAAAAAAA --AAAAAAAAAAAAACCCCCAAAAAAAA --AAAAAAAAAAAAACCCCCAAAAAAAA --AAAAAAAAAAAAACCCCCAAAAAAAA ---AAAAAAAAAAAABBBBBAAAA--A- --------AAAAAAABBBBBAA------ --------AAAAAAABBBBBAA------ --------AAAAAAABBBBAAA------ --------AAAAABBBBBBAAA------ ----------AAABBBBBBAA------- -----------AABBBBBBA-------- -----------AAAABBBCA-------- -----------AAAACCCCA-------- -----------AAAACCCCA-------- ------AAAAAAAAAAAAAAAAAA---- -----AAAAAAAAAAAAAAAAAAAA--- -----ABAAAAAAAAAAAAAAAAAAA-- ---ABABAAAAAAAAAAAAAAAAAAA-- ---ABBBAAAAAAAAAAAAAAAAAAA-- ---AAABAAAAAAAAAAAAAAAAAAA-- ---AAABAAAAAAAAAAAAAAAAAAA-- ---AAAAAAAAAAAAAAAAAAAAAAA-- ------------AAAAAAAAAAAAAA-- ------------AAAAAAAAAAAAAA-- 
---AAAAAAAAAAAACCCCCCCEEEAA- --AAAAAAAAAAAAACCCCCCCAAAAAA --AAAAAAAAAAAAACCCCCCCAAAAAA --AAAAAAAAAAAAABBBBBDDAAAAAA --AAAAAAAAAAAAABBBBBDDAAAAAA --AAAAAAAAAAAAAAAAABDDAAAAAA --AAAAAAAAAAAAAAAAABADAAAAAA ---AAAAAAAAAAAAAAAABEEAA--A- --------AAAAAAAAAAABEA------ --------AAAAAAAAAAABEA------ --------AAAAAAAAAAAAAA------ --------AAAAAAAAAAAAAA------ ----------AAAAAAAAAAA------- -----------AAAAAAAAA-------- -------------AAAAAA--------- -------------AAAAAA--------- -------------AACCAA--------- ------AAAAAAAAAAAAAAAAAA---- -----AAAAAAAAAAAAAAAAAAAA--- ---AAABAAAAAAAAAAAAAAAAAAA-- -AAAAABAAAAAAAAAAAAAAAAAAA-- AAAAABBAAAAAAAAAAAAAAAAAAA-- AAAAAABAAAAAAAAAAAAAAAAAAA-- AAAAAABAAAAAAAAAAAAAAAAAAA-- -AAAAAAAAAAAAAAAAAAAAAAAAA-- ------------AAAAAAAAAAAAAA-- ------------AAAAAAAAAAAAAA-- 
--AAAAAAAAAAAAAABBBBDDEEEAAA --AAAAAAAAAAAAAABBBBDDAAAAAA --AAAAAAAAAAAAAABBBBDDAAAAAA --AAAAAAAAAAAAAABBBBDDAAAAAA --AAAAAAAAAAAAAABBBBDDAAAAAA --AAAAAAAAAAAAAAAAABDDAAAAAA --AAAAAAAAAAAAAAAAABADAAAAAA ---AAAAAAAAAAAAAAAABEEAA--A- --------AAAAAAAAAAABEA------ --------AAAAAAAAAAABEA------ --------AAAAAAAAAAAAAA------ ---------AAAAAAAAAAAAA------ ----------AAAAAAAAAAA------- ------------AAAAAAA--------- --------------AAA----------- --------------AAA----------- --------------AAA----------- -------AAAAAAAAAAAAAAAA----- -----AAAAAAAAAAAAAAAAAAA---- ---AAABAAAAAAAAAAAAAAAAAAA-- AAAAAABAAAAAAAAAAAAAAAAAAA-- AAAAABBAAAAAAAAAAAAAAAAAAA-- AAAAAABAAAAAAAAAAAAAAAAAAA-- AAAAAABAAAAAAAAAAAAAAAAAAA-- AAAAAAAAAAAAAAAAAAAAAAAAAA-- ------------AAAAAAAAAAAAAA-- ------------AAAAAAAAAAAAAA-- 
---AAAAAAAAAAAAABBBBDDEEEAA- --AAAAAAAAAAAAAABBBBDDAAAAAA --AAAAAAAAAAAAAABBBBDDAAAAAA --AAAAAAAAAAAAAABBBBDDAAAAAA --AAAAAAAAAAAAAABBBBDDAAAAAA --AAAAAAAAAAAAAAAAABDDAAAAAA ---AAAAAAAAAAAAAAAABADAAAAA- ----AAAAAAAAAAAAAAABEEAA---- --------AAAAAAAAAAAAAA------ --------AAAAAAAAAAAAAA------ --------AAAAAAAAAAAAAA------ ----------AAAAAAAAAAAA------ -----------AAAAAAAAA-------- ---------------------------- ---------------------------- ---------------------------- ---------------------------- -------AAAAAAAAAAAAAAAA----- -----AAAAAAAAAAAAAAAAAAA---- --AAAAAAAAAAAAAAAAAAAAAAAA-- AAAAAAAAAAAAAAAAAAAAAAAAAA-- AAAAABAAAAAAAAAAAAAAAAAAAA-- AAAAAAAAAAAAAAAAAAAAAAAAAA-- AAAAAAAAAAAAAAAAAAAAAAAAAA-- AAAAAAAAAAAAAAAAAAAAAAAAAA-- ------------AAAAAAAAAAAAAA-- ------------AAAAAAAAAAAAAA-- 
--AAAAAAAAAAAAAABBBBDDEEEAAA --AAAAAAAAAAAAAABBBBDDAAAAAA --AAAAAAAAAAAAAABBBBDDAAAAAA --AAAAAAAAAAAAAABBBBDDAAAAAA --AAAAAAAAAAAAAABBBBDDAAAAAA ---AAAAAAAAAAAAAAAABDDAAAAA- ---AAAAAAAAAAAAAAAABAAAAAAA- ----AAAAAAAAAAAAAAABEAAA---- --------AAAAAAAAAAAAAA------ --------AAAAAAAAAAAAAA------ --------AAAAAAAAAAAAAA------ ----------AAAAAAAAAAA------- ---------------------------- ---------------------------- ---------------------------- ---------------------------- ---------------------------- --------AAAAAAAAAAAAAA------ -------AAAAAAAAAAAAAAAA----- --AAAAAAAAAAAAAAAAAAAAAAA--- AAAAAAAAAAAAAAAAAAAAAAAAAA-- AAAAABAAAAAAAAAAAAAAAAAAAA-- AAAAAAAAAAAAAAAAAAAAAAAAAA-- AAAAAAAAAAAAAAAAAAAAAAAAAA-- AAAAAAAAAAAAAAAAAAAAAAAAAA-- ------------AAAAAAAAAAAAAA-- ------------AAAAAAAAAAAAAA-- 
---AAAAAAAAAAAAABBBBDDEEEAA- --AAAAAAAAAAAAAABBBBDDAAAAAA --AAAAAAAAAAAAAABBBBDDAAAAAA --AAAAAAAAAAAAAABBBBDDAAAAAA --AAAAAAAAAAAAAABBBBDDAAAAAA ---AAAAAAAAAAAAAAAABDDAAAAA- ---AAAAAAAAAAAAAAAABAAAAAAA- -----AAAAAAAAAAAAAABEAAA---- --------AAAAAAAAAAAAAA------ --------AAAAAAAAAAAAAA------ ---------AAAAAAAAAAAA------- ---------------------------- ---------------------------- ---------------------------- ---------------------------- ---------------------------- ---------------------------- ---------AAAAAAAAAAAA------- --------AAAAAAAAAAAAAA------ ---AAAAAAAAAAAAAAAAAAAAAA--- -AAAAAAAAAAAAAAAAAAAAAAAAA-- AAAAACAAAAAAAAAAAAAAAAAAAA-- AAAAAAAAAAAAAAAAAAAAAAAAAA-- AAAAAAAAAAAAAAAAAAAAAAAAAA-- -AAAAAAAAAAAAAAAAAAAAAAAAA-- ------------AAAAAAAAAAAAAA-- ------------AAAAAAAAAAAAAA-- 
--AAAAAAAAAAAAAABBBBDDEEEAAA --AAAAAAAAAAAAAABBBBDDAAAAAA --AAAAAAAAAAAAAABBBBDDAAAAAA --AAAAAAAAAAAAAABBBBDDAAAAAA --AAAAAAAAAAAAAABBBBDDAAAAAA ---AAAAAAAAAAAAAAAABDDAAAAA- ----AAAAAAAAAAAAAAABEEAAAA-- -----AAAAAAAAAAAAAABEAAA---- --------AAAAAAAAAAAAAA------ ---------AAAAAAAAAAAA------- ---------------------------- ---------------------------- ---------------------------- ---------------------------- ---------------------------- ---------------------------- ---------------------------- ----------AAAAAAAAAA-------- ---------AAAAAAAAAAAA------- ---AA-AAAAAAAAAAAAAAAAAA---- ---AAAAAAAAAAAAAAAAAAAAAA--- ---AAAAAAAAAAAAAAAAAAAAAAA-- --AAAAAAAAAAAAAAAAAAAAAAAA-- --AAAAAAAAAAAAAAAAAAAAAAAA-- --A------------------------- ---------------------------- ---------------------------- 
---AAAAAAAAAAAAABBBBCDEAAA-- --AAAAAAAAAAAAAABBBBCDAAAAA- --AAAAAAAAAAAAAABBBBCDAAAAAA --AAAAAAAAAAAAAABBBBCDAAAAAA --AAAAAAAAAAAAAABBBBCDAAAAAA ----AAAAAAAAAAAAAAABCDAAAA-- ----AAAAAAAAAAAAAAABCEAAAA-- ------AAAAAAAAAAAAABAAAA---- ---------------------------- ---------------------------- ---------------------------- ---------------------------- ---------------------------- ---------------------------- ---------------------------- ---------------------------- ---------------------------- ------------AAAAAA---------- ----------AAAAAAAAAA-------- -------AAAAAAAAAAAAAAAA----- ------AAAAAAAAAAAAAAAAAA---- ---------------------------- ---------------------------- ---------------------------- ---------------------------- ---------------------------- ---------------------------- 
--AAAAAAAAAAAAAABBBBDDEAAA-- --AAAAAAAAAAAAAABBBBDDAAAAA- --AAAAAAAAAAAAAABBBBDDAAAAAA ---AAAAAAAAAAAAABBBBDDAAAAA- ---AAAAAAAAAAAAABBBBADAAAAA- ----AAAAAAAAAAAAAAABADAAAA-- -----AAAAAAAAAAAAAABAEAAA--- -------AAAAAAAAAAAABAAA----- ---------------------------- ---------------------------- ---------------------------- ---------------------------- ---------------------------- ---------------------------- ---------------------------- ---------------------------- ---------------------------- --------------AA------------ ------------AAAAAA---------- --------AAAAAAAAAAAAAA------ -------AAAAAAAAAAAAAAAA----- ---------------------------- ---------------------------- ---------------------------- ---------------------------- ---------------------------- ---------------------------- 
---AAAAAAEAAAAAAAAAAAADAAAA- ---AAAAAAAAAAAAAAAAAAAAAAAA- ---AAAAAAAAAAAAAAAAAAAAAAAA- ----AAAAAAAAAAAAAAAAAAAAAA-- ----AAAAAAAAAAAAAAAAAAAAAA-- -----AAAAAAAAAAAAAAAAAAAA--- ------AAAAAAAAAAAAAAAAAA---- --------AAAAAAAAAAAAAA------ ---------------------------- ---------------------------- ---------------------------- ---------------------------- ---------------------------- ---------------------------- ---------------------------- ---------------------------- ---------------------------- ---------------------------- --------------AA------------ ---------------------------- --------AA------------------ ---------------------------- ---------------------------- ---------------------------- ---------------------------- ---------------------------- ---------------------------- 
----AAAAACAAAAAAAAAAAACAAA-- ----AAAAAAAAAAAAAAAAAAAAAA-- ----AAAAAAAAAAAAAAAAAAAAAA-- -----AAAAAAAAAAAAAAAAAAAA--- -----AAAAAAAAAAAAAAAAAAAA--- -------AAAAAAAAAAAAAAAA----- --------AAAAAAAAAAAAAA------ -----------AAAAAAAA--------- ---------------------------- ---------------------------- ---------------------------- ---------------------------- ---------------------------- ---------------------------- ---------------------------- ---------------------------- ---------------------------- ---------------------------- ---------------------------- ---------------------------- ---------------------------- ---------------------------- ---------------------------- ---------------------------- ---------------------------- ---------------------------- ---------------------------- 
-----A-A-A-A-A-A-A-A-A-A---- -----AAAAAAAAAAAAAAAAAAAA--- -----AAAAAAAAAAAAAAAAAAAA--- ------AAAAAAAAAAAAAAAAAA---- ------AAAAAAAAAAAAAAAAAA---- ----------AAAAAAAAAA-------- -----------AAAAAAAA--------- --------------AA------------ ---------------------------- ---------------------------- ---------------------------- ---------------------------- ---------------------------- ---------------------------- ---------------------------- ---------------------------- ---------------------------- ---------------------------- ---------------------------- ---------------------------- ---------------------------- ---------------------------- ---------------------------- ---------------------------- ---------------------------- ---------------------------- ---------------------------- 
