model
size = 27 18 23, scale = 0.05, origin = -y
material 
  colors = A:#FFAA57 B:#84492C C:#FEAE89 D:#000 E:#A17A43 F:#FEEA41 G:#037C30 H:#A9523A I:#94453E J:#8E695F K:#FFF L:#01512E M:#259A3E N:#FFA5A5
voxels
--------------------------- --------------------------- --------------------------- --------------------------- --------------------------- --------------------------- --------------------------- --------------------------- --------------------------- --------------------------- --------------------------- --------------------------- -------------CC------------ --------------------------- --------------------------- --------------------------- --------------------------- --------------------------- 
--------------------------- --------------------------- --------------------------- --------------------------- --------------------------- --------------------------- --------------------------- --------------------------- --------------------------- -------------AC------------ ---------D---AC------------ ---------D--AAC------------ ---------D--C--C----------- ---------D----------------- ---------D----------------- ---------D----------------- --------------------------- --------------------------- 
--------------------------- --------------------------- --------------------------- --------------------------- --------------------------- --------------------------- --------------------------- --------------------------- -------------AA------------ ----------AAAAA------------ ----------AAAAAAAAAAAAAAAAA ------AAAAAAAABA----------- ------AAAAAACCCC----------- -------AAAAAA-C------------ -------AAAAAA-------------- --------DDD-D-------------- ---------DDD--------------- ---------D----------------- 
--------------------------- --------------------------- --------------------------- --------------------------- --------------------------- ---------------A-A--------- ------AAAAAAAAAAAA--------- -----AAAAAAAAAAAAA--------- -----AAAAAAAAAAAAA--------- ------AAAAAAAAAAAAAAA------ -----AAAAAAAAAAAAAAAA------ -----AAAAAAAAABBCCCCC------ -----AAAABDBCCCCCCCCC------ ------AAAD-BCCC------------ -------ADD-ADAC------------ --------DD-D--------------- -----------D--------------- ---------DD---------------- 
--------------------------- --------------------------- --------------------------- --------------------------- ----------------AAAA------- ------AAAAAAAAAAAAAAAAAAAAA -----AAAAAAAAAAAAAAAAAAAA-- ----AAAAAAAAAAAAAAAAAAAAAAA ----AAAAAAAAAAAAAAAAA------ ---AAAAAAAAAAAAAAAAAAAAAAAA ---AAAAAAAAAAAAAAAAAAA----A -----AAAAAAAAABBCCCCCC----- -----ABBBBBBBBBCCCCCCC----- ------ABBBBBBBBCCCCCCC----- ------CBBBDBBDC----CCC----- ------CCBBDBD-------------- --------DDGGD-------------- --------DDLDD-------------- 
--------------------------- --------------------------- -------------A------------- -----------AAAAAAAAA------- --------AAAAAAAAAAAAAAA---- -----AAAAAAAAAAAAAAA-A----- ----AABBBBBAAAAAAAAA------- ---AAABBBBBAAAAAAAAA------- ---AABBBBBBAAAAAAAAA------- --AAAAAAAAAAAAAAAAAAAA----- --AAAAAAAAAAAAAAAAAAAA----- ---AAAAAAAAAAAFFEEEBCC----- ---AABBFFFFFFFBBBBBBBC----- ----ACBKKKKKKBBBBBBBBC----- -----CBKB--BBDCCCCCCCCC---- -----CCCBBBBGDCCCCCCCC----- ------CCBKGGGD------------- --------DDGGMD------------- 
--------------------------- --------------------------- -----------AAAAAAA--------- ---------AAAAAAAAAAAAAAAAA- -------AAAAAAAA-AAAAAA----- -----AAAAAAAAAAAAAAAAAAAAAA ---AAAAAAAAAAAAAAAAAAA----- --AAABBBBBBAAAAAAAAAAA----- --AAABBBBBBAAAAAAAAAAA----- ---AAAAAAAAAAAAAAAAAAA----- ---AAAAAAAAAAAAAAAAAAAC---- --AAA-AAAAAAAAFJEEEECCC---- --AAABBBBBBBBBBBBBEEECC---- ---AABBBBBBBBBBBBBBBICC---- ----ABBBBBBBBDCCCCCCCCC---- -----CCCBIBBGDCCCCCCCCC---- -----CCCBDGGGDCNCCCCC------ --------D-MLGD--CC--------- 
--------------------------- -----------AAAAAA---------- ----------AAAAAAAAAA------- --------AAAAAAAAAAAAA------ ------AAAAAAAAA-AAAAAA----- -----AAAAAAAAAAAAAAAAC----- ---AAAAAAAAAAAAAAAAAAC----- --AAABBBBBBBBBBBBBBCCC----- --AAABBBBBBBBBBBBBBCCC----- ---ADDDDDDDDDDDDEEEEBC----- ---AADDDDDDDDDDDEEEECCC---- --AAAHFFFFFFFFFJEEEECCC---- --AAABBBBBBBBBBBEEEEECC---- ---AABBBBBBBBBBBBBBIICC---- ----ABBBBBIBBDCCCCCCCCC---- -----CCCBB-BGDCCCCCCCCC---- -----CCCBDGGGDCCCCCCCCC---- --------D-LGLD--CC--------- 
--------------------------- -----------AAAAAA---------- --------AAAAAAAAAAAA------- --------AAAAAAAAAAAAA------ -----AAAAAAAAAA-AAAAAA----- -----AAAAAAAAAAAAAAAAC----- ---AAAAAAAAAAAAAAAAAAC----- --AAABBBBBBBBBBBBBBBBC----- -AAAABBBBBBBBBBBBBBBBC----- --AADDDDDDDDDDDDEEEEEC----- --AAADDDDDDDDDDDEEEECCC---- --AAAHHFFFFFFFJJEEEECCC---- --AAABBBBBBBBBBBEEEEEBC---- ---AABBBBBBBBBBBBBBIIBC---- ----ABBBBBBBBDCCCCCCCCCC--- -----CCCBBBBGDCCCCCCCCCC--- -----CCCBKGGGDCCCCCCCCCC--- --------DDGGGD------------- 
------------A-------------- -----------AAAAAA---------- --------AAAAAAAAAAAA------- -------AAAAAAAAAAAAAA------ -------AAAAAAAA-AAAAAA----- -----AAAAAAAAAAAAAAAAC----- ---AAAAAAAAAAAAAAAAAAC----- --AABBBBBBBBBBBBBBBBBC----- -AAABBBBBBBBBBBBBBBBBC----- -AAADDDDDDDDDDDDEEEEEC----- ---AADDDDDDDDDDDEEEECCC---- --AAAHHFFFFFFFJJEEEECCC---- -AAAABBBBBBBBBBBEEEEEBC---- --AAABBBBBBBBBBBBBBIIBC---- ----ADBBBBBBBDCCCCCCCCCC--- -----CCCBBBBD-CCCCCCCCCC--- -----CCCDDGG-DCCCCCCCCCC--- ---------DMGLD------------- 
--------------AA----------- -----------AAAAAA---------- --------AAAAAAAAAAAA------- --------AAAAAAAAAAAAA------ -------AAAAAAAA-AAAAAA----- -----AAAAAAAAAAAAAAAAC----- ---AAAAAAAAAAAAAAAAAAC----- --AABBBBBBBBBBBBBBBBBC----- -AAABBBBBBBBBBBBBBBBBC----- AAAADDDDDDDDDDDDEEEE-C----- -AAADDDDDDDDDDDDEEEECCC---- -AAAHHHHFFFFFFJJEEEECCC---- AAAAABBBBBBBBBBBEEEEEBC---- -AAAABBBBBBBBBBBBBBIIBC---- ---AADDBBBBBBBCCCCCCCCCC--- -----CCCDDDDDBCCCCCCCCCC--- -----CCCD-DDDBCCCCCCCCCC--- ----------DDDD------------- 
--------------AA----------- ---------A-AAAAAA---------- --------AAAAAAAAAAAA------- --------AAAAAAAAAAAAA------ -------AAAAAAAA-AAAAAA----- -----AAAAAAAAAAAAAAAAC----- ---AAAAAAAAAAAAAAAAAAC----- --AABBBBBBBBBBBBBBBBBC----- -AAABBBBBBBBBBBBBBBBBC----- AAAADDDDDDDDDDDDEEEE-C----- AAAADDDDDDDDDDDDEEEECCC---- -AAAHHHHFFFFFFJJEEEECCC---- AAAAABBBBBBBBBBBEEEEEBC---- -AAAABBBBBBBBBBBBBBIIBC---- ---AADDDD--BBBCCCCCCCCCC--- ----ACCCDDD-DFCCCCCCCCCC--- -----CCCDDDDDBCCCCCCCCCC--- ----------DDDD-CC---N------ 
--------------AA----------- ---------A-AAAAAA---------- --------AAAAAAAAAAAA------- --------AAAAAAAAAAAAA------ -------AAAAAAAA-AAAAAA----- -----AAAAAAAAAAAAAAAAC----- ---AAAAAAAAAAAAAAAAAAC----- --AABBBBBBBBBBBBBBBBBC----- -AAABBBBBBBBBBBBBBBBBC----- AAAADDDDDDDDDDDDEEEEEC----- -AAADDDDDDDDDDDDEEEECCC---- -AAAHHHHFFFFFFJJEEEECCC---- AAAAABBBBBBBBBBBEEEEEBC---- -AAAABBBBBBBBBBBBBBIIBC---- ---AADDDD--BBBCCCCCCCCCC--- ----ACCCDDDDDFCCCCCCCCCC--- -----CCCDDD-DBCCCCCCCCCC--- ----------DD-D-CC---N------ 
--------------------------- -----------AAAAAA---------- --------AAAAAAAAAAAA------- --------AAAAAAAAAAAAA------ -------AAAAAAAA-AAAAAA----- -----AAAAAAAAAAAAAAAAC----- ---AAAAAAAAAAAAAAAAAAC----- --AABBBBBBBBBBBBBBBBBC----- -AAABBBBBBBBBBBBBBBBBC----- AAAADDDDDDDDDDDDEEEB-C----- -AAADDDDDDDDDDDDEEEE-CC---- -AAAHHHHFFFFFFJJEEEE-CC---- AAAAABBBBBBBBBBBEEEE-CC---- -AAAABBBBBBBBBBBBBBI-CC---- ---AADDBBBBBB--CCCCC-CCC--- ----ACCCD-GGGGCCCCCC-CCC--- -----CCCDDGGGGCCCCCCCCCC--- ---------DMGMD------------- 
--------------------------- -----------AAAAAAA--------- --------AAAAAAAAAAAA------- --------AAAAAAAAAAAAA------ -------AAAAAAAA-AAAAAA----- -----AAAAAAAAAAAAAAAAC----- ---AAAAAAAAAAAAAAAAAAC----- --AABBBBBBBBBBBBBBBBBC----- -AAABBBBBBBBBBBBBBBBBC----- -AAADDDDDDDDDDDDEBBB-C----- -AAADDDDDDDDDDDDEEEEBCC---- -AAAHHHHFFFFFFJJEEEEBCC---- AAAAABBBBBBBBBBBEEEEBCC---- -AAAABBBBBBBBBBBBBBIBCC---- ---AADBBBBB--BCCCCCCCCCC--- -----CCCBBGG---CCCCCCCCC--- -----CCCDDGGGGCCCCCCCCCC--- ---------DGLGD------------- 
--------------------------- -----------AAAAAA---------- ---------AAAAAAAAAAA------- --------AAAAAAAAAAAAA------ -------AAAAAAAA-AAAAAA----- -----AAAAAAAAAAAAAAAABA---- ----AAAAAAAAAAAAAAAAAC----- --AABBBBBBBBBBBBBBBBBC----- -AAABBBBBBBBBBBBBBBBBC----- --AADDDDDDDDDDDDEBBB-C----- -AAADDDDDDDDDDDDEEEEBCC---- -AAAHHHHFFFFFFJJEEEEBCC---- -AAAABBBBBBBBBBBEEEEBCC---- --AAABBBBBBBBBBBBBBBBCC---- ----ABBBBBB--BCCCCCCCCCC--- -----CCCBBGGG--CCCCCCCCC--- -----CCCBKGG--CCCCCCCCCC--- --------DDLGMD------------- 
--------------------------- --------------------------- ---------A-AAAAAAA--------- --------AAAAAAAAAAAAAAAAAAA -------AAAAAAAA-AAAAAAA---- -----AAAAAAAAAAAAAAAAAAAAAA ----AAAAAAAAAAAAAAAAAC----- ---ADBBBBBBBBBBBBBBBBC----- --AABBBBBBB----BBBBBBC----- --AADDDDDDDDDDDDBBBBBC----- -AAADDDDDDDDDDDDEEEEECC---- -AAAHHHHFFFFFFFJEEEEECC---- --AAABBBBBBBBBBBEEEEECC---- ---AABBBBBBBBBBBBBBBBCC---- ----ABBBBBB--BCCCCCCCCC---- -----CCCBBGGGG-CCCCCCCC---- -----CCCBDGG-GCCCCCCCCC---- --------DDMGLD--CC--------- 
--------------------------- --------------------------- --------------------------- --------AA-AAAAAAAAAAAA---- --------AAAAAAAAAAAAAAA---- ------AAAAAAAAAAAAAAAA----- -----AAAAAAAAAAAAAAAAA----- ---AABBBBBBBBBBBBBBBAA----- --AABBBBBBB---BBBBBBDDA---- --AADDDDDDDDDDDDBBBBBC----- --AADDDDDDDDDDDDEEEEEEC---- --A-HHHFFFFFFFFJEEEEEEC---- --AABBBBBBBBBBBBEEEEEEC---- ---AABBBBBBBBBBBBBBBBBC---- ----ABBBBBBB-BCCCCCCCCC---- -----CCCBBGGGDCCCCCCCCC---- -----CCCBDGGG-CNCCCCC------ --------DDLGGD--CC--------- 
--------------------------- --------------------------- --------------------------- ---------A-------A-A------- --------AA---AAAAAAA------- ------AAAAAAAAAAAAAAAAAAAAA -----AAAAAAAAAAAAAAA------- ----AABBBBBBBBDAAAAA------- ---AAABBBBB---BB-DDAAAA---- ---AAADDDDDDDDDBBBBAAAAAAAA ---AAADDDDDDDDDDDBDDDDC---- --AAAAHFFFFFFFFFFJJIIIC---- --AABBBBBBBBBBBBBBBIIIC---- ---AABBBBBBBBBBBBBBBBBC---- ----ABBBBBBBBBCCCCCCCCC---- -----CCCBBGGGD------------- ------CCBKGGGD------------- --------DDGMLD------------- 
--------------------------- --------------------------- --------------------------- --------------------------- --------AA----A---A-------- ------AAAAAAAAAAAA--------- -----AAAAAAAAAA------------ ----AAAAAAAAAAA------------ ----AABBBBBBBBAAAAAAAAA---- ---AAADDDDDDDDAAAAAAAAAA--- ---AAADDDDDDDDDDDBDDDDCA--- ---AAABBFFFFFFFFFJJIIICA--- ---ABBBBFFFFFFBBBJJIICC---- ---AABBBKKKKKBBCCCCCCCC---- ----AACBBBBBBDCC----------- ------CCBBBBD-------------- --------DDDDD-------------- --------DDLDD-------------- 
--------------------------- --------------------------- --------------------------- --------------------------- --------------------------- ------------A-------------- ------AAAAAAAA------------- -----AAAAAAAAA------------- ----AAAAAAAAAAAAAA--------- ---AAAAAAAAAAAAAAAAAAAA---- ---AAAAAAAABBBBBCCCCCC-A--- ---AAAAAAAABBCCCCCCCCC-AAAA ---AAAAAAAABCCCCCCCCCC----- ----AAAAAAABCCC----CCC----- -------AAAADDDC------------ --------DDDD--------------- --------------------------- ----------D---------------- 
--------------------------- --------------------------- --------------------------- --------------------------- --------------------------- --------------------------- --------------------------- --------------------------- ------A-ADA---------------- ----AAAAADAAAAAAAAAAAAAAAA- ----AAAAADAACCCC----------- --------ADAAC--C----------- --------ADAAC--C----------- --------ADAA--------------- --------ADA---------------- --------DDDD--------------- --------------------------- --------------------------- 
--------------------------- --------------------------- --------------------------- --------------------------- --------------------------- --------------------------- --------------------------- --------------------------- --------------------------- ------A-ADA---------------- ---------DA---------------- --------ADA---------------- ---------DA--CC------------ ---------DA---------------- ---------D----------------- ---------D----------------- --------------------------- --------------------------- 
