model
size = 27 18 23, scale = 0.05, origin = -y
material 
  colors = A:#84492C B:#000 C:#FEAE89 D:#A17A43 E:#FEEA41 F:#037C30 G:#A9523A H:#94453E I:#8E695F J:#FFF K:#01512E L:#259A3E M:#1E1729 N:#FFA5A5
voxels
--------------------------- --------------------------- --------------------------- --------------------------- --------------------------- --------------------------- --------------------------- --------------------------- --------------------------- --------------------------- --------------------------- --------------------------- -------------CC------------ --------------------------- --------------------------- --------------------------- --------------------------- --------------------------- 
--------------------------- --------------------------- --------------------------- --------------------------- --------------------------- --------------------------- --------------------------- --------------------------- --------------------------- -------------CC------------ -------------CC------------ ------------CCC------------ ------------C--C----------- --------------------------- --------------------------- --------------------------- --------------------------- --------------------------- 
--------------------------- --------------------------- --------------------------- --------------------------- --------------------------- --------------------------- --------------------------- --------------------------- -------------BB------------ ----------BBBAC------------ ----------BBBAABBBBBBBBBB-- ------BBBBBBBAAB----------- ------BBBBBBCCCC----------- -------BBBBBC-C------------ -------BBBB-B-------------- --------B-B-B-------------- ---------BBB--------------- ---------B----------------- 
--------------------------- --------------------------- --------------------------- --------------------------- --------------------------- ---------------B-B--------- ------BBBBBBBBBBBB--------- -----BBBBBBBBBBBBB--------- -----BBBBBBBBBBBBB--------- ------BBBBBBAAACCBBBB------ -----BBBBBBBAAAAAAAAC------ -----BAAAAAAAAAACCCCC------ -----BAAAABACCCCCCCCC------ ------BAAB-ACCC----CC------ -------BBB-BBBC-----C------ --------BB-B--------------- -----------B--------------- ---------BB---------------- 
--------------------------- --------------------------- --------------------------- --------------------------- ----------------BBBB------- ------BBBBBBBBBBBBBBBBBBBBB -----BAAAAAAAAAAAABBBBBBB-- ----BAAAAAAAAAAAAABB------- ----BAAAAAAAAAAAAABBB------ ---BBBABBBBBBBBBDAAAABBBBB- ---BBBABBBBBBBBBDDDDCC----- -----BAAAAAAAAAACCCCCC----- -----BAAAAAAAAACCCCCCC----- ------AAAAAAAAACCCCCCC----- ------CAAABAABC----CCC----- ------CCAABAB-------------- --------BBFFB-------------- --------BBKBB-------------- 
--------------------------- --------------------------- -------------B------------- -----------BBBBBBBBB------- --------BBBBBBBBAAAABBB---- -----BBBAAAAAAAAAAAA-B----- ----BAAAAAAAAAAAAAAC------- ---BAAAAAAAAAAAAAAAC------- ---BAAAAAAAAAAAAAAAC------- --BABAABBBBBBBBBDDAAAC----- --BABAABBBBBBBBBDDDACC----- ---BBAAEEEEEEEEEDDDACC----- ---BBAAEEEEEEEAAAAAAAC----- ----BCAJJJJJJAAAAAAAAC----- -----CAJA--AABCCCCCCCCC---- -----CCCAAAAFBCCCCCCCC----- ------CCAJFFFB------------- --------BBFFLB------------- 
--------------------------- --------------------------- -----------BBBBBBB--------- ---------BBAAAAAAABBB------ -------BBAAAAAA-AAAAAB----- -----BBAAAAAAAAAAAAAAABBBBB ---BBAAAAAAAAAAAAAACCC----- --BAAAAAAAAAAAAAAAACCC----- --BAAAAAAAAAAAAAAAACCC----- ---BBBBBBBBBBBBBDDDAAC----- ---BBBBBBBBBBBBBDDDDCCC---- --BGG-EEEEEEEEEIDDDDCCCC--- --BAAAAAAAAAAAAAAADDDC----- ---BAAAAAAAAAAAAAAAAHC----- ----BAAAAAAAABCCCCCCCCC---- -----CCCAHAAFBCCCCCCCCC---- -----CCCABFFFBCNCC--------- --------B-LKFB------------- 
--------------------------- -----------BBBBBB---------- ----------BAAAAAABBB------- --------BBAAAAAAAAAAB------ ------BBAAAAAAA-AAAAAB----- -----BBAAAAAAAAAAAAAAC----- ---BBAAAAAAAAAAAAAACCC----- --BAAAAAAAAAAAAAAAACCC----- --BAAAAAAAAAAAAAAAACCC----- ---BBBBBBBBBBBBBDDDDAC----- ---BBBBBBBBBBBBBDDDDCCCC--- --BGGGEEEEEEEEEIDDDDCCCC--- --BAAAAAAAAAAAAADDDDDCCC--- ---BAAAAAAAAAAAAAAAHHCCC--- ----BAAAAAHAABCCCCCCCCC---- -----CCCAA-AFBCCCCCCCCC---- -----CCCABFFFBCCCCCCCCC---- --------B-KFKB------------- 
--------------------------- -----------BBBBBB---------- --------BBBAAAAAABBB------- --------BBAAAAAAAAAAB------ -----BBBAAAAAAA-AAAAAB----- -----BBAAAAAAAAAAAAAAC----- ---BBAAAAAAAAAAAAAAAAC----- --BAAAAAAAAAAAAAAAAAAC----- -BAAAAAAAAAAAAAAAAAAAC----- --BBBBBBBBBBBBBBDDDDDC----- --BBBBBBBBBBBBBBDDDDCCCCC-- --BGGGGEEEEEEEIIDDDDCCCCC-- --BAAAAAAAAAAAAADDDDDACCC-- ---BAAAAAAAAAAAAAAAHHACCC-- ----BAAAAAAAABCCCCCCCCCCC-- -----CCCAAAAFBCCCCCCCCCCC-- -----CCCAJFFFBCCCCCCCCCC--- --------BBFFFB------------- 
------------B-------------- -----------BBBBBB---------- --------BBBAAAAAABBB------- -------BBBAAAAAAAAAAB------ -------BAAAAAAA-AAAAAB----- -----BBAAAAAAAAAAAAAAC----- ---BBAAAAAAAAAAAAAAAAC----- --BAAAAAAAAAAAAAAAAAAC----- -BAAAAAAAAAAAAAAAAAAAC----- -BBBBBBBBBBBBBBBDDDDDC----- ---BBBBBBBBBBBBBDDDDCCCCCC- --BGGGGEEEEEEEIIDDDDCCCCCC- -BAAAAAAAAAAAAAADDDDDAAAAC- --BBAAAAAAAAAAAAAAAHHAACC-- ----BBAAAAAAABCCCCCCCCCCC-- -----CCCAAAAB-CCCCCCCCCCC-- -----CCCBBFF-BCCCCCCCCCCC-- ---------BLFKB------------- 
--------------BB----------- -----------BBBAAB---------- --------BBBAAAAAABBB------- --------BBAAAAAAAAAAB------ -------BAAAAAAA-AAAAAB----- -----BBAAAAAAAAAAAAAAC----- ---BBAAAAAAAAAAAAAAAAC----- --BAAAAAAAAAAAAAAAAAACC---- -BAAAAAAAAAAAAAAAAAAACC---- BBBBBBBBBBBBBBBBDDDD-CC---- -BBBBBBBBBBBBBBBDDDDCCCCCC- -BGGGGGGEEEEEEIIDDDDCCCCCC- BAAAAAAAAAAAAAAADDDDDAAAAC- -BBBAAAAAAAAAAAAAAAHHAACCC- ---BBBBAAAAAAACCCCCCCCCCCC- -----CCCBBBBBACCCCCCCCCCC-- -----CCCB-BBBACCCCCCCCCCC-- ----------BBBB------------- 
--------------BB----------- ---------B-BBBAAB---------- --------BBBAAAAAABBB------- --------BBAAAAAAAAAAB------ -------BAAAAAAA-AAAAAB----- -----BBAAAAAAAAAAAAAAC----- ---BBAAAAAAAAAAAAAAAAC----- --BAAAAAAAAAAAAAAAAAACC---- -BAAAAAAAAAAAAAAAAAAACC---- BBBBBBBBBBBBBBBBDDDD-CC---- BGBBBBBBBBBBBBBBDDDDCCCCCC- -BGGGGGGEEEEEEIIDDDDCCCCCC- BAAAAAAAAAAAAAAADDDDDAAAAC- -BBBAAAAAAAAAAAAAAAHHAACCC- ---BBBBBB--AAACCCCCCCCCCCC- ----BCCCBBB-BECCCCCCCCCCCC- -----CCC-BBBBACCCCCCCCCCC-- ---------BBBBBCCC---C------ 
--------------BB----------- ---------B-BBBAAB---------- --------BBBAAAAAABBB------- --------BBAAAAAAAAAAB------ -------BAAAAAAA-AAAAAB----- -----BBAAAAAAAAAAAAAAC----- ---BBAAAAAAAAAAAAAAAAC----- --BAAAAAAAAAAAAAAAAAACC---- -BAAAAAAAAAAAAAAAAAAACC---- BBBBBBBBBBBBBBBBDDDDDCC---- -BBBBBBBBBBBBBBBDDDDCCCCCC- -BGGGGGGEEEEEEIIDDDDCCCCCC- BAAAAAAAAAAAAAAADDDDDAAAAC- -BBBAAAAAAAAAAAAAAAHHAAAAC- ---BBBBBB--AAACCCCCCCCCCCC- ----BCCC-BBBBECCCCCCCCCCCC- -----CCC-BB-BACCCCCCCCCCC-- ---------BBB-BCCC---C------ 
--------------------------- -----------BBBBBB---------- --------BBBAAAAAABBB------- --------BBAAAAAAAAAAB------ -------BAAAAAAA-AAAAAB----- -----BBAAAAAAAAAAAAAAC----- ---BBAAAAAAAAAAAAAAAAC----- --BAAAAAAAAAAAAAAAAAACC---- -BAAAAAAAAAAAAAAAAAAACC---- BBBBBBBBBBBBBBBBDDDA-CC---- -BBBBBBBBBBBBBBBDDDD-CCCCC- -BGGGGGGEEEEEEIIDDDD-CCCCC- BAAAAAAAAAAAAAAADDDD-CCCCC- -BBBAAAAAAAAAAAAAAAH-CCCCC- ---BBBBAAAAAA--CCCCC-CCCCC- ----BCCCB-FFFFCCCCCC-CCCCC- -----CCC-BFFFFCCCCCCCCCCC-- ---------BLFLB------------- 
--------------------------- -----------BBBBBB---------- --------BBBAAAAAABBB------- --------BBAAAAAAAAAAB------ -------BAAAAAAA-AAAAAB----- -----BBAAAAAAAAAAAAAAA----- ---BBAAAAAAAAAAAAAAAAC----- --BAAAAAAAAAAAAAAAAAAC----- -BAAAAAAAAAAAAAAAAAAAC----- -BBBBBBBBBBBBBBBDAAA-C----- -BBBBBBBBBBBBBBBDDDDACCCCC- -BGGGGGGEEEEEEIIDDDDACCCCC- BAAAAAAAAAAAAAAADDDDACCCCC- -BBBAAAAAAAAAAAAAAAHACCCCC- ---BBBAAAAA--ACCCCCCCCCCCC- -----CCCAAFF---CCCCCCCCCC-- -----CCCBBFFFFCCCCCCCCCCC-- ---------BFKFB------------- 
--------------------------- -----------BBBBBB---------- ---------BBAAAAAABBB------- --------BBAAAAAAAAAAB------ -------BBAAAAAA-AAAAAB----- -----BBAAAAAAAAAAAAAAABBBBB ----BAAAAAAAAAAAAAAAAC----- --BBAAAAAAAAAAAAAAAAAC----- -BAAAAAAAAAAAAAAAAAAAC----- --BBBBBBBBBBBBBBDAAA-C----- -BBBBBBBBBBBBBBBDDDDACCCCC- -BGGGGGGEEEEEEIIDDDDACCCCC- -BAAAAAAAAAAAAAADDDDACCCCC- --BBAAAAAAAAAAAAAAAAACCCC-- ----BAAAAAA--ACCCCCCCCCCC-- -----CCCAAFFF--CCCCCCCCCC-- -----CCCAJFF--CCCCCCCCCC--- --------BBKFLB------------- 
--------------------------- --------------------------- ---------B-BBBBBBB--------- --------BBBAAAAAAABBB------ -------BBAAAAAA-AAAAABB---- -----BBAAAAAAAAAAAAAAABBBBB ----BAAAAAAAAAAAAAAAAC----- ---BBAAAAAAAAAAAAAAAAC----- --BAAAAAAAA----AAAAAAC----- --BBBBBBBBBBBBBBAAAAAC----- -BBBBBBBBBBBBBBBDDDDDCCC--- -BGGGGGGEEEEEEEIDDDDDCCC--- --BAAAAAAAAAAAAADDDDDCCC--- ---BAAAAAAAAAAAAAAAAACCC--- ----BAAAAAA--ACCCCCCCCCC--- -----CCCAAFFFF-CCCCCCCCC--- -----CCCABFF-FCCCCCCCCCC--- --------BBLFKB------------- 
--------------------------- --------------------------- --------------------------- --------BB-BBBBBBBBBBBB---- --------BBBBBBBBAAAABBB---- ------BBAAABBBAAAAAABB----- -----BAAAAAAAAAAAAAABB----- ---BBAAAAAAAAAAAAAAABB----- --BAAAAAAAA---AAAAAABBB---- --BBBBBBBBBBBBBBAAAAAAAB--- --BBBBBBBBBBBBBBDDDDDDAB--- --B-GGGEEEEEEEEIDDDDDDAB--- --BAAAAAAAAAAAAADDDDDDDC--- ---BAAAAAAAAAAAAAAAAAAAC--- ----BAAAAAAA-ACCCCCCCCCC--- -----CCCAAFFFBCCCCCCCCC---- -----CCCABFFF-CNCC--------- --------BBKFFB------------- 
--------------------------- --------------------------- --------------------------- ---------B-------B-B------- --------BB---BBBBBBB------- ------BBBBBBBBAAABBBBBBBBBB -----BAAAAAAAABBBBBB------- ----BAAAAAAAAABBBBBB------- ---BAAAAAAA---AA-BBBBBB---- ---BBBBBBBBBBBBAAAAAAAABBBB ---BBBBBBBBBBBBBBABBBBABB-- --BGGGGEEEEEEEEEEIIHHHABB-- --BAAAAAAAAAAAAAAAAHHHAB--- ---BAAAAAAAAAAAAAAAAAAAC--- ----BAAAAAAAAACCCCCCCCC---- -----CCCAAFFFB------------- ------CCAJFFFB------------- --------BBFLKB------------- 
--------------------------- --------------------------- --------------------------- --------------------------- --------BB----B---B-------- ------BBBBBBBBBBBB--------- -----BAAAAAAAAB------------ ----BAAAAAAAAAB------------ ----BAAAAAAAAAABBBBBBBB---- ---BBBBBBBBBBBBAAAAAAACB--- ---BBBBBBBBBBBBBBABBBBCB--- ---BGGAAEEEEEEEEEIIHHHCB--- ---BAAAAEEEEEEAAAIIHHCC---- ---BAAAAJJJJJAACCCCAACC---- ----BBCAAAAAABCC---CC------ ------CCAAAAB-------------- --------BBBBB-------------- --------BBKBB-------------- 
--------------------------- --------------------------- --------------------------- --------------------------- --------------------------- ------------B-------------- ------BBBBBBBB------------- -----BBBBBBBBB------------- ----BBABBBABBBBBBB--------- ---BAABAAABAAAAAAABBBBC---- ---BAAAAAAAAAAAACCCCCC-B--- ---BBBBBAAAAACCCCCCCCC-BBBB ---BBBBBAAAACCCCCCCCCC----- ----BBBBAAAACCC----CCC----- -------CAAABBBC-----C------ --------BBBB--------------- --------------------------- ----------B---------------- 
--------------------------- --------------------------- --------------------------- --------------------------- --------------------------- --------------------------- --------------------------- --------------------------- ------B-BBB---------------- ----BBABAAABBBBBBBBBBBBBBB- ----BBBBBBMBCCCC----------- --------MBBBC--C----------- --------BBBBC--C----------- --------BBBB--------------- --------BBB---------------- --------BBBB--------------- --------------------------- --------------------------- 
--------------------------- --------------------------- --------------------------- --------------------------- --------------------------- --------------------------- --------------------------- --------------------------- --------------------------- ------B-BBB---------------- ----------B---------------- --------B-B---------------- -------------CC------------ --------------------------- ----------B---------------- ----------B---------------- --------------------------- --------------------------- 
