model
size = 27 19 23, scale = 0.05, origin = -y
material 
  colors = A:#84492C B:#000 C:#A17A43 D:#FEEA41 E:#037C30 F:#A9523A G:#94453E H:#8E695F I:#FFF J:#01512E K:#259A3E L:#1E1729 M:#BA5F42
voxels
--------------------------- --------------------------- --------------------------- --------------------------- --------------------------- --------------------------- --------------------------- --------------------------- --------------------------- --------------------------- --------------------------- --------------------------- -------------AA------------ --------------------------- --------------------------- --------------------------- --------------------------- --------------------------- --------------------------- 
--------------------------- --------------------------- --------------------------- --------------------------- --------------------------- --------------------------- --------------------------- --------------------------- --------------------------- -------------AA------------ -------------AA------------ ------------AAA------------ ------------A--A----------- --------------------------- --------------------------- --------------------------- --------------------------- --------------------------- --------------------------- 
--------------------------- --------------------------- --------------------------- --------------------------- --------------------------- --------------------------- --------------------------- --------------------------- -------------BB------------ ----------BBBAA------------ ----------BBBAABBBBBBBBBB-- ------BBBBBBBAAB----------- ------BBBBBBBAAA----------- -------BBBBBA-A------------ -------BBBB-B-------------- --------B---B-------------- ---------BBB--------------- ---------B----------------- --------------------------- 
--------------------------- --------------------------- --------------------------- --------------------------- --------------------------- ---------------B-B--------- ------BBBBBBBBBBBB--------- -----BBBBBBBBBBBBB--------- -----BBBBBBBBBBBBB--------- ------BBBBBBAAAAABBBB------ -----BBBBBBBAAAAAAAAA------ -----BAAAAAAAAAAAAAAA------ -----BAAAABAAAAAAAAAA------ ------BAAB-AAAA----AA------ -------BBB-BBBA-----A------ --------BB-B--------------- -----------B--------------- ---------BB---------------- --------------------------- 
--------------------------- --------------------------- --------------------------- --------------------------- ----------------BBBB------- ------BBBBBBBBBBBBBBBBBBBBB -----BAAAAAAAAAAAABBBBBBB-- ----BAAAAAAAAAAAAABB------- ----BAAAAAAAAAAAAABBB------ ---BBBABBBBBBBBBCAAAABBBBB- ---BBBABBBBBBBBBCCCCCA----- -----BAAAAAAAAAACCCCCA----- -----BAAAAAAAAAAAAAACA----- ------AAAAAAAAAAAAAAGA----- ------AAAABAABA----AAA----- ------AAAABAB-------------- --------BBEEB-------------- --------BBJEB-------------- --------------------------- 
--------------------------- --------------------------- -------------B------------- -----------BBBBBBBBB------- --------BBBBBBBBAAAABBB---- -----BBBAAAAAAAAAAAA-B----- ----BAAAAAAAAAAAAAAA------- ---BAAAAAAAAAAAAAAAA------- ---BAAAAAAAAAAAAAAAA------- --BABAABBBBBBBBBCCAAAA----- --BABAABBBBBBBBBCCCAAA----- ---BBAADDDDDDDDDCCCAAA----- ---BBAADDDDDDDAAAAAAAA----- ----BAAIIIIIIAAAAAAAAA----- -----AAIA--AABAAAAAAAAA---- -----AAAAAAAEBAAAAAAAA----- ------AAAIEEEB------------- --------BBEEKB------------- --------------------------- 
--------------------------- --------------------------- -----------BBBBBBB--------- ---------BBAAAAAAABBB------ -------BBAAAAAA-AAAAAB----- -----BBAAAAAAAAAAAAAAABBBBB ---BBAAAAAAAAAAAAAAAAA----- --BAAAAAAAAAAAAAAAAAAA----- --BAAAAAAAAAAAAAAAAAAA----- ---BBBBBBBBBBBBBCCCAAAA---- ---BBBBBBBBBBBBBCCCCCAA---- --BFF-DDDDDDDDDHCCCCCAAA--- --BAAAAAAAAAAAAAAACCCA----- ---BAAAAAAAAAAAAAAAAGA----- ----BAAAAAAAABAAAAAAAAA---- -----AAAAGAAEBAAAAAAAAA---- -----AAAABEEEBAAMA--------- --------B-KJEB------------- --------------------------- 
--------------------------- -----------BBBBBB---------- ----------BAAAAAABBB------- --------BBAAAAAAAAAAB------ ------BBAAAAAAA-AAAAAB----- -----BBAAAAAAAAAAAAAAA----- ---BBAAAAAAAAAAAAAAAAA----- --BAAAAAAAAAAAAAAAAAAA----- --BAAAAAAAAAAAAAAAAAAA----- ---BBBBBBBBBBBBBCCCCAAAA--- ---BBBBBBBBBBBBBCCCCCAAA--- --BFFFDDDDDDDDDHCCCCCAAA--- --BAAAAAAAAAAAAACCCCCAAA--- ---BAAAAAAAAAAAAAAAGGAAA--- ----BAAAAAGAABAAAAAAAAA---- -----AAAAA-AEBBAAAAAAAA---- -----AAAABEEEBAAAAAAAAA---- --------B-JEJB------------- --------------------------- 
--------------------------- -----------BBBBBB---------- --------BBBAAAAAABBB------- --------BBAAAAAAAAAAB------ -----BBBAAAAAAA-AAAAAB----- -----BBAAAAAAAAAAAAAAA----- ---BBAAAAAAAAAAAAAAAAA----- --BAAAAAAAAAAAAAAAAAAA----- -BAAAAAAAAAAAAAAAAAAAA----- --BBBBBBBBBBBBBBCCCCCAAAA-- --BBBBBBBBBBBBBBCCCCCAAAA-- --BFFFFDDDDDDDHHCCCCCAAAA-- --BAAAAAAAAAAAAACCCCCAAAA-- ---BAAAAAAAAAAAAAAAGGAAAA-- ----BAAAAAAAABAAAAAAAAAAA-- -----BAAAAAAEBEAAAAAAAAAA-- -----AAAAIEEEBAAAAAAAAAA--- --------BBEEEB------------- --------------------------- 
------------B-------------- -----------BBBBBB---------- --------BBBAAAAAABBB------- -------BBBAAAAAAAAAAB------ -------BAAAAAAA-AAAAAB----- -----BBAAAAAAAAAAAAAAA----- ---BBAAAAAAAAAAAAAAAAA----- --BAAAAAAAAAAAAAAAAAAAA---- -BAAAAAAAAAAAAAAAAAAAAA---- -BBBBBBBBBBBBBBBCCCCCAAAA-- ---BBBBBBBBBBBBBCCCCCAAAAA- --BFFFFDDDDDDDHHCCCCCAAAAA- -BAAAAAAAAAAAAAACCCCCAAAAA- --BBAAAAAAAAAAAAAAAGGAAAA-- ----BBAAAAAAABAAAAAAAAAAA-- -----AAAAAAAB-BAAAHGGGAAA-- -----AAABBEE-BAAAAAAAAAAA-- ---------BKEJB------------- --------------------------- 
--------------BB----------- -----------BBBAAB---------- --------BBBAAAAAABBB------- --------BBAAAAAAAAAAB------ -------BAAAAAAA-AAAAAB----- -----BBAAAAAAAAAAAAAAA----- ---BBAAAAAAAAAAAAAAAAA----- --BAAAAAAAAAAAAAAAAAAAA---- -BAAAAAAAAAAAAAAAAAAAAA---- BBBBBBBBBBBBBBBBCCCC-AAAA-- -BBBBBBBBBBBBBBBCCCCCAAAAA- -BFFFFFFDDDDDDHHCCCCCAAAAA- BAAAAAAAAAAAAAAACCCCCAAAAA- -BBBAAAAAAAAAAAAAAAGGAAAAA- ---BBBBAAAAAAAAAAAAAAAAAAA- -----AAABBBBBAAAAHHGGGAAA-- -----AAAB-BBBAAAAAAAAAAAA-- ----------BBBBA-----A------ --------------------------- 
--------------BB----------- ---------B-BBBAAB---------- --------BBBAAAAAABBB------- --------BBAAAAAAAAAAB------ -------BAAAAAAA-AAAAAB----- -----BBAAAAAAAAAAAAAAA----- ---BBAAAAAAAAAAAAAAAAA----- --BAAAAAAAAAAAAAAAAAAAA---- -BAAAAAAAAAAAAAAAAAAAAA---- BBBBBBBBBBBBBBBBCCCC-AAAA-- BFBBBBBBBBBBBBBBCCCCCAAAAA- -BFFFFFFDDDDDDHHCCCCCAAAAA- BAAAAAAAAAAAAAAACCCCCAAAAA- -BBBAAAAAAAAAAAAAAAGGAAAAA- ---BBBBBB--AAAAAAAAAAAAAAA- ----BAAABBB-BDDDDHHGGGAAAA- -----AAA-BBBBAAAAAAAAAAAA-- ---------BBBBBAAA----A----- ---------------AA---------- 
--------------BB----------- ---------B-BBBAAB---------- --------BBBAAAAAABBB------- --------BBAAAAAAAAAAB------ -------BAAAAAAA-AAAAAB----- -----BBAAAAAAAAAAAAAAA----- ---BBAAAAAAAAAAAAAAAAA----- --BAAAAAAAAAAAAAAAAAAAA---- -BAAAAAAAAAAAAAAAAAAAAA---- BBBBBBBBBBBBBBBBCCCCCAAAA-- -BBBBBBBBBBBBBBBCCCCCAAAAA- -BFFFFFFDDDDDDHHCCCCCAAAAA- BAAAAAAAAAAAAAAACCCCCAAAAA- -BBBAAAAAAAAAAAAAAAGGAAAAA- ---BBBBBB--AAAAAAAAAAAAAAA- ----BAAA-BBBBDDAAAHGGAAAAA- -----AAA-BB-BAAAAAAAAAAAA-- ---------BBB-BAAA----A----- ---------------AA---------- 
--------------------------- -----------BBBBBB---------- --------BBBAAAAAABBB------- --------BBAAAAAAAAAAB------ -------BAAAAAAA-AAAAAB----- -----BBAAAAAAAAAAAAAAA----- ---BBAAAAAAAAAAAAAAAAA----- --BAAAAAAAAAAAAAAAAAAAA---- -BAAAAAAAAAAAAAAAAAAAAA---- BBBBBBBBBBBBBBBBCCCA-AAAA-- -BBBBBBBBBBBBBBBCCCC-AAAAA- -BFFFFFFDDDDDDHHCCCC-AAAAA- BAAAAAAAAAAAAAAACCCC-AAAAA- -BBBAAAAAAAAAAAAAAAG-AAAAA- ---BBBBAAAAAA--AAAAA-AAAAA- ----BAAAB-EEEEAAAAAG-AAAAA- -----AAA-BEEEEAAAAAAAAAAA-- ---------BKEKBA-----A------ --------------------------- 
--------------------------- -----------BBBBBB---------- --------BBBAAAAAABBB------- --------BBAAAAAAAAAAB------ -------BAAAAAAA-AAAAAB----- -----BBAAAAAAAAAAAAAAA----- ---BBAAAAAAAAAAAAAAAAA----- --BAAAAAAAAAAAAAAAAAAA----- -BAAAAAAAAAAAAAAAAAAAA----- -BBBBBBBBBBBBBBBCAAA-A----- -BBBBBBBBBBBBBBBCCCCAAAAAA- -BFFFFFFDDDDDDHHCCCCAAAAAA- BAAAAAAAAAAAAAAACCCCAAAAAA- -BBBAAAAAAAAAAAAAAAGAAAAAA- ---BBBAAAAA--AABAAAAAAAAAA- -----AAAAAEE---AAAAAAAAAA-- -----AAABBEEEEAAAAAAAAAAA-- ---------BEJEB------------- --------------------------- 
--------------------------- -----------BBBBBB---------- ---------BBAAAAAABBB------- --------BBAAAAAAAAAAB------ -------BBAAAAAA-AAAAAB----- -----BBAAAAAAAAAAAAAAABBBBB ----BAAAAAAAAAAAAAAAAA----- --BBAAAAAAAAAAAAAAAAAA----- -BAAAAAAAAAAAAAAAAAAAA----- --BBBBBBBBBBBBBBCAAA-A----- -BBBBBBBBBBBBBBBCCCCAAAAAA- -BFFFFFFDDDDDDHHCCCCAAAAAA- -BAAAAAAAAAAAAAACCCCAAAAAA- --BBAAAAAAAAAAAAAAAAAAAAA-- ----BAAAAAA--AAAAAAAAAAAA-- -----BAAAAEEE--AAAAAAAAAA-- -----AAAAIEE--AAAAAAAAAA--- --------BBJEKB------------- --------------------------- 
--------------------------- --------------------------- ---------B-BBBBBBB--------- --------BBBAAAAAAABBB------ -------BBAAAAAA-AAAAABB---- -----BBAAAAAAAAAAAAAAABBBBB ----BAAAAAAAAAAAAAAAAA----- ---BBAAAAAAAAAAAAAAAAA----- --BAAAAAAAA----AAAAAAA----- --BBBBBBBBBBBBBBAAAAAA----- -BBBBBBBBBBBBBBBCCCCCAAA--- -BFFFFFFDDDDDDDHCCCCCAAA--- --BAAAAAAAAAAAAACCCCCAAA--- ---BAAAAAAAAAAAAAAAAAAAA--- ----BAAAAAA--AABAAAAAAAA--- -----AAAAAEEEE-AAAAAAAAA--- -----AAAABEE-EAAAAAAAAAA--- --------BBKEJB------------- --------------------------- 
--------------------------- --------------------------- --------------------------- --------BB-BBBBBBBBBBBB---- --------BBBBBBBBAAAABBB---- ------BBAAABBBAAAAAABB----- -----BAAAAAAAAAAAAAABB----- ---BBAAAAAAAAAAAAAAABB----- --BAAAAAAAA---AAAAAABBB---- --BBBBBBBBBBBBBBAAAAAAAB--- --BBBBBBBBBBBBBBCCCCCCAB--- --B-FFFDDDDDDDDHCCCCCCAB--- --BAAAAAAAAAAAAACCCCCCCA--- ---BAAAAAAAAAAAAAAAAAAAA--- ----BAAAAAAA-AABAAAAAAAA--- -----AAAAAEEEBAAAAAAAAA---- -----AAAABEEE-AAMA--------- --------BBJEEB------------- --------------------------- 
--------------------------- --------------------------- --------------------------- ---------B-------B-B------- --------BB---BBBBBBB------- ------BBBBBBBBAAABBBBBBBBBB -----BAAAAAAAABBBBBB------- ----BAAAAAAAAABBBBBB------- ---BAAAAAAA---AA-BBBBBB---- ---BBBBBBBBBBBBAAAAAAAABBBB ---BBBBBBBBBBBBBBABBBBABB-- --BFFFFDDDDDDDDDDHHGGGABB-- --BAAAAAAAAAAAAAAAAGGGAB--- ---BAAAAAAAAAAAAAAAAAAAA--- ----BAAAAAAAAAAAAAAAAAA---- -----AAAAAEEEB------------- ------AAAIEEEB------------- --------BBEKJB------------- --------------------------- 
--------------------------- --------------------------- --------------------------- --------------------------- --------BB----B---B-------- ------BBBBBBBBBBBB--------- -----BAAAAAAAAB------------ ----BAAAAAAAAAB------------ ----BAAAAAAAAAABBBBBBBB---- ---BBBBBBBBBBBBAAAAAAAAB--- ---BBBBBBBBBBBBBBABBBBAB--- ---BFFAADDDDDDDDDHHGGGAB--- ---BAAAADDDDDDAAAHHGGGA---- ---BAAAAIIIIIAAAAAAAAAA---- ----BBAAAAAAABAA---AA------ ------AAAAAAB-------------- --------BBBBB-------------- --------BBJEB-------------- --------------------------- 
--------------------------- --------------------------- --------------------------- --------------------------- --------------------------- ------------B-------------- ------BBBBBBBB------------- -----BBBBBBBBB------------- ----BBABBBABBBBBBB--------- ---BAABAAABAAAAAAABBBBB---- ---BAAAAAAAAAAAAAAAAAA-B--- ---BBBBBAAAAAAAAAAAAAA-BBBB ---BBBBBAAAAAAAAAAAAAA----- ----BBBBAAAAAAA----AAA----- -------AAAABBBA-----A------ --------BBBB--------------- --------------------------- --------------------------- --------------------------- 
--------------------------- --------------------------- --------------------------- --------------------------- --------------------------- --------------------------- --------------------------- --------------------------- ------B-BBB---------------- ----BBABAAABBBBBBBBBBBBBBB- ----BBBBBBLBAAAA----------- --------LBBBA--A----------- --------BBBBA--A----------- --------BBBB--------------- --------BBB---------------- --------BBBB--------------- --------------------------- --------------------------- --------------------------- 
--------------------------- --------------------------- --------------------------- --------------------------- --------------------------- --------------------------- --------------------------- --------------------------- --------------------------- ------B-BBB---------------- ----------B---------------- --------B-B---------------- -------------AA------------ --------------------------- ----------B---------------- ----------B---------------- --------------------------- --------------------------- --------------------------- 
