model
size = 31 31 13, scale = 0.05, origin = -y
material 
  colors = A:#111 B:#FFF C:#888 D:#9CF
voxels
---------AAAAAAAAAAAAA--------- ---------AAAAAAAAAAAAA--------- ---------AAAAAAAAAAAAA--------- ---------AAAAAAAAAAAAA--------- ---------AAAAAAAAAAAAA--------- ---------AAAAAAAAAAAAA--------- ---------AAAAAAAAAAAAA--------- ---------AAAAAAAAAAAAA--------- ---------AAAAAAAAAAAAA--------- ---------AAAAAAAAAAAAA--------- ---------AAAAAAAAAAAAA--------- ---------AAAAAAAAAAAAA--------- ---------AAAAAAAAAAAAA--------- ---------AAAAAAAAAAAAA--------- ---------AAAAAAAAAAAAAA-------- --------AAAAAAAAAAAAAAA-------- --------AAAAAAAAAAAAAAA-------- -------AAAAAAAAAAAAAAAAA------- -------AAAAAAAAAAAAAAAAA------- ------AAAAAAAAAAAAAAAAAAA------ ------AAAAAAAAAAAAAAAAAAA------ ------AAAAAAAAAAAAAAAAAAA------ -----AAAAAAAAAAAAAAAAAAAAA----- -----AAAAAAAAAAAAAAAAAAAAA----- ------AAAAAAAAAAAAAAAAAAA------ -------AAAAAAAAAAAAAAAAA------- ----------AAAAAAAAAAA---------- ------------------------------- ------------------------------- ------------------------------- ------------------------------- 
--------A-------------A-------- --------A-------------A-------- --------A-------------A-------- --------A-------------A-------- --------A-------------A-------- --------A-------------A-------- --------A-------------A-------- --------A-------------A-------- --------A-------------A-------- --------A-------------A-------- --------A-------------A-------- --------A-------------A-------- --------A-------------A-------- --------A-------------A-------- --------A-------------A-------- --------A-------------AA------- -------A---------------A------- -------A---------------A------- ------AA---------------AA------ ------AA---------------AA------ -----AAA---------------AAA----- ----AAAA---------------AAAA---- ----AAAA---------------AAAA---- ----AAAAA-------------AAAAA---- ------AAAA-----------AAAAA----- ------AAAAAA-------AAAAAA------ -------AAAAAAAAAAAAAAAAA------- ---------AAAAAAAAAAAAA--------- -----------AAAAAAAAA----------- ------------------------------- ------------------------------- 
-------A---------------A------- -------A---------------A------- -------A---------------A------- -------A---------------A------- -------A---------------A------- -------A---------------A------- -------A---------------A------- -------A---------------A------- -------A---------------A------- -------A---------------A------- -------A---------------A------- -------A---------------A------- -------A---------------A------- -------A---------------A------- -------A---------------A------- -------A---------------A------- ------------------------------- ------------------------------- ------------------------------- ------------------------------- ------------------------------- ------------------------------- ---AAA-------------------AAA--- --A-AAA-----------------AAAAA-- -----AAA---------------AAAA---- -----AAAA-------------AAAA----- ------AAAAAAAAAAAAAAAAAAA------ -------AAAAAAAAAAAAAAAAA------- ---------AAAAAAAAAAAAA--------- ------------AAAAAAA------------ ------------------------------- 
-------A---------------A------- -------A---------------A------- -------A---------------A------- -------A---------------A------- -------A---------------A------- -------A---------------A------- -------A---------------A------- -------A---------------A------- -------A---------------A------- -------A---------------A------- -------A---------------A------- -------A---------------A------- -------A---------------A------- -------A---------------A------- -------A---------------A------- -------A---------------A------- ------------------------------- ------------------------------- ------------------------------- ------------------------------- ------------------------------- ------------------------------- ------------------------------- --AAA---------------------AAA-- -AAAA---------------------AAAA- -----A-------------------AAA--- ----AAAA---------------AAAA---- -----AAAAAA---------AAAAAA----- -------AAAAAA-----AAAAAA------- ---------AAAA-----AAAA--------- ------------AAAAAAA------------ 
-------AA--------------A------- -------AA--------------A------- -------AA--------------A------- -------AA--------------A------- -------AA--------------A------- -------AA--------------A------- -------AA--------------A------- -------AA--------------A------- -------AA--------------A------- -------AA--------------A------- -------AA--------------A------- -------AA--------------A------- -------AA--------------A------- -------AA--------------A------- -------AA--------------A------- -------A---------------A------- ------------------------------- ------------------------------- ------------------------------- ------------------------------- ------------------------------- ------------------------------- ------------------------------- ------------------------------- -AAA-----------------------AAA- AAAAA---------------------AAAAA --AAA---------------------AAA-- ----AAAAA-------------AAAAA---- -----AAAAA-----------AAAAA----- --------AA-----------AA-------- ----------AAA-----AAA---------- 
-------AA--------------A------- -------AA--------------A------- -------AA--------------A------- -------AA--------------A------- -------AA--------------A------- -------AA--------------A------- -------AA--------------A------- -------AA--------------A------- -------AA--------------A------- -------AA--------------A------- -------AA--------------A------- -------AA--------------A------- -------AA--------------A------- -------AA--------------A------- -------AA--------------A------- -------A---------------A------- ------------------------------- ------------------------------- ------------------------------- ------------------------------- ------------------------------- ------------------------------- ------------------------------- ------------------------------- -AAA-----------------------AAA- AAAAA---------------------AACAA -AAAA---------------------AAAA- ---AAA-------------------AAA--- ----AAAAAA-----------AAAAAA---- ------AAAA-----------AAAA------ ----------A---------A---------- 
-------A---------------A------- -------A---------------A------- -------A---------------A------- -------A---------------A------- -------A---------------A------- -------A---------------A------- -------A---------------A------- -------A---------------A------- -------A---------------A------- -------A---------------A------- -------A---------------A------- -------A---------------A------- -------A---------------A------- -------A---------------A------- -------A---------------A------- -------A---------------A------- ------------------------------- ------------------------------- ------------------------------- ------------------------------- ------------------------------- ------------------------------- ------------------------------- ------------------------------- -AAA-----------------------AAA- AAAAA---------------------ACCAA -AAAA---------------------ADAA- ---AAA-------------------ACA--- ----AAAAAA-----------AAAAAA---- ------AAAA-----------AAAA------ ----------A---------A---------- 
-------A---------------A------- -------A---------------A------- -------A---------------A------- -------A---------------A------- -------A---------------A------- -------A---------------A------- -------A---------------A------- -------A---------------A------- -------A---------------A------- -------A---------------A------- -------A---------------A------- -------A---------------A------- -------A---------------A------- -------A---------------A------- -------A---------------A------- -------A---------------A------- ------------------------------- ------------------------------- ------------------------------- ------------------------------- ------------------------------- ------------------------------- ------------------------------- ------------------------------- -AAA-----------------------AAA- AAAAA---------------------AAAAA --AAA---------------------AAA-- ----AAAAA-------------AAAAA---- -----AAAAA-----------AAAAA----- --------AA-----------AA-------- ----------AAA-----AAA---------- 
-------A---------------A------- -------A---------------A------- -------A---------------A------- -------A---------------A------- -------A---------------A------- -------A---------------A------- -------A---------------A------- -------A---------------A------- -------A---------------A------- -------A---------------A------- -------A---------------A------- -------A---------------A------- -------A---------------A------- -------A---------------A------- -------A---------------A------- -------A---------------A------- ------------------------------- ------------------------------- ------------------------------- ------------------------------- ------------------------------- ------------------------------- ------------------------------- --AAA---------------------AAA-- -AAAAA-------------------AAAAA- ---AAAAAA-------------AAAAAA--- ----AAAAAA-----------AAAAAA---- -----AAAAA-----------AACAA----- -------AAAAA-------AAAAA------- ---------AAA-------AAA--------- ------------A-----A------------ 
--------A-------------A-------- --------A-------------A-------- --------A-------------A-------- --------A-------------A-------- --------A-------------A-------- --------A-------------A-------- --------A-------------A-------- --------A-------------A-------- --------A-------------A-------- --------A-------------A-------- --------A-------------A-------- --------A-------------A-------- --------A-------------A-------- --------A-------------A-------- --------A-------------A-------- -------A---------------A------- ------------------------------- ------------------------------- ------------------------------- ------------------------------- ------------------------------- ------------------------------- ---AAAA-----------------AAAA--- --AAAAA-----------------AAAAA-- ----AAAA---------------AAAA---- -----AAAAA-----------AAAAA----- ------AAAA-----------ACCA------ -------AAAAAAAAAAAAAAAAA------- ---------AAAAAAAAAAAAA--------- ------------AAAAAAA------------ ------------------------------- 
---------A-----------A--------- ---------A-----------A--------- ---------A-----------A--------- ---------A-----------A--------- ---------A-----------A--------- ---------A-----------A--------- ---------A-----------A--------- ---------A-----------A--------- ---------A-----------A--------- ---------A-----------A--------- ---------A-----------A--------- ---------A-----------A--------- ---------A-----------A--------- ---------A-----------A--------- --------AA-----------AA-------- --------A-------------A-------- -------AA-------------AA------- -------A---------------A------- ------AA---------------AA------ ------AA---------------AA------ -----AAA---------------AAA----- ----AAAA---------------AAAA---- ----AAAA---------------AAAA---- ----AAAA---------------AAAA---- -----AAAA-------------AAAA----- ------AAAAA---------AAAAA------ -------AAAAAAAAAAAAAAAAA------- ---------AAAAAAAAAAAAA--------- ------------AAAAAAA------------ ------------------------------- ------------------------------- 
----------AAAAAAAAAAA---------- ----------AAAAAAAAAAA---------- ----------AAAAAAAAAAA---------- ----------ABAAAAAAABA---------- ----------BAAAAAAAAAB---------- ----------AAAAAAAAAAA---------- ----------AAAAAAAAAAA---------- ----------AAAAAAAAAAA---------- ----------AAAAAAAAAAA---------- ----------AAAAAAAAAAA---------- ----------AAAAAAAAAAA---------- ----------AAAAAAAAAAA---------- ----------BBAAAAAAAAB---------- ---------AABABBBBBABAA--------- ---------AAAAAAAAAAAAA--------- ---------AAAAAAAAAAAAA--------- --------AAAAABBBBBAAAAA-------- --------AAAAAAAAAAABAAAA------- -------AAAAAAAABAAABBAAA------- -------AAAAAAAAAAAABBAAA------- ------AAAAAAAAAAAAABBAAAA------ ------AAAAAAABAABAABBAAAA------ -----AAAAAAAAAAAAAABBAAAAA----- -----AAAAAAABBAAAAABAAAAAA----- ------AAAAAAABBBBBBAAAAAA------ -------AAAAAAAAAAAAAAAAA------- ----------AAAAAAAAAAA---------- ------------------------------- ------------------------------- ------------------------------- ------------------------------- 
------------------------------- ------------------------------- ------------------------------- ------------------------------- -----------B-------B----------- ------------B-----B------------ -------------B---B------------- --------------B-B-------------- ---------------B--------------- --------------B-B-------------- -------------B---B------------- ------------B-----B------------ -----------B-------B----------- --------------BBB-------------- ------------BBBBBBB------------ ------------B-----B------------ -------------BBBB-------------- ------------B----BB------------ ------------B--B---B----------- -----------B-------B----------- -----------B-BB-BB-B----------- -----------B--B--B-B----------- ------------B------B----------- -------------B----B------------ --------------BBBB------------- ------------------------------- ------------------------------- ------------------------------- ------------------------------- ------------------------------- ------------------------------- 
