model
size = 31 31 13, scale = 0.05, origin = -y
material 
  colors = A:#C69 B:#111
voxels
---------AAAAAAAAAAAAA--------- ---------AAAAAAAAAAAAA--------- ---------AAAAAAAAAAAAA--------- ---------AAAAAAAAAAAAA--------- ---------AAAAAAAAAAAAA--------- ---------AAAAAAAAAAAAA--------- ---------AAAAAAAAAAAAA--------- ---------AAAAAAAAAAAAA--------- ---------AAAAAAAAAAAAA--------- ---------AAAAAAAAAAAAA--------- ---------AAAAAAAAAAAAA--------- ---------AAAAAAAAAAAAA--------- ---------AAAAAAAAAAAAA--------- ---------AAAAAAAAAAAAA--------- ---------AAAAAAAAAAAAAA-------- --------AAAAAAAAAAAAAAA-------- --------AAAAAAAAAAAAAAA-------- -------AAAAAAAAAAAAAAAAA------- -------AAAAAAAAAAAAAAAAA------- ------AAAAAAAAAAAAAAAAAAA------ ------AAAAAAAAAAAAAAAAAAA------ ------AAAAAAAAAAAAAAAAAAA------ -----AAAAAAAAAAAAAAAAAAAAA----- -----AAAAAAAAAAAAAAAAAAAAA----- ------AAAAAAAAAAAAAAAAAAA------ -------AAAAAAAAAAAAAAAAA------- ----------AAAAAAAAAAA---------- ------------------------------- ------------------------------- ------------------------------- ------------------------------- 
--------A-------------A-------- --------A-------------A-------- --------A-------------A-------- --------A-------------A-------- --------A-------------A-------- --------A-------------A-------- --------A-------------A-------- --------A-------------A-------- --------A-------------A-------- --------A-------------A-------- --------A-------------A-------- --------A-------------A-------- --------A-------------A-------- --------A-------------A-------- --------A-------------A-------- --------A-------------AA------- -------A---------------A------- -------A---------------A------- ------AA---------------AA------ ------AA---------------AA------ -----AAA---------------AAA----- ----AAAA---------------AAAA---- ----AAAA---------------AAAA---- ----AABAA-------------AAAAA---- ------AAAA-----------AAAAA----- ------AAAAAA-------AAAAAA------ -------AAAAAAAAAAAAAAAAA------- ---------AAAAAAAAAAAAA--------- -----------AAAAAAAAA----------- ------------------------------- ------------------------------- 
-------A---------------A------- -------A---------------A------- -------A---------------A------- -------A---------------A------- -------A---------------A------- -------A---------------A------- -------A---------------A------- -------A---------------A------- -------A---------------A------- -------A---------------A------- -------A---------------A------- -------A---------------A------- -------A---------------A------- -------A---------------A------- -------A---------------A------- -------A---------------A------- ------------------------------- ------------------------------- ------------------------------- ------------------------------- ------------------------------- ------------------------------- ---AAA-------------------AAA--- --A-AAA-----------------AAAAA-- -----AAA---------------AAAA---- -----AAAA-------------AAAA----- ------AAAAAAAAAAAAAAAAAAA------ -------AAAAAAAAAAAAAAAAA------- ---------AAAAAAAAAAAAA--------- ------------AAAAAAA------------ ------------------------------- 
-------A---------------A------- -------A---------------A------- -------A---------------A------- -------A---------------A------- -------A---------------A------- -------A---------------A------- -------A---------------A------- -------A---------------A------- -------A---------------A------- -------A---------------A------- -------A---------------A------- -------A---------------A------- -------A---------------A------- -------A---------------A------- -------A---------------A------- -------A---------------A------- ------------------------------- ------------------------------- ------------------------------- ------------------------------- ------------------------------- ------------------------------- ------------------------------- --AAA---------------------AAA-- -AAAA---------------------AAAA- -----A-------------------AAA--- ----AAAA---------------AAAA---- -----AAAAAA---------AAAAAA----- -------AAAAAA-----AAAAAA------- ---------AAAA-----AAAA--------- ------------AAAAAAA------------ 
-------AA--------------A------- -------AA--------------A------- -------AA--------------A------- -------AA--------------A------- -------AA--------------A------- -------AA--------------A------- -------AA--------------A------- -------AA--------------A------- -------AA--------------A------- -------AA--------------A------- -------AA--------------A------- -------AA--------------A------- -------AA--------------A------- -------AA--------------A------- -------AA--------------A------- -------A---------------A------- ------------------------------- ------------------------------- ------------------------------- ------------------------------- ------------------------------- ------------------------------- ------------------------------- ------------------------------- -AAA-----------------------AAA- AAAAA---------------------AAAAA --AAA---------------------AAA-- ----AAAAA-------------AAAAA---- -----AAAAA-----------AAAAA----- --------AA-----------AA-------- ----------AAA-----AAA---------- 
-------AA--------------A------- -------AA--------------A------- -------AA--------------A------- -------AA--------------A------- -------AA--------------A------- -------AA--------------A------- -------AA--------------A------- -------AA--------------A------- -------AA--------------A------- -------AA--------------A------- -------AA--------------A------- -------AA--------------A------- -------AA--------------A------- -------AA--------------A------- -------AA--------------A------- -------A---------------A------- ------------------------------- ------------------------------- ------------------------------- ------------------------------- ------------------------------- ------------------------------- ------------------------------- ------------------------------- -AAA-----------------------AAA- AAAAA---------------------AAAAA -AAAA---------------------AAAA- ---AAA-------------------AAA--- ----AAAAAA-----------AAAAAA---- ------AAAA-----------AAAA------ ----------A---------A---------- 
-------A---------------A------- -------A---------------A------- -------A---------------A------- -------A---------------A------- -------A---------------A------- -------A---------------A------- -------A---------------A------- -------A---------------A------- -------A---------------A------- -------A---------------A------- -------A---------------A------- -------A---------------A------- -------A---------------A------- -------A---------------A------- -------A---------------A------- -------A---------------A------- ------------------------------- ------------------------------- ------------------------------- ------------------------------- ------------------------------- ------------------------------- ------------------------------- ------------------------------- -AAA-----------------------AAA- AAAAA---------------------AAAAA -AAAA---------------------AAAA- ---AAA-------------------AAA--- ----AAAAAA-----------AAAAAA---- ------AAAA-----------AAAA------ ----------A---------A---------- 
-------A---------------A------- -------A---------------A------- -------A---------------A------- -------A---------------A------- -------A---------------A------- -------A---------------A------- -------A---------------A------- -------A---------------A------- -------A---------------A------- -------A---------------A------- -------A---------------A------- -------A---------------A------- -------A---------------A------- -------A---------------A------- -------A---------------A------- -------A---------------A------- ------------------------------- ------------------------------- ------------------------------- ------------------------------- ------------------------------- ------------------------------- ------------------------------- ------------------------------- -AAA-----------------------AAA- AAAAA---------------------AAAAA --AAA---------------------AAA-- ----AAAAA-------------AAAAA---- -----AAAAA-----------AAAAA----- --------AA-----------AA-------- ----------AAA-----AAA---------- 
-------A---------------A------- -------A---------------A------- -------A---------------A------- -------A---------------A------- -------A---------------A------- -------A---------------A------- -------A---------------A------- -------A---------------A------- -------A---------------A------- -------A---------------A------- -------A---------------A------- -------A---------------A------- -------A---------------A------- -------A---------------A------- -------A---------------A------- -------A---------------A------- ------------------------------- ------------------------------- ------------------------------- ------------------------------- ------------------------------- ------------------------------- ------------------------------- --AAA---------------------AAA-- -AAAAA-------------------AAAAA- ---AAAAAA-------------AAAAAA--- ----AAAAAA-----------AAAAAA---- -----AAAAA-----------AAAAA----- -------AAAAA-------AAAAA------- ---------AAA-------AAA--------- ------------A-----A------------ 
--------A-------------A-------- --------A-------------A-------- --------A-------------A-------- --------A-------------A-------- --------A-------------A-------- --------A-------------A-------- --------A-------------A-------- --------A-------------A-------- --------A-------------A-------- --------A-------------A-------- --------A-------------A-------- --------A-------------A-------- --------A-------------A-------- --------A-------------A-------- --------A-------------A-------- -------A---------------A------- ------------------------------- ------------------------------- ------------------------------- ------------------------------- ------------------------------- ------------------------------- ---AAAA-----------------AAAA--- --AAAAA-----------------AAAAA-- ----AAAA---------------AAAA---- -----AAAAA-----------AAAAA----- ------AAAA-----------AAAA------ -------AAAAAAAAAAAAAAAAA------- ---------AAAAAAAAAAAAA--------- ------------AAAAAAA------------ ------------------------------- 
---------A-----------A--------- ---------A-----------A--------- ---------A-----------A--------- ---------A-----------A--------- ---------A-----------A--------- ---------A-----------A--------- ---------A-----------A--------- ---------A-----------A--------- ---------A-----------A--------- ---------A-----------A--------- ---------A-----------A--------- ---------A-----------A--------- ---------A-----------A--------- ---------A-----------A--------- --------AA-----------AA-------- --------A-------------A-------- -------AA-------------AA------- -------A---------------A------- ------AA---------------AA------ ------AA---------------AA------ -----AAA---------------AAA----- ----AAAA---------------AAAA---- ----AAAA---------------AAAA---- ----AAAA---------------AAAA---- -----AAAA-------------AAAA----- ------AAAAA---------AAAAA------ -------AAAAAAAAAAAAAAAAA------- ---------AAAAAAAAAAAAA--------- ------------AAAAAAA------------ ------------------------------- ------------------------------- 
----------AAAAAAAAAAA---------- ----------AAAAAAAAAAA---------- ----------AAAAAAAAAAA---------- ----------AAAAAAAAAAA---------- ----------AAAAAAAAAAA---------- ----------AAAAAAAAAAA---------- ----------AAAAAAAAAAA---------- ----------AAAAAAAAAAA---------- ----------AAAAAAAAAAA---------- ----------AAAAAAAAAAA---------- ----------AAAAAAAAAAA---------- ----------AAAAAAAAAAA---------- ----------AAAAAAAAAAA---------- ---------AAAAAAAAAAAAA--------- ---------AAAAAAAAAAAAA--------- ---------AAAAAAAAAAAAA--------- --------AAAAAAAAAAAAAAA-------- --------AAAAAAAAAAAAAAAA------- -------AAAAAAAAAAAAAAAAA------- -------AAAAAAAAAAAAAAAAA------- ------AAAAAAAAAAAAAAAAAAA------ ------AAAAAAAAAAAAAAAAAAA------ -----AAAAAAAAAAAAAAAAAAAAA----- -----AAAAAAAAAAAAAAAAAAAAA----- ------AAAAAAAAAAAAAAAAAAA------ -------AAAAAAAAAAAAAAAAA------- ----------AAAAAAAAAAA---------- ------------------------------- ------------------------------- ------------------------------- ------------------------------- 
------------------------------- ------------------------------- ------------------------------- -----------A-------A----------- ----------AA-------AA---------- ------------A-----A------------ -------------A---A------------- --------------A-A-------------- ---------------A--------------- --------------A-A-------------- -------------A---A------------- ------------A-----A------------ ----------AA-------AA---------- -----------A--AAA--A----------- ------------AAAAAAA------------ ------------A-----A------------ -------------AAAA-------------- ------------A----AA------------ ------------A--A---A----------- -----------A-------A----------- -----------A-AA-AA-A----------- -----------A--A--A-A----------- ------------A------A----------- -------------A----A------------ --------------AAAA------------- ------------------------------- ------------------------------- ------------------------------- ------------------------------- ------------------------------- ------------------------------- 
