model
size = 13 16 11, scale = 0.05, origin = -y
material 
  colors = A:#F96 B:#BBB C:#DDD D:#EEE E:#F99 F:#E00 G:#039
voxels
------------- ------------- ------------- ------------- ------------- ------------- ------------- ------------- ------------- -------A----- -------A----- -------A----- -------A----- -------A----- ------------- ------------- 
------------- ------------- ------------- ------------- ------------- ------------- ------------- ------CCCCC-- ------------- --------A---- ------BAA---- --BBBBAA----- --BBBBAA----- --BBBBBA----- --DDDDDA----- ------------- 
------------- ------------- ------------- ------------- ------------- -------D----- ------DCCCC-- ----------C-- --------AAC-- -------BAA--- ---AAA-BAE--- -BBBBAAC----- -BBBBAAC----- -BBBBAABAE--- -DDAAAADA---- ------------- 
------------- ------------- ------------- ------------- ------------- --------DD--- ----------C-- ---------CC-- ---------BC-- ---AAA-BBBC-- --AAAAA-BA--- BBBBBAAG----- BBBBBAAC----- BBBBBAAAAE--- DDDAAAADDA--- ----AA------- 
-------CC---- -------CC---- -------CCC--- -------CCCC-- -------CCCCCC -------CCDCCC -------CCCC-- ---------BB-- ---AAA---BC-- --AAAAABBBC-- -AAAAAAFBA--- BBBBBAAC----- BBBBBAAC----- BBBBBAAAAE--- DDDAAAADDA--- ---AAAA------ 
-------CC---- -------CC---- -------CCC--- -------CCCC-- -------CCCCCC -------CCDCCC -------CCCC-- ---------BB-- ---AFA---BC-- --AAAAA-BCC-- -AAAAFFFBAA-- BBBAAAAAAA--- BBBAAAAAAA--- BBBAAAAAAA--- DDDAAAADDA--- ---AAAA------ 
-------CC---- -------CC---- -------CCC--- -------CCCC-- -------CCCCCC -------CCDCCC -------CCCC-- ---------BB-- ---AAA---BC-- --AAAAA-BBC-- -AAAAFAFBA--- BBBAAAAC----- BBBAAAAC----- BBBAAAAAAE--- DDDAAAADDA--- ---AAAA------ 
------------- ------------- ------------- ------------- ------------- ---------C--- ----------C-- ----------C-- ---------BC-- ---AAA--BBC-- --AAAAA-BA--- BBBAAAAG----- BBBAAAAC----- BBBAAAAAAE--- DDDAAAADDA--- ----AA------- 
------------- ------------- ------------- ------------- ------------- -------DC---- -------CCCC-- ---------AC-- ---------AC-- ------AABA--- ---AAABBBE--- -BBAAAAC----- -BBAAAAC----- -BBAAAABAE--- -DDAAAADA---- ------------- 
------------- ------------- ------------- ------------- ------------- ------------- ------------- ------CCCCC-- ------------- ------AAA---- ------BAA---- --BBBBAA----- --BBBBAA----- --BBBBBA----- --DDDDDA----- ------------- 
------------- ------------- ------------- ------------- ------------- ------------- ------------- ------------- ------------- -------A----- -------A----- -------A----- -------A----- -------A----- ------------- ------------- 
