model
size = 32 23 12, scale = 0.05, origin = -y
material 
  colors = A:#E5E5E5 B:#0BF C:#B20000 D:#D10000 E:#222 F:#0DA1D3
voxels
157-B94-B36-B28-B26-B-B5-B34-B20-B28-2(B5-)B3-B18-B7-B28-B351-B30-BA29-BAB29-ABA28-2(AB)2-A25-2(BA)2-BA23-2(BA)B2-ABA21-3(BA)2-2(BA)19-3(BA)B2-2(AB)A17-4(BA)2-3(BA)15-4(BA)B2-3(AB)A14-4(AB)A2-3(BA)15-4(BA)B319-B30-2A-B27-CAB-A27-3A-B26-3AB-A26-4A-B26-3AB-A25-5A-B25-4AB-A25-5A-B23-6AB-A21-9A-B21-8AB-6A20-5A-3(BA)B16-4(BA)256-B31-6(AB30-BA30-)AB4A21-5AB6A22-4A7D16-8D-7A215-2AB28-2ABA28-3AB28-2ABA28-C2A4(B28-2ABA28-3A)B28-2ABA29-2AB27-3ABD28-AD-7D16-7A162-B29-AB2A27-C2ABAC25-3AB3A25-4ABCA25-3AB2AC25-C3A4(B2A25-3AB3A25-4A)B2A27-ABA27-4AD28-AD-7A16-7D130-B29-A-2A28-2AB2A26-2AB4A24-C3AB2AC24-3AB4A24-4AB3A24-3AB3AC24-C3A3(B2A25-3AB3A25-4A)B2A25-3AB3A27-2AC22-8AB-7A15-7AD2-7A15-7A4-5B25-A2BE3B27-4B29-2A27-A31-B2A27-AB4A26-2AB3A26-AB4A26-2AB2AC24-3AB4A24-4AB3A24-3AB3AC24-C3A3(BA26-3AB2A26-4A)CA28-AC8A15-9A-7D15-7A4-5A16-7D4-F3AB25-AB4AB27-B2AF29-2A59-ABA29-B2A27-B-4A26-A-B3A26-C-3AC24-C2A-B3A24-2AB-4A24-3A-B2AC24-2AB-2A26-C2A2(-BA26-2AB-2A26-3A)-CA26-2AC-2A28-A-B7A15-7AB3-5D16-7A4-5A27-F3AB25-AB4AB27-B2AF29-2A93-B30-2(BA)25-A-2(BA)B22-A2(2-B)3A22-4A2-3AC22-C2A2B-B3A22-4A-B4A22-3AB2-2ACA22-4A2-3AC22-C2A2B-B3A22-4A-BA25-3A2B-C25-3AC2-A25-3AB2-A20-9A2-7A14-8D2B2-5D27-5A27-4FB25-AB4AB27-B2AF29-2A93-B91-B4-4(B-)B7-5(B-)B4-2(BA)BC2(BA)B6-2(AB)AC2(AB)A4-CBAC2AC2(BA)6-2(BA)C2ACBAB4-BCBAC2ACBAB6-ABA2(C2A)BCB3-ABC2A2(CA)BA6-BABCAC2ABCB4-BAB2(CA)C2ABE4-EAB2(AC)2ACBA4-4(AC)ABAE4-EB2A2(CA)2(CB)4-C2A2(CA)C2ABE4-EAB3(AC)2ACB3-3A3(CA)BA2E2-2EB2A2(CA)C3A4-4(AC)A10E4(AC)A4-4(AC)A10-ACBAC2ACA2-3BCBAC3AC10-C2(BACA)359-2(B13-)2B7-B15-B34-B3-2B17-B22-B15-B5-2B-B56-B14-B7-B98-B232-
