model
size = 9 11 5, scale = 0.05, origin = -y
material 
  colors = A:#222 B:#717171
voxels
AAA---AAA AAA---AAA AAA---AAA AAA---AAA AAA---AAA AAA---AAA AAA---AAA AAAAAAAAA AAAAAAAAA AAAAAAAAA AAABBBAAA 
AAA---AAA AAA---AAA AAA---AAA AAA---AAA AAA---AAA AAA---AAA AAA---AAA AAAAAAAAA AAAAAAAAA AAAAAAAAA AAAAAAAAA 
AAA---AAA AAA---AAA AAA---AAA AAA---AAA AAA---AAA AAA---AAA AAA---AAA AAAAAAAAA AAAAAAAAA AAAAAAAAA AAAAAAAAA 
AAA---AAA AAA---AAA AAA---AAA AAA---AAA AAA---AAA AAA---AAA AAA---AAA AAAAAAAAA AAAAAAAAA AAAAAAAAA AAAAAAAAA 
--------- --------- --------- --------- --------- --------- --------- --AAAAA-- --AAAAA-- --AAAAA-- --AAAAA-- 
