model
size = 28 29 19, scale = 0.05, origin = -y
material 
  colors = A:#888 B:#FC0 C:#FFF D:#222 E:#FC3 F:#FF3
voxels
---------------------------- ---------------------------- ---------------------------- ---------------------------- ---------------------------- ---------------------------- ---------------------------- -------------B-------------- ------------BBB------------- -----BBBBB--B--B--BBBBB----- ------------BBB------------- -----BBBBB--B--B--BBBBB----- ------------BBB------------- -------------B-------------- -----------------A---------- -----------------A---------- ---------------------------- ---------------------------- ---------------------------- ---------------------------- ---------------------------- ------------BBBB------------ ---------------------------- ---------------------------- ---------------------------- ---------------------------- ---------------------------- ---------------------------- ---------------------------- 
---------------------------- ---------------------------- ---------------------------- ---------------------------- ----------AAAAAAAA---------- ---------AAAAAAAAAA--------- --------AAAAAAAAAAAA-------- -------AAAAAABAAAAAAA------- ------AAAAAABBBAAAAAAA------ -----BBBBBAABAABAABBBBB----- ------AAAAAABBBAAAAAAA------ -----BBBBBAABAABAABBBBB----- ------AAAAAABBBAAAAAAA------ ------AAAAAAABAAAAAAAA------ ------AAAAAAAAAAAAAAAA------ -------AADCCCCCCCADAA------- --------AAAAAAAAAAAA-------- ---------AAAAAAAAAA--------- ---------------------------- ----------AAAAAAAA---------- ----------AAAAAAAA---------- -----------ABBBBA----------- -----------AAAAAA----------- ---------------------------- ---------------------------- ---------------------------- ---------------------------- ---------------------------- ---------------------------- 
---------------------------- ---------------------------- ---------------------------- ---------------------------- ------AAAAAAAAAAAAAAAA------ -----AAAAAAAAAAAAAAAAAA----- -----AAAAAAAAAAAAAAAAAA----- -----AAAAAAAAAAAAAAAAAA----- -----AAAAAAAAAAAAAAAAAA----- -----AAAAAAAAAAAAAAAAAA----- -----AAAAAAAAAAAAAAAAAA----- -----AAAAAAAAAAAAAAAAAA----- -----AAAAAAAAAAAAAAAAAA----- -----AAAAAAAAAAAAAAAAAA----- -----AAAAAAAAAAAAAAAAAA----- -----AAAAAAAAAAAAAAAAAA----- ------AAAAAAAAAAAAAAAA------ -------AAAAAAAAAAAAAA------- --------AAAAAAAAAAAA-------- --------AAAAAAAAAAAA-------- ---------AAAAAAAAAA--------- ---------AAAAAAAAAA--------- ----------AAAAAAAA---------- ----------AAAAAAAA---------- ---------------------------- ---------------------------- ---------------------------- ---------------------------- ---------------------------- 
---------------------------- ---------------------------- ---------------------------- ----BBBBBBBBBBBBBBBBBBBB---- ----BAAAAAAAAAAAAAAAAAAB---- ----BAAAAAAAAAAAAAAAAAAB---- ----BAAAAAAAAAAAAAAAAAAB---- ----BAAAAAAAAAAAAAAAAAAB---- ----BAAAAAAAAAAAAAAAAAAB---- ----BAAAAAAAAAAAAAAAAAAB---- ----BAAAAAAAAAAAAAAAAAAB---- ----BAAAAAAAAAAAAAAAAAAB---- ----BAAAAAAAAAAAAAAAAAAB---- ----BAAAAAAAAAAAAAAAAAAB---- ----BAAAAAAAAAAAAAAAAAAB---- ----BAAAAAAAAAAAAAAAAAAB---- ----BBAAAAAAAAAAAAAAAABB---- -----BBAAAAAAAAAAAAAABB----- ------BAAAAAAAAAAAAAAB------ ------BBAAAAAAAAAAAABB------ -------BBAAAAAAAAAABB------- --------BAAAAAAAAAAB-------- --------BBAAAAAAAABB-------- ---------BAAAAAAAAB--------- ---------BBBBBBBBBB--------- ---------------------------- ---------------------------- ---------------------------- ---------------------------- 
---------------------------- ---------------------------- -------AAAAAAAAAAAAAA------- ----AAAAAAAAAAAAAAAAAAAA---- --BAAAAAAAAAAAAAAAAAAAAAAB-- --BAAAAAAAAAAAAAAAAAAAAAAB-- --BAAAAAAAAAAAAAAAAAAAAAAB-- --BAAAAAAAAAAAAAAAAAAAAAAB-- --BAAAAAAAAAAAAAAAAAAAAAAB-- --AAAAAAAAAAAAAAAAAAAAAAAA-- --BAAAAAAAAAAAAAAAAAAAAAAB-- --BAAAAAAAAAAAAAAAAAAAAAAB-- --BAAAAAAAAAAAAAAAAAAAAAAB-- ----AAAAAAAAAAAAAAAAAAAA---- ----AAAAAAAAAAAAAAAAAAAA---- ----AAAAAAAAAAAAAAAAAAAA---- ----DAAAAAAAAAAAAAAAAAAD---- -----CAAAAAAAAAAAAAAAAC----- ------CAAAAAAAAAAAAAAC------ ------CAAAAAAAAAAAAAAC------ -------CAAAAAAAAAAAAC------- --------CAAAAAAAAAAC-------- --------CAAAAAAAAAAC-------- ---------CAAAAAAAAC--------- ---------CCCCCCAACC--------- ---------------AA----------- ---------------------------- ---------------------------- ---------------------------- 
------AAAAAAAAAAAAAAAA------ ------AAAAAAAAAAAAAAAA------ ---AAAAAAAAAAAAAAAAAAAAAA--- ---AAAAAAAAAAAAAAAAAAAAAA--- --BAAAAAAAAAAAAAAAAAAAAAAB-- --AAAAAAAAAAAAAAAAAAAAAAAA-- --AAAAAAAAAAAAAAAAAAAAAAAA-- --AAAAAAAAAAAAAAAAAAAAAAAA-- --BAAAAAAAAAAAAAAAAAAAAAAB-- --AAAAAAAAAAAAAAAAAAAAAAAA-- --AAAAAAAAAAAAAAAAAAAAAAAA-- --AAAAAAAAAAAAAAAAAAAAAAAA-- --BAAAAAAAAAAAAAAAAAAAAAAB-- ---AAAAAAAAAAAAAAAAAAAAAA--- ---AAAAAAAAAAAAAAAAAAAAAA--- ---AAAAAAAAAAAAAAAAAAAAAA--- ---AAAAAAAAAAAAAAAAAAAAAA--- ---AAAAAAAAAAAAAAAAAAAAAA--- ----AAAAAAAAAAAAAAAAAAAA---- ----AAAAAAAAAAAAAAAAAAAA---- -----AAAAAAAAAAAAAAAAAA----- ------AAAAAAAAAAAAAAAA------ ------AAAAAAAAAAAAAAAA------ ------AAAAAAAAAAAAAAAA------ -------AAAAAAAAAAAAAA------- --------AAAAAAAAAAAA-------- ---------------------------- ---------------------------- ---------------------------- 
------AAAAAAAAAAAAAAAA------ ------AAAAAAAAAAAAAAAA------ ---AAAAAAAAAAAAAAAAAAAAAA--- ---AAAAAAAAAAAAAAAAAAAAAA--- --BAAAAAAAAAAAAAAAAAAAAAAB-- --AAAAAAAAAAAAAAAAAAAAAAAA-- --AAAAAAAAAAAAAAAAAAAAAAAA-- --AAAAAAAAAAAAAAAAAAAAAAAA-- --BAAAAAAAAAAAAAAAAAAAAAAB-- --AAAAAAAAAAAAAAAAAAAAAAAA-- -FAAAAAAAAAAAAAAAAAAAAAAAAF- -FAAAAAAAAAAAAAAAAAAAAAAAAF- --BAAAAAAAAAAAAAAAAAAAAAAB-- ---BBBBBAAAAAAAAAAAABBBBB--- ---BBBBBAAAAAAAAAAAABBBBB--- ---BBBBBAAAAAAAAAAAABBBBB--- ---BBBBBAAAAAAAAAAAABBBBB--- ---BBBBBAAAAAAAAAAAABBBBB--- ----BBBBAAAAAAAAAAAABBBB---- ----BBBBAAAAAAAAAAAABBBB---- -----BBBAAAAAAAAAAAABBB----- ------BBAAAAAAAAAAAABB------ ------BBAAAAAAAAAAAABB------ ------BBAAAAAAAAAAAABB------ -------BAAAAAAAAAAAAB------- --------AAAAAAAAAAAA-------- ---------A--------A--------- ---------A--------A--------- ---------ABABAABABA--------- 
------AAAAAAAAAAAAAAAA------ ------AAAAAAAAAAAAAAAA------ ---AAAAAAAAAAAAAAAAAAAAAA--- ---AAAAAAAAAAAAAAAAAAAAAA--- --BAAAAAAAAAAAAAAAAAAAAAAB-- --AAAAAAAAAAAAAAAAAAAAAAAA-- --AAAAAAAAAAAAAAAAAAAAAAAA-- --AAAAAAAAAAAAAAAAAAAAAAAA-- --BAAAAAAAAAAAAAAAAAAAAAAB-- --AAAAAAAAAAAAAAAAAAAAAAAA-- CFAAAAAAAAAAAAAAAAAAAAAAAAFC -FAAAAAAAAAAAAAAAAAAAAAAAAF- --BAAAAAAAAAAAAAAAAAAAAAAB-- ---AAAAAAAAAAAAAAAAAAAAAA--- ---AAAAAAAAAAAAAAAAAAAAAA--- ---AAAAAAAAAAAAAAAAAAAAAA--- ---AAAAAAAAAAAAAAAAAAAAAA--- ---AAAAAAAAAAAAAAAAAAAAAA--- ----AAAAAAAAAAAAAAAAAAAA---- ----AAAAAAAAAAAAAAAAAAAA---- -----AAAAAAAAAAAAAAAAAA----- ------AAAAAAAAAAAAAAAA------ ------AAAAAAAAAAAAAAAA------ ------AAAAAAAAAAAAAAAA------ -------AAAAAAAAAAAAAA------- --------AAAAAAAAAAAA-------- ---------A--------A--------- ---------A--------A--------- ---------ABABAABABA--------- 
------AAAAAAAAAAAAAAAA------ ------AAAAAAAAAAAAAAAA------ ---AAAAAAAAAAAAAAAAAAAAAA--- ---AAAAAAAAAAAAAAAAAAAAAA--- --BAAAAAAAAAAAAAAAAAAAAAAB-- --AAAAAAAAAAAAAAAAAAAAAAAA-- --AAAAAAAAAAAAAAAAAAAAAAAA-- --AAAAAAAAAAAAAAAAAAAAAAAA-- --BAAAAAAAAAAAAAAAAAAAAAAB-- --AAAAAAAAAAAAAAAAAAAAAAAA-- -FAAAAAAAAAAAAAAAAAAAAAAAAF- -FAAAAAAAAAAAAAAAAAAAAAAAAF- --BBBBAAAAAAAAAAAAABBABBBB-- ---BBBAAAAAAAAAAAAAABABBB--- ---BBBAAAAAAAAAAAAAAAABBB--- ---BBBBBAAAAAAAAAAAABBBBB--- ---BBBBBAAAAAAAAAAAABBBBB--- ----BBBBAAAAAAAAAAAABBBB---- ----BBBBAAAAAAAAAAAABBBB---- -----BBBAAAAAAAAAAAABBB----- ------BBAAAAAAAAAAAABB------ ------BBAAAAAAAAAAAABB------ ------BBAAAAAAAAAAAABB------ -------BAAAAAAAAAAAAB------- --------AAAAAAAAAAAA-------- --------AAAAAAAAAAAA-------- ---------A--------A--------- ---------A--------A--------- ---------ABABAABABA--------- 
------AAAAAAAAAAAAAAAA------ ------AAAAAABBBBAAAAAA------ ---AAAAAAAAABBBBAAAAAAAAA--- ---AAAAAAAAABBBBAAAAAAAAA--- --BAAAABBBAABBBBAABBBAAAAB-- --AAAAABBBAABBBBAABBBAAAAA-- --AAAAABBBAABBBBAABBBAAAAA-- --AAAAAEEEEEEEEEEEEEEAAAAA-- --BAAAAEEBBBBBBBBBBBEAAAAB-- --AAABBEEBBBBBBBBBBBEBBAAA-- --AAAB----------------BAAA-- --AAAB-DD--DD-DDD-D-D-BAAA-- --BAAB--D-D-D-D-D-DDD-BAAB-- ---AAB--D--DD-DDD-D-D-BAA--- ---AAB----------------BAA--- ---AABBBBBBBBBBBBBBBBBBAA--- ---AAAABBBBBBBBBBBBBBAAAA--- ---AAAABBBBBBBBBBBBBBAAAA--- ----AAABBBAABBBBAABBBAAA---- ----AAABBBAABBBBAABBBAAA---- -----AABBBAABBBBAABBBAA----- ------AAAAAABBBBAAAAAA------ ------AAAAAABBBBAAAAAA------ ------AAAAAABBBBAAAAAA------ -------AAAAAAAAAAAAAA------- --------AAAAAAAAAAAA-------- ---------------------------- ---------------------------- ---------------------------- 
---------------------------- ---------------------------- ------BBBBB------BBBBB------ ---------------------------- --BA--------------------AB-- --BA--------------------AB-- --BA--------------------AB-- --BA--------------------AB-- --BA--------------------AB-- --AA--------------------AA-- --BA--------------------AB-- --BA--------------------AB-- --BA--------------------AB-- ---------------------------- ---------------------------- ---------------------------- ---------------------------- ---------------------------- ---------------------------- ---------------------------- ---------------------------- ---------------------------- ---------------------------- ------BBBBB------BBBBB------ ---------------------------- ---------------------------- ---------------------------- ---------------------------- ---------------------------- 
---------------------------- ---------------------------- ------BBBBB------BBBBB------ ---------------------------- ---------------------------- ---------------------------- ---------------------------- ---------------------------- ---------------------------- ---------------------------- ---------------------------- ---------------------------- ---------------------------- ---------------------------- ---------------------------- ---------------------------- ---------------------------- ---------------------------- ---------------------------- ---------------------------- ---------------------------- ---------------------------- ---------------------------- ------BBBBB------BBBBB------ ---------------------------- ---------------------------- ---------------------------- ---------------------------- ---------------------------- 
---------------------------- ---------------------------- ------AABAA------AABAA------ ---------------------------- ---------------------------- ---------------------------- ---------------------------- ---------------------------- ---------------------------- ---------------------------- ---------------------------- ---------------------------- ---------------------------- ---------------------------- ---------------------------- ---------------------------- ---------------------------- ---------------------------- ---------------------------- ---------------------------- ---------------------------- ---------------------------- ---------------------------- ------AABAA------AABAA------ ---------------------------- ---------------------------- ---------------------------- ---------------------------- ---------------------------- 
---------------------------- ---------------------------- ------AABAA------AABAA------ ------AABAA------AABAA------ ---------------------------- ---------------------------- ---------------------------- ---------------------------- ---------------------------- ---------------------------- ---------------------------- ---------------------------- ---------------------------- ---------------------------- ---------------------------- ---------------------------- ---------------------------- ---------------------------- ---------------------------- ---------------------------- ---------------------------- ---------------------------- ------AABAA------AABAA------ ------AABAA------AABAA------ ---------------------------- ---------------------------- ---------------------------- ---------------------------- ---------------------------- 
---------------------------- ---------------------------- ---------------------------- ------AABAA------AABAA------ ---------------------------- ---------------------------- ---------------------------- ---------------------------- ---------------------------- ---------------------------- ---------------------------- ---------------------------- ---------------------------- ---------------------------- ---------------------------- ---------------------------- ---------------------------- ---------------------------- ---------------------------- ---------------------------- ---------------------------- ---------------------------- ------AABAA------AABAA------ ---------------------------- ---------------------------- ---------------------------- ---------------------------- ---------------------------- ---------------------------- 
---------------------------- ---------------------------- ---------------------------- ------AABAA------AABAA------ ---------------------------- ---------------------------- ---------------------------- ---------------------------- ---------------------------- ---------------------------- ---------------------------- ---------------------------- ---------------------------- ---------------------------- ---------------------------- ---------------------------- ---------------------------- ---------------------------- ---------------------------- ---------------------------- ---------------------------- ---------------------------- ------AABAA------AABAA------ ---------------------------- ---------------------------- ---------------------------- ---------------------------- ---------------------------- ---------------------------- 
---------------------------- ---------------------------- ---------------------------- ------AABAA------AABAA------ ------AABAA------AABAA------ ---------------------------- ---------------------------- ---------------------------- ---------------------------- ---------------------------- ---------------------------- ---------------------------- ---------------------------- ---------------------------- ---------------------------- ---------------------------- ---------------------------- ---------------------------- ---------------------------- ---------------------------- ---------------------------- ------AABAA------AABAA------ ------AABAA------AABAA------ ---------------------------- ---------------------------- ---------------------------- ---------------------------- ---------------------------- ---------------------------- 
---------------------------- ---------------------------- ---------------------------- ---------------------------- ------AABAA------AABAA------ ---------------------------- ---------------------------- ---------------------------- ---------------------------- ---------------------------- ---------------------------- ---------------------------- ---------------------------- ---------------------------- ---------------------------- ---------------------------- ---------------------------- ---------------------------- ---------------------------- ---------------------------- ---------------------------- ------AABAA------AABAA------ ---------------------------- ---------------------------- ---------------------------- ---------------------------- ---------------------------- ---------------------------- ---------------------------- 
---------------------------- ---------------------------- ---------------------------- ---------------------------- ------AABAA------AABAA------ ------AABAA------AABAA------ ------AABAA------AABAA------ ------AABAA------AABAA------ ------AABAA------AABAA------ ------AABAA------AABAA------ ------AABAA------AABAA------ ------AABAA------AABAA------ ------AABAA------AABAA------ ------AABAA------AABAA------ ------AABAA------AABAA------ ------AABAA------AABAA------ ------AABAA------AABAA------ ------AABAA------AABAA------ ------AABAA------AABAA------ ------AABAA------AABAA------ ------AABAA------AABAA------ ------AABAA------AABAA------ ---------------------------- ---------------------------- ---------------------------- ---------------------------- ---------------------------- ---------------------------- ---------------------------- 
