model
size = 27 32 27, scale = 0.05, origin = -y
material 
  colors = A:#FC0 B:#E00 C:#D00 D:#C03 E:#F03 F:#B00 G:#700 H:#800
voxels
39-3(3A24-)3A23-AC2BA22-ACDBA22-AC2BA22-A3BA22-A2BGA22-A3BA22-ABDBA22-A2BC2(A22-A3B)A22-AF2BA22-AD2B2(A22-A3B)A22-A2BHA22-A3BA22-AG2BA22-A3BA22-A2BFA22-A3BA22-AEDFA22-A2EBA23-3(3A24-)3A49-8(7A20-)7A18-A-7A-A17-9A19-2(7A20-)7A18-2(11A16-)11A18-3(7A20-)7A19-9A17-A-7A-A18-8(7A20-)7A18-6(11A16-)11A14-A-11A-A13-13A15-11A17-9A19-2(7A20-)7A16-2(15A12-)15A16-3(7A20-)7A19-9A17-11A15-13A13-A-11A-A14-6(11A16-)11A14-5(4A7-4A12-)4A7-4A11-5A7-5A11-4A7-4A13-3A7-3A15-2A7-2A17-A7-A95-2(5A7-5A10-)5A7-5A122-A7-A17-2A7-2A15-3A7-3A13-4A7-4A11-5A7-5A11-5(4A7-4A12-)4A7-4A2(11-3A)4(10-3A11-3A)9-4A11-4A9-2(3A11-)2A11-2A13-A11-A146-2(4A11-4A8-)4A11-4A173-A11-A13-2(2A11-)3A11-3A9-4A11-4A9-4(3A11-3A10-)3A11-3A9-3(3A13-3A8-)3A13-3A7-4A13-4A7-3A13-3A9-2A13-2A11-A13-A171-2(4A13-4A6-)4A13-4A198-A13-A11-2A13-2A9-3A13-3A7-4A13-4A7-3(3A13-3A8-)3A13-3A7-2(3A15-3A6-)3A15-3A5-4A15-4A5-3A15-3A7-2A15-2A9-A15-A196-2(4A15-4A4-)4A15-4A223-A15-A9-2A15-2A7-3A15-3A5-4A15-4A5-3(3A15-3A6-)2A17-2A6-2A17-2A5-3A17-3A5-2A17-2A6-2A17-2A7-A17-A222-2(3A17-3A4-)3A17-3A249-A17-A7-2A17-2A6-2A17-2A5-3A17-3A5-2A17-2A6-2A17-2A5-2A19-2A3-3A19-3A3-2A19-2A5-A19-A6-A19-A247-2(3A19-3A2-)3A19-3A274-A19-A6-A19-A5-2(2A19-2A3-3A19-3A3-)2A19-2A4-2A19-2A5-A19-A6-A19-A247-2(3A19-3A2-)3A19-3A274-A19-A6-A19-A5-2A19-2A4-2A19-2A3-3A19-3A37(2-2A21-2A)-3A21(21-6A)21-3A-5(2A21-2A2-)2A21-2A-3A3(21-6A)21-3AC2(2A21-2A2C)2A21-2ACB6(2A21-2A2B)2A21-2ABF2A21-2AFD2A21-2ADB3(2A21-2A2B)2A21-2ABG2A21-2AGB2(2A21-2A2B)2A21-2ABE2A21-2A2E2A21-2AE3A3(21-6A)21-3A-2A21-2A2-2A21-2A-3A3(21-6A)21-3AB2(2A21-2ABD2A21-2ADB3(2A21-2A2B))9(2A21-2A2B)2A21-2ABD2A21-2ADE2A21-2AE3A3(21-6A)21-3A-2A21-2A2-2A21-2A-3A3(21-6A)21-3AB3(2A21-2A2B)2A21-2ABG2A21-2AGB2A21-2A2B2A21-2ABC2A21-2ACB5(2A21-2A2B)2A21-2ABH2A21-2AHB2(2A21-2A2B)2(2A21-2ABF2A21-2AFB)2A21-2AB3A3(21-6A)21-3A-5(2A21-2A2-)2A21-2A-3A21(21-6A)21-3A-37(2A21-2A2-)3A19-3A3-2(2A19-2A4-)2(2A19-A5-)8(2A25-)2A24-2(3A19-3A2-)3A19-3A274-A19-A6-A2(19-A5-2A)19-A4-3A19-3A3-2A19-2A3-3A19-3A3-2A19-2A5-A19-A6-A19-A247-2(3A19-3A2-)3A19-3A274-A19-A6-A19-A5-2A19-A4-3A19-3A3-2A19-2A5-2A17-2A6-2A17-2A5-3A17-4A4-2A17-2A6-2A17-2A7-A17-A222-2(3A17-3A4-)3A17-3A249-A17-A7-2A17-2A6-2A17-2A5-3A17-4A4-2(2A17-2A6-)2(3A15-3A6-)3A15-3A5-4A15-4A5-3A15-3A7-2A15-2A9-A15-A196-2(4A15-4A4-)4A15-4A223-A15-A9-2A15-2A7-3A15-3A5-4A15-4A5-2(3A15-3A6-)3A15-3A7-3(3A13-3A8-)3A13-3A7-4A13-4A7-3A13-3A9-2A13-2A11-A13-A171-2(4A13-4A6-)4A13-4A198-A13-A11-2A13-2A9-3A13-3A7-4A13-4A7-3(3A13-3A8-)3A13-3A9-4(3A11-3A10-)3A11-3A9-4A11-4A9-2(3A11-)2A11-2A13-A11-A146-2(4A11-4A8-)4A11-4A173-A11-A13-2(2A11-)3A11-3A9-4A11-4A9-4(3A11-3A10-)2(3A11-)5(4A7-4A12-)4A7-4A11-5A7-5A11-4A7-4A13-3A7-3A15-2A7-2A17-A7-A95-2(5A7-5A10-)5A7-5A122-A7-A17-2A7-2A15-3A7-3A13-4A7-4A11-5A7-5A11-5(4A7-4A12-)4A7-4A14-6(11A16-)11A14-A-11A-A13-13A15-11A17-9A19-2(7A20-)7A16-2(15A12-)15A16-3(7A20-)7A19-9A17-11A15-13A13-A-11A-A14-6(11A16-)11A18-8(7A20-)7A18-A-7A-A17-9A19-2(7A20-)7A18-2(11A16-)11A18-3(7A20-)7A19-9A17-A-7A-A18-8(7A20-)7A49-3(3A24-)3A23-AC2BA22-ACDBA22-AC2BA22-A3BA22-A2BGA22-A3BA22-ABDBA22-A2BC2(A22-A3B)A22-AF2BA22-AD2B2(A22-A3B)A22-A2BHA22-A3BA22-AG2BA22-A3BA22-A2BFA22-A3BA22-AEDFA22-A2EBA23-3(3A24-)3A39-
