model
size = 24 31 15, scale = 0.05, origin = -y
material 
  colors = A:#FFF B:#EEE C:#009B00 D:#00B100 E:#008600
voxels
-----AABAAAABBAABAB----- -----AAABAAAABBABAB----- -----CCDEECDDECDCED----- -----CECEEEDCDCEDCD----- -----CDCCDCCDDCDCEC----- -----CEDECDCCDDDECC----- -----EDCABCCAAABCEE----- -----DCDAADCABABBCE----- -----CEEBADCEDCBBDC----- -----DCDABEDEDEBBEC----- -----EDDBBCECEDAADD----- -----CEEAACEDBBBAED----- -----EEDAADCDBBBAEE----- -----EDCABECCDDAADC----- -----CCEBBDDDCDBBCC----- -----CDBAAEEABBBAED----- -----CEEABEEBBABDED----- -----DCDDDEECCEDDEE----- -----CDECCEEEEDCDED----- -----DCCDCECDDEECDE----- -----CECCCCEDEDEDEC----- -----CBABBBBBBBBBAD----- -----BBA--------BAA----- -----BB----------BB----- -----A------------A----- -----A------------A----- ------------------------ ------------------------ ------------------------ ------------------------ ------------------------ 
---BBAAAABAABBBAAAAAA--- ---BABBAABBAAAAABBBAA--- ---EDAAAAABBABBAABACD--- ---CDBAABABAABBBABAEE--- ---DEABABBBAAABAABBCD--- ---CCAABAAAAABBBBABEE--- ---DCBABAAAABAABBBACD--- ---DEBBAAABABABABABEC--- ---EEBAAABABBBBAABADC--- ---CDABBBABBBBBABABCC--- ---CCABBABBAABBBABBEC--- ---DEBAAAABAAABABBBDD--- ---EDBABAAAABABAABADC--- ---DEAABBBBABABBABBDC--- ---DEABAAABBABBBBABEE--- ---EEABBBBAAABBABBBCC--- ---DDBBAAAABAAAAAAADC--- ---DCBABABBBABBBAABCD--- ---CDAAABABBABAAAABCD--- ---ADBBBBAABBAABBBBDB--- ---ACABBBBBABBBABABDB--- ---ACBBBBBBAAABBAABCA--- ---AEBBAABBBBBAABAACB--- ---ADAB----------AADA--- ---AAA------------BBB--- ---BBB------------ABB--- ---AA--------------AB--- ----B--------------A---- ------------------------ ------------------------ ------------------------ 
--AAB--------------ABA-- --BAA--------------AAB-- --EAA--------------ABD-- --EBA--------------ABD-- --EBA--------------AAC-- --DAA--------------AAE-- --EAA--------------ABE-- --DAB--------------BBE-- --DBB--------------BAE-- --DAA--------------BAD-- --DAA--------------BBD-- --EBA--------------AAC-- --EAA--------------ABD-- --EBA--------------BBE-- --CAB--------------ABD-- --DBA--------------ABD-- --DBA--------------BBC-- --BAB--------------BBA-- --BBA--------------AAB-- --BBA--------------AAA-- --BBA--------------ABA-- --ABA--------------BBA-- --BAB--------------ABB-- --BAA--------------BBB-- --ABA--------------AAA-- --BAB--------------BAB-- --BABA------------BABA-- --AAA--------------AAB-- ---B----------------B--- ------------------------ ------------------------ 
-AA------------------BB- -BA------------------AA- -EE------------------EC- -DB------------------BE- -EA------------------AC- -DB------------------BE- -EB------------------AE- -EB------------------BD- -DB------------------AD- -DA------------------AD- -DA------------------AC- -DB------------------AD- -CA------------------BC- -CB------------------AD- -EA------------------AE- -DB------------------BC- -AA------------------BB- -BB------------------BB- --B------------------A-- ------------------------ ------------------------ ------------------------ ------------------------ ------------------------ ------------------------ ------------------------ --A------------------B-- -BB------------------AB- -AA------------------BA- --AA----------------BB-- ------------------------ 
-A--------------------B- -A--------------------A- -D--------------------E- -E--------------------C- -C--------------------C- -E--------------------E- -D--------------------C- -D--------------------D- -E--------------------C- -D--------------------D- -E--------------------D- -C--------------------E- -D--------------------E- -C--------------------E- -C--------------------C- -C--------------------E- -A--------------------A- -A--------------------B- ------------------------ ------------------------ ------------------------ ------------------------ ------------------------ ------------------------ ------------------------ ------------------------ ------------------------ -B--------------------A- -A--------------------A- -B--------------------B- --AB----------------BB-- 
B----------------------A A----------------------A C----------------------C D----------------------C C----------------------D C----------------------D E----------------------C E----------------------E D----------------------D C----------------------E E----------------------D E----------------------C E----------------------C D----------------------D C----------------------C B----------------------B B----------------------B ------------------------ ------------------------ ------------------------ ------------------------ ------------------------ ------------------------ ------------------------ ------------------------ ------------------------ ------------------------ ------------------------ B----------------------A B----------------------B -BAB----------------ABB- 
A----------------------B B----------------------B C----------------------D D----------------------C C----------------------C E----------------------E E----------------------D D----------------------C C----------------------E C----------------------C D----------------------D C----------------------E D----------------------E C----------------------D D----------------------E B----------------------A A----------------------A ------------------------ ------------------------ ------------------------ ------------------------ ------------------------ ------------------------ ------------------------ ------------------------ ------------------------ ------------------------ ------------------------ B----------------------A A----------------------A -AA------------------AB- 
B----------------------A B----------------------B A----------------------A A----------------------A A----------------------A A----------------------A A----------------------A A----------------------A A----------------------A A----------------------A A----------------------A A----------------------A A----------------------A A----------------------A A----------------------A A----------------------B B----------------------A ------------------------ ------------------------ ------------------------ ------------------------ ------------------------ ------------------------ ------------------------ ------------------------ ------------------------ ------------------------ ------------------------ B----------------------A B----------------------B -AB------------------AA- 
B----------------------A A----------------------B D----------------------D C----------------------E C----------------------D C----------------------D C----------------------C D----------------------D C----------------------C D----------------------C E----------------------C C----------------------E D----------------------D D----------------------C C----------------------D B----------------------A B----------------------B ------------------------ ------------------------ ------------------------ ------------------------ ------------------------ ------------------------ ------------------------ ------------------------ ------------------------ ------------------------ ------------------------ B----------------------B A----------------------A -AA------------------AA- 
B----------------------A B----------------------B C----------------------D C----------------------E C----------------------C C----------------------E D----------------------C C----------------------E E----------------------D C----------------------C D----------------------E D----------------------E C----------------------C D----------------------C D----------------------C A----------------------B A----------------------A ------------------------ ------------------------ ------------------------ ------------------------ ------------------------ ------------------------ ------------------------ ------------------------ ------------------------ ------------------------ ------------------------ A----------------------A A----------------------A -BAB----------------BBB- 
-B--------------------B- -B--------------------B- -E--------------------E- -C--------------------E- -C--------------------E- -C--------------------D- -C--------------------C- -C--------------------E- -D--------------------C- -C--------------------D- -E--------------------D- -D--------------------E- -C--------------------C- -C--------------------C- -E--------------------C- -E--------------------C- -A--------------------A- -B--------------------B- ------------------------ ------------------------ ------------------------ ------------------------ ------------------------ ------------------------ ------------------------ ------------------------ ------------------------ -A--------------------B- -A--------------------B- -A--------------------B- --BA----------------AA-- 
-AA-----BA----AB-----BB- -BB-----BB----BB-----BB- -CB-----AA----BB-----AC- -CB-----AA----BB-----AC- -DA-----AB----BB-----AC- -DA-----BA----AA-----AC- -EA-----BA----BA-----BC- -CA-----BA----BB-----BE- -EB-----BA----AA-----AD- -EB-----AB----BA-----AE- -CB-----AB----AA-----BE- -DB-----AA----BA-----AE- -EB-----BA----AB-----BE- -CA-----BA----AB-----BC- -DA-----AA----BB-----AD- -EB-----BB----BB-----BE- -BA-----BB----BB-----AA- -BB-----AB----BA-----AA- --A-----BB----BB-----A-- ------------------------ ------------------------ ------------------------ ------------------------ ------------------------ ------------------------ ------------------------ --B------------------B-- -BB------------------BA- -BBA----------------BBA- --AB----------------AA-- ------------------------ 
--BBABBABAB--ABABBBBBB-- --BAAAAABAB--BAAABABBA-- --EBABAAAAA--ABABAAAAE-- --DABABBBBA--AAAAAAAAE-- --EAABBAABA--AAAABAAAE-- --CAABABBAB--AABBABAAD-- --DBABABBBA--BBBAAAAAC-- --DABABBAAA--BBABBAABE-- --EAAAABABB--BBBBBAABD-- --DABABAAAA--ABBBBABBE-- --CAAABBBAB--BBAAAAAAC-- --DBBBBBBBB--AAABBBBBD-- --CBBABABBA--ABBBBBABC-- --EAAAABBAB--ABBBBBBAD-- --EBAAABABA--AABBABBAD-- --CAABBBBAA--BABAABBAE-- --DAAAAAAAA--ABBAABBBD-- --BABBBABAA--BABBAAABA-- --BBABAAABB--AAABABAAA-- --AAABAAAAB--ABBAABBBA-- --ABBAABBAB--BABAABBAA-- --ABABBBAAA--AABBBABAB-- --BAB-BA--------AB-ABA-- --AAB-B----------B-ABA-- --BBB--------------AAA-- --BBB--------------BBB-- --BAA--------------BBB-- ---BA--------------BB--- ----A--------------A---- ----A--------------B---- ------------------------ 
---BBABBBBABABBAAABAB--- ---AAABBABBBABABAAABB--- ---CCAAAAAABBAAABAAEC--- ---EDBABBAAABBABBABED--- ---CDAAAABABABBBBAAEC--- ---DCAABBBAAAABABBADC--- ---DDAABBBBAABBABABED--- ---DEBAAAABAABBABABCE--- ---DCABAAAAAAABBAAACD--- ---EEAAABBABBBAAAABCD--- ---CCAABAABAABAAABBDE--- ---DEBAABABBBABAAAACE--- ---CCAAABBBBAABBBBADD--- ---DEABBABBAABAAAAADE--- ---DEBBBBBAAAAABABACD--- ---CEBBABBABBBBAAAAEE--- ---DCBBBBBABBBBAAABCD--- ---CEBBBABBBAABBBABDD--- ---ACBBAAAAAABAAAABDA--- ---AEAABABBABABAAAAEA--- ---BDBBBABABBABBBBADA--- ---BCBABBBABAAAAABADA--- ---BEABABABAABABABBEA--- ---ADBAAB------BAAADA--- ---ABBAB--------BAAAB--- ---BAB------------BAB--- ---BAB------------BBA--- ----AA------------BA---- -----B------------B----- ------------------------ ------------------------ 
-----BBBBAAAAAABBAA----- -----BBAAAABAAABABA----- -----ECEECEEEEEDDCD----- -----EDCCECCECDCEDC----- -----EEDCEECEEDDEEE----- -----DDCDDDEEECDEDD----- -----EDDCDEECDEECDE----- -----DCBEDBDDACCBEC----- -----ECBCCACDADDBDC----- -----DCBBAECDBABBCE----- -----ECBEDAEDACEAEE----- -----DDBBBBEEAABBCE----- -----CCDECECDECDDCE----- -----CEABBADDAAABED----- -----DCADEADCAEEAEE----- -----ECBAEBDEBEDBCC----- -----EDDDCBECBDCBCE----- -----ECBABAECAABBDE----- -----DEECEECEEECECD----- -----DDCCEDEECCECEE----- -----CDCBBABAABBCDD----- -----DCAABBBAABABEE----- -----EAAA------BBAE----- -----BBA--------AAB----- -----AA----------BA----- -----B------------A----- -----B------------B----- -----B------------B----- ------------------------ ------------------------ ------------------------ 
