model
size = 13 10 32, scale = 0.05, origin = -y
material 
  colors = A:#FFF B:#EEE C:#9FF D:#5FF E:#7FF F:#BEBEBE G:#E93E2D H:#E00F0B I:#D00 J:#E62E22 K:#EC4D38 L:#0F6 M:#F26C4F N:#EF5D44 O:#E31F17
voxels
4-2DECE9-EDE10-D2C10-2DE85-DE2C2D2ED6-2BABA8-3ABA8-4AB9-2BA71-ED2(CE)2C2DE4-2A2BABA6-2(AB)3A6-B4A2B7-3BAB70-2(ED)CEDE2CD3-2(B2A)3B4-2AB5AB4-3A4BAB5-2BA2B2A8-B2A57-CDE3DEDC2E2D-D2(3AB)AC2-E2BA4BABC3-AB3ABA2B5-B6A7-4AB56-2ECDC2E2DE3C-D2ABA3BABD2-CAB2ABA2BAD3-AB2A5B5-2AB4A7-2AB2A56-D4CD3ED2CE2-C2BAB2ABC3-E3BA3B2AC3-BA3B2A2B5-4A3B7-2(BA)B56-C2EDE4DE3C-D2AB3A2BAE2-D5BA2BAE3-2A2BABA2B5-2B4AB7-2BA2B56-CDCE2DC2EC2DE-EB2(A2B)ABE2-C2(3AB)AE4-2B2A2BA6-ABA3BA7-2AF2A56-4CDE2CD2CEC2-2B2A2(BA)B4-2ABA2B3A5-2BA3BA6-A4B2A7-5A10-F45-4CDED2CECDE3-A3BABA6-B4A2B6-BA3B2A6-A5-B7-F3AF9-FAF45-2(3ED)3C4-2ABAB2A6-3A2(BA)6-2(AB)A2B6-A5-B7-B3AB9-AFA45-DECDE4CDC3-E5BABD4-E4BABAC5-A2(B2A)6-B5-B7-5A9-AFA45-DED3CECD2C3-E2BA4BE4-C2B2A3BD5-A2B2ABA6-B5-B7-F3AF9-FAF45-2(2CDE)CED4-EAB2ABE5-C3(BA)BE5-2B2A2BA6-B5-B7-5A9-AFA45-E2(DC)DE2CED3-D3A3BAC4-D2B5AD5-BAB2A2B6-B5-B7-5A9-AFA45-CECD2(CE)DEC3-EBA3BABD4-EA4BABC5-A3B3A6-A5-B7-F3AF9-FBF45-C3D2(CDE)C4-4ABAB6-2B2ABAB6-2(AB)2A2(B6-A5-)A6-2ABF3A44-2C2ECDCEC6-C4D8-DB2AC7-4BAB2(A6-B5-)A6-7A8-AFA62-EDE9-3ABA7-A5-B6-B5-B6-2BAB3A7-2B2AB9-JKM20-C3EDCDED6-4CD8-EABAD7-ABA2BAB6-A2(5-B6-B)5-A6-2B3-BA7-HI-KH9-G-G6-C2D2CD2CEDE4-AB4AB6-2B3ABA6-2AB3AB6-BA2B2AB6-2B3-2B6-B5-A7-B3-B8-A3-A8-G3-G5-E5C3EDE3-BA2(B2A)B4-2ABAB2A2B5-A2BA3B6-A3BA2B6-2B3-A8-B3-B2(8-A3-A)8-N3-G4-E2C5DC4D-C2B2A4BAC2-CAB2A3BABE3-AB2AB4A4-3BA2B3A5-B5-A2(6-B5-B)6-A5-A6-M5-K3-4D2(EC)2D3C-D2(AB)A4BE2-CAB2AB4AC3-B2A3BABA4-BA5BA2(B5-)B6-B5-A2(6-B5-B)6-H5-G3-2C2D2ECDCE2DC2-DB2A2(BA)E3-C2BA2B2A2BC3-ABA2B4A4-2BABA2BA2(B5-)B6-A5-A6-B5-B6-A5-B6-I5-H3-2EC2DEDE2CDEC-CBAB2A2(BA)C2-D2BA3B2ABE3-2AB5AB4-2(AB)3ABA5-AB3-2A7-3(A3-B8-)J3-J4-E2DE4DCE3C-D3A2B3ABE2-CB4AB3AD3-2B4A2BA4-ABA4B2A5-BA-L-AB7-A-L-A8-B3-B8-A3-B8-OGINI5-DC4EC2EDC3-4BA3BA4-A2BABA3B5-ABA2B2A6-AB3A2B7-2B-2B8-2A-AB8-3BAB9-ABA19-ED3CD2CDEC4-BABDB2A6-AB2ABAB7-B2A2B8-B3AB71-2ECDEDCEC6-ED-2D8-CE2CD99-ECDEC121-
