model
size = 30 21 15, scale = 0.05, origin = -y
material 
  colors = A:#FFF B:#EEE C:#E31F17 D:#EC4D38 E:#E62E22 F:#5FF G:#EF5D44 H:#7FF I:#E93E2D J:#F26C4F K:#9FF L:#E00F0B M:#D00 N:#F7CB39 O:#F7D45F P:#F7DC85
voxels
-----LJLJM----------DCIDE----- ------------------------------ ------------------------------ ------------------------------ ------------------------------ ------------------------------ ------------------------------ ------------------------------ ------------------------------ ------------------------------ ------------------------------ ------------------------------ ------------------------------ ------------------------------ ------------------------------ ------------------------------ ------------------------------ ------------------------------ ------------------------------ ------------------------------ ------------------------------ 
---CELLGELMC------GJDEEIGLE--- -----MMMDD----------DMCCI----- -----CGCCL----------LJJJM----- -----JCIDC----------EJMGG----- -----MICJI----------CICGE----- ------------------------------ ------------------------------ ------------------------------ --------AAA--------BAB-------- ------AAABBAB----BAABBAA------ ------AABBBBAA--AABBBBAA------ -----BOOPAONPA--AOANBOBPA----- -----BNAPBNANB--ANAOANBOB----- -----BPBPBPABA--AOPNBAOOB----- -----AOAOAOBAB--BPAOANAPA----- -----BNNNAONNA--ANNNBOPPB----- ------AABABAAB--AABABBBA------ ------AAABBBA----AABBAAB------ --------ABB--------AAA-------- ------------------------------ ------------------------------ 
--MJM-----MJC----IGI-----MEE-- ---DC-----MM------EM-----CL--- ---IL-----GG------GL-----LI--- ---JL-----LE------CD-----EJ--- ---DL-----CJ------ED-----GC--- -----BBBBBBB------ABBABAB----- -----ABBAABA------BABABBA----- -----ABABAAB------BBBBAAA----- -----ABBAB-A------A-AABBB----- -----AAABABAB----ABAABBAA----- -----BBBBB---A--A---AAABB----- ----A--BBA------A---AAA--B---- ----B--AAB---BAA----BAB--A---- ----B--BBA----BB----ABB--B---- ----B---------BB---------A---- ----B---------BB---------A---- ----AB-------A--B-------BA---- ----AABAABBBA----ABBBBBABB---- -------AABBB------AABBB------- ------------------------------ ------------------------------ 
-CGE-------CIC--EME-------EDE- --GL-------ED----GL-------LJ-- --ED-------DC----CI-------DM-- --CE-------LM----JC-------MD-- --GD-------CC----II-------JI-- ----B-----A--------B-----B---- ----A-----A--------B-----B---- ----A-----B--------B-----A---- ----A-----B--------A-----A---- ----A-----A--------B-----B---- ----A-----B--------B-----B---- ----B-----BABBBAAAAA-----B---- ----A--------BBAA--------A---- ----B---------BA---------B---- ----A---------AB---------A---- ----A---------BA---------A---- ----A--------AAAA--------A---- ----A-------BBBBAB-------B---- ----FKHFFFFKKHHFHHKHHHFKHH---- ----HFKHKHFFHKHFHFFFHFFKFF---- ----FKHHFFHFKKKHKHKKFHFFKK---- 
-EI---------IL--JJ---------MC- --I---------G----L---------M-- --C---------M----M---------E-- --G---------J----M---------I-- --C---------G----L---------J-- ---A-------B------A-------B--- ---A-------A------A-------B--- ---B-------A------B-------A--- ---A-------A------A-------A--- ---B-------A------B-------A--- ---A-------B------B-------B--- ---B-------BBABABBB-------B--- ---A----------------------A--- ---B----------------------A--- ---B----------------------B--- ---B----------------------B--- ---B----------------------A--- ---A----------------------B--- ---K----------------------K--- ---F----------------------F--- ---H----------------------F--- 
GJ-----------G--D-----------JE -D-----------L--L-----------D- -M-----------E--M-----------E- -J-----------E--M-----------I- -J-----------E--I-----------E- --A---------A----A---------A-- --B---------A----A---------B-- --B---------A----A---------B-- --B---------B----B---------A-- --B---------B----A---------B-- --A---------A----A---------A-- --A---------ABBAAA---------A-- --B------------------------A-- --B------------------------A-- --B------------------------B-- --A------------------------B-- --A------------------------A-- --A------------------------B-- --K------------------------F-- --F------------------------F-- --K------------------------H-- 
MD-----------L--E-----------EE -E-----------L--I-----------D- -L-----------C--L-----------E- -L-----------M--C-----------C- -G-----------J--M-----------I- --B---------A----A---------B-- --A---------B----B---------B-- --A---------B----A---------B-- --A---------B----A---------B-- --A---------BB--BB---------A-- --B---------BABABA---------A-- --A------------------------B-- --A------------------------B-- --B------------------------A-- --A------------------------B-- --A------------------------B-- --A------------------------B-- --A------------------------B-- --K------------------------H-- --H------------------------K-- --H------------------------H-- 
CD-----------E--J-----------MG -I-----------J--E-----------L- -D-----------C--I-----------M- -E-----------D--J-----------D- -J-----------G--J-----------D- --B---------A----B---------A-- --A---------B----A---------A-- --A---------B----A---------A-- --A---------A----B---------B-- --A---------BB--BA---------A-- --A----------ABBA----------B-- --B------------------------A-- --A------------------------B-- --B------------------------B-- --B------------------------B-- --B------------------------B-- --A------------------------A-- --B------------------------A-- --H------------------------K-- --F------------------------K-- --H------------------------F-- 
GI-----------L--I-----------CG -D-----------G--L-----------D- -M-----------C--G-----------I- -D-----------G--C-----------E- -D-----------C--M-----------C- --B---------B----B---------B-- --B---------B----A---------B-- --B---------A----A---------A-- --B---------A----B---------A-- --A---------BA--BA---------A-- --B----------AABA----------A-- --A------------------------A-- --A------------------------B-- --A------------------------A-- --A------------------------A-- --A------------------------A-- --A------------------------A-- --A------------------------B-- --K------------------------F-- --H------------------------H-- --H------------------------K-- 
ED-----------J--G-----------EG -J-----------C--E-----------C- -I-----------E--C-----------C- -L-----------D--J-----------G- -I-----------I--D-----------D- --B---------A----B---------A-- --A---------A----A---------B-- --A---------B----A---------B-- --B---------A----A---------B-- --A---------A----A---------B-- --B---------ABAAAA---------A-- --A------------------------A-- --B------------------------B-- --A------------------------A-- --B------------------------B-- --B------------------------B-- --B------------------------A-- --A------------------------A-- --H------------------------F-- --F------------------------H-- --H------------------------K-- 
-JE---------GC--GM---------EM- --M---------E----G---------E-- --D---------D----M---------G-- --E---------C----C---------E-- --E---------G----J---------I-- ---B-------A------A-------A--- ---B-------A------B-------A--- ---B-------B------B-------A--- ---B-------A------B-------A--- ---A-------A------B-------A--- ---A-------B-BBAB-A-------B--- ---A-------BBBAAAAB-------A--- ---A---------ABBA---------A--- ---B--------BBABBB--------A--- ---B--------BABABA--------A--- ---A--------ABAABA--------B--- ---A--------ABABBA--------A--- ---B--------ABAABB--------A--- ---H----------------------H--- ---F----------------------F--- ---K----------------------H--- 
-DGI-------CCL--GLJ-------ELG- --LJ-------CC----DE-------IJ-- --GJ-------ED----CD-------CC-- --DM-------GI----DD-------LC-- --CM-------GL----JL-------JI-- ----A-----A--------A-----B---- ----A-----A--------B-----A---- ----A-----A--------A-----B---- ----A-----B--------B-----B---- ----B-----A--------B-----B---- ----A-----B---BB---A-----A---- ----B-----AA-BBAA-AB-----A---- ----B----BBBBABABBAAB----A---- ----A----BBAABBBAABAA----B---- ----B----ABABBAABBAAB----A---- ----A----AAABABBBABAB----A---- ----A----BBBABAAABBAA----B---- ----B----BBBABBABAAAA----A---- ----K----KHFHKFKHHFFF----F---- ----K----KKFKFKHHFKHK----F---- ----F----KFKFFKFFFFKF----H---- 
--ILE-----IIL----DID-----MJG-- ---CE-----IE------DM-----GC--- ---DD-----JI------CJ-----CD--- ---JG-----IE------GG-----DD--- ---CL-----ED------CL-----LG--- -----AABBA----------ABBBA----- -----ABAAA----------ABBBB----- -----AAABA----------ABAAA----- -----BBBBA----------BABBA----- -----BAABB----------BBBBA----- -----BAAAA----------BABAA----- -----AABAB----------ABABB----- -----BABA-----BA-----ABBB----- -----BBBB----AABB----AAAB----- -----BAAA----BBBB----BBBA----- -----ABBA----ABBA----AABA----- -----BABB----ABAA----ABBA----- -----AABA----AAAA----BAAA----- -----KHHK------------HKFK----- -----FFKH------------HFHF----- -----HHKK------------HFFF----- 
---MMIDLJCLC------IMDIDDEGC--- -----DDGGG----------MIDGC----- -----GJCEE----------DGIEI----- -----GJCII----------MGEEL----- -----IGLCC----------DMDEJ----- ------------------------------ ------------------------------ ------------------------------ ------------------------------ ------------------------------ ------------------------------ ------------------------------ ------------------------------ ------------------------------ ------------------------------ ------------------------------ ------------------------------ ------------------------------ ------------------------------ ------------------------------ ------------------------------ 
-----JLMDC----------DEDJG----- ------------------------------ ------------------------------ ------------------------------ ------------------------------ ------------------------------ ------------------------------ ------------------------------ ------------------------------ ------------------------------ ------------------------------ ------------------------------ ------------------------------ ------------------------------ ------------------------------ ------------------------------ ------------------------------ ------------------------------ ------------------------------ ------------------------------ ------------------------------ 
