model
size = 26 32 26, scale = 0.05, origin = -y
material 
  colors = A:#FFF B:#100 C:#222 D:#383838 E:#333 F:#777 G:#DDD H:#CCC I:#444 J:#555 K:#AAA L:#999 M:#666 N:#BBB O:#888
voxels
10-2E4I2E17-8C3(18-8A)18-LG4AGL18-8D18-3N2HG2A18-BDCEIMFL18-CBJHLMED18-2BDI2EIJ18-MOLKHG2A18-2AK2C3A18-2FC2BJ2F18-2CB5C18-NG6A18-DBDCEJFL18-OBDNKFJC18-E2B2IE2I18-JFLKNG2A18-8A18-7DC18-8G18-8A18-3AIDI2A18-M2F3B2F18-2CE2B2CE18-8A18-3JIEC2B18-O3F2EFO18-2BCEFKHA18-NKOMI3B32(18-8A)16-31(2A8-2A14-)2A8-2(2A12-)31(2A10-2A12-)2A9-31(A16-A8-)A16-A7-31(A18-A6-)A18-A5-63(A20-A4-)A20-A3-63(A22-A2-)A22-A-A255(24-2A)24-A-63(A22-A2-)A22-A3-63(A20-A4-)A20-A5-31(A18-A6-)A18-A7-31(A16-A8-)A16-A9-AC12-BK10-2A12-DK10-AL12-JG10-HB12-BF10-HB12-DN10-2A12-GA10-AM12-2A10-AJ12-2A10-2A12-BK10-AN12-KG10-KD12-2A10-2A12-BK10-AF12-BL10-HJ12-MH10-AO12-2A10-AF12-2A10-2A12-BJ10-AG12-LH10-AJ12-NG10-2A12-BI10-HJ12-BJ10-2A12-BJ10-AG12-FL10-HI12-DM10-KE12-BC10-KE12-CE10-2A12-2A10-HO12-BI10-2A12-HG10-HM12-2A10-2A12-EO10-HM12-DM12-2C8-DB14-2A8-KD14-OL8-LJ14-BF8-KB14-BC8-CB14-OI8-EO14-LK8-2A14-EC8-NH14-2A8-2B14-LF8-MO14-CI8-2A14-2A8-NB14-2F8-IB14-2B8-2B14-FL8-2A14-EC8-NH14-2A8-2B14-KL8-JF14-CE8-AH14-2A8-GB14-2D8-2D14-AG8-HD14-2H8-AF14-BC8-AE14-2B8-MB14-BC8-EB14-2A8-2A14-JM8-2B14-AK8-LK14-CD8-2A14-AG8-DB14-2E8-2C7-
