model
size = 32, scale = 0.05, origin = -y
material 
  colors = A:#450082 B:#EEE C:#8400C0 D:#F500F8 E:#120051 F:#00FDC3 G:#111
voxels
128-32F867-7(29E2-30A-31CF31B-2F29B3-2E27B5-AE25A7-25A9-C22A10-22A11-21A12-C19A13-19A14-C17A15-17A16-16C17-15C17-A2(14C18-)14C2(19-2C11D)20-12D20-12C2(21-11D)22-C9D22-10D2(23-9D)24-8D24-F7G3-)29E2-30A-31CF31B-2F29B3-2E27B5-AE25A7-25A9-C22A10-22A11-21A12-C19A13-19A14-C17A15-17A16-16C17-15C17-A2(14C18-)14C2(19-2C11D)20-12D20-12C2(21-11D)22-C9D22-10D2(23-9D)24-F7D24-8F3-29E2-30A-31CF31B-2F29B3-2E27B5-AE25A7-25A9-C22A10-22A11-21A12-C19A13-19A14-C17A15-17A16-16C17-15C17-A2(14C18-)14C2(19-2C11D)20-12D20-12C2(21-11D)22-C9D22-10D2(23-F8D)67-29E2-30A-31CF31B-2F29B3-2E27B5-AE25A7-25A9-C22A10-22A11-21A12-C19A13-19A14-C17A15-17A16-16C17-15C17-A2(14C18-)14C2(19-2C11D)20-12D20-12C2(21-11D)22-F9C22-F9D131-29E2-30A-31CF31B-2F29B3-2E27B5-AE25A7-25A9-C22A10-22A11-21A12-C19A13-19A14-C17A15-17A16-16C17-15C17-A2(14C18-)14C2(19-2C11D)20-12D20-12C2(21-F10D)195-29E2-30A-31CF31B-2F29B3-2E27B5-AE25A7-25A9-C22A10-22A11-21A12-C19A13-19A14-C17A15-17A16-16C17-15C17-A2(14C18-)14C2(19-2C11D)20-F11D20-F11C259-29E2-30A-31CF31B-2F29B3-2E27B5-AE25A7-25A9-C22A10-22A11-21A12-C19A13-19A14-C17A15-17A16-16C17-15C17-A2(14C18-)14C2(19-F12C)323-29E2-30A-31CF31B-2F29B3-2E27B5-AE25A7-25A9-C22A10-22A11-21A12-C19A13-19A14-C17A15-17A16-16C17-15C17-A14C2(18-F13C)387-29E2-30A-31CF31B-2F29B3-2E27B5-AE25A7-25A9-C22A10-22A11-21A12-C19A13-19A14-C17A15-17A16-16C17-F14C17-F14A451-29E2-30A-31CF31B-2F29B3-2E27B5-AE25A7-25A9-C22A10-22A11-21A12-C19A13-19A14-C17A15-17A16-F15C515-29E2-30A-31CF31B-2F29B3-2E27B5-AE25A7-25A9-C22A10-22A11-21A12-C19A13-19A14-C17A15-F16A547-29E2-30A-31CF31B-2F29B3-2E27B5-AE25B7-25A9-C22A10-22A11-21A12-C19A13-19A14-F17C579-29E2-30A-31CF31B-2F29B3-2E27B5-AE25B7-25A9-C22A10-22A11-21A12-C19A13-F18A611-29E2-30A-31CF31B-2F29B3-2E27B5-AE25B7-25A9-C22A10-22A11-21A12-F19C643-29E2-30A-31CF31B-2F29B3-2E27B5-AE25B7-25A9-C22A10-22A11-F20A675-29E2-30A-31CF31B-2F29B3-2E27B5-AE25B7-25A9-C22A10-F21A707-29E2-30A-31CF31B-2F29B3-2E27B5-AE25B7-25A9-F22C739-29E2-30A-31CF31B-2F29B3-2E27B5-AE25B7-AF23A771-29E2-30A-31CF31B-2F29B3-2E27B5-AE25B7-F24A771-29E2-30A-31CF31B-2F29B3-2E27B5-AF25E803-29E2-30A-31CF31B-2F29B3-2E27B5-F26A803-29E2-30A-31CF31B-2F29B3-EF27E835-29E2-30A-31CF31B-2F29B3-F28E866-30A-31CFB30F-31F929-31CFB30F-31F864-
