model
size = 30 29 9, scale = 0.05, origin = -y
material 
  colors = A:#450082 B:#120051 C:#90F
voxels
------------------------------ ------------------------------ ------------------------------ ------------------------------ ------------------------------ ------------------------------ ------------------------------ ------------------------------ ------------------------------ ------------------------------ ------------------------------ ------------------------------ ------------------------------ ------------------------------ ------------------------------ ------------------------------ ------------------------------ ------------------------------ ------------------------------ ------------------------------ ------------------------------ ------------------------------ ------------------------------ ------------------------------ ------------------------------ BBBBBB--BBBBBB--BBBBBB--BBBBBB BBBBBB--BBBBBB--BBBBBB--BBBBBB BBBBBB--BBBBBB--BBBBBB--BBBBBB BBBBBB--BBBBBB--BBBBBB--BBBBBB 
------------------------------ ------------------------------ ------------------------------ ------------------------------ ------------------------------ ------------------------------ ------------------------------ ------------------------------ ------------------------------ ------------------------------ ------------------------------ ------------------------------ ------------------------------ ------------------------------ ------------------------------ ------------------------------ ------------------------------ ------------------------------ ------------------------------ ------------------------------ ------------------------------ ------------------------------ ------------------------------ ------------------------------ ------------------------------ -------------------------AAA-- -AAAA----AAAA----AAAA----AAAA- -AAAA----AAAA----AAAA----AAAA- ------------------------------ 
------------------------------ ------------------------------ ------------------------------ ------------------------------ ------------------------------ ------------------------------ ------------------------------ ------------------------------ ------------------------------ ------------------------------ ------------------------------ ------------------------------ ------------------------------ ------------------------------ ------------------------------ ------------------------------ ------------------------------ ------------------------------ ------------------------------ ------------------------------ ------------------------------ ------------------------------ ------------------------------ ------------------------------ ------------------------------ -------------------------AAA-- -AAAA----AAAA----AAAA----AAAA- -AAAA----AAAA----AAAA----AAAA- ------------------------------ 
-AAAA------------------------- -AAAA------------------------- -AAAA------------------------- -AAAA------------------------- -AAAA------------------------- -AAAA------------------------- -CAAC------------------------- -AAAA------------------------- -AAAA------------------------- -AAAA------------------------- -AAAA------------------------- -CAAC------------------------- -AAAA------------------------- -AAAA------------------------- -AAAA------------------------- -AAAA------------------------- -AAAA------------------------- -CCCC------------------------- -AAAA------------------------- -AAAA------------------------- -AAAA------------------------- -AAAA------------------------- -AAAA------------------------- -AAAA------------------------- -CCCC------------------------- -AAAA------------CCCC----AAAA- -AAAA----AAAA----AAAA----AAAA- --AA------AA------AA------AA-- ------------------------------ 
-AAAA--------------------AAAA- -AAAA--------------------AAAA- -AAAA--------------------AAAA- -AAAA--------------------AAAA- -AAAA--------------------AAAA- -AAAA--------------------CCCC- -CCCC--------------------AAAA- -AAAA--------------------AAAA- -AAAA--------------------AAAA- -AAAA--------------------AAAA- -AAAA--------------------AAAA- -CCCC--------------------AAAA- -AAAA--------------------CCCC- -AAAA--------------------AAAA- -AAAA--------------------AAAA- -AAAA--------------------AAAA- -AAAA--------------------AAAA- -CCCC--------------------AAAA- -AAAA--------------------AAAA- -AAAA--------------------CCCC- -AAAA--------------------AAAA- -AAAA--------------------AAAA- -AAAA--------------------AAAA- -AAAA--------------------CCCC- -CCCC----AAAA----AAAA----AAAA- -AAAA----AAAA----CCCC----AAAA- --AA-----AAAA-----AA-----AAA-- ------------------------------ ------------------------------ 
--AA----------------------AA-- --AA----------------------AA-- --AA----------------------AA-- --AA----------------------AA-- --AA----------------------AA-- --AA----------------------AA-- --AA----------------------AA-- --AA----------------------AA-- --AA----------------------AA-- --AA----------------------AA-- --AA----------------------AA-- --AA----------------------AA-- --AA----------------------AA-- --AA----------------------AA-- --AA----------------------AA-- --AA----------------------AA-- --AA----------------------AA-- --AA----------------------AA-- --AA----------------------AA-- --AA----------------------AA-- --AA----------------------AA-- --AA----------------------AA-- --AA----------------------AA-- --AA-------------AAAA-----AA-- --AA-----AAAA----AAAA-----AA-- --AA-----AAAA-----AA------AA-- --AA------AA------------------ ------------------------------ ------------------------------ 
---------AAAA------AA--------- ---------AAAA------AA--------- ---------AAAA------AA--------- ---------AAAA------AA--------- ---------AAAA------AA--------- ---------AAAA------AA--------- ---------AAAA------AA--------- ---------CCCC------AA--------- ---------AAAA------AA--------- ---------AAAA------AA--------- ---------AAAA------AA--------- ---------AAAA------AA--------- ---------AAAA------AA--------- ---------AAAA------AA--------- ---------AAAA------AA--------- ---------AAAA------AA--------- ---------CCCC------AA--------- ---------AAAA------AA--------- ---------AAAA------AA--------- ---------AAAA------AA--------- ---------CCCC------AA--------- ---------AAAA------CC--------- ---------AAAA----AAAA--------- ---------AAAA----AAAA--------- ---------AAAA-----AA---------- ----------AA------------------ ------------------------------ ------------------------------ ------------------------------ 
----------AA-----AAAA--------- ----------AA-----AAAA--------- ----------AA-----AAAA--------- ----------AA-----AAAA--------- ----------AA-----CCCC--------- ----------AA-----AAAA--------- ----------AA-----AAAA--------- ----------AA-----AAAA--------- ----------AA-----AAAA--------- ----------AA-----AAAA--------- ----------AA-----CCCC--------- ----------AA-----AAAA--------- ----------AA-----AAAA--------- ----------AA-----CCCC--------- ----------AA-----AAAA--------- ----------AA-----AAAA--------- ----------AA-----AAAA--------- ----------AA-----AAAA--------- ----------AA-----AAAA--------- ----------AA-----AAAA--------- ----------AA-----AAAA--------- ----------AA-----CCCC--------- ----------AA-----AAAA--------- ----------AA------------------ ----------AA------------------ ------------------------------ ------------------------------ ------------------------------ ------------------------------ 
------------------AA---------- ------------------AA---------- ------------------AA---------- ------------------AA---------- ------------------AA---------- ------------------AA---------- ------------------AA---------- ------------------AA---------- ------------------AA---------- ------------------AA---------- ------------------AA---------- ------------------AA---------- ------------------AA---------- ------------------AA---------- ------------------AA---------- ------------------AA---------- ------------------AA---------- ------------------AA---------- ------------------AA---------- ------------------AA---------- ------------------AA---------- ------------------AA---------- ------------------AA---------- ------------------------------ ------------------------------ ------------------------------ ------------------------------ ------------------------------ ------------------------------ 
