model
size = 31 32 32, scale = 0.05, origin = -y
material 
  colors = A:#FFB11B B:#F7C242 C:#777 D:#444 E:#555 F:#222
voxels
35-2(B30-)B113-3A25-4(7A24-)7A23-B3-4A27-4A19-2B6-4A25-B-2(4A27-)4A439-3B28-3B17-2B9-3B17-2B8-12A9-2B8-2(12A19-)12A5-A2-7A4-4(12A8-6A-A3-)12A8-6A-A22-5(7A-A4-15A3-)9A4-15A3-8A5-2(15A3-7A6-)15A3-7A19-2A3-7A5(25-6A)130-6B25-A5B5A9-2B8-A6B4-2A7-3B8-A6B15AB8-2(22A9-)27A4-22A5-A3-18A-3A5-A3-13A6-3A5-A3-13A7-2A5-A3-13A6-4A4-A7-9A6-4A4-A4-15A3-5A3-AB3-12A10-A3-AB2-16A2(3-A)2B-A3-16A3-AB2-2(A3-)16A2(3-A)2-2A3-16A3-8A4-2(16A3-7A5-)16A3-7A19-2A3-7A5(23-8A)130-6B25-11A19-A6B4-2A7-3B8-A6B5-10AB8-A11-7A3B8-BA11-8A2B8-DA11-15A3-DA11-10A5-A3-A11-6A-3A5-A3-A11-A6-3A5-A3-A11-A7-2A5-A3-13A6-4A4-A7-9A6-4A4-A14-2(5A3-)AB2-B10-2A10-A3-AB2-A11-4A2(3-A)2B-A3-A11-4A4(3-A)9-2B4A2(3-A)2-2A3-A9-2B2(4A3-9A3-A11-)4A3-9A3-16A3-9A17-2A3-9A21-10A21-3(8A23-)8A161-11A19-A10-2A7-3B8-A11-10AB8-A11-10A9-A11-10A8-DA11-15A2-FDA11-10A5-A-2DA11-6A-3A5-A2-2A11-A6-3A5-A2-2A11-A7-2A5-AC-14A6-4A4-AC-A4-9A6-4A4-A2CA11-2(5A3-)A-CAB10-2A10-A3-A-C2A10-5A3-A3-2AB-A-2CA10-5A3-A3-2A2-AC-CA9-B5A3-A3-2A-2AC-CA9-B2(5A3-9AC2-A10-)5A3-9A3-16A3-9A10-3B-5A3-9A10-2B9-10A21-8A2C21-2(8AC22-)8AC27-4C129-11A19-A10-2A7-3B8-A11-10AB8-A11-10A9-A11-10A8-DA11-15A3-DA11-10A5-A-2CA11-6A-3A5-A-C2A11-A6-3A5-A2C2A11-A7-2A5-A2C14A6-4A4-A-CA4-6A6B3-4A4-A2CA10-B2(5A3-)AC-AB10-2A10-A3-AC-2A10-5A3-A3-2AB-AC2-A10-5A3-A3-2A2-AC2-A9-B5A3-A3-2A-2A2-CA9-B5A3-9A2-CA10-5A3-9AC-CA10-5A3-9AC2-16A3-9AC9-3B-5A3-9AC9-2B9-10AC20-8A-2C20-2(8A23-)8A28-C132-11A19-A10-2A7-3B8-A11-10AB8-2(A11-10A9-)A11-15A4-A11-10A5-A3-A11-10A5-A2-2A11-A5-4A5-AC-2A11-A7-2A5-A2-14A6-4A-2A-A2-A4-6A9B4A-2A-A2-A10-B2(5A3-)A2-A11-2A10-A3-A2-2A10-5A3-A3-2A2-A3-A10-5A3-A3-2A2-A2-BA10-5A3-A3-2AB2A2(2-BA6-4B5A3-9A)2-CA6-4B5A3-9A3-16A3-9A10-3B-5A3-9A5-2C14-10A6-C14-8A8-4C8-2(11A11-3D6-)11A20-6A2-C107-2B23-11A19-A10-2A18-3(A11-10A9-)A11-15A2-2BA11-10A3-2BA3BA11-10A3-2BA-B2A11-A5-4A3-2BAC-2A11-5A3-2A3-2BAC-18A2-6A2BA2-11A9B6A2BA2-2A5B4-B13A3-A2-2A5B5-2A14-A2-2A2(5B5-9A4-A2-A3-A)5B5-9A4-A-2A3-A5B-4B16A4-2(A6-4B15A4-C)14A3B9A4-4C23A7-C2(14A-8A8-)23A8-23A11-3D6-11A20-6A2-C107-2B23-11A19-A2-10A18-2(A2-8A-10A9-)A2-8A-10A4-B4-A2-8A-15A2-2BA2-8A-10A3-2BA3BA2-8A-10A3-2BA-2BA2-8A-A12-2BA3-A2-8A-5A8-2BAC2-17A4-2AB-2BA3-10A9B2-4A2BA3-A5B4AB12A4-A3-A5B7A14-2(A3-A5B14A4-A2-)A3-A5B14A4-A-2A3-A5BA4B16A4-2(A2-4A4B15A5-)14A3B9A8-23A8-14A-8A3(8-23A)10-10C11A20-6A3C26-2AC14-9C6-C15-10C219-10A21-11A20-10A21-10A13-B7-10AC12-B-A5-10A14-8B9A5-4B5-B17A4-4B6-A6-10A3(4-4B6-17A)4-4B6-16A15-2(15A16-)3A3B9A8-23A8-14A3-6A3(8-23A)8-D12C10A8-2D-8C-6A16-8C5-2A14-10C6-C14-3C6E3C77-13A18-24A7-24A9-22A2-B6-25A6-A2-20A2BAB4-A2-20A2(3B2-4A2-8A4-8A)3BD-4A2-8A4-6ABA3B3-10A8B7A3B3-10AB17A4(3-28A)3-27A4-10A-10A2B2A6-10A-13A7-10A-13A10-21A10-14A15-2(2D18A11-)2D18A12-2D12C3-2A13-2D10C4-2A15-10C3-C2A14-12C2-3C14-2C2E4D2E2C77-13A18-A11-3(12A7-6A6-)15A4-6A2(6-16A2-7A)6-A4-11AD-7A6-A4-11AF-4A2-8A4-11AD2-13A4-11A3-3(A3B3A3B16A5-)A3B22A5-2(A3-21A4-C-)A3-18AB2A4-C-A3-21A4-C-19A2B4A4-C4-16A2B4A4-C4-11AB2A2-3B7-3C2(2D18A11-)2D18A12-D-12CD2C2A15-10C2D-C2A15-10C3-C2A14-12C19-C2E2D2F2D2EC77-13A4-4B10-A2-B8-12A7-3AB2A2(6-12A6-D6A)6-15A4-6A6-16A-2C6A6-16A-C7A6-A4-11ADC7A6-A4-6A-4AD-14A4-6A-4AD2-13A4-6A-4A-2BA3B20A7-A3B9A10-A7-A3B9A10-2A4-2BA3B9A10-2A6-A3-9A7-B2-2A4-C-A3-9A7-B-3A6-A3-8A8-B-3A6-A3-8A10-3A6-12A7-3B3A9-16A2B4A9-11AB2A2-3B12-2(18A13-)18A14-12CD2-2A15-10C2D2-2A15-10C4-2A14-12C19-CE2D4F2DEC49-2B26-13A4-4B10-A2-B8-12A7-3AB2A6-12A6-D6A6-12A5-FD6A6-15A2-2D6A6-16A2-C3AB2A6-16A2-4AB2A6-A4-11A-C4AB2A6-A4-6A-4A-C2AB11A4-6A-4A-C2A2B10A4-B5A-4A-B2A3B8A5-3A9-CA4B8A5-6A6-CA4B9A4-6A6-B2A3B9A4-6A2(6-C2A3-9A4-3AB2A)8-A3-8A5-3AB2A8-A3-8A5-6A8-6AB5A7-3BA11-16A2BA12-14A2-3B12-2(18A13-)18A14-12CD19-10C2D19-10C20-12C19-CED6FDEC49-2B10-4B12-13A2-6B10-A6B5-12A7-2(A6B5-12A6-D)A6B5-15A4-A6B5-16A3-A6B5-16A2-4AB2A6-A4-7AB3A2-4AB2A6-A4-6A2B3A2-14A4-6A-4A2-A3B10A4-6A-4A-BA4B8A5-3A10-A4B8A5-6A7-A4B9A4-3B3A6-B2A3B2(8A5-6A7-2A3-)9AB3-3B3A8-A3-8A2B3-6A8-A3-8A5-6A8-6AB5A7-3BA11-16A2BA12-14A2-3B12-2(18A13-)18A14-12C20-10C21-10C20-12C19-CED6FDEC49-2B10-4B12-13A2-4B12-3(A6B5-12A7-)2(A6B5-15A4-)A6B5-15A3-2A2-B8-A4-7AB2A3-2A2-B8-A4-6A2B2A3-14A4-6A-3A3-A3-10A-B2-6A-3A2-BA4-8A5-3A10-A4-8A5-6A7-A4-9A4-B5A6-B2(2A3-8A5-6A7-)2A3-9AB3-B5A8-A3-8A2B3-6A8-A3-8A5-6A8-12A7-3BA11-16A2BA12-16A3B12-18A2(13-14AD3A)14-12C2(2D18-10C-)2D17-12C2D17-CE2D4F2DEC49-2B-B8-4B12-13A2-4B12-A6B5-12A6-2A6B3(5-12A6-A7B)5-12A6-2A6B5-12A6-2A11-A4-7A6-2A11-A4-6A7-14A4-6A7-A3-10A4-6A6-BA4-16A10-A4-9A4-6A7-A4-9A4-B5A2(7-2A3-8A5-6A)7-2A3-9A4-B5A8-A3-8A5-6A8-A2-B8A5-6A8-12A5-6A11-19A12-16A15-14A17-14AD16-14AD17-12C2(2D18-10C-)2D17-12C2D17-C2E2D2F2D2EC61-4B12-13A2-4B12-A6B5-12A6-2A6B3(5-12A6-A7B)5-12A6-2A6B5-12A6-2A11-A4-7A6-2A11-A4-6A7-13A5-6A7-A3-10A4-6A7-A4-16A10-A4-9A4-6A7-A4-9A4-B5A7-2(2A3-9A4-B5A6-B)2A3-9A4-B5A2(6-2BA3-8A5-6A)8-12A5-6A11-19A12-16A14-2(C14A16-)D14A16-2D12C17-3D10C20-D10C20-12C19-2C2E4D2E2C61-4B12-13A2-4B12-6(A11-12A7-)A11-A4-7A7-A11-A4-6A7-14A4-6A7-4AB9A4-6A7-6A6-9A10-6A6-2A4-6A2(7-6A6-2A4-B5A)2(8-A10-2A4-B5A)2(8-A10-2A4-6A)8-13A4-6A11-4A2B13A12-16A14-C2(15A16-)16A16-12C-2A17-10C20-D10C20-12C19-3C6E3C49-2B26-13A18-6(24A7-)2(13A18-)13A20-11AB18-19A12-12A4(B3-6A8-13A)3(4-6A8-13A)4-6A11-20A11-16A14-C2(15A16-)16A17-11C-2A17-9C21-D2(9C22-)2C5E2C142-B100-B58-B66-2A23-9B18-3B-6B10A11-4(3B-6B9A12-)B9-9A22-9A11-B10-9A10-4C8-9A13-C19A11-C15A15-C2(15A16-)16A17-8C4-2A18-2D2-3D28-3D23-9C22-9C18-11A20-11A19-13A18-6(22A9-)3(13A18-)13AB17-A5B6-A18-2(A5B6-5A14-)A5B6-5AB13-A5B6-5A14-A5B-2(5B5A14-A6-)5B5A13-C17A5(17-14A)20-2D3-D25-2D2-2(3D28-)3D50-6A2B3A20-11A19-13A18-3(22A9-)3(22A7-2B)3(13A4-5A9-)13A18-A5B6-A18-4(A5B6-4A15-)A5B-2(5B4A15-A6-)5B4A14-C16A114-3(2D3-D25-)2D3-D119-2B23-11A19-A10-2A6-2B10-A11-10A9-2(A11-10AB8-)A11-10AB6-2(2BA11-10A7-)B2(2A11-A4-5A8-)14A4-5A8-14A17-2A5B6-A17-2A5B6-2A16-2A3(5B6-3A16-A)5B-5B3A16-2(A6-5B3A15-C)13A360-11A19-A10-2A6-2B10-A11-10A9-2(A11-10AB7-D)A11-10AB8-A11-10A9-A11-10A8-2(2A11-A4-5A7-C)14A4-5A7-CA4-9A17-A12-A17-A12-2A16-2A11-2A17-2(A11-2A16-B)A6-5B2A16-BA6-5B2A16-CA6-5BA18-13A25-3B332-11A19-A10-2A6-2B10-A11-10A9-A11-10AB7-DA11-10AB6-FDA11-10AB6-DCA11-10A7-2CA11-10A7-C2A11-A4-5AB6-C2A11-A4-5AB7-14A4-5AB6-CA4-9A8-2B6-CA12-A16-CAB11-A16-C2A11-A16-2C4(A11-A17-C)A11-A18-13A25-3B332-11A19-A10-2A18-A11-10A9-2(A11-10A8-D)2(A11-10A9-)A11-10A8-2(2A11-A4-5AB7-)14A4-5AB7-A4-9A8-2B7-A12-A17-AB11-A17-2A5(11-A18-A)11-A18-13A25-3B301-6B25-A5B5A19-A6B4-2A18-A6B5-6(10A9-A11-)A4-5A9-A11-A4-5A8-14A4-5AB7-2A3-9A8-2B7-2A11-A17-2A5(11-A18-A)-5A5-A18-A-5A5-A18-13A329-6B25-A5B5A18-BA6B4-2A18-A6B5-10A9-A11-10A9-A4-B6-4(10A9-A11-)A4-5A9-A11-A4-5A8-14A4-5A8-2A3-9A2(17-2A11-A)18-A2-B8-3(A18-A11-)2(A18-A-5A5-)A18-13A360-A5-5A19-13A18-6(22A9-)4(13A18-)13A5(19-12A)3(18-13A)329-6B25-A5B5A18-B2(A6B6A18-)13A18-5AB7A8(18-13A)19-12A18-3AB9A3(18-13A)3(18-2A5-6A)422-7(10A21-)10A83-4(11A20-)11A451-
