model
size = 31 32 32, scale = 0.05, origin = -y
material 
  colors = A:#FFB11B B:#F7C242 C:#777 D:#444 E:#555 F:#222
voxels
57-2(B30-)B69-3A27-5(7A24-)4A3-B23-4A27-4A6-2B19-4A-B25-4A27-4A484-2(3B9-2B17-)3B9-2B9-2(12A19-)12A4-7A2-A5-5(12A3-A-6A8-)12A3-A-7A22-4(A-7A3-15A4-)9A3-15A5-8A4(3-15A6-7A)3-2A19-4(6A25-)6A168-6B9-2B9-5A5BA9-3B7-2A4-6BA8-B15A6BA2(9-22A)4-27A3-A5-22A3-A5-3A-18A3-A5-3A6-13A3-A5-2A7-2(13A3-A4-4A6-)9A6-BA3-5A3-15A3-BA3-A10-12A4-A-2B2(A3-)16A2(3-A)2-BA3-16A3-2A2-2(A3-)16A4-8A4(3-16A5-7A)3-2A19-4(8A23-)8A166-6B20-11A9-3B7-2A4-6BA8-B10A5-6BA9-3B7A11-A9-2B8A11-AB3-15A11-AD2-A5-10A11-AD2-A5-3A-6A11-A3-A5-3A6-A11-A3-A5-2A7-A11-A3-A4-4A6-13A3-A4-4A6-9A6-BA2(3-5A)13-BA3-A10-2A10-B3-A-2B2(A3-)4A11-4(A3-)4A11-A3-2A2-2(A3-)2(4A2B9-A3-9A3-)2(4A11-A3-9A3-)16A3-9A3-2A17-10A4(23-8A)192-11A9-3B7-2A10-A8-B2(10A11-A9-)10A11-A4-15A11-AD2-A5-10A11-ADF-A5-3A-6A11-A2D-A5-3A6-A11-2A-CA5-2A7-A11-2A-CA4-4A6-14A-CA4-4A6-9A4-A2-A2(3-5A)11-AC-A3-A10-2A10-BAC-A-B2A3-A3-5A10-2A2CA2-2A3-A3-5A10-A3C2A-2A3-A2(3-5AB9-AC-C9A)2(3-5A10-A3-9A)3-16A3-9A3-5A-3B10-10A9-2B10-2C3(8A22-C)8A22-4C166-11A9-3B7-2A10-A8-B2(10A11-A9-)10A11-A4-15A11-AD2-A5-10A11-AD2-A5-3A-6A11-A3CA5-3A6-A11-2A2CA5-2A7-A11-2AC-A4-4A6-14A2CA4-4A3-6B6A4-A2CA2(3-5A)B10-A2CA3-A10-2A10-BA-CA-B2A3-A3-5A10-2A-CA2-2A3-A3-5A10-A3-2A-2A3-A3-5AB9-A3-9A3-5AB9-2(AC-C9A3-5A10-)AC-C9A3-16A2-C9A3-5A-3B9-C10A9-2B9-2C-3(8A23-)8A25-C166-11A9-3B7-2A10-A8-B2(10A11-A9-)10A11-A4-15A2(11-A3-A5-10A)11-A2-CA5-4A5-A11-2A2-A5-2A7-A11-2A2-A-2A-4A6-14A2-A-2A-4A9B6A4-A2-A2(3-5A)B10-A2-A3-A10-2A11-2(A2-)2A3-A3-5A10-2A2-A2-2A3-A3-5A10-A3-2AB2A3-A3-5A10-3(AB2-9A3-5A4B6-)AC2-9A3-16A3-9A3-5A-3B10-10A14-2C7-8A14-C8-11A8-4C8-11A6-3D11-11A6-3D13-C2-6A130-2B26-11A19-2A10-3(A9-10A11-)A4-15A11-A2-BA2B3-10A11-A2B-A2B3-10A11-A2BCA2B3-4A5-A11-2ABCA2B3-2A3-5A11-2A2-A2B6A2-18A2-A2B6A9B11A2-A3-13AB4-5B2A2-A14-2A2(5-5B2A2(2-A)4-9A)5-5BA3-2A-A4-9A5-5BA4-16A4B-5B2(A5-15A4B6-)AC4-9A3B14AC4-23A4C4-8A-14AC7-8A-14A2(8-23A)8-11A6-3D13-C2-6A130-2B26-11A19-10A2(2-A9-10A-8A)2-A4-B4-10A-8A2-A4-15A-8A2-A2-B2(A2B3-10A-8A2-A2B-)A2B12-A-8A2-A2BCA2B8-5A-8A2-A3-A2B-B2A4-17A3-A2B4A2-9B10A3-A4-12AB4A5BA3-A14-7A2(5BA3-A2-A4-14A)5BA3-2A-A4-14A5BA4-16A4BA5B2(A5-15A4B4A2-)A5-9A3B14A5-23A8-8A-14A3(8-23A)8-11A10C12-3C6A24-C2A29-C6-9C21-10C195-10A20-11A2(21-10A)20-C10A7-B13-10A5-A-B13-9A8B13-17AB5-4B4-10A6-A3(6-4B4-17A)6-4B5-16A6-4B6-2(15A16-)9A3B3A16-23A8-6A3-14A3(8-23A)8-10A12CD13-6A-8C-2D13-2A5-8C16-C6-10C19-3C6E3C84-13A2(7-24A)4-B2-22A6-25A4-BA2B2(20A2-A5-3B)8A4-8A2-4A-D3B8A4-8A2-4A2-3BAB6A4-8A2-4A2-3B7A8B10A3-17AB10A4(3-28A)4-27A6-2A2B10A2(-10A7-13A)-10A7-21A17-14A13-3(18A2D11-)2A3-12C2D12-2A4-10C2D13-2AC3-10C15-3C2-12C19-2C2E4D2E2C84-13A7-12A11-A2(7-12A6-6A)4-15A2(6-6A3-16A)6-7A-D11A4-A6-7A-F11A4-A6-7A-D11A4-8A2-4A2-11A4-13A3(5-16A3B3A3BA)5-22A3B2(A6-21A3-)A-C4-2AB18A3-A-C4-21A3-A-C4-4A2B19A-C4-4A2B16A4-C7-3B2-2AB11A4-C8-18A2D3C8-2(18A2D11-)2A2CD12C-D12-2AC-2D10C15-2AC3-10C20-12C19-C2E2D2F2D2EC76-4B4-13A7-12A8-B2-A7-12A6-2AB3A7-12A6-6AD3-15A6-6AD2-16A6-6A3-16A6-6A2CD11A2(4-A6-7ACD4A-6A)4-14A2-4A-6A4-13A7-20A3BA2B5-A2(10-9A3BA6-2A)10-9A3BA2B4-2A2-B7-9A3-A6-3A-B7-9A3-A-C4-3A-B8-8A3-A6-3A10-8A3-A6-3A3B7-12A6-4A2B16A12-3B2-2AB11A3(13-18A)13-2A2-D12C14-2A2-2D10C15-2A4-10C20-12C19-CE2D4F2DEC61-2B13-4B4-13A7-12A8-B2-A7-12A6-2AB3A7-12A6-6AD3-15A6-6ADF-16A6-6A2D-16A6-2AB3AC2-11A4-A6-2AB4A2-4A-6A4-A6-2AB4AC-4A-6A4-11AB2AC-4A-5AB4-10A2B2AC9-3A5-8A3B2AB6-6A5-8A2(4BAC6-6A4-9A)3B2AB2(6-2AB3A4-9A3-2AC)6-2AB3A5-8A3-A8-6A5-8A3-A8-A3B7-5AB6A9-A2B16A12-3B2-14A3(13-18A)17-D12C18-2D10C21-10C20-12C19-CED6FDEC47-4B10-2B13-6B2-13A3(7-12A5-6BA)D3-15A5-6BAD2-2(16A5-6BA3-)3AB7A4-A6-2AB4A2-3A2B6A4-A6-2AB4A2-4A-6A4-14A2-4A-6A4-10A3BA10-3A5-8A4BAB6-6A5-8A4BA7-3A3B4-9A4BA7-6A5-8A3B2AB6-6A5-8A3-2A7-3A3B3-B9A3-2A7-6A3-2B8A3-A8-6A5-8A3-A8-A3B7-5AB6A9-A2B16A12-3B2-14A3(13-18A)18-12C20-10C21-10C20-12C19-CED6FDEC47-4B10-2B15-4B2-13A3(7-12A5-6BA)3(4-15A5-6BA)4-2AB7A4-A8-B2-2A3-2A2B6A4-A8-B2-2A3-3A-6A4-14A3-3A-6A2-B-10A3-A10-3A5-8A4-AB6-6A5-8A4-A7-5AB4-9A4-A7-6A5-8A3-2AB6-6A5-8A3-2A7-5AB3-B9A3-2A7-6A3-2B8A3-A8-6A5-8A3-A8-A3B7-12A9-A2B16A12-3B16A13-18A2(13-3AD14A)16-2D12C17-2(2D-10C18-)2D12C19-CE2D4F2DEC47-4B8-B-2B15-4B2-13A7-12A5-6BA7-12A5-6B2A3(6-12A5-7BA)6-12A5-6B2A6-7A2(4-A11-2A7-6A)4-14A7-6A4-10A3-A10-16A4-AB6-6A4-9A4-A7-5AB4-9A4-A2(7-6A5-8A3-2A)7-5AB4-9A3-2A7-6A5-8A3-A8-6A5-8AB2-A8-6A5-12A9-19A15-16A17-2(14A16-D)14A16-2D12C17-2(2D-10C18-)2D12C19-C2E2D2F2D2EC47-4B27-4B2-13A7-12A5-6BA7-12A5-6B2A3(6-12A5-7BA)6-12A5-6B2A6-7A2(4-A11-2A7-6A)5-13A7-6A4-10A3-A10-16A4-A7-6A2(4-9A4-A7-5AB)4-9A3-2A7-2(5AB4-9A3-2AB6-)2(6A5-8A3-A2B6-)6A5-12A9-19A15-16A17-2(14AC16-)14AD17-12C2D18-10C3D18-10CD19-12C19-2C2E4D2E2C47-4B27-4B2-13A6(7-12A11-A)7-7A2(4-A11-A8-6A)4-14A7-6A4-9AB4A10-9A6-6A7-6A3(4-2A6-6A7-5AB)4-2A10-A8-5AB3(4-2A10-A8-6A)4-13A9-13A2B4A15-16A16-15AC15-15A15-16A15-2A-12C20-10C21-10CD19-12C19-3C6E3C61-2B21-13A6(7-24A)3(18-13A)17-B11A13-19A9-6A3-B12A9-3(6A3-B13A8-)4(6A4-13A8-)20A15-16A16-15AC15-15A15-16A15-2A-11C2(22-9C)D21-9C22-2C5E2C158-B84-B64-B55-2A28-9B15-10A5(6B-3B12-9A)9-B12-9A22-9A10-B11-9A8-4C8-19A3(C15-15A)15-16A15-2A4-8C23-3D2-2D24-3D27-9C22-9C24-11A20-11A19-13A6(9-22A)3(18-13A)17-B13A18-A2(6-5BA14-5A)6-5BA13-B2(5A6-5BA14-)5A5B-5B2(A14-5A5B6-)A14-17AC13-4(14A17-)14A22-D3-2D24-3D2-2D24-3D28-3D60-3A2B6A20-11A19-13A5(9-22A)2B7-22A2(2B7-5A4-13A)9-5A4-2(13A18-)A5(6-5BA15-4A)5B-5B2(A15-4A5B6-)A15-16AC111-3(D3-2D25-)D3-2D121-2B26-11A11-2B6-2A10-A9-3(10A11-A8-B)10A11-A9-2(10A11-A2B7-)5A4-A11-2AB7-5A4-A11-2A8-5A4-2(14A17-)A6-5B2A16-2A2(6-5B2A15-3A)2(6-5BA16-3A)5B-5B2(A16-3A5B6-)AC17-13AC359-11A11-2B6-2A10-A9-2(10A11-A8-B)10A11-AD7-B10A11-AD8-2(10A11-A9-)5A4-A11-2A8-5A4-A11-2AC7-5A4-14AC16-9A4-AC16-A2(12-A16-2A)11-2A16-2A11-A17-2A11-2(AB16-2A5B6-)AB17-A5B6-AC17-13A21-3B336-11A11-2B6-2A10-A9-2(10A11-A8-B)10A11-AD7-B10A11-ADF7-10A11-ACD7-10A11-A2C2(6-B5A4-A11-2AC)6-B5A4-14A7-2B8-9A4-AC16-A12-AC16-A11-BAC16-A11-2AC16-A11-A2C16-4(A11-AC17-)13A21-3B336-11A19-2A10-3(A9-10A11-)2(AD8-10A11-)A9-10A11-A8-2(B5A4-A11-2A7-)B5A4-14A7-2B8-9A4-A17-A12-A17-A11-BA17-A11-2A17-5(A11-A18-)13A21-3B310-6B20-5A5BA19-2A4-6BA9-10A5-6B5(A9-10A11-)2(A9-5A4-A11-)A8-B5A4-14A7-2B8-9A3-3(2A17-A11-)3(A18-A11-)2(A18-A5-5A-)A18-13A334-6B20-5A5BA19-2A4-6BAB8-10A5-6BA9-10A11-A9-10A6-B4-3(A9-10A11-)2(A9-5A4-A11-)A9-5A4-14A17-9A3-2(2A17-A11-)2A17-A8-B2-3(A18-A11-)2(A18-A5-5A-)A18-13A360-5A5-A19-13A6(9-22A)5(18-13A)18-5(12A19-)2(13A18-)13A334-6B20-5A5BA19-6A6BAB17-6A6BA18-13A18-7AB5A8(18-13A)18-12A19-9AB3A3(18-13A)3(18-6A5-2A)423-7(10A21-)10A82-4(11A20-)11A437-
