model
size = 21 32 3, scale = 0.05, origin = -y
material 
  colors = A:#111
voxels
2A17-2A-2A15-2A3-A15-A4-2A13-2A5-A13-A6-2A11-2A7-A11-A8-2(2A9-)A9-A10-2A7-2A11-A7-A12-2A5-2A13-A5-A14-2A3-2A15-A3-A16-5A9-2A6-3A6-2A3-A6-3A6-A4-2A5-3A5-2A5-A5-3A5-A6-2A5-A5-2A7-2(A5-)A8-2A4-A4-2A9-2(A4-)A10-2A3-A3-2A11-2(A3-)A12-2A-3A-2A13-A-3A-A14-7A16-3A19-A20-A10-A19-A-A17-A2-2A15-2A3-A15-A4-2A13-2A5-A13-A6-2A11-2A7-A11-A8-2(2A9-)A9-A10-2A7-2A11-A7-A12-2A5-2A13-A5-A14-2A3-2A15-5A9-A6-5A6-A2-2A6-3A6-2A3-A6-3A6-A4-2A5-3A5-2A5-A5-3A5-A6-2A4-3A4-2A7-A4-3A4-A8-2A3-3A3-2A9-A3-3A3-A10-2A2-3A2-2A11-A2-3A2-A12-2A-3A-2A13-7A15-5A17-3A18-3A9-2A17-2A-2A15-2A3-A15-A4-2A13-2A5-A13-A6-2A11-2A7-A11-A8-2(2A9-)A9-A10-2A7-2A11-A7-A12-2A5-2A13-A5-A14-2A3-2A15-A3-A16-5A9-2A6-3A6-2A3-A6-3A6-A4-2A5-3A5-2A5-A5-3A5-A6-2A5-A5-2A7-2(A5-)A8-2A4-A4-2A9-2(A4-)A10-2A3-A3-2A11-2(A3-)A12-2A-3A-2A13-A-3A-A14-7A16-3A19-A20-A10-
