model
size = 19 24 7, scale = 0.05, origin = -y
material 
  colors = A:#400 B:#111 C:#500 D:#700 E:#800 F:#444 G:#777 H:#555 I:#222 J:#F30 K:#C60 L:#888 M:#D00 N:#E00 O:#AAA P:#BBB Q:#200 R:#A00 S:#B00 T:#F60
voxels
------------------- ------------------- ------------------- ------------------- ------------------- ------------------- ------------------- ------------------- ---------E--------- ---------D--------- ------------------- ------------------- ------------------- ------------------- ------------------- ------------------- ------------------- ------------------- ------------------- ------------------- ------------------- ------------------- ------------------- ------------------- 
---------I--------- -------G-I-G------- ------------------- ------------------- ------------------- -------O---O------- -------P---P------- ---------A--------- --------CAC-------- --------DED-------- ---------C--------- ---------A--------- ------------------- ------------------- ------------------- ------------------- ------GI---IG------ ------G-----G------ ------------------- ------------------- ------------------- ------------------- ------------------- ------------------- 
-------AFFFA------- ------FACFCAF------ ------AACACAA------ ------CMCACMC------ ------CCCACCC------ ------JH---HJ------ -K----JJCACJJ----K- -K---EJDQAQDJE---K- -----EJDCACDJE----- -------DCACD------- -------DCACD------- ----MAADCACDAAM---- -----MRDCACDRM----- ------SDCACDS------ ------EDCTCDE------ ------DDCACDD------ ------DCCACCD------ ------CCCACCC------ --------AAA-------- ------------------- ------------------- ------------------- ------------------- ------------------- 
------FAAAAAF------ ----FCAAAAAAACF---- -----LAAAAAAAL----- ----FCCCAAACCCF---- ----CCCCAAACCCC---- -K--DDDJBBBJDDD--K- ----EDDJAAAJDDE---- ----EEEAAAAAEEE---- -K--MEEAAAAAEEM--K- ----EEJAAAAAJEE---- ----E--NAAAN--E---- ----E--NAAAN--E---- ----EMNAAAAANME---- ----EJAAAAAAAJE---- ----EEAAAAAAAEE---- ----MEAAAAAAAEM---- ----DDDAAAAADDD---- -----CCCCACCCC----- -------AAAAA------- ---------C--------- ------------------- ------------------- ------------------- ------------------- 
-----F-------F----- ----AA-BBBBB-AA---- ---LAABBBBBBBAAL--- ---CAABBBBBBBAAC--- --CFAABBBBBBBAAFC-- -KCDAABBBBBBBAADCK- --CDAABBBBBBBAADC-- IICDAABBBBBBBAADCII IICDAABBBBBBBAADCII IICDAABBBBBBBAADCII -ICDABBBBBBBBBADCI- --CDANNBBBBBNNADC-- --CDAABBBBBBBAADC-- --CDAAABBBBBAAADC-- ---DAAAAAAAAAAAD--- ---DAAAAAAAAAAAD--- ----AAAAAAAAAAA---- ---HFAAAAAAAAAFH--- --GLHFAAAAAAAFHLG-- --LG----CCC----GL-- ---L-----------L--- ------------------- ------------------- ------------------- 
------------------- ------------------- ---AA-B-----B-AA--- --FAABB-----BBAAF-- --AAABB-----BBAAA-- -AAAABB-----BBAAAA- -KAAABB-----BBAAAK- -KAAABB-----BBAAAK- -AAAABB-----BBAAAA- -AAAABB-----BBAAAA- -AAAABB-----BBAAAA- -AAAABB-----BBAAAA- -AAAABB-----BBAAAA- --AAABBBBBBBBBAAA-- --FAAABBBBBBBAAAF-- --LAAAAAAAAAAAAAL-- ---FAAAAAAAAAAAF--- --HGFAAAAAAAAAFGH-- -HGGGFAAAAAAAFGGGH- -OGG---CCCCC---GGO- --OGH---------HGO-- ---OG---------GO--- ----K---------K---- ----E---------E---- 
------------------- ------------------- ---A-----------A--- --AA-----------AA-- -FAA-----------AAF- -AAA-----------AAA- -AAA-----------AAA- -AAA-----------AAA- -AAA-----------AAA- -AAA-----------AAA- -AAA-----------AAA- -AAA-----------AAA- -AAA-----------AAA- -FAA-----------AAF- --AA-----------AA-- --AAA---------AAA-- ---AAAAAAAAAAAAA--- ---HFAAAAAAAAAFH--- --HHHFAAAAAAAFHHH-- --GH---CCCCC---HG-- ---G-----------G--- ------------------- ------------------- ------------------- 
