model
size = 17 28 17, scale = 0.05, origin = -y
material 
  colors = A:#111 B:#9CF C:#777
voxels
-------ACA------- ----------------- ----------------- ----------------- ----------------- ----------------- ----------------- ----------------- ----------------- ----------------- ----------------- ----------------- ----------------- ----------------- ----------------- ----------------- ----------------- ----------------- ----------------- ----------------- ----------------- ----------------- ----------------- ----------------- ----------------- ----------------- ----------------- ----------------- 
-------ACA------- -------ACA------- ----------------- ----------------- ----------------- ----------------- ----------------- ----------------- ----------------- ----------------- ----------------- ----------------- ----------------- ----------------- ----------------- ----------------- ----------------- ----------------- ----------------- ----------------- ----------------- ----------------- ----------------- ----------------- ----------------- ----------------- ----------------- ----------------- 
----------------- -------ACA------- -------ACA------- ----------------- ----------------- ----------------- ----------------- ----------------- ----------------- ----------------- ----------------- -------AAA------- ----------------- ----------------- ----------------- ----------------- ----------------- ----------------- ----------------- ----------------- ----------------- ----------------- ----------------- ----------------- ----------------- ----------------- ----------------- ----------------- 
----------------- ----------------- -------ACA------- -------ACA------- ----------------- ----------------- ----------------- ----------------- ----------------- ----------------- -------AAA------- ------AAAAA------ ----------------- ----------------- ----------------- ----------------- ----------------- ----------------- ----------------- ----------------- ----------------- ----------------- ----------------- ----------------- ----------------- ----------------- ----------------- ----------------- 
----------------- ----------------- ----------------- -------ACA------- -------ACA------- ----------------- ----------------- ----------------- ----------------- ----------------- ------AAAAA------ -----AAAAAAA----- -------CCC------- ----------------- ----------------- ----------------- ----------------- ----------------- ----------------- ----------------- ----------------- ----------------- ----------------- ----------------- ----------------- ----------------- ----------------- ----------------- 
----------------- ----------------- ----------------- ----------------- -------ACA------- -------ACA------- ----------------- ----------------- --------C-------- --------C-------- -----AAAAAAA----- ----AAAAAAAAA---- ------CAAAC------ ----------------- ----------------- ----------------- ----------------- ----------------- ----------------- ----------------- ----------------- ----------------- ----------------- ----------------- ----------------- ----------------- ----------------- ----------------- 
----------------- ----------------- ----------------- ----------------- ----------------- -------ACA------- -------ACA------- -------AAA------- -------ABA------- -------ABA------- ----AAAAAAAAA---- ---AAAAAAAAAAA--- -----CAAAAAC----- ----------------- ----------------- ----------------- ----------------- ----------------- ----------------- ----------------- ----------------- ----------------- ----------------- ----------------- ----------------- ----------------- ----------------- ----------------- 
AA-------------AA -AA-----------AA- --AA---------AA-- ---AA-------AA--- ----AA-----AA---- -----AA---AA----- ------AAAAA------ ------A---A------ ------AAAAA------ ------ABBBA------ ---AAAAABBBAAA--- --AAAAAABBBAAAA-- ----CAAAAAAAC---- ----------------- ----------------- ----------------- ----------------- ----------------- ----------------- ----------------- ----------------- ----------------- ----------------- ----------------- ----------------- ----------------- ----------------- ----------------- 
CC-------------CC -CC-----------CC- --CC---------CC-- ---CC-------CC--- ----CC-----CC---- -----CC---CC----- ------CA--C------ ------A---A------ -----CBAAABC----- -----CBBBBBC----- ---AABBBBBBAAA--- --AABBBBBBBAAAA-- ----CAAAAAAAC---- ----------------- ----------------- ----------------- ----------------- ----------------- ----------------- ----------------- ----------------- ----------------- ----------------- ----------------- ----------------- ----------------- ----------------- ----------------- 
AA-------------AA -AA-----------AA- --AA---------AA-- ---AA-------AA--- ----AA-----AA---- -----AA---AA----- ------AAAAA------ ------A---A------ ------AAAAA------ ------ABBBA------ ---AAABBBBBAAA--- --AABBBBBBBAAAA-- ----CAAAAAAAC---- ----------------- ----------------- ----------------- ----------------- ----------------- ----------------- ----------------- ----------------- ----------------- ----------------- ----------------- ----------------- ----------------- ----------------- ----------------- 
----------------- ----------------- ----------------- ----------------- ----------------- -------ACA------- -------ACA------- -------AAA------- -------ABA------- -------ABA------- ---AAAAAAAAAAA--- --AAABBBBBBAAAA-- -----CAAAAAC----- ----------------- ----------------- ----------------- ----------------- ----------------- ----------------- ----------------- ----------------- ----------------- ----------------- ----------------- ----------------- ----------------- ----------------- ----------------- 
----------------- ----------------- ----------------- ----------------- -------ACA------- -------ACA------- ----------------- ----------------- --------C-------- --------C-------- ----AAAAAAAAA---- ---AAABBBBBAAA--- ------ABBBA------ -----CAAAAAC----- ----CAAAAAAAC---- ----CAAAAAAAC---- ---CAAAAAAAAAC--- ---CAAAAAAAAAC--- ---CAAAAAAAAAC--- ---CAAAAAAAAAC--- ----CAAAAAAAC---- ----CAAAAAAAC---- ----CAAAAAAAC---- -----CAAAAAC----- ------CAAAC------ -------CCC------- ----------------- ----------------- 
----------------- ----------------- ----------------- -------ACA------- -------ACA------- ----------------- ----------------- ----------------- ----------------- ----------------- -----AAAAAAA----- -----ABBBBBA----- ---AAABBBBBAAA--- --AAAABBBBBBAAA-- --AAAABBBBBBAAA-- --AAABBBBBBBAAA-- -AAAABBBBBBBAAAA- -AAAABBBBBBBAAAA- -AAAABBBBBBBAAAA- -AAAABBBBBBBAAAA- --AAABBBBBBBAAA-- --AAABBBBBBBAAA-- --AAABBBBBBBAAA-- ---AABBBBBBBAA--- ----AAAAAAAAA---- -----AAAAAAA----- ------AAAAA------ -------AAA------- 
----------------- ----------------- -------ACA------- -------ACA------- ----------------- ----------------- ----------------- ----------------- ----------------- ----------------- -----AAAAAAA----- -----AAAAAAA----- ----AAAAAAAAA---- ---AAAAAAAAAAA--- ---AAAAAAAAAAA--- ---AAAAAAAAAAA--- --AAAAAAAAAAAAA-- --AAAAAAAAAAAAA-- --AAAAAAAAAAAAA-- --AAAAAAAAAAAAA-- ---AAAAAAAAAAA--- ---AAAAAAAAAAA--- ---AAAAAAAAAAA--- ----AAAAAAAAA---- -----AAAAAAA----- ------AAAAA------ -------AAA------- --------A-------- 
----------------- -------ACA------- -------ACA------- ----------------- ----------------- ----------------- ----------------- ----------------- ----------------- ----------------- ----------------- -------AAA------- ------AAAAA------ -----AAAAAAA----- ----AAAAAAAAA---- ----AAAAAAAAA---- ----AAAAAAAAA---- ----AAAAAAAAA---- ----AAAAAAAAA---- ----AAAAAAAAA---- ----AAAAAAAAA---- ----AAAAAAAAA---- -----AAAAAAA----- ------AAAAA------ -------AAA------- --------A-------- ----------------- ----------------- 
-------ACA------- -------ACA------- ----------------- ----------------- ----------------- ----------------- ----------------- ----------------- ----------------- ----------------- ----------------- ----------------- ----------------- ----------------- ----------------- ----------------- ----------------- ----------------- ----------------- ----------------- ----------------- ----------------- ----------------- ----------------- ----------------- ----------------- ----------------- ----------------- 
-------ACA------- ----------------- ----------------- ----------------- ----------------- ----------------- ----------------- ----------------- ----------------- ----------------- ----------------- ----------------- ----------------- ----------------- ----------------- ----------------- ----------------- ----------------- ----------------- ----------------- ----------------- ----------------- ----------------- ----------------- ----------------- ----------------- ----------------- ----------------- 
