model
size = 17 28 17, scale = 0.05, origin = -y
material 
  colors = A:#633 B:#630 C:#9CF D:#600 E:#603 F:#CC0
voxels
-------BBB------- ----------------- ----------------- ----------------- ----------------- ----------------- ----------------- ----------------- ----------------- ----------------- ----------------- ----------------- ----------------- ----------------- ----------------- ----------------- ----------------- ----------------- ----------------- ----------------- ----------------- ----------------- ----------------- ----------------- ----------------- ----------------- ----------------- ----------------- 
-------BBB------- -------BBB------- ----------------- ----------------- ----------------- ----------------- ----------------- ----------------- ----------------- ----------------- ----------------- ----------------- ----------------- ----------------- ----------------- ----------------- ----------------- ----------------- ----------------- ----------------- ----------------- ----------------- ----------------- ----------------- ----------------- ----------------- ----------------- ----------------- 
----------------- -------BBB------- -------BBB------- ----------------- ----------------- ----------------- ----------------- ----------------- ----------------- ----------------- ----------------- -------AFA------- ----------------- ----------------- ----------------- ----------------- ----------------- ----------------- ----------------- ----------------- ----------------- ----------------- ----------------- ----------------- ----------------- ----------------- ----------------- ----------------- 
----------------- ----------------- -------BBB------- -------BBB------- ----------------- ----------------- ----------------- ----------------- ----------------- ----------------- -------AAA------- ------AAAAA------ ----------------- ----------------- ----------------- ----------------- ----------------- ----------------- ----------------- ----------------- ----------------- ----------------- ----------------- ----------------- ----------------- ----------------- ----------------- ----------------- 
----------------- ----------------- ----------------- -------BBB------- -------BBB------- ----------------- ----------------- ----------------- ----------------- ----------------- ------AAAAA------ -----AAAAAAA----- -------DED------- ----------------- ----------------- ----------------- ----------------- ----------------- ----------------- ----------------- ----------------- ----------------- ----------------- ----------------- ----------------- ----------------- ----------------- ----------------- 
----------------- ----------------- ----------------- ----------------- -------BBB------- -------BBB------- ----------------- ----------------- --------F-------- --------F-------- -----AAAAAAA----- ----AAAAAAAAA---- ------EDEDD------ ----------------- ----------------- ----------------- ----------------- ----------------- ----------------- ----------------- ----------------- ----------------- ----------------- ----------------- ----------------- ----------------- ----------------- ----------------- 
----------------- ----------------- ----------------- ----------------- ----------------- -------BBB------- -------BBB------- -------BBB------- -------BCB------- -------BCB------- ----AAAAAAAAA---- ---AAAAAAAAAAA--- -----DDDEEDD----- ----------------- ----------------- ----------------- ----------------- ----------------- ----------------- ----------------- ----------------- ----------------- ----------------- ----------------- ----------------- ----------------- ----------------- ----------------- 
BB-------------BB -BB-----------BB- --BB---------BB-- ---BB-------BB--- ----BB-----BB---- -----BB---BB----- ------BBBBB------ ------B---B------ ------BCCCB------ ------BCCCB------ ---AAAAACCCAAA--- --AAAAAACCCAAAA-- ----DDDDDDDDD---- ----------------- ----------------- ----------------- ----------------- ----------------- ----------------- ----------------- ----------------- ----------------- ----------------- ----------------- ----------------- ----------------- ----------------- ----------------- 
BB-------------BB -BB-----------BB- --BB---------BB-- ---BB-------BB--- ----BB-----BB---- -----BB---BB----- ------BB--B------ ------B---B------ -----FCCCCCF----- -----FCCCCCF----- ---AACCCCCCAAA--- --AACCCCCCCAAAA-- ----DDEDEDEDD---- ----------------- ----------------- ----------------- ----------------- ----------------- ----------------- ----------------- ----------------- ----------------- ----------------- ----------------- ----------------- ----------------- ----------------- ----------------- 
BB-------------BB -BB-----------BB- --BB---------BB-- ---BB-------BB--- ----BB-----BB---- -----BB---BB----- ------BBBBB------ ------B---B------ ------BCCCB------ ------BCCCB------ ---AACCCCCCAAA--- --AACCCCCCCAAAA-- ----DDDDDDEDD---- ----------------- ----------------- ----------------- ----------------- ----------------- ----------------- ----------------- ----------------- ----------------- ----------------- ----------------- ----------------- ----------------- ----------------- ----------------- 
----------------- ----------------- ----------------- ----------------- ----------------- -------BBB------- -------BBB------- -------BBB------- -------BCB------- -------BCB------- ---AAAAAAAAAAA--- --AAACCCCCCAAAA-- -----DDEDDDD----- ----------------- ----------------- ----------------- ----------------- ----------------- ----------------- ----------------- ----------------- ----------------- ----------------- ----------------- ----------------- ----------------- ----------------- ----------------- 
----------------- ----------------- ----------------- ----------------- -------BBB------- -------BBB------- ----------------- ----------------- --------F-------- --------F-------- ----AAAAAAAAA---- ---AAACCCCCAAA--- ------CCCCC------ -----EDDDEDD----- ----DDDDDDDDD---- ----DDDDDDEDD---- ---DEDEDEDDDDD--- ---DDDDDDDDDDD--- ---DEEDDDDDDED--- ---DDDDDEDDEDD--- ----DDDDDDDDD---- ----EDEDDDEED---- ----DDDDDDDDD---- -----DEDEDDD----- ------EDDDD------ -------DDE------- ----------------- ----------------- 
----------------- ----------------- ----------------- -------BBB------- -------BBB------- ----------------- ----------------- ----------------- ----------------- ----------------- -----AAAAAAA----- -----ACCCCCA----- ---AAACCCCCCAA--- --AAAACCCCCCAAA-- --AAAACCCCCCAAA-- --AAACCCCCCCAAA-- -AAAACCCCCCCAAAA- -FAAACCCCCCCAAAF- -FAAACCCCCCCAAAF- -AAAACCCCCCCAAAA- --AAACCCCCCCAAA-- --AAACCCCCCCAAA-- --AAACCCCCCCAAA-- ---AACCCCCCCAA--- ----AAAAAAAAA---- -----AAAAAAA----- ------AAAAA------ -------AFA------- 
----------------- ----------------- -------BBB------- -------BBB------- ----------------- ----------------- ----------------- ----------------- ----------------- ----------------- -----AAAAAAA----- -----AAAAAAA----- ----AAAAAAAAA---- ---AAAAAAAAAAA--- ---AAAAAAAAAAA--- ---AAAAAAAAAAA--- --AAAAAAAAAAAAA-- --AAAAAAAAAAAAA-- --AAAAAAAAAAAAA-- --AAAAAAAAAAAAA-- ---AAAAAAAAAAA--- ---AAAAAAAAAAA--- ---AAAAAAAAAAA--- ----AAAAAAAAA---- -----AAAAAAA----- ------AAAAA------ -------AAA------- --------A-------- 
----------------- -------BBB------- -------BBB------- ----------------- ----------------- ----------------- ----------------- ----------------- ----------------- ----------------- ----------------- -------AAA------- ------AAAAA------ -----AAAAAAA----- ----AAAAAAAAA---- ----AAAAAAAAA---- ----AAAAAAAAA---- ----AAAAAAAAA---- ----AAAAAAAAA---- ----AAAAAAAAA---- ----AAAAAAAAA---- ----AAAAAAAAA---- -----AAAAAAA----- ------AAAAA------ -------AAA------- --------A-------- ----------------- ----------------- 
-------BBB------- -------BBB------- ----------------- ----------------- ----------------- ----------------- ----------------- ----------------- ----------------- ----------------- ----------------- ----------------- ----------------- ----------------- ----------------- ----------------- ----------------- ----------------- ----------------- ----------------- ----------------- ----------------- ----------------- ----------------- ----------------- ----------------- ----------------- ----------------- 
-------BBB------- ----------------- ----------------- ----------------- ----------------- ----------------- ----------------- ----------------- ----------------- ----------------- ----------------- ----------------- ----------------- ----------------- ----------------- ----------------- ----------------- ----------------- ----------------- ----------------- ----------------- ----------------- ----------------- ----------------- ----------------- ----------------- ----------------- ----------------- 
