model
size = 32 32 31, scale = 0.05, origin = -y
material 
  colors = A:#FF0 B:#FFFA06 C:#100 D:#FFFF38 E:#CC0 F:#001 G:#660 H:#010 I:#330 J:#111 K:#990
voxels
3-26C5-28C3-3CAE22A3C-3C26A5C2(28A4C)9A2GCH3CFK10ACF2C7AG3C3FCH3CE8A4C6AGCHIE6AG3C7ACF2C5AGCHE10AGFC6ACF2C4AGCE13AEFK5A4C4ACE15AECG4A4C4AE17AGC4ACF2C22AEFG3A4C22ACJC3ACF2C28A4C2(7A3E)8A4C6AE2CIE5AEIHJE7A4C6AIHCFI5AI3CI7A4C6ACF2CF5A5C7ACF2C6ACF3C5A5C7A4C6ACH3C5A5C7A4C6A5C5A2C2FC7ACF2C6AE2CFC5AC2FCE7A4C7AE2CE5AEJCE8ACF2C2(28A4C)28A5C26A3C-3C24A3C3-28C5-26C6-26C5-CA26C3-C4A2BA2B3ADAB2A2BD2B2D2ABAC-CDB3ABD2B4AD5A2BD2B2A2BAD2C3(BA)2B2A2BA2D2AB3A3BA4BA2C3B3ABA3B4A2BAB3A4BA3B2CA3BABA2BAB2A2B3A3B2AB4ABA2CBABD5B2A2B3ADA2B2DA4B2AB2CB2A3B3ABAB2A2B3A2BADAB2ADAB2C2ABD3B2(A2B)2(AB)13A2CA3BA5BA2B4A2BAD2AB2A2(DA)2CA3BA2B3ADA4BA3B2A2B5AD2CA2B3AB6ABAB3A6B2A3D2C2BADA2B5AD2A2BADA2B2A2B3AD2C2B3ABDBAB4A3B3A2B2AB3ADA2C2B3A3B2A2B3A4BA2B2AB5A2C7BDB2A2B3AB2ABAB2A2B4A2CB4A3BAD2A5B3AB3A3BA2D2CBADABA2B6ABD2(BAB2A)B2AD2C2BAB2A2BA3B2A2BA4BD6B2A2CBA3BA2BAB2A3BA4BA2D3BD3B2C3ABD3BA2BAB3A3B2A2D2A2B2AB2C3A2BDB2A2B3AB4AB3AD2AB3A2C2B2(AB)A4BAB3A3B2A2B2A3B2A2CBA3B6AB5AB2A2BAB2A3BA2CB2A3B2AB3A4B7A3BD3B2C4B2(AB)A2B2(2AB)2A2B2ABD2BA2B2C3DBA3BAB3A2B4ABAB2ABDBA2B2C3(4BA)D2ABA2BABAD4AC-CB2ABA2B5AB3A3B3AB2ABABC3-28C5-26C5-2C2B2A2D2(AD)3A4B3DB3A2C3-CABDBAB2AB3A2B2A2BA6BA2BC-C2A2B2AB4AB3A2(4BA)4B3C3B3A3BA2BADA2B2ABABDB2A2B2ACDB3AB2A2BA2B4A2BA3B3DA2B2A2BAB9A2B3A2B2ABA2B4ABA2B5A2(BA)D2A4BA5B2AB3ABAB4AD2A3BABA3B3A3B11ABAB2A5B2AB2A6B2ABAB3A5BD3B2ABA2B2A2(BA)B3A6B2(2A2B)2AB2A2B2A4BA2BABA3BDB3A3BA4B2(4AB)ABD3B2A4B2A2B3ABA3B3A5B2A2B8ADA2DB3A2BAB2ABD2(B2A)3BA2B3A2DA2BAB3AB2(A2B)4(AB)7ADA9BA5B2(2AB)A5BAB2A3B4A2BA4B3A6BA2B2A3B3ABA3D2AB9AB3AB2ADA3B2AD5A4B2AB2A3B3ABA2B2A3BADA3B2ABA4B2(3AB)A3B2A2(2BA)DBAB2A2B2A3BABD2(B2A)BADABDBAB2A6B8AB2(4A3B)A2B6A6B3A2B2(AB)4AB3A4BAB3AB5A4B2(A2BAB)2A3BD3(B2A)BA6B2(AB)A5B3A2(2BABA)2BA4B2AB2A2B2(AB)2(A2B)2AB3ABA7BA2B3AB2A2B5A5B2(AB)2A2BA3B3AB2ABA3BABA2BCD3(BA)B4ABAB3AB2A2B3A4B2C2BAB2A2(BA)2DA3B2A3BA8BC-CA28C3-2CD2B3AD4AB2(2A2B)AD2ABC3-2CBDB8A3BABA2B3DB2AB2C-C3B2D2(2BA)BA3B3ABA6BDB3CB2A3B5A2B2AB9A3BA2C4B2(AB)A3B2ADABA2B2A3BA2B2ABA2B2A2BAB2A2B4AB3ABABDB2A4BA2B3A2B7AB2A2BA7BAB2A4B4A3B2A6B5A3B2(AB)2ABAB4AB2A4B4A4B2A2BAB3A3(BA)2B2A4BA2B3A2(B2A)3(BA)7BD3B4A3B2ABA5BA6B5AD4A5B4AB4A4B2A2(2BA)BAB2AD2(AB)2A2BAB2A2(2BA)B2AD3B2(3A2B)3AB8A2(B2A)2BA2B2ABA2B2A2BA3BAB4AB5AB4A3B2(5AB)ABA4B2ABA4B2(AB)A2B2(AB)A3BA2BA3B4A2BAB6AB2ABA3B4AB3A2(BA)B2A2(BA)2(DA)B3A9B2A4B3A2B4A2D2A2(3BA)B4A2BA5B3AD2AB2A3BA2B3A2BABA2B3ABA3BABAD3ABAB5A2(BA)B3AB5A3B4ADB2A2(BA)2DA5B5A3B2AB2A3BD3(B2A)BD2B2(AB)4ABA3B3A5B3A2B2A2BAB5A2B2A3BABA3BDAB2A2(BA)2BABA3B2A4B4A2B3A4B2(AB)3(2AB)A3BAB4A4B2AB5A2B2AB6A2B2ABA3B2A3B2(AB)A2B7A7B2AB3ABA2B2A4BDB4A2B6ABA4BA2B2A3BC2BABAD2A2B2AB2A3BAB2A4BA3B2CDBA2B2(3AB)2A2B3ABAB3ABA2BC-2C3BA2B6A4B2A3BA2D3AC2-CBA2B3A5B2A2B2ABA4B2ABAC-C10BA2BABA4BABA5BA2CD2BA2B2A2(BA)B2A4BA2B4A2(BA)CAB3A2(2BA)BAB3AB2ABA2B2AB7A3BD2B2A2DB2AB5A2BAD5(AB)A2B5ABA4B8A2B5ABA5BA2BA4BA2BABA2BA4B3A3BA3B3AB4AB3A2BAB4AB2A2B2ABA3BABA4BAB2A5B3ABA3B3ABABD4BA2B2A2BABA3B3ABA3BAB3A4B4A3B2(AB)5A2B2A3B3AB2A6B2A2(BA)DA2BA4B2(2A3B)A2(B3A)B4A3B2ABA5B2A2B2A6BABA5BA2BA3BA2(2B4A)2BAB3ABA2B3A2BD2BAB2A2(2BA)B2A2B7A2B2A4BA4B5A3B2AB3AB2A3B2A2B2A2(BA)B3ABAD5AB2A8BA3BAB3A2B5A2BAD3A2(B2A)BA4B2(3A2B)ADA3B4A5B3A4BA2BA3(B2A)B5AB3ABA2BA2(B2A)4B2AB3A2DAD2(AB)3A3BA3B4AB2DB4AB2A2B6ABA2B4A5BA2B3A3BABD3BAB3ABA3BABA3B2ABAB4ABABD2AB3A2BA2B11AB3A2B2A2B3AB6A2BAB2A2B2ABAB4A2(B2A)2B2(3A5B)A5B2AB2A2B2ABA3BAB2ABA3B2(2AB)DB3A3B2A3B2(AB)2ABA4BAB5AB2A2BA2(2B2A)B2A3BA4BAB3AB2A7BABCBAB2A2BAB3ABAD2ABA3BD2BA4BC-CA3B2(A2B)2AB5ABA3B3ABAC-2CBAB2ABA3B2(AB)A5B2AB2A3B3C3BAB2ABAB3A2BABD2B2A3BA2BA2C2BABA4BA2B2ABA3BABA2B3A2BAC4AB5A3BA2B2A5B2A2B2AB3ADABA4B2A3B2(AB)2(3AB)2DAB2A2(B3A)4BA5B3A6B7A2BA2(B2A)2BA4BABA2B3ABA6BAB2A7B6A2BDBA2B2A3BAB2A2B2ABA2(B2A)2B3A2BABA2B2A9B2(AB)2A3BA5B4A2BABD2B2ABAB7AB2A5B2(AB)A6BAD4A2B3A2(BA)B3A2B3AB4AB2ABD3B2ABAB5A2B3A2BAB3A4BA2B2AB3A2BABA4B3A6B5A2B3A3B2ABA2B2(2A4B)3ABA2B2A4(BA)8B2AB4A5BAB2ADB3A3(BA)2B2AB3AD2A3B3AB3A2B3A2(3B2A)2BAB2ADABD2BAB4AB5ABAB4A4BA2BA4BAB5A6B2(AB)A2B2(AB)2ABAB3A4BAB4A2B5A2B2AB5AB3ABA3BA2B2A2(BA2BA)BA2B3A3BAB2AB3A7BA2B2A4BA3B5A2(2BA)4BA2B3ABA2B2(2AB)D3BAB3A5B3A2BABA3B3AB2A2B5A2(B2A)BA6B3AB2A2BADAB5A4BA3BABA2BAB2(2A2B)3(4A2B)2A2BABA2B3A2BA2B2ABA4B3A2(BA)3BA7B2A3B2ABA2B2A2B3ABAB4AB2A2BA2B2ABAB2ABA5BABA3BCA2BA3BABA2B4A2BA3B2DB5A3C5B2A3BA3B3AD3ABD5B4CB2A4BA2BABA2BD2(BA)3BA4B3CB3A2(B2A)BA2B2ABD6B2AB2A2C2A2B3A3B3A4BA2B2A3B2A2BAC6A2B2(AB)A2BD2B3(2AB)A3B9AB6AB3A2B3ABAB2AB3ABAB6A2(2B2A)BA2BAB6A6BABA2BA3B3(AB)A3BA2BABA3B2DBA2B2ABAB3AB5AB2D2(BA)4B3(A2B)5AD2AB3ABD2BAB2(A2B)D4AB2ABAD3ABAB4A2(BA)2BA2B2DB2A2(BA)2B2(2AB)3A4B2(A2B)A3B2A2B3A5B2A2B3ABAB3ADA4BABA3B2A2BA5BA2BABA3BAD2AB3A2(BA)2B6A5BA5BDBAD2A3BA2B2AB3A3B2A2BD2(2BA)B3A2BABA2B2A2D2B2ABA2(B3A)BAB2A2(B3A)3B3(AB)3A4B2ABA7BAB2A3BAB4A3B2(3AB)4A2B2A3B2(AB)A4B4A3BA2B3AB4AB2A2B2A4BAB7ABA4B7A7BAB3ABA5BAD2A2B3A2BAB2ABA2BA4BABA2B3ABA3BA2BA3B2A2BAB3A2BDB3A3(BA)4B2(AB)6A2(2BA)3BAD2(AB)A6B2AB3ABAB3AB2ABAB2AD3A3B5A2BADA2B2(AB)2A2B2A2(3BA)BAB11ABA5BA3BAB3A2B2(2A3B)3AB3A3BAD2A2B3AB3A2BAB3ABD5B2(A2B4AB)A2B3A2B2ABA2BA5BAD2A3B4AB7A2BA3BA6BACD2A2(BA)2B3ABA3BABA2BD2B3ABA3CB3A3BA3BD2B2AB2A4BDB3A4CBAB4A2(2B2A)2B4ABD3BAB3C2AB3ABA3B2A2BA2B3A5B2AB2C3A2(2BA)3B2A2B3ABAD2A3BA2BCABA4BD8B2ABAB2A3BA2(B2A)3B3AB4ABA2B2A3B2(AB)2A2BA3BD6B3A4B3ABA3B2A3BA5B7A2B3A2(B2A)BD2B2(AB)A6B2(AB)4A3(2BABA)2B2ABA3B10ADA5BA2B2A3B3ABDABA5B2AD2AB2A2B4A3B2ABA4B3AB3A2BD2B2A2BAB11AB2A2BA9B3A3BA2B2AD5ABAB2A3B2(AB)A3B11ADA3B2A2B3AB2AB6ABA3B2A2BADA2B2A4BAB3A2B3A3BABA2B3AB4A2(BA)2BA3B2AB4A6B3A2B2AD2A2(2BA)B3A4B7AB4A2(BA)2BAB2A3BA3B4ABA5B2(2A2B)2A2(BA)BD2B2A2BA4BA2B3A6B2ABADAB2(A2B)5A2(BA)3BA5BAB2AB3A2BA3B2AB7A4B2A2BA3B2A2BD3(B2ABA)2(BA)B2A2BD2B3A5B2(2ABA2B)A2B3A2BA2(B2A)BAB5AB2A2BA3B2(A4B)2AB2A2BA3B3A2BAB3ABA2B2A3BA3B2A3BAB6AB2(A2B)4A7BD3B6AB2A2BA4B3A4B2AB2A2BDBA4BABA3B2ABAB3A2B2AB2A5B2A2(3BA)B3A2B2(2AB)2(4AB)ADAB3ABA2B2A2BABA2B2AB3ABA2BABC2A5B4A2BA3B5ABAB2ABAD3C3B3ABA4B3A3B2A2B2(AB)2A4C4BAD4A3B2A3B4A4B2A3C5B2ADA2BAB2A4B2A3BA2BAB2CA7B4AB2A2(BA)B4AB3A2BCBA3B2(A2B)2ABA3BAB2A3BD3B2ABA3B2A2B2A4B3AB4A5BAB2(A2B)4A5B2A2B4A2(BA)2(2BA)3B2A2B6A3BA2B2A6B6A3B3A3B2(A2B)2A4BAB2A2(BA)B2ABD4B2A2(BA)2BAD3A2BABA2B2A5BDABA4BAB3ABD2BABA7BA3B2(A2B)2A2(BA)4B6A3B2(AB2AB)ABA2B2ABAB5A2BA5B2AD2(2A2B)A5B2AB4A3B6ADABA2B9A2BA3BABA2B3ABAD2A2(BA)B5A4B2A3(BA)B3AD8AB2A9B2ADABA4B2ABAB5A3(BA)2B5ABAD2A2B4AB2ABA2B4(AB)2A2(BA)2BA3BA2BA6B2A2BABA3B4A2(BA)B10A3B2(5AB)AB4AB3AB2AB3A2BA3BAD2(B2A)4B2A2BAD2A3B3AB5AB2(2A2B)A2B2(AB)2ABAB2A2BA5BAB2A3BABA4BA3BA2B6A2(2BA)2B3ABA3B2AB4A2(3BA)2B2A3B4AB5A4B2(AB)2AB3A4B3A3B2(A2BAB)A2B2AB4AD2AB5A2(BA)2B2AB2AD2(A2B)A3B3A2B4A2BABA2B2A4(BA)7BA2BABA4B2AD2AB3ABAB3AB2D3B4A3B2A2B4A2B2ABAD2A5B2A2(BA)B2A2BA2B2AC2(A2B)AD2(A2B)2ABAB2AB3A2B2AD3C2A2B3A7B2(AB)AD4A4B4C2B4AD4A2BAD4ADA2B2ABAB3C2B2A3BAB3AB5A2BAB2AB3AB2C6B3A4B3ADAB2(2A2B)ABDCB2AB3A2B2(AB)2A2B2ABA2(2BD)BA4B2(3AB)A3BAB2(A2B)2(2AB)3A3BABA2BA2(B2A)4B5AB2ABAB2A5BA2BABA4B8A7B6A5B2(DB)3AD2A2(BA)8BA9BD2BA2B3A2B3(AB)5A2BABA4BABA2B3ABAB2A2(BA)2BABA4BDAB2ABAB2A3BABA2B8A9BAB2A2B6A3BA3B3AD3A2BA4B2A5B2AD3AB2A2BABADA3B3A2B2(AB)2ABAB2A5B6AD3AB4A2B2A2B3ABA4BAB2AB3ADABA4B4AB5AB3A2BABA2B2ABADA4B2A3BDB2(5A2B)2(AB)3A4BA2BD2BAB2A2B5A3BD3B4A5BA2BA3BAD2ABA3BABA5B3(AB)2(4AB)3AB2(A2B)5A2B2A3B2A2BA3BAB2AD2AB5A5B2(AB)A2B2A2B3AB7ABAB6AB2A2B2(AB3AB)A3B2ABAB2AD4AB2A3B3AB4A2BA2B2(2ABA3B)A2DBAB2A2B4A4(BA)4B3ABD2BAB4ABA2B3AB2A2D4B3A2(BA)6B2A2B2AB2A2BADABA2B2(AB)5AB8AB2AB3AD3A3BAB3A3B2ABAB2AB5ABA2B2ABA2BD8B2A2B2(A3B)A2(B2A)BA4BABD4B2(AB)5ACB2ABAB2A2B4A12B4A3C2A3B4A2B2AB4AB2AB3AB2A4CB3A2BAB2A2B3AD5A2BA4B3C2(B2A)3B2A4BADABA2BAB2A2BA2C2A4BA2B3A3B5A3B2ABA3BC2(DA)3B3(AB)3AB3A3(2BA)5B2(2AB)2A2B2A4BA3B2(AB)A5BA2BA2(3B2A)3BAD2(AB)A2D2(BA)2B4ABAB2A4B2A2BA2D2(AB)2DBAB3AB2ABD5BAB3A2B6A3B2AB3AB2A3BA3B2A2BA7BA3BABA2B2A2BD2B3A2BA2B2AB2(A2B)2(3A2B)2(A2B)3AB2(A3B)2A2(BA)4B2A2B3A3B2(AB)2A2B4AB2A3BABA2BAB3A2B2AB2A2B2ABA2BA3BA2B4AB6A2B2A5B2AB2(A2B)AB2A3B2ABAD4A2B4AB6ADAB5A3B2(2AB)AB2(A2B)AB10ABAD3A3BDABA6BA2B7A5B2ABAB3A3B2A2(BA)3BABA5BABA3BABA6B2(AB)2A3B3A2BA3B3AB3A2B2A3B2AD2ABA2B3ABD2B2A3B2AB4A4B3A3BA2BAB2A2(BA)3BAB2A3BA2B3ABA3B4A2BA2B3ABDB4AB3A2(BA)3B2AB2ADAB3AD3AB4A3B3A2B2A2BA2(B2A)2BADA4B3A2(B2A)B6AD2(2AB)AB3ABABD5BAB2A3B5ADABA3B2A5BD2B2(A2B3AB)4A2B2ABA2BA3BDBA4BA3B2(AB)AD2ADABA3B2A3(2BA)3B5A2B7A2BA2B7AB2(A3B)2(AB)A3BABA5B2ABAD2AB3ABACB4A2(BA)2BADABA2BA3B3AB2A2B3CB2A2B3ABDBA3BA2BAB2A2B2ABA4CB4AB5A3BAD2A3BAB2A2BA3C2AB3A2B10ABAB2A2B4A2CD2ABA2B2DB2A3B2A5B2AB3A2BCD2A7B4A2B5A6B2A5B2ABA5BA3BAB2A2(2BA)2(B4ABA)3B2A3B2(4A2B)2AD2(AB)4A2B4A3BAB3A2B2A3B3AB5A6B2(2A2B)A2B2A5BA4B2(2AB)2A4B5A5BAB3A9B2(AB)DB3A2BAB2A3B2AB8A2BABD3BD2B2A2BA5B2A4B2(AB)2(A3B)ABA2B2AB2A4BA2(B2A)2B2A3B2AB3ABAB3A2BA2B3AB5AB3A2(3BA)B2ABAB2A3B2A2B3(AB)4A2B3AB2ABAB6A2BABA2B3AB2ADAB2A2B4A4B2ABA3B4A2(BA)B3ABAB2A2B2(A3B)3A2B3A3B6ABAB2A2(BA)4BA3B2A2(2BA)B4A3B3AB2A3B2ABA3BA4BD4B2A2B2AD2A2B3A3B2A2B2AB2A2BA7B5A2BA4BDB2(A2B)2A2B2A4B3A3BA8B8A2BA2B2A3BA7BA2(B3A)B2A2B2A2(BA)2B2ABDB2AB4A2B2(AB)5ABA3B2AB3A3BA2B3A2BA2B2AB2A2BD7BAD3BD5BABD4B4A4BABA4B2A3B4A6BA3BAB2A3BDBA5B3ABAB3ABA2B2AB4ABA4B2A2BD2A2(2BA)D2(AB)2ABAB2ABAD7A2B2A3B2(A2B)2A7B2AD2A3BA2BACA5B5ADAB2A3B4A5B2A3C3BDBA2DAD5ABDB4A3BABA4CB2A2B5ABA3B4AB5ABAD3CAB2(A2B)AB2ABA2B2A3B2AB2A2BA2CA2(4B2A)B5A2(BA)2B2A2BACD5A2(B2A)2B5A3(BA)2(2BA)B3A2B2(3AB)D2B5A5B3A2B2A4B8A3B2A2(BA)3B3AB2A7BA3BAD6A2B3(AB)A3B2ABA6B5A3BAB2A3BABD2(B2A)BA2(B2A)2B2A5B3(AB)2(2A3B)2AB2A5B4ABAB2ABAB7ABABDABA2BA4B2A3BA2(B2A2B2A)BA2BABDBAB2A2B5A5BA4BA3BABA3B3(2A2B)2(A3B)3A2(BA)2(B3A)BADABA2B5AB5A2B3A2B2A5B2(3A2B)A5B2(A2B)D4A2B3A3BAB2A3B2ABA2BABA3BAB2A3B2A2B3A2B2AB2(A5B)A2BA5B2(2AB)4A2BAB2A2B2(AB)3A4BAB10A3BA5B5ABAB3AB6ABA2BAB5AB3A5B2AB3A4(BA)2BAB2A3(BA)D2ABA6BAB2AB3A2(BA)6B2ABA3BA4BA2(BA3B2A)7B2(AB)2(2AB)2A4BA2B2ABAB2AB5A2B2AB2AD2A4B2A2B4ABAB2(2ABA2B)5AB4A2BABA3BA3(B2A)3B4A11B3A3(2BA)3B2A3B3A3BD2B2ABAB5A2B5A2(BA)4B2(AB)DB4ABA2B4AB2A2B3A4BA5B2DBAB3A4B2AB6AB2A2BCBD2BA4B4A2(2BA)2(3BA)2BA3CB2ABDB6AB3AB2A4B4AB4C6BA4B2A3BA6B2AB2A3C2B6AB2A2(BA)5B2A2B2AB2A2C2(2AB)3AB6ABA2B2(AB)3A2BACD2ABA7BA3B2A3B4ABA2B2ABAB5ABAB2A2B2ABA2BAB2A2B2A3BAD2ABA2BABA4B2(2A3B)4AB5A2(3B2A)BA2(2B2A)B2(2A2B)3ABA2B2A2BADA2B4ABA4BDBA4BA2B2A3B5ABA3B2ABA2BA7BABA2B2A5BA3BA2BAB4A2BAB3ABA4B2A3B2A2BAB3AB4A2B8A4(2BA)3B2ABA3BA2B2AB2A4B3(A2B)3A2B4A3BABAD3A2BA2(B4A)4B2A3BDBAD4A3B2(AB)2AB3AD4A5BD3B2A4B4A2B2AB4AB8AB4A2B5ABAB3A2(B2A)BA2BAB4ABAB2A2(BA)2(2BA)2B3A3B2A4B2AB4A3B3A4BABA4B5ABDBA5B3A2(BA)2BA2(2B2A)BA3B2D7A2BABA4B2A2B2AB2A4BAB3A5B2ABA4BAB2A2(2BA)2B3ABA2BD2BAB2ABA4BA2B3A2(BA)BD3B4ABAB3AD2ABA3BA2BA3BD3B3A3B4A3B3ABADBAB4AB2(A3BA2B)A3B2A2BA3BA2BA3B4A2(B2A)2(BA)2BA4BA2BA6B4A10BAB2(2A2B)5A3B6A6B3A2B4ABA2BAB2ABAB3ABABDBA2B2A2(5B3A)2BDB2A5B2A4B2(AB)2A2BDCDB5A3BA4BA3BA2B3AB4A3C2BA9B4A2B2AB3A4B4CABA4BA2BAB2ABDB7A4B3C2AB2A3B2A2BAB2AB3A2(BA)DA3B2C2B2(AB)2(A2B)AB3ABA2B3AB2A3BCDB2ABAB5ABAB3AB2A3B2A5BAD2BAB2A2(BA)D4A3B7AB2A2BADBA2(B2A)2B3ABAB5AB3A2B7A4B2A2B5A2(BA)2(D3A)5BD2A2B2(AB)2A6B4A2B2(AB)A4B6A2(BA)B3A2B2A3BA5B3ABA3BAB3AB2A5B2A2BA3BAB2A6BD2B3AB2AB3AB4A2BA3B2A5BA2B2A4B2AB6A2(BA)B4A3(BA)B3ABA2BAB8A2BAB2AB4AD5B2ABAB3A3B5A2B7ABDBAB2A3B2AB7A4B2ABA2B3AB2A2BAB4A5BABA2BAB3A2B4A4B2A2B3AB5A4B3(AB)2(A2B)AB2AB5AB6A2B3A2B2A3B2AB4ABAB4A2BAB2A2B5A2B3AB2AD2AB3A2BA3B3A2B4A4(BA)2B3(AB)2ABA2BAB2A3B3A3B2A2BA4B3AB4ABA2B2A2BABA3B3A2B2A4BAB2A5BD5BABA3BAB4A2B2(DB)2ABD2(BA)B4A2B2AB2A2BA5BDAD2(2A3B)A2BABA5B3A2(B2A)B6AB2ABA2BAB4A2B3A2B2A2BA3B2A2B2A4B4A3B3ABA2B2AB4A2B2A2BAB3A2(BA)2BA2B4A2BABA6B2AB2A2BA2B2AB5AB3A3BA5BA3B2A2BA5B6A2BABA2BC4B2ABDB2(A2B)A8B2A3BA3C2BA2B2D4BA3B5A3BA2B2A4C4ABA2BDB2(A3B)6A2B2A3CB3(A2B)3AB4A6BA2B2A2CB2AB9AB2A5B2(AB)A3BAC2D3B3ABA5BA2B4A4BAB4ADB5A2BABA3BAB4A2(BA)2B3A2BA3B4A2B2ABA2B2AB2A4BA2BABA3B2AB2A3B2AB2(A2B)ADAB3A2BA3B3A4B6AB2DB3A2D4ABD2B2A2(2BA)BADA2B2A6B5A4B2(A2BAB)5AB5A2BAD3(2AB)3A2B2(2AB)3A2(DA)B4A2(BA)2BABA3B2(2A2B)A2B2ADA4B2(2A2B)A2BA7B2(A2B)3A2B2A2(2B5A)2BAB2A2B5A2B2(AB)2AB4AB2(A3B)10A2(BA)3B3A3(BA)B2A2(4B4A)4BA2DAB5AB2A5B2A2B5AB7AB6AB5ABAB4A6BA2B2AB8AB3AB2A3B2A2B4ABA4B2A5BAB2A5B3A2B2A3BA2B2(2AB)AB4A2BA3B3(2AB)A2B3AB3A2(2B2ABA)4B5ABA2B2A3BA2B3(AB)2ABA2B4A3B3ABA2B3A3BAB2A4BABD3B2A2BA2DA2B4A8B3A4BDB2A2B6ABAB6A2B2(4AB)2A2B2A2(BA)3BAB3A7B7A3B2A2(BA2BA)2BABA2BA4BA2BA5B3A4B2ABAB2A3B7A2B4A2B2A2(BA)2B7ABAB2A2B2AB3A2B2(AB)3A2BABA3BA2B3ABCA3(B2A)BA3BAB2ABAB2D4B2A3CD3BA3B2A4BABA3BD3B4A4CB3AB2AB2D8B2(AB)2AB2AD3C6BABA5B3ABA5B2AB2A2CBA3B2(2A2B)A2(B2A)2B2A3BABACD5(2BA)2(BA)D2AB2A5BAD3A2BABD3B2(2A2B)A3B2ABA4B2(AB)2(A2B)3A6B3A4B4A2BA2(B2A)BDB3(A2B)2(2A2B)2AB5A2(2B2A)6BA2B4A4B2(3A2(BA)B)ABDB5A6B2A2B2ABA5B2(AB)2(2AB)A2BA3BAB2A2B6A4B3ADA2(B4A)2BD2B3A3B2ABA2(B3A)DA3(B2A)2B2AB2A7B3A2B3AB2A2BABA2(2B2A3B3A)2BABA5BA2B3A2BA3B4A5BAB2A4B3AB2A3BA2BAB2A3BA4BA2BA3B2A3B4A2(BA)2(B4ABA)2(3BA)BA3BA4BADB3A3B3ABA5BABA2BAB3AB4A2BA5B2AB3AB2A3BABA5B3A2BA3B8ABAB4AB6AB7AB3A2B2ADAB2ABA2B3ABAD2ABAB4AB5A2BAB3A2B4A3B2(AB)A2B6ABAD3AB2A2BAB3A3BAB2ABAB2(2A2B)3A3B3ABA2B2A3B4A2B3A2(BA)B3AB2ABA2B3AB2A2B4A3BAB2ABA2B5A4BAB2A2(2BABA)2BA5BA2B2A2BDB6AB2ABA3B3ABA2BAB3AB2A2BAB3A2B5A2B7A2B3A2B2(2AB)6A3BAB2A2B3A2BAD2ABA2BADA2(2B2A)BAB2A2BCA2B4A2(BA)BD2(B2A)5B4A2B3C4B7AB4A3BABD2(2BA)4CD2B4ABDBAB3A3BABA3BA2BD3C2(2BA)5BA2BAB2A3BABA5B2CBAB4A6BA4B2ABAB2AB3ABCD2ABAB5AB6A2BAB2AD3A3B7ADA2BAB4AB2A3BAB6A4B2(AB)3A3B5A2BAB3AB2A5BA2B2ABA2B3A3BA2B2A2(BA)4(2BA)B2A2B2ABA4B2A3BA3B5A3B2A2BA2B5A2BAB2ABD3BDBAB2A3BABA2B2A3BAB3A2B2AB3ABDB5A5BA2B2(2AB)5ADAD2A2BAB2(A3B)AD4A4BABA2BABA4BAB3A2BABDBA2BABD2B2AB8ABA2B2(AB)2A9B7A3(3BA)BD3B3A2B3AB2A2B4A2(BA)B2AB3A2BAB3ABAB2AB4AB2A2B3(AB)A6BABA2BA5BAB2A3BAB4AB3ABA4BAB3A8B2ABAB2A2B4AB2A3BAB3A4BAB2A2B2(2AB)A2BA3BAB3AB2A3B2(A2B)2(AB)3ABABD2B7AB3A2B2(3AB)A2BAB2A4B2(A3B)2ADA2B2(AB)7A2B5AB4AB3AD2ABA4B2(A3B)2ABA2(B2A)BD2B2A3BAB3A2BA7BA3B2A2BABA3B3AB3A2B5A2B3AB2A2BD3BAB3A2B6A3(BA)B4A2B2ABABD2(BA)4B2A7B4A2B2(AB)2A4BABA3B3AB2ABAB5A5BAB5A2B2A4B5A3B2(A4B)2ABAB6A3B3A3B11ABAC3BA3B2ABA11BA2B3ABA3CB2A3B2ABAB2A5B2A2B4A2B4C4BABA4BDB2ABDB2ADAB2A3B3CA2BABA2B4A2B3A2BABA4BDBD2C3B2AB3A5B4A2B2ABA2B2(AB)C2A3B3ABAB2A9B4ABA3BA2B3AB2AB4ABA2BA6B2ABA3BA7BA2BA4BA2B3A2(B2ABA)5B3A2BA4B2A2BABA4B5A3B2(AB)2A2(2BA)4BA4B9A2B9ABA6BA13BDA2BAB2A2B3A2B4ABA7B3A4B4AB3A2(BA)D2A2B2(3AB)A3B2(3AB)4A2(BA)4BABA2BAB4AB3(A2B)2A3B2(AB)2A2(BA2BA)B5ABD3BA6BAB2A2B3A2B2DBA2BAB2A2(BA)B2ABA6BAB2ABD3BA2BAB4ADA3BAB7A2BA4B4A2(BA)2B6AB2A2B5A3(BA)2(2BA)B3A4B3(AB)2A2B3A2B2A2(BA)5BAB3A5B3A2BABA2D2B3A3B2ABA2BABA2BD2(BA)2B2A2B2(AB)A2B2DB4AB3A2BABD2BA2(3B2A)6BABA2B3A2(2BA)B2A5B7A3B2ADABA3B4AB2AB2(A2B)3A2BA2B2ABA4B2AB3ABAD2AB2A4B2(AB)2AB3AB2A6B3ADABADA3BA4B2A5B2(AB)5AB6A4B3A2(BA)B4A2BABA3B3AD3A3(B2ABA)BAB4A3BAB2A2(BA)4BA3B5A2B2ABA2B3A2BAB2A4B6AB2A2B3A4B2A2(B3A)2B4A2(2B2A)2BCB3A6B3AB2AB3A2BAB2A2B2A3C3A2BD3(2B3A)4BABA4C2BA3BAB3A9B2ABA3BA3C2AB2A3B3A2BABA2BDB4A3BAB2C2(2B2A)2BAB5A2(BA)6B2ABC4A2B2AB3A2BA4B2ABA3B2(2AB)3A2BAB2AB3ABAB4A2B4ABA6BAB2A3B2AB6AD5A2B2AB7ABA3B6AB4AD2A2(BA)B2ABAB3A2B4A2(BA)2BAB7A2B2A2B3A3BAD4A4BAB3AB2A2B4A2BAB4A2(B2A)3BADA2B3A2BA5B6A3BAB7ABAB2A2B3A2(2BA)2(BA)2BAB2A2(BA)B2ABA4BA2(B2A)4B3AB2A4BAB3A6BA3BD3BAB3A2B4AB3A2BA3B4ABD3B2(AB)2A5B4ABA6BAB2A2B2AB3AB2AB3A2B2(3AB)2(2AB)AB2A2BABA2B2ABAB5A2(2BA)5B2AB4A3B2A5B4A4B3ABA2BAB3A2BABDBAB2ABA2BABA2B3AD3A4B2A2BA5B2A2B3(2AB)2A2B3A2(BA)BDBA2B2ADA8BA7BA5BDB2AB5AB2A2B2A3B2ABAB3ABA3B7A2BD2(2B2A)2B5A4B2AB4A6BA2B3A4(BA)B2DB2A2B3ABA2BAB2AB8ABA2BA4B2ABA5BAB4A5BA5B2(DB)ABA2B2A5B3AD2(AB)5AB2ABA2B2A2(BA4BA)4BAB9ABA3B2A6BAB2A2(BA)4B3A2B2(2AB)4AB2A2B3ABAB2AB3A2B3AD3A2BA3B2AC2B4ABAB4A4B2AD2(AB)AD2ABA3C2(A3BAB)A3B3A2B5A2B4C2A3BA3B3A4B3D2BABA3BA3CAB2A2BA4BA2B2AB3D3B2A3BA2C2A4BA2B2ABA2BADA2D2BDBA3BABC2(2AB)2A4B2A3BDBAB2A8BA2B5A4B2A2B2AB2(A3B)2A3BA2B2A3B2(AB)2AB2AD2A2B4AB3A3B2A5B3ABA2BAB2A2B4ABA4BA2(B2A)B4A2(B2A)3B2(AB)5ABA6BAB2A2BABA2BA3BA2B2A3B5A4B3A2BA3B3A3B2A3B4ABA2B3(AB)A4B4A4BA3B3AB3A2BA5B4A2B2(AB)3A2B2D2(2B2A)B4ABADABA3BDB2(A3B)ABA3BABA2BAB4A2(BA)4BAB5A2(BA)BDB3A4BA5B4A2B2ABAB2A3B2(A2B)2(2AB)2A2BAB5A3B5ABAB2ABDBA3B4AB3A3BAB6A2BA3BA3(B2A)B7A3(BA)B2A4B2ABA2B4A2BABA5BAB5A2BA4B2(AB)A4B4AB5A3B2ABAB2A2BABDB4A3(BA)4B5A2(B2A)B3A3B3AB14A2BABA2B2ABAB4A2B2A3BA2(B3A)B4A2(BA)2BA6B2AB2A2B3AB4A2BA2B2A3BA2BA3B4A2B2AB4A2(BA)B3AB2(A2B)AB2ABA2BABA3BA5B2(A2B)3A3BA2B2A2B3A2BAB2A4B2A3BD2BA5BD9B2(A2B)3A2(BA)5BAB2A2BABA9BABADAB4AB2ABA2B2(AB)2A2BA2B2AB5A2B4(AB)CD2B2(AB)A2BA6B2(AB)3A3(BA)3CA3B3A4B2AB2A2B2ABA4B2A4C3B2(AB)3A4BA2BDBA3B4AD3C2AB5A2B5ADABD4B6A2C2(BA)4B2ABAD6ABA3BA4BACA2BABD4B2AD4AB2A2BABDB2(A2B)3A4B3AB6A2BABDBA2B4ABA2(B3A)2B2(AB)A2D3A2B2A3BABA2B2A5B2ABA2BAB3A3B2A2B3A2(2B2A)BA2B2A2B3ABAB2ABA3B2(AB)2(3AB)2(AB)A7BAB2ABA4B2(3AB)2AD3AB3A7BA2(B3A)2B2ABAB2A4BA2BA4BAB3ABAB5ABA3B2ABA2BA8BA5B2A3BA2B2(3AB)A2(BD)2BD2B3A2B2(AB)2A2BAB4A2B2(AB)D2B2(DB)2A3B4A2B2A2D2B3ABA2(B2A)3BA3B2A3B2(AB)3(2AB)AB2A3(BA)2BDBAB5A2BAD5B5A10B3A2B2(AB)DB9A2BAB3A2BA5B5A2BA3B3A4B2AB5A2B2AB4A2(B2A)BA2BAB3A2B2A4B2A2BA5B5A2BAB4AB7A2BA3BA5B2(AB)9ABAD3AB3A2BAD2A3B2(AB)A5BA2B2(AB)AD3ABA2BA3BA4B2A7B3ABA2D4ABAB6AB4A2B2A4B2A2B4AB5A3B2AB3A3(BA)3B2(ABA4B)2A2BAB2(AD)2B2(2AB)2(AB)2(3AB)2AD3(AB)2(A3B2AB)DB2ABAB2AD4A2B8AB4A2B2D2B2A4BA2B3(AB)A4B3A4BD4B8A2(2BA)3BCD2BA2B3A3(BA)B4A3BA4B2A3C3A3BABDBADA2BA4B4A4B4CB3ABA3BA2B3ABA2B2(AB)3A2D3C4B2AB2A6B2ABD3BA4BAD2CD2B3A4B3A2B2ADABA2B2A3B2ACAB3ABA4B3AB2A3(BA)3BA2B3A2BA4B2AB2ADA4BABA2B3A2B2ABA3BAB2AB3A3(B2A)BA2B4ABAB2A3BA3B5A2BA2B2ABAB2A3BABA3BA4BA2BA4BABA3B7ABAB2A3B2AB7A3B4ABA2B2A4BA2B4A2BAB2A2B5A2BD3(BA)3B3A3B2(AB)DB2A5BA4BABA5B4A3B2A2B2(AB)2A4B2(A3B)D2BAB3AB2AD3A3BA2BD2B2ABA5B5A2B4A6BA5B3(2AB)2A2D2B3ABAB2A2(2BA)4B2(AB)2AD2AB2A2B4AB3A3B2AB3A7BAB7A5B6A3BA2BABA4BA3BABA2B2ABAB2A2B2A3BDB3AB7A2BA3B2AB3ABA3B2A3(2BA)D4A3(BA)2B2ABADABDB2A7B2A4BAB2A2B3AB5A2BA5B4ABA3BDA2B5A2BA4BAB2AB4ABAB2A2B2A3B2ABA4B4A3B3(A2B)4ABD2B2A3(BA)DAD2A2B3ABA4BABA3B2A7B6A2(B4A)BAB5A2B4A4B7A4BA3B2AD2B2A4BA3B2A4BA2(B2A)BA4B2AB2(A2B)2ABDB4A4BA4B2A2(3BA)4B2ABDB2A5B2(3A4B)2DA2B3ABD2B2A2(BA)B6A2BABDC2BD2(BA)4B3AD2A3BAB7AB3C5BABDB6AB4ABA2B2A2B4C2AB4AB2A5B2AB6A2DAD3CBA2B2AB3AB5ABA2B2AB4A2D2C3(BA)B2A4B2A2BA2B2A4BABADCAB3A2(BA)5B2A2BAB2A3BA4BAB2AB5A2(B2A)3BABA2B3A3B2A3BAB2A4BABA4B2ABA2B4A2B2ABAB2ABA2BA3BA2B2AB3A2B2ABAB2A5BAB4AB3A2BAB2A2B2ABA4B4ABA3B2A3B2(A2B)3A3B2A2B3ABA5B2A2BA7B3(AB)A3BADA2B4A2BABA6B5A3B3A2B2(AB)4AB6ABAB5A3B2ABA6BA3B2ABAD2AB6ABDBAD3ABD2(BA)D3A3B2A6BAB2A2B2AB3ABAB5A2BA2(2B3A)B2A2B3AB5AB4A2B4AD2(A3B)2AB3A2BA5B3ABAB2ABDBAB3A2BA3BA4BD2B2AB2A3B3A3BA2BA3BAB2A7BABA6B2(AB)A2BABD5B2AB5A2B3A2B4(AB)2ABD2BA4B2AB3AB2A2(BA)2B2AB2A2(2BA)BA3(B2A)5BD2A3BAB2(3A3B)AB2AB3AB5ABD2B5A2B4AB2A4B2AB2(2A3B)2(4AB)AB3A3B2AB2A3B4AB2A2BA4B2ABA2(B3A)B2AB7AB5AB2D2B2A5B4A5BABA2BAB5A2B2ABA3B3AB2ABABD2BABA2B2A2(3BA)BA3B3ABAB2A4B3A4B2ABA7B4ADABA2BABDB2ABA2BAB3A4B2A4BAD2A3B2ABDCA2(2B3A)B3ABA2BAB5ABABD3CD4BA4B2A2BAB2A5BAB3A4C2A2B2(A4B)4A3B4ADAD3C3ABAB4AB3ABA3B2A4BAD2A2C2ABA3BAB2AB4A3B2A2BD2B4ACDABADA2B2ABAB4A2BA3B2(AB)A4B6ABA3BA2BABA2B2ABADA5B4A2B2AB4A2BAB5A2B2A5B3AB4ABA5B2A2(BA)2BABA5BAB2AB3AB2A5B4A3B2A2B3AB2A2BAB3ABADA2B2(AB)2(2AB)ABADAB3A2B2(AB)2ADAB2(2A4B)AB3AB4A2BA2B3A2B2ABD2BA3B4A4B2AB4A2B3A2B3(AB)A3B2A2BA4B2AB3ABA2DABA2BAB2(A3B)4A3B5AD2B2AB4A2B3A3BA5B2A3BAD2ABA4BA3B2AB2A3B2A5B2AB2ADABA5B2A3BA2B4A4B2A2(BA)B2A2B2ABA3BAB2A2(3BA)2BABD2B3A3B2ABA4B2(AB)4A4BDBA5BAB4A2BDB3ABA6B2A2B3A4BAB3A2(B2A)3BA4B2A2B3ABAB2A2BABA3B2A2(BA)2BA2B2ABAB3A2BA2B2AB2A3BABDB3ABA4BDB3ABA2BAB2ABA2BD2(2BA)B2A2(BA)2BA3B3A2B4(AB)4ABAB2A7B3AD3A3B8AB3ABA4B3AB4AB2A3(2BA)B3A2(2BA)B4ABA4B2ABA3B2A2BA3B2(AB)2(3ABAB)4A2(BD)5A3(BA)B5A2BADA2B2A2BA3B2A5BA5B4AB5A2(2BA)3B4A2B2AB3A3BABD3BADA3BDBABDC2BA3B2AB2(A3B)D2(BA)3BABA2B3CB4A2(BA)B3A4B2A2BDBAB2AB4CD2(2AB)3AB9AB2AB4A3CBA2(B4A)B3A3BA2BAB3ADA2C2(A4B)3A3B2(AB)3A2B2ABABC2A2B2AB3A9B7ABAB2ABAB10A4BA4B3AB4A3B3ABA5BA2B2A4B3A3BABA4B5A2(BA)2BAB3A4B3ABA2BA6B2AB5A7BA3BA2BABA2BDB2(4A3B)D2B9ABA2BDBA3B4A3B2A2B4A3B3A2(BA)4BA8B2A4BABA2B7ABAB2AD2AB3A2B2A3BAB2A3B3A2B4ABADB3AB2AB4A2(BA)B2ABA3BAB3AB2A2B2AB3A2(BA)2B2AB2A3BAB2A2B2ADAD2BAB2A2(BA)5B3A2B3A2(BA)D3ABA4BA6B2A2B4AB7A3B2ABA2B5A2BA2B4AB3A2BA2(4BD)B2A3BD2B2AD5A3BABDB2A3BA2BADAB2A5BAB3A3(BA)2BADAB2ABABD4BA4B2AB3ABA2BA2(3B2A)3BA2B4ABA2D2(2BAB2A)2B3A9BA3BABA4BABDBA5BA2BD2(BA)6B2AB3ABA10BABA2B2A5B2AB2A3B4A2B2(AB)2A2B6A5BAB5A2BAD3A2BDB2(A3B)A5BABA2B2ABAB2ABA5B4ABA2B4AB3A3BABA3BABD2BA3B3ABA2B2A2BA3B2AB4A5BD2B2AB2A3BABA2BAB4A2(BA)6BD3(AB)3A5BA3B2(AB)2ABD3BA2BC2(2A2BAB)4A2BABDB2A4BAB3CABA4B4ADAB3ABA3B2A2(BA)4CD3(AB)3ABA2BA2(B2A)BA2B3A3CB4A2B5AB2(2A5B)2A2C2A3B2AB2A2B3A3BABADA2BA4BCDB8A3B2A2B4ABA2B2A2BAB2A7BAB4ABD4BA5BAB2ABA3BABD2B4(AB)3AB3(A2B)AB3A2BA2BD2B3A2(BA)3BAB2ABA2B2(2AB)3(AB)2A4BABA4BA5B2AB3A3B2(2AB)A4B2A2BA5B2A2(BA)2BD2(BA)2(B4A)DA2B3A2BA3B3ABDB2ABD2BA4BABDB3A3B3AB5ABAB2ABA2BAB2ABDB3ABA4BA2B2ADABA2BA4BABA3(3B2A)2(BA)DBA7B3(AB)A2B2A2(BA)3B5ABAB3AB2AB3(A2B)3A5B2ADAB2A3BA3BDBA2B3AB2A4B2A3BABD4A2B3A2B2(AB)2A4B2(AB)2A2BA2B2ABA4B3A3B3AB4AB3A2B2AB3AB4A2B2A2BD2(B2A)B3A2B2(A3B)3A4BAB2A3B2A4B2ABAB3A2B5A2B2(AB)A3B3AB2A4B3(AB)DA2B3A3B3ABAB3A2B4A2BDB3A4B2ADABA2B2A2(BA)D2A4BD2BAB2A2BD2B3ABA2B2(2A4B)A2BDB2A5BA2B2(AB)5A2BA3B2AB2A2B2(3AB)ABA3B2AB9A2(B2A)BABDA3BAB3A2(BA)D3A3BA2(B3A)3BA2B3(AB)3AB2ABA5BA2B2ABA2BD3BABA3B3AB2A2B2ABA5B3A2BDAB8A4BA2B3AB4A2B2(AB)DCAD3A6BAB2AB3A2(2BA)3BAB3CD4A2(BA)B2AD2A4BA2B5AD2C-2C2(AB)4A2BABA2B2A9B2C-CD3(BA)2(2BA)B2A3BAB2ABABDB2A2C2BA2B2A2B3A4BAB3AD3A3BADC2(BA)B2A5BABDB2(A2B)4A2B3A2B2A4B3A3BA2B2(AB)3ABAB3A3BAB2A2BD2BAB4A2B2A2BAB2A2(BA)2B3A2BD3BABA3B2ABA2B2A2B3A2B2A2B3(AB)A2BABA2B3A4B6AB2A3BA2B3(AB)3A2BAB4ABA2BAB2A3BD2(2BA)BAB5AB3A2D2A7BADBA2BD2B2(AB)A4B2AB4A3BABA3B3A2B5A2BA3BA6BAB3ABDBA7BA2B2(AB)3ABAB8A2BDA5BD3BA2BABA3B2(AB)A2B2A2BA3BD2BAB2(A2B)5A2BAB3A3B3ABA3BA5BABD3BA2BA7BA2(B2A)2(2B3A)2B6A2BA3BAB4A4BA2B2A3B3A4B4A4BDBAB6A3B2AB2A2BAB2ABA4B2ABAB8AB3ABABD3B2A6B2AB3AB2DADAB2A2B2A3B2AB4A3(BA)4B9ABA3B4A3(BA)8BAB2ABA2BAB2AB6A3BA2B4A3(2BA)B2A2(B4A)B3ABA2BAB3A2(BA)2BA4B3A3B6A2BABA2B7ABABD3B2(A2B)AB4A3BABA2BAB3ABA3BA2BDBA2(B3A)3BA3BD3(AB)A2BABA3B3ABA3B2(AB)2ABADBA2B3AB2A5BABA2B2AB3AB4ADC2A2BAB2A3BA4BA2BA7B3A2CDA5B3A2B4ADABA2B2(AB)4AC-2CA3B2A4B2AD2ABDB3A2(BA)D2C2-3CB3AD3A2B2D2A3D4BDBD3C-C3B7A3(B2A)B3A2B2DA2D2C2A2(BA)3B4AB4A2B5AB4A2C2BA3BD2B3ABDB3ABD2(2BA)BA2BCD2(3BA)BA5B2A4B3A6BD3BA2BDB2AB3A2B2AB2A5BAB2A2(2BA)B2DBA3BAB4A7B6A2B4A2B2A2B3(AB)2AB3AB5A2BD4A4B2(3A2B)3A3BAB2(A2B)2(AB)2AB2(A2B)3ABAB3ABA2BAB4A2B2(AB)2ABA2BAB3A3BAD3A2B2(AB)2(A2B)2A3BA2B4ABDB3ABA2B2(AB)3ABA3BAB3A3B3ABA2B7ABABD3A2(BA)2B5ABA2B2A6BA2BABA2B8A4(2BA)BA7B5A3BAB2A3B2AB3AB2A3B2A12B3A4BA2B2ABA2BDB2A5B2A7BA3B2A3B3ABA4BAB8AB3A5B2A4B5ABA2BADA3BAB3ABA3B5A2B2A6BAB2AB4A3B2A6B2ABAB2A2BA2B3A2B2A2B2(AB)2(A2B)AB5A7B6ABDB2A10B2A2BA3B3ABAB4AB2(2A2B)A4B5AB2ABA3B3A4BA2B4ABA2B3(AB)2AD2A3(BA)B3AD3A2B2A5BA2(B2A)4BA3B2(2AB)2A2B2A3BAB3A3(BA)BD6AB2A2B2AB5A5B3A2B2ADC4ABA3BAB2AB6A2B2ABA4B2CDABA4BAB2A2B2A6B2AB4AB2C2D2A2(BA)B2ABA2B2AB5AB6AC-3CBD2(B2A)3B5D2A3D3B3C3-28C3-CA28C-CDABA3BD2BADAB6A4BA2BAD3C2AB3A4B3A2B2A3B2D2B2A2BD3CB4A2BA2B4ABA6B2A2BABD3C4BA3B2A2D10A2B3A2B3C2ABA4BAB2A2BADA4B4A4B3CA2(B3A)B6ABA9B2A3CABA2B3ABA3B4AB7AB2AB3C2B2ABA2B2A2B2(AB)A2B3A2B2ABAB3C2B2A2B5A3BA2BD2BA7BA3C2B2A2B5A2(BA)3B2(A2BAB)A3CBA6BA2BD5B2A2B3AB2A2B3C6ABDBA2B6AB2(A2B)A2DB3C3A2BA3B3ABA3BAB2(3A2B)3CAD3ABABDB2A3B2ABAB5AB3A3C2ABAB2A2B2AB4A7B2(A2B)3CAB2AB3AB4A2BAB2AB2(A2B)2AB3CABADA2(2B2A)2B7A3B4A3CD3AB5ABA3B4AB3A2B3AB3CA7BA3B2AB2A3BAB3ABA2B3CBAB2A2(3BABA)B3AB4A2BD3CAD2ABD4B5A4(BA)DA2BAB3C3ABA2B2A7B2AB3AD2A2(BA)3C4B2(AB)3AB2AB3A2B5A2(BA)3CAB3A2(B5A)B3ABAB2A3B3CBA2B2(AB)4A3B3(3AB)2A3CB4AB2A4B2A2B4ABA2B2AB2A3C3AD2ABAB2A2B2A4B2ABA3BD2B3CDAB6ABA3BAB2ABA2B4AB2A2C-CD4AB3AD2A2BAD2AD7A2DC3-28C5-26C5-28C3-3C3A2B3AD6ABA2BDB3A3C-3C2ADAB2A2BAD5ABA3BAD2AB5CD8AB2A2BA4B2AB2A2B2D4C2(3A4BAB)2AB2ADAB2D4C2(AB)DBA3B2(2AB)4ABAD2A3B4CA4B2AB4ABA5BAB3AB2AB4C4BA3BA2B6AB3A7B4C2BA2B4AB2A6B2A5BA2B4CB3A3B3ABA3BABDB2A4B3A4CBAD2AB2A3B3ABA2B2AD3AB2AB4C4ABD2BD6B2A3B4A4B4C2DABA4B3A2BA3BAB2ABAB2DB4C2DABA2B3A2(B2A)3BA2BD3BDB4C3ABA4BAB3A2B2(DB)A2B2A2BA4C2(2BA)2B2A2B3AB2D2B2A2BABDB4CBADAB3A4B4A2DABA2B3ABD4C2AD2ABA4BABAD2ADA2B5A2B4C3A2BADAB2A2B2AD3ABA2B2ADAB4C2(AB)DB2A2B3AB3A3BAB2ABA2B4CABA2B2AD3ABA2B3A4BA3BDB4CABA2BAB3AD2AB2(3A4B)4CBAB4A3B4A2BA2B4ADA2BA4C2(BA)3B2(AB)A5B3A3B3ABA4C2B4ABA3BA7BABA3BABA4C3B3A3B4A2(2B2A)B2A4B4CAB2ABABD7B3A2BA4BD2B5CAD3A3B4A4B2AB4AB2D3C-3C4D3A2BAB2AB4A2B2A2B3C3-28C5-26C3-
