model
size = 32 32 31, scale = 0.05, origin = -y
material 
  colors = A:#FF409F B:#FD3AB8 C:#FF48A3 D:#100 E:#0CC F:#E738A1 G:#010 H:#222 I:#ED0E12 J:#FFF K:#C9C L:#3CC M:#6CC
voxels
3-26A5-28A3-30A-45A7F24AF7IF22AF2D5I2DF20AF11DF18AF13DF16AF5D5H5DF15A5DH5JH2G3D15A5H7J5H43AKEK20AKEK5AK3E19AK3E5A2ELE19AEL2E2(5A4E19A4E)6A3EK17AK3E8AL2E7F3A7F2EM12A3GH3G3A3GH3G16A2DGDH5A3GDH18AD2G7A2GD201A-30A3-28A5-26A6-3B2AB8A2BA2B2C2B3A5-4AB2A2BAB2ABA2B2A3BCB3AB3-5A2BA2B3ABAB2A2(2BC)B2ABAB-BAB3ABC2B4AB5A2BC2B2A2BA4B2(AB)A2B2A2BA2B2AB3A3BA4B3A3B3ABA3B4A2BAB3A4BA3B3A3BABA2BAB2A2B3A3B2AB4A3(BA)BC5B2A2B3ABA2BCBA4B2ABA2B2A3B3ABAB2A2B3A2B2(AB)2ABA3B2ABC3B2(A2B)2(AB)14ABA3BA5BA2B4A2BA2(B2A)BAB4A3BA2B3ABA4BA3B2A2B5A3BA2B3AB6ABAB3A6B2A4BC2BABA2B5AB2A2BABA2B2A2B3ABA3B3ABCBAB4A3B3A2B2AB3ABA4B3A3B2A2B3A4BA2B2AB6AC7BCB2A2B3AB2ABAB2A2B5A2B4A3BAB2A5B3AB3A3BA5B2(AB)A2B6ABC2(BAB2A)B2ABAC2BAB2A2BA3B2A2BA4BC6B3A2BA3BA2BAB2A3BA4BABC3BC5B3ABC3BA2BAB3A3B3(2A2B)4A2BCB2A2B3AB4AB3AB2AB5A2B2(AB)A4BAB3A3B2A2B2A3B2A2(BA)3B6AB5AB2A2BAB2A3B2A2B2A3B2AB3A4B7A3BC3BA5B2(AB)A2B2(2AB)2A2B2ABC2BA3B4CBA3BAB3A2B4ABAB2ABCBA3BC3(4BA)B2ABA2B2(AB)4AB-CB2ABA2B5AB3A3B3AB2ABA2B3-2BA5B2A3B2A2B3(AB)2A3B5-2(CB)2(A2B)2ABA5BCB3A2B5-2(2A2B)2(AB)3A4B3CB4AB3-2A2(BA)B2AB3A2B2A2BA6BA3B-B2A2B2AB4AB3A2(4BA)4B2A4B3A3BA2BABA2B2ABABCB2A2B2ABCB3AB2A2BA2B4A2BA3B2CBA2B2A2BAB9A2B3A2B2ABA2B4ABA2B5A2(BA)B2A4BA5B2AB3ABAB4AB2A3BABA3B3A3B11ABAB2A5B2AB2A6B2ABAB3A5BC3B2ABA2B2A2(BA)B3A6B2(2A2B)2AB2A2B2A4BA2BABA3BCB3A3BA4B2(4AB)ABC3B2A4B2A2B3ABA3B3A5B2A2B8ABA2CB3A2BAB2ABC2(B2A)3BA2B3A2(2BA)B3AB2(A2B)4(AB)7ABA9BA5B2(2AB)A5BAB2A3B4A2BA4B3A6BA2B2A3B3ABA3B2AB9AB3AB2ABA3B2AB5A4B2AB2A3B3ABA2B2A3BABA3B2ABA4B2(3AB)A3B2A3(2BA)B2A2B2A3BABC2(B2A)2(BA)BCBAB2A6B8AB2(4A3B)A2B6A6B3A2B2(AB)4AB3A4BAB3AB5A4B2(A2BAB)2A3BC3(B2A)BA6B2(AB)A5B3A2(2BABA)2BA4B2AB2A2B2(AB)2(A2B)2AB3ABA7BA2B3AB2A2B5A5B2(AB)2A2BA3B3AB2ABA3BABA3BC3(BA)B4ABAB3AB2A2B3A4B2C2BAB2A2(BA)2BA3B2A3BA9B-3ABA4B10ABA3B2(AB)2A3-2BC2B3AB4AB2(2A2B)AB2ABA3-3BAB8A3BABA2B3CB2ABAB-C3B2A2(2BA)BA3B3ABA6BC3BCB2A3B5A2B2AB9A3B2A5B2(AB)A3B2A2(BA)2B2A3BA2B2ABA2B2A2BAB2A2B4AB3ABABCB2A4BA2B3A2B7AB2A2BA7BAB2A4B4A3B2A6B5A3B2(AB)2ABAB4AB2A4B4A4B2A2BAB3A3(BA)2B2A4BA2B3A2(B2A)3(BA)7BC3B4A3B2ABA5BA6B5AB4A5B4AB4A4B2A2(2BA)BAB2A2(BA)2(B2A2BA)2BAB2AC3B2(3A2B)3AB8A2(B2A)2BA2B2ABA2B2A2BA3BAB4AB5AB4A3B2(5AB)ABA4B2ABA4B2(AB)A2B2(AB)A3BA2BA3B4A2BAB6AB2ABA3B4AB3A2(BA)B2A4(BA)B3A9B2A4B3A2B4A2B2A2(3BA)B4A2BA5B3A2(B2A)3BA2B3A2BABA2B3ABA3B2(AB)3ABAB5A2(BA)B3AB5A3B4A2B2A2(BA)2BA5B5A3B2AB2A3BC3(B2A)BC2B2(AB)4ABA3B3A5B3A2B2A2BAB5A2B2A3BABA3BCAB2A2(BA)2BABA3B2A4B4A2B3A4B2(AB)3(2AB)A3BAB4A4B2AB5A2B2AB6A2B2ABA3B2A3B2(AB)A2B7A7B2AB3ABA2B2A4BCB4A2B6ABA4BA2B2A3BC2B2(AB)2A2B2AB2A3BAB2A4BA5BABA2B2(3AB)2A2B3ABAB3ABA2BC-5BA2B6A4B2A3BA2B3AB2-CBA2B3A5B2A2B2ABA4B2AB2A-11BA2BABA4BABA5B2ABC2BA2B2A2(BA)B2A4BA2B4A3(BA)B3A2(2BA)BAB3AB2ABA2B2AB7A3BC2B2ABCB2AB5A2B6(AB)A2B5ABA4B8A2B5ABA5BA2BA4BA2BABA2BA4B3A3BA3B3AB4AB3A2BAB4AB2A2B2ABA3BABA4BAB2A5B3ABA3B3ABABC4BA2B2A2BABA3B3ABA3BAB3A4B4A3B2(AB)5A2B2A3B3AB2A6B2A3(BA)2BA4B2(2A3B)A2(B3A)B4A3B2ABA5B2A2B2A6BABA5BA2BA3BA2(2B4A)2BAB3ABA2B3A2BC2BAB2A2(2BA)B2A2B7A2B2A4BA4B5A3B2AB3AB2A3B2A2B2A2(BA)B3ABAB5AB2A8BA3BAB3A2B5A2BAB3A2(B2A)BA4B2(3A2B)ABA3B4A5B3A4BA2BA3(B2A)B5AB3ABA2BA2(B2A)4B2AB3ABC3(AB)3A3BA3B4AB2CB4AB2A2B6ABA2B4A5BA2B3A3BABC3BAB3ABA3BABA3B2ABAB4ABABC2AB3A2BA2B11AB3A2B2A2B3AB6A2BAB2A2B2ABAB4A2(B2A)2B2(3A5B)A5B2AB2A2B2ABA3BAB2ABA3B2(2AB)CB3A3B2A3B2(AB)2ABA4BAB5AB2A2BA2(2B2A)B2A3BA4BAB3AB2A7BA3BAB2A2BAB3ABAB2ABA3BC2BA4BC-BA3B2(A2B)2AB5ABA3B3ABAB-3BAB2ABA3B2(AB)A5B2AB2A4B2A3BAB2ABAB3A2BABC2(2B2A3BA)BA4BA2B2ABA3BABA2B3A2B6AB5A3BA2B2A5B2A2B2AB3A2(BA)4B2A3B2(AB)2(3AB)CBAB2A2(B3A)4BA5B3A6B7A2BA2(B2A)2BA4BABA2B3ABA6BAB2A7B6A2BCBA2B2A3BAB2A2B2ABA2(B2A)2B3A2BABA2B2A9B2(AB)2A3BA5B4A2BABC2B2ABAB7AB2A5B2(AB)A6BAB4A2B3A2(BA)B3A2B3AB4AB2ABC3B2ABAB5A2B3A2BAB3A4BA2B2AB3A2BABA4B3A6B5A2B3A3B2ABA2B2(2A4B)3ABA2B2A4(BA)8B2AB4A5BAB2ACB3A3(BA)2B2AB3AB2A3B3AB3A2B3A2(3B2A)2BAB2ABABC2BAB4AB5ABAB4A4BA2BA4BAB5A6B2(AB)A2B2(AB)2ABAB3A4BAB4A2B5A2B2AB5AB3ABA3BA2B2A2(BA2BA)BA2B3A3BAB2AB3A7BA2B2A4BA3B5A2(2BA)4BA2B3ABA2B2(2AB)C3BAB3A5B3A2BABA3B3AB2A2B5A2(B2A)BA6B3AB2A2B2(AB)5A4BA3BABA2BAB2(2A2B)3(4A2B)2A2BABA2B3A2BA2B2ABA4B3A2(BA)3BA7B2A3B2ABA2B2A2B3ABAB4AB2A2BA2B2ABAB2ABA5BABA4BA2BA3BABA2B4A2BA3B2CB5ABC6B2A3BA3B2(3AB)C6B2(AB)2A4BA2BABA2BC2(BA)3BA4B2(3AB)2(2AB)A2B2ABC6B2AB3AB2A2B3A3B3A4BA2B2A3B2A2BAB6A2B2(AB)A2BC2B3(2AB)A3B9AB6AB3A2B3ABAB2AB3ABAB6A2(2B2A)BA2BAB6A6BABA2BA3B3(AB)A3BA2BABA3B2CBA2B2ABAB3AB5AB2C2(BA)4B3(A2B)5AB2AB3ABC2BAB2(A2B)C4AB2ABAB3ABAB4A2(BA)2BA2B2CB2A2(BA)2B2(2AB)3A4B2(A2B)A3B2A2B3A5B2A2B3ABAB3ABA4BABA3B2A2BA5BA2BABA3BAB2AB3A2(BA)2B6A5BA5BCBAB2A3BA2B2AB3A3B2A2BC2(2BA)B3A2BABA2B2ABC2B2ABA2(B3A)BAB2A2(B3A)3B3(AB)3A4B2ABA7BAB2A3BAB4A3B2(3AB)4A2B2A3B2(AB)A4B4A3BA2B3AB4AB2A2B2A4BAB7ABA4B7A7BAB3ABA5BAB2A2B3A2BAB2ABA2BA4BABA2B3ABA3BA2BA3B2A2BAB3A2BCB3A3(BA)4B2(AB)6A2(2BA)3B3(AB)A6B2AB3ABAB3AB2ABAB2AB3A3B5A2(2BABA)B2A2B2A2(3BA)BAB11ABA5BA3BAB3A2B2(2A3B)3AB3A3BAB2A2B3AB3A2BAB3ABC5B2(A2B4AB)A2B3A2B2ABA2BA5BAB2A3B4AB7A2BA3BA6B2(2AB)ABA2B3ABA3BABA2BC2B3AB2A3B3A3BA3BC2B2AB2A4BC2(B3A)BAB4A2(2B2A)2B4ABC3BA4B2AB3ABA3B2A2BA2B3A5B2A3B3A2(2BA)3B2A2B3ABAB2A3BA2B2ABA4BC8B2ABAB2A3BA2(B2A)3B3AB4ABA2B2A3B2(AB)2A2BA3BC6B3A4B3ABA3B2A3BA5B7A2B3A2(B2A)BC2B2(AB)A6B2(AB)4A3(2BABA)2B2ABA3B10ABA5BA2B2A3B3ABCABA5B2(2AB)2A2B4A3B2ABA4B3AB3A2BC2B2A2BAB11AB2A2BA9B3A3BA2B2AB5ABAB2A3B2(AB)A3B11ABA3B2A2B3AB2AB6ABA3B2A2BABA2B2A4BAB3A2B3A3BABA2B3AB4A2(BA)2BA3B2AB4A6B3A2B2AB2A2(2BA)B3A4B7AB4A2(BA)2BAB2A3BA3B4ABA5B2(2A2B)2A2(BA)BC2B2A2BA4BA2B3A6B2A3(BA)2BA2B5A2(BA)3BA5BAB2AB3A2BA3B2AB7A4B2A2BA3B2A2BC3(B2ABA)2(BA)B2A2BC2B3A5B2(2ABA2B)A2B3A2BA2(B2A)BAB5AB2A2BA3B2(A4B)2AB2A2BA3B3A2BAB3ABA2B2A3BA3B2A3BAB6AB2(A2B)4A7BC3B6AB2A2BA4B3A4B2AB2A2BCBA4BABA3B2ABAB3A2B2AB2A5B2A2(3BA)B3A2B2(2AB)2(4AB)2(AB)3ABA2B2A2BABA2B2AB3ABA2BAB3A5B4A2BA3B5ABAB2AB2(A3B)3ABA4B3A3B2A2B2(AB)6A4BAB4A3B2A3B4A4B2ABA6B2ABA2BAB2A4B2A3BA2BA3BA7B4AB2A2(BA)B4AB3A2BABA3B2(A2B)2ABA3BAB2A3BC3B2ABA3B2A2B2A4B3AB4A5BAB2(A2B)4A5B2A2B4A2(BA)2(2BA)3B2A2B6A3BA2B2A6B6A3B3A3B2(A2B)2A4BAB2A2(BA)B2ABC4B2A2(BA)2BAB3A2BABA2B2A5BCABA4BAB3ABC2BABA7BA3B2(A2B)2A2(BA)4B6A3B2(AB2AB)ABA2B2ABAB5A2BA5B2AB2(2A2B)A5B2AB4A3B6A2(BA)2B9A2BA3BABA2B3ABAB2A2(BA)B5A4B2A3(BA)B3AB8AB2A9B2A2(BA)4B2ABAB5A3(BA)2B5ABAB2A2B4AB2ABA2B4(AB)2A2(BA)2BA3BA2BA6B2A2BABA3B4A2(BA)B10A3B2(5AB)AB4AB3AB2AB3A2BA3BA2B2AB2A4B2A2BAB2A3B3AB5AB2(2A2B)A2B2(AB)2ABAB2A2BA5BAB2A3BABA4BA3BA2B6A2(2BA)2B3ABA3B2AB4A2(3BA)2B2A3B4AB5A4B2(AB)2AB3A4B3A3B2(A2BAB)A2B2AB4AB2AB5A2(BA)2B2(2AB)2(A2B)A3B3A2B4A2BABA2B2A4(BA)7BA2BABA4B2(2AB)3ABAB3AB2C3B4A3B2A2B4A2B2ABAB2A5B2A2(BA)B2A2BA2B4A2(2BA)B2(A2B)2ABAB2AB3A2B2A2BAB2A2B3A7B3(AB)4A4BABA3B4AB4A2BAB4ABA2B2ABAB2(2A3B)AB3AB5A2BAB2AB3A9B3A4B3ABAB2(2A2B)A2(B2A)B3A2B2(AB)2A2B2ABA2(2BC)BA4B2(3AB)A3BAB2(A2B)2(2AB)3A3BABA2BA2(B2A)4B5AB2ABAB2A5BA2BABA4B8A7B6A5B2(CB)3AB2A2(BA)8BA9BC2BA2B3A2B3(AB)5A2BABA4BABA2B3ABAB2A2(BA)2BABA4BCAB2ABAB2A3BABA2B8A9BAB2A2B6A3BA3B3AB3A2BA4B2A5B2AB3AB2A2B2(AB)A3B3A2B2(AB)2ABAB2A5B6AB3AB4A2B2A2B3ABA4BAB2AB3A2(BA)4B4AB5AB3A2BABA2B2A2(BA)4B2A3BCB2(5A2B)2(AB)3A4BA2BC2BAB2A2B5A3BC3B4A5BA2BA3BAB2ABA3BABA5B3(AB)2(4AB)3AB2(A2B)5A2B2A3B2A2BA3BA2(B2A)B5A5B2(AB)A2B2A2B3AB7ABAB6AB2A2B2(AB3AB)A3B2ABAB2AB4AB2A3B3AB4A2BA2B2(2ABA3B)ABCBAB2A2B4A4(BA)4B3ABC2BAB4ABA2B3AB2ABC4B3A2(BA)6B2A2B2AB2A2B2(AB)A2B2(AB)5AB8AB2A2(B3A)3BAB3A3B2ABAB2AB5ABA2B2ABA2BC8B2A2B2(A3B)A2(B2A)BA4BABC4B2(AB)6AB2ABAB2A2B4A12B4A2B3A3B4A2B2AB4AB2AB3A2(B2A)2B3A2BAB2A2B3AB5A2BA4B2(AB)2AB2A3B2A4B2(AB)A2BAB2A2B2AB2A4BA2B3A3B5A3B2ABA4BCABA3B3(AB)3AB3A3(2BA)5B2(2AB)2A2B2A4BA3B2(AB)A5BA2BA2(3B2A)3B4(AB)C2(BA)2B4ABAB2A4B2A2(2BA)BAB2CBAB3AB2ABC5BAB3A2B6A3B2AB3AB2A3BA3B2A2BA7BA3BABA2B2A2BC2B3A2BA2B2AB2(A2B)2(3A2B)2(A2B)3AB2(A3B)2A2(BA)4B2A2B3A3B2(AB)2A2B4AB2A3BABA2BAB3A2B2AB2A2B2ABA2BA3BA2B4AB6A2B2A5B2AB2(A2B)AB2A3B2ABAB4A2B4AB6ABAB5A3B2(2AB)AB2(A2B)AB10ABAB3A4BABA6BA2B7A5B2ABAB3A3B2A2(BA)3BABA5BABA3BABA6B2(AB)2A3B3A2BA3B3AB3A2B2A3B2(2AB)A2B3ABC2B2A3B2AB4A4B3A3BA2BAB2A2(BA)3BAB2A3BA2B3ABA3B4A2BA2B3ABCB4AB3A2(BA)3B2(2AB)A2(B3A)B4A3B3A2B2A2BA2(B2A)2BABA4B3A2(B2A)B6A2(B2A)BAB3ABABC5BAB2A3B5A2(BA)3B2A5BC2B2(A2B3AB)4A2B2ABA2BA3BCBA4BA3B3(AB)2A2(BA)3B2A3(2BA)3B5A2B7A2BA2B7AB2(A3B)2(AB)A3BABA5B2ABAB2AB3ABA2B4A2(BA)2B2(AB)A2BA3B3AB2A3BA2B2A2B3ABCBA3BA2BAB2A2B2AB5AB4AB5A2(3BAB2A)2B2A2(B3A)2B10ABAB2A2B5A2B2ABA2B2CB2A3B2A5B2AB3A3BC2A7B4A2B5A6B2A5B2ABA5BA3BAB2A2(2BA)2(B4ABA)3B2A3B2(4A2B)2A2(BA)B4A2B4A3BAB3A2B2A3B3AB5A6B2(2A2B)A2B2A5BA4B2(2AB)2A4B5A5BAB3A9B2(AB)CB3A2BAB2A3B2AB8A2BABC3BC2B2A2BA5B2A4B2(AB)2(A3B)ABA2B2AB2A4BA2(B2A)2B2A3B2AB3ABAB3A2BA2B3AB5AB3A2(3BA)B2ABAB2A3B2A2B3(AB)4A2B3AB2ABAB6A2BABA2B3AB2ABAB2A2B4A4B2ABA3B4A2(BA)B3ABAB2A2B2(A3B)3A2B3A3B6ABAB2A2(BA)4BA3B2A2(2BA)B4A3B3AB2A3B2ABA3BA4BC4B2A2B2AB2A2B3A3B2A2B2AB2A2BA7B5A2BA4BCB2(A2B)2A2B2A4B3A3BA8B8A2BA2B2A3BA7BA2(B3A)B2A2B2A2(BA)2B2ABCB2AB4A2B2(AB)5ABA3B2AB3A3BA2B3A2BA2B2AB2A2BC7BA4BC5BABC4B4A4BABA4B2A3B4A6BA3BAB2A3BCBA5B3ABAB3ABA2B2AB4ABA4B2A2BC2A2(2BA)2(BA)2(B2ABA)B7A2B2A3B2(A2B)2A7B2AB2A3BA2B3A5B5ABAB2A3B4A5B2AB2A3BCBA2BAB5ABCB4A3BA3(B2A)2B5ABA3B4AB5ABA3B2AB2(A2B)AB2ABA2B2A3B2AB2A2B4A2(4B2A)B5A2(BA)2B2A2BA2B5A2(B2A)2B5A3(BA)2(2BA)B3A2B2(3AB)C2B5A5B3A2B2A4B8A3B2A2(BA)3B3AB2A7BA3BAB6A2B3(AB)A3B2ABA6B5A3BAB2A3BABC2(B2A)BA2(B2A)2B2A5B3(AB)2(2A3B)2AB2A5B4ABAB2ABAB7A2(BA2BA)4B2A3BA2(B2A2B2A)BA2BABCBAB2A2B5A5BA4BA3BABA3B3(2A2B)2(A3B)3A2(BA)2(B3A)3(BA)2B5AB5A2B3A2B2A5B2(3A2B)A5BA2BA3B4A2B3A3BAB2A3B2ABA2BABA3BAB2A3B2A2B3A2B2AB2(A5B)A2BA5B2(2AB)4A2BAB2A2B2(AB)3A4BAB10A3BA5B5ABAB3AB6ABA2BAB5AB3A5B2AB3A4(BA)2BAB2A3(BA)B2ABA6BAB2AB3A2(BA)6B2ABA3BA4BA2(BA3B2A)7B2(AB)2(2AB)2A4BA2B2ABAB2AB5A2B2(2AB)2A4B2A2B4ABAB2(2ABA2B)5AB4A2BABA3BA3(B2A)3B4A11B3A3(2BA)3B2A3B3A3BC2B2ABAB5A2B5A2(BA)4B2(AB)CB4ABA2B4AB2A2B3A4BA5B2CBAB3A4B2AB6AB2A2BABC2BA4B4A2(2BA)2(3BA)2B2A3B2ABCB6AB3AB2A4B4A2BABA6BA4B2A3BA6B2AB5A2B6AB2A2(BA)5B2A2B2AB6AB2AB3AB6ABA2B2(AB)3A2B2(2AB)A7BA3B2A3B4ABA2B2ABAB5ABAB2A2B2ABA2BAB2A2B2A3BAB2ABA2BABA4B2(2A3B)4AB5A2(3B2A)BA2(2B2A)B2(2A2B)3ABA2B2A2BABA2B4ABA4BCBA4BA2B2A3B5ABA3B2ABA2BA7BABA2B2A5BA3BA2BAB4A2BAB3ABA4B2A3B2A2BAB3AB4A2B8A4(2BA)3B2ABA3BA2B2AB2A4B3(A2B)3A2B4A3B2(AB)3A2BA2(B4A)4B2A3BCBAB4A3B2(AB)2AB3AB4A5BC3B2A4B4A2B2AB4AB8AB4A2B5ABAB3A2(B2A)BA2BAB4ABAB2A2(BA)2(2BA)2B3A3B2A4B2AB4A3B3A4BABA4B5ABCBA5B3A2(BA)2BA2(2B2A)BA3BCB7A2BABA4B2A2B2AB2A4BAB3A5B2ABA4BAB2A2(2BA)2B3ABA2BC2BAB2ABA4BA2B3A2(BA)BC3B4ABAB3AB2ABA3BA2BA3BC3B3A3B4A3B3ABACBAB4AB2(A3BA2B)A3B2A2BA3BA2BA3B4A2(B2A)2(BA)2BA4BA2BA6B4A10BAB2(2A2B)5A3B6A6B3A2B4ABA2BAB2ABAB3ABABCBA2B2A2(5B3A)2BCB2A5B2A4B2(AB)2A2B3AB5A3BA4BA3BA2B3AB5A4BA9B4A2B2AB3A4B2(2AB)A4BA2BAB2ABCB7A4BA2B2AB2A3B2A2BAB2AB3A3(BA)2(3BA)2(BA)2(2BA)B3ABA2B3AB2A3BA2B2ABAB5ABAB3AB2A3B2A5BA3BAB2A2(BA)B4A3B7AB2A2(2BA)2(B2A)2B3ABAB5AB3A2B7A4B2A2B5A2(BA)2(B3A)6B2A2B2(AB)2A6B4A2B2(AB)A4B6A2(BA)B3A2B2A3BA5B3ABA3BAB3AB2A5B2A2BA3BAB2A6BC2B3AB2AB3AB4A2BA3B2A5BA2B2A4B2AB6A2(BA)B4A3(BA)B3ABA2BAB8A2BAB2AB4A6B2ABAB3A3B5A2B7ABCBAB2A3B2AB7A4B2ABA2B3AB2A2BAB4A5BABA2BAB3A2B4A4B2A2B3AB5A4B3(AB)2(A2B)AB2AB5AB6A2B3A2B2A3B2AB4ABAB4A2BAB2A2B5A2B3A2(B2A)B3A2BA3B3A2B4A4(BA)2B3(AB)2ABA2BAB2A3B3A3B2A2BA4B3AB4ABA2B2A2BABA3B3A2B2A4BAB2A5BC5BABA3BAB4A2B2(CB)2ABC2(BA)B4A2B2AB2A2BA6BAB2(2A3B)A2BABA5B3A2(B2A)B6AB2ABA2BAB4A2B3A2B2A2BA3B2A2B2A4B4A3B3ABA2B2AB4A2B2A2BAB3A2(BA)2BA2B4A2BABA6B2AB2A2BA2B2AB5AB3A3BA5BA3B2A2BA5B6A2BABA7B2ABCB2(A2B)A8B2A3BA2BC2BA2B2C4BA3B5A3BA2B4ACB4ABA2BCB2(A3B)6A2B2ABC3(2BA)2B3AB4A6BA2B2A3B2AB9AB2A5B2(AB)A3B2ABC3B3ABA5BA2B4A4BAB4A2B5A2BABA3BAB4A2(BA)2B3A2BA3B4A2B2ABA2B2AB2A4BA2BABA3B2AB2A3B2AB2(A2B)2(AB)3A2BA3B3A4B6AB2CB3A2B4ABC2B2A2(2BA)2(BA)2B2A6B5A4B2(A2BAB)5AB5A2BA3(B2A)B3A2B2(2AB)3A2(BA)B4A2(BA)2BABA3B2(2A2B)A2B2ABA4B2(2A2B)A2BA7B2(A2B)3A2B2A2(2B5A)2BAB2A2B5A2B2(AB)2AB4AB2(A3B)10A2(BA)3B3A3(BA)B2A2(4B4A)4BA2BAB5AB2A5B2A2B5AB7AB6AB5ABAB4A6BA2B2AB8AB3AB2A3B2A2B4ABA4B2A5BAB2A5B3A2B2A3BA2B2(2AB)AB4A2BA3B3(2AB)A2B3AB3A2(2B2ABA)4B5ABA2B2A3BA2B3(AB)2ABA2B4A3B3ABA2B3A3BAB2A4BABC3B2A2(2BA)2B4A8B3A4BCB2A2B6ABAB6A2B2(4AB)2A2B2A2(BA)3BAB3A7B7A3B2A2(BA2BA)2BABA2BA4BA2BA5B3A4B2ABAB2A3B7A2B4A2B2A2(BA)2B7ABAB2A2B2AB3A2B2(AB)3A2BABA3BA2B3A4(B2A)BA3BAB2ABAB2C4B2ABABC3BA3B2A4BABA3BC3B4ABABCB3AB2AB2C8B2(AB)2AB2A10BABA5B3ABA5B2AB2A3BA3B2(2A2B)A2(B2A)2B2A3BAB3A5(2BA)2(BA)2(B2A)5BAB3A2BABC3B2(2A2B)A3B2ABA4B2(AB)2(A2B)3A6B3A4B4A2BA2(B2A)BCB3(A2B)2(2A2B)2AB5A2(2B2A)6BA2B4A4B2(3A2(BA)B)ABCB5A6B2A2B2ABA5B2(AB)2(2AB)A2BA3BAB2A2B6A4B3ABA2(B4A)2BC2B3A3B2ABA2(B3A)BA3(B2A)2B2AB2A7B3A2B3AB2A2BABA2(2B2A3B3A)2BABA5BA2B3A2BA3B4A5BAB2A4B3AB2A3BA2BAB2A3BA4BA2BA3B2A3B4A2(BA)2(B4ABA)2(3BA)BA3BA4BA2B3A3B3ABA5BABA2BAB3AB4A2BA5B2AB3AB2A3BABA5B3A2BA3B8ABAB4AB6AB7AB3A2B2ABAB2ABA2B3ABAB2ABAB4AB5A2BAB3A2B4A3B2(AB)A2B6ABAB3AB2A2BAB3A3BAB2ABAB2(2A2B)3A3B3ABA2B2A3B4A2B3A2(BA)B3AB2ABA2B3AB2A2B4A3BAB2ABA2B5A4BAB2A2(2BABA)2BA5BA2B2A2BCB6AB2ABA3B3ABA2BAB3AB2A2BAB3A2B5A2B7A2B3A2B2(2AB)6A3BAB2A2B3A2BAB2ABA2BABA2(2B2A)BAB2A3BA2B4A2(BA)BC2(B2A)5B4A2B2A5B7AB4A3BABC2(2BA)4BC2B4ABCBAB3A3BABA3BA2BCBA3BA2BA5BA2BAB2A3BABA6B2(AB)4A6BA4B2ABAB2AB3A3B2ABAB5AB6A2BAB2AB3A3B7ABA2BAB4AB2A3BAB6A4B2(AB)3A3B5A2BAB3AB2A5BA2B2ABA2B3A3BA2B2A2(BA)4(2BA)B2A2B2ABA4B2A3BA3B5A3B2A2BA2B5A2BAB2ABC3BCBAB2A3BABA2B2A3BAB3A2B2AB3ABCB5A5BA2B2(2AB)5ABAB2A2BAB2(A3B)AB4A4BABA2BABA4BAB3A2BABCBA2BABC2B2AB8ABA2B2(AB)2A9B7A3(3BA)BC3B3A2B3AB2A2B4A2(BA)B2AB3A2BAB3ABAB2AB4AB2A2B3(AB)A6BABA2BA5BAB2A3BAB4AB3ABA4BAB3A8B2ABAB2A2B4AB2A3BAB3A4BAB2A2B2(2AB)A2BA3BAB3AB2A3B2(A2B)2(AB)3ABABC2B7AB3A2B2(3AB)A2BAB2A4B2(A3B)2ABA2B2(AB)7A2B5AB4AB3AB2ABA4B2(A3B)2ABA2(B2A)BC2B2A3BAB3A2BA7BA3B2A2BABA3B3AB3A2B5A2B3AB2A2BC3BAB3A2B6A3(BA)B4A2B2ABABC2(BA)4B2A7B4A2B2(AB)2A4BABA3B3AB2ABAB5A5BAB5A2B2A4B5A3B2(A4B)2ABAB6A3B3A3B11ABA4BA3B2ABA11BA2B3AB2(2A3B)2ABAB2A5B2A2B4A2B2ABA4BABA4B2(CB2AB)AB2A4B3A2BABA2B4A2B3A2BABA4BCB3A3B2AB3A5B4A2B2ABA2BABA2B2A3B3ABAB2A9B4ABA3BA2B3AB2AB4ABA2BA6B2ABA3BA7BA2BA4BA2B3A2(B2ABA)5B3A2BA4B2A2BABA4B5A3B2(AB)2A2(2BA)4BA4B9A2B9ABA6BA13BCA2BAB2A2B3A2B4ABA7B3A4B4AB3A2(BA)B2A2B2(3AB)A3B2(3AB)4A2(BA)4BABA2BAB4AB3(A2B)2A3B2(AB)2A2(BA2BA)B5ABC3BA6BAB2A2B3A2B2CBA2BAB2A2(BA)B2ABA6BAB2ABC3BA2BAB4ABA3BAB7A2BA4B4A2(BA)2B6AB2A2B5A3(BA)2(2BA)B3A4B3(AB)2A2B3A2B2A2(BA)5BAB3A5B3A2B2(AB)C2B3A3B2ABA2BABA2BC2(BA)2B2A2B2(AB)A2B2CB4AB3A2BABC2BA2(3B2A)6BABA2B3A2(2BA)B2A5B7A3B2A2(BA)3B4AB2AB2(A2B)3A2BA2B2ABA4B2AB3ABA2(B2A)4B2(AB)2AB3AB2A6B3A3(BA)3BA4B2A5B2(AB)5AB6A4B3A2(BA)B4A2BABA3B2(3AB)3(2ABAB)AB4A3BAB2A2(BA)4BA3B5A2B2ABA2B3A2BAB2A4B6AB2A2B3A4B2A2(B3A)2B4A2(2B2A)2BAB3A6B3AB2AB3A2BAB2A2B2ABAB3A2BC3(2B3A)4BABA6BA3BAB3A9B2ABA3BAB4AB2A3B3A2BABA2BCB4A3BAB3(2A2B)AB5A2(BA)6B2AB5A2B2AB3A2BA4B2ABA3B2(2AB)3A2BAB2AB3ABAB4A2B4ABA6BAB2A3B2AB6AB5A2B2AB7ABA3B6AB4AB2A2(BA)B2ABAB3A2B4A2(BA)2BAB7A2B2A2B3A3BAB4A4BAB3AB2A2B4A2BAB4A2(B2A)3BABA2B3A2BA5B6A3BAB7ABAB2A2B3A2(2BA)2(BA)2BAB2A2(BA)B2ABA4BA2(B2A)4B3AB2A4BAB3A6BA3BC3BAB3A2B4AB3A2BA3B4ABC3B2(AB)2A5B4ABA6BAB2A2B2AB3AB2AB3A2B2(3AB)2(2AB)AB2A2BABA2B2ABAB5A2(2BA)5B2AB4A3B2A5B4A4B3ABA2BAB3A2BABCBAB2ABA2BABA2B3AB3A4B2A2BA5B2A2B3(2AB)2A2B3A2(BA)BCBA2B2ABA8BA7BA5BCB2AB5AB2A2B2A3B2ABAB3ABA3B7A2BC2(2B2A)2B5A4B2AB4A6BA2B3A4(BA)B2CB2A2B3ABA2BAB2AB8ABA2BA4B2ABA5BAB4A5BA5B2(CB)ABA2B2A5B3A2(BA)B5AB2ABA2B2A2(BA4BA)4BAB9ABA3B2A6BAB2A2(BA)4B3A2B2(2AB)4AB2A2B3ABAB2AB3A2B3AB3A2BA3B2A3B4ABAB4A4B2A3(BA)B2A3(BA)2(3BABA)3B3A2B5A2BA3B2A3BA3B3A4B3C2BABA3B2(2AB)2A2BA4BA2B2A2(BC)3B2A3BA2B2A4BA2B2ABA2B2(AB)C2BCBA3BA2B2(2AB)2A4B2A3BCBAB2A8BA2B5A4B2A2B2AB2(A3B)2A3BA2B2A3B2(AB)2(2AB)2A2B4AB3A3B2A5B3ABA2BAB2A2B4ABA4BA2(B2A)B4A2(B2A)3B2(AB)5ABA6BAB2A2BABA2BA3BA2B2A3B5A4B3A2BA3B3A3B2A3B4ABA2B3(AB)A4B4A4BA3B3AB3A2BA5B4A2B2(AB)3A2B2C2(2B2A)B4A3(BA)3BCB2(A3B)ABA3BABA2BAB4A2(BA)4BAB5A2(BA)BCB3A4BA5B4A2B2ABAB2A3B2(A2B)2(2AB)2A2BAB5A3B5ABAB2ABCBA3B4AB3A3BAB6A2BA3BA3(B2A)B7A3(BA)B2A4B2ABA2B4A2BABA5BAB5A2BA4B2(AB)A4B4AB5A3B2ABAB2A2BABCB4A3(BA)4B5A2(B2A)B3A3B3AB14A2BABA2B2ABAB4A2B2A3BA2(B3A)B4A2(BA)2BA6B2AB2A2B3AB4A2BA2B2A3BA2BA3B4A2B2AB4A2(BA)B3AB2(A2B)AB2ABA2BABA3BA5B2(A2B)3A3BA2B2A2B3A2BAB2A4B2A3BC2BA5BC9B2(A2B)3A2(BA)5BAB2A2BABA9B3(AB)4AB2ABA2B2(AB)2A2BA2B2AB5A2B3(AB)2(A2B)2(AB)A2BA6B2(AB)3A3(BA)3BA3B3A4B2AB2A2B2ABA4B2ABC5B2(AB)3A4BA2BCBA3B4A3B3AB5A2B5ABABC4B6A3(BA)4B2ABAB6ABA3BA4BABA2BABC4B2AB4AB2A2BABCB2(A2B)3A4B3AB6A2BABCBA2B4ABA2(B3A)2B2(AB)A2B3A2B2A3BABA2B2A5B2ABA2BAB3A3B2A2B3A2(2B2A)BA2B2A2B3ABAB2ABA3B2(AB)2(3AB)2(AB)A7BAB2ABA4B2(3AB)2A2(B3A)7BA2(B3A)2B2ABAB2A4BA2BA4BAB3ABAB5ABA3B2ABA2BA8BA5B2A3BA2B2(3AB)A2(BC)2BC2B3A2B2(AB)2A2BAB4A2B2(AB)C2B2(CB)2A3B4A2B2ABC2B3ABA2(B2A)3BA3B2A3B2(AB)3(2AB)AB2A3(BA)2BCBAB5A2BA6B5A10B3A2B2(AB)CB9A2BAB3A2BA5B5A2BA3B3A4B2AB5A2B2AB4A2(B2A)BA2BAB3A2B2A4B2A2BA5B5A2BAB4AB7A2BA3BA5B2(AB)9ABA2(B3A)2BAB2A3B2(AB)A5BA2B3(AB)3ABA2BA3BA4B2A7B3ABA2B4ABAB6AB4A2B2A4B2A2B4AB5A3B2AB3A3(BA)3B2(ABA4B)2A2B2(AB)AC2B2(2AB)2(AB)2(3AB)2A4(BA)3B2ABA3B2ABCB2ABAB2AB4A2B8AB4A2B2C2B2A4BA2B3(AB)A4B3A4BC4B8A2(2BA)3B2A2BA2B3A3(BA)B4A3BA4B8A3BABC2(BA)2BA4B4A4BA4B3ABA3BA2B3ABA2B2(AB)3A2(B2A6B2A)BC3BA4B2(AB)C2B3A4B3A2B2A2(BA)2B2A3B2ABAB3ABA4B3AB2A3(BA)3BA2B3A2BA4B2(2AB)A4BABA2B3A2B2ABA3BAB2AB3A3(B2A)BA2B4ABAB2A3BA3B5A2BA2B2ABAB2A3BABA3BA4BA2BA4BABA3B7ABAB2A3B2AB7A3B4ABA2B2A4BA2B4A2BAB2A2B5A2BC3(BA)3B3A3B2(AB)CB2A5BA4BABA5B4A3B2A2B2(AB)2A4B2(A3B)C2BAB3AB2AB3A3BA2BC2B2ABA5B5A2B4A6BA5B3(2AB)2A4B3ABAB2A2(2BA)4B2(AB)2(2AB)2A2B4AB3A3B2AB3A7BAB7A5B6A3BA2BABA4BA3BABA2B2ABAB2A2B2A3BCB3AB7A2BA3B2AB3ABA3B2A3(2BA)B4A3(BA)2B2A2(BA)BCB2A7B2A4BAB2A2B3AB5A2BA5B4ABA4BA2B5A2BA4BAB2AB4ABAB2A2B2A3B2ABA4B4A3B3(A2B)4ABC2B2A4(BA)B2A2B3ABA4BABA3B2A7B6A2(B4A)BAB5A2B4A4B7A4BA2(3B2A)4BA3B2A4BA2(B2A)BA4B2AB2(A2B)2ABCB4A4BA4B2A2(3BA)4B2ABCB2A5B2(3A4B)CBA2B3ABC2B2A2(BA)B6A2BABA3BC2(BA)4B3AB2A3BAB7A2(BA)5BABCB6AB4ABA2B2A6B2AB4AB2A5B2AB6A2B2(AB)CBA2B2AB3AB5ABA2B2AB4A2B2A3(BA)B2A4B2A2BA2B2A4B2(AB)2AB3A2(BA)5B2A2BAB2A3BA4BAB2AB5A2(B2A)3BABA2B3A3B2A3BAB2A4BABA4B2ABA2B4A2B2ABAB2ABA2BA3BA2B2AB3A2B2ABAB2A5BAB4AB3A2BAB2A2B2ABA4B4ABA3B2A3B2(A2B)3A3B2A2B3ABA5B2A2BA7B3(AB)A3BABA2B4A2BABA6B5A3B3A2B2(AB)4AB6ABAB5A3B2ABA6BA3B2ABAB2AB6ABCBAB3ABC2(BA)B3A3B2A6BAB2A2B2AB3ABAB5A2BA2(2B3A)B2A2B3AB5AB4A2B4AB2(A3B)2AB3A2BA5B3ABAB2ABCBAB3A2BA3BA4BC2B2AB2A3B3A3BA2BA3BAB2A7BABA6B2(AB)A2BABC5B2AB5A2B3A2B4(AB)2ABC2BA4B2AB3AB2A2(BA)2B2AB2A2(2BA)BA3(B2A)6B2A3BAB2(3A3B)AB2AB3AB5ABC2B5A2B4AB2A4B2AB2(2A3B)2(4AB)AB3A3B2AB2A3B4AB2A2BA4B2ABA2(B3A)B2AB7AB5AB2C2B2A5B4A5BABA2BAB5A2B2ABA3B3AB2ABABC2BABA2B2A2(3BA)BA3B3ABAB2A4B3A4B2ABA7B4A2(BA)2BABCB2ABA2BAB3A4B2A4BAB2A3B2A2(BA)2(2B3A)B3ABA2BAB5ABA3(BC)4BA4B2A2BAB2A5BAB3A2BCB2A2B2(A4B)4A3B4ABAB2AB3ABAB4AB3ABA3B2A4BAB3AB2ABA3BAB2AB4A3B2A2BC2B4A2B2(AB)A2B2ABAB4A2BA3B2(AB)A4B6ABA3BA2BABA2B2A2(BA)5B4A2B2AB4A2BAB5A2B2A5B3AB4ABA5B2A2(BA)2BABA5BAB2AB3AB2A5B4A3B2A2B3AB2A2BAB3A2(BA)2B2(AB)2(2AB)3(AB)3A2B2(AB)2ABAB2(2A4B)AB3AB4A2BA2B3A2B2ABC2BA3B4A4B2AB4A2B3A2B3(AB)A3B2A2BA4B2AB3A2(BA2BA)B2(A3B)4A3B5A3B2AB4A2B3A3BA5B2A3BAB2ABA4BA3B2AB2A3B2A5B2(2AB)ABA5B2A3BA2B4A4B2A2(BA)B2A2B2ABA3BAB2A2(3BA)2BABC2B3A3B2ABA4B2(AB)4A4BCBA5BAB4A2BCB3ABA6B2A2B3A4BAB3A2(B2A)3BA4B2A2B3ABAB2A2BABA3B2A2(BA)2BA2B2ABAB3A2BA2B2AB2A3BABCB3ABA4BCB3ABA2BAB2ABA2BC2(2BA)B2A2(BA)2BA3B3A2B4(AB)4ABAB2A7B3AB3A3B8AB3ABA4B3AB4AB2A3(2BA)B3A2(2BA)B4ABA4B2ABA3B2A2BA3B2(AB)2(3ABAB)4A2(BC)5A3(BA)B5A2BABA2B2A2BA3B2A5BA5B4AB5A2(2BA)3B4A2B2AB3A3BABC3BABA3BCBAB2A2BA3B2AB2(A3B)C2(BA)3BABA2BA3B4A2(BA)B3A4B2A2BCBAB2A6B2(2AB)3AB9AB2AB4ABA2BA2(B4A)B3A3BA2BAB3ABAB2A4BA4B3A3B2(AB)3A2B2ABAB3A2B2AB3A9B7ABAB2ABAB10A4BA4B3AB4A3B3ABA5BA2B2A4B3A3BABA4B5A2(BA)2BAB3A4B3ABA2BA6B2AB5A7BA3BA2BABA2BCB2(4A3B)C2B9ABA2BCBA3B4A3B2A2B4A3B3A2(BA)4BA8B2A4BABA2B7ABA2(B2A)B3A2B2A3BAB2A3B3A2B4ABA2B3AB2AB4A2(BA)B2ABA3BAB3AB2A2B2AB3A2(BA)2B2AB2A3BAB2A2B2ABAC2BAB2A2(BA)5B3A2B3A2(BA)B3ABA4BA6B2A2B4AB7A3B2ABA2B5A2BA2B4AB3A2BA2(4BC)B2A3BC2B2AB5A3BABCB2A3BA2B2(AB)2A5BAB3A3(BA)2B2(AB)2ABABC4BA4B2AB3ABA2BA2(3B2A)3BA2B4ABABC2(2BAB2A)2B3A9BA3BABA4BABCBA5BA2BC2(BA)6B2AB3ABA10BABA2B2A5B2AB2A3B4A2B2(AB)2A2B6A5BAB5A2BAB3A2BCB2(A3B)A5BABA2B2ABAB2ABA5B4ABA2B4AB3A3BABA3BABC2BA3B3ABA2B2A2BA3B2AB4A5BA2B2AB2A3BABA2BAB4A2(BA)6B2A2(BA)B3A5BA3B2(AB)2ABC3BA3B2(2A2BAB)4A2BABCB2A2(4BA)BA4B4ABAB3ABA3B2ABAB3A3B3(AB)3ABA2BA2(B2A)BA2B4A3B4A2B5AB2(2A5B)3AB2A3B2AB2A2B3A3B2(AB)A2BA4BA2B8A3B2A2B4ABA2B2A2BAB2A7BAB4ABC4BA5BAB2ABA3BABC2B4(AB)3AB3(A2B)AB3A2BA2BC2B3A2(BA)3BAB2ABA2B2(2AB)3(AB)2A4BABA4BA5B2AB3A3B2(2AB)A4B2A2BA5B2A2(BA)2BC2(BA)2(B4A)BA2B3A2BA3B3ABCB2ABC2BA4BABCB3A3B3AB5ABAB2ABA2BAB2ABCB3ABA4BA2B2A2(BA)2BA4BABA3(3B2A)2(BA)2BA7B3(AB)A2B2A2(BA)3B5ABAB3AB2AB3(A2B)3A5B2ABAB2A3BA3BCBA2B3AB2A4B2A3BABC4A2B3A2B2(AB)2A4B2(AB)2A2BA2B2ABA4B3A3B3AB4AB3A2B2AB3AB4A2B2A2BC2(B2A)B3A2B2(A3B)3A4BAB2A3B2A4B2ABAB3A2B5A2B2(AB)A3B3AB2A4B3(AB)CA2B3A3B3ABAB3A2B4A2BCB3A4B2A2(BA)2B2A2(BA)B2A4BC2BAB2A2BC2B3ABA2B2(2A4B)A2BCB2A5BA2B2(AB)5A2BA3B2AB2A2B2(3AB)ABA3B2AB9A2(B2A)BABCA3BAB3A2(BA)B3A3BA2(B3A)3BA2B3(AB)3AB2ABA5BA2B2ABA2BA3BABA3B3AB2A2B2ABA5B3A2B2AB8A4BA2B3AB4A2B2(AB)3AB3A6BAB2AB3A2(2BA)3B2(A2B)4A2(BA)2(B2A)4BA2B5A2BA-B2ABAB4A2BABA2B2A11B-2A3(BA)2(2BA)B2A3BAB2ABABCB2AB2(A2B)2A2B3A4BA2(B3A)3BABC2(BA)B2A5BABCB2(A2B)4A2B3A2B2A4B3A3BA2B2(AB)3ABAB3A3BAB2A2BC2BAB4A2B2A2BAB2A2(BA)2B3A2BC3BABA3B2ABA2B2A2B3A2B2A2B3(AB)A2BABA2B3A4B6AB2A3BA2B3(AB)3A2BAB4ABA2BAB2A3BC2(2BA)BAB5AB3A2B2A7BACBA2BC2B2(AB)A4B2AB4A3BABA3B3A2B5A2BA3BA6BAB3ABCBA7BA2B2(AB)3ABAB8A2BCA5BC3BA2BABA3B2(AB)A2B2A2BA3BC2BAB2(A2B)5A2BAB3A3B3ABA3BA5BABC3BA2BA7BA2(B2A)2(2B3A)2B6A2BA3BAB4A4BA2B2A3B3A4B4A4BCBAB6A3B2AB2A2BAB2ABA4B2ABAB8AB3ABABC3B2A6B2AB3A3B2(AB)2A2B2A3B2AB4A3(BA)4B9ABA3B4A3(BA)8BAB2ABA2BAB2AB6A3BA2B4A3(2BA)B2A2(B4A)B3ABA2BAB3A2(BA)2BA4B3A3B6A2BABA2B7ABABC3B2(A2B)AB4A3BABA2BAB3ABA3BA2BCBA2(B3A)3BA3BC3(AB)A2BABA3B3ABA3B2(AB)2AB2(A2B)3AB2A5BABA2B2AB3AB4A2B2A2BAB2A3BA4BA2BA7B4A2BA5B3A2B4A2(BA)2B2(AB)5A-2BA3B2A4B2(2AB)CB3A2(BA)B2A2-4B3AB3A2BAB2A2BC4BAB2A2B-A3B7A3(B2A)B3A2BCBA2BCB2A2(BA)3B4AB4A2B5AB4ABA2BA3BC2B3ABCB3ABC2(2BA)BA2B2A2(3BA)BA5B2A4B3A6BA3BA2BCB2AB3A2B2AB2A5BAB2A2(2BA)B2CBA3BAB4A7B6A2B4A2B2A2B3(AB)2AB3AB5A2B5A4B2(3A2B)3A3BAB2(A2B)2(AB)2AB2(A2B)3ABAB3ABA2BAB4A2B2(AB)2ABA2BAB3A3BAB3A2B2(AB)2(A2B)2A3BA2B4ABCB3ABA2B2(AB)3ABA3BAB3A3B3ABA2B7ABA2B3A2(BA)2B5ABA2B2A6BA2BABA2B8A4(2BA)BA7B5A3BAB2A3B2AB3AB2A3B2A12B3A4BA2B2ABA2BCB2A5B2A7BA3B2A3B3ABA4BAB8AB3A5B2A4B5ABA2BABA3BAB3ABA3B5A2B2A6BAB2AB4A3B2A6B2ABAB2A2BA2B3A2B2A2B2(AB)2(A2B)AB5A7B6ABCB2A10B2A2BA3B3ABAB4AB2(2A2B)A4B5AB2ABA3B3A4BA2B4ABA2B3(AB)2(2AB)3(AB)3AB3A2B2A5BA2(B2A)4BA3B2(2AB)2A2B2A3BAB3A3(BA)BC6AB2A2B2AB5A5B3A2B2AB5ABA3BAB2AB6A2B2ABA7BABA4BAB2A2B2A6B2AB4A5B2A2(BA)B2ABA2B2AB5AB7A-2C2BC2(B2A)3BA2BCB2A2BC3B3A3-ABA3B2A2BC2(BA)5B2(2AB)AB3-B4A2B2ABAB4A2B2A2BA3B2A2B-C2(BA)3BA2B2(AB)6A4BA2BA2(B2A)B3A4B3A2B2A3B2C2B2A2BCB2AB4A2BA2B4ABA6B2A2BABC2BA4BA3B2A2B10A2B3A3BC3ABA4BAB2A2BABA4B4A4BA2BA2(B3A)B6ABA9B4A2(BA)2B3ABA3B4AB7AB2(2A2B)2ABA2B2A2B2(AB)A2B3A2B2ABA2(2B2A)2B5A3BA2BC2BA7B2ABA2B2A2B5A2(BA)3B2(A2BAB)2A3BA6BA2BC5B2A2B3AB2A2BA2B6ABCBA2B6AB2(A2B)ABC4B3A2BA3B3ABA3BAB2(3A2B)AB2AB3ABABCB2A3B2ABAB5AB4AB3ABAB2A2B2AB4A7B2(A2B)A2(B2A)B3AB4A2BAB2AB2(A2B)2(2AB)2(AB)A2(2B2A)2B7A3B4ABA2B3AB5ABA3B4AB3A2B3ABAB2A7BA3B2AB2A3BAB3ABA6BAB2A2(3BABA)B3AB4A2B5AB2ABC4B5A5(BA)2BABA2B3ABA2B2A7B2AB3AB2ABAB3A5B2(AB)3AB2AB3A2B5A2(BA)2(B3A)2(B5A)B3ABAB2A3BC2(BA)2B2(AB)4A3B3(3AB)2ABC2B4AB2A4B2A2B4ABA2B2(2AB)CB3AB2ABAB2A2B2A4B2ABA3BC6BAB6ABA3BAB2ABA2B4AB2A2B-CB4AB3AB2A2BAB2AB7A2BA3-CBA3BA2(B3A)2B2ABA5BAB5-B2AB3A2B2CBA2B2(3AB)A2B5-2B4A6B3AB6A2(2BA)3-B5A2B3AB6ABA2BAB3AB2A-A2B2ABAB2A2BAB5ABA3BAB2A2B3A2B8AB2A2BA4B2AB2A2BC3B2(AB3A4B)A2(B2A)BAB2CBC3ABABCBA3B2(2AB)4ABAB2A3BA2B2A4B2AB4ABA5BAB3AB2ABA2BA4BA3BA2B6AB3A7BAB2A2BA2B4AB2A6B2A5BA4B2AB3A3B3ABA3BABCB2A4B4ABA2BA2(B2A)3B3ABA2B2(2AB3AB)4ABC2BC6B2A3B4A4B2A4BABA4B3A2BA3BAB2ABAB2C2B2A3BABA2B3A2(B2A)3BA2BC3BCBAB5ABA4BAB3A2B2(CB)A2B2A2B3A4B2(A2B)2A2B3AB2C2B2A2BABC4B3(AB)3A4B4A2BABA2B3ABC2B4AB2ABA4B2(AB)2ABA2B5A2B3AB3A2B2(AB)2A2B2AB3ABA2B2A2(BA)B3ABABCB2A2B3AB3A3BAB2ABA6BABA2B2AB3ABA2B3A4BA3BC4(BA)2BAB3AB2AB2(3A4B)ABA2BAB4A3B4A2BA2B4ABA2B5A2(BA)3B2(AB)A5B3A3B3ABA3BA2B4ABA3BA7BABA3BABA2B2A3B3A3B4A2(2B2A)B2A7B2(2AB)ABC7B3A2BA4BC2B2C2B2AB3A3B4A4B2AB4AB2C3B-C6B3A2BAB2AB4A2B2A4BC3-2(2B5A)B3AB5AB2AB5-2ABA7BA3BABA2B2(AB)2A3-
