model
size = 20 26 24, scale = 0.05, origin = -y
material 
  colors = A:#EEE B:#BBB C:#111 D:#D00 E:#00E
voxels
-------------------- -------------------- -------------------- ------------BBBB---- ------------CCCC---- ------------CCCC---- -------------B------ -------------B------ -------------B------ -------------B------ -------------B------ -------------B------ -------------B------ -------------B------ -------------B------ -------------B------ -------------B------ -------BBBBBBB------ -------------------- -------------------- -------------------- -------------------- -------------------- -------------------- -------------------- -------------------- 
-------------------- -------------------- -------------------- ------------BBBB---- ------------CBBC---- ------------CCCC---- -------------------- -------------------- -------------------- -------------------- -------------------- -------------------- -------------------- -------------------- -------------------- -------------------- -------------------- -------B------------ -------------------- -------------------- -------------------- -------------------- -------------------- -------------------- -------------------- -------------------- 
-------------------- -------------------- -------------------- ------------BBBB---- ------------CBBC---- ------------CCCC---- -------------------- -------------------- -------------------- -------------------- -------------------- -------------------- -------------------- -------------------- -------------------- -------------------- -------------------- -------B------------ -------------------- -------------------- -------------------- -------------------- -------------------- -------------------- -------------------- -------------------- 
-------------------- -------------------- -------------------- -----BBBBBBBBBBB---- -----BBBBBBBBBBB---- -----BBBBBBBBBBB---- -----BBBBBBBBBBB---- -----BBBBBBBBBBB---- -----BBBBBBBBBBB---- -----BBBBBBBBBBB---- -----BBBBBBBBBBB---- -----BBBBBBBBBBB---- -----BBBBBBBBBBB---- -----BBBBBBBBBBB---- -----BBBBBBBBBBB---- -----BBBBBBBBBBB---- -----BBBBBBBBBBB---- -----BBBBBBBBBBB---- -----BBBBBBBBBBB---- -----BBBBBBBBBBB---- -------------------- -------------------- -------------------- -------------------- -------------------- -------------------- 
-------------------- -------------------- -------------------- -----BBBBBBBBBBB---- -----BBBBBBBBBBB---- -----BBBBBBBBBBB---- -----BBBBBBBBBBB---- -----BBBBBBBBBBB---- -----BBBBBBBBBBB---- -----BBBBBBBBBBB---- -----BBBBBBBBBBB---- -----BBBBBBBBBBB---- -----BBBBBBBBBBB---- -----BBBBBBBBBBB---- -----BBBBBBBBBBB---- -----BBBBBBBBBBB---- -----BBBBBBBBBBB---- -----BBBBBBBBBBB---- -----BBBBBBBBBBB---- -----BBBBBBBBBBB---- -------------------- -------------------- -------------------- -------------------- -------------------- -------------------- 
---AAAAAAAAAAAAAA--- ---AAAAAAAAAAAAAA--- ---AAAAAAAAAAAAAA--- ---AAAAAAAAAAAAAA--- ---AAAAAAAAAAAAAA--- ---AAAAAAAAAAAAAA--- ---AAAAAAAAAAAAAA--- ---AAAAAAAAAAAAAA--- ---AAAAAAAAAAAAAA--- ---AAAAAAAAAAAAAA--- ---AAAAAAAAAAAAAA--- ---AAAAAAAAAAAAAA--- ---AAAAAAAAAAAAAA--- ---AAAAAAAAAAAAAA--- ---AAAAAAAAAAAAAA--- ---AAAAAAAAAAAAAA--- ---AAAAAAAAAAAAAA--- ---AAAAAAAAAAAAAA--- ---AAAAAAAAAAAAAA--- ---AAAAAAAAAAAAAA--- ---AAAAAAAAAAAAAA--- ---AAAAAAAAAAAAAA--- ---AAAAAAAAAAAAAA--- -------------------- -------------------- -------------------- 
--AAAAAAAAAAAAAAAA-- --AAAAAAAAAAAAAAAA-- --AAAAAAAAAAAAAAAA-- --AAAAAAAAAAAAAAAA-- --AAAAAAAAAAAAAAAA-- --AAAAAAAAAAAAAAAA-- --AAAAAAAAAAAAAAAA-- --AAAAAAAAAAAAAAAA-- --AAAAAAAAAAAAAAAA-- --AAAAAAAAAAAAAAAA-- --AAAAAAAAAAAAAAAA-- --AAAAAAAAAAAAAAAA-- --AAAAAAAAAAAAAAAA-- --AAAAAAAAAAAAAAAA-- --AAAAAAAAAAAAAAAA-- --AAAAAAAAAAAAAAAA-- --AAAAAAAAAAAAAAAA-- --AAAAAAAAAAAAAAAA-- --AAAAAAAAAAAAAAAA-- --AAAAAAAAAAAAAAAA-- --AAAAAAAAAAAAAAAA-- --AAAAAAAAAAAAAAAA-- --AAAAAAAAAAAAAAAA-- -------------------- -------------------- -------------------- 
-AAAAAAAAAAAAAAAAAA- -AAAAAAAAAAAAAAAAAA- -AAAAAAAAAAAAAAAAAA- -AAAAAAAAAAAAAAAAAA- -AAAAAAAAAAAAAAAAAA- -AAAAAAAAAAAAAAAAAA- -AAAAAAAAAAAAAAAAAA- -AAAAAAAAAAAAAAAAAA- -AAAAAAAAAAAAAAAAAA- -AAAAAAAAAAAAAAAAAA- -AAAAAAAAAAAAAAAAAA- -AAAAAAAAAAAAAAAAAA- -AAAAAAAAAAAAAAAAAA- -AAAAAAAAAAAAAAAAAA- -AAAAAAAAAAAAAAAAAA- -AAAAAAAAAAAAAAAAAA- -AAAAAAAAAAAAAAAAAA- -AAAAAAAAAAAAAAAAAA- -AAAAAAAAAAAAAAAAAA- -AAAAAAAAAAAAAAAAAA- -AAAAAAAAAAAAAAAAAA- -AAAAAAAAAAAAAAAAAA- -AAAAAAAAAAAAAAAAAA- -------------------- -------------------- -------------------- 
AAAAAAAAAAAAAAAAAAAA AAAAAAAAAAAAAAAAAAAA AAAAAAAAAAAAAAAAAAAA AAAAAAAAAAAAAAAAAAAA AAAAAAAAAAAAAAAAAAAA AAAAAAAAAAAAAAAAAAAA AAAAAAAAAAAAAAAAAAAA AAAAAAAAAAAAAAAAAAAA AAAAAAAAAAAAAAAAAAAA AAAAAAAAAAAAAAAAAAAA AAAAAAAAAAAAAAAAAAAA AAAAAAAAAAAAAAAAAAAA AAAAAAAAAAAAAAAAAAAA AAAAAAAAAAAAAAAAAAAA AAAAAAAAAAAAAAAAAAAA AAAAAAAAAAAAAAAAAAAA AAAAAAAAAAAAAAAAAAAA AAAAAAAAAAAAAAAAAAAA AAAAAAAAAAAAAAAAAAAA AAAAAAAAAAAAAAAAAAAA AAAAAAAAAAAAAAAAAAAA AAAAAAAAAAAAAAAAAAAA AAAAAAAAAAAAAAAAAAAA ---AAAAAAAAAAAAAA--- -------------------- -------------------- 
AAAAAAAAAAAAAAAAAAAA AAAAAAAAAAAAAAAAAAAA AAAAAAAAAAAAAAAAAAAA AAAAAAAAAAAAAAAAAAAA AAAAAAAAAAAAAAAAAAAA AAAAAAAAAAAAAAAAAAAA AAAAAAAAAAAAAAAAAAAA AAAAAAAAAAAAAAAAAAAA AAAAAAAAAAAAAAAAAAAA AAAAAAAAAAAAAAAAAAAA AAAAAAAAAAAAAAAAAAAA AAAAAAAAAAAAAAAAAAAA AAAAAAAAAAAAAAAAAAAA AAAAAAAAAAAAAAAAAAAA AAAAAAAAAAAAAAAAAAAA AAAAAAAAAAAAAAAAAAAA AAAAAAAAAAAAAAAAAAAA AAAAAAAAAAAAAAAAAAAA AAAAAAAAAAAAAAAAAAAA AAAAAAAAAAAAAAAAAAAA AAAAAAAAAAAAAAAAAAAA AAAAAAAAAAAAAAAAAAAA AAAAAAAAAAAAAAAAAAAA ---AAAAAAAAAAAAAA--- -------------------- -------------------- 
AAAAAAAAAAAAAAAAAAAA AAAAAAAAAAAAAAAAAAAA AAAAAAAAAAAAAAAAAAAA AAAAAAAAAAAAAAAAAAAA AAAAAAAAAAAAAAAAAAAA AAAAAAAAAAAAAAAAAAAA AAAAAAAAAAAAAAAAAAAA AAAAAAAAAAAAAAAAAAAA AAAAAAAAAAAAAAAAAAAA AAAAAAAAAAAAAAAAAAAA AAAAAAAAAAAAAAAAAAAA AAAAAAAAAAAAAAAAAAAA AAAAAAAAAAAAAAAAAAAA AAAAAAAAAAAAAAAAAAAA AAAAAAAAAAAAAAAAAAAA AAAAAAAAAAAAAAAAAAAA AAAAAAAAAAAAAAAAAAAA AAAAAAAAAAAAAAAAAAAA AAAAAAAAAAAAAAAAAAAA AAAAAAAAAAAAAAAAAAAA AAAAAAAAAAAAAAAAAAAA AAAAAAAAAAAAAAAAAAAA AAAAAAAAAAAAAAAAAAAA ---AAAAAAAAAAAAAA--- -----AAAAAAAAAA----- -------------------- 
AAAAAAAAAAAAAAAAAAAA AAAAAAAAAAAAAAAAAAAA AAAAAAAAAAAAAAAAAAAA AAAAAAAAAAAAAAAAAAAA AAAAAAAAAAAAAAAAAAAA AAAAAAAAAAAAAAAAAAAA AAAAAAAAAAAAAAAAAAAA AAAAAAAAAAAAAAAAAAAA AAAAAAAAAAAAAAAAAAAA AAAAAAAAAAAAAAAAAAAA AAAAAAAAAAAAAAAAAAAA AAAAAAAAAAAAAAAAAAAA AAAAAAAAAAAAAAAAAAAA AAAAAAAAAAAAAAAAAAAA AAAAAAAAAAAAAAAAAAAA AAAAAAAAAAAAAAAAAAAA AAAAAAAAAAAAAAAAAAAA AAAAAAAAAAAAAAAAAAAA AAAAAAAAAAAAAAAAAAAA AAAAAAAAAAAAAAAAAAAA AAAAAAAAAAAAAAAAAAAA AAAAAAAAAAAAAAAAAAAA AAAAAAAAAAAAAAAAAAAA ---AAAAAAAAAAAAAA--- -----AAAAAAAAAA----- -------------------- 
AAAAAAAAAAAAAAAAAAAA AAAAAAAAAAAAAAAAAAAA AAAAAAAAAAAAAAAAAAAA AAAAAAAAAAAAAAAAAAAA AAAAAAAAAAAAAAAAAAAA AAAAAAAAAAAAAAAAAAAA AAAAAAAAAAAAAAAAAAAA AAAAAAAAAAAAAAAAAAAA AAAAAAAAAAAAAAAAAAAA AAAAAAAAAAAAAAAAAAAA AAAAAAAAAAAAAAAAAAAA AAAAAAAAAAAAAAAAAAAA AAAAAAAAAAAAAAAAAAAA AAAAAAAAAAAAAAAAAAAA AAAAAAAAAAAAAAAAAAAA AAAAAAAAAAAAAAAAAAAA AAAAAAAAAAAAAAAAAAAA AAAAAAAAAAAAAAAAAAAA AAAAAAAAAAAAAAAAAAAA AAAAAAAAAAAAAAAAAAAA AAAAAAAAAAAAAAAAAAAA AAAAAAAAAAAAAAAAAAAA AAAAAAAAAAAAAAAAAAAA ---AAAAAAAAAAAAAA--- -----AAAAAAAAAA----- --------AAAA-------- 
AAAAAAAAAAAAAAAAAAAA AAAAAAAAAAAAAAAAAAAA AAAAAAAAAAAAAAAAAAAA AAAAAAAAAAAAAAAAAAAA AAAAAAAAAAAAAAAAAAAA AAAAAAAAAAAAAAAAAAAA AAAAAAAAAAAAAAAAAAAA AAAAAAAAAAAAAAAAAAAA AAAAAAAAAAAAAAAAAAAA AAAAAAAAAAAAAAAAAAAA AAAAAAAAAAAAAAAAAAAA AAAAAAAAAAAAAAAAAAAA AAAAAAAAAAAAAAAAAAAA AAAAAAAAAAAAAAAAAAAA AAAAAAAAAAAAAAAAAAAA AAAAAAAAAAAAAAAAAAAA AAAAAAAAAAAAAAAAAAAA AAAAAAAAAAAAAAAAAAAA AAAAAAAAAAAAAAAAAAAA AAAAAAAAAAAAAAAAAAAA AAAAAAAAAAAAAAAAAAAA AAAAAAAAAAAAAAAAAAAA AAAAAAAAAAAAAAAAAAAA ---AAAAAAAAAAAAAA--- -----AAAAAAAAAA----- --------AAAA-------- 
AAAAAAAAAAAAAAAAAAAA AAAAAAAAAAAAAAAAAAAA AAAAAAAAAAAAAAAAAAAA AAAAAAAAAAAAAAAAAAAA AAAAAAAAAAAAAAAAAAAA AAAAAAAAAAAAAAAAAAAA AAAAAAAAAAAAAAAAAAAA AAAAAAAAAAAAAAAAAAAA AAAAAAAAAAAAAAAAAAAA AAAAAAAAAAAAAAAAAAAA AAAAAAAAAAAAAAAAAAAA AAAAAAAAAAAAAAAAAAAA AAAAAAAAAAAAAAAAAAAA AAAAAAAAAAAAAAAAAAAA AAAAAAAAAAAAAAAAAAAA AAAAAAAAAAAAAAAAAAAA AAAAAAAAAAAAAAAAAAAA AAAAAAAAAAAAAAAAAAAA AAAAAAAAAAAAAAAAAAAA AAAAAAAAAAAAAAAAAAAA AAAAAAAAAAAAAAAAAAAA AAAAAAAAAAAAAAAAAAAA AAAAAAAAAAAAAAAAAAAA ---AAAAAAAAAAAAAA--- -----AAAAAAAAAA----- --------AAAA-------- 
AAAAAAAAAAAAAAAAAAAA AAAAAAAAAAAAAAAAAAAA AAAAAAAAAAAAAAAAAAAA AAAAAAAAAAAAAAAAAAAA AAAAAAAAAAAAAAAAAAAA AAAAAAAAAAAAAAAAAAAA AAAAAAAAAAAAAAAAAAAA AAAAAAAAAAAAAAAAAAAA AAAAAAAAAAAAAAAAAAAA AAAAAAAAAAAAAAAAAAAA AAAAAAAAAAAAAAAAAAAA AAAAAAAAAAAAAAAAAAAA AAAAAAAAAAAAAAAAAAAA AAAAAAAAAAAAAAAAAAAA AAAAAAAAAAAAAAAAAAAA AAAAAAAAAAAAAAAAAAAA AAAAAAAAAAAAAAAAAAAA AAAAAAAAAAAAAAAAAAAA AAAAAAAAAAAAAAAAAAAA AAAAAAAAAAAAAAAAAAAA AAAAAAAAAAAAAAAAAAAA AAAAAAAAAAAAAAAAAAAA AAAAAAAAAAAAAAAAAAAA ---AAAAAAAAAAAAAA--- -----AAAAAAAAAA----- -------------------- 
AAAAAAAAAAAAAAAAAAAA AAAAAAAAAAAAAAAAAAAA AAAAAAAAAAAAAAAAAAAA AAAAAAAAAAAAAAAAAAAA AAAAAAAAAAAAAAAAAAAA AAAAAAAAAAAAAAAAAAAA AAAAAAAAAAAAAAAAAAAA AAAAAAAAAAAAAAAAAAAA AAAAAAAAAAAAAAAAAAAA AAAAAAAAAAAAAAAAAAAA AAAAAAAAAAAAAAAAAAAA AAAAAAAAAAAAAAAAAAAA AAAAAAAAAAAAAAAAAAAA AAAAAAAAAAAAAAAAAAAA AAAAAAAAAAAAAAAAAAAA AAAAAAAAAAAAAAAAAAAA AAAAAAAAAAAAAAAAAAAA AAAAAAAAAAAAAAAAAAAA AAAAAAAAAAAAAAAAAAAA AAAAAAAAAAAAAAAAAAAA AAAAAAAAAAAAAAAAAAAA AAAAAAAAAAAAAAAAAAAA AAAAAAAAAAAAAAAAAAAA ---AAAAAAAAAAAAAA--- -----AAAAAAAAAA----- -------------------- 
AAAAAAAAAAAAAAAAAAAA AAAAAAAAAAAAAAAAAAAA AAAAAAAAAAAAAAAAAAAA AAAAAAAAAAAAAAAAAAAA AAAAAAAAAAAAAAAAAAAA AAAAAAAAAAAAAAAAAAAA AAAAAAAAAAAAAAAAAAAA AAAAAAAAAAAAAAAAAAAA AAAAAAAAAAAAAAAAAAAA AAAAAAAAAAAAAAAAAAAA AAAAAAAAAAAAAAAAAAAA AAAAAAAAAAAAAAAAAAAA AAAAAAAAAAAAAAAAAAAA AAAAAAAAAAAAAAAAAAAA AAAAAAAAAAAAAAAAAAAA AAAAAAAAAAAAAAAAAAAA AAAAAAAAAAAAAAAAAAAA AAAAAAAAAAAAAAAAAAAA AAAAAAAAAAAAAAAAAAAA AAAAAAAAAAAAAAAAAAAA AAAAAAAAAAAAAAAAAAAA AAAAAAAAAAAAAAAAAAAA AAAAAAAAAAAAAAAAAAAA ---AAAAAAAAAAAAAA--- -------------------- -------------------- 
AAAAAAAAAAAAAAAAAAAA AAAAAAAAAAAAAAAAAAAA AAAAAAAAAAAAAAAAAAAA AAAAAAAAAAAAAAAAAAAA AAAAAAAAAAAAAAAAAAAA AAAAAAAAAAAAAAAAAAAA AAAAAAAAAAAAAAAAAAAA AAAAAAAAAAAAAAAAAAAA AAAAAAAAAAAAAAAAAAAA AAAAAAAAAAAAAAAAAAAA AAAAAAAAAAAAAAAAAAAA AAAAAAAAAAAAAAAAAAAA AAAAAAAAAAAAAAAAAAAA AAAAAAAAAAAAAAAAAAAA AAAAAAAAAAAAAAAAAAAA AAAAAAAAAAAAAAAAAAAA AAAAAAAAAAAAAAAAAAAA AAAAAAAAAAAAAAAAAAAA AAAAAAAAAAAAAAAAAAAA AAAAAAAAAAAAAAAAAAAA AAAAAAAAAAAAAAAAAAAA AAAAAAAAAAAAAAAAAAAA AAAAAAAAAAAAAAAAAAAA ---AAAAAAAAAAAAAA--- -------------------- -------------------- 
-AAAAAAAAAAAAAAAAAA- -AAAAAAAAAAAAAAAAAA- -AAAAAAAAAAAAAAAAAA- -AAAAAAAAAAAAAAAAAA- -AAAAAAAAAAAAAAAAAA- -AAAAAAAAAAAAAAAAAA- -AAAAAAAAAAAAAAAAAA- -AAAAAAAAAAAAAAAAAA- -AAAAAAAAAAAAAAAAAA- -AAAAAAAAAAAAAAAAAA- -AAAAAAAAAAAAAAAAAA- -AAAAAAAAAAAAAAAAAA- -AAAAAAAAAAAAAAAAAA- -AAAAAAAAAAAAAAAAAA- -AAAAAAAAAAAAAAAAAA- -AAAAAAAAAAAAAAAAAA- -AAAAAAAAAAAAAAAAAA- -AAAAAAAAAAAAAAAAAA- -AAAAAAAAAAAAAAAAAA- -AAAAAAAAAAAAAAAAAA- -AAAAAAAAAAAAAAAAAA- -AAAAAAAAAAAAAAAAAA- -AAAAAAAAAAAAAAAAAA- -------------------- -------------------- -------------------- 
--AAAAAAAAAAAAAAAA-- --AAAAAAAAAAAAAAAA-- --AAAAAAAAAAAAAAAA-- --AAAAAAAAAAAAAAAA-- --AAAAAAAAAAAAAAAA-- --AAAAAAAAAAAAAAAA-- --AAAAAAAAAAAAAAAA-- --AAAAAAAAAAAAAAAA-- --AAAAAAAAAAAAAAAA-- --AAAAAAAAAAAAAAAA-- --AAAAAAAAAAAAAAAA-- --AAAAAAAAAAAAAAAA-- --AAAAAAAAAAAAAAAA-- --AAAAAAAAAAAAAAAA-- --AAAAAAAAAAAAAAAA-- --AAAAAAAAAAAAAAAA-- --AAAAAAAAAAAAAAAA-- --AAAAAAAAAAAAAAAA-- --AAAAAAAAAAAAAAAA-- --AAAAAAAAAAAAAAAA-- --AAAAAAAAAAAAAAAA-- --AAAAAAAAAAAAAAAA-- --AAAAAAAAAAAAAAAA-- -------------------- -------------------- -------------------- 
---AAAAAAAAAAAAAA--- ---AAAAAAAAAAAAAA--- ---AAAAAAAAAAAAAA--- ---AAA--------AAA--- ---AAA--------AAA--- ---AAA--------AAA--- ---AAA-DD-----AAA--- ---AAA-DD-----AAA--- ---AAA--------AAA--- ---AAA-----EE-AAA--- ---AAA-----EE-AAA--- ---AAA--------AAA--- ---AAA-AA-----AAA--- ---AAA-AA-----AAA--- ---AAA--------AAA--- ---AAA-----AA-AAA--- ---AAA-----AA-AAA--- ---AAA--------AAA--- ---AAA--------AAA--- ---AAAAAAAAAAAAAA--- ---AAAAAAAAAAAAAA--- ---AAAAAAAAAAAAAA--- ---AAAAAAAAAAAAAA--- -------------------- -------------------- -------------------- 
-------------------- -------------------- -------------------- -------------------- -------------------- -------------------- -------------------- -------------------- -------------------- -------------------- -------------------- -------------------- -------DD----------- -------DD----------- -------------------- -----------AA------- -----------AA------- -------------------- -------------------- -------------------- -------------------- -------------------- -------------------- -------------------- -------------------- -------------------- 
-------------------- -------------------- -------------------- -------------------- -------------------- -------------------- -------------------- -------------------- -------------------- -------------------- -------------------- -------------------- -------------------- -------------------- -------------------- -----------EE------- -----------EE------- -------------------- -------------------- -------------------- -------------------- -------------------- -------------------- -------------------- -------------------- -------------------- 
