model
size = 31 31 17, scale = 0.05, origin = -y
material 
  colors = A:#111 B:#DDD C:#63C D:#FCF E:#F60 F:#888 G:#609 H:#FCC I:#639
voxels
---------AAAAAAAAAAAAA--------- ---------AAAAAAAAAAAAA--------- ---------AAAAAAAAAAAAA--------- ---------AAAAAAAAAAAAA--------- ---------AAAAAAAAAAAAA--------- ---------AACACCACCACAA--------- ---------ACDCDDCDDCDCA--------- ---------CDBDBBDBBDBDC--------- ---------CDBFBBBBBFBDC--------- ---------CDFBFBBBFBFDC--------- ---------CDBBFBBBFBBDC--------- ---------CDFFBBBBBFFDC--------- ---------CDBBBBBBBBBDC--------- ---------CDBBBBBBBBBDC--------- ---------CDBBBFFFBBBDC--------- ---------CDHBFBBBFBHDC--------- ---------CDBBBBBBBBBDC--------- ---------CDBAABBBAABDC--------- ---------CDAAAABAAAADC--------- ---------CAAABABAABAAC--------- ---------AAAAAAAAAAAAA--------- --------BCDBBBGIGBBBDCB-------- -------BAAAAAAAEAAAAAAAB------- -------BAAAAAEEEEAAAAAAB------- --------BAAAAAEAAEAAAAB-------- ---------BAAAAEEEAAAAB--------- ----------BAAAEAAEAAB---------- -----------BAEEEEAAB----------- --------------AEA-------------- --------------BBB-------------- ------------------------------- 
-------AA-------------AA------- -------AA-------------AA------- -------AA-------------AA------- -------AA-------------AA------- -------AA-------------AA------- -------AA-------------AA------- -------AA-------------AA------- -------AA-------------AA------- -------AA-------------AA------- -------AA-------------AA------- -------AA-------------AA------- -------AA-------------AA------- -------AA-------------AA------- -------AAA-----------AAA------- -------AAA-----------AAA------- --------AA-----------AA-------- --------AA-----------AA-------- --------AA-----------AA-------- --------AA-----------AA-------- --------AA-----------AA-------- ------AABA-----------ABAA------ -----AAAA-------------AAAA----- -----AAA---------------AAA----- -----AAA---------------AAA----- ------AA---------------AA------ -------AA-------------AA------- --------AAAAAAAAAAAAAAA-------- --------AAAABAAAAABAAAA-------- -------------BAAAB------------- -------------AAAAA------------- -------------AAAAA------------- 
------A-----------------A------ ------A-----------------A------ ------A-----------------A------ ------A-----------------A------ ------A-----------------A------ ------A-----------------A------ ------A-----------------A------ ------A-----------------A------ ------A-----------------A------ ------AA---------------AA------ ------AA---------------AA------ ------AA---------------AA------ ------AA---------------AA------ -------A---------------A------- -------A---------------A------- -------AA-------------AA------- -------AA-------------AA------- -------AA-------------AA------- -------AA-------------AA------- --------A-------------A-------- ---AAA--A-------------A--AAA--- ---AAA-------------------AAA--- ---AAA-------------------AAA--- ---AAA-------------------AAA--- ----AA-------------------AA---- ----AAAA---------------AAAA---- -----AAA---------------AAA----- -------A---------------A------- --------AAAAA-----AAAAA-------- ------------A-----A------------ ------------A-----A------------ 
-----A-------------------A----- -----A-------------------A----- -----A-------------------A----- -----A-------------------A----- -----A-------------------A----- -----A-------------------A----- -----A-------------------A----- -----A-------------------A----- -----A-------------------A----- ------A-----------------A------ ------A-----------------A------ ------A-----------------A------ ------A-----------------A------ ------A-----------------A------ ------A-----------------A------ -------A---------------A------- -------A---------------A------- -------A---------------A------- -------A---------------A------- -------A---------------A------- --A----A---------------A----A-- --A-------------------------A-- --A-------------------------A-- --AA-----------------------AA-- --AAA---------------------AAA-- ---AAA-------------------AAA--- ---AAAA-----------------AAAA--- ----AAAA---------------AAAA---- ------AA---------------AA------ --------AAAA-------AAAA-------- -----------A-------A----------- 
-----A-------------------A----- -----A-------------------A----- -----A-------------------A----- -----A-------------------A----- -----A-------------------A----- -----A-------------------A----- -----A-------------------A----- -----A-------------------A----- -----A-------------------A----- -----AA-----------------AA----- -----AA-----------------AA----- -----AA-----------------AA----- ------A-----------------A------ ------A-----------------A------ ------A-----------------A------ ------AA---------------AA------ ------AA---------------AA------ -------A---------------A------- -------A---------------A------- -------A---------------A------- -A-----A---------------A-----A- -A---------------------------A- -A---------------------------A- -AA-------------------------AA- --AA-----------------------AA-- --AAA---------------------AAA-- --AAAA-------------------AAAA-- ---AAAA-----------------AAAA--- ----AAAA---------------AAAA---- -------AA-------------AA------- ---------AAA-------AAA--------- 
-----A-------------------A----- -----A-------------------A----- -----A-------------------A----- -----A-------------------A----- -----A-------------------A----- -----A-------------------A----- -----A-------------------A----- -----A-------------------A----- -----A-------------------A----- -----A-------------------A----- -----A-------------------A----- -----A-------------------A----- -----A-------------------A----- -----A-------------------A----- -----A-------------------A----- ------A-----------------A------ ------A-----------------A------ ------A-----------------A------ ------A-----------------A------ -------A---------------A------- -A-----A---------------A-----A- -A---------------------------A- -A---------------------------A- -A---------------------------A- -AA-------------------------AA- -AAA-----------------------AAA- --AAA---------------------AAA-- --AAAA-------------------AAAA-- ---AAAA-----------------AAAA--- -----AAA---------------AAA----- --------A-------------A-------- 
-----A-------------------A----- -----A-------------------A----- -----A-------------------A----- -----A-------------------A----- -----A-------------------A----- -----A-------------------A----- -----A-------------------A----- -----A-------------------A----- -----A-------------------A----- -----A-------------------A----- -----A-------------------A----- -----A-------------------A----- -----A-------------------A----- -----A-------------------A----- -----A-------------------A----- -----AA-----------------AA----- -----AA-----------------AA----- ------A-----------------A------ ------A-----------------A------ ------AA---------------AA------ A------A---------------A------A A----------------------------AA A----------------------------AA A----------------------------AA -A--------------------------AA- -AA-------------------------AA- -AAA-----------------------AAA- --AAA---------------------AAA-- ---AAA-------------------AAA--- ----AAAA---------------AAAA---- -------A---------------A------- 
-----A-------------------A----- -----A-------------------A----- -----A-------------------A----- -----A-------------------A----- -----A-------------------A----- -----A-------------------A----- -----A-------------------A----- -----A-------------------A----- -----A-------------------A----- -----A-------------------A----- -----A-------------------A----- -----A-------------------A----- -----A-------------------A----- -----A-------------------A----- -----A-------------------A----- -----AA-----------------AA----- -----AA-----------------AA----- -----AA-----------------AA----- ------A-----------------A------ ------AA----------------A------ A-----AA----------------A-----A A----------------------------AA A----------------------------AA A----------------------------AA A----------------------------AA -A--------------------------AA- -AA-------------------------AA- --AA-----------------------AA-- --AAA---------------------AAA-- ----AA-------------------AA---- ------AA----------------A------ 
-----A-------------------A----- -----A-------------------A----- -----A-------------------A----- -----A-------------------A----- -----A-------------------A----- -----A-------------------A----- -----A-------------------A----- -----A-------------------A----- -----A-------------------A----- -----A-------------------A----- -----A-------------------A----- -----A-------------------A----- -----A-------------------A----- -----A-------------------A----- -----A-------------------A----- -----AA-----------------AA----- -----AA-----------------AA----- -----AA-----------------AA----- -----AA-----------------AA----- -----AAA----------------AA----- A-----AA----------------A-----A A----------------------------AA A----------------------------AA A----------------------------AA A----------------------------AA A----------------------------AA -A--------------------------AA- -AA-------------------------AA- --AA-----------------------AA-- ---AAA-------------------AAA--- ------AA----------------A------ 
-----A-------------------A----- -----A-------------------A----- -----A-------------------A----- -----A-------------------A----- -----A-------------------A----- -----A-------------------A----- -----A-------------------A----- -----A-------------------A----- -----A-------------------A----- -----A-------------------A----- -----A-------------------A----- -----A-------------------A----- -----A-------------------A----- -----A-------------------A----- -----A-------------------A----- -----AA-----------------AA----- -----AA-----------------AA----- -----AA-----------------AA----- ------A-----------------A------ ------AA----------------A------ A-----AA----------------A-----A A----------------------------AA A----------------------------AA A----------------------------AA A----------------------------AA A----------------------------AA -A--------------------------AA- -AA-------------------------AA- --AA-----------------------AA-- ---AAA-------------------AAA--- ------AA----------------A------ 
-----A-------------------A----- -----A-------------------A----- -----A-------------------A----- -----A-------------------A----- -----A-------------------A----- -----A-------------------A----- -----A-------------------A----- -----A-------------------A----- -----A-------------------A----- -----A-------------------A----- -----A-------------------A----- -----A-------------------A----- -----A-------------------A----- -----A-------------------A----- -----A-------------------A----- -----AA-----------------AA----- -----AA-----------------AA----- ------A-----------------A------ ------A-----------------A------ ------AA----------------A------ A------A----------------------A A----------------------------AA A----------------------------AA A----------------------------AA A----------------------------AA -A--------------------------AA- -AA-------------------------AA- --AA-----------------------AA-- --AAA---------------------AAA-- ----AA-------------------AA---- ------AA----------------A------ 
-----A-------------------A----- -----A-------------------A----- -----A-------------------A----- -----A-------------------A----- -----A-------------------A----- -----A-------------------A----- -----A-------------------A----- -----A-------------------A----- -----A-------------------A----- -----A-------------------A----- -----A-------------------A----- -----A-------------------A----- -----A-------------------A----- -----A-------------------A----- -----A-------------------A----- ------A-----------------A------ ------A-----------------A------ ------A-----------------A------ ------A-----------------A------ -------A---------------A------- A------A---------------A------A A----------------------------AA A----------------------------AA A----------------------------AA -A--------------------------AA- -AA-------------------------AA- -AAA-----------------------AAA- --AAA---------------------AAA-- ---AAAA-----------------AAAA--- ----AAAA---------------AAAA---- -------AA--------------A------- 
-----A-------------------A----- -----A-------------------A----- -----A-------------------A----- -----A-------------------A----- -----A-------------------A----- -----A-------------------A----- -----A-------------------A----- -----A-------------------A----- -----A-------------------A----- -----AA-----------------AA----- -----AA-----------------AA----- -----AA-----------------AA----- ------A-----------------A------ ------A-----------------A------ ------A-----------------A------ -------A---------------A------- -------A---------------A------- -------A---------------A------- -------A---------------A------- -------A---------------A------- -A-----A---------------A-----A- -A---------------------------A- -A---------------------------A- -A--------------------------AA- -AA-------------------------AA- -AAA-----------------------AAA- --AAA---------------------AAA-- --AAAA-------------------AAAA-- ---AAAA-----------------AAAA--- -----AAA---------------AAA----- --------A-------------A-------- 
-----A-------------------A----- -----A-------------------A----- -----A-------------------A----- -----A-------------------A----- -----A-------------------A----- -----A-------------------A----- -----A-------------------A----- -----A-------------------A----- -----A-------------------A----- ------A-----------------A------ ------A-----------------A------ ------A-----------------A------ ------A-----------------A------ ------A-----------------A------ ------A-----------------A------ -------A---------------A------- -------A---------------A------- -------A---------------A------- -------A---------------A------- -------A---------------A------- -A-----A---------------A-----A- -A---------------------------A- -A---------------------------A- -AA-------------------------AA- --AA-----------------------AA-- --AAA---------------------AAA-- --AAAA-------------------AAAA-- ---AAAA-----------------AAAA--- ----AAAA---------------AAAA---- -------A---------------A------- --------A-------------A-------- 
------A-----------------A------ ------A-----------------A------ ------A-----------------A------ ------A-----------------A------ ------A-----------------A------ ------A-----------------A------ ------A-----------------A------ ------A-----------------A------ ------A-----------------A------ ------AA---------------AA------ ------AA---------------AA------ ------AA---------------AA------ ------AA---------------AA------ -------A---------------A------- -------A---------------A------- -------A---------------A------- -------A---------------A------- -------A---------------A------- -------A---------------A------- --------A-------------A-------- --A-----A-------------A-----A-- --A----AA-------------AA----A-- --A-------------------------A-- --AA-----------------------AA-- --AAA---------------------AAA-- ---AAA-------------------AAA--- ---AAAA-----------------AAAA--- ----AAAA----------------AAA---- ------AA---------------AA------ --------AA-----------AA-------- ---------AA---------AA--------- 
-------A---------------A------- -------A---------------A------- -------A---------------A------- -------AAAAAAAAAAAAAAAAA------- -------AAAAAAAAAAAAAAAAA------- -------AAAAAAAAAAAAAAAAA------- -------AAAAAAAAAAAAAAAAA------- -------AAAAAAAAAAAAAAAAA------- -------AAAAAAAAAAAAAAAAA------- -------AAAAAAAAAAAAAAAAA------- -------AAAAAAAAAAAAAAAAA------- -------AAAAAAAAAAAAAAAAA------- -------AAAAAAAAAAAAAAAAA------- -------AAAAAAAAAAAAAAAAA------- -------AAAAAAAAAAAAAAAAA------- --------AAAAAAAAAAAAAAA-------- --------AAAAAAAAAAAAAAA-------- --------AAAAAAAAAAAAAAA-------- --------AAAAAAAAAAAAAAA-------- --------AAAAAAAAAAAAAAA-------- ---AAAA-AAAAAAAAAAAAAAA-AAAA--- ---AAAAAAAAAAAAAAAAAAAAAAAAA--- ---AAAAAAAAAAAAAAAAAAAAAAAAA--- ---AAAAAAAAAAAAAAAAAAAAAAAAA--- ----AAAAAAAAAAAAAAAAAAAAAAA---- ----AAAAAAAAAAAAAAAAAAAAAAA---- -----AAAAAAAAAAAAAAAAAAAAA----- -------AAAAAAAAAAAAAAAAA------- --------AAAAAAAAAAAAAAA-------- ---------AAAAAAAAAAAAA--------- ----------AAAAAAAAAAA---------- 
--------AAAAAAAAAAAAAAA-------- --------AAAAAAAAAAAAAAA-------- --------AAAAAAAAAAAAAAA-------- --------AAAAAAAAAAAAAAA-------- --------AAAAAAAAAAAAAAA-------- --------AAAAAABBAAAAAAA-------- --------AAAAAABBAAAAAAA-------- --------AAAAAABBAAAAAAA-------- --------AAAAAABBAAAAAAA-------- --------AAAAABBBBAAAAAA-------- --------AAAAAAAAAAAAAAA-------- --------AAAAABBBBAAAAAA-------- --------AAAAABAAAAAAAAA-------- ---------AAAABBBBAAAAA--------- ---------AAAAAAABAAAAA--------- ---------AAAABBBBAAAAA--------- ---------AAAAAAAAAAAAA--------- ---------AAAABAABAAAAA--------- ---------AAAABAABAAAAA--------- ---------AAAABBBBAAAAA--------- ---------AAAABAABAAAAA--------- --------AAAAABAABAAAAAA-------- ------AAAAAAAAAAAAAAAAAAA------ ------AAAAAAABBBBAAAAAAAA------ ------AAAAAAABAABAAAAAAAA------ -------AAAAAABBABAAAAAAA------- --------AAAAAAAABAAAAAA-------- --------AAAAABAABAAAAAA-------- ----------AAABBBBAAAA---------- ----------AAAAAAAAAAA---------- -----------AAAAAAAAA----------- 
