model
size = 29 32 13, scale = 0.05, origin = -y
material 
  colors = A:#EEE B:#111
voxels
8-13A19-2(7A22-)7A21-9A20-9A21-5(7A22-)2A3B2A21-2A5B2A19-3A5B3A18-4ABAB4A18-3A2(BA)B2(3A18-3A5B)3A18-2A2BABA2B2A18-A9B2(A18-A2B2AB2A2B)A18-A9BA18-2A7B2A19-2A5B2A220-7A-7A15-2(5A3-5A16-)5A3-4A17-3(3A6-4A16-)4A5-3A17-4A5-4A16-4A6-3A16-4A5-3A17-2(4A6-3A16-)3A7-3A16-2A9-2A17-A2(9-2A16-2A)9-A17-3(2A9-2A16-)A10-2A16-2A9-2A16-3A7-3A16-13A17-11A19-9A162-2A11-3A12-3A11-2A2(14-3A9-3A)14-2A10-3A14-2A11-2A14-2A10-3A14-3A9-3A15-2A9-3A15-A10-2A15-2A9-3A15-2A2(10-2A16-A)11-A16-2A10-A2(16-2A9-2A)16-A2(10-2A15-2A)11-2A14-2A11-2(2A13-)A2(13-2A)12-3A11-3A12-4A9-3A14-4A7-4A15-13A17-11A21-5A106-A13-2A11-3A13-2A12-2(2A13-A13-)3A12-A2(13-2A12-2A)3(14-2A11-2A)14-2A10-3A2(14-2A11-2A)15-A11-A15-5(2A11-2A14-)A12-2(2A13-)2A12-2A13-2(2A11-2A14-)2A12-2A13-2A12-3A11-3A12-4A9-3A14-6A3-6A16-11A20-6A92-A2(11-2A14-2A)3(12-A14-2A)2(12-2A13-2A)2(13-A)14-A13-A2(14-A12-2A)3(14-2A11-2A)3(14-A13-A)13-2A13-A2(13-2A)12-2A13-2A11-2A15-2A10-2A15-2A9-2(3A15-3A8-)3A14-4A8-4A13-4A2(9-5A)11-6A4-7A15-5A-5A89-2(A11-2A15-)2(A12-A15-)A2(12-A14-2A)2(12-2A13-2A)12-2A13-A13-2A5(13-A14-A)13-A2(13-2A)9-5A13-5A4-7A13-7A2-6A14-7A2-6A2(15-6A3-5A)16-4A4-4A17-4A2(4-3A19-3A)5-3A17-3A6-4A15-4A7-6A9-6A10-7A3-7A16-2A5-2A61-2(A11-2A15-)2(A12-A15-)A2(12-A14-2A)12-A15-A2(12-A14-2A)12-2(2A13-)2(A13-A14-)2(A13-)2A13-A2(13-2A)12-2A13-2A11-2A15-2A5-2A3-2A15-2A3-4A4-A15-A4-5A3-A15-A4-A2-2A3-A15-A3-2(2A2-2A23-)2A3-A23-A2(4-2A21-2A)4-3A19-2A6-4A15-4A8-6A7-6A13-4A5-4A18-2A5-2A31-2(2A11-2A14-)2A12-A14-3(2A12-2A13-)3(2A12-A14-)2(A13-2A13-)2(A14-A13-)A13-2A2(13-A)14-2A2(12-A15-A)6-A5-2(A15-A4-4A4-)A14-2A4-A2-A4-A14-2A4-A2-A24-2(2A2-2A23-)A4-A23-A4-A22-2A4-2A21-A6-3A17-3A7-5A11-5A10-5A7-4A16-3A5-3A30-2A11-3A2(13-2A12-2A)13-A13-2A13-A14-2A12-A13-3A11-3A12-2A12-3A12-2A13-A3(13-2A12-2A)2(14-A13-A)13-2A13-A2(13-2A)12-A14-2A12-A15-A6-2A4-A15-A4-4A4-A15-A4-2A-A4-A14-2A3-2A2-2A3-A14-2A3-2(2A2-2A23-)2(A4-A23-)A4-2A21-2A4-2A20-2A6-3A17-3A7-4A13-4A10-5A7-4A16-3A5-3A14-3A12-3A13-3(2A11-2A14-)3A10-2A14-3A9-3A14-3A8-4A14-2A9-4A2(14-2A10-3A)14-2A10-2A15-A11-3A2(14-A12-2A)14-2(A13-)2A13-A2(13-2A)11-3A13-3A6-2A2-2A3(15-A3-2A2-2A3-A)15-A3-A4-2A-2A15-A2-3(2A4-2A21-)2A4-3A19-3A5-3A17-3A6-5A13-4A9-6A7-6A12-15A17-9A16-3A10-3A14-3A9-2A15-3A9-2A16-3A2-2A4-2A16-7A3-3A17-4A-7A16-12A17-2A2-8A17-2A6-5A16-3A8-2A15-4A8-A16-4A8-2A15-3A9-2A15-2A10-3A3(14-A12-2A)10-5A12-6A5-2(6A13-6A4-)6A14-2(5A4-5A15-)5A5-3A16-4A2(6-2A19-2A)6-3A17-3A7-4A13-4A9-7A5-7A12-15A17-9A45-15A17-2(11A18-)11A19-10A20-8A19-2(9A20-)11A18-3A4-4A19-2A6-2A18-3A6-2A17-4A6-2A16-2(5A6-3A15-)4A8-2(2A15-2A10-)3A14-2A11-2A14-2A11-3A12-2A12-3A12-2A13-2A10-4A13-2A10-2(3A15-3A8-)3A14-4A8-7A7-7A9-19A12-15A18-7A77-11A21-7A196-6A23-4(8A21-)8A20-10A2(17-12A)17-13A16-13A15-14A15-15A14-15A13-4(17A12-)16A17-9A126-
