model
size = 17 11 27, scale = 0.05, origin = -y
material 
  colors = A:#070707 B:#050505 C:#0D0D0D D:#0F0F0F E:#0B0B0B F:#0A0A0A G:#0E0E0E H:#090909 I:#080808 J:#0C0C0C K:#101010
voxels
------BBBBB------ ----------------- ----------------- ----------------- ----------------- ----------------- ----------------- ----------------- ----------------- ----------------- ----------------- 
----BBBBBBBBB---- ----------------- ----------------- ----------------- ----------------- ----------------- ----------------- ----------------- ----------------- ----------------- ----------------- 
---BBBBBBBBBBB--- ----------------- ----------------- ----------------- ----------------- ----------------- ----------------- ----------------- ----------------- ----------------- ----------------- 
--BBBBBBBBBBBBB-- ----------------- ----------------- ----------------- ----------------- ----------------- ----------------- ----------------- ----------------- ----------------- ----------------- 
--BBBBBBBBBBBBB-- ----------------- ----------------- ----------------- ----------------- ----------------- ----------------- ----------------- ----------------- ----------------- ----------------- 
-BBBBBBBBBBBBBBB- ----------------- ----------------- ----------------- ----------------- ----------------- ----------------- ----------------- ----------------- ----------------- ----------------- 
-BBBBBBBBBBBBBBB- ----------------- ----------------- ----------------- ----------------- ----------------- ----------------- ----------------- ----------------- ----------------- ----------------- 
-BBBBBBBBBBBBBBB- ----------------- ----------------- ----------------- ----------------- ----------------- ----------------- ----------------- ----------------- ----------------- ----------------- 
BBBBBAAAAAAABBBBB -----AAAAAAA----- ------IIIII------ ------HHHHH------ -------FFF------- ----------------- ----------------- ----------------- ----------------- ----------------- ----------------- 
BBBAAACCCCCAAABBB ---AAA-----AAA--- ---III-----III--- ----HH-----HH---- ----FFFAAAFFF---- -----EEEEEEE----- -------JJJ------- ----------------- ----------------- ----------------- ----------------- 
BBAACC-----CCAABB --AA---------AA-- --IAAA-----AAAI-- --HHAA-----AAHH-- ---FAAAAAAAAAF--- ---EEAAAAAAAEE--- ----JJJAAAJJJ---- ------CCCCC------ ----------------- ----------------- ----------------- 
BACC---------CCAB -AAC---------CAA- -IAA---------AAI- -HAA---------AAH- --FAAA-----AAAF-- --EAAA-----AAAE-- ---JAAAAAAAAAJ--- ----CCAAAAACC---- ------GGGGG------ ----------------- ----------------- 
BAC-----------CAB AAC-----------CAA IAAC---------CAAI -HAC---------CAH- -FAC---------CAF- -EAC---------CAE- --JAAAAAAAAAAAJ-- ---CAAAAAAAAAC--- ----GGGAAAGGG---- -------DDD------- ----------------- 
BC-------------CB A---------------A IA-------------AI HA-------------AH FAA-C-------C-AAF -EA-C-------C-AE- -JAAC-------CAAJ- --CAAA-----AAAC-- ---GGAAAAAAAGG--- -----DDDDDDD----- ----------------- 
BC-------------CB A---------------A IA-------------AI HA-------------AH FAA-----------AAF EAA-----------AAE -JAA-C-----C-AAJ- --CAAC-----CAAC-- ---GAC-----CAG--- ----DDDAAADDD---- -------KKK------- 
BC-------------CB A---------------A I---------------I H---------------H FA-------------AF EA-------------AE -JAA---------AAJ- -CAA---------AAC- --GGA-C---C-AGG-- ----DDAAAAADD---- ------KKKKK------ 
BC-------------CB A---------------A I---------------I H---------------H FA-------------AF EA-------------AE JAAA---------AAAJ -CAA---------AAC- --GAA--CCC--AAG-- ---DDAAAAAAADD--- -----KKKKKKK----- 
BC-------------CB A---------------A I---------------I H---------------H FA-------------AF EA-------------AE JAAA---------AAAJ -CAA---------AAC- --GAA--CCC--AAG-- ---DDAAAAAAADD--- -----KKKKKKK----- 
BC-------------CB A---------------A I---------------I H---------------H FA-------------AF EA-------------AE JAAA---------AAAJ -CAA---------AAC- --GAA--CCC--AAG-- ---DDAAAAAAADD--- -----KKKKKKK----- 
BC-------------CB A---------------A I---------------I H---------------H FA-------------AF EA-------------AE -JAA---------AAJ- -CAA---------AAC- --GGA-C---C-AGG-- ----DDAAAAADD---- ------KKKKK------ 
BC-------------CB A---------------A IA-------------AI HA-------------AH FAA-----------AAF EAA-----------AAE -JAA-C-----C-AAJ- --CAAC-----CAAC-- ---GAC-----CAG--- ----DDDAAADDD---- -------KKK------- 
BC-------------CB A---------------A IA-------------AI HA-------------AH FAA-C-------C-AAF -EA-C-------C-AE- -JAAC-------CAAJ- --CAAA-----AAAC-- ---GGAAAAAAAGG--- -----DDDDDDD----- ----------------- 
BAC-----------CAB AAC-----------CAA IAAC---------CAAI -HAC---------CAA- -FAC---------CAF- -EAC---------CAE- --JAAAAAAAAAAAJ-- ---CAAAAAAAAAC--- ----GGGAAAGGG---- -------DDD------- ----------------- 
-BCC---------CCB- -AAC---------CAA- -IAA---------AAI- -HAA---------AAH- --FAAA-----AAAF-- --EAAA-----AAAE-- ---JAAAAAAAAAJ--- ----CCAAAAACC---- ------GGGGG------ ----------------- ----------------- 
--BAC-------CAB-- --AA---------AA-- --IAAA-----AAAI-- --HHAA-----AAHH-- ---FAAAAAAAAAF--- ---EEAAAAAAAEE--- ----JJJAAAJJJ---- ------CCCCC------ ----------------- ----------------- ----------------- 
---BB-------BB--- ---AA-------AA--- ---III-----III--- ----HHH---HHH---- ----FFFFFFFFF---- -----EEEEEEE----- -------JJJ------- ----------------- ----------------- ----------------- ----------------- 
-----BBBBBBB----- ----------------- ----------------- ----------------- ----------------- ----------------- ----------------- ----------------- ----------------- ----------------- ----------------- 
