model
size = 32 29 26, scale = 0.05, origin = -y
material 
  colors = A:#AB3B3A B:#86473F C:#F05E1C D:#C73E3A E:#CC543A F:#F9BF45 G:#CA7A2C H:#FFB11B
voxels
9-2DA29-D31-2D30-2DA30-D2A2BA26-D2A2BA761-2DAD2BACA-2D2-DAE15-2DAD2BA2CB2DB-DC2(16-2DAD2BACAB2D2-2A)16-D-AD2BACA2B3-AC16-2DAD2BACA2B3-A18-DAD2B2ACBD22-D2AD2BACBD23-2AD2B2ABD23-2AD2BABAD22-D3AD2(BA)D22-D3AD2B-AD23-D2ADB28-A507-B2D-2A3-A4B2DAE14-B2D7A2BDB2DAE13-2B2D7A2B3DA-C13-B-2D7A2B3DA-C15-2D4-3A2B3DAC16-2D7AB2D-2AC16-D-7ABD2-2A17-D-3A2B2ABD2-AC18-DA-A2B2ABD2-AC18-DA4-A2-D2-AC18-DA4-2A-D2-AC18-D-A3-3A3DACA17-2D2-D2B2AD2-ACA18-D2AD2B2AD3-C19-D2ADBD2AD23-D2ADBD27-2ADB402-2CE-EB-3A9-3A-EA2B5-2CE-E2B2A9-5AEA2B6-CE-E2B3A8-4A2CA2B10-2B3A8-3A-C-EAB10-2B2A9-4AC2-B12-B2A8-3D2AC2-B13-2A8-3DA-C2-B13-BA7-F3D2A3-B13-B-3A2BA-F3D2A16-2B-3A2B-2A3D2A15-2(E2B4ADB3A3DA-A14-)2E2B-2ADB4-D2A-A15-E2B8-2DA2CA16-2B6-2A2DA2CA17-BD4-D2AD-A2C19-2(D2ADBD2AD23-)D2ADBD2A26-ADBD304-A2CE-E2-A-A9-2A-AE2AC5-2CE-E5A9-2A-AE2A2C4-2C3E4A10-2A-AE2AC6-C3E2B2A13-A2EAC7-3EB-2A12-2A2EAC7-3E2B2A9-D2-2A-3B10-2B3A8-D2-2A-B2C9-2C2BA8-2DA-2A-B2(C8-A-2C2B2A7-2D4ABE)C10-2C-B2A7-2DA-2ABEC10-2C2-2A6-A2DA-G-BEC10-2C3-H-ADBF2A2D2A2-BC11-2CE3-2ADBF2A2-2A-A14-C2E2-2ADB4-D3-A14-C2EB-A-D4-2D2ACB15-2EB8-2DE2CB16-EBD7-2DECB19-D5-2A2DE21-D2A2-D2AD24-DADBD2A25-DADBD2A28-B209-AC-3A18-3A2C3-AC-3A17-4A-C4-C-3A17-3A2-C4-2C4A16-3A-C6-C4A16-2A2-C6-C4A15-3A2-C7-6A13-3A2-C7-3A-3A12-2AB2-A6-4A-4A11-A3-C7-C3A-3A12-A4-A7-3A-2A13-A3-A8-3A-4A11-G3-A8-3A2-3A7-2D2-G2-CA9-AE2-E2A5-2A2D2A2-BC10-AE4-A3-BD2A2D2A2-BC11-EC4-2A2BD2A-DA2-BAC12-CE3-2A2BD7-BA13-C2EB-GA2BD5-F2BA14-2EB3-2B4-DFC2B16-E2B7-2D2C19-2B7-2D2C20-B2A3-2A2D23-DADBD2A26-2DBDA174-2A3-2A21-2A3-AC2-3A19-2A4-AC2-3A18-A2-E4-C2-2A19-A2-E4-DC3A19-A-A6-C4A17-A2(2-A6-C4A16-2A)2-A6-5A16-2A2-A6-C4A16-A3-A6-C-3A16-A3-A6-C5A14-2G3-A7-3A-A14-2G2-A8-A-E-2E2A11-G3-A8-2A3-E2A7-2A-A4-A9-AE3-3A5-3A-A3-C10-AE5-A4-5A4-C11-EC4-GA2-D5A3-AC12-CE4-3ADA2-A3-BA14-2E3-3ADA4-F2BC14-2EB11-CB17-E2B7-DF2C18-E2B6-A2DCB20-2BE2AD2A2D23-BE2BDA142-2A3-2A21-2A2-2A4-A20-2A4-2A3-A20-2A4-2A24-2A2(5-DA22-A-A)5-D-A21-A-A5-D2(-A)19-A-A5-D-A-2A17-A2-A5-D-2(A20-A2-A6-C)2(-A)17-A2-A6-C-3A16-A3-A6-C-A3E15-A2-A7-2A-3E14-2A2-A8-A2-E-E12-2A3-A8-2A3-E12-A3-E10-AE11-2A-A4-E10-A2E13-A4-E11-2E16-FC12-3E14-2BC13-2E13-2BE15-2E12-2B17-E2C7-2DCB19-E2BEFBD2ADCB21-2BE2BDA2DC107-2EF25-2B3-EF25-2B3-A-A23-3B3-3A23-3B4-DA23-3B4-D2A3(21-A-B5-D-A)21-A-3(2B4-D-A20-A2-)B6-A-A19-A2-B6-A-A18-A3-B6-A-A2-E15-A2-B7-C2-H-E15-A2-B8-C2-3E13-A3-B8-C3-2E12-A3-E10-C2-2E11-2A3-E10-C15-A4-C11-E18-C12-2E16-FC13-2(2E14-2B14-)3E11-3B17-2E2B5-3F3B17-14B19-B-9B23-9B13-2B25-B4-2B24-BAB2-3B23-3(2BA4-2BA22-)2(3B4-2BA21-A)-2B4-B2(-A21-A-BA4-A)-A20-2A-BA4-2(A2-A19-A2-B5-)A2-A18-A3-B6-A-2A17-A2-2B6-A2-A20-B7-A2-A20-B8-E2-A19-B8-E3-2A17-B9-C2-2A16-A10-C20-A11-2(C18-C12-)2C16-HC13-C16-C14-2C14-FC15-2B11-4B16-B4-10B18-13B10-3B25-AB2-3BA24-2A2-3B2(A23-3A4-B)A22-4A4-BA22-3A2(5-B-A21-A-A)5-B-A20-2A-3(A4-B2-A20-A2-)A4-B3-A18-A3-A4-B3-A21-2A4-B3-A21-A6-B2-A21-A6-B3-A19-FA6-E3-A19-E8-E2-A19-B8-E3-A18-B9-C20-A10-C20-A11-2(C18-E12-)C18-C13-C17-A13-B16-B2(14-2B)15-2B12-2B8-EF28-2AE-2A26-2A-E3A24-3A-2E2A24-2A3-E2A23-3A2(3-E2A23-A-A)3-E2A22-2A-A3-E3(2-A21-A2-A3-B)2-A20-2(A3-)B2-A20-A2-2(A4-B3-A18-A3-)A5-B3-A20-2A5-B3-A20-A6-B4-A19-A6-B23-2(B8-B22-)B9-2(B20-B10-)B20-B11-B19-E11-B18-A12-B18-B13-B16-2B14-B15-B7-2E29-3E29-E-EA27-2E-E-A26-2E-E-A25-2E3-2A25-2E3-A3(-A23-E-E3-E)-A22-A2-E3-E-A25-3(E3-E2-A24-)2(E3-)A22-E4-E3-A22-E5-E3-A21-E5-E3-A20-A6-E24-2(A7-E22-B)8-E22-B9-2(E20-B10-)E20-B11-C2(19-B11-B)18-B13-B17-B6-2E29-3E29-2E-2(A27-2E-E)2(-A25-2EB-E)-A24-E-EB-E-A24-E-C3-D-A23-E-4(C3-D-A25-)2(C3-D2-A24-)C3-2(E3-A22-E4-)E4-A21-E5-E3-A20-A6-E24-A7-E23-A7-2(E22-A8-)E21-2(A10-E20-)A11-B19-B11-B18-B13-B17-B6-DA29-3C28-3C-A27-2C-CA26-E2(-C)A26-E2(C2-C-A24-E-)C2-C-A24-2EB3-CA25-EB3-C3(-A24-EB3-A)-A24-2(B4-A2-A23-)2(C4-A3-A22-)C2(4-A)21-C5-2(E3-A20-C6-)E24-C7-B23-C7-B22-C8-B22-C9-B20-C10-B20-C11-B19-B11-B18-B13-B17-B6-DA28-4C27-E3C-2(A26-EC2-C)-A24-E-C2-E-A24-2EC3-DA24-2E4-DA23-A-2(E4-D-A24-)2(E4-C-A24-)3(E4-C2-A23-)2(E4-C3-A22-)E5-B3-A21-E5-B3-A20-2(A6-B24-)A7-B23-A7-B22-A8-B22-A9-B20-A10-B20-A11-B19-B11-B18-B13-B17-B6-2D27-2A-2D27-2A2-DA25-E2A2-D-A24-E2A3-2(2A24-EA4-)3A2(22-A-A4-A-A)24-A4-A-2A22-A5-A2-A22-A6-B-A23-A5-B-A23-A4-E2-2A2(22-A4-E3-A)22-2(A5-B3-A21-)A5-B24-A6-B24-A7-E23-A7-A22-A8-2A21-A9-A21-E9-A20-B11-A19-B11-B18-B12-B18-B13-B17-B6-2A27-B3-2A25-2B3-A-A2(24-2B4-2A)24-2B4-A-A23-B5-A-A22-AB5-A-2A21-AB5-A2-A21-A3(B6-B-A22-)3(B6-B2-A21-)2(B6-B3-A20-)2(B6-B24-)B7-A23-A7-A22-2B8-A21-B9-A20-FB9-A20-2(B11-A19-)B11-2B2(17-B13-B)17-B7-AB26-B3-A2B25-B4-2B24-3(2B4-B-A23-)2B2(4-B2-A21-A-B)5-B-A20-2A2(B6-B2-A19-A-)2(B6-B2-2A18-A-)B6-B2-2A2(20-B6-B3-A)20-B6-B24-2(B7-A23-)B7-A2(C21-B9-)AC18-3A10-C19-A11-2C17-2A11-2C17-A13-CA15-FA13-2B15-2B13-2B3(15-B)9-2B25-2A3-2B-A20-5A3-2B-2A17-5A-A4-2(B4A16-6A5-)2(B-3A16-6A5-)B-3A16-4A-A5-B2-3A17-2A-A5-B2-2A3-2A14-A-A5-B2-2A18-3A6-B2-2A19-2A2(6-B22-3A)6-B9-A12-3A6-BA8-A12-3A7-A8-A11-4A7-AC-F16-A2(D2A9-CEF16-C)D2A10-EF16-2(CDA11-2CA15-)CD13-C2A13-FCD14-2(2A13-FC15-)2B13-2B15-2B13-2B16-2B11-2B10-2B16-B3-A-D4A3-2B5A10-A2B4AD2A2E3-B-A-3A10-A2B4AD2AE5-B2-A-A10-A2B2A-2(AD2AE5-B2-2A11-A2B3-)AD2A6-B2-2A11-A2B3-A2(D3A5-B2-2A11-A-BA2-C)D3A5-A2-2A2(5-A)-BA-2CD2A6-A2-2A5-2A4-A-BAD2CD-A2(6-A2-A6-2A4-A-BAD2CD2A)6-5A5-3A3-A-BAD2CD2A7-ACAB5-4A2-A-BAD2CD2A7-A2(CE2B2-F9-FAD2C11-)CE2B2-F9-FADC13-E2BF-F9-FADC14-2BF-F9-FAD15-2BE-C10-AD16-3BE10-AD17-2BE2(10-AD17-3B)A9-AD17-2BA10-AD17-4B8-3B18-4B7-2B19-3B7-3B11-BC2(2A2B)9-2BADC2-2E4-B2-A2B4A6-2A-2BADC8-B2-A2B4A6-AG-2BADC9-C-A2B2A-2A5-2A-2BADC9-CEA2B2A-2A6-A-2BADC9-CEA2BA2-3A5-A-2BADC2-2A5-CEA2B6A5-AB-BADC2-2A5-2CA2B3AB-2A4-AB-BD2C10-CA2BA2C2B3A3-AB-2(ADC11-CA2BA2C2B-6A-B)A-C11-CA2BA2C2B-6A-B-A12-CA2B2AC2B2-5A-B14-C2A2BACEB2-5A-B17-2BAE2C3-3A-FB18-BAE2C4-2A-4(FB19-AE2C7-)FB20-C-CE6-FB21-2ECB2F3-FB22-AC4B2-FB2(22-ACA3BCA2B)A20-2A2(CA2BA)21-10B23-9B22-9B13-2CDA3-C2-A6-EB13-2CDA3-C2BA6-E2B13-CDA3-C2BA6-E15-CEA3-C2B2A5-EB15-EA3-C4BA4-EB16-A3-C4B2A3-EB20-CA2B-5AEB20-C-2B-5AEB23-BA-4AEB23-BA2-D2A-B23-B2A-D2AEB23-B3ADCA3(EB23-B3ADCD)2A23-E2BADCD2A23-2EBADCD2A2(24-EBADC2DA)24-EB2ADCDA24-E2BADCDA24-C2BADCDA28-DCDA29-CD184-A6-E24-2A5-EB23-3A3-AEB23-D6AEB23-DB5AEB24-D3ACAEB24-2D2A2(CAEB24-2ADA)CAEB24-2A2DCAE26-2ADC-E26-2A2-AE568-CA3-2(CAEB23-E4A)CAE25-2ABACAE25-D2ABCA27-3AC29-C32-C31-C669-BAD-A25-C-BADCA25-C-ABAC27-C32-C31-C753-
