model
size = 20 12 31, scale = 0.05, origin = -y
material 
  colors = A:#FD8B68 B:#6E40E5 C:#E824A4 D:#5BCDE6 E:#69F96C F:#FA9E58 G:#FF7877 H:#F9FF75
voxels
------HHHHHHHH------ -------------------- -------------------- -------------------- -------------------- -------------------- -------------------- -------------------- -------------------- -------------------- -------------------- -------------------- 
----EEEAAAAAAEEE---- -------EEEEEE------- -------------------- -------------------- -------------------- -------------------- -------------------- -------------------- -------------------- -------------------- -------------------- -------------------- 
---DDAAAAAAAAAAEE--- -----DDDDDDDDDD----- -------------------- -------------------- -------------------- -------------------- -------------------- -------------------- -------------------- -------------------- -------------------- -------------------- 
--DDAAAAAAAAAAAAEE-- ----BBBBBBBBBBDD---- -------------------- -------------------- -------------------- -------------------- -------------------- -------------------- -------------------- -------------------- -------------------- -------------------- 
--DAAAAAAAAAAAAAAD-- ---BCCCCCBCBCBDDD--- -------------------- -------------------- -------------------- -------------------- -------------------- -------------------- -------------------- -------------------- -------------------- -------------------- 
--DAAAAAAAAAAAAAAD-- ---BCBCBCBCBCBBBB--- -------------------- -------------------- -------------------- -------------------- -------------------- -------------------- -------------------- -------------------- -------------------- -------------------- 
-BDAAAAAAAAAAAAAADB- ---BCBCBCBCBCCCCB--- -------------------- -------------------- -------------------- -------------------- -------------------- -------------------- -------------------- -------------------- -------------------- -------------------- 
-BAAAAAAAAAAAAAAAAB- --DBCBCBCBCBCBBCBD-- -------------------- -------------------- -------------------- -------------------- -------------------- -------------------- -------------------- -------------------- -------------------- -------------------- 
-BAAAAAAAAAAAAAAAAB- --DBCBBBCBCBCBBCBD-- -------------------- -------------------- -------------------- -------------------- -------------------- -------------------- -------------------- -------------------- -------------------- -------------------- 
-BAAAAAAAAAAAAAAAAB- --DBCBDBCBCBCCCCBD-- -------------------- -------------------- -------------------- -------------------- -------------------- -------------------- -------------------- -------------------- -------------------- -------------------- 
-BAAAAAAAAAAAAAAAAB- --DBBBDBBBBBBBBBBD-- -------------------- -------------------- -------------------- -------------------- -------------------- -------------------- -------------------- -------------------- -------------------- -------------------- 
-BAAAAAAAAAAAAAAAAB- --DDDDDDDDDDDDDDDD-- -------EEEEEE------- --------HHHH-------- -------------------- -------------------- -------------------- -------------------- -------------------- -------------------- -------------------- -------------------- 
-BAAAAA------AAAAAB- --DDDDDAAAAAADDDDD-- -----EEAAAAAAEE----- -----HHHAAAAHHH----- ------FFFFFFFF------ -------GGGGGG------- -------------------- -------------------- -------------------- -------------------- -------------------- -------------------- 
-BAAA----------AAAB- --DDDAA------AADDD-- ----EAA------AAE---- ----HAAA----AAAH---- ----FFAAAAAAAAFF---- -----GGAAAAAAGG----- ------CCCCCCCC------ ---------CC--------- -------------------- -------------------- -------------------- -------------------- 
-BA--------------AB- --DAA----------AAD-- ---EA----------AE--- ---HA----------AH--- ---FAA--------AAF--- ----GAA------AAG---- -----CAAAAAAAAC----- ------GGGAAGGG------ ---------GG--------- -------------------- -------------------- -------------------- 
-BA--------------AB- --DA------------AD-- --EA------------AE-- --HA------------AH-- --FA------------AF-- ---GA----------AG--- ----CA--------AC---- -----GAAAAAAAAG----- ------FFFFFFFF------ -------------------- -------------------- -------------------- 
-BA--------------AB- -DA--------------AD- -EA--------------AE- -HA--------------AH- --FA------------AF-- --GA------------AG-- ---CA----------AC--- ----GAA------AAG---- -----FFAAAAAAFF----- -------HHHHHH------- -------------------- -------------------- 
-BA--------------AB- -DA--------------AD- -EA--------------AE- -HA--------------AH- -FA--------------AF- --GA------------AG-- --CA------------AC-- ---GAA--------AAG--- ----FFAAAAAAAAFF---- ------HEEEEEEH------ -------------------- -------------------- 
BA----------------AB BA----------------AB BA----------------AB -BA--------------AB- -BA--------------AB- -BA--------------AB- --CA------------AC-- ---GA----------AG--- ----FAAA----AAAF---- -----HEEAAAAEEH----- --------DDDD-------- -------------------- 
CA----------------AC CA----------------AC CA----------------AC CA----------------AC -CA--------------AC- -BA--------------AB- --CA------------AC-- ---GA----------AG--- ----FAA------AAF---- -----HEAAAAAAEH----- -------DBBBBD------- -------------------- 
CA----------------AC CA----------------AC CA----------------AC CA----------------AC -CA--------------AC- -BA--------------AB- --CA------------AC-- --CAA----------AAC-- ---GFAA------AAFG--- -----HEAAAAAAEH----- -------DBBBBD------- ---------CC--------- 
CA----------------AC CA----------------AC CA----------------AC CA----------------AC -CA--------------AC- -BA--------------AB- --CA------------AC-- --CAA----------AAC-- ---GFAA------AAFG--- -----HEAAAAAAEH----- -------DBBBBD------- ---------CC--------- 
CA----------------AC CA----------------AC CA----------------AC CA----------------AC -CA--------------AC- -BA--------------AB- --CA------------AC-- ---GA----------AG--- ----FAA------AAF---- -----HEAAAAAAEH----- -------DBBBBD------- -------------------- 
BA----------------AB BA----------------AB BA----------------AB -BA--------------AB- -BA--------------AB- -BA--------------AB- --CA------------AC-- ---GA----------AG--- ----FAAA----AAAF---- -----HEEAAAAEEH----- --------DDDD-------- -------------------- 
-BA--------------AB- -DA--------------AD- -EA--------------AE- -HA--------------AH- -FA--------------AF- --GA------------AG-- --CA------------AC-- ---GAA--------AAG--- ----FFAAAAAAAAFF---- ------HEEEEEEH------ -------------------- -------------------- 
-BA--------------AB- -DA--------------AD- -EA--------------AE- -HA--------------AH- --FA------------AF-- --GA------------AG-- ---CA----------AC--- ----GAA------AAG---- -----FFAAAAAAFF----- -------HHHHHH------- -------------------- -------------------- 
--BA------------AB-- --DA------------AD-- --EA------------AE-- --HA------------AH-- --FA------------AF-- ---GA----------AG--- ----CA--------AC---- -----GAAAAAAAAG----- ------FFFFFFFF------ -------------------- -------------------- -------------------- 
--BAA----------AAB-- --DAA----------AAD-- ---EA----------AE--- ---HA----------AH--- ---FAA--------AAF--- ----GAA------AAG---- -----CAAAAAAAAC----- ------GGGGGGGG------ ---------GG--------- -------------------- -------------------- -------------------- 
---BBAA------AABB--- ---DDAA------AADD--- ----EAA------AAE---- ----HAAAAAAAAAAH---- ----FFAAAAAAAAFF---- -----GBAAAAAABG----- ------BBBBBBBB------ ---------CC--------- -------------------- -------------------- -------------------- -------------------- 
-----BB------BB----- -----DB------BD----- -----EB------BE----- -----HBCCCCCCBH----- ------BCCCCCCB------ -------CCCCCC------- -------------------- -------------------- -------------------- -------------------- -------------------- -------------------- 
-------CHCCCC------- -------------------- -------------------- -------------------- -------------------- -------------------- -------------------- -------------------- -------------------- -------------------- -------------------- -------------------- 
