model
size = 32, scale = 0.05, origin = -y
material 
  colors = A:#AAA B:#C4C4C4 C:#E7E7E7 D:#F2F2F2 E:#FD0 F:#888 G:#DFC100
voxels
141-3(8C24-)8C152-3(8C24-)8C535-3(8D24-)8D22-3(3B8A3B18-)3B8A3B146-3(3B8A3B18-)3B8A3B20-3(8C24-)8C25-3(8C24-)8C151-3(8D24-)8D21-3C8D3C18-3C3(BA)2B2(3C18-3C8B)3C18-2(2AC10AC2A16-)2AC7ACA2C2A16-3A10-3A18-3(8C24-)8C22-2(2AC10AC2A16-)2AC7ACA2C2A16-3A10-3A16-3(3B8A3B18-)3B8A3B19-3(3B8A3B18-)3B8A3B20-3(8C24-)8C21-2(3C8B3C18-)3C3(BA)2B3C18-14D17-B2D10-2DB16-2BC2A2(BA)BCB2C2(2B16-2BC10BC)2B16-2(AC14ACA14-)AC10ACA3CA2(14-2A)14-4(3B8A3B18-)2(AC14ACA14-)AC10ACA3CA3(14-2A)2(C10AC2A16-2A)C7ACA2C2A16-3A10-3A17-2(2AC10AC2A16-)2AC7ACA2C2A16-3A10-3A16-3(3B8A3B18-)3B8A3B17-2(2BC10BC2B16-)2BC2A2(BA)B2(C2B)16-3D10-3D15-BD14-DB14-BC3A2(BA)3B5C2(B14-BC14BC)B14-2(FC16ACF12-)FC8A2(CA)2(CD)CF12-FA5-E10-AF12-2(2AC10AC2A16-)2AC7ACA2C2A16-3A10-3A16-2(FC16ACF12-)FC8A2(CA)2(CD)CF12-FA5-E10-AF12-2(AC14ACA14-)AC10ACA3CA2(14-2A)15-2(AC14ACA14-)AC10ACA3CA3(14-2A)2(C10AC2A16-2A)C7ACA2C2A16-3A10-3A15-2(BC14BCB14-)BC3A2(BA)3B2C2BCB2(14-2D)13-AD5-E10-DA12-AC3A2(BA)BCB3C2(DC)2(A12-AC16BC)A12-2(FC18ACF10-)FC10ACA3C2(DC)F10-FA6-2E10-AF10-2(AC14ACA14-)AC10ACA3CA2(14-2A)14-2(FC18ACF10-)FC10ACA3C2(DC)F10-FA6-2E10-AF10-2(FC16ACF12-)FC8A2(CA)2(CD)CF12-FA5-E10-AF13-2(FC16ACF12-)FC8A2(CA)2(CD)CF12-FA5-E10-AF12-2(AC14ACA14-)AC10ACA3CA2(14-2A)13-2(AC16BCA12-)AC3A2(BA)BCB3CDCBCA12-2D5-E10-2D11-AD6-2E10-DA10-AC3ABA5B5C2(DC)2(A10-AC18BC)A10-2(AC20ACA8-)AC10ACA2(CD)C3DCA8-2A7-2E11-2A8-2(FC16ACF12-)FC8A2(CA)2(CD)CF12-FA5-E10-AF12-2(AC20ACA8-)AC10ACA2(CD)C3DCA8-2A7-2E11-2A8-2(FC18ACF10-)FC10ACA3C2(DC)F10-FA6-2E10-AF11-2(FC18ACF10-)FC10ACA3C2(DC)F10-FA6-2E10-AF10-2(FC16ACF12-)FC8A2(CA)2(CD)CF12-FA5-E10-AF11-2(AC18BCA10-)AC3ABA5B5CDCBCA10-2D6-2E10-2D9-BD7-2E11-DB8-BC3A2(BA)3B3C2(DC)3D2(CB8-BC20B)CB8-2(AC22ACA6-)AC12A3CDC3DCDCA6-2A8-E-E11-2A6-2(FC18ACF10-)FC10ACA3C2(DC)F10-FA6-2E10-AF10-2(AC22ACA6-)AC12A3CDC3DCDCA6-2A8-E-E11-2A6-2(AC20ACA8-)AC10ACA2(CD)C3DCA8-2A7-2E11-2A9-2(AC20ACA8-)AC10ACA2(CD)C3DCA8-2A7-2E11-2A8-2(FC18ACF10-)FC10ACA3C2(DC)F10-FA6-2E10-AF9-2(BC20BCB8-)BC3A2(BA)3B3C2(DC)2DBCB8-2D7-2E11-2D7-BD8-E-E11-DB6-BC3A2(BA)4B4CDC3DCD2(CB6-BC22B)CB6-2(B26AB4-)B9ACAC2A2(DC)3D2A2CAB4-BA9-E2-E7-2E2-AB4-2(AC20ACA8-)AC10ACA2(CD)C3DCA8-2A7-2E11-2A8-2(B26AB4-)B9ACAC2A2(DC)3D2A2CAB4-BA9-E2-E7-2E2-AB4-2(AC22ACA6-)AC12A3CDC3DCDCA6-2A8-E-E11-2A7-2(AC22ACA6-)AC12A3CDC3DCDCA6-2A8-E-E11-2A6-2(AC20ACA8-)AC10ACA2(CD)C3DCA8-2A7-2E11-2A7-2(BC22BCB6-)BC3A2(BA)4B4CDC3D2(CB)6-2D8-E-E11-2D5-CD9-E2-E7-2E2-DC4-CB3A2(BA)BCB2CB2(DC)3D2B2CB2(C4-C26B)C5-2(BC24ACB4-)BC11ACA2(CD)4ACD2CB4-BA9-E2-E4-4E3-AB3-2(AC22ACA6-)AC12A3CDC3DCDCA6-2A8-E-E11-2A7-2(BC24ACB4-)BC11ACA2(CD)4ACD2CB4-BA9-E2-E4-4E3-AB3-2(B26AB4-)B9ACAC2A2(DC)3D2A2CAB4-BA9-E2-E7-2E2-AB5-2(B26AB4-)B9ACAC2A2(DC)3D2A2CAB4-BA9-E2-E7-2E2-AB4-2(AC22ACA6-)AC12A3CDC3DCDCA6-2A8-E-E11-2A5-2(C26BC4-)CB3A2(BA)BCB2CB2(DC)3D2(2BC)4-2D9-E2-E7-2E2-2D4-CD9-E2-E4-4E3-DC4-2C2A2(BA)4B2CB2(CD)4BCD3C2(4-2C24B2C)5-2(B26AB4-)B7A2(CA)CDC4ADCA3CACB4-B10-E3-EG2E2-E5-B2-2(B26AB4-)B9ACAC2A2(DC)3D2A2CAB4-BA9-E2-E7-2E2-AB6-2(B26AB4-)B7A2(CA)CDC4ADCA3CACB4-B10-E3-EG2E2-E5-B3-2(BC24ACB4-)BC11ACA2(CD)4ACD2CB4-BA9-E2-E4-4E3-AB5-2(BC24ACB4-)BC11ACA2(CD)4ACD2CB4-BA9-E2-E4-4E3-AB3-2(B26AB4-)B9ACAC2A2(DC)3D2A2CAB4-BA9-E2-E7-2E2-AB2(4-2C24B2C)4-2C2A2(BA)4B2CB2(CD)4BCDB2C4-2D9-E2-E4-4E3-2D4-C10-E3-EG2E2-E5-C4-C2A2(BA)3(BC)DC4BDCB6C2(4-C26BC)4-2(C26ACAC2-)C9AC2AC4A2DCACDCA2CAC2-CA10-G-2EGE3-E6-AC-2(BC24ACB4-)BC11ACA2(CD)4ACD2CB4-BA9-E2-E4-4E3-AB5-2(C28AC2-)C9AC2AC4A2DCACDCAC2AC2-CA10-G-2EGE3-E6-AC2-2(B26AB4-)B7A2(CA)CDC4ADCA3CACB4-B10-E3-EG2E2-E2(5-B)2(26AB4-B)7A2(CA)CDC4ADCA3CACB4-B10-E3-EG2E2-E5-B3-2(BC24ACB4-)BC11ACA2(CD)4ACD2CB4-BA9-E2-E4-4E3-AB2(4-C26BC)4-C3(BA)3(BC)DC4BDCB4CBC4-D10-E3-EG2E2-E5-D3-2D10-G-2EGE3-E6-2D2-D3(BA)3B2CBC4B2DCBCD3C2B2(D2-D28B)D3-2(2C25A3C2-)2C5ACAC4ADCDAD2A3CACA3C2-CA9-3E3-G-2E7-AC-2(B26AB4-)B7A2(CA)CDC4ADCA3CACB4-B10-E3-EG2E2-E5-B5-2(2C26A2C2-)2C5ACAC4ADCDAD2A3CACA3C2-CA9-3E3-G-2E7-AC-2(C29A2-)C9AC2AC4A2DCACDCAC3A2-CA10-G-2EGE3-E6-2A3-2(C26ACAC2-)C9AC2AC4A2DCACDCA2CAC2-CA10-G-2EGE3-E6-AC2-2(B26AB4-)B7A2(CA)CDC4ADCA3CACB4-B10-E3-EG2E2-E5-B3-2(D28BD2-)D3(BA)3B2CBC4B2DCBCD3C2BD2-2D10-G-2EGE3-E6-2D2-2D9-3E3-G-2E7-2D2-DC2(BA)BCB2C3BDCDBD2B5CB2C2(D2-DC26BC)D3-2(2C25A3C2-)2C9ACADC3D2ACDCAC2A3C2-CA6-3E-G5-GE8-A2C2(28AC2-C)9AC2AC4A2DCACDCAC2AC2-CA10-G-2EGE3-E6-AC4-2(2C25A3C2-)2C9ACADC3D2ACDCAC2A3C2-CA6-3E-G5-GE8-AC-2(2C26A2C2-)2C5ACAC4ADCDAD2A3CACA3C2-CA9-3E3-G-2E7-AC3-2(2C25A3C2-)2C5ACAC4ADCDAD2A3CACA3C2-CA9-3E3-G-2E7-AC-2(C28AC2-)C9AC2AC4A2DCACDCAC2AC2-CA10-G-2EGE3-E6-AC2(2-DC26BCD)2-DC2(BA)BCB2C3BDCDBD2B5CB2CD2-2D9-3E3-G-2E7-2D2-2D6-3E-G5-GE8-2D2-DCABA6BCBDC3D2BCD3C3B2(CD2-DC26B)CD3-2(2C25A3C2-)2C7ACDCAC3DCA3C2(AC)A3C2-CA3-3E4-E5-E9-A3C2(26A2C2-2C)5ACAC4ADCDAD2A3CACA3C2-CA9-3E3-G-2E7-AC4-2(2C25A3C2-)2C7ACDCAC3DCA3C2(AC)A3C2-CA3-3E4-E5-E9-AC-2(2C26A2C2-)2C9ACADC3D2ACDCAC3A2C2-CA6-3E-G5-GE8-AC3-2(2C25A3C2-)2C9ACADC3D2ACDCAC2A3C2-CA6-3E-G5-GE8-AC-2(2C26A2C2-)2C5ACAC4ADCDAD2A3CACA3C2-CA9-3E3-G-2E7-AC2(2-DC26BCD)2-DCABA6BCBDC3D2BCD3C3BCD2-2D6-3E-G5-GE8-2D2-2D3-3E4-E5-E9-2D2-DCBA4B2CDCBC3DCB5CBCBA2(CD2-DC26B)CD3-2(2C25A3C2-)2C6A3CDA3DCDADCAC4A3C2-CA3-3E4-E5-E9-A3C2(26A2C2-2C)9ACADC3D2ACDCAC3A2C2-CA6-3E-G5-GE8-AC4-2(2C25A3C2-)2C6A3CDA3DCDADCAC4A3C2-CA3-3E4-E5-E9-AC-2(2C26A2C2-)2C7ACDCAC3DCA3C2(AC)2A2C2-CA3-3E4-E5-E9-AC3-2(2C25A3C2-)2C7ACDCAC3DCA3C2(AC)A3C2-CA3-3E4-E5-E9-AC-2(2C26A2C2-)2C9ACADC3D2ACDCAC3A2C2-CA6-3E-G5-GE8-AC2(2-DC26BCD)2-DCBA4B2CDCBC3DCB5CBCBACD2(2-2D3-3E4-E5-E9-2D)2-DCA5B3CDB3DCDBD3C3BAB2(CD2-DC26B)CD3-2(2C25A3C2-)2C3(AC)3ACA2DCDC3ACAC3A3C2-CA6-3E-E5-EG8-A3C2(26A2C2-2C)7ACDCAC3DCA3C2(AC)2A2C2-CA3-3E4-E5-E9-AC4-2(2C25A3C2-)2C3(AC)3ACA2DCDC3ACAC3A3C2-CA6-3E-E5-EG8-AC-2(2C26A2C2-)2C6A3CDA3DCDADCAC5A2C2-CA3-3E4-E5-E9-AC3-2(2C25A3C2-)2C6A3CDA3DCDADCAC4A3C2-CA3-3E4-E5-E9-AC-2(2C26A2C2-)2C7ACDCAC3DCA3C2(AC)2A2C2-CA3-3E4-E5-E9-AC2(2-DC26BCD)2-DCA5B3CDB3DCDBD3C3BABCD2-2D3-3E4-E5-E9-2D2-2D6-3E-E5-EG8-2D2-D2(CB)3C3BCB2DCDC2B2CBC2(BA)2(CD2-DC26B)CD3-2(2C25A3C2-)2C2ACA3CDC3ACDCAC8A3C2-CA9-GEG3-E-2E7-A3C2(26A2C2-2C)6A3CDA3DCDADCAC5A2C2-CA3-3E4-E5-E9-AC4-2(2C25A3C2-)2C2ACA3CDC3ACDCAC8A3C2-CA9-GEG3-E-2E7-AC-2(2C26A2C2-)2C3(AC)3ACA2DCDC3ACAC4A2C2-CA6-3E-E5-EG8-AC3-2(2C25A3C2-)2C3(AC)3ACA2DCDC3ACAC3A3C2-CA6-3E-E5-EG8-AC-2(2C26A2C2-)2C6A3CDA3DCDADCAC5A2C2-CA3-3E4-E5-E9-AC2(2-DC26BCD)2-D2(CB)3C3BCB2DCDC2B2CBC2(BA)CD2-2D6-3E-E5-EG8-2D2-2D9-GEG3-E-2E7-2D2-DC2B5CDC3BCDCBC5B2(AB)2(CD2-DC26B)CD3-2(C26ACAC2-)C2ACA2(CD)C2DAC5AC7ACAC2-CA10-E-3EG3-E6-A3C2(26A2C2-2C)3(AC)3ACA2DCDC3ACAC4A2C2-CA6-B2E-E5-EG8-AC4-2(C26ACAC2-)C2ACA2(CD)C2DAC5AC7ACAC2-CA10-E-3EG3-E6-AC-2(2C26A2C2-)2C2ACA3CDC3ACDCAC9A2C2-CA9-GEG3-E-2E7-AC3-2(2C25A3C2-)2C2ACA3CDC3ACDCAC8A3C2-CA9-GEG3-E-2E7-AC-2(2C26A2C2-)2C3(AC)3ACA2DCDC3ACAC4A2C2-CA6-3E-E5-EG8-AC2(2-DC26BCD)2-DC2B5CDC3BCDCBC5B2(AB)CD2-2D9-GEG3-E-2E7-2D2-2D10-E-3EG3-E6-2D2-D2B3C2(DC)2DBC4B2C3B3(AB)2(D2-D28B)D2(4-B25ACB)4-B2A3CDC3DADCD11ACB4-B10-E3-G3E2-E5-B-2(2C26A2C2-)2C2ACA3CDC3ACDCAC9A2C2-CA9-GEG3-E-2E7-AC5-2(B26AB4-)B2A3CDC3DADCD12AB4-B10-E3-G3E2-E5-B2(2-C28AC)2-C2ACA2(CD)C2DAC5AC9AC2-CA10-E-3EG3-E6-AC3-2(C26ACAC2-)C2ACA2(CD)C2DAC5AC7ACAC2-CA10-E-3EG3-E6-AC-2(C28AC2-)C3ACA3CDC3ACDCAC10AC2-CA9-GEG3-E-2E7-AC2(2-D28BD)2-D2B3C2(DC)2DBC4B2C3B3(AB)D2-2D10-E-3EG3-E6-2D3-C10-E3-G3E2-E5-C4-6CDC3DBDCD8BAB2A2(C4-C26B)C5-2(BC24ACB4-)B2C2(DC)3DCA2C2ACAC7ACB4-BA9-E2-E4-4E3-CB-2(C28AC2-)C2ACA2(CD)C2DAC5AC9AC2-CA10-E-3EG3-E6-AC5-2(BC24ACB4-)B2C2(DC)3DCA2C2ACAC7ACB4-BA9-E2-E4-4E3-AB3-2(B26AB4-)B2A3CDC3DADCD12AB4-B10-E3-G3E2-E2(5-B)2(26AB4-B)2A3CDC3DADCD12AB4-B10-E3-G3E2-E5-B2(2-C28AC)2-C2ACA2(CD)C2DAC5AC9AC2-CA10-E-3EG3-E6-AC3-2(C26BC4-)CB4CDC3DBDCD8B2(AB)C4-D10-E3-G3E2-E5-D4-CD9-E2-E4-4E3-DC4-3C2(DC)3DC2(B2C)BC5B2A2(2C4-2C24B)2C5-2(B26AB4-)B2ACDC3DCDA2CAC11AB4-BA9-E2-E7-2E2-AB2-2(B26AB4-)B2A3CDC3DADCD12AB4-B10-E3-G3E2-E5-B6-2(B26AB4-)B2ACDC3DCDA2CAC11AB4-BA9-E2-E7-2E2-AB3-2(BC24ACB4-)B2C2(DC)3DCA2C2ACAC7ACB4-BA9-E2-E4-4E3-AB5-2(BC24ACB4-)B2C2(DC)3DCA2C2ACAC7ACB4-BA9-E2-E4-4E3-AB3-2(B26AB4-)B2A3CDC3DADCD12AB4-B10-E3-G3E2-E5-B2(4-2C24B2C)4-2CB2(DC)3DC2(B2C)BC5B2A2C4-2D9-E2-E4-4E3-2D4-CD9-E2-E7-2E2-DC4-CB2CDC3DCDB2CBC3BABA2B2AB2(C4-C26B)C2(6-AC22ACA)6-ACDC3DCD3(CA)C8ACA6-2A8-E-E11-2A3-2(BC24ACB4-)B2C2(DC)3DCA2C2ACAC7ACB4-2B9-E2-E4-4E3-AB7-2(AC22ACA6-)ACDC3DCD3(CA)C8ACA6-2A8-E-E11-2A2(4-B26AB)4-B2ACDC3DCDA2CAC11AB4-BA9-E2-E7-2E2-AB5-2(B26AB4-)B2ACDC3DCDA2CAC11AB4-BA9-E2-E7-2E2-AB3-2(BC24ACB4-)B2C2(DC)3DCA2C2ACAC7ACB4-BA9-E2-E4-4E3-AB2(4-C26BC)4-C2BCDC3DCDB2CBC3BABA2B2ABC4-2D9-E2-E7-2E2-2D5-BD8-E-E11-DB6-BCDC3DCD4(CB)2(AB)3A2(CB6-BC22B)CB2(8-AC20ACA)8-AC3DCD2C2AC10ACA8-2A7-2E11-2A2(4-B26AB)4-B2ACDC3DCDA2CAC11AB4-BA9-E2-E7-2E2-AB2(8-AC20ACA)8-AC3DCD2C2AC10ACA8-2A7-2E11-2A2(6-AC22ACA)6-ACDC3DCD3(CA)C8ACA6-2A8-E-E11-2A7-2(AC22ACA6-)ACDC3DCD3(CA)C8ACA6-2A8-E-E11-2A2(4-B26AB)4-B2ACDC3DCDA2CAC11AB4-BA9-E2-E7-2E2-AB5-2(BC22BCB6-)2(BC)3DCD4(CB)2(AB)3ACB6-2D8-E-E11-2D7-BD7-2E11-DB8-BC3DCD2C2BC3B2(AB)3A2(CB8-BC20B)CB2(10-FC18ACF)10-F2(CD)3C3AC8ACF10-FA6-2E10-AF2(6-AC22ACA)6-ACDC3DCD3(CA)C8ACA6-2A8-E-E11-2A2(10-FC18ACF)10-F2(CD)3C3AC8ACF10-FA6-2E10-AF2(8-AC20ACA)8-AC3DCD2C2AC10ACA8-2A7-2E11-2A9-2(AC20ACA8-)AC3DCD2C2AC10ACA8-2A7-2E11-2A2(6-AC22ACA)6-ACDC3DCD3(CA)C8ACA6-2A8-E-E11-2A7-2(BC20BCB8-)BCB2DCD2C2BC3B2(AB)3ACB8-2D7-2E11-2D9-AD6-2E10-DA10-A2(CD)3C3BC2(BA)B3A2(CA10-AC18B)CA2(12-FC16ACF)12-FCD3C12ACF12-FA5-E10-AF2(8-AC20ACA)8-AC3DCD2C2AC10ACA8-2A7-2E11-2A2(12-FC16ACF)12-FCD3C12ACF12-FA5-E10-A2(F10-FC18AC)F10-F2(CD)3C3AC8ACF10-FA6-2E10-AF11-2(FC18ACF10-)F2(CD)3C3AC8ACF10-FA6-2E10-AF2(8-AC20ACA)8-AC3DCD2C2AC10ACA8-2A7-2E11-2A9-2(AC18BCA10-)ACBCD3C3BC2(BA)B3ACA10-2D6-2E10-2D11-AD5-E10-DA12-ACD4C4B2(AB)3A2(CA12-AC16B)2(CA14-AC14A)CA14-4(AC)8ACA2(14-2A)2(10-FC18ACF)10-F2(CD)3C3AC8ACF10-FA6-2E10-AF2(14-AC14ACA)14-4(AC)8ACA2(14-2A)2(12-FC16ACF)12-FCD3C12ACF12-FA5-E10-AF13-2(FC16ACF12-)FCD3C12ACF12-FA5-E10-A2(F10-FC18AC)F10-F2(CD)3C3AC8ACF10-FA6-2E10-AF11-2(AC16BCA12-)ACB4C4B2(AB)3ACA12-2D5-E10-2D13-BD14-DB14-B5CBC2(BA)B3A2(CB14-BC14B)CB3(16-2AC10AC2A)16-3A10-3A2(12-FC16ACF)12-FCD3C12ACF12-FA5-E10-AF3(16-2AC10AC2A)16-3A10-3A2(14-AC14ACA)14-4(AC)8ACA2(14-2A)15-2(AC14ACA14-)4(AC)8ACA2(14-2A)2(12-FC16ACF)12-FCD3C12ACF12-FA5-E10-AF13-2(BC14BCB14-)BC2B2CBC2(BA)B3ACB2(14-2D)15-B2D10-2DB16-2B2C3B2(AB)2A2(C2B16-2BC10B)C2B4(18-3B8A3B)2(14-AC14ACA)14-4(AC)8ACA2(14-2A)4(18-3B8A3B)3(16-2AC10AC2A)16-3A10-3A17-3(2AC10AC2A16-)3A10-3A2(14-AC14ACA)14-4(AC)8ACA2(14-2A)15-2(2BC10BC2B16-)2BC4B2(AB)2AC2B16-3D10-3D17-3C8D3C18-3CB2(AF)2AB2(3C18-3C8B)3C22-3(8C24-)8C18-3(2AC10AC2A16-)3A10-3A22-3(8C24-)8C20-3(3B8A3B18-)3B8A3B19-3(3B8A3B18-)3B8A3B3(16-2AC10AC2A)16-3A10-3A17-2(3C8B3C18-)3CB2(AF)2AB3C18-14D21-3(8D24-)8D148-3(3B8A3B18-)3B8A3B150-3(8C24-)8C25-3(8C24-)8C20-3(3B8A3B18-)3B8A3B21-3(8D24-)8D279-3(8C24-)8C409-3(8C24-)8C140-
