model
size = 26 31 32, scale = 0.05, origin = -y
material 
  colors = A:#8E354A B:#64363C
voxels
273-BA23-2ABA21-3ABA21-B2ABA20-2B2ABA19-A-2BABA22-BAB2A20-2BA2B568-2B23-A2BA21-BA2B3AB17-AB6AB16-2AB6A2(2B15-2A2B5A)2B15-2A3B2(4A2B15-3A2B)A2BA2(B17-2A2(2BA))20-2BAB439-2B22-BA2B2A20-BA2B3A18-ABA2B3A16-A-AB5-3A14-2(3A6-4A12-B)2A8-3A13-3A7-3A12-B3A7-3A13-2A8-3A12-B3A6-4A13-4A4-B3A14-4AB3-B2AB15-3A2BA2B2A18-3B2AB22-A337-AB22-B2ABAB19-2B4A2B18-2A4-2B16-B2A6-2B15-BA8-BA13-2BA9-2(3A10-ABA10-)3A10-AB13-A10-AB12-2A10-AB12-3A9-ABA11-2A10-ABA11-2A11-BA10-3A11-BA10-2B12-2B2A7-A2B13-B2A2B2-A2BA17-A2BA4B21-AB258-AB23-2ABA20-2B2AB3A17-A2BA3-2A17-AB6-2A15-BA8-2A13-2B10-2A12-B12-A11-AB12-2A10-2A13-AB8-3A13-AB8-2A15-2(B8-2A14-A)B8-3A13-AB8-2A14-AB8-3A12-2AB9-2A12-2B10-A2(2B11-)2B10-2B13-B2A6-BAB16-A2BA4B19-2(2BA)20-2(2BA)22-A127-B2(2ABAB19-2B)2ABA2B18-2B4-2B17-AB6-B16-BA8-2B14-B9-2B13-2B10-2B11-AB12-2B10-A14-B9-2(2A14-AB8-)2A15-BA7-2(A16-BA6-B)3(A16-2B6-B)2A14-A2B6-B2A14-3B7-2A14-BA9-AB12-2B11-2B10-2B13-BA8-B16-2A6-2B16-2A2(2BA)2B17-2(A2B)2A20-BA-B98-B6-B17-B7-2B2(16-B8-B)15-2B8-B14-2B10-2A12-B12-A11-2B12-2A9-2(2B14-2A8-)2B15-2A6-2B16-2A6-BA16-2A2(6-B18-A)6-B18-BA5-B18-B5-2BA17-BA5-B18-B6-BA16-2B6-BA16-2A7-2A14-BA9-AB12-2B11-B11-2A13-B10-A13-2B2AB4-4A14-B2A2B5A2B15-2A2B2(2AB)145-B10-A14-B10-A13-B11-A12-2B12-A11-B13-2A9-2B14-A9-B16-A7-2(2B16-2A6-)B2(18-2A4-2B)19-A4-2B18-2A4-2B19-A4-2B18-3A3-2B19-A2(4-2B18-2A)4-2BA16-A2B5-BA16-AB7-2A14-2A9-A13-AB11-2B10-2AB10-A-BA8-3AB11-2B2A2B5A2BA13-B2AB-2AB2A2B17-2B2ABA120-5(B12-)B11-A14-B9-2A14-B9-A16-B7-2A16-2B6-A17-2B5-2A18-AB4-2B18-AB4-2A18-AB4-A20-B3-4(2A20-AB2-)2A20-AB3-2A18-2A4-2B18-2B5-B18-B6-BA16-AB7-2A14-B10-A13-AB10-3A10-2AB10-3A10-B2A11-4A2B2-B2A2BA14-2A2B2(2AB)131-B11-B13-B11-B14-B10-A14-2B8-A16-B7-A17-2B6-A18-B5-2A18-BA2(4-A20-B)3-2A20-B3-BA20-BA2-2A3(20-AB2-BA)21-2(B2-BA20-A)B3-2B18-2A4-2B18-2A5-B18-B7-A16-B8-A15-2A8-4A10-4A8-5A8-2B2AB10-4A-B3A-A2BA14-2A2B5A2B19-A-B120-B14-A9-B15-A9-B16-A25-A26-A5-2B18-2A4-B19-2A4-B20-A3-2(2A20-2A2-)B22-A2-A22-A2-B22-A-ABA21-2A-2(B22-A2-)BA20-AB2-2B20-A4-B19-2A5-B18-A7-A16-B7-A-A14-A-A6-A2B14-3A7-3B12-2AB9-4A8-2B2A11-3BA-B5A2BA16-2B2A2B267-A4-B20-A3-B2(21-2A2-A)22-A2-B22-4A22-3AB22-2A2B2(22-3AB)22-2A-BA20-ABA-2B20-AB3-B20-A4-2B18-2A5-B18-B6-2A16-2A6-A2B14-3A6-A4B10-B-A2B8-4A8-2B2A12-2B8A2BA15-A2B2A2BA347-2(A23-A-)AB22-3AB22-2A2B2(22-3AB)22-2A-BA21-BA-B22-B2-AB20-2A3-B20-A5-B18-B6-2A17-A6-A2B14-3A7-3B12-2A2B8-3A2-A7-B2A12-2B6A-A2B16-A2B2A2BA373-A2(24-2A)B22-2A2B22-3A23-3AB22-2A2B22-B2-B22-B2-AB20-2A3-B20-A4-2B18-B6-BA16-3A5-3B15-2A6-A3B12-2A2B8-2A-A9-B2A12-2B8A2BA14-2(2A2B)2A346-A24-2A24-ABA23-3A22-2ABA22-4A23-3A22-2A2B22-BA-B22-B2-AB20-BA3-2(B20-B4-)2B18-AB5-2B16-2AB5-A4B11-2A2B9-2A10-B2A12-2B8A2B16-A2B2A2BA319-B25-B-2(BA22-4A22-2A)BA2(22-AB2A)22-A2BA22-A2B2A21-AB-2A20-BA3-AB19-BA3-AB18-ABA3-2BA16-BAB5-2B16-BA7-3B12-A2B10-3A6-A-2BAB12-2B8A2B16-A2B2A2BA22-A222-A50-B22-B-2B22-3BA22-AB2A22-2ABA22-4A22-2ABA22-AB2A22-AB-A22-B2-BA21-AB-2A20-BA2-2A20-BA3-A20-B4-AB18-ABA3-2BA16-BAB5-3B14-2BA7-3B11-BA2B10-4A-2A-2BA-BA13-2B5A2BA2B16-A2B2A2BA219-B25-B20-B3-2B20-B3-B21-2B-2B22-B-2B22-2B2A22-BA2B22-B2AB22-BA2B22-AB-A22-A-2A22-AB-BA20-2A2-2A20-BA3-A20-2(B4-AB18-A)B4-2BA16-BAB5-3B14-2BA6-A-3B10-BA2BA9-4A-3AB-A-BA14-B5A2BAB18-2B2A2B348-2B22-B2-A22-B-2B22-B-AB22-BA-B22-B2(2-2A21-A)2-2A20-2A3-A20-2(B4-AB18-A)B4-2B18-AB5-B2A15-BAB5-A2B14-2BA8-3BA8-2BAB12-7A2BA2B15-B2A-2A2BA-B18-B2AB350-2(B22-B2-)B22-B-2B22-BA3B20-2AB-2A2(20-2A2-AB)20-2A3-2B18-AB5-B18-AB4-ABA16-BAB4-2B2A15-BAB5-B2A14-2BA6-A3B12-A2BA10-BA8-2BAB12-2AB4A2BA2B16-B-B2A2-A20-B2-B424-B2-ABA20-2BA-BA20-2A2-B2A18-3A2-3B18-3A3-2B18-2A4-2B18-AB5-B17-BAB5-2A16-BAB5-2A15-2BA6-4A12-A2BA9-2B11-AB12-2(BA)-2A3-2B16-B4A2BAB17-B-B2AB24-A429-B21-2B2-BA20-2B3-A20-B4-B20-B4-2B18-2B4-3B16-A2B5-B18-AB5-A-A15-BAB6-B2A12-A2BA7-B3A10-2A2B10-2BA9-2A13-BAB4A-2A2B16-B4A2BA20-B2A2B454-3(A20-B4-)2(2B18-2B4-)B-B16-A-B5-2B15-2BAB6-B-A13-2BA7-B2A12-A2BA8-3A10-2AB11-2B2A6-4A14-ABA3B3A2B15-A-A5BA20-5B533-2(A18-B6-)ABA15-2B7-BA13-3B8-B2A12-A2BA8-3A10-2AB-A8-5A6-A-2A2B11-B2A-A2-A-4A14-ABA3B3A2B17-A5BA21-3B561-B25-BA15-B9-2A11-4B9-A13-A2B9-3A10-2A2B10-4A6-4AB11-6A2-6A15-BA3B3A-B19-2B25-B589-A11-B-2B10-AB11-3B10-AB12-2A11-B11-3A12-B-3A2-3A-2A13-BA-3A-6A16-A3B2A2-2A17-5B23-B602-2B12-2B2A6-A3B12-2B3A4-2A-2A12-2B-2A4-2A-3A12-B-A5-2A-A15-3A3(-2A)14-3A3B3A-2A15-2A-4B23-B575-B17-A2-2B2-AB15-A-AB-2B2A2-B15-2AB-2B-3A2B13-4A-A2-3A2B14-4A2(2-A)-BA13-4A-2A2-A-B15-2AB-BA2-AB18-3B3-A21-B571-4B20-7B18-4B2-2B17-B-6B-B16-2(B-)2A-2AB15-A-2B6A2B17-BA-4A2B17-3B4A2B18-2B4A22-A596-2B-B22-5B19-B3A-2A18-B-4A-2A16-B2-7A16-B2-6A17-B2-2B4A21-B3A672-2AB2A19-BA2BABA19-BA2B3A19-B-2B3A19-B2-2ABA23-ABA724-B3A20-A-BAB21-A117-
