model
size = 20 12 31, scale = 0.05, origin = -y
material 
  colors = A:#731251 B:#191919 C:#E824A4 D:#FFF E:#FC0
voxels
------CCCCCCCC------ -------------------- -------------------- -------------------- -------------------- -------------------- -------------------- -------------------- -------------------- -------------------- -------------------- -------------------- 
----CCCAAAAAACCC---- -------BBBBBB------- -------------------- -------------------- -------------------- -------------------- -------------------- -------------------- -------------------- -------------------- -------------------- -------------------- 
---CCAAAAAAAAAACC--- -----BBBBBBBBBB----- -------------------- -------------------- -------------------- -------------------- -------------------- -------------------- -------------------- -------------------- -------------------- -------------------- 
--CCAAAAAAAAAAAACC-- ----BBBBBBBBBBBB---- -------------------- -------------------- -------------------- -------------------- -------------------- -------------------- -------------------- -------------------- -------------------- -------------------- 
--CAAAAAAAAAAAAAAC-- ---BCCCCCBCBCBBBB--- -------------------- -------------------- -------------------- -------------------- -------------------- -------------------- -------------------- -------------------- -------------------- -------------------- 
--CAAAAAAAAAAAAAAC-- ---BCBCBCBCBCBBBB--- -------------------- -------------------- -------------------- -------------------- -------------------- -------------------- -------------------- -------------------- -------------------- -------------------- 
-CCAAAAAAAAAAAAAACC- ---BCBCBCBCBCCCCB--- -------------------- -------------------- -------------------- -------------------- -------------------- -------------------- -------------------- -------------------- -------------------- -------------------- 
-CAAAAAAAAAAAAAAAAC- --BBCBCBCBCBCBBCBB-- -------------------- -------------------- -------------------- -------------------- -------------------- -------------------- -------------------- -------------------- -------------------- -------------------- 
-CAAAAAAAAAAAAAAAAC- --BBCBBBCBCBCBBCBB-- -------------------- -------------------- -------------------- -------------------- -------------------- -------------------- -------------------- -------------------- -------------------- -------------------- 
-CAAAAAAAAAAAAAAAAC- --BBCBBBCBCBCCCCBB-- -------------------- -------------------- -------------------- -------------------- -------------------- -------------------- -------------------- -------------------- -------------------- -------------------- 
-CAAAAAAAAAAAAAAAAC- --BBBBBBBBBBBBBBBB-- -------------------- -------------------- -------------------- -------------------- -------------------- -------------------- -------------------- -------------------- -------------------- -------------------- 
-CAAAAAAAAAAAAAAAAC- --BBBBBBBBBBBBBBBB-- -------BBBBBB------- --------BBBB-------- -------------------- -------------------- -------------------- -------------------- -------------------- -------------------- -------------------- -------------------- 
-CAAAAA------AAAAAC- --BBBBBAAAAAABBBBB-- -----BBAAAAAABB----- -----BBBAAAABBB----- ------BBBBBBBB------ -------BBBBBB------- -------------------- -------------------- -------------------- -------------------- -------------------- -------------------- 
-CAAA----------AAAC- --BBBAA------AABBB-- ----BAA------AAB---- ----BAAA----AAAB---- ----BBAAAAAAAABB---- -----BBAAAAAABB----- ------BBBBBBBB------ ---------BB--------- -------------------- -------------------- -------------------- -------------------- 
-CA--------------AC- --BAA----------AAB-- ---BA----------AB--- ---BA----------AB--- ---BAA--------AAB--- ----BAA------AAB---- -----BAAAAAAAAB----- ------BBBAABBB------ ---------BB--------- -------------------- -------------------- -------------------- 
-CA--------------AC- --BA------------AB-- --BA------------AB-- --BA------------AB-- --BA------------AB-- ---BA----------AB--- ----BA--------AB---- -----BAAAAAAAAB----- ------BBBBBBBB------ -------------------- -------------------- -------------------- 
-CA--------------AC- -BA--------------AB- -BA--------------AB- -BA--------------AB- --BA------------AB-- --BA------------AB-- ---BA----------AB--- ----BAA------AAB---- -----BBAAAAAABB----- -------BBBBBB------- -------------------- -------------------- 
-CA--------------AC- -BA--------------AB- -BA--------------AB- -BA--------------AB- -BA--------------AB- --BA------------AB-- --BA------------AB-- ---BAA--------AAB--- ----BBAAAAAAAABB---- ------BBBBBBBB------ -------------------- -------------------- 
CA----------------AC CA----------------AC CA----------------AC -CA--------------AC- -CA--------------AC- -CA--------------AC- --BA------------AB-- ---BA----------AB--- ----BAAA----AAAB---- -----BBBAAAABBB----- --------BBBB-------- -------------------- 
DA----------------AD DA----------------AD DA----------------AD DA----------------AD -DA--------------AD- -CA--------------AC- --BA------------AB-- ---BA----------AB--- ----BAA------AAB---- -----BBAAAAAABB----- -------BBBBBB------- -------------------- 
DA----------------AD DA----------------AD DA----------------AD DA----------------AD -DA--------------AD- -CA--------------AC- --BA------------AB-- --BAA----------AAB-- ---BBAA------AABB--- -----BBAAAAAABB----- -------BBBBBB------- ---------CC--------- 
DA----------------AD DA----------------AD DA----------------AD DA----------------AD -DA--------------AD- -CA--------------AC- --BA------------AB-- --BAA----------AAB-- ---BBAA------AABB--- -----BBAAAAAABB----- -------BBBBBB------- ---------CC--------- 
DA----------------AD DA----------------AD DA----------------AD DA----------------AD -DA--------------AD- -CA--------------AC- --BA------------AB-- ---BA----------AB--- ----BAA------AAB---- -----BBAAAAAABB----- -------BBBBBB------- -------------------- 
CA----------------AC CA----------------AC CA----------------AC -CA--------------AC- -CA--------------AC- -CA--------------AC- --BA------------AB-- ---BA----------AB--- ----BAAA----AAAB---- -----BBBAAAABBB----- --------BBBB-------- -------------------- 
-CA--------------AC- -BA--------------AB- -BA--------------AB- -BA--------------AB- -BA--------------AB- --BA------------AB-- --BA------------AB-- ---BAA--------AAB--- ----BBAAAAAAAABB---- ------BBBBBBBB------ -------------------- -------------------- 
-CA--------------AC- -BA--------------AB- -BA--------------AB- -BA--------------AB- --BA------------AB-- --BA------------AB-- ---BA----------AB--- ----BAA------AAB---- -----BBAAAAAABB----- -------BBBBBB------- -------------------- -------------------- 
--CA------------AC-- --BA------------AB-- --BA------------AB-- --BA------------AB-- --BA------------AB-- ---BA----------AB--- ----BA--------AB---- -----BAAAAAAAAB----- ------BBBBBBBB------ -------------------- -------------------- -------------------- 
--CAA----------AAC-- --BAA----------AAB-- ---BA----------AB--- ---BA----------AB--- ---BAA--------AAB--- ----BAA------AAB---- -----BAAAAAAAAB----- ------BBBAABBB------ ---------BB--------- -------------------- -------------------- -------------------- 
---CCAA------AACC--- ---BBAA------AABB--- ----BAA------AAB---- ----BAAAAAAAAAAB---- ----BBAAAAAAAABB---- -----BCAAAAAACB----- ------CCCCCCCC------ ---------BB--------- -------------------- -------------------- -------------------- -------------------- 
-----CC------CC----- -----BC------CB----- -----BC------CB----- -----BCDDDDDDCB----- ------CDDDDDDC------ -------DDDDDD------- -------------------- -------------------- -------------------- -------------------- -------------------- -------------------- 
-------CECCCC------- -------------------- -------------------- -------------------- -------------------- -------------------- -------------------- -------------------- -------------------- -------------------- -------------------- -------------------- 
