model
size = 26 32 25, scale = 0.05, origin = -y
material 
  colors = A:#777 B:#FFB11B C:#222 D:#444 E:#555 F:#FCFAF2 G:#8A6BBE
voxels
-4(C25-)2(B25-)B675-C14-4(C25-)2(B25-)B660-C14-C595-D25-A22-4A20-3D23-3D119-C4-C9-C15-3(C25-)2(B25-)B464-2(12B14-)12B20-3D119-C4-C9-C609-3(13B13-)B10A15-B53-9A16-10A14-3(C4-)C20-3(C25-)2(B25-)B434-9E14-3(14B12-)B12AD12-2B-8A-2D15-8A18-10A14-3A6E3A13-3(C4-)C182-B3C21-2B2-2C19-2B4-2C17-2B6-3(2C25-)7(C25-)C16-10C5-7C4-C13-9E3-C3(10-14B2D)11-12A2D13-10A2D14-10A15-12A14-2A2E4D2E2A13-3(C4-)C535-G3-G20-2C3-2C18-3E3F3E14-3(14B2D10-)D12A-D11-2D10A16-10A15-12A14-A2E2D2C2D2EA13-3(C4-)C560-2C3-2C18-3E3F3E14-3(14B12-)D12A13-2D10A16-10A15-12A14-AE2D4C2DEA13-3(C4-)C535-G3-G20-2C3-2C18-3E3F3E14-3(14B12-)D12A13-2D10A16-10A15-12A14-AED6CDEA13-3(C4-)C504-2(C25-)C3-7C15-2(C2-9E14-)C13B2E9-3D12B2E9-2D12A15-10A16-10A15-12A14-AED6CDEA13-3(C4-)C504-C14-2(C25-)2(C13-9E3-)C10-14B-CD9-14B-ED9-D12A2-E10-2(D-10A14-)D12A14-AE2D4C2DEA13-3(C4-)C504-C14-C114-2(14B12-)D12A13-2(D-10A14-)D12A14-A2E2D2C2D2EA13-3(C4-)C504-C4-C9-C15-3(C25-)C20-5BC8BA11-14BD12-12A2D13-10A3D13-10AD14-12A14-2A2E4D2E2A13-3(C4-)C504-C4-C9-C114-14B12-14B13-12A15-10A16-10AD14-12A14-3A6E3A13-3(C4-)C504-3(C4-)C20-3(C25-)C15-10BC3B12-14B13-11A2(17-9A)D16-9A17-2A5E2A14-3(C4-)C504-3(C4-)C114-14B12-14B16-8A18-3D2-2D19-3D22-9A17-9A14-3(C4-)C504-3(C4-)C114-14B12-14B17-D3-2D19-3D2-2D19-3D23-3D45-3(C4-)C504-3(C4-)C119-3(D3-2D20-)D3-2D93-3(C4-)C10-19(C25-)3(C4-)C301-2(C4-)19(C25-)C15-2(C4-)C301-C4-C514-C4-C306-C4-C20-19(C25-)C4-C311-C519-C311-20(C25-)C300-
