model
size = 18 31 6, scale = 0.05, origin = -y
material 
  colors = A:#FBE251 B:#E16B8C C:#2EA9DF D:#FCFAF2 E:#E9A368 F:#E9CD4C
voxels
------------------ ------------------ ------------------ ------------------ ------------------ ------------------ ------------------ ------------------ ------------------ ------------------ ------------------ ------------------ ------------------ ------------------ --------BBBB------ ------BB----B----- ----BB-------B---- ---B----BBB--B---- ---B--BB---B--B--- --B--B-----B--B--- --B--B--BB--B--B-- --B--B--BB--B--B-- ---B--B---B--B-B-- ---B--B---B--B--B- ----B--BBB---B--B- ----B------BB--B-- -----B---BB---B--- ------BBB----B---- -----------BB----- -------BBBB------- ------------------ 
------------------ ------------------ ------------------ ------------------ ------------------ ------------------ ------------------ ------------------ ------------------ ------------------ ------------------ --------A--------- -------AAAA------- -----AAACCCCA----- ----AACCDDAACA---- ---ACCAAAAAAACA--- ---CAAAACCCAAAA--- --CAAACCDDACAACA-- -ACAACAAAAAACAACA- -CAACAAACCAACAACA- -CAACAACDDCAACADA- -CAACAACAACAACADA- -ACAACAACCACAACDA- -ACAACAAAAACAACAF- --ACAACAAACAAACAA- ---CAAACCCAAACAA-- ----CAAAAAACCAA--- -----CAAACCAAA---- ------CCCAAAA----- -------AAAAA------ ------------------ 
--------EE-------- --------EE-------- --------EE-------- --------EE-------- --------EE-------- --------EE-------- --------EE-------- --------EE-------- --------EE-------- --------EA-------- --------EA-------- --------EA-------- -----AAADDAAA----- ----AAAADDAAAA---- ---AAAAADDAAAAA--- --AAAAAADDAAAAAA-- -AAAAAAADDAAAAAAA- -AAAAAAADDAAAAAAA- AAAAAAAADDAAAAAAAA AAAAAAAADDAAAAAAAA AAAAAAAADDAAAAADAA AAAAAAAAAAAAAAADAA AAAAAAAAAAAAAAAAAA AAAAAAAAAAAAAAAAAA -AAAAA-AAAA-AAAAA- -AAAAAAAAAAAAAAAA- --AAAAAAAAAAAAAA-- ---AAAAAAAAAAAA--- ----AAAAAAAAAA---- -----AAAAAAAA----- -------AAAA------- 
--------EE-------- --------EE-------- --------EE-------- --------EE-------- --------EE-------- --------EE-------- --------EE-------- --------EE-------- -------AEE-------- -------AEE-------- -------AEE-------- -------AEE-------- -----AAADDAAA----- ----AAAADDAAAA---- ---AAAAADDAAAAA--- --AAAAAADDAAAAAA-- -AAAAAAADDAAAAAAA- -AAAAAAADDAAAAAAA- AAAAAAAADDAAAAAAAA AAAAAAAADDAAAAAAAA AAAAAAAADDAAAAADAA AAAAAAAAAAAAAAADAA AAAAAAAAAAAAAAAAAA AAAAAAAAAAAAAAAAAA -AAAAA-AAAA-AAAAA- -AAAAAAAAAAAAAAAA- --AAAAAAAAAAAAAA-- ---AAAAAAAAAAAA--- ----AAAAAAAAAA---- -----AAAAAAAA----- -------AAAA------- 
------------------ ------------------ ------------------ ------------------ ------------------ ------------------ ------------------ ------------------ ------------------ ------------------ ------------------ --------A--------- -------AAAA------- -----AAACCCCA----- ----AACCDDAACA---- ---ACCAAAAAAACA--- ---CAAAACCCAAAA--- --CAAACCDDACAACA-- -ACAACAAAAAACAACA- -CAACAAACCAACAACA- -CAACAACDDCAACADA- -CAACAACAACAACADA- -ACAACAACCACAACDA- -ACAACAAAAACAACAF- --ACAACAAACAAACAA- ---CAAACCCAAACAA-- ----CAAAAAACCAA--- -----CAAACCAAA---- ------CCCAAAA----- -------AAAAA------ ------------------ 
------------------ ------------------ ------------------ ------------------ ------------------ ------------------ ------------------ ------------------ ------------------ ------------------ ------------------ ------------------ ------------------ ------------------ --------BBBB------ ------BB----B----- ----BB-------B---- ---B----BBB--B---- ---B--BB---B--B--- --B--B-----B--B--- --B--B--BB--B--B-- --B--B--BB--B--B-- ---B--B---B--B-B-- ---B--B---B--B--B- ----B--BBB---B--B- ----B------BB--B-- -----B---BB---B--- ------BBB----B---- -----------BB----- -------BBBB------- ------------------ 
