model
size = 23, scale = 0.05, origin = -y
material 
  colors = A:#400 B:#500 C:#700 D:#800 E:#A00 F:#B00 G:#D00 H:#E00 I:#200 J:#F39
voxels
--------IIIIIII-------- ----------------------- ----------------------- ----------------------- ----------------------- ----------------------- ----------------------- ----------------------- ----------------------- ----------------------- ----------------------- ----------------------- ----------------------- ----------------------- ----------------------- ----------------------- ----------------------- ----------------------- ----------------------- ----------------------- ----------------------- ----------------------- ----------------------- 
------IIAAAAAAAII------ --------AAAAAAA-------- ----------------------- ----------------------- ----------------------- ----------------------- ----------------------- ----------------------- ----------------------- ----------------------- ----------------------- ----------------------- ----------------------- ----------------------- ----------------------- ----------------------- ----------------------- ----------------------- ----------------------- ----------------------- ----------------------- ----------------------- ----------------------- 
----IIAABBBBBBBAAII---- ------AAAAAAAAAAA------ --------BBBBBBB-------- ----------------------- ----------------------- ----------------------- ----------------------- ----------------------- ----------------------- ----------------------- ----------------------- ----------------------- ----------------------- ----------------------- ----------------------- ----------------------- ----------------------- ----------------------- ----------------------- ----------------------- ----------------------- ----------------------- ----------------------- 
---IIABBBCCCCCBBBAII--- -----AAAAAAAAAAAAA----- ------BBBBBBBBBBB------ ---------CCCCC--------- ----------------------- ----------------------- ----------------------- ----------------------- ----------------------- ----------------------- ----------------------- ----------------------- ----------------------- ----------------------- ----------------------- ----------------------- ----------------------- ----------------------- ----------------------- ----------------------- ----------------------- ----------------------- ----------------------- 
--IIABBCCDDDDDCCBBAII-- ----AAAAAAAAAAAAAAA---- -----BBBBBBBBBBBBB----- -------CCCCCCCCC------- ---------DDDDD--------- ----------------------- ----------------------- ----------------------- ----------------------- ----------------------- ----------------------- ----------------------- ----------------------- ----------------------- ----------------------- ----------------------- ----------------------- ----------------------- ----------------------- ----------------------- ----------------------- ----------------------- ----------------------- 
--IABCCDDEEEEEDDCCBAI-- ---AAAAAAAAAAAAAAAAA--- ----BBBBBBBBBBBBBBB---- -----CCCCCCCCCCCCC----- -------DDDDDDDDD------- ---------EEEEE--------- ----------------------- ----------------------- ----------------------- ----------------------- ----------------------- ----------------------- ----------------------- ----------------------- ----------------------- ----------------------- ----------------------- ----------------------- ----------------------- ----------------------- ----------------------- ----------------------- ----------------------- 
-IABBCDEEFFFFFEEDCBBAI- --AAAAAAAAAAAAAAAAAAA-- ---BBBBBBBBBBBBBBBBB--- -----CCCCCCCCCCCCC----- ------DDDDDDDDDDD------ -------EEEEEEEEE------- ---------FFFFF--------- ----------------------- ----------------------- ----------------------- ----------------------- ----------------------- ----------------------- ----------------------- ----------------------- ----------------------- ----------------------- ----------------------- ----------------------- ----------------------- ----------------------- ----------------------- ----------------------- 
-IABCDEEFGGGGGFEEDCBAI- --AAAAAAAAAAAAAAAAAAA-- ---BBBBBBBBBBBBBBBBB--- ----CCCCCCCCCCCCCCC---- -----DDDDDDDDDDDDD----- ------EEEEEEEEEEE------ --------FFFFFFF-------- ---------GGGGG--------- ----------------------- ----------------------- ----------------------- ----------------------- ----------------------- ----------------------- ----------------------- ----------------------- ----------------------- ----------------------- ----------------------- ----------------------- ----------------------- ----------------------- ----------------------- 
IABBCDEFHHHHHHHFEDCBBAI -AAAAAAAAAAAAAAAAAAAAA- --BBBBBBBBBBBBBBBBBBB-- ----CCCCCCCCCCCCCCC---- -----DDDDDDDDDDDDD----- ------EEEEEEEEEEE------ -------FFFFFFFFF------- --------GGGGGGG-------- --------HHHHHHH-------- ----------------------- ----------------------- ----------------------- ----------------------- ----------------------- ----------------------- ----------------------- ----------------------- ----------------------- ----------------------- ----------------------- ----------------------- ----------------------- ----------------------- 
IABCDEFGHHHHHHHGFEDCBAI -AAAAAAAAAAAAAAAAAAAAA- --BBBBBBBBBBBBBBBBBBB-- ---CCCCCCCCCCCCCCCCC--- ----DDDDDDDDDDDDDDD---- -----EEEEEEEEEEEEE----- ------FFFFFFFFFFF------ -------GGGGGGGGG------- --------H-----H-------- ----------------------- ----------------------- ----------------------- ----------------------- ----------------------- ----------------------- ----------------------- ----------------------- ----------------------- ----------------------- ----------------------- ----------------------- ----------------------- ----------------------- 
IABCDEFGHHHHHHHGFEDCBAI -AAAAAAAAAAAAAAAAAAAAA- --BBBBBBBBBBBBBBBBBBB-- ---CCCCCCCCCCCCCCCCC--- ----DDDDDDDDDDDDDDD---- -----EEEEEEEEEEEEE----- ------FFFFFFFFFFF------ -------GGGGGGGGG------- --------H-HHH-H-------- ----------------------- ----------------------- ----------------------- ----------------------- ----------------------- ----------------------- ----------------------- ----------------------- ----------------------- ----------------------- ----------------------- ----------------------- ----------------------- ----------------------- 
IABCDEFGHHHHHHHGFEDCBAI -AAAAAAAAAAJAAAAAAAAAA- --BBBBBBBBBCBBBBBBBBB-- ---CCCCCCCCDCCCCCCCC--- ----DDDDDDDEDDDDDDD---- -----EEEEEEFEEEEEE----- ------FFFFFGFFFFF------ -------GGGGHGGGG------- --------H-H-H-H-------- -----------I----------- -----------I----------- -----------A----------- -----------A----------- -----------B----------- -----------B----------- -----------C----------- ------CCCCCCCCCCC------ -----------D----------- --------EEEEEEE-------- --------F-----F-------- --------GGGGGGG-------- --------H-----H-------- --------HHHHHHH-------- 
IABCDEFGHHHHHHHGFEDCBAI -AAAAAAAAAAAAAAAAAAAAA- --BBBBBBBBBBBBBBBBBBB-- ---CCCCCCCCCCCCCCCCC--- ----DDDDDDDDDDDDDDD---- -----EEEEEEEEEEEEE----- ------FFFFFFFFFFF------ -------GGGGGGGGG------- --------H-HHH-H-------- ----------------------- ----------------------- ----------------------- ----------------------- ----------------------- ----------------------- ----------------------- ----------------------- ----------------------- ----------------------- ----------------------- ----------------------- ----------------------- ----------------------- 
IABCDEFGHHHHHHHGFEDCBAI -AAAAAAAAAAAAAAAAAAAAA- --BBBBBBBBBBBBBBBBBBB-- ---CCCCCCCCCCCCCCCCC--- ----DDDDDDDDDDDDDDD---- -----EEEEEEEEEEEEE----- ------FFFFFFFFFFF------ -------GGGGGGGGG------- --------H-----H-------- ----------------------- ----------------------- ----------------------- ----------------------- ----------------------- ----------------------- ----------------------- ----------------------- ----------------------- ----------------------- ----------------------- ----------------------- ----------------------- ----------------------- 
IABBCDEFHHHHHHHFEDCBBAI -AAAAAAAAAAAAAAAAAAAAA- --BBBBBBBBBBBBBBBBBBB-- ----CCCCCCCCCCCCCCC---- -----DDDDDDDDDDDDD----- ------EEEEEEEEEEE------ -------FFFFFFFFF------- --------GGGGGGG-------- --------HHHHHHH-------- ----------------------- ----------------------- ----------------------- ----------------------- ----------------------- ----------------------- ----------------------- ----------------------- ----------------------- ----------------------- ----------------------- ----------------------- ----------------------- ----------------------- 
-IABCDEEFGGGGGFEEDCBAI- --AAAAAAAAAAAAAAAAAAA-- ---BBBBBBBBBBBBBBBBB--- ----CCCCCCCCCCCCCCC---- -----DDDDDDDDDDDDD----- ------EEEEEEEEEEE------ --------FFFFFFF-------- ---------GGGGG--------- ----------------------- ----------------------- ----------------------- ----------------------- ----------------------- ----------------------- ----------------------- ----------------------- ----------------------- ----------------------- ----------------------- ----------------------- ----------------------- ----------------------- ----------------------- 
-IABBCDEEFFFFFEEDCBBAI- --AAAAAAAAAAAAAAAAAAA-- ---BBBBBBBBBBBBBBBBB--- -----CCCCCCCCCCCCC----- ------DDDDDDDDDDD------ -------EEEEEEEEE------- ---------FFFFF--------- ----------------------- ----------------------- ----------------------- ----------------------- ----------------------- ----------------------- ----------------------- ----------------------- ----------------------- ----------------------- ----------------------- ----------------------- ----------------------- ----------------------- ----------------------- ----------------------- 
--IABCCDDEEEEEDDCCBAI-- ---AAAAAAAAAAAAAAAAA--- ----BBBBBBBBBBBBBBB---- -----CCCCCCCCCCCCC----- -------DDDDDDDDD------- ---------EEEEE--------- ----------------------- ----------------------- ----------------------- ----------------------- ----------------------- ----------------------- ----------------------- ----------------------- ----------------------- ----------------------- ----------------------- ----------------------- ----------------------- ----------------------- ----------------------- ----------------------- ----------------------- 
--IIABBCCDDDDDCCBBAII-- ----AAAAAAAAAAAAAAA---- -----BBBBBBBBBBBBB----- -------CCCCCCCCC------- ---------DDDDD--------- ----------------------- ----------------------- ----------------------- ----------------------- ----------------------- ----------------------- ----------------------- ----------------------- ----------------------- ----------------------- ----------------------- ----------------------- ----------------------- ----------------------- ----------------------- ----------------------- ----------------------- ----------------------- 
---IIABBBCCCCCBBBAII--- -----AAAAAAAAAAAAA----- ------BBBBBBBBBBB------ ---------CCCCC--------- ----------------------- ----------------------- ----------------------- ----------------------- ----------------------- ----------------------- ----------------------- ----------------------- ----------------------- ----------------------- ----------------------- ----------------------- ----------------------- ----------------------- ----------------------- ----------------------- ----------------------- ----------------------- ----------------------- 
----IIAABBBBBBBAAII---- ------AAAAAAAAAAA------ --------BBBBBBB-------- ----------------------- ----------------------- ----------------------- ----------------------- ----------------------- ----------------------- ----------------------- ----------------------- ----------------------- ----------------------- ----------------------- ----------------------- ----------------------- ----------------------- ----------------------- ----------------------- ----------------------- ----------------------- ----------------------- ----------------------- 
------IIAAAAAAAII------ --------AAAAAAA-------- ----------------------- ----------------------- ----------------------- ----------------------- ----------------------- ----------------------- ----------------------- ----------------------- ----------------------- ----------------------- ----------------------- ----------------------- ----------------------- ----------------------- ----------------------- ----------------------- ----------------------- ----------------------- ----------------------- ----------------------- ----------------------- 
--------IIIIIII-------- ----------------------- ----------------------- ----------------------- ----------------------- ----------------------- ----------------------- ----------------------- ----------------------- ----------------------- ----------------------- ----------------------- ----------------------- ----------------------- ----------------------- ----------------------- ----------------------- ----------------------- ----------------------- ----------------------- ----------------------- ----------------------- ----------------------- 
