model
size = 27 32 17, scale = 0.05, origin = -y
material 
  colors = A:#EEE B:#111
voxels
468-8A18-10A18-8A774-10A16-12A15-2AB6AB2A2(15-12A)343-11(4A23-)4A22-6A20-8A17-12A14-14A13-3A8-3A13-2(2A10-3A12-)14A13-14A14-12A259-2(10A17-)4A2-4A3(17-4A3-3A)18-4(3A2-3A19-)3A2-3A18-2(4A2-4A17-)4A2-5A15-4A4-4A14-4A6-4A12-3A10-3A4(11-2A12-2A)12-2A10-3A12-14A14-13A15-10A203-5A7-4A11-5A7-4A12-2(3A8-3A13-)3A8-3A14-3A7-3A14-3A6-3A15-3A6-3A16-2A6-2A17-2A6-2A16-2(3A7-2A15-)2A8-2A15-2A8-3A13-3A9-2A13-2A10-3A11-2A12-2A3(11-A14-A)11-2A13-A11-2A12-2A11-3A11-2A12-3A8-4A12-6A2-6A14-13A15-4A3-3A20-A3-A124-2A13-A10-3A2(12-3A10-2A)12-2A11-3A11-2A12-2A10-3A12-2A10-2A13-3A2(9-2A14-2A)9-2A13-3A9-3(2A13-2A10-)2A13-2(2A11-)2A12-2A11-2A13-A11-4(A14-2A10-)A14-A11-2A13-A11-2A12-2A2(11-3A)10-4A8-5A10-5A5-7A11-6A3-5A16-A7-A121-2A15-2A8-2A14-2A9-2A14-2A10-2A13-2A10-2A12-2A11-2(2A12-)4(2A11-A13-)A12-A13-A3(12-2A11-2A)13-2(A11-A14-)2A2(10-A15-A)10-A14-2A10-A14-A11-A14-2A8-3A2(14-4A5-4A)15-3A5-5A12-5A6-6A8-7A8-5A7-5A13-A9-A92-2A16-2A8-A16-2A8-2A15-A9-2A14-2A10-A14-2A10-2A12-2A11-2(2A12-)A12-2A2(12-A)13-A12-A13-A2(12-2A11-2A)13-3(A11-A14-)2A10-A14-2A2(10-A15-A)10-A14-3A7-3A14-4A4-5A14-5A3-5A15-4A3-3A19-2A3-2A20-2A3-3A19-2A4-4A15-4A4-6A10-6A7-6A8-5A11-3A74-2A17-A8-A16-2A8-A16-A9-2A15-A10-A14-2A10-A14-A11-2A13-A4(11-2A12-2A)11-2A13-3(A11-A14-)2A10-A14-2A4(10-A15-A)2(9-2A14-2A)2-2A-2A3-A18-2A-2A22-2A2-A22-2A2-2A21-A3-2A20-2A4-3A17-3A4-6A10-6A7-5A9-4A35-2A25-2A17-A8-A16-2A8-A16-A9-2A15-A10-A14-2A10-A14-A11-2A13-A4(11-2A12-2A)11-2A13-4(A11-A14-)2A10-A14-2A2(10-A15-A)3(10-A14-2A)3-A-A4-A19-4A23-4A22-2A2-A22-2A2-2A21-A3-2A20-2A4-3A16-3A7-5A10-3A12-2A22-A26-2(A16-2A8-)2A15-A9-2A14-2A10-A14-2A10-2A13-A11-2(2A12-)3(A12-2A12-)A3(12-2A11-2A)13-3(A11-A14-)5(2A10-A14-)A4-A-A3-2A19-4A23-4A22-2A2-A22-2A2-2A21-A3-3A19-2A4-3A16-3A7-5A9-4A12-2A9-A12-A26-2A15-A2(9-2A14-2A)10-2A13-2A10-2A12-2A11-2(2A12-)A2(12-2A)4(10-2A13-2A)11-A13-A4(12-2A11-2A)13-2(A11-A14-)2A10-A14-2A9-2A14-2A2-A6-2A14-2A2-A2(2-2A)14-2A2-2A-2A22-2A2-2A21-2A2-2A20-2A3-3A19-2A4-3A16-4A5-4A12-5A7-18A13-11A12-2A14-A10-2A14-2A10-2A13-2A10-2A12-2A11-2(2A12-)2A10-3A12-2(2A10-2A13-)3A9-2A14-2(2A8-2A15-)2A8-2A14-3A8-3A13-3A9-2(2A13-2A10-)2A13-2(2A11-)3(2A12-2A11-)2A13-3A8-2A14-4A5-4A14-5A3-5A14-5A3-4A17-3A3-3A18-3A4-2A18-3A4-3A16-3A6-4A12-5A7-18A11-14A39-2(2A12-2A11-)3A11-2A12-2A10-3A12-3A8-3A13-4A6-4A14-3A6-3A15-8A-3A15-12A16-3(10A17-)10A16-5A3-4A15-4A5-3A15-3A6-4A2(13-3A8-3A)13-2A10-2A13-2A10-2(3A11-)2(2A11-2A12-)2A9-4A12-4A7-4A13-4A6-3A14-4A6-4A13-3A7-6A2-4A2-6A8-18A11-14A67-2(2A10-3A12-)3A8-3A14-13A14-12A16-10A18-8A19-8A103-2A24-5A21-7A19-8A18-10A17-10A16-2(12A15-)4A4-5A13-4A6-4A2(13-3A8-3A)13-3A8-4A3(11-16A)12-15A14-4A2-4A97-13A14-12A15-12A16-10A397-6A20-8A18-4(10A17-)10A207-8A19-8A820-
