model
size = 32 32 29, scale = 0.05, origin = -y
material 
  colors = A:#4B3C00 B:#121327 C:#F8D92C D:#CFA604 E:#FFF950 F:#BB8900 G:#7A5E13 H:#DFB419 I:#E2B919 J:#FFF
voxels
11-JEC4-CEJ1012-CE10-EC20-EJEC2-CEJE979-2C12-2C18-CE3B2-3BEC22-EJE2CEJE347-CE2(30-2E30-2C)3(30-2E)30-JE30-EJ310-C16-C15-I2C4B2-4B2CI19-2CE4IE2C25-4E221-2C30-2C29-CE2C28-C2AC27-2(2C2A2C26-)EC2ACE25-2CE2AE2C24-2EC2AC2E24-2CE2AE2C24-ECE2AECE24-C2E2A2EC24-ECE2AECE24-3EJ4E27-EJ245-2H5-B4-B5-2H13-2I6B2-6B2I16-2C10B2C20-3C4I3C23-I2C2E2CI123-CI30-IC29-C2AC27-CI2AIC25-CI4AIC23-CIC4ACIC22-IC6ACI2(22-2C6A2C)21-2(2C8A2C20-)CE8AEC20-2C8A2C20-CE8AEC20-EC8ACE20-CJ8AJC20-2EJEC2ACEJ2E25-2E212-2H18-2H11-2H3B10-3B2H14-3H10B3H17-HI10HIH20-I8HI24-FD2FDF26-2DCI2D26-C2ICIC26-HI2AIH25-HCI2AICH24-CI4AIC23-CI6AIC21-CI8AIC19-2H10A2H18-HC10ACH18-CI10AIC17-HIC10ACIH16-2C12A2C15-H2I12A2IH2(14-CIC12ACIC)14-ICI12AICI14-I2C12A2CI14-CIC12ACIC15-CE12AEC17-ECJECE2CECEJCE18-C3EC4-C3EC173-FD20-DF9-FD2B14-2BDF12-H16BH15-16H17-2H10A2H20-FD6ADF22-DC6ACD22-CD6ADC22-CH6AHC21-2H8A2H20-DC8ACD19-2H10A2H17-CH12AHC16-H14AH15-18D14-HC14ACH14-C16AC13-CH16AHC4(12-H18AH)12-C18AC12-H18AH12-HI16AIH12-GHC5AE2AE5ACHG9-ID2-GH4AE-2C-E4AHG2-DI7-ID2-GHC2E6-2ECHG2-DI9-ID18-DI11-2ID14-D2I74-F22-F9-F2B16-2BF11-F3B2-8B2-3BF13-2D14B2D15-2D12B2D18-D10AD20-C10AC20-H10AH19-HD10ADH18-C12AC17-2C12A2C15-2(18D14-)18D13-F18AF12-20D12-H18AH11-2(22D10-)22D11-20D11-2(22D10-)F20AF10-G20AG10-22A7-I10A2C2A2C10AI5-H7A2E-4C-2E7AH6-CH4AGE3-4E3-EG4AHC7-CHIHAG12-GAHIHC12-I14-I44-G22-G9-G2B16-2BG11-F3B12-3BF13-FDB12-BDF15-DA12BAD17-F12AF18-D12AD18-H12AH17-16D16-16D15-F16AF2(14-H16AH)13-20D12-H18AH12-F18AF11-F20DF10-F20AF10-F8A4B8A2(F10-F9A2B9A)F10-F20A2(F10-F9A2B9A)F10-G9A2B9AG10-10A2B10A6-I12A4B12AI3-H9A2CB2-B2C9AH4-C2F5A2E-CB2-BC-2E7AC5-2C4AH3-E4-E3-H4A2C8-C2IAG12-GA2IC13-I14-I12-A22-A8-A3B16-3BA9-A4B12-4BA11-G2DB12-B2DG13-FDB12-BDF15-FD12BDF16-H4D6B4DH16-F4A6B4AF2(16-H4A6B4AH)15-H5A6B5AH14-F5A6B5AF13-F6D6B6DF12-F6A6B6AF11-2(F7A6B7AF10-)G7A6B7AG9-G9A4B9AG8-G8A6B8A3(G8-G9A4B9A)2(G8-G9AB2-B9A)G2(8-10AB2-B10A)4-I13AB2-B13AI-H12AB2-B12AH3-I8AEC2B2-2BCE8AI4-2C6AE-C6-C-E6A2C6-4CAD2-E6-E2-DA4C12-C14-C12-G22-G8-G3B16-3BG9-A4B12-4BA11-3GB12-B2GA13-GDB12-BDG15-2F3B6-3B2F16-D4AB4-B4AD16-D4FB4-B4FD15-2(6FB4-B6F14-)D5AB4-B5AD13-F6AB4-B6AF12-G6AB4-B6AG11-2(G7AB4-B7AG10-)G7AB4-B7AG9-9AB4-B9A2(8-F8AB4-B8AF)8-F8GB4-B9G8-9AB4-B9A9-2(8AB4-B8A10-)6ABAB4-BAB6A2(10-8AB4-B8A)5-I11A2B4-2B11AI-H11AB4-B11AI2-CF9AB6-B10AC3-C7AEC8-CE7AC5-2C2ACAD-C8-C-DAC2A2C8-2E-C2-E8-E2-C-2E9-F22-F8-F2B18-2BF8-G2A3B12-3B2AG9-G4AB10-B4AG12-3AB10-B3A15-DAB10-BAD16-DA3B6-3BAF16-FA3B6-3BAF15-F2A3B6-3B2AF14-F2A3B6-3B2AF13-4A3B6-3B4A12-G3A3B6-3B3AG12-4A3B6-3B4A11-G4A3B6-3B4AG10-F4A-2B6-2B-4AF10-F6AB6-B6AF9-2F6AB6-B6A2F8-D7GB6-B7GD8-F7GB6-B7GF8-2AB5AB6-B5AB2A9-7AB6-B7A11-3(7B6-7B12-)7B6-7B10-9B6-9B4-I3ABA7B6-7BAB3AI-H10AB6-B10AI2-C9A2B6-2B9AC2-C8AB10-B8AC3-CE5ADC10-CD5AEC6-3ECE2-E8-E2-EC3E8-D22-D8-DB20-BD8-F5B12-5BF9-F3AB12-B3AF11-G2AB12-B2AG14-GB12-BG16-AB12-BA16-A2B10-2BA15-GA2B10-2BAG14-GA2B10-2BAG13-GA3B10-3BAG2(12-F2A2B10-2B2AF)11-2F2A2B10-2B2A2F10-F3A3B8-3B3AF10-D2G4B8-4B2GD9-DF2G4B8-4B2GFD8-FG6B8-6BGF8-2A6B8-6B2A11-5B8-5B13-6B8-6B171-B20-B5-CA3BA6B8-6BA3BAC-I9AB8-B9AI2-C9AB8-B9AC3-2E5ADAB8-BAD5A2E6-EJECE-E10-E-ECEJE8-H22-H8-DB20-BD8-2D3B14-3B2D9-D2GB14-B2GD11-FGB14-BGF13-F3(B14-BF14-D)B14-BF13-2DB14-BDF2(12-DGB14-BGD)11-3(2DGB14-BG2D10-)2DGB14-BG2D9-F3GB14-B3GF8-GA2B16-2BAG8-2A3B14-3B2A262-10B8-10B2-C10AB8-B10AC-C9AB8-B9AC3-E6ADAB8-BAD6AE5-2(EJ)CE-E10-E-EC2(JE)7-C22-C8-HB20-BH8-2D2B16-2B2D9-D2FB14-B2FD11-2FB14-B2F13-2(DB14-BD14-)IB14-BI14-HB14-BH13-IDB14-BDI12-HDB14-BDH12-IDB14-BDI11-H2DB14-B2DH10-E2DB14-B2DE10-H2DB14-B2DH9-I2DAB14-BA2DI8-G3AB14-B3AG8-GA2B16-2BAG294-9B10-9B2-C10AB8-B10AC-E9AB8-B9AE3-J6ADAB8-BAD6AJ5-2(EJ)CJ-E10-E-JC2(JE)7-E22-E8-CB20-BC8-CH2B16-2BHC9-H2FB14-B2FH11-HFB14-BFH13-FB14-BF14-HB14-BH2(14-CB14-BC)13-2CB14-B2C12-CHB14-BHC12-EHB14-BHE11-2(2EHB14-BH2E10-)EHAB14-BAHE9-ICHAB14-BAHCI8-GA3B14-3BAG8-GAB18-BAG294-9B10-9B2-C10AB8-B10AC-J9AB8-B9AJ3-E6ADAB8-BAD6AE5-2(JE)CJ-E10-E-JC2(EJ)7-C22-C8-HB20-BH8-2D2B16-2B2D9-D2FB14-B2FD11-2FB14-B2F13-2(DB14-BD14-)HB14-BH14-IB14-BI13-HDB14-BDH12-IDB14-BDI12-HDB14-BDH11-I2DB14-B2DI10-E2DB14-B2DE10-IDAB14-BADI9-H2DAB14-BA2DH8-GA3B14-3BAG8-GAB18-BAG296-7B10-7B4-CA2B7AB8-B7A2BAC-E9AB8-B9AE3-J6ADAB8-BAD6AJ5-2(EJ)CJ-E10-E-JC2(JE)7-H22-H8-DB20-BD8-2D2B16-2B2D9-D2GB14-B2GD11-FGB14-BGF13-F3(B14-BF14-D)B14-BF13-2DB14-BDF2(12-2DB14-B2D)11-2(3DB14-B3D10-)2DAB14-BA2D10-2DAB14-BA2D9-FG3B14-3BGF8-GAB18-BAG8-2A20-2A265-5B12-5B5-CA3B5A2B8-2B5A3BAC-C9AB8-B9AC3-E6ADAB8-BAD6AE5-2(EJ)CE-E10-E-EC2(JE)7-D22-D8-DB20-BD8-F3B16-3BF9-F2GB14-B2GF11-GA2B12-2BAG14-G2B10-2BG16-A3B8-3BA16-G4B6-4BA15-G5B6-5BG14-A5B6-5BA13-GA5B6-5BAG2(12-FA5B6-5BAF)11-2(2FA5B6-5BA2F10-)DFA5B6-5BAFD9-DG7B6-7BGD8-F2B2-3B8-3B2-2BF8-2AB18-B2A260-CA2-9B6-9B2-AC-I2B8AB6-B8A2BI2-C9AB8-B9AC3-2E5ADAB8-BAD5A2E6-EJECE-2E8-2E-ECEJE8-F22-F8-FB20-BF8-G3B16-3BG9-3A2B12-2B3A11-4AB10-B4A14-FA4B4-4BAF16-D3A8B3AF16-F2ABA6BAB2AF15-F4A8B4AF14-F4A8B4AF13-2(7A6B7A12-)G6A6B6AG11-G7A6B7AG2(10-F7A6B7AF)9-2F2AB4A6B4AB2A2F8-D2G2B3G8B3G2B2GD8-FG20BGF8-2A9B2-9B2A169-22B5-IA3-9B4-9B3-AI-H3B7AB6-B7A3BI2(2-C10AB6-B10AC)3-CE5ADCAB6-BACD5AEC6-3ECE2-CE6-EC2-EC3E2(8-A22-A)8-A4B14-4BA9-4A2B10-2B4A11-G3AB10-B3AG14-FA12BAF16-I14AI3(16-F14AF)15-F16AF13-D18AD12-F18AF11-10A2B10A10-G9A2B9AG10-G20AG9-AG20AGA8-FG20AGF8-F22AF8-F10G2B11G8-2A20B2A9-4(A20BA10-)9A4B9A5-I13A4B13AI-H11A6B11AI2-C11A6B11AC3-C10A6B10AC5-2C2ACAD3CB4-B3CDAC2A2C8-2E-I3-2E4-2E3-I-2E9-G22-G8-G22-G9-G4B12-4BG10-GD3AB10-B3ADG12-D2AB10-B2AD15-DA12BAD17-D12AD18-H12AH17-HC12ACH16-2H12A2H15-2H14A2H14-H16AH13-D18AD12-F18AF11-2(D20AD10-)F20AF9-2(2G20A2G8-)6(G22AG8-)24A4-I30AI-H28AH2-C12AB2AB12AC3-2C6A3CA4-A3C6A2C6-4CAD3-6C3-DA4C12-I4-6E4-I12-G22-G8-D22-D9-D-3B12-3B-D11-D3AB10-B3AD13-D2AB10-B2AD15-FA12BAF17-D12BD19-2C2I4A2I2C20-2HCI4AIC2H20-C2I6A2IC19-C2I8A2IC17-2IC10AC2I15-CIC12ACIC13-2H16A2H2(12-D18AD)11-D20AD7(10-F20AF)10-G20AG10-22A6-I28AI3-H26AH4-C26AC5-2C5A2CECJ2CECE2C5A2C8-3CAD12-DA3C13-I14-I12-D22-D9-D20-D11-D3B12-3BD12-D3A12B3AD13-IHA12BAHI16-2(DI)6B2(ID)19-H2(I2D)ID2IH24-I2CI28-C2IC27-CI2CIC25-2C4A2C23-2C6A2C21-2IC6AC2I18-H2CI8AI2CH15-2(CI)10A2(IC)13-HI2C12A2CIH12-CI16AIC11-DH18AHD10-H20AH10-D20AD10-H20AH3(10-F20AF)10-G20AG10-22A7-I26AI5-H24AH6-2CI2HAD3CECEJCE3CDA2HI2C8-2CHAD12-DAH2C13-I14-I44-D22-D9-D20-D11-D-16B-D13-I2F12A2FI15-2I2CH6AH2C2I21-DI2DID155-4C27-ICE2CI26-3CE2C25-CEC2ECEC23-2C6A2C21-2C8A2C18-I2C10A2CI15-HC14ACH13-HCI14AICH12-C2I14A2IC12-IC16ACI12-2I16A2I12-IC16ACI12-FH16AHF12-2G16A2G12-2AGF12AFG2A9-I5AGC10ACG5AI7-3HDAG2CECEJ2ECE2CGAD3H12-I14-I16-I14-I77-D20-D11-IF16-FI13-I2F12B2FI15-I2C10A2CI19-4C2E4C312-2C2E2C25-8C23-2C6A2C20-I2C8A2CI2(18-CE10AEC)17-CEC10ACEC16-2CE10AE2C16-CEC10ACEC16-ICE10AECI16-FIC10ACIF18-ICE6AECI14-4I3-EC2E2J2ECE3-4I11-ID14-DI141-IF16-FI13-C16-C15-3C10-3C19-2C2EJ3E2C408-2C2E2C25-2(2CE)2C23-2CEC2ECE2C22-2(CE)2C2(EC)22-3EC2EC3E22-2(CE)2C2(EC)22-EC6ECE22-C8EC22-4EJ5E24-EJ2EJE212-2C14-2C15-2C12-2C18-2C4EJ3E2C947-3C4EJ3E3C19-3C2EJ3E3C970-
