model
size = 31 32 17, scale = 0.05, origin = -y
material 
  colors = A:#C39 B:#FFF C:#6B0059 D:#FCF E:#F9C F:#F8F8F8 G:#FF53A9 H:#F86ABA I:#FF74CC J:#FCC
voxels
9-13C18-4AE3DE4A18-3AE5BE3A18-2AI7BI2A18-2EF7BFEI4(18-13B)18-5D2(BD)4B18-5A2(DA)D3B18-2(AE)2(AD)A4D18-4(AD)5A18-4(AD)A3EA18-ADE3(DA)3DA18-ADB2(DA)D5A18-E3B2(EB)5E3(18-13B)18-IEF7BFEI17-3AEF5BFE3A15-5AEF3BFE5A14-6A5E6A15-7AC7A17-5AC-C5A202-2C13-2C3(14-2A13-2A)14-GH13-HG14-FB13-BF2(14-2B13-2B)2(14-DB13-2B)2(14-2D13-2B)14-2D13-2(DB14-2DB11-B)DB15-DB11-BD16-F2(A11-2B16-B)A11-AB16-BA11-AB14-2CHA11-AH2C11-4A13-4A2(10-3A15-3A)11-2A15-2(2A13-)2A15-5AC3-C5A16-4AC5-C4A138-C17-C4(12-A17-A)12-I17-I12-F17-F2(12-B17-B)2(12-BA15-AB)12-BA15-AF12-FA15-AF13-B15-F14-B15-B14-D3(A13-2B14-B)A13-AB14-HA13-AG10-3C2-I13-G2-3C3(6-3A19-3A)7-2A19-2A8-4A15-4A9-3A15-3A12-2(A15-)4AC5-C4A106-C19-C5(10-A19-A)10-H19-H10-J19-J10-F19-F11-D17-F12-E17-E12-H17-H12-G17-G12-H17-H12-E17-E13-3(B15-B14-)H15-I14-A15-A9-C4-A15-A4-C2(4-A25-A)4-2A23-2A4-3A21-3A5-3A19-3A6-4A17-4A7-4A15-4A10-2A15-2A14-3AC7-C3A75-C19-C7(10-A19-A)10-G19-G10-GA17-AG2(10-2A17-2A)11-3(A17-A12-)DA15-AF12-FA15-AF13-J15-J14-H15-H14-A15-A8-C5-C15-A5-C2(2-A27-A)2-2A25-2A3-2A23-2A4-3A21-3A4-4A19-4A5-4A17-4A7-4A15-4A11-2A13-2A16-2AC7-C2A45-C19-C14(10-A19-A)11-2(G17-G12-)A17-A12-A17-A13-A15-A8-C5-A15-A5-C3(2-A27-A)2-2A25-2A2-3A23-3A3-3A21-3A4-4A19-4A5-4A17-4A8-3A15-3A2(13-A)17-2C9-2C14-C19-C14(10-A19-A)2(10-2A17-2A)11-2(A17-A12-)2A15-2A6-C6-A15-A6-CA2(28-3A)28-2A-A26-2A2-2A25-2A2-3A23-3A3-3A21-3A5-3A19-3A7-4A15-4A11-2(A15-)2(C13-)C19-C14(10-A19-A)3(10-2A17-2A)11-A17-A12-2A15-2A6-C5-2A15-2A5-CA3(28-3A)28-2A-A26-2A2-2A25-2A3-2A23-2A4-3A21-3A6-2A19-2A10-2A15-2A14-2(C13-)C19-C14(10-A19-A)4(10-2A17-2A)10-3A15-3A5-C5-2A15-2A5-CA4(28-3A)28-2A-A26-2A2-2A25-2A3-2A23-2A5-3A19-3A9-2A15-2A14-2(C13-)C19-C14(10-A19-A)3(10-2A17-2A)11-A17-A12-2A15-2A6-C5-2A15-2A5-CA4(28-3A)28-2A-A26-2A2-2A25-2A3-2A23-2A5-3A19-3A9-2A15-2A14-2(C13-)C19-C14(10-A19-A)2(10-2A17-2A)11-2(A17-A12-)2A15-2A6-C6-A15-A6-CA3(28-3A)28-2A-A26-2A2-2A25-2A3-2A23-2A4-3A21-3A6-2A19-2A10-2A15-2A14-2(C13-)C19-C14(10-A19-A)11-3(A17-A12-)A17-A13-A15-A7-C6-A15-A6-CA2(28-3A)28-2A-A26-2A2-2A25-2A2-3A23-3A3-3A21-3A5-4A17-4A7-4A15-4A11-2A14-A16-C12-C13-C19-C8(10-A19-A)3(10-2A17-2A)11-2(A17-A12-)A17-A13-4(A15-A14-)A15-A8-C5-A15-A5-C2(2-A27-A)2-A26-2A2-2A25-2A2-3A23-3A3-3A21-3A4-4A19-4A5-4A17-4A8-3A15-3A2(13-A)17-C11-C14-C19-C8(10-A19-A)11-5(A17-A12-)A17-A13-4(A15-A14-)A15-A8-C5-A15-A5-C2(2-A27-A)2-2A25-2A3-2A23-2A4-3A21-3A4-4A19-4A5-4A17-4A7-4A15-4A11-2(A15-)A13-A17-2C9-2C15-C17-C8(12-A17-A)4(12-2A15-2A)13-5(A15-A14-)2(A15-)A13-A10-C5-C13-C5-C4-A4-2A13-2A2(4-A)25-A4-2A23-2A4-3A21-3A5-3A19-3A6-4A17-4A7-4A16-3A10-2A15-2A14-2A11-2A17-2A9-2A20-C7-C18-C15-C2(14-A15-A)12(14-17A)15-4(15A16-)15A11-4C-C13AC-4C3(6-25A)7-23A8-23A9-21A12-17A15-15A17-13A19-11A22-7C20-15C12(16-15A)17-7(13A18-)13A17-15A14-2(19A12-)19A13-17A15-15A16-15A18-11A20-11A21-9A42-
