model
size = 20 12 31, scale = 0.05, origin = -y
material 
  colors = A:#505064 B:#1E1E23 C:#28282D D:#FF8C00 E:#FFED00 F:#008026 G:#004DFF H:#FFF I:#750787 J:#E40303
voxels
------DEEEFFFG------ -------------------- -------------------- -------------------- -------------------- -------------------- -------------------- -------------------- -------------------- -------------------- -------------------- -------------------- 
----DDDEEEFFFGGG---- -------EEEFFF------- -------------------- -------------------- -------------------- -------------------- -------------------- -------------------- -------------------- -------------------- -------------------- -------------------- 
---JDDDEEEFFFGGGI--- -----DDEEEFFFGG----- -------------------- -------------------- -------------------- -------------------- -------------------- -------------------- -------------------- -------------------- -------------------- -------------------- 
--JJDDDEEEFFFGGGII-- ----DDDEHEFHFGGG---- -------------------- -------------------- -------------------- -------------------- -------------------- -------------------- -------------------- -------------------- -------------------- -------------------- 
--JJDDDEEEFFFGGGII-- ---HDDDEHEFHFHHHI--- -------------------- -------------------- -------------------- -------------------- -------------------- -------------------- -------------------- -------------------- -------------------- -------------------- 
--JJDDDEEEFFFGGGII-- ---HDDDEHEFHFHGGH--- -------------------- -------------------- -------------------- -------------------- -------------------- -------------------- -------------------- -------------------- -------------------- -------------------- 
-JJJDDDEEEFFFGGGIII- ---HDDDEHHHHFHGGH--- -------------------- -------------------- -------------------- -------------------- -------------------- -------------------- -------------------- -------------------- -------------------- -------------------- 
-JJJDDDEEEFFFGGGIII- --JHHHDEHEFHFHHHII-- -------------------- -------------------- -------------------- -------------------- -------------------- -------------------- -------------------- -------------------- -------------------- -------------------- 
-JJJDDDEEEFFFGGGIII- --JHDDDEHEFHFHGGHI-- -------------------- -------------------- -------------------- -------------------- -------------------- -------------------- -------------------- -------------------- -------------------- -------------------- 
-JJJDDDEEEFFFGGGIII- --JHDDDEEHHFFHGGHI-- -------------------- -------------------- -------------------- -------------------- -------------------- -------------------- -------------------- -------------------- -------------------- -------------------- 
-JJJDDDEEEFFFGGGIII- --JHHHHEEEFFFHHHII-- -------------------- -------------------- -------------------- -------------------- -------------------- -------------------- -------------------- -------------------- -------------------- -------------------- 
-JJJDDDEEEFFFGGGIII- --JJDDDBBBBBBGGGII-- -------BBBBBB------- --------BHBB-------- -------------------- -------------------- -------------------- -------------------- -------------------- -------------------- -------------------- -------------------- 
-JJJDDD------GGGIII- --JJDBBAAAAAABBGII-- -----BBAAAAAABB----- -----BBBAAAABBB----- ------BBHHHHBB------ -------BBBBHB------- -------------------- -------------------- -------------------- -------------------- -------------------- -------------------- 
-JJJD----------GIII- --JJBAA------AABII-- ----BAA------AAB---- ----BAAA----AAAB---- ----BBAAAAAAAABB---- -----BBAAAAAABB----- ------BBBBBHBB------ ---------HH--------- -------------------- -------------------- -------------------- -------------------- 
-JJ--------------II- --JAA----------AAI-- ---BA----------AB--- ---BA----------AB--- ---BAA--------AAB--- ----BAA------AAB---- -----BAAAAAAAAB----- ------BBHHHBBB------ ---------BB--------- -------------------- -------------------- -------------------- 
-JJ--------------II- --BA------------AB-- --BA------------AB-- --BA------------AB-- --BA------------AB-- ---BA----------AB--- ----BA--------AB---- -----BAAAAAAAAB----- ------BBHBBBBB------ -------------------- -------------------- -------------------- 
-JA--------------AI- -BA--------------AB- -BA--------------AB- -BA--------------AB- --BA------------AB-- --BA------------AB-- ---BA----------AB--- ----BAA------AAB---- -----BBAAAAAABB----- -------BHHHHB------- -------------------- -------------------- 
-CA--------------AC- -CA--------------AC- -CA--------------AC- -CA--------------AC- -CA--------------AC- --CA------------AC-- --CA------------AC-- ---BAA--------AAB--- ----BBAAAAAAAABB---- ------BBBBHBBB------ -------------------- -------------------- 
IA----------------AJ IA----------------AJ IA----------------AJ -IA--------------AJ- -IA--------------AJ- -IA--------------AJ- --CA------------AC-- ---BA----------AB--- ----BAAA----AAAB---- -----BBBAAAABBB----- --------BBHB-------- -------------------- 
GA----------------AD GA----------------AD GA----------------AD GA----------------AD -GA--------------AD- -GA--------------AD- --CA------------AC-- ---BA----------AB--- ----BAA------AAB---- -----BBAAAAAABB----- -------BBBBBB------- -------------------- 
FA----------------AE FA----------------AE FA----------------AE FA----------------AE -FA--------------AE- -FA--------------AE- --CA------------AC-- --BAA----------AAB-- ---BBAA------AABB--- -----BBAAAAAABB----- -------BBBBBB------- ---------HH--------- 
EA----------------AF EA----------------AF EA----------------AF EA----------------AF -EA--------------AF- -EA--------------AF- --CA------------AC-- --BAA----------AAB-- ---BBAA------AABB--- -----BBAAAAAABB----- -------BBBBBB------- ---------HH--------- 
DA----------------AG DA----------------AG DA----------------AG DA----------------AG -DA--------------AG- -DA--------------AG- --CA------------AC-- ---BA----------AB--- ----BAA------AAB---- -----BBAAAAAABB----- -------BBBBBB------- -------------------- 
JA----------------AI JA----------------AI JA----------------AI -JA--------------AI- -JA--------------AI- -JA--------------AI- --CA------------AC-- ---BA----------AB--- ----BAAA----AAAB---- -----BBBAAAABBB----- --------BBBB-------- -------------------- 
-CA--------------AC- -CA--------------AC- -CA--------------AC- -CA--------------AC- -CA--------------AC- --CA------------AC-- --CA------------AC-- ---BAA--------AAB--- ----BBAAAAAAAABB---- ------BBBBBBBB------ -------------------- -------------------- 
-CA--------------AC- -BA--------------AB- -BA--------------AB- -BA--------------AB- --BA------------AB-- --BA------------AB-- ---BA----------AB--- ----BAA------AAB---- -----BBAAAAAABB----- -------BBBBBB------- -------------------- -------------------- 
--CA------------AC-- --BA------------AB-- --BA------------AB-- --BA------------AB-- --BA------------AB-- ---BA----------AB--- ----BA--------AB---- -----BAAAAAAAAB----- ------BBBBBBBB------ -------------------- -------------------- -------------------- 
--CCA----------ACC-- --BAA----------AAB-- ---BA----------AB--- ---BA----------AB--- ---BAA--------AAB--- ----BAA------AAB---- -----BAAAAAAAAB----- ------BBBBBBBB------ ---------BB--------- -------------------- -------------------- -------------------- 
---CCAA------AACC--- ---BBAA------AABB--- ----BAA------AAB---- ----BAAAAAAAAAAB---- ----BBAAAAAAAABB---- -----BCAAAAAACB----- ------CCCCCCCC------ ---------BB--------- -------------------- -------------------- -------------------- -------------------- 
-----CC------CC----- -----BC------CB----- -----BC------CB----- -----BCIGFEDJCB----- ------CIGFEDJC------ -------IGFEDJ------- -------------------- -------------------- -------------------- -------------------- -------------------- -------------------- 
-------CECCCC------- -------------------- -------------------- -------------------- -------------------- -------------------- -------------------- -------------------- -------------------- -------------------- -------------------- -------------------- 
