model
size = 16 26 16, scale = 0.05, origin = -y
material 
  colors = A:#FFF B:#E00 C:#00F
voxels
---------------- ---------------- ---------------- ---------------- ---------------- ---------------- ---------------- ---------------- ------AAAA------ ----AAAAAAAA---- ---AAAAAAAAAA--- ---AAAAAAAAAA--- ---AAAAAABAAA--- ---AAABBBBAAA--- ---AAABAABAAA--- ---AAABAAAAAA--- ---AAABAACAAA--- ---AAAAAAAAAA--- ---AAAAAAAAAA--- ---AAA----AAA--- ---AA------AA--- ---------------- ---------------- ---------------- ---------------- ---------------- 
---------------- ---------------- ---------------- ---------------- ---------------- ---------------- -----AAAAAA----- ----AAAAAAAA---- ---AAA----AAA--- --AA--------AA-- -AA----------AA- -AA----------AA- -AA----------AA- -AA----------AA- -AA----------AA- -AA----------AA- -AA----------AA- -AA----------AA- -AA----------AA- -AA----------AA- -AA----------AA- --AA--------AA-- ---------------- ---------------- ---------------- ---------------- 
---------------- ---------------- ---------------- -------AA------- -----AAAAAA----- ----AAAAAAAA---- ---AA------AA--- --AA--------AA-- --A----------A-- -A------------A- -A------------A- A--------------A A--------------A A--------------A A--------------A A--------------A A--------------A A--------------A A--------------A ---------------- ---------------- ---------------- --AA--------AA-- ---------------- ---------------- ---------------- 
------AAAA------ -----AAAAAA----- ----AAAAAAAA---- ---AAAA--AAA---- ---AA------AA--- --AA--------AA-- --A----------A-- -A------------A- -A------------A- A--------------A A--------------A A--------------A A--------------A A--------------A A--------------A A--------------A A--------------A A--------------A ---------------- ---------------- ---------------- ---------------- ---------------- --AA--------AA-- ---------------- ---------------- 
----AAA--AAA---- ---AA------AA--- ---A--------A--- ---A--------A--- --A----------A-- --A----------A-- -A------------A- -A------------A- A--------------A A--------------A A--------------A A--------------A A--------------A A--------------A A--------------A A--------------A A--------------A ---------------- ---------------- ---------------- ---------------- ---------------- ---------------- ---------------- --AA--------AA-- ---------------- 
----A------A---- ---A--------A--- --A----------A-- --A----------A-- -A------------A- -A------------A- A--------------A A--------------A A--------------A A--------------A A--------------A A--------------A A--------------A A--------------A A--------------A A--------------A ---------------- ---------------- ---------------- ---------------- ---------------- ---------------- ---------------- ---------------- --AA--------AA-- ---------------- 
---AA------AA--- --A----------A-- --A----------A-- -A------------A- -A------------A- -A------------A- A--------------A A--------------A A--------------A A--------------A A--------------A A--------------A A--------------A A--------------A A--------------A ---------------- ---------------- ---------------- ---------------- ---------------- ---------------- ---------------- ---------------- ---------------- ---------------- --AA--------AA-- 
---A--------A--- --A----------A-- --A----------A-- -A------------A- -A------------A- A--------------A A--------------A A--------------A A--------------A A--------------A A--------------A A--------------A A--------------A A--------------A A--------------A ---------------- ---------------- ---------------- ---------------- ---------------- ---------------- ---------------- ---------------- ---------------- ---------------- --AA--------AA-- 
--AA--------A--- --A----------A-- -A------------A- -A------------A- -A------------A- A--------------A A--------------A A--------------A A--------------A A--------------A A--------------A A--------------A A--------------A A--------------A A--------------A ---------------- ---------------- ---------------- ---------------- ---------------- ---------------- ---------------- ---------------- ---------------- ---------------- --AA--------AA-- 
--AA--------A--- --A----------A-- -A------------A- -A------------A- -A------------A- A--------------A A--------------A A--------------A A--------------A A--------------A A--------------A A--------------A A--------------A A--------------A A--------------A ---------------- ---------------- ---------------- ---------------- ---------------- ---------------- ---------------- ---------------- ---------------- ---------------- --AA--------AA-- 
---A--------A--- --A----------A-- --A----------A-- -A------------A- -A------------A- A--------------A A--------------A A--------------A A--------------A A--------------A A--------------A A--------------A A--------------A A--------------A A--------------A ---------------- ---------------- ---------------- ---------------- ---------------- ---------------- ---------------- ---------------- ---------------- ---------------- --AA--------AA-- 
---A-------AA--- --A----------A-- --A----------A-- -A------------A- -A------------A- -A------------A- A--------------A A--------------A A--------------A A--------------A A--------------A A--------------A A--------------A A--------------A A--------------A ---------------- ---------------- ---------------- ---------------- ---------------- ---------------- ---------------- ---------------- ---------------- ---------------- --AA--------AA-- 
----A------A---- ---A--------A--- --A---------A--- --A----------A-- --A----------A-- -A------------A- -A------------A- -A------------A- A--------------A A--------------A A--------------A A--------------A A--------------A A--------------A A--------------A A--------------A ---------------- ---------------- ---------------- ---------------- ---------------- ---------------- ---------------- ---------------- ---------------- --AA--------AA-- 
----AAAAAAAA---- ----AAAAAAAA---- ---AAAAAAAAAA--- ---AA------AA--- --AA--------AA-- --A----------A-- --A----------A-- -A------------A- -A------------A- -A------------A- A--------------A A--------------A A--------------A A--------------A A--------------A A--------------A A--------------A A--------------A ---------------- ---------------- ---------------- ---------------- ---------------- ---------------- --AA--------AA-- ---------------- 
---------------- ---------------- ---------------- -----AAAAAA----- ----AAAAAAAA---- ---AAAAAAAAAA--- ---AAAAAAAAAA--- --AAAA----AAAA-- --AA--------AA-- -AA---------AAA- -AA----------AA- -A------------A- -A------------A- -A------------A- AA------------AA A--------------A A--------------A A--------------A A--------------A ---------------- ---------------- ---------------- ---------------- --AA--------AA-- ---------------- ---------------- 
---------------- ---------------- ---------------- ---------------- ---------------- ---------------- ---------------- ------AAAA------ ----AAAAAAAA---- ---AAAAAAAAA---- ---AAAAAAAAAA--- --AAAAAAAAAAAA-- --AAAAAAAAAAAA-- --AAAAAAAAAAAA-- --AAAAAAAAAAAA-- -AAAAAAAAAAAAAA- -AAAAAAAAAAAAAA- -AAAAAAAAAAAAAA- -AAAAAAAAAAAAAA- -AAAAAAAAAAAAAA- -AAAAAAAAAAAAAA- --AAAA----AAAA-- --AAA------AAA-- ---------------- ---------------- ---------------- 
