model
size = 22 31 19, scale = 0.05, origin = -y
material 
  colors = A:#222 B:#444 C:#AAA D:#555
voxels
---------------------- ---------------------- ---------------------- ---------------------- -------C-------------- ---------------------- ---------------------- ---------------------- -------C-------------- ---------------------- ---------------------- ---------------------- ---------------------- ---------------------- ---------------------- ---------------------- ---------------------- ---------------------- ---------------------- -------A------A------- -------A------A------- ------AA------AA------ -----AAA------AAA----- -----AAA------AAA----- -----AAA------AAA----- ---------------------- ---------------------- ---------------------- ---------------------- ---------------------- ---------------------- 
-----AAA------AAA----- -----AAA------AAA----- -----AAA------AAA----- -----AAA------AAA----- -----AAA------BDA----- -----AAA------AAA----- -----AAA------AAA----- -----AAA------AAA----- -----AAA------BDA----- -----AAA------AAA----- -----AAA------AAA----- -----AAA------AAA----- -----AAA------AAA----- -----AAA------AAA----- -----AAA------AAA----- -----AAA------AAA----- -----AAA------AAA----- -----AAA------AAA----- -----AAA------AAA----- -----AAA------AAA----- -----AAA------AAA----- -----A-A------A-A----- -----A-A------A-A----- -----A-A------A-A----- -----A-A------A-A----- -----AAA------AAA----- ---------------------- ---------------------- ---------------------- ---------------------- ---------------------- 
---AA-----------AAA--- ---AA------------AA--- ---AA------------AA--- ---AA------------AA--- ---AA------------AA--- ---BA------------AB--- ---AA------------AA--- ---AA------------AA--- ---AA------------AA--- ---AA------------AA--- ---AA------------AA--- ---AA------------AA--- ---AA------------AA--- ---AA------------AA--- ---AA------------AA--- ---AA------------AA--- ---AA------------AA--- ---AA------------AA--- ---AA------------AA--- ---AA------------AA--- ---AA------------BB--- ---AA------------AA--- ---AA------------AA--- ---AA------------AA--- ---AA--A------A--AA--- -----AAA------AAA----- -----AAA------AAA----- ---------------------- ---------------------- ---------------------- ---------------------- 
--A----------------A-- --A----------------A-- --A----------------A-- --A----------------A-- --A----------------A-- --B----------------B-- --A----------------A-- --A----------------A-- --A----------------A-- --A----------------A-- --A----------------A-- --A----------------A-- --A----------------A-- --A----------------A-- --A----------------A-- --A----------------A-- --A----------------A-- --A----------------A-- --A----------------A-- --A----------------A-- --A----------------B-- --A----------------A-- --A----------------A-- --A---------------AA-- --A--------------AAA-- ---AA--A------A--AA--- -----AAA------AAA----- -----AAA------AAA----- ---------------------- ---------------------- ---------------------- 
--A----------------A-- --A----------------A-- --A----------------A-- --A----------------A-- --A----------------A-- --B----------------B-- --A----------------A-- --A----------------A-- --A----------------A-- --A----------------A-- --A----------------A-- --A----------------A-- --A----------------A-- --A----------------A-- --A----------------A-- --A----------------A-- --A----------------A-- --A----------------A-- --A----------------A-- --A----------------A-- --A----------------B-- --A----------------A-- --A----------------A-- --AA---------------A-- --A----------------A-- --A--------------AAA-- --AAA--A------A--AAA-- -----AAA------AAA----- -----AAA------AAA----- ---------------------- ---------------------- 
-A------------------A- -A------------------A- -A------------------A- -A------------------A- -A------------------A- -B------------------B- -A------------------A- -A------------------A- -A------------------A- -A------------------A- -A------------------A- -A------------------A- -A------------------A- -A------------------A- -A------------------A- -A------------------A- -AA----------------AA- -AA----------------AA- -AA----------------AA- -AA----------------AA- -AA----------------AA- -AA----------------AA- -AA----------------AA- -A-A---------------AA- -A-----------------AA- -A---------------AA-A- -A------------------A- --AAA--A------A--AAA-- -----AAA------AAA----- -----AAA------AAA----- ---------------------- 
-A------------------A- -A------------------A- -A------------------A- -A------------------A- -A------------------A- -A------------------A- -A------------------A- -A------------------A- -A------------------A- -A------------------A- -A------------------A- -A------------------A- -A------------------A- -AA----------------AA- -AA----------------AA- -AA----------------AA- -AA----------------AA- -AA----------------AA- -AA----------------AA- -AA----------------AA- -AA----------------AA- -AA----------------AA- -AA----------------AA- -A-A---------------AA- -A-----------------AA- -A---------------AA-A- -A---------------A--A- -A------------------A- --AAA--A------A--AAA-- -----AAA------AAA----- -----AAA------AAA----- 
-A------------------A- -A------------------A- -A------------------A- -A------------------A- -A------------------A- -A------------------A- -A------------------A- -A------------------A- -A------------------A- -A------------------A- -A------------------A- -A------------------A- -AA----------------AA- -AA----------------AA- -AA----------------AA- -AA----------------AA- -AA----------------AA- -AA----------------AA- -AA----------------AA- -AA----------------AA- -AA----------------AA- -AA----------------AA- -AA----------------AA- -A-A---------------AA- -A-----------------AA- -A---------------AA-A- -A---------------A--A- -A------------------A- -AAAA--A------A--AAAA- -----AAA------AAA----- -----AAA------AAA----- 
A--------------------A A--------------------A A--------------------A A--------------------A A--------------------A A--------------------A A--------------------A A--------------------A A--------------------A A--------------------A A--------------------A A--------------------A A-A----------------A-A A-A----------------A-A A-A----------------A-A A-A----------------A-A -AA----------------AA- -AA----------------AA- -AA----------------AA- -AA----------------AA- -AA----------------AA- -AA----------------AA- -AA----------------AA- -A-A---------------AA- -A-----------------AA- -A---------------AA-A- -A---------------A--A- -A---------------A--A- -A------------------A- --AAA--A------A--AAA-- -----AAA------AAA----- 
A--------------------A A--------------------A A--------------------A A--------------------A A--------------------A A--------------------A A--------------------A A--------------------A A--------------------A A--------------------A A--------------------A A-A----------------A-A A-A----------------A-A A-A----------------A-A A-A----------------A-A A-A----------------A-A -AA----------------AA- -AA----------------AA- -AA----------------AA- -AA----------------AA- -AA----------------AA- -AA----------------AA- -AA----------------AA- -A-A---------------AA- -A-----------------AA- -A---------------AA-A- -A---------------A--A- -A---------------A--A- -A------------------A- --AAA--A------A--AAA-- -----AAA------AAA----- 
A--------------------A A--------------------A A--------------------A A--------------------A A--------------------A A--------------------A A--------------------A A--------------------A A--------------------A A--------------------A A--------------------A A-A----------------A-A A-A----------------A-A A-A----------------A-A A-A----------------A-A A-A----------------A-A -AA----------------AA- -AA----------------AA- -AA----------------AA- -AA----------------AA- -AA----------------AA- -AA----------------AA- -AA----------------AA- -A-A---------------AA- -A-----------------AA- -A-----------------AA- -A---------------AA-A- -A---------------A--A- -A------------------A- --AAA--A------A--AAA-- -----AAA------AAA----- 
A--------------------A A--------------------A A--------------------A A--------------------A A--------------------A A--------------------A A--------------------A A--------------------A A--------------------A A--------------------A A--------------------A A-A----------------A-A A-A----------------A-A A-A----------------A-A A-A----------------A-A A-A----------------A-A -AA----------------AA- -AA----------------AA- -AA----------------AA- -AA----------------AA- -AA----------------AA- -AA----------------AA- -AA----------------AA- -A-A---------------AA- -A-----------------AA- -A-----------------AA- -A---------------AA-A- -A---------------A--A- -A------------------A- --AAA--A------A--AAA-- -----AAA------AAA----- 
-A------------------A- -A------------------A- -A------------------A- -A------------------A- -A------------------A- -A------------------A- -A------------------A- -A------------------A- -A------------------A- -A------------------A- -A------------------A- -A------------------A- -AA----------------AA- -AA----------------AA- -AA----------------AA- -AA----------------AA- -AA----------------AA- -AA----------------AA- -AA----------------AA- -AA----------------AA- -AA----------------AA- -AA----------------AA- -AA----------------AA- -A-A---------------AA- -A-----------------AA- -A-----------------AA- -A---------------AA-A- -A---------------A--A- -A------------------A- --AAA--A------A--AAA-- -----AAA------AAA----- 
-A------------------A- -A------------------A- -A------------------A- -A------------------A- -A------------------A- -A------------------A- -A------------------A- -A------------------A- -A------------------A- -A------------------A- -A------------------A- -A------------------A- -AA----------------AA- -AA----------------AA- -AA----------------AA- -AA----------------AA- -AA----------------AA- -AA----------------AA- -AA----------------AA- -AA----------------AA- -AA----------------AA- -AA----------------AA- -AA----------------AA- -A-A---------------AA- -A-----------------AA- -A-----------------AA- -A---------------AA-A- -A---------------A--A- -A------------------A- --AAA--A------A--AAA-- -----AAA------AAA----- 
-A------------------A- -A------------------A- -A------------------A- -A------------------A- -A------------------A- -A------------------A- -A------------------A- -A------------------A- -A------------------A- -A------------------A- -A------------------A- -A------------------A- -A------------------A- -AA----------------AA- -AA----------------AA- -AA----------------AA- -AA----------------AA- -AA----------------AA- -AA----------------AA- -AA----------------AA- -AA----------------AA- -AA----------------AA- -AA----------------AA- -A-A---------------AA- -A-----------------AA- -A-----------------AA- -A---------------AA-A- -A---------------A--A- --A----------------A-- ---AAAAA------AAAAA--- -----AAA------AAA----- 
--A----------------A-- --A----------------A-- --A----------------A-- --A----------------A-- --A----------------A-- --A----------------A-- --A----------------A-- --A----------------A-- --A----------------A-- --A----------------A-- --A----------------A-- --A----------------A-- --A----------------A-- --A----------------A-- --A----------------A-- --A----------------A-- --A----------------A-- --A----------------A-- --A----------------A-- --A----------------A-- --A----------------A-- --A----------------A-- --A----------------A-- --AA---------------A-- --A----------------A-- --A----------------A-- --A--------------AAA-- --A----------------A-- ---AAAAAAAAAAAAAAAA--- --------AAAAAA-------- ------AAAAAAAAAA------ 
--A----------------A-- --A----------------A-- --A----------------A-- --A----------------A-- --A----------------A-- --A----------------A-- --A----------------A-- --A----------------A-- --A----------------A-- --A----------------A-- --A----------------A-- --A----------------A-- --A----------------A-- --A----------------A-- --A----------------A-- --A----------------A-- --A----------------A-- --A----------------A-- --A----------------A-- --A----------------A-- --A----------------A-- --A----------------A-- --A----------------A-- --AA---------------A-- --A----------------A-- --A----------------A-- --AA-------------AAA-- ---AAAAAAAAAAAAAAAA--- ---------------------- ---------------------- ---------------------- 
---A---B------B---A--- ---A---B------B---A--- ---A---B------B---A--- ---A---B------B---A--- ---A---B------B---A--- ---A---B------B---A--- ---A---B------B---A--- ---A--------------A--- ---A--------------A--- ---A--------------A--- ---A--------------A--- ---A--------------A--- ---A--------------A--- ---A--------------A--- ---A--------------A--- ---A--------------A--- ---A--------------A--- ---A--------------A--- ---A--------------A--- ---A--------------A--- ---A--------------A--- ---A--------------A--- ---A--------------A--- ---A--------------A--- ---A-------------AA--- ---AA------------AA--- ----AAAAAAAAAAAAAA---- ---------------------- ---------------------- ---------------------- ---------------------- 
----AAABAAAAAA-AAA---- ----AAABAAAAAA-AAA---- ----AAABAAAAAA-AAA---- ----AAABAAAAAA-AAA---- ----AAABAAAAAA-AAA---- ----AAABAAAAAA-AAA---- ----AAABAAAAAA-AAA---- ----AAAAAAAAAAAAAA---- ----AAAAAAAAAAAAAA---- ----AAAAAAAAAAAAAA---- ----AAAAAAAAAAAAAA---- ----AAAAAAAAAAAAAA---- ----AAAAAAAAAAAAAA---- ----AAAAAAAAAAAAAA---- ----AAAAAAAAAAAAAA---- ----AAAAAAAAAAAAAA---- ----AAAAAAAAAAAAAA---- ----AAAAAAAAAAAAAA---- ----AAAAAAAAAAAAAA---- ----AAAAAAAAAAAAAA---- ----AAAAAAAAAAAAAA---- ----AAAAAAAAAAAAAA---- ----AAAAAAAAAAAAAA---- ----AAAAAAAAAAAAAA---- ----AAAAAAAAAAAAAA---- -----AAAAAAAAAAAA----- ---------------------- ---------------------- ---------------------- ---------------------- ---------------------- 
