model
size = 29 21 21, scale = 0.05, origin = -y
material 
  colors = A:#111 B:#00E C:#BBB D:#F60 E:#D00 F:#555 G:#AAA H:#444 I:#0F6
voxels
----------------------------- ----------------------------- ----------------------------- ----------------------------- ----------------------------- ----------------------------- ----------------------------- ----------------------------- ----------------------------- ----------------------------- ----------------------------- ----------------------------- ----------------------------- ----------------------------- ----------------------------- ----------------------------- ----------------------------- ------------CCCCC------------ ------------AAAAA------------ ------------DDDDD------------ ------------AAAAA------------ 
----------------------------- ----------------------------- ----------------------------- ----------------------------- ----------------------------- ----------------------------- ----------------------------- ----------------------------- ----------------------------- ----------------------------- ----------------------------- ----------------------------- ----------------------------- ----------------------------- ----------------------------- ----------------------------- ----------------------------- ----------CCCCCCCCC---------- ----------AAAAAAAAA---------- ----------DD-----DD---------- ----------AA-----AA---------- 
----------------------------- ----------------------------- ----------------------------- ----------------------------- ----------------------------- ----------------------------- ----------------------------- ----------------------------- ----------------------------- ----------------------------- ----------------------------- ----------------------------- ----------------------------- ----------------------------- ----------------------------- ----------------------------- ----------------------------- --------CCCCCCCCCCCCC-------- --------AAAAAACAAAAAA-------- --------DD---------DD-------- --------AA---------AA-------- 
----------------------------- ----------------------------- ----------------------------- ----------------------------- ----------------------------- ----------------------------- ----------------------------- ----------------------------- ----------------------------- ----------------------------- ----------------------------- ----------------------------- ----------------------------- ----------------------------- ----------------------------- ----------------------------- ----------------------------- -------CCCCCCCCCCCCCCC------- -------AAACAAACAAACAAA------- -------D-------------D------- -------A-------------A------- 
----------------------------- ----------------------------- ----------------------------- ----------------------------- ----------------------------- ----------------------------- ----------------------------- ----------------------------- ----------------------------- ----------------------------- ----------------------------- ----------------------------- ----------------------------- ----------------------------- ----------------------------- ----------------------------- ----------------------------- -------CCCCCCCCCCCCCCC------- -------AAAAAAAAAAAAAAA------- -------D-------------D------- -------A-------------A------- 
----------------------------- ----------------------------- ----------------------------- ----------------------------- ----------------------------- ----------------------------- ----------------------------- ----------------------------- ----------------------------- ----------------------------- ----------------------------- ----------------------------- ----------------------------- ----------------------------- ----------------------------- ----------------------------- ----------------------------- ------CCCCCCCCCCCCCCCCC------ ------AACAAAAAAAAAAACAA------ ------D---------------D------ ------A---------------A------ 
----------------------------- ----------------------------- ----------------------------- ----------------------------- ----------------------------- ----------------------------- ----------------------------- ----------------------------- ----------------------------- ----------------------------- ----------------------------- ----------------------------- ----------------------------- ----------------------------- ----------------------------- ----------------------------- ----------------------------- ------CCCCCCCCCCCCCCCCC------ ------AAAAAAAAAAAAAAAAA------ ------D---------------D------ ------A---------------A------ 
----------------------------- ----------------------------- ----------------------------- ----------------------------- ----------------------------- ----------------------------- ----------------------------- ----------------------------- ----------------------------- ----------------------------- ----------------------------- ----------------------------- ----------------------------- ----------------------------- ----------------------------- ----------------------------- ----------------------------- -----CCEEEEECECECCCCCCCC----- ---AAAAAAAAAAAAAAAAAAAAAAA--- -----D-----------------D----- -----A-----------------A----- 
-----BBBBBBBBFFFFBBBBBBB----- ----BB-----------------BB---- ---BB-------------------BB--- --BB---------------------BB-- --B-----------------------B-- -BB-----------------------BB- -BB-----------------------BB- -BB-----------------------BB- BB-------------------------BB BB-------------------------BB BB-------------------------BB BB-------------------------BB BB-------------------------BB BB-------------------------BB BB-------------------------BB -BB-----------------------BB- -BB-----------------------BB- -BBBBCCECCCCCECECCCCCCECBBBB- --BACAAAAAAAAAAAAAAAAAAACAB-- ---BBD-----------------DBB--- -----A-----------------A----- 
-----BBBBBBHFFHHFFHBBBBB----- ----BB-----------------BB---- ---BB-------------------BB--- --BB---------------------BB-- --B-----------------------B-- -BB-----------------------BB- -BB-----------------------BB- -BB-----------------------BB- BB-------------------------BB BB-------------------------BB BB-------------------------BB BB-------------------------BB BB-------------------------BB BB-------------------------BB BB-------------------------BB -BB-----------------------BB- -BB-----------------------BB- -BBBBCCEECCCCEECCEEEEEECBBBB- --BACAACEAAAAABAAAAACCAACAB-- ---BBD--------F--------DBB--- -----A--------FGGGGGI--A----- 
-----BBBBBBBBFFFFBBBBBBB----- ----BB-----------------BB---- ---BB-------------------BB--- --BB---------------------BB-- --B-----------------------B-- -BB-----------------------BB- -BB-----------------------BB- -BB-----------------------BB- BB-------------------------BB BB-------------------------BB BB-------------------------BB BB-------------------------BB BB-------------------------BB BB-------------------------BB BB-------------------------BB -BB-----------------------BB- -BB-----------------------BB- -BBBBCCECCCCCECECECCCCECBBBB- --BACAAAAAAAAAAAAAAAAAAACAB-- ---BBD--------G--------DBB--- -----A-----------------A----- 
----------------------------- ----------------------------- ----------------------------- ----------------------------- ----------------------------- ----------------------------- ----------------------------- ----------------------------- ----------------------------- ----------------------------- ----------------------------- ----------------------------- ----------------------------- ----------------------------- ----------------------------- ----------------------------- ----------------------------- -----CCEEEEECECECCCCCCCC----- ---AAAAAAAAAAAAAAAAAAAAAAA--- -----D--------G--------D----- -----A-----------------A----- 
----------------------------- ----------------------------- ----------------------------- ----------------------------- ----------------------------- ----------------------------- ----------------------------- ----------------------------- ----------------------------- ----------------------------- ----------------------------- ----------------------------- ----------------------------- ----------------------------- ----------------------------- ----------------------------- ----------------------------- ------CCCCCCCCCCCCCCCCC------ ------AAAAAAAAAAAAAAAAA------ ------D-------G-------D------ ------A---------------A------ 
----------------------------- ----------------------------- ----------------------------- ----------------------------- ----------------------------- ----------------------------- ----------------------------- ----------------------------- ----------------------------- ----------------------------- ----------------------------- ----------------------------- ----------------------------- ----------------------------- ----------------------------- ----------------------------- ----------------------------- ------CCCCCCCCCCCCCCCCC------ ------AACAAAAAAAAAAACAA------ ------D-------I-------D------ ------A---------------A------ 
----------------------------- ----------------------------- ----------------------------- ----------------------------- ----------------------------- ----------------------------- ----------------------------- ----------------------------- ----------------------------- ----------------------------- ----------------------------- ----------------------------- ----------------------------- ----------------------------- ----------------------------- ----------------------------- ----------------------------- -------CCCCCCCCCCCCCCC------- -------AAAAAAAAAAAAAAA------- -------D-------------D------- -------A-------------A------- 
----------------------------- ----------------------------- ----------------------------- ----------------------------- ----------------------------- ----------------------------- ----------------------------- ----------------------------- ----------------------------- ----------------------------- ----------------------------- ----------------------------- ----------------------------- ----------------------------- ----------------------------- ----------------------------- ----------------------------- -------CCCCCCCCCCCCCCC------- -------AAACAAACAAACAAA------- -------D-------------D------- -------A-------------A------- 
----------------------------- ----------------------------- ----------------------------- ----------------------------- ----------------------------- ----------------------------- ----------------------------- ----------------------------- ----------------------------- ----------------------------- ----------------------------- ----------------------------- ----------------------------- ----------------------------- ----------------------------- ----------------------------- ----------------------------- --------CCCCCCCCCCCCC-------- --------AAAAAACAAAAAA-------- --------DD---------DD-------- --------AA---------AA-------- 
----------------------------- ----------------------------- ----------------------------- ----------------------------- ----------------------------- ----------------------------- ----------------------------- ----------------------------- ----------------------------- ----------------------------- ----------------------------- ----------------------------- ----------------------------- ----------------------------- ----------------------------- ----------------------------- ----------------------------- ----------CCCCCCCCC---------- ----------AAAAAAAAA---------- ----------DD-----DD---------- ----------AA-----AA---------- 
----------------------------- ----------------------------- ----------------------------- ----------------------------- ----------------------------- ----------------------------- ----------------------------- ----------------------------- ----------------------------- ----------------------------- ----------------------------- ----------------------------- ----------------------------- ----------------------------- ----------------------------- ----------------------------- ----------------------------- ------------CCCCC------------ ------------AAAAA------------ ------------DDDDD------------ ------------AAAAA------------ 
----------------------------- ----------------------------- ----------------------------- ----------------------------- ----------------------------- ----------------------------- ----------------------------- ----------------------------- ----------------------------- ----------------------------- ----------------------------- ----------------------------- ----------------------------- ----------------------------- ----------------------------- ----------------------------- ----------------------------- ----------------------------- --------------A-------------- ----------------------------- ----------------------------- 
----------------------------- ----------------------------- ----------------------------- ----------------------------- ----------------------------- ----------------------------- ----------------------------- ----------------------------- ----------------------------- ----------------------------- ----------------------------- ----------------------------- ----------------------------- ----------------------------- ----------------------------- ----------------------------- ----------------------------- --------------A-------------- -------------AAA------------- --------------A-------------- ----------------------------- 
