model
size = 20 25 29, scale = 0.05, origin = -y
material 
  colors = A:#B80000 B:#101010 C:#A80000
voxels
-------------------- -------------------- -------------------- -------------------- -------------------- -------------------- -------------------- -------------------- -------------------- -------------------- -------------------- -------------------- -------AAAAAA------- ------AAAAAAA------- ------AAAAAAA------- ------AAAAAAA------- ------AAAAAAA------- -------AAAAAA------- ---------AA--------- -------------------- -------------------- -------------------- -------------------- -------------------- -------------------- 
-------------------- -------------------- -------------------- -------------------- -------------------- -------------------- -------------------- -------------------- -------------------- -------------------- -------AAAAAA------- -----AAAAAAAAA------ -----AAAAAAAAAA----- -----AAAAAAAAAA----- ----AAAAAAAAAAA----- ----AAAAAAAAAAA----- -----AAAAAAAAAA----- -----AAAAAAAAAA----- -----AAAAAAAAA------ ------AAAAAAA------- ---------AA--------- -------------------- -------------------- -------------------- -------------------- 
-------------------- -------------------- -------------------- -------------------- -------------------- -------------------- -------------------- -------------------- --------AAAA-------- ------AAAAAAAA------ -----AAAAAAAAAA----- ----AAAAAAAAAAAA---- ---AAAAA---AAAAA---- ---AAAA-----AAAA---- ---AAAA------AAA---- ---AAAA------AAA---- ---AAAA-----AAAA---- ---AAAAA---AAAAA---- ----AAAAAAAAAAAA---- ----AAAAAAAAAAA----- -----AAAAAAAAA------ -------AAAAA-------- -------------------- -------------------- -------------------- 
-------------------- -------------------- -------------------- -------------------- -------------------- -------------------- -------------------- --------AAAA-------- -----AAAAAAAAA------ ----AAAAAAAAAAA----- ---AAAAAA-AAAAAA---- ---AAAA-----AAAAA--- --AAAA-------AAAA--- --AAAA--------AAA--- --AAA---------AAA--- --AAA---------AAA--- --AAA---------AAA--- --AAAA--------AAA--- ---AAAA------AAAA--- ---AAAAA---AAAAA---- ----AAAAAAAAAAAA---- -----AAAAAAAAA------ -------AAAAA-------- -------------------- -------------------- 
-------------------- -------------------- -------------------- -------------------- -------------------- -------------------- ------CCBBBBCC------ ------AAAAAAAA------ ----AAAAAAAAAAA----- ---AAAAAA--AAAAA---- ---AAAA------AAAA--- --AAAA--------AAA--- --AAA----------AAA-- --AA-----------AAA-- --AA-----------AAA-- --AA-----------AAA-- --AA-----------AAA-- --AAA----------AAA-- --AAA---------AAAA-- ---AAA-------AAAA--- ---AAAAA----AAAA---- ----AAAAAAAAAAAA---- -----AAAAAAAAA------ ---------AA--------- -------------------- 
-------------------- -------------------- -------------------- -------------------- -------------------- -------------------- ------CCBCCCCC------ -----AAAAAAAAAC----- ---AAAAAA--AAAAA---- ---AAAA------AAAA--- --AAA---------AAAA-- --AAA----------AAA-- -BAA------------AA-- -BAA------------AA-- -BB-------------AA-- -BB-------------AA-- -BAA------------AA-- -BAA------------AA-- --AA-----------AAA-- --AAA---------AAAA-- ---AAA-------AAAA--- ---AAAAA---AAAAA---- ----AAAAAAAAAAA----- ------AAAAAAA------- -------------------- 
-------------------- -------------------- -------------------- -------------------- -------------------- -------------------- -----AC-BCBBCC------ ----AAA-AAAAAAAA---- ---AAAA-----AAAAA--- --AAAA--------AAA--- --AAA----------AAA-- -BAA------------AA-- -BB-------------AAB- -BB--------------BB- -BB--------------BB- -BB--------------BB- -BB--------------BB- -BB-------------AAB- -BAA------------AA-- --AA-----------AAA-- --AAA---------AAA--- ---AAAA------AAAA--- ----AAAAAAAAAAAA---- -----AAAAAAAAA------ -------------------- 
-------------------- -------------------- -------------------- -------------------- -------------------- -------------------- -----ACCBBBBCC------ ----AAAA----AAAA---- --AAAA-------AAAA--- --AAA----------AAA-- -BAA------------AA-- -BB-------------AAB- -BB--------------BB- -BB--------------BB- -BB--------------BB- -BB--------------BB- -BB--------------BB- -BB--------------BB- -BB-------------AAB- -BAA------------AA-- --AAA----------AAA-- ---AAA--------AAA--- ----AAAA---AAAAA---- -----AAAAAAAAAA----- --------AAAA-------- 
-------AAAAAA------- -------AAAAAA------- -------AAAAAA------- ------AAAAAAA------- ------AAAAAAA------- ------AAAAAAAC------ ----AAAAA--AAAA----- ---AAAA------AAA---- --AAAA--------AAA--- --AA-----------AAA-- -BAA------------AAB- -BB-------------AAB- -BB--------------BB- BAB--------------BB- BA---------------BB- BA---------------BB- BA---------------BB- -BB--------------BB- -BB-------------AAB- -BAA------------AA-- --AAA----------AAA-- --AAAA--------AAA--- ---AAAAA----AAAA---- -----AAAAAAAAAA----- -------AAAAAA------- 
------AAAAAAAA------ -----AAAAAAAAAA----- ----AAAAAAAAAAA----- ----AAAAAAAAAAAA---- ----AAAAA--AAAAA---- ----AAAA----AAAA---- ----AAA-----AAAA---- ---AAA-------AAAA--- --AAA---------AAAA-- -BAA-----------AAA-- -BB-------------AAB- -BB--------------BB- BAB--------------BB- BA---------------BB- BA---------------BB- BA---------------BB- BA---------------BB- BAB--------------BB- -BB--------------BB- -BAA------------AAB- -BAA-----------AAA-- --AAA---------AAA--- ---AAAA-----AAAAA--- ----AAAAAAAAAAA----- ------BBBBBBB------- 
-------------------- -----AA------AA----- ---AAAA------AAAA--- ---AAAA------AAAA--- --AAAA-------AAAA--- --AAAA--------AAA--- --AAAA--------AAA--- --AAA----------AAA-- --AA-----------AAA-- -BAA------------AA-- -BB-------------AAB- BAB--------------BB- BA---------------BB- BA---------------BB- BA---------------BB- BA---------------BB- BA---------------BB- BA---------------BB- BAB--------------BB- -BB-------------AAB- -BAA-----------AAA-- --AAA---------AAAA-- ---AAAA------AAAA--- ----AAAAAAAAAAA----- ------AAAAAABA------ 
-------------------- -------------------- ---AA----------AA--- ---AA----------AA--- --AAA----------AA--- --AA-----------AA--- --AA-----------AAA-- --AA------------AA-- --B-------------AA-- -BB-------------AA-- -BB--------------BB- BA---------------BB- BA---------------BB- BA----------------AB BA----------------AB BA----------------AB BA----------------AB BA---------------BB- BAB--------------BB- -BB-------------AAB- -BAA------------AA-- --AAA---------AAAA-- ---AAAA------AAAA--- ----AAAAAAAAAAAA---- ------AAAAAABA------ 
-------------------- -------------------- -------------------- -------------------- -------------------- -------------------- -------------------- -------------------- -------------------- -BB--------------B-- -BB--------------BB- BAB--------------BB- BA---------------BB- BA----------------B- BA----------------AB BA----------------AB BA----------------AB BA---------------BB- BAB--------------BB- -BB-------------AAB- -BAA------------AA-- --AAA----------AAA-- ---AAAA------AAAA--- ----AAAAAAAAAAAA---- ------AAAAAABA------ 
-------------------- -------------------- -------------------- -------------------- -------------------- -------------------- -------------------- -------------------- -------------------- -------------------- -BB--------------BB- BAB--------------BB- BA---------------BB- BA----------------AB BA----------------AB BA----------------AB BA----------------AB BA---------------BB- BAB--------------BB- -BB-------------AAB- -BAA------------AA-- --AAA----------AAA-- ---AAA-------AAAA--- ----AAAAAAAAAAA----- ------BBBAAABA------ 
-------------------- -------------------- -------------------- -------------------- -------------------- -------------------- -------------------- -------------------- -------------------- -------------------- -BB--------------BB- BAB--------------BB- BA---------------BB- BA----------------AB BA----------------AB BA----------------AB BA----------------AB BA----------------B- BAB--------------BB- -BB-------------AAB- -BAA------------AA-- --AAA---------AAAA-- ---AAAA------AAAA--- ----AAAAAAAAAAA----- ------BAAAAABA------ 
-------------------- -------------------- -------------------- -------------------- -------------------- -------------------- -------------------- -------------------- -------------------- -------------------- -BB--------------BB- -BB--------------BB- BA---------------BB- BA----------------AB BA----------------AB BA----------------AB BA----------------AB BA----------------B- BAB--------------BB- -BB-------------AAB- -BAA-----------AAA-- --AAA---------AAA--- ---AAAA------AAAA--- ----AAAAAAAAAAA----- ------BAAAAAB------- 
-------------------- -------------------- -------------------- -------------------- -------------------- -------------------- -------------------- -------------------- -------------------- -------------------- -BB--------------B-- -BB--------------BB- BA---------------BB- BA----------------AB BA----------------AB BA----------------AB BA----------------AB BA---------------BB- BAB--------------BB- -BB-------------AAB- -BAA-----------AAA-- --AAAA--------AAA--- ---AAAAA----AAAA---- -----ABAAAAAAAA----- -------BBBBBB------- 
-------------------- -------------------- -------------------- -------------------- -------------------- -------------------- -------------------- -------------------- -------------------- -------------------- -------------------- -BB--------------BB- BA---------------BB- BA----------------AB BA----------------AB BA----------------AB BA----------------AB BA---------------BB- BAB--------------BB- -BB-------------AAB- --AA-----------AAA-- --AAAA--------AAA--- ----AAAA----AAAA---- -----AAAAAAAAA------ -------------------- 
-------------------- -------------------- -------------------- -------------------- -------------------- -------------------- -------------------- -------------------- -------------------- -------------------- -------------------- -BB--------------BB- BA---------------BB- BA----------------B- BA----------------AB BA----------------AB BA----------------AB BA---------------BB- BAB--------------BB- -BB-------------AAB- --AA------------AA-- -------------------- -------------------- -------------------- -------------------- 
-------------------- -------------------- -------------------- -------------------- -------------------- -------------------- -------------------- -------------------- -------------------- -------------------- -------------------- -BB--------------BB- BAA--------------BB- BA---------------BB- BA----------------B- BA----------------AB BA----------------B- BA---------------BB- -BB--------------BB- -BB-------------AAB- -------------------- -------------------- -------------------- -------------------- -------------------- 
-------------------- -------------------- -------------------- -------------------- -------------------- -------------------- -------------------- -------------------- -------------------- -------------------- -------------------- -BB--------------BB- BAA--------------BB- BA---------------BB- BA----------------B- BA----------------B- BA----------------B- BA---------------BB- -BB--------------BB- -BB--------------B-- -------------------- -------------------- -------------------- -------------------- -------------------- 
-------------------- -------------------- -------------------- -------------------- -------------------- -------------------- -------------------- -------------------- -------------------- -------------------- -------------------- -BB--------------BB- BAA--------------BB- BA---------------BB- BA----------------B- BA----------------B- BA---------------BB- BAB--------------BB- -BB--------------BB- -BB--------------B-- -------------------- -------------------- -------------------- -------------------- -------------------- 
-------------------- -------------------- -------------------- -------------------- -------------------- -------------------- -------------------- -------------------- -------------------- -------------------- -------------------- -BB--------------BB- -BA--------------BB- BA---------------BB- BA---------------BB- BA----------------B- BA---------------BB- BAB--------------BB- -BB--------------BB- -BB--------------B-- -------------------- -------------------- -------------------- -------------------- -------------------- 
-------------------- -------------------- -------------------- -------------------- -------------------- -------------------- -------------------- -------------------- -------------------- -------------------- -------------------- -BB--------------BB- -BA--------------BB- BA---------------BB- BA---------------BB- BA---------------BB- BA---------------BB- -BB--------------BB- -BB--------------BB- --B--------------B-- -------------------- -------------------- -------------------- -------------------- -------------------- 
-------------------- -------------------- -------------------- -------------------- -------------------- -------------------- -------------------- -------------------- -------------------- -------------------- -------------------- -BB--------------B-- -BA--------------BB- -BA--------------BB- BA---------------BB- BA---------------BB- BAB--------------BB- -BB--------------BB- -BB--------------BB- -------------------- -------------------- -------------------- -------------------- -------------------- -------------------- 
-------------------- -------------------- -------------------- -------------------- -------------------- -------------------- -------------------- -------------------- -------------------- -------------------- -------------------- -BB--------------B-- -BA--------------BB- -B---------------BB- -B---------------BB- -BB--------------BB- -BB--------------BB- -BB--------------BB- -BB--------------B-- -------------------- -------------------- -------------------- -------------------- -------------------- -------------------- 
-------------------- -------------------- -------------------- -------------------- -------------------- -------------------- -------------------- -------------------- -------------------- -------------------- -------------------- -------------------- -B---------------B-- -B---------------BB- -BB--------------BB- -BB--------------BB- -BB--------------BB- -BB--------------BB- -BB--------------B-- -------------------- -------------------- -------------------- -------------------- -------------------- -------------------- 
-------------------- -------------------- -------------------- -------------------- -------------------- -------------------- -------------------- -------------------- -------------------- -------------------- -------------------- -------------------- -------------------- -BB--------------B-- -BB--------------BB- -BB--------------BB- -BB--------------BB- -BB--------------B-- -------------------- -------------------- -------------------- -------------------- -------------------- -------------------- -------------------- 
-------------------- -------------------- -------------------- -------------------- -------------------- -------------------- -------------------- -------------------- -------------------- -------------------- -------------------- -------------------- -------------------- -------------------- -B---------------B-- -B---------------B-- -B---------------B-- -------------------- -------------------- -------------------- -------------------- -------------------- -------------------- -------------------- -------------------- 
