model
size = 25 32 16, scale = 0.05, origin = -y
material 
  colors = A:#101010 B:#747474
voxels
456-2A10-A11-4A2-3B3-3A10-4A2-4B-4A10-5A-4B-A-2A10-5A2(6-4A11-4A)6-4A11-3A7-3A540-8A16-10A11-2A2-10A-2A8-18A6-19A2(6-3A-15A)7-18A7-14A-3A7-3A-13A9-16A9-3A3-4A2-3A440-5A18-10A14-12A12-14A10-15A8-20A5(4-21A)5-20A5-19A6-19A7-17A9-A2-10A-2A12-9A367-7A16-11A13-13A11-15A9-6A5-6A6-7A8-6A4-6A9-7A3-5A3(11-6A2-6A)11-6A3-5A11-6A3-6A10-6A3-7A8-6A5-7A5-8A5-19A7-18A10-11A16-8A319-4A18-10A13-13A11-6A4-5A9-5A2(8-4A)10-4A5-5A12-5A2-5A13-5A2-5A14-3(4A2-4A15-)4A2-5A14-4A2-5A13-5A3-5A12-5A3-5A11-5A4-6A9-6A2(5-7A)9-13A13-11A17-6A293-3BA4B15-2B9AB11-2B4A3-5AB9-5A8-3AB8-3A11-3AB6-3A13-3A4-2(4A15-4A2-)2(4A16-3A2-)3A17-2(3A2-4A16-)3A2(2-4A15-4A)3-4A13-5A3-5A11-5A5-5A9-6A7-6A4-5A12-12A14-9A291-5AB3A14-11ABA11-B4A6-4A9-4A10-3A7-4A12-2AB6-3A14-3A3-4A16-3A2-4A16-2(3A2B3A17-)3A2B3A18-2A2B3A17-3A2B3A17-2A-B-2(4A16-3A2-)5A14-4A3-4A13-5A3-6A10-5A2(7-4A)11-13A14-10A18-3A247-2AB18-10AB13-6A-7A10-B3A7-5A8-3A11-3A7-3A13-2AB6-2A15-3A3-4A16-3AB-2(3A17-3A2B)3(-2A18-2A2B)3A18-2AB-3A17-2A3-A-2A16-3A2-4A15-4A3-4A13-5A3-5A11-5A7-4A8-3A11-5A3-5A13-11A17-5A245-3ABA17-10AB13-5A3-6A10-B3A8-4A8-3A11-3AB6-3A13-3A6-2A15-3A3-4A16-3A2B3A17-3A2B3A18-2A2B-2A18-2A2B-A19-2A2B-2A2(18-2A2B3A)17-2A3-4A16-3A2-4A15-4A2-5A13-5A3-5A12-5A6-3A9-4A10-5A4-5A12-11A17-6A243-A2BAB2A16-10ABA11-B5A4-5A9-5A8-4A8-3A11-3AB6-3A13-3A6-2A15-3A3-4A16-3A2B3A17-3A2B-2A18-3(2A2B-A19-)2A2B-2A18-2A2B3A17-2A-B-4A16-2A3-A-2A15-4A2-5A14-2A-A3-5A12-5A6-3A9-4A10-4A5-5A12-11A16-7A243-2ABAB2A16-10ABA11-B5A4-5A9-5A8-4A8-3A11-3AB6-3A13-3A6-2A15-3A3-4A16-3A2B3A17-3A2B-2A18-2(2A2B2A19-)2A2B-A19-2A2B-2A18-2A2B3A17-3AB-4A16-3A2-A-2A15-4A2-5A14-2A-A3-5A12-5A6-2(3A10-)4A5-5A12-11A16-7A243-2ABAB2A16-12A11-B5A4-5A10-2(4A8-)3A11-3AB6-3A13-3A6-2A15-3A3-2(3A17-3A2B)-2A18-3(2A2B2A19-)2A2B-2A18-2A2B3A17-3AB-4A16-3A2-A-2A15-4A2-5A14-2A-A3-5A12-5A6-2(3A10-)4A6-4A12-12A15-7A244-2BAB2A16-3B8A13-B4A4-5A9-AB3A8-4A8-3A11-3AB6-3A14-2A5-3A15-3A3-3A17-3A2B3A18-2A2B-2A18-3(2A2B2A19-)2(2A2B3A18-)2AB-3A17-3A2-4A15-4A2-5A14-2A-A3-5A12-5A5-4A10-3A9-5A6-4A12-12A15-7A244-6A16-11A13-5A4-5A2(9-4A)8-3A11-4A6-3A14-3A4-3A16-2A3-3A17-3A2B3A18-2A2B-2A18-3(2A2B2A19-)2(2A2B3A18-)2A2-3A17-3A2-4A16-3A2-5A14-4A3-5A12-5A5-4A10-3A9-5A6-4A12-12A15-7A244-6A16-11A13-5A4-5A2(9-4A)8-3A12-3A6-3A14-3A4-3A16-2A3-3A17-3A-B2(3A18-2A2B)4(2A19-2A2B)3A18-2A2-3A17-3A2-4A16-3A2-5A14-4A3-4A13-4A6-4A10-3A9-5A6-4A12-12A15-7A18-7B16-11B13-14B10-16B8-18B6-19B6-20B2(4-21B)4-8B6A7B4-5B11A6B3-4B4A5-5A4B3-2B4A9-4A3B3-2B3A11-4A2B3-B3A13-4AB3-3A15-3AB2-3A17-3A2-3A18-2A2-4(2A19-2AB-)2A19-A3-3A18-2A2-3A17-3A3-3A16-3A3-3A15-3A5-3A13-3A7-4A10-3A9-4A7-4A12-12A15-7A9-
