model
size = 26 17 32, scale = 0.05, origin = -y
material 
  colors = A:#9F8B72 B:#0F0904 C:#56341A D:#3E302D E:#B49C80 F:#C4B190 G:#DFC8A9 H:#412E27 I:#352726 J:#A0886C K:#E1CAAB L:#B19A7A M:#D5C2A2 N:#CFBC9C O:#372928 P:#BEAB8B
voxels
8-10B16-3B4-3B406-10B14-5B4-5B12-2B10-2B378-10B14-5B4-5B2(10-4B)9-B14-B351-10B14-5B4-5B2(10-4B)7-3B14-3B350-8B15-5BD3C5B2(10-4B)7-3B14-3B6-B18-B274-4B22-4B20-8B15-3B-B4A2-3B10-4BD4CELDCD4B7-3B2-CECDCHICEC2-3B5-2B5-2C2DCKDC5-2B221-4B21-6B19-2B-2A-2B17-10B16-10B14-2B2-6A2-2B10-3B3-6A2-4B7-3B-E3-4A3-E-3B5-2B3-CD2-4A2-2C3-2B4-B6-HGCEJCGD6-B12-IH2CJD20-CKIHKG20-DCL2CD20-2C3DC20-2CHJMC20-2DCDCE19-CKGJDGCK18-2C4A2D17-2B6A2B15-3B2A2-3A2B14-12B15-2B6-2B14-2B-8B-2B10-2B3-8A3-2B7-3BC2-8A2-C3B5-2B2-2C-8A-AC2-2B3-2B5-D8AG5-2B9-2C6A2C17-L6AC18-C6AC18-D6AC18-E6AD17-2C6AGD16-D8AI15-ME8ADA14-B-B6-A-B13-B-B8-B-B12-14B37-4B8-4B9-B3-A8BA3-B7-2B3-10A3-2B5-2B-H2-10A-AH-2(2B3-)2G10A2G3-2B2-B5-D10AD5-B8-D-8A-D15-9AD16-9AC15-C-8A-C14-D10AD14-G10AG13-C-10A-C11-2B-B8-B-2B2(10-B-B)10-16B36-3B10-3B9-B2-A10BA2-B7-B3-12A3-B5-3B2-12A-D3B3-2B2-C-13AC2-2B2-B4-C-10A-C4-B7-D2A8-DAD14-J9AC15-E9AD13-M-A8-M-M2(12-J12AJ)11-C-12A-C2(10-B-B)9-B-B12-B-B8-18B35-2B12-2B9-B-AB10-BA-B7-B2-2A10B2A2-B5-2B2-14AC-2B3-2B-E-14AEA2(-2B)3-N-12A-N3-2B6-O12AO12-P12AP2(12-D12AD)11-I14AI10-G14AG10-C14AC9-B-B12-B-B8-2B14-2B8-18B60-4B10-4B7-B-3A10B3A-B5-2B2-14AL-2B3-2B-E-14AEA2(-2B)3-C14AC3-4B3-D14AD3-2B5-C14AC10-D14AD2(10-C14AC)10-D14AD9-2C15AC2(8-2B14-2B)7-20B59-4B10-4B7-B-3A10B3A-B5-B2-15AD2-B3-3B-15AG4B-2B2-G15A2G2-4B3-D14AD3-2B5-D14AD2(10-C14AC)10-E15A9-2C15AC8-C16AC8-BA14-2B7-2B16-2B6-20B59-4B10-4B7-B-3A10B3A-B5-B2-16A2-B3-3B-16A-3B-2B2-C16AC2-4B2-C16AC2-2B5-C14AC10-C14AC9-I16AI2(8-D16AD)8-G16AG7-2(2B-16AB6-)20B59-4B10-4B7-B4A2B2(3FB)4AB5-B-18A-B3-3B-17A3B-2B2-C16AC2-4B2-E16AE2-2B4-C16AC8-D16AD8-I16AI8-D16AD8-DA15-D8-E-15AE7-2(2B-16AB6-)20B59-4B10-4B7-B4A2B2FB4FB4AB5-B-18A-B3-2B-18A3B-2B-C18AC-4B2-C16AC2-2B4-E16AE8-D16AD8-C16AC8-C16-C8-C-15AC7-BA2(-16AB6-2B)-16AB5-22B58-4B10-4B7-B4A2B3F2(BF)B4AB5-B-18A-B3-2B-18A2(-2B)-C18AC-4B2-I16AI2-2B4-2(C16AC8-)J16AJ8-E16-E8-C-15AC7-BA-16AB6-2B-16AB6-B18-B5-22B58-4B10-4B7-B4A2(3BF)2B4AB5-B-18A-B3-2B-18A2(-2B)-D-17AD-4B2-D16AD2-2B4-3(C16AC8-)NA15-N8-H-15AH8-C-15AC7-2B-16AB6-2B-16AB5-22B58-4B10-4B7-B-3A2B2(FB)3FB3A-B5-B2-17A-B3-2B2-17A2(-2B)-D-17AD-4B2-C16AC2-2B4-J16AJ8-C16AC8-N16AN2(8-C16AC)8-H16-H7-2(2B-16AB6-)20B59-4B10-4B7-B-3A2B4FB2FB3A-B5-B2-16A2-B3-3B-17A3B-2B2-O16AO2-4B2-C16AC2-2B5-C14AC10-D14AD9-C15A2C8-D16AD8-J16AJ8-C16AC7-2(2B-16AB6-)20B59-4B10-4B7-B-3A2B2(3FB)3A-B5-B2-16A2-B3-3B-16A-3B-2B2-H16AH2-4B2-D-14A-D2-2B5-D14AD2(10-C14AC)10-G15A9-D16AD8-K16AK8-B16A-B6-2B-16AB6-20B34-2B12-2B9-B-AB10-BA-B7-B2-2A10B3A-B5-B3-14A3-B3-3B2-14A2-3B-2B2-D-14A-D2-2B4-2C14A-C9-D14AD2(10-C14AC10-I14AI)9-2M15AM2(8-BA14-2B)7-20B34-2B12-2B9-B-AB10-BA-B7-B2-2A10B2A2-B5-2B2-14A2-2B3-2B-D2-12A2-A-2B2-B3-C-12A-C3-B6-C-12A-C11-C12AC12-D12AD12-E12AE12-C12AC11-D-13AD10-E14A11-2B12-B-B8-2B14-2B8-18B35-3B10-3B9-B2-A10BA2-B7-B3-12A3-B5-2BA2-12A2-A2B3-2B-HA2-10A3-A-2B2-B3-C2-10A2-C3-B6-2L-10A-2L11-C-10A-C12-D-10A-D12-E-10A-E12-C-10A-C12-C12AC11-C-12A-C2(10-B-B)9-B-B12-B-B8-18B11-3B6-3B13-12B-B10-2B2-10A2-2B7-2B3-10A3-2B5-2B-C2-10A2-C-2B3-2B2-2G2-8A2-2G2-2B7-I2-8A2-I13-C9A-C14-D9A2D2(14-C9A2C)14-D-8A-D14-K10AK13-2C11AC11-2B-B8-B-2B10-B-B10-A-B10-16B12-5B2-5B13-2B2-2A2B2A3-B10-2B3-8A2-3B7-4B2-8A2-4B5-2B2-2D8A-A2D2-2B4-B4-C-7A2-C4-B9-HC-6A-2H14-KCL-5ACK17-C-5AC18-D6AC18-E6AD17-2C6AGD16-D-6A-G16-E8AM15-B-B7A-B13-B-2B6-2A-B12-14B14-10B14-2B3-4A3-2B10-3B2-A-4A4-3B7-3B-2CE-4A-E2C-3B5-2B4-D2C-2A-DCD4-2B10-DHGCEJCGDE17-CIH2CJDC19-CKIHKG20-DCL2CD20-2C3DC20-2CHJMC20-2DCDCE19-CKGJDGCK18-2C4A2D17-B2-4A2-B15-2B-6A-2B14-12B16-8B15-3B8-3B10-6B3CELD6B7-3B4-CDCHIC4-3B6-B7-2DCK7-B222-4B20-8B18-8B17-10B16-10B14-5BD3C5B2(10-4B)7-3B14-3B326-4B19-10B14-5B4-5B2(10-4B)9-B14-B351-10B14-5B4-5B12-2B10-2B378-10B16-3B4-3B398-
