model
size = 24 32 30, scale = 0.05, origin = -y
material 
  colors = A:#B8C0C6 B:#4B4B4B C:#051E48 D:#606E7C E:#37C4E4
voxels
690-2A22-2(A23-)A647-A22-3A2(22-2A)668-2A23-A23-3A22-2A22-A669-3A21-4A23-A21-2A669-2A21-5A20-4A21-3A21-A646-2A22-3A21-4A20-4A21-2A668-D2AD20-D3A2D17-D5AD20-2A515-A2-A-A17-A4-A42-A4-A3-A15-A2-A4-A48-4D20-D3A2DA16-D5ADA18-4ADA20-3A396-3A21-2A23-A20-A23-3A20-7A16-A4-A2-A15-A4-A3-A14-A4-AD18-5A4-A23-ADA18-A-D5A18-D6A14-D-2D6A18-D5A19-4A326-A48-2A18-A-3DA16-8A14-2A-6A16-A-5A19-6A17-A4C4A14-2(AC4-CD16-)DC3-C2AD15-DA3C2A2D16-9AD4A11-2AD-3A-D7A12-2A2D8A13-A-8A13-A2D2AD5A14-A3-5A22-A152-2(2A23-)A52-A17-3A3-2A15-5A-AD2A14-A-9A12-AD2-A-3A2D2A12-AD-2(AD)2AD3A11-9AD2A12-AD-8A13-AD8A14-D9AD13-3A4C4AD12-DAC4-CA2D14-DC4-CAD14-DAC3-C2A2D15-A3C4A-A15-7AD3A-3A12-2A3DA-8A10-2DA-10A10-D-D11A12-3AD5A-A14-4A-2A20-3A104-A23-2AD2(21-3A21-4A)20-3A3-AD14-A-4A-3AD13-AD9AD11-2A2D6AD2AD11-2AD9AD11-4ADAD4A2D11-2(3AD7AD12-)5A-5ADC11-AD-D8ADC11-2DA4C4ADC11-2AC4-C3ADC12-DC4-C2AD2C12-AC2-3C3AD14-A3C4AD3AC12-6AD3-2A2C10-3AD3-5A5C9-2D-3A2B3A3C2A9-D2-12A9-D4A4-5A13-10A16-7A18-6A78-A2D20-2ADADC18-4A2(DC20-2A)DC16-A3-DADC16-A3-D2ADC15-2AD-3A2D3C13-2A2D4A3DC13-AD8ADC12-10A2D11-13AD10-12AD2C2(10-12ADC)9-2(AD)9ADC10-AD2A4C4AD3C8-ADAC4-C3AD3C8-ADAC3-2C3ADC-C9-2AC-4C3ADC-C9-3A3C9AC9-6A4-2BAC11-A10B2AC11-2A6B4A5CA7-AD15A9-14A12-11A14-A-7A18-5A79-A22-AD2-C20-2DBC21-DBC17-A3-DBC17-A4-2BC16-A-2CD2BC16-A2BC3B5C12-A2B-8B2(C12-A10B)2(AC11-A10B)A2C11-A11BAC10-2(A11BC11-)A4B2C5B4C8-A3B4C-3BC-BC8-AD2BC-E2-BC2B4C8-ADB4C6B2C9-A11B4C9-2A8BC-B2C10-A7B2A-3BC10-2A3B5A3B4CA7-17A8-D7A-6A13-9A15-A-7A17-6A153-C23-2C21-C2BC16-3C-C2BC16-C2BC3B5C12-A11B2(C12-A10B)2(AC11-A10B)A2C11-A11BAC10-A12BC10-A11B2C10-A4BC7B3C8-A4B4C6B2C8-A5B3C3B2C-BC7-D11BC2-C8-A11B2C-C10-A11B2C10-A13BC10-2A11B4CA8-2A2-12A9-3A-10A14-2A2(2-5A16-A)158-C23-2C21-C2BC16-5C2BC16-C2BC3B6C11-A11BC12-A10B2C2(11-A10BAC)11-A10BA2C11-A11BAC10-A12BC10-A11B3C9-A4BC7BC10-A4B4C5B3C8-A3B4C4B2C-BC7-D3B3C5BC2-C8-A11B2C-C10-A11B2C10-A5B2A6BC10-2A5BA5B4CA8-2A2-12A9-3A-10A14-2A2(2-5A16-A)84-A22-ADB22-2D-C21-DBC17-A3-DBC17-A4-2BC16-A2C-D2BC16-A2BC3B5C12-A2BC8B2(C12-A10B)2(AC11-A10B)A2C11-A11BAC10-2(A11BC11-)A4B2C5B4C8-A3B4C-3BC-B2C7-AD2BC-E2-4B4C8-ADB4C6B2C9-A11B4C9-2A8BC-B2C10-A7B2A-3BC10-2A3B5A3B4CA7-17A8-D7A-6A13-9A15-A-7A17-6A79-A2D20-2ADADC18-4A2(DC20-2A)DC16-A3-DADC16-A3-D2ADC15-2AD-3A2D3C13-2A2D4A3DC13-AD8ADC12-10A2D11-13AD10-12AD2C2(10-12ADC)9-2(AD)9ADC10-AD2A4C4AD3C8-ADAC4-C3AD3C8-ADAC3-2C3ADC-C9-2AC-4C3ADC-C9-3A3C9AC9-6A4-2BAC11-A10B2AC11-2A6B4A5CA7-AD15A9-14A12-11A14-A-7A18-5A79-A23-2AD2(21-3A21-4A)20-3A3-AD14-A-4A-3AD13-AD9AD11-2A2D6AD2AD11-2AD9AD11-4ADAD4A2D11-2(3AD7AD12-)5A-5ADC11-AD-D8ADC11-2DA4C4ADC11-2AC4-C3ADC12-DC4-C2AD2C12-AC2-3C3AD14-A3C4AD3A13-6AD3-2A2C10-3AD3-5A5C9-2D-3A2B3A3C2A9-D2-12A9-D4A4-5A13-10A16-7A18-6A126-2(2A23-)A52-A17-3A3-2A15-5A-AD2A14-A-9A12-AD2-A-3A2D2A12-AD-2(AD)2AD3A11-9AD2A12-AD-8A13-AD8A14-D9AD13-3A4C4AD12-DAC4-CA2D14-DC4-CAD14-DAC3-C2A2D15-A3C4A-A15-7AD3A-3A12-2A3DA-8A10-2DA-10A10-D-D11A12-3AD5A-A14-4A-2A20-3A303-A48-2A18-A-3DA16-8A14-2A-6A16-A-5A19-6A17-A4C4A14-2(AC4-CD16-)DC3-C2AD15-DA3C2A2D16-9AD4A11-2AD-3A-D7A12-2A2D8A13-A-8A13-A2D2AD5A14-A3-5A22-A374-3A21-2A23-A20-A23-3A20-7A16-A4-A2-A15-A4-A3-A14-A4-AD18-5A4-A23-ADA18-A-D5A18-D6A14-D-2D6A18-D5A19-4A514-A2-A-A17-A4-A42-A4-A3-A15-A2-A4-A48-4D20-D3A2DA16-D5ADA18-4ADA20-3A690-D2AD20-D3A2D17-D5AD20-2A693-2A22-3A21-4A20-4A21-2A693-2A21-5A20-4A21-3A21-A694-3A21-4A23-A21-2A693-2A23-A23-3A22-2A22-A695-A22-3A2(22-2A)742-2A22-2(A23-)A5-
