model
size = 32 24 16, scale = 0.05, origin = -y
material 
  colors = A:#500 B:#444 C:#AAA D:#888
voxels
678-5B27-5B59-20(5A27-)5A25-2B5A2B8-5B10-2B5A2B8-5B12-5A25-20(2A5-2A8-5A10-)2A5-2A8-5A9-B2A5-2A2B4-2B5A2B7-B2A5-2A2B4-2B5A2B8-2A5-2A8-5A2(9-A)9(5-2A4-3A7-A9-A)5-2A4-11(3A7-A9-2(2A4-))3A6-BA9-2A4B2A4-3AB5-BA9-2A4B2A4-3AB6-A9-2(2A4-)3A7-A9-A4-A9-A6-A8(9-A4-A9-A3-4A)9-A4-A9-A6-A9-6A10(9-A6-A11-4A)9-A5-BA11-4A9-AB4-BA11-4A9-AB5-A11-4A2(9-A5-A11-A3-A)9-A3-3A6(11-A3-A9-5A-A)2(11-A3-A9-4A2-A)11-5A9-3A3-9(A25-A5-)A25-A4-BA25-AB3-BA25-AB4-A25-A5-A11-A2-A11-A4-2(A11-A2-)3(3A11-A2-A11-4A5(-A11-A2-A11-A-2A)-A11-A2-A11-A-2(A2-A11-)A-A2-A11-4A11-10(A4-A26-)A3-BA26-AB2-BA26-AB3-A26-2(A4-A11-A2-A11-)A2-)3A11-A2-A11-4A5(-A11-A2-A11-A-2A)-A11-A2-A11-A-2(A2-A11-)A-A2-A11-4A11-10(A4-A26-)A3-BA26-AB2-BA26-AB3-A26-2(A5-A9-A3-A11-)A2-4A9-A3-A11-7A6(9-A3-A11-A-5A)9-A3-A11-A-A3-A9-5A11-10(A5-A25-)A4-BA25-AB3-BA25-AB4-A25-A5-2(A9-A4-A9-A6-)8(A9-A4-A9-4A3-)A9-6A9-3A4-A24-A6-A9-6A3(9-A6-A9-2ABD2A9-A6-A9-2ADB2A)9-A6-A9-2A2B2A9-A6-A9-6A9-A5-BA9-6A9-AB4-BA9-6A9-AB5-A9-6A10(9-A7-2(2A5-)A)9-A7-2A5-8A9-2(A7-2A6-8A8-)8(A7-2A2(6-A)8-)A6-B2A6-A6BA8-AB5-B2A6-A6BA8-AB6-2A2(6-A)8-A8-10(6A8-2A4-3A9-)10(8A6-2A4-3A9-)8A6-2A4-3A8-B8AB4CB2A4-3AB7-B8AB4CB2A4-3AB8-8A6-2A4-3A25-20(5A27-)5A11-8B6-2B5A2B9-8B6-2B5A2B25-5A699-5B27-5B38-
