model
size = 32 24 16, scale = 0.05, origin = -y
material 
  colors = A:#63C B:#FC3 C:#FF0 D:#F93 E:#FF6 F:#F03 G:#F9C H:#FC0 I:#F96 J:#FC9 K:#F33 L:#FC6 M:#F6F N:#CC6 O:#FF9 P:#F0F Q:#F9F R:#F00 S:#FFC T:#F06 U:#F60 V:#CF0 W:#CCF X:#FFF Y:#FCC Z:#FCF Aa:#CF6 Ab:#F09 Ac:#F90 Ad:#F99 Ae:#FF3 Af:#F6C Ag:#CFF Ah:#F39 Ai:#CC0 Aj:#F63 Ak:#F66 Al:#F36 Am:#CCC An:#CF9 Ao:#CF3 Ap:#F3C Aq:#F0C Ar:#CFC As:#CC3 At:#F3F Au:#F30 Av:#CC9 Aw:#F69 Ax:#111 Ay:#DDD
voxels
678-5A27-5A59-KAfXTAk27-LApAjAvU27-TOAqAgJ27-AjNArYJ27-AaAqYPO27-GAeBAkAv27-AfZGAsB27-OAdAoJAf27-QWAgEAj27-AdAvQArAu27-AqGAbXL27-AcNAfAkC27-AbPApBH27-AoMO2U27-FAfNAsAm27-VAuAqZK27-DAt2AeL27-JAtZYT27-AhEAdAtAj27-ZN2WAa27-SAbAvAlG25-9A8-5A10-9A8-5A12-FMPCQ25-AlV5-YE8-DAtAbCB10-CM5-AtAr8-AeEAfAoAc10-BAp5-WX8-ApNApAeAn10-AnJ5-AlAk8-FAbOZN10-EAe5-XB8-BENAiK10-AjAa5-AhU8-KPAqZW10-PF5-CAs8-AlMAeAcAq10-IAw5-AdZ8-CUZApAa10-FAv5-AsAe8-BGAdIAh10-ArI5-QY8-AnQWAcAk10-AwAn5-AlAt8-EAgAvSU10-IAw5-HW8-AjYGAtJ10-AdAe5-AkAl8-PDNAbJ10-HG5-RX8-IVPApO10-RZ5-HAh8-FAmMAcAv10-AiAu5-AbC8-ArWAfKB10-DW5-LAd8-AwIAuAgAf10-BE5-TAs8-IRAtAmAj10-AcD5-TQ8-AdGAtDAu10-AnAe5-AoAl8-HLEVL10-NAp5-NH8-RAiNMC9-AKF5-CAk2A4-2AAiXAbApH2A7-AWB5-JR2A4-2ADCEJU2A8-AqK5-AaH8-BOPAeAm9-S9-E5-OB4-NAiAd7-Ag9-P5-SG4-PXH7-H9-M5-AsAo4-MCR7-F9-U5-MAg4-AfOAi7-O9-G5-XQ4-AuVD7-S9-Q5-QAb4-AtYB7-As9-Ag5-AiAf4-AtTAc7-M9-Y5-RAp4-EAvAn7-X9-D5-MO4-NAgN7-Q9-V5-SN4-AbYK7-Ai9-AmAj4-TAq4-EPW7-R9-WAa4-EAe4-PAkAq7-M9-IG4-SZ4-MAsAa7-S9-RAf4-AmAd4-UJAh7-T9-GO4-LW4-GEAk7-E9-LQ4-AdAv4-QArU7-S9-AiAd4-AiG4-AgXJ7-Am9-XAq4-HN4-YAkJ7-L9-CAc4-SP4-DBO7-Ad9-OAb4-XM4-VUAv7-Ai9-VAo4-AjAf4-AmAsB6-2A9-YF6A4-WZAfA5-2A9-TV6A4-IAeAjA6-X9-AvD4-YAt4-RYAu7-Ar9-F4-Q9-D6-Aw9-B4-Ab9-V3-ArAdSI9-K4-Af9-Am3-YAqAgAd9-Al4-Ap9-W3-BAc2H9-C4-O9-I3-GAbFR9-B4-N9-R3-2AoOAi9-An4-Aq9-G3-AgFSD9-E4-Ae9-L3-QVAsB9-Aj4-Z9-Ai3-AbDMAc9-P4-Ad9-X6-An9-ITAbFCW9-C6-N11-AfOAoAv9-O6-K11-ApSAeG9-V6-W11-OAsZN9-Y6-Aq11-NMAiP9-T6-Aa11-AqXZM9-Av6-Ah11-AeQAcAf9-Ag6-Ak11-ZAiApAu9-Y6-U11-AdRIAt9-P6-J11-WMAcAt9-Ak6-J11-Av2SE9-As5-2A11-GTAtN9-2A4-2A11-NE2Ab9-2A5-B11-PSApE9-Ar5-M11-Z3-N9-Ae5-X11-Au3-K9-G3-RAhQ11-W3-W9-ZQAoAhI-Ai11-E3-Aq9-Au2AgCAr-R11-D3-Aa9-WYQAdAh-M11-Ae3-Ah9-EDAbAsQ-S11-Ap3-Ak9-DVAfQAf-T11-F3-U9-AeAmApAlAr-E11-B3-J9-ApWOH2-S11-K3-J9-FINAk2-Am11-AlAfELO9-BRAq3-L25-K5-Ad25-Al5-Ai25-C5-H25-B5-S25-An5-X25-E5-Aj25-Aj5-Aq25-P5-Ar25-I5-Y25-F4-AB25-ArA3-AG25-AwA4-Ao25-I5-Aa11-E2-Al11-K4-G11-D2-At11-L2-BHAf11-Ae2-Aw11-TAfAjK-O11-Ap2-Aq11-Aj-AuAl-Q11-F2-Ah11-Aa-LC-Ad11-B2-Ak11-G-CB-Aq11-K2-U11-Af-HAn-Ac11-Al2-An11-O-UE-Ab11-C2-Am11-Q-Am2-Ao11-B2-X11-Ad-K2-F11-AnUAkAl11-Aq4-V26-Ac4-D26-Ab4-J26-Ao4-Ah26-F4-Z26-V4-S26-D4-Ag26-J4-H26-Ah4-F26-Z4-O26-S3-AS26-AgA2-AAs26-HA3-M26-F4-K11-G2-P11-T4-Al11-Q2-I11-Av2-ArOC11-Ag2-F11-AgDAfX-B11-Y2-Ar11-Y-AjAk-An11-D2-Aw11-P-AuB-E11-V2-I11-Ak-LU-Aj11-Am2-Ad11-As-CAs-P11-W2-H11-J-HZ-I11-I2-R11-E-U2-F11-R2-Ai11-Ar-Am2-Ar11-GAtCD11-X4-Aw26-Ak4-I26-B4-Ad26-U4-H26-As4-R26-Z4-Ai26-Ae4-D26-Y4-B26-At4-Ac26-W4-An26-Al3-AN26-XA2-AK26-AhA3-W26-C4-B11-Ab2-D11-I4-K11-E2-B11-R2-AhJAl11-P2-Ac11-GAsLZ-C11-M2-An11-L-TS-B11-U2-N11-Ai-TAg-An11-G2-K11-X-AoH-E11-Q2-W11-C-NF-Aj11-Ag2-Aq11-O-CO-P11-Y2-Aa11-V-J2-I11-D2-Ah11-Y-Aa2-F11-VAcJAk11-T4-Ar26-Av4-Aw26-Ag4-I26-Y4-Ad26-P4-H26-Ak4-R26-As4-Ai26-J4-D26-E4-B26-Ar4-Ac26-X3-AAn26-AkA2-AN26-BA3-K26-U4-P11-N2-Ac11-H4-Aw11-Ab2-An11-R2-2AcAu11-E2-N11-AiAbAtS-Ao11-P2-K11-D-EAt-Al11-M2-W11-B-NAb-At11-U2-Aq11-Ac-AbAp-Aw11-G2-Aa11-An-EAc-Aq11-Q2-Ah11-N-PK-Ah11-Ag2-Ak11-K-M2-Ak11-Y2-U11-W-U2-U11-DAaArJ11-Aq4-An26-Aa4-Am26-Ah4-X26-Ak4-Al26-U4-Aj26-J4-Au26-J4-O26-O4-Ad26-Av4-Aa26-B4-R26-Af3-AI26-AjA2-AAr26-AuA3-Ah26-L5-C9-H3-Aw11-Al5-H9-U3-Ae11-C2-FAoKU9-Am3-G11-BDAfBNLAm9-K3-Z11-An-ArKCTK9-L3-Au11-E-AnAlJAjL9-T3-W11-Aj-KC2AaT9-Aj3-E11-P-LBPGAj9-Aa3-D11-I-AvAnAwAfAa9-G3-Ae11-F-VEAuOG9-Af3-Ap11-Ar-Y3-Af9-OMAaAmF11-Aw5-O25-I5-Q25-Ad5-Ad25-H5-Aq25-R5-Ac25-Ai5-Ab25-D5-Ao25-B5-F25-Ac5-V25-An5-D25-N4-AJ25-KA3-AAh25-WA4-Z25-Aq5-Aq9-Aa4-X9-E6-Ah9-Ah4-Ah9-P6-Ak9-Ak4-C9-MKND3-U9-U4-Ad9-ULAbJ3-An9-J4-As9-GAvEAh3-Am9-J4-Q9-QVPZ3-X9-O4-Al9-AgYMS3-Al9-Av4-H9-YAsUAg3-Aj9-B4-Ak9-DCGH3-Au9-Af4-R9-VAoQF3-O9-AjJMApAvH9-AmAeAg4-Ad24-W6-Aa9-LArQAeAfL9-I6-R9-CXAxAyAjT9-R6-I9-HAkAyAxAuT9-G6-Ar9-UBAxAyLAo9-L6-Ah9-AmUAyAxCN9-Ai6-Q9-KAsAxAyHC9-X6-Af9-LZAyAxUJ9-C6-Ar9-TAe2AxAmAa9-O6-An9-AjYAmAeKP9-V5-AK9-AaAtLGLAw9-YA4-AL9-GWAdZTAu9-2A5-Av9-AfAlAiAuAjAo9-Av7-AgI5-WAb5-Aa9-F7-AmAn5-IAo5-R9-B7-DAw5-RF5-I9-K7-VAe5-GV5-Ar9-Al7-MG5-LD5-Ah9-C7-ApZ5-AiJ5-Q9-B7-JAu5-XAh5-Af9-An7-AeW5-CZ5-Ar9-E7-AaE5-OS5-An9-Aj7-FD5-VAg5-K9-P7-AwAe5-YHNITRPL9-I7-AvAp6-FPAcTGAkAvG8-F7-IF6-OMSAoLAsVAf8-Ar7-AnB6-S6-O8-Aw7-AwK6-As6-Q8-I7-AeAl6-M6-Ad8-Ad7-GC6-X6-Aq8-H7-ZB6-Q6-Ac8-R7-AuAn6-Ai6-Ab8-Ai7-WE6-R6-Ao8-D7-EAj6-M6-F8-B6-ADP6-SPVAlAgZAcV8-2A5-AAeI6-T2MAtYAeApD8-2A6-ApF6-E6-J8-N8-AoAqDCZAc8-RAo4-AvXM9-FAcAeBAcS8-HAe4-BAhU9-VAbApAnApAt8-AbZ4-AfCG9-DAoFEIAb8-LAi4-AjAdQ9-JFBAjAcAp8-TZ4-AuAsAg9-AhVKPSAc8-TAc4-LQY9-ZDAlIAtK8-AoAp4-CAlD9-SJCFAbAg8-NI4-2HV9-AgAhBArApAm8-CAc4-UAkAm9-HZAnAwAcD8-JS4-AmRW9-FSEIKVQZ6-AaAt4-KHI9-OAgAjAdAgMAgAe6-PAb4-LAbR9-SHPHAmAp2Y6-AwAp4-TLG9-AsFIRDJDAt6-AuAc4-AjTL9-MOFAiVAeVW6-AoK4-AaTAi9-XSArDMAaAmAl6-AlAg4-GAoX9-QAsAwBApFWX6-AtAm4-AfNC9-AiMIAcJAwIAh6-AwD4-OCO9-RXAdAnAeAvRC6-AqV4-QJV9-MQHNAaIGAd6-AhM4-AdAaY9-SAiRKFAnLAs6-AkAp4-AqPT8-ATRAiWAw4A4Ax3A4-4A7-10A4Ax3A4-4A8-2SBAaIGCH6-AmAa4-2AoY25-AlEFAqH27-XNVAaAb27-AhAbDAhL27-CEJAkT27-AdPAhUT27-AsMZJAo27-QUSJN27-AlGAgOC27-HQHAvJ27-AkAgFBAa27-RYOAfP27-HDSAjAw27-AbVAs2Au27-LAmMLAo27-TWXCAl27-TIQHAt27-AoRAiUAw27-NGRAmAq27-CLMKAh27-JAiSLAk27-AaX2TU11-8A6-9A9-8A6-9A25-AuVAmGX699-5A27-5A38-
