model
size = 13 32 9, scale = 0.05, origin = -y
material 
  colors = A:#060606 B:#000
voxels
354-3A-3A5-A2B3AB2A4-3A2B2ABA4-A2B4A2B277-B7-A4-ABA3-BAB2(3-4A)2-2A2BA-2(AB)A2-B2A2B-4BA2-5B-A2B2A2-B6AB3A2-AB2ABAB4A2-2BABA3BA2B2-AB7-2B2-2A7-AB3-A7-B3-A2B5-2BA2-A2B5-3B3-B2(7-B4-A)7-A122-B5-A6-2(B5-)AB5-2A4-3A3-2AB3-3AB3-2A2B2-BA2B3-4B2-BA2B3-3AB2-2BABA-ABA2B2-A2-2A-2A2-A-BA2-2A-2A2-4B3-A2B3-2(BA)3-2BA3-2(BA)3-2AB3-BA-B9-A2-A9-B2(2-A9-A)2-BA7-2B-BAB2A3-3BAB2A2B5-2AB2-3A5-BAB2-3A5-A2B2-2AB5-ABA2-AB7-2B2-2B7-BA2-BAB5-3B2-2BA5-ABA3-2A5-2B4-A7-A4-B7-A4-2B5-AB4-2BA3-3A4-2AB2(3-ABA)B3-B3A2-2(AB)3-2A2B2-2(AB)3-2B2A2-2(BA-)AB-AB2(2-A)B-AB2-A2-B2-AB-BA2-B-AB3-B-A3-BA2B3-B-A3-2BA4-B-B4-AB4-3A4-BA11-BAB2(9-2ABA)9-BA-A2(9-A2-B)A7-2A-BA-AB3-2A-3AB-AB3-2B-4A-B5-B-B2AB-B5-A-2A2B3A4-A2(B2A)2B3-2A2BA-2A2B3-3AB2-AB2A3-2BAB2-3AB3-A2BA2-A2BA3-2B2A2-B3A3-3AB2-B3A3-AB2A2-2ABA3-B3A2-4A3-2(BA)2-2A-BA2(-AB)2-A2-BA-2A2(2-A)2-2A-B3(A2-)AB-2A2-B2-A2-2B-BA2-B-BA3-B-B3-2A2B3-A-B3-2BAB3-B-B3-BAB2(4-A-A4-2B)4-B2A4-2BA10-ABA9-B3A9-2BAB9-BA-A9-B2-2A7-2A2-BA7-2B-A2(3-B)3-2A2-AB3-2B2-AB2-BA3-BA2-2B2-AB3-BA2-2B3-A3-BA2-2A3-B3-2B2-3B2-B3-A2-3AB2-B3-B2-2A2B2-B3-B2-A3B2-B3-B2-B3A2-A3-A2-3BA2-B3-B2-A2BA2-A3-A2-4B2-AB-BA2-2A-A2-BA-2A2-A-BA2-2A-BA2-2BAB2-2B-2A2-2A-A2-BA-2A2-B-BA3-A-A3-3BA3-A-A3-A3B3-B-B3-2BAB3-B-A3-B2AB3-B-A3-A2BA3-3B3-4A3-B2A3-2(AB)9-AB-A9-A2-A9-B2(2-BA7-2A)2-AB7-BA3-A2B3A2BA2-2B-2B3-2B-4B-2B3-2A-3AB-2A3-2B-B3A-AB3-AB-A2B3-A3-B3-2A3-B3-A3-2A2(3-B)3-2(A3(B3-))2B2(3-A)3-2A2(3-A)3-BA2(3-B)3-3B2-B3-B2-4A2-B3-A2-A2BA2-B3-A2-2A-B2-A3-2(A2-)2B-B3-A-AB2-2B-BA2(-2A)2-AB-2B-BA-2B2-2(2A-)2B-2B2-AB-BA2(-2B)2-2(2B-)2A-BA2-2(2A-)BA-2B2-2B-AB-2A-2B2-BA-2B-BA-2A2-2(2B2-A)B2-2B7-BA2(2-2A7-AB)3-2A5-2A4-2ABA3BAB5-3A2(BA)4-2AB5-2AB2-BAB5-3B2-3A5-A2B2-3A5-2AB-B3AB3-4ABAB-2A3-AB-BA2B-2A3-AB-2BAB2-A3-B2-B3A2-A3-B2-A3B2-B3-B2-AB2A-2A3-2A-4B-2B3-2A-2A2BABA3-BA3B-3BA3-2(BA)2-2(AB)3-2(BA)2-4A3-2A2B2-AB2A3-A2BA3-A2B3-BAB4-3A3-2AB4-3A3-3B4-ABA3-2AB4-B2A3-2BA4-2AB3-ABA4-BAB3-2BA4-3AB-B3A4-ABA2BA3B4-B6ABA4-A2BABA3B4-BA3B2A2B4-2A2BAB2AB5-4B2AB7-B2ABA6-B7-A4-B7-B4-2A5-2B4-BA5-2B4-2B5-BAB2-3A5-BAB2-BA2B3-2B2A2-A3B3-A3B2-B3A3-BA2B2-4B3-AB2A2-A3B4-BAB2-BAB5-A2B3-AB5-BA4-B7-B148-2AB-B2A6-3A-3A6-2AB-ABA6-A2B-BAB42-
