model
size = 26 27 23, scale = 0.05, origin = -y
material 
  colors = A:#100 B:#C93 C:#FF9 D:#FC6 E:#FC3 F:#963 G:#FC9 H:#CC9 I:#CC6 J:#FFC K:#993 L:#FFF M:#F93 N:#630 O:#330 P:#660 Q:#C63 R:#111 S:#001 T:#CCC U:#DDD V:#777 W:#C60 X:#996 Y:#FF6 Z:#C96 Aa:#FCC Ab:#CC3 Ac:#222 Ad:#555 Ae:#444 Af:#F96
voxels
- - - - - - - - - - - - - - - - - - - - - - - - - -   - - - - - - - - - - - - - - - - - - - - - - - - - -   - - - - - - - - - - - - - - - - - - - - - - - - - -   - - - - - - - - - - - - - - - - - - - - - - - - - -   - - - - - - - - - - - - - - - - - - - - - - - - - -   - - - - - - - - - - - - - - - - - - - - - - - - - -   - - - - - - - - - - - - - - - - - - - - - - - - - -   - - - - - - - - - - - - A A - - - - - - - - - - - -   - - - - - - - - - - - - T D - - - - - - - - - - - -   - - - - - - - - - H A A - - B O A - - - - - - - - -   - - - - - - - - - A A A - - B A A - - - - - - - - -   - - - - - - - - - - A A - - A A - - - - - - - - - -   - - - - - - - - - - E E - - A X - - - - - - - - - -   - - - - - - - - - - B B - - A B - - - - - - - - - -   - - - - - - - - - - U B - - A G - - - - - - - - - -   - - - - - - - - - - A A - - A A - - - - - - - - - -   - - - - - - - - - B A A - - H A A - - - - - - - - -   - - - - - - - - - - - - - - - - A - - - - - - - - -   - - - - - - - - - - - - - - - - - - - - - - - - - -   - - - - - - - - - - - - - - - - - - - - - - - - - -   - - - - - - - - - - - - - - - - - - - - - - - - - -   - - - - - - - - - - - - - - - - - - - - - - - - - -   - - - - - - - - - - - - - - - - - - - - - - - - - -   - - - - - - - - - - - - - - - - - - - - - - - - - -   - - - - - - - - - - - - - - - - - - - - - - - - - -   - - - - - - - - - - - - - - - - - - - - - - - - - -   - - - - - - - - - - - - - - - - - - - - - - - - - -   
- - - - - - - - - - - - - - - - - - - - - - - - - -   - - - - - - - - - - - - - - - - - - - - - - - - - -   - - - - - - - - - - - - - - - - - - - - - - - - - -   - - - - - - - - - - - - - - - - - - - - - - - - - -   - - - - - - - - - - - - - - - - - - - - - - - - - -   - - - - - - - - - - - - - - - - - - - - - - - - - -   - - - - - - - - - A A A A A A A A - - - - - - - - -   - - - - - - - - - A A A A A A A A - - - - - - - - -   - - - - - - - - - B A A T A C A A A - - - - - - - -   - - - - - - - - E - - - B B - - - A - - - - - - - -   - - - - - - - - P - - - A K - - - A - - - - - - - -   - - - - - - - - A A - - A A - - A A - - - - - - - -   - - - - - - - - A A - - A A - - B D - - - - - - - -   - - - - - - - - - A A - D A A A L - - - - - - - - -   - - - - - - - - - - - B - - A - - - - - - - - - - -   - - - - - - - - - - A A - - A A - - - - - - - - - -   - - - - - - - B I A - A - - A - A A A - - - - - - -   - - - - - - - F - L A A M G C R A - A - - - - - - -   - - - - - - - - - - A A - - B A - - - - - - - - - -   - - - - - - - - - - - - - - - - - - - - - - - - - -   - - - - - - - - - - - - - - - - - - - - - - - - - -   - - - - - - - - - - - - - - - - - - - - - - - - - -   - - - - - - - - - - - - - - - - - - - - - - - - - -   - - - - - - - - - - - - - - - - - - - - - - - - - -   - - - - - - - - - - - - - - - - - - - - - - - - - -   - - - - - - - - - - - - - - - - - - - - - - - - - -   - - - - - - - - - - - - - - - - - - - - - - - - - -   
- - - - - - - - - - - - - - - - - - - - - - - - - -   - - - - - - - - - - - - - - - - - - - - - - - - - -   - - - - - - - - - - - - - - - - - - - - - - - - - -   - - - - - - - - - A H C A A A F L - - - - - - - - -   - - - - - - - - - A B D B A A AaE - - - - - - - - -   - - - - - - - - - A I J N A A B D - - - - - - - - -   - - - - - - A A A A A A A A A A A A A A - - - - - -   - - - - - - A A N - - - - - - - - A A V - - - - - -   - - - - - - A J F - - - - - - - - - B B - - - - - -   - - - - - - A K - - - - - - - - - - D E - - - - - -   - - - - - - A A - - - - - - - - - - A W - - - - - -   - - - - - - A A - - - - - - - - - - A A - - - - - -   - - - - - - B A - - - - - - - - - - A A - - - - - -   - - - - - - J A A - - - - A - - - J A A - - - - - -   - - - - - - G A A A U - A A - G Q D A A - - - - - -   - - - - - - - A O A - - A A - - A A A - - - - - - -   - - - - - - - B - A - - A A - - A A C - - - - - - -   - - - - - - - F C - A - - A - A A A H - - - - - - -   - - - - - - - A B A - - - - - - A A S - - - - - - -   - - - - - - - - A A - - - - - - A A - - - - - - - -   - - - - - - - - - - - - - - - - - - - - - - - - - -   - - - - - - - - - - - - - - - - - - - - - - - - - -   - - - - - - - - - - - - - - - - - - - - - - - - - -   - - - - - - - - - - - - - - - - - - - - - - - - - -   - - - - - - - - - - - - - - - - - - - - - - - - - -   - - - - - - - - - - - - - - - - - - - - - - - - - -   - - - - - - - - - - - - - - - - - - - - - - - - - -   
- - - - - - - - - L A A M G C R A - - - - - - - - -   - - - - - - - - - A A A A B B A A - - - - - - - - -   - - - - - - - - - A A A A A A A A - - - - - - - - -   - - - - - - - A A A A A A A A A A B A A - - - - - -   - - - - - - - A A A A A A A A A A C A A - - - - - -   - - - - - - - A A A A A A A A A A P A A - - - - - -   - - - - - - A A A A A A A A A A A A A A A - - - - -   - - - - - - A - - - - - - - - - - - - - A - - - - -   - - - - - A - - - - - - - - - - - - - - B - - - - -   - - - - - A - - - - - - - - - - - - - - F - - - - -   - - - - - A - - - - - - - - - - - - - - A - - - - -   - - - - - A - - - - - - - - - - - - - - A - - - - -   - - - - - H - - - - - - - - - - - - - - A - - - - -   - - - - - B - - - - - - - - - - - - - - B - - - - -   - - - - - B - - - - - - - - - - - - - - A - - - - -   - - - - - A A - - - - - - - - - - - A AdA - - - - -   - - - - - - A - A - - - - - - - - A C I - - - - - -   - - - - - - - F A A - - - - - - A A H - - - - - - -   - - - - - - - - B A A A A B B A A A - - - - - - - -   - - - - - - - - A A A A A A A A A A - - - - - - - -   - - - - - - - - - - - - - - - - - - - - - - - - - -   - - - - - - - - - - - - - - - - - - - - - - - - - -   - - - - - - - - - - - - - - - - - - - - - - - - - -   - - - - - - - - - - - - - - - - - - - - - - - - - -   - - - - - - - - - - - - - - - - - - - - - - - - - -   - - - - - - - - - - - - - - - - - - - - - - - - - -   - - - - - - - - - - - - - - - - - - - - - - - - - -   
- - - - - - - - C - - - - - - - - A - - - - - - - -   - - - - - - - - B - - - - - - - - A - - - - - - - -   - - - - - - - - A - - - - - - - - A - - - - - - - -   - - - - - - G A A - - - - - - - - A A A - - - - - -   - - - - - - C A A - - - - - - - - A A A - - - - - -   - - - - - - G A A - - - - - - - - A A A - - - - - -   - - - - - A A A A - - - - - - - - A A A A - - - - -   - - - - - A - - - - - - - - - - - - - - A - - - - -   - - - - - A - - - - - - - - - - - - - - B - - - - -   - - - - - A - - - - - - - - - - - - - - F - - - - -   - - - - - A - - - - - - - - - - - - - - A - - - - -   - - - - - A - - - - - - - - - - - - - - A - - - - -   - - - - - H - - - - - - - - - - - - - - A - - - - -   - - - - - B - - - - - - - - - - - - - - - A - - - -   - - - - - B - - - - - - - - - - - - - - - A - - - -   - - - - - A - - - - - - - - - - - - - - A - - - - -   - - - - - A A - - - - - - - - - - - - - B - - - - -   - - - - - - A - - - - - - - - - - - - Q B - - - - -   - - - - - - A A A A - - A A - - - A S - - - - - - -   - - - - - - - A A A - - A A - - - A A - - - - - - -   - - - - - - - A A A H C A A A F L B A - - - - - - -   - - - - - - - - - - - - - - - - - - - - - - - - - -   - - - - - - - - - - - - - - - - - - - - - - - - - -   - - - - - - - - - - - - - - - - - - - - - - - - - -   - - - - - - - - - - - - - - - - - - - - - - - - - -   - - - - - - - - - - - - - - - - - - - - - - - - - -   - - - - - - - - - - - - - - - - - - - - - - - - - -   
- - - - - - L F - - - - - - - - - - H - - - - - - -   - - - - - - A A - - - - - - - - - - S - - - - - - -   - - - - - - A A - - - - - - - - - - A - - - - - - -   - - - - - A G A - - - - - - - - - - A A A - - - - -   - - - - - A A A - - - - - - - - - - A A A - - - - -   - - - - - A A A - - - - - - - - - - A A A - - - - -   - - - - A A A A - - - - - - - - - - A A A A - - - -   - - - - A A - - - - - - - - - - - - - - - A - - - -   - - - - B - - - - - - - - - - - - - - - - B - - - -   - - - - H - - - - - - - - - - - - - - - - H - - - -   - - - - A - - - - - - - - - - - - - - - - A - - - -   - - - - A - - - - - - - - - - - - - - - - A - - - -   - - - - A - - - - - - - - - - - - - - - - A - - - -   - - - - A - - - - - - - - - - - - - - - - A - - - -   - - - - A - - - - - - - - - - - - - - - - A - - - -   - - - - A - - - - - - - - - - - - - - - - A - - - -   - - - - B - - - - - - - - - - - - - - - - B - - - -   - - - - L A - - - - - - - - - - - - - - - L - - - -   - - - - - A A A A - - - - - - - - - A I A - - - - -   - - - - - A A A A - - - - - - - - - A A A - - - - -   - - - - - F G A A - - C A A A - - A A A A - - - - -   - - - - - - C A A A B - - - - AaE C A A - - - - - -   - - - - - - G A A - - - - - - - - P A A - - - - - -   - - - - - - - - - - - - - - - - - - - - - - - - - -   - - - - - - - - - - - - - - - - - - - - - - - - - -   - - - - - - - - - - - - - - - - - - - - - - - - - -   - - - - - - - - - - - - - - - - - - - - - - - - - -   
- - - - - - A - - - - - - - - - - - - A - - - - - -   - - - - - A A - - - - - - - - - - - - A - - - - - -   - - - - - A A - - - - - - - - - - - - A - - - - - -   - - - - - H G - - - - - - - - - - - - A H - - - - -   - - - - B E C - - - - - - - - - - - - A K B - - - -   - - - - I C G - - - - - - - - - - - - A A I - - - -   - - - - A A A - - - - - - - - - - - - A A A - - - -   - - - - A A A - - - - - - - - - - - - V A A - - - -   - - - - A - - - - - - - - - - - - - - - - A - - - -   - - - - A - - - - - - - - - - - - - - - - A - - - -   - - - - A - - - - - - - - - - - - - - - - A - - - -   - - - - A - - - - - - - - - - - - - - - - A - - - -   - - - - E - - - - - - - - - - - - - - - - E - - - -   - - - - B - - - - - - - - - - - - - - - - B - - - -   - - - - U - - - - - - - - - - - - - - - - U - - - -   - - - - A - - - - - - - - - - - - - - - - A - - - -   - - - - A - - - - - - - - - - - - - - - - A - - - -   - - - - A - - - - - - - - - - - - - - - - A - - - -   - - - L A - - - - - - - - - - - - - - - - A A - - -   - - - A A - - - - - - - - - - - - - - - - A A - - -   - - A A A A - - - - - - - - - - - - - - A M B A - -   - - A A B E - - - - - D B A A - - - - - K B B C - -   - - A A R C - - - A I - - - - B D - - - A I D A - -   - - - A A A A A A A - - - - - - A A A A A A A - - -   - - - - - - - - - - - - - - - - - - - - - - - - - -   - - - - - - - - - - - - - - - - - - - - - - - - - -   - - - - - - - - - - - - - - - - - - - - - - - - - -   
- - - - - - A - - - - - - - - - - - - A - - - - - -   - - - - - A A - - - - - - - - - - - - I A - - - - -   - - - - - A A - - - - - - - - - - - - A A - - - - -   - - - - - C G - - - - - - - - - - - - A C - - - - -   - - - - D E C - - - - - - - - - - - - A K D - - - -   - - - - J C G - - - - - - - - - - - - A A J - - - -   - - - - A A A - - - - - - - - - - - - A A A - - - -   - - - - A - - - - - - - - - - - - - - - - A - - - -   - - - - A - - - - - - - - - - - - - - - - A - - - -   - - - - A - - - - - - - - - - - - - - - - A - - - -   - - - - A - - - - - - - - - - - - - - - - A - - - -   - - - - A - - - - - - - - - - - - - - - - A - - - -   - - - - E - - - - - - - - - - - - - - - - E - - - -   - - - - B - - - - - - - - - - - - - - - - B - - - -   - - - - B - - - - - - - - - - - - - - - - B - - - -   - - - - A - - - - - - - - - - - - - - - - A - - - -   - - - - A - - - - - - - - - - - - - - - - A - - - -   - - - W - - - - - - - - - - - - - - - - - - A - - -   - - - L - - - - - - - - - - - - - - - - - - A - - -   - A A - - - - - - - - - - - - - - - - - - - - A A -   C E - - - - - - - - - - - - - - - - - - - - - - A C   D M - - - - - - - - - - - - - - - - - - - - - - A D   J B - - - - - - - - I J N A A - - - - - - - - - A J   A A A - - - - - - A A A - - A A - - - - - - - A A A   A A A AcA A A A N A - - - - - - A A A V A A A A O A   - - A B R A A E - - - - - - - - - - - A B R A A - -   - - - - - - - - - - - - - - - - - - - - - - - - - -   
- - - - - - M - - - - - - - - - - - - M - - - - - -   - - - - - - A - - - - - - - - - - - - I A - - - - -   - - - - - A A - - - - - - - - - - - - A A - - - - -   - - - - - A G - - - - - - - - - - - - A A - - - - -   - - - - B E C - - - - - - - - - - - - A K B - - - -   - - - - N C G - - - - - - - - - - - - A A N - - - -   - - - - A A A - - - - - - - - - - - - A A A - - - -   - - - - A - - - - - - - - - - - - - - - - A - - - -   - - - - T - - - - - - - - - - - - - - - - T - - - -   - - - - B - - - - - - - - - - - - - - - - B - - - -   - - - - A - - - - - - - - - - - - - - - - A - - - -   - - - - A - - - - - - - - - - - - - - - - A - - - -   - - - - A - - - - - - - - - - - - - - - - A - - - -   - - - - D - - - - - - - - - - - - - - - - - D - - -   - - - K - - - - - - - - - - - - - - - - - - K - - -   - - - A - - - - - - - - - - - - - - - - - - A - - -   - - - I - - - - - - - - - - - - - - - - - - I - - -   - - M W - - - - - - - - - - - - - - - - - - M - - -   - - A L - - - - - - - - - - - - - - - - - - A A - -   - A - - - - - - - - - - - - - - - - - - - - - - A A   A E - - - - - - - - - - - - - - - - - - - - - - A A   B M - - - - - - - - - - - - - - - - - - - - - - A B   - I - - - - - - - - - - - - - - - - - - - - - - N -   A A - - - - - - - - A A A A A A - - - - - - - - A A   A A - - - - - - - A - - - - - - A - - - - - - - O A   A A F E C A A A A A - - - - - - A A A F E C A A A A   - - - - - - - - - - - - - - - - - - - - - - - - - -   
- - - - - - G G - - - - - - - - - - - G - - - - - -   - - - - - - B B - - - - - - - - - - - B - - - - - -   - - - - - - A A - - - - - - - - - - - A A - - - - -   - - - - - A A A - - - - - - - - - - - A A - - - - -   - - - - A A A A - - - - - - - - - - - A A A - - - -   - - - - A A A A - - - - - - - - - - - A A A - - - -   - - - - A A A A - - - - - - - - - - - A A A - - - -   - - - - A - - - - - - - - - - - - - - - - A - - - -   - - - - D - - - - - - - - - - - - - - - - D - - - -   - - - - B - - - - - - - - - - - - - - - - B - - - -   - - - - K - - - - - - - - - - - - - - - - K - - - -   - - - - A - - - - - - - - - - - - - - - - A - - - -   - - - - A - - - - - - - - - - - - - - - - A - - - -   - - - A - - - - - - - - - - - - - - - - - - A - - -   - - - A - - - - - - - - - - - - - - - - - - A - - -   - - - A - - - - - - - - - - - - - - - - - - A - - -   - - B A - - - - - - - - - - - - - - - - - - B - - -   - - G A - - - - - - - - - - - - - - - - - - G G - -   - A A - - - - - - - - - - - - - - - - - - - - - A B   A A - - - - - - - - - - - - - - - - - - - - - - A A   A A - - - - - - - - - - - - - - - - - - - - - - A A   - D - - - - - - - - - - - - - - - - - - - - - - A -   - J - - - - - - - - - - - - - - - - - - - - - - A -   - A - - - - - - - - - - - - - - - - - - - - - - A -   A A - - - - - - - A - - - - - - A - - - - - - - A A   A A G C - A A A A A - - - - - - A A A G C - A A A A   - - - - A - - - A A - - - - - - A A - - - A - - - -   
- - - - - - - C A A A B B B A A AbE E A - - - - - -   - - - - - - - A A A A A V A A A A O A A - - - - - -   - - - - - - - A - - - - - - - - - - A A - - - - - -   - - - - - A A A - - - - - - - - - - A A A - - - - -   - - - - - A A A - - - - - - - - - - A A A - - - - -   - - - - - A A A - - - - - - - - - - A A A - - - - -   - - - - - A A A - - - - - - - - - - A A A A - - - -   - - - - A - - - - - - - - - - - - - - - - A - - - -   - - - - C - - - - - - - - - - - - - - - - C - - - -   - - - - B - - - - - - - - - - - - - - - - B - - - -   - - - - B - - - - - - - - - - - - - - - - B - - - -   - - - - A - - - - - - - - - - - - - - - - A - - - -   - - - - A - - - - - - - - - - - - - - - - A - - - -   - - - A A - - - - - - - - - - - - - - - - - A - - -   - - - A - - - - - - - - - - - - - - - - - - A - - -   - - - A - - - - - - - - - - - - - - - - - - A - - -   - - H - - - - - - - - - - - - - - - - - - - - H - -   - - C - - - - - - - - - - - - - - - - - - - - C - -   B A - - - - - - - - - - - - - - - - - - - - - - A B   A A - - - - - - - - - - - - - - - - - - - - - - A A   - A - - - - - - - - - - - - - - - - - - - - - - A -   - B - - - - - - - - - - - - - - - - - - - - - - A -   - N - - - - - - - - - - - - - - - - - - - - - - A -   - A - - - - - - - - - - - - - - - - - - - - - - A -   - A - - - - - - - - - - - - - - - - - - - - - - A -   A A A A - - - J - - - - - - - - - - A - - - - A J K   - - - - A A J - A - - - - - - - - A - A A A A - - -   
- - - - - - - - - - - - - - - - - - - - - - - - - -   - - - - - - A A A A A A A O A A A A A A - - - - - -   - - - - - - A P Z Q A A B I B A A I B A - - - - - -   - - - - - F A B W B A A F C L A A M G C F - - - - -   - - - - - - A F A A A A A A A A A A H Q - - - - - -   - - - - - - A A A A A A A A A A A A S I - - - - - -   - - - - - A A A A A A A A A A A A A A A A - - - - -   - - - - - A - - - - - - - - - - - - - - A - - - - -   - - - - - A - - - - - - - - - - - - - - K - - - - -   - - - - - O - - - - - - - - - - - - - - - O - - - -   - - - - A - - - - - - - - - - - - - - - - A - - - -   - - - - A - - - - - - - - - - - - - - - - A - - - -   - - - - X - - - - - - - - - - - - - - - - X - - - -   - - - - B - - - - - - - - - - - - - - - - B - - - -   - - - - G - - - - - - - - - - - - - - - - - G - - -   - - - A - - - - - - - - - - - - - - - - - - A - - -   - - A - - - - - - - - - - - - - - - - - - - - A - -   - - R - - - - - - - - - - - - - - - - - - - - R - -   A M - - - - - - - - - - - - - - - - - - - - - - A A   A A - - - - - - - - - - - - - - - - - - - - - - A A   - A - - - - - - - - - - - - - - - - - - - - - - F -   - A - - - - - - - - - - - - - - - - - - - - - - Aa-   - A - - - - - - - - - - - - - - - - - - - - - - B -   - A - - - - - - - - - - - - - - - - - - - - - - A -   A A - - - - - - - - - - - - - - - - - - - - - - A -   B A - - - - - - - - - - - - - - - - - - - - - - F E   - - A A A N F E P - - - - - - - - A A A A A N F - -   
- - - - - - - - - - - - - - - - - - - - - - - - - -   - - - - - - - - - - - - - - - - - - - - - - - - - -   - - - - - - - - - - - - - - - - - - - - - - - - - -   - - - - - - - B I B A A - - H A A A C - - - - - - -   - - - - - - A F C L A A M G C R A A H Q - - - - - -   - - - - - - A A B A A A A B B A A A S I - - - - - -   - - - - - A A A A A A A A A A A A A A A A - - - - -   - - - - - A - - - - - - - - - - - - - - A - - - - -   - - - - - A - - - - - - - - - - - - - - K - - - - -   - - - - - A - - - - - - - - - - - - - - A - - - - -   - - - - - A - - - - - - - - - - - - - - A - - - - -   - - - - A - - - - - - - - - - - - - - - - A - - - -   - - - - B - - - - - - - - - - - - - - - - B - - - -   - - - - L - - - - - - - - - - - - - - - - L - - - -   - - - - Q - - - - - - - - - - - - - - - - Q - - - -   - - - - A - - - - - - - - - - - - - - - - - A - - -   - - - A - - - - - - - - - - - - - - - - - - - A - -   - - A - - - - - - - - - - - - - - - - - - - - A - -   - M - - - - - - - - - - - - - - - - - - - - - - A -   A A - - - - - - - - - - - - - - - - - - - - - - A A   L A - - - - - - - - - - - - - - - - - - - - - - L L   - A - - - - - - - - - - - - - - - - - - - - - - E -   - A - - - - - - - - - - - - - - - - - - - - - - D -   - A - - - - - - - - - - - - - - - - - - - - - - A -   A A - - - - - - - - - - - - - - - - - - - - - - A A   A A - - - - - - - - - - - - - - - - - - - - - - B H   - - A A A A B H A - - - - - - - - A A A A A A B - -   
- - - - - - - - - - - - - - - - - - - - - - - - - -   - - - - - - - - - - - - - - - - - - - - - - - - - -   - - - - - - - - - - - - - - - - - - - - - - - - - -   - - - - - - - - - - - - - - - - - - - - - - - - - -   - - - - - - - - - - - - - - - - - - - - - - - - - -   - - - - - - - - - - - - - - - - - - - - - - - - - -   - - - - - - - A A A A A - - A A A A A - - - - - - -   - - - - - - G A A A H C A A A F L B A A - - - - - -   - - - - - - C A A A B D B A A AaE C A A - - - - - -   - - - - - - G A - - - J N A - - - P A A - - - - - -   - - - - - - A A - - - - - - - - - A A A - - - - - -   - - - - - A - - - - - - - - - - - - - - A - - - - -   - - - - - A - - - - - - - - - - - - - - B - - - - -   - - - - J - - - - - - - - - - - - - - - - J - - - -   - - - - D - - - - - - - - - - - - - - - - D - - - -   - - - - A - - - - - - - - - - - - - - - - A - - - -   - - - A - - - - - - - - - - - - - - - - - - B - - -   - - A - - - - - - - - - - - - - - - - - - - - A - -   - M - - - - - - - - - - - - - - - - - - - - - - A -   A A - - - - - - - - - - - - - - - - - - - - - - A A   B A - - - - - - - - - - - - - - - - - - - - - - A B   C A - - - - - - - - - - - - - - - - - - - - - - C C   - B - - - - - - - - - - - - - - - - - - - - - - P -   A A - - - - - - - - - - - - - - - - - - - - - - A A   A A - - - - - - - - - - - - - - - - - - - - - - A A   A A H - - - - - - - - - - - - - - - - - - - - A A A   - - - I A A A A A - - - - - - - - A H B I A A - - -   
- - - - - - - - - - - - - - - - - - - - - - - - - -   - - - - - - - - - - - - - - - - - - - - - - - - - -   - - - - - - - - - - - - - - - - - - - - - - - - - -   - - - - - - - - - - - - - - - - - - - - - - - - - -   - - - - - - - - - - - - - - - - - - - - - - - - - -   - - - - - - - - - - - - - - - - - - - - - - - - - -   - - - - - - - - - - - - - - - - - - - - - - - - - -   - - - - - - - - - - - - - - - - - - - - - - - - - -   - - - - - - - - - - - - - - - - - - - - - - - - - -   - - - - - - - - A A I J - - A B D P - - - - - - - -   - - - - - - - - A A A A A A A A A A - - - - - - - -   - - - - - - A A N A A A A A A A A A A V - - - - - -   - - - - - - A J - - - - T D - - - - B B - - - - - -   - - - - - A A - - - - - - - - - - - - E F - - - - -   - - - - A A - - - - - - - - - - - - - - A A - - - -   - - - - A - - - - - - - - - - - - - - - - A - - - -   - - - - C - - - - - - - - - - - - - - - - - B - - -   - - H A - - - - - - - - - - - - - - - - - - - H - -   - - S - - - - - - - - - - - - - - - - - - - - S - -   - - A - - - - - - - - - - - - - - - - - - - - A - -   A A - - - - - - - - - - - - - - - - - - - - - - V A   A - - - - - - - - - - - - - - - - - - - - - - - - A   A - - - - - - - - - - - - - - - - - - - - - - - - A   A A - - - - - - - - - - - - - - - - - - - - - - - A   A A A - - - - - - - - - - - - - - - - - - - - - A A   - - C - - - - A - - - - - - - - - - A - - - - A - -   - - - J A A A - A A - - - - - - A A - D J A A - - -   
- - - - - - - - - - - - - - - - - - - - - - - - - -   - - - - - - - - - - - - - - - - - - - - - - - - - -   - - - - - - - - - - - - - - - - - - - - - - - - - -   - - - - - - - - - - - - - - - - - - - - - - - - - -   - - - - - - - - - - - - - - - - - - - - - - - - - -   - - - - - - - - - - - - - - - - - - - - - - - - - -   - - - - - - - - - - - - - - - - - - - - - - - - - -   - - - - - - - - - - - - - - - - - - - - - - - - - -   - - - - - - - - - - - - - - - - - - - - - - - - - -   - - - - - - - - - - - - - - - - - - - - - - - - - -   - - - - - - - - - - - - - - - - - - - - - - - - - -   - - - - - - - - - - - - - - - - - - - - - - - - - -   - - - - - - - - F B A A - - C A A A - - - - - - - -   - - - - - - - K E H A A B B B O A A D - - - - - - -   - - - - - - A A - - - - A K - - - - A W - - - - - -   - - - - - A A A - - - - - - - - - - - A A - - - - -   - - - - I H B - - - - - - - - - - - - - A M - - - -   - - - A B - - - - - - - - - - - - - - - - Z C - - -   - - I A A - - - - - - - - - - - - - - - - B E I - -   - - A A - - - - - - - - - - - - - - - - - - A A - -   - - A - - - - - - - - - - - - - - - - - - - - A - -   - A - - - - - - - - - - - - - - - - - - - - - - B -   - A - - - - - - - - - - - - - - - - - - - - - - G -   - A A - - - - - - - - - - - - - - - - - - - - - G -   - - A - - - - - - - - - - - - - - - - - - - - A - -   - - A - - D L A A A - - - - - - B E A A A - - A - -   - - - N A - - - - - A D - - - M - - - - - A A - - -   
- - - - - - - - - - - - - - - - - - - - - - - - - -   - - - - - - - - - - - - - - - - - - - - - - - - - -   - - - - - - - - - - - - - - - - - - - - - - - - - -   - - - - - - - - - - - - - - - - - - - - - - - - - -   - - - - - - - - - - - - - - - - - - - - - - - - - -   - - - - - - - - - - - - - - - - - - - - - - - - - -   - - - - - - - - - - - - - - - - - - - - - - - - - -   - - - - - - - - - - - - - - - - - - - - - - - - - -   - - - - - - - - - - - - - - - - - - - - - - - - - -   - - - - - - - - - - - - - - - - - - - - - - - - - -   - - - - - - - - - - - - - - - - - - - - - - - - - -   - - - - - - - - - - - - - - - - - - - - - - - - - -   - - - - - - - - - - - - - - - - - - - - - - - - - -   - - - - - - - - - - - - - - - - - - - - - - - - - -   - - - - - - - - P A A A A - B A A A - A - - - - - -   - - - - - - - - A - - - A A - - - - A A - - - - - -   - - - - - - B A - - - - - - - - - - A - B - - - - -   - - - - - B J - - - - - - - - - - - - A B - - - - -   - - - - - A - - - - - - - - - - - - - - A - - - - -   - - - - A - - - - - - - - - - - - - - - - A - - - -   - - A Ae- - - - - - - - - - - - - - - - - - A A - -   - - K E - - - - - - - - - - - - - - - - - - A K - -   - - A E - - - - F - - - - - - - - - - - - - A A - -   - - A - - - - - - - - - - - - - - - - - - - - A - -   - - - A - - - - - - - - - - - - - - - - - - A - - -   - - - A A D L A A A D F A A A F B E A A A A B - - -   - - - - - - - - - - - - A A A - - - - - - - - - - -   
- - - - - - - - - - - - - - - - - - - - - - - - - -   - - - - - - - - - - - - - - - - - - - - - - - - - -   - - - - - - - - - - - - - - - - - - - - - - - - - -   - - - - - - - - - - - - - - - - - - - - - - - - - -   - - - - - - - - - - - - - - - - - - - - - - - - - -   - - - - - - - - - - - - - - - - - - - - - - - - - -   - - - - - - - - - - - - - - - - - - - - - - - - - -   - - - - - - - - - - - - - - - - - - - - - - - - - -   - - - - - - - - - - - - - - - - - - - - - - - - - -   - - - - - - - - - - - - - - - - - - - - - - - - - -   - - - - - - - - - - A A A A A A - - - - - - - - - -   - - - - - - - - - A A A A A A A A - - - - - - - - -   - - - - - - - - M B A A T D C A A M - - - - - - - -   - - - - - - - Z E H A A B B B O A A Z - - - - - - -   - - - - - - B A - - - A A - A - - - A B - - - - - -   - - - - - - A A - - - A - - A - - - - A - - - - - -   - - - - - - A - - - - - A A - - - - - A A - - - - -   - - - - - A - - - - - - - - - - - - - - A - - - - -   - - - - - A - - - - - - - - - - - - - - A - - - - -   - - - - - A - - - - - - - - - - - - - - A - - - - -   - - - - M - - - - - - - - - - - - - - - - M - - - -   - - - - B - - - - - - - - - - - - - - - - B - - - -   - - - - I - - - - - - - - - - - - - - - - I - - - -   - - - B - - - - - - - - - - - - - - - - - - A - - -   - - - A - - A A A A A A A A A A A A A A - - A - - -   - - - A A D - - - - - - - - - - - - - - A B A - - -   - - - - - - - - - - - - - - - - - - - - - - - - - -   
- - - - - - - - - - - - - - - - - - - - - - - - - -   - - - - - - - - - - - - - - - - - - - - - - - - - -   - - - - - - - - - - - - - - - - - - - - - - - - - -   - - - - - - - - - - - - - - - - - - - - - - - - - -   - - - - - - - - - - - - - - - - - - - - - - - - - -   - - - - - - - - - - - - - - - - - - - - - - - - - -   - - - - - - - - - - - - - - - - - - - - - - - - - -   - - - - - - - - - - - - - - - - - - - - - - - - - -   - - - - - - - - - - - - - - - - - - - - - - - - - -   - - - - - - - - - - - - - - - - - - - - - - - - - -   - - - - - - - - - - A A A A A A - - - - - - - - - -   - - - - - - - - - A - - - - - - A - - - - - - - - -   - - - - - - - - B - - - - - - - - B - - - - - - - -   - - - - - - - C - - - - - - - - - - C - - - - - - -   - - - - - - E - - - - - - K - - - - - E - - - - - -   - - - - - - A - - - - - A A - - - - - A - - - - - -   - - - - - A B - - - - - - - - - - - - - A - - - - -   - - - - - A - - - - - - - - - - - - - - A - - - - -   - - - - - A - - - - - - - - - - - - - - A - - - - -   - - - - - A - - - - - - - - - - - - - - A - - - - -   - - - - B - - - - - A - - - - - - - - - - B - - - -   - - - - B - - - - - - - - - - - - - - - - B - - - -   - - - - D - - - - G A A C B F AcA A - - - D - - - -   - - - B A - A A G A A A A U B A A A A Y - - A - - -   - - - A A A - - - - - - - - - - - - - - A A A - - -   - - - - A - - - - - - - - - - - - - - - - - - - - -   - - - - - - - - - - - - - - - - - - - - - - - - - -   
- - - - - - - - - - - - - - - - - - - - - - - - - -   - - - - - - - - - - - - - - - - - - - - - - - - - -   - - - - - - - - - - - - - - - - - - - - - - - - - -   - - - - - - - - - - - - - - - - - - - - - - - - - -   - - - - - - - - - - - - - - - - - - - - - - - - - -   - - - - - - - - - - - - - - - - - - - - - - - - - -   - - - - - - - - - - - - - - - - - - - - - - - - - -   - - - - - - - - - - - - - - - - - - - - - - - - - -   - - - - - - - - - - - - - - - - - - - - - - - - - -   - - - - - - - - - - - - - - - - - - - - - - - - - -   - - - - - - - - - - A A A A A A - - - - - - - - - -   - - - - - - - - - A - - - - - - A - - - - - - - - -   - - - - - - - - A - - - - - - - - A - - - - - - - -   - - - - - - - B - - - - - - - - - - B - - - - - - -   - - - - - - A A - - - - - - - - - - - A - - - - - -   - - - - - - A - - - - - - - - - - - - A - - - - - -   - - - - - - B - - - - - - - - - - - - B - - - - - -   - - - - - F - - - - - - - - - - - - - - F - - - - -   - - - - - A - - - - - - - - - - - - - - A - - - - -   - - - - - A - - - - - - - - - - - - - - A - - - - -   - - - - - A - - - A - - - - - A A - - - A - - - - -   - - - - C A - - A E A A K F Y A A A - - - C - - - -   - - - - A - - J F - - - - - - - - - D - - A - - - -   - - - - A - A A - - - - - - - - - - - Y A A - - - -   - - - - A A - - - - - - - - - - - - - - A A - - - -   - - - - - - - - - - - - - - - - - - - - - - - - - -   - - - - - - - - - - - - - - - - - - - - - - - - - -   
- - - - - - - - - - - - - - - - - - - - - - - - - -   - - - - - - - - - - - - - - - - - - - - - - - - - -   - - - - - - - - - - - - - - - - - - - - - - - - - -   - - - - - - - - - - - - - - - - - - - - - - - - - -   - - - - - - - - - - - - - - - - - - - - - - - - - -   - - - - - - - - - - - - - - - - - - - - - - - - - -   - - - - - - - - - - - - - - - - - - - - - - - - - -   - - - - - - - - - - - - - - - - - - - - - - - - - -   - - - - - - - - - - - - - - - - - - - - - - - - - -   - - - - - - - - - - - - - - - - - - - - - - - - - -   - - - - - - - - - - L A A A A H - - - - - - - - - -   - - - - - - - - - - A A A A A A - - - - - - - - - -   - - - - - - - - - B A - - - - A A - - - - - - - - -   - - - - - - - - E H - - - - - O A A - - - - - - - -   - - - - - - - - P - - - - - - - - A A - - - - - - -   - - - - - - - A A - - - - - - - - A A - - - - - - -   - - - - - - D A - - - - - - - - - - A D - - - - - -   - - - - - - I - - - - - - - - - - - - I - - - - - -   - - - - - F G - - - - - - - - - - - - A F - - - - -   - - - - - A A A A A A A A A A A A - - A A - - - - -   - - - - - A A - F - - A A A A - - A - - A - - - - -   - - - - - A A - Ab- - - - - - - - A - - A - - - - -   - - - - - A - A A - - - - - - - - - D - A - - - - -   - - - - - A A A - - - - - - - - - - - Y A - - - - -   - - - - - - - - - - - - - - - - - - - - - - - - - -   - - - - - - - - - - - - - - - - - - - - - - - - - -   - - - - - - - - - - - - - - - - - - - - - - - - - -   
- - - - - - - - - - - - - - - - - - - - - - - - - -   - - - - - - - - - - - - - - - - - - - - - - - - - -   - - - - - - - - - - - - - - - - - - - - - - - - - -   - - - - - - - - - - - - - - - - - - - - - - - - - -   - - - - - - - - - - - - - - - - - - - - - - - - - -   - - - - - - - - - - - - - - - - - - - - - - - - - -   - - - - - - - - - - - - - - - - - - - - - - - - - -   - - - - - - - - - - - - - - - - - - - - - - - - - -   - - - - - - - - - - - - - - - - - - - - - - - - - -   - - - - - - - - - - - - - - - - - - - - - - - - - -   - - - - - - - - - - - - - - - - - - - - - - - - - -   - - - - - - - - - - - - - - - - - - - - - - - - - -   - - - - - - - - - - - A T D C - - - - - - - - - - -   - - - - - - - - - - A A B B B O - - - - - - - - - -   - - - - - - - - - A A A A K B A A - - - - - - - - -   - - - - - - - - - A A A A A A A A - - - - - - - - -   - - - - - - - - A A E E A A A X B D - - - - - - - -   - - - - - - - A A A B B D A A B A J A - - - - - - -   - - - - - - - A A A U B K A A G Q D A - - - - - - -   - - - - - - A A A A A A A A A A A A A A - - - - - -   - - - - - - A A F A A A A A A A A A A F - - - - - -   - - - - - - A D AbE A A - - - A A A AfD - - - - - -   - - - - - - A J A - - - - - - - - A D J - - - - - -   - - - - - - - - - - - - - - - - - - - - - - - - - -   - - - - - - - - - - - - - - - - - - - - - - - - - -   - - - - - - - - - - - - - - - - - - - - - - - - - -   - - - - - - - - - - - - - - - - - - - - - - - - - -   
- - - - - - - - - - - - - - - - - - - - - - - - - -   - - - - - - - - - - - - - - - - - - - - - - - - - -   - - - - - - - - - - - - - - - - - - - - - - - - - -   - - - - - - - - - - - - - - - - - - - - - - - - - -   - - - - - - - - - - - - - - - - - - - - - - - - - -   - - - - - - - - - - - - - - - - - - - - - - - - - -   - - - - - - - - - - - - - - - - - - - - - - - - - -   - - - - - - - - - - - - - - - - - - - - - - - - - -   - - - - - - - - - - - - - - - - - - - - - - - - - -   - - - - - - - - - - - - - - - - - - - - - - - - - -   - - - - - - - - - - - - - - - - - - - - - - - - - -   - - - - - - - - - - - - - - - - - - - - - - - - - -   - - - - - - - - - - - - - - - - - - - - - - - - - -   - - - - - - - - - - - - - - - - - - - - - - - - - -   - - - - - - - - - - - - - - - - - - - - - - - - - -   - - - - - - - - - - - A A A A - - - - - - - - - - -   - - - - - - - - - - E E A A A X - - - - - - - - - -   - - - - - - - - - - B B D A A B - - - - - - - - - -   - - - - - - - - - A U B K A A G Q - - - - - - - - -   - - - - - - - - A A A A A A A A A A - - - - - - - -   - - - - - - - - - A A A A A A A A A - - - - - - - -   - - - - - - - - - E A A K F Y A A A - - - - - - - -   - - - - - - - - - - - - - - - - - - - - - - - - - -   - - - - - - - - - - - - - - - - - - - - - - - - - -   - - - - - - - - - - - - - - - - - - - - - - - - - -   - - - - - - - - - - - - - - - - - - - - - - - - - -   - - - - - - - - - - - - - - - - - - - - - - - - - -   
