model
size = 20 29 7, scale = 0.05, origin = -y
material 
  colors = A:#F7A8B8 B:#FFF C:#55CDFC D:#4B4B4B
voxels
-------------------- -------------------- -------------------- -------------------- -------------------- -------------------- -------------------- -------------------- -------------------- -------------------- -------------------- -------------------- -------------------- -------------------- -------------------- -----A--------A----- -----A--------A----- -----A--------A----- -----A--------A----- -----A--------A----- -----A--------A----- -----AB------BA----- -----CB------BC----- -----CB------BC----- -----CB------BC----- -----CB------BC----- ------C------C------ -------------------- -------------------- 
-------------------- -------------------- -------------------- -------------------- -------------------- -------------------- -------------------- -------------------- ----C----------C---- ----C----------C---- ----BA--------AB---- ----CA--------AC---- ----CC--------CC---- ----CC--------CC---- ----CC--------CC---- ----CB--------BC---- ----CB--------BC---- ----CB--------BC---- ----CB--------BC---- ----CB--------BC---- ----CB--------BC---- ----CB--------BC---- ----CB--------BC---- ----BB--------BB---- ----CB--------BC---- ----ABB------BBA---- ----CAC------CAC---- ----CC--------CC---- -------------------- 
-------------------- -------------------- -------------------- -------------------- -------------------- -------------------- ---A------------A--- ---A------------A--- ---AC----------CA--- ---AC----------CA--- ---AC----------CA--- ---AC----------CA--- ---AB----------BA--- ---AB----------BA--- ---AB----------BA--- ---AB----------BA--- ---AB----------BA--- ---AB----------BA--- ---AB----------BA--- ---AA----------AA--- ---AB----------BA--- ---AB----------BA--- ---AB----------BA--- ---AA----------BA--- ---AC----------AA--- ---AA----------AA--- ---ACA--------ADA--- ----CCC------CCC---- -----C--------C----- 
-------------------- -------------------- -------------------- -------------------- -------------------- -------------------- ---A------------A--- --BA------------AB-- --BA------------AB-- --BA------------AB-- --BA------------AB-- --BA------------AB-- --BA------------AB-- --BA------------AB-- --BA------------AB-- --BA------------AB-- --BA------------AB-- --BA------------AB-- --BA------------AB-- --BA------------AB-- --BA------------AB-- --BA------------AB-- --AA------------AA-- --AA------------AA-- ---A------------A--- ---AA----------AA--- ---ADA--------ADA--- ----CDC------CDC---- -----C--------C----- 
-------------------- -------------------- -------------------- -------------------- --B--------------B-- --B--------------B-- --B--------------B-- --B--------------B-- -BB--------------BB- -BB--------------BB- -BB--------------BB- -BB--------------BB- -BB--------------BB- -BB--------------BB- -BB--------------BB- -BB--------------BB- -BB--------------BB- -BB--------------BB- -BB--------------BB- -BB--------------BB- -BB--------------BB- -BB--------------BB- --A--------------A-- --A--------------A-- --AA------------AA-- --AAA----------AAA-- ---ADA--------ADA--- ----CBC------CBC---- -----C--------C----- 
-------------------- -------------------- -A----------------A- -A----------------A- -A----------------A- -A----------------A- -A----------------A- -A----------------A- -A----------------A- AA----------------AA AA----------------AA AA----------------AA AA----------------AA AA----------------AA AA----------------AA AA----------------AA AA----------------AA AA----------------AA AA----------------AA AA----------------AA -A----------------A- -A----------------A- -A----------------A- -AA--------------AA- -AAA------------AAA- --AAA----------AAA-- ---ACA--------ADA--- ----CC--------CC---- -------------------- 
C------------------C C------------------C C------------------C C------------------C C------------------C C------------------C C------------------C C------------------C C------------------C C------------------C C------------------C C------------------C C------------------C C------------------C C------------------C C------------------C C------------------C C------------------C C------------------C C------------------C C------------------C C------------------C CC----------------CC -CA--------------AC- -CCA------------ACC- --CCA----------ACC-- ---CCA--------ACC--- -------------------- -------------------- 
