model
size = 32, scale = 0.05, origin = -y
material 
  colors = A:#FFF B:#DDD C:#999 D:#CCC E:#EEE F:#888 G:#BBB H:#AAA I:#C99 J:#CC9 K:#FCC L:#222 M:#555 N:#C69 O:#444 P:#966 Q:#666 R:#111 S:#777 T:#969 U:#333 V:#C9C W:#669 X:#99C Y:#001 Z:#500 Aa:#936 Ab:#C66 Ac:#336 Ad:#100 Ae:#400 Af:#633 Ag:#F9C Ah:#636 Ai:#002 Aj:#010 Ak:#300 Al:#663 Am:#FFC An:#603 Ao:#996 Ap:#303
voxels
2F5CGDCDH5C4HGH2G2HGCH2C4F2HD3BGD3CHCG4CFC3F3CFC3FCG2CFEFH5FCFH2(GF)CGFCHFGFC3FCGFXBH2C3FH4FG2FCGC2FCF3C3F4C2HCF2CFDC3FBCG2FCFG3C2GFCF4WF4C2FGHCHG2DGDHF3G2CH3FWMRLQM4CGHBGDBG4BDHD2B2GDG2FQYWAcLAhQT4CDGD4BCHBHCDHGCHFCFAcUEYLAiQW4C2G2DBEDB2DG4HX2(CG)CM2EUCMFC3HG4DB2(HD)B2DBH2DB2CHCOGEULFGF3HG2B2DBD2B2GBHGD2G3HFLABERUMHSHGHBH7BDBD4G2XCXMAE2AY2LSCGHG3HG2HGBHDG3CG2CXM2RBE2ALCFPF2TFTFC2T2S3FQO2FWHX2BLE4AULSC2GHDHG2DG3DHSQCF2HVA3E5AE2B2E2AE2A6EAAjSUCBE21A2E2(AE)OQHABAAdLOE4AAk2AE2AO2AUESEAU4AUS4AL5AAeCAlAE2AMAEFEQ2EO3AEMF4AL4AZPDEFAEAMOQMAMQDM2(EA)LF4AR3AZIEKGAmD2AM2AY3EBOA3ERO4AOAEAAe2PD3KGAMAELE2ARQMDAELPA2ERLFD2AAnAfBZAfB3A2OB3AER2E2A2LV2(EK)2E3A2EAB6AE3A3EAEAd2TVNAE2AE3AEA3E3AEA2E2A2EAERBKNIAp2Aa2NI3N5IAoJIJNFCJIN2PIGIP2IAgPAaAbPG2NAb2IJ2(G2J)2G2JDAbICPI2P2I3NI2GTIJBJH4DGDI4D2IDIDNI3D2VAgB3VBE2BE4B2D2JKDJ6IDK4DBD6BG4BDB2DJHJ6IKD2K2DK2BDE7B2(D2B)4D3JI2(2D2K)JKBD5BDBK6B5KD2F3C3FCF4CGCH3CDG3BD2H5F30-2F30-CF2(30-CH)30-FD2(30-FB)30-CB30-FG30-CD3(30-2C)30-GH30-2C30-HG3(30-2C)30-DC30-GF30-BC2(30-BF)30-DF2(30-HC)30-FC30-2F30-5F2HD3BGD3CHCG4CFC3F3CFC2FGFH2(CFG)FGHFC5FHFEF2CGC4F30-2F30-GC30-FG30-HC30-2C30-2F30-GE30-CF30-FH30-GF30-2F30-GF30-HF30-2F30-2C30-2F30-FH30-FG30-2F30-FG30-HF30-FC30-EG30-2F30-2C30-CH30-GF30-CG30-2F30-4FCG2CFEFH5FCFH2(GF)CGFCHFGFCF2CFC2FCGC2FG4FH3F2CHBXFGC4F30-CF30-2C30-FG30-CF30-FX30-FB30-CH30-GC30-2C2(30-2F)30-GF30-FH3(30-2F)30-HF30-FG2(30-2F)30-2C30-CG30-HC30-BF30-XF30-FC30-GF30-2C30-FC30-4FCGFXBH2C3FH4FG2FCGC2FCF3CFG3CGFC2FGCB3FCDF2CFC2H4C4F30-GF3(30-2C)30-GC30-FH30-CH30-FC30-2F30-GC30-2C30-BF30-FD30-FC30-2F30-CF30-DF30-FB30-2C30-CG30-2F30-CF30-HC30-HF30-CG3(30-2C)30-FG30-4F4C2HCF2CFDC3FBCG2FCFG3C2GFH2C3GFHDG2DGHCHG2F4CF4W2(FC)30-HF2(30-CW)2(30-GW)30-GF30-FC30-HC30-DC30-GC2(30-DF)30-2G30-2H30-2C30-2H30-2G2(30-FD)30-CG30-CD30-CH30-CF30-F3(G30-W)C30-WC30-FH30-2(CF)4WF4C2FGHCHG2DGDHF3G2CH2FD2G2BDHD4BGBDGBHG4CMQLRMW3F30-DW30-GM30-GR30-BL30-BQ30-DM30-HC30-D3(C30-B)G30-BH30-GB30-BG30-2D30-GB30-BG30-HB30-G3(B30-C)D30-CH30-MD30-QB30-LB30-RG30-MG30-WD30-3FWMRLQM4CGHBGDBG4BDHD2B2GDGFHCGHDCHBHC4BDGD4CTQAhLAcWYQ3F30-HQ30-CY30-GW30-HAc30-DL30-CAh30-HQ30-BT30-HC30-2C2(30-BC)30-BD30-BG30-2D30-GB30-D2(B30-C)B30-2C30-CH30-TB30-QH30-AhC30-LD30-AcH30-WG30-YC30-QH30-3FQYWAcLAhQT4CDGD4BCHBHCDHGCHF2CX4HG2DBDEB2D2G4CWQAiLYEUAcFCF30-CAc30-XU30-HE30-HY30-HL30-HAi30-GQ30-DW30-DC30-BC30-DC30-EC30-BG30-DG30-2D30-GD30-GB30-CE30-CD30-CB30-CD30-WD30-QG30-AiH30-LH30-YH30-EH30-UX30-AcC30-FCFAcUEYLAiQW4C2G2DBEDB2DG4HXCGC2DHB2DB2(DH)B4DG3HCFMCU2EM2(CG)30-DC30-DM30-HE30-BE30-DU30-DC30-BM30-DF30-HC30-DH30-2H30-BH30-DG3(30-2D)30-GD30-HB30-2H30-HD30-CH30-FD30-MB30-CD30-UD30-EB30-EH30-MD30-CD30-2(GC)M2EUCMFC3HG4DB2(HD)B2DBH2DBCGDGHB2G2BDB2D2BG3HFGFLUEGOCH3C30-GH30-DC30-GO30-HG30-BE30-GU30-GL30-BF30-BG30-DF30-B2(H30-D)H30-BG30-2B30-GB2(30-HD)30-HB30-FD30-GB30-FB30-LG30-UG30-EB30-GH30-OG30-CD30-HG30-3CHCOGEULFGF3HG2B2DBD2B2GBHGD2GH3GDBD7BHBHGHSHMUREBALF4H30-GH30-GF30-GL30-DA30-2B30-DE30-BR30-BU30-BM30-BH30-BS30-BH30-BG30-2H30-2B30-2H30-GB30-HB30-SB30-HB30-MB30-UB30-RB30-ED30-2B30-AD30-LG30-FG30-HG30-4HFLABERUMHSHGHBH7BDBD4GX3CGDHBG2HG3HGHGCS2LY2AEAMXC3X30-2C30-CX30-CM30-GA30-DE30-HA30-BA30-GY2(30-HL)30-GS30-HC30-HG30-2H30-2G30-2H30-GH30-CH30-SG2(30-LH)30-YG30-AB30-AH30-ED30-AG30-MC30-XC30-2C30-3XCXMAE2AY2LSCGHG3HG2HGBHDG3CGCFOQ3F2S2TCFTF2TFPFCL2AEB2RMX3C30-FX30-OM30-Q2(R30-F)B30-FE2(30-SA)30-TL30-TC30-CF30-FP30-TF30-FT30-2T30-TF30-FT30-PF30-FC30-CT30-LT2(30-AS)30-EF30-B2(F30-R)Q30-MO30-XF30-3CXM2RBE2ALCFPF2TFTFC2T2S3FQO2FWCQSH3DG2DGHDH2GCSLU4AEL2BXHWH30-CX30-QB30-SB30-HL30-DE2(30-DA)30-G2(A30-D)U30-GL30-HS30-DC30-HG30-2G30-GH30-CD30-SH30-LG30-U2(D30-A)G2(30-AD)30-ED30-LH30-BS30-BQ30-XC30-HWHX2BLE4AULSC2GHDHG2DG3DHSQCFHSAjA6E2AE2A2E2BE5A3EAV3H30-SV30-AjA30-AE2(30-2E)4(30-EA)30-2A30-AE30-E2(B30-A)E30-2E30-E2(A30-B)E30-EA30-2A4(30-AE)2(30-2E)30-EA30-AAj30-VS30-3HVA3E5AE2B2E2AE2A6EAAjSUCO2(EA)2E21AEBCB30-OE2(30-EA30-2A)2(30-EA)15(30-2A)2(30-AE)2(30-2A30-AE)30-EO30-BCBE21A2E2(AE)OQH4AUAESEU2AO2AE2AAk4AEOLAdABAHA30-AB30-2A30-AAd30-AL30-UO30-AE30-EA30-SA30-EA30-UA30-AAk30-2A30-OA30-AE30-2A30-EA30-AO30-2A30-AkA30-AU30-AE30-AS30-AE30-EA30-OU30-LA30-AdA30-2A30-BA30-AHABAAdLOE4AAk2AE2AO2AUESEAU4AUSE3AO2EQEFEAM2AEAAlCAe5AL4ASA30-EA2(30-2A)30-AL30-O2(A30-E)A30-QA30-EA30-FAe30-EC30-AAl30-MA30-AE30-2A30-EA30-AM30-AlA30-CE30-AeF30-AE30-AQ2(30-AE)30-AO30-LA2(30-2A)30-AE30-AS4AL5AAeCAlAE2AMAEFEQ2EO3AEMF2(AE)MDQMAMQOMAEAFEDPZ4AL4AF2(A30-2A30-E)L30-MA30-DA30-QA30-MA30-AZ30-MP30-QD30-OE30-MF30-2A30-2E30-2A30-FM30-EO30-DQ30-PM30-ZA30-AM30-AQ30-AD30-AM30-L2(E30-2A30-A)F4AL4AZPDEFAEAMOQMAMQDM2(EA)LF3EAOB3EY2AM2ADAmGKEIZ3AR4AF3(A30-E)A30-AR30-OA30-B2(A30-E)Z30-EI30-YE30-AK30-AG30-MAm30-AD30-2A30-DA30-AmM30-GA30-KA30-EY30-IE30-Z2(E30-A)B30-AO30-RA3(30-AE)30-AF4AR3AZIEKGAmD2AM2AY3EBOA3EROEADMQR2AELEAMAG3KD2PAeAEAO4AOA30-EA30-2A30-DA30-MO30-QA30-RE30-2A30-AAe30-EP30-LP30-ED30-AK30-MK30-AK30-2G30-KA30-KM30-KA30-DE30-PL30-PE30-AeA30-2A30-ER30-AQ30-OM30-AD30-2A30-AE30-AO4AOAEAAe2PD3KGAMAELE2ARQMDAELP2A2ERE3AB2O3ABAfZBAfAn2ADFLR2EAPA2(30-AE)30-ER30-EL30-RF30-ED2(30-2A)30-AAn30-BAf30-OB30-OZ30-AAf30-AB30-2A30-BA30-AfA30-ZO30-BO30-AfB30-AnA2(30-2A)30-DE30-FR30-LE30-RE2(30-EA)30-APA2ERLFD2AAnAfBZAfB3A2OB3AER2E2A2LAdEA3E3AE6ABA2E3A2E2(KE)VLV30-AdE30-EK30-AE30-EK2(30-2E)3(30-2A)30-2E30-AE30-2A30-AB3(30-2A)30-BA30-2A30-EA30-2E3(30-2A)2(30-2E)30-KE30-EA30-KE30-EAd30-VLV2(EK)2E3A2EAB6AE3A3EAEAd2TBREA2E2A2EAE3A3EAE3AE2AEANVTV30-BN30-RA30-2E30-2A30-EA30-2E2(30-2A)30-EA30-2E30-2A30-2E2(30-AE)30-2A2(30-EA)30-2E30-2A30-2E30-AE2(30-2A)30-2E30-AE30-2A30-2E30-AR30-NB30-VTVNAE2AE3AEA3E3AEA2E2A2EAERBKNIGI2PNIJCFNJIJAo5I3NI2N2AaApINI30-IAp30-GAa30-IAa2(30-PN)30-NI30-IN30-JN30-CN30-FI30-NI30-JI30-2I30-JI30-2Ao30-IJ30-2I30-IJ30-IN30-IF30-NC30-NJ30-NI30-IN2(30-NP)30-AaI30-AaG30-ApI30-INIAp2Aa2NI3N5IAoJIJNFCJIN2PIG3(IP)CIAbD2J2G2(2JG)J2IAb2NGPAbAaPAg3I30-PAg30-IP30-PAa30-CAb30-IP30-AbG30-D2(N30-J)Ab2(30-GI)2(30-2J30-JG30-GJ)30-2J2(30-IG)30-Ab2(J30-N)D30-GAb30-PI30-AbC30-AaP30-PI30-AgP30-3IAgPAaAbPG2NAb2IJ2(G2J)2G2JDAbICPI2PINDID2I4DIDG4DHJBJIT2GI3N3I30-2N30-DN30-IN30-DI2(30-IG)30-DT30-DI30-DJ30-DB30-IJ30-DH30-GD3(30-2D)30-DG30-HD30-JI30-BD30-JD30-ID30-TD2(30-GI)30-ID30-NI30-ND30-2N30-3I3NI2GTIJBJH4DGDI4D2IDIDNID5IJDK2J2D4BE2BEB3VBAg2V4D30-ID2(30-IV)30-IAg30-IB30-JV30-DV30-KV30-JB30-JE2(30-DB)30-BE3(30-2B)30-EB2(30-BD)30-EJ30-BJ30-VK30-VD30-VJ30-BI30-Ag2(I30-V)I30-DI30-4D2VAgB3VBE2BE4B2D2JKDJ6ID5IJHJ2DBD4BG6BDB4DKDK4(30-ID)30-IB30-JD30-HB30-J2(B30-D)B30-2B30-DB30-BG3(30-2B)30-GB30-BD30-2B2(30-BD)30-BJ30-BH30-DJ30-B4(I30-D)I30-KDK4DBD6BG4BDB2DJHJ6IK3J4D2(2BD)7BED2BK2D2KDKD2(30-JK)30-JD30-2D30-DK2(30-DB)30-BD30-BE2(30-DB2(30-2B))30-2B30-BD2(30-2B)30-BD30-EB30-DB2(30-BD)30-KD30-2D30-D2(J30-K)J30-DKD2K2DK2BDE7B2(D2B)4D3JID5K6BKBD5BDBKJ2(2K2D)I3J4D2(2BD)7BED2BK2D2KDK6IJHJ2DBD4BG6BDB4DKD6IJDK2J2D4BE2BEB3VBAg2V3DINDID2I4DIDG4DHJBJIT2GI3N2I2PIPCIAbD2J2G2(2JG)J2IAb2NGPAbAaPAg2IPIGI2PNIJCFNJIJAo5I3NI2N2AaApINKBREA2E2A2EAE3A3EAE3AE2AEANV2TAdEA3E3AE6ABA2E3A2E2(KE)V2L2A2ERE3AB2O3ABAfZBAfAn2ADFLR2EAPLEADMQR2AELEAMAG3KD2PAeAEAO4AOR3EAOB3EY2AM2ADAmGKEIZ3AR4AFL2(AE)MDQMAMQOMAEAFEDPZ4AL4AFME3AO2EQEFEAM2AEAAlCAe5AL4ASU4AUAESEU2AO2AE2AAk4AEOLAdABAHQO2(EA)2E21AEBCUSAjA6E2AE2A2E2BE5A3EAV2HFCQSH3DG2DGHDH2GCSLU4AEL2BXHW2FOQ3F2S2TCFTF2TFPFCL2AEB2RMX2CG3CGDHBG2HG3HGHGCS2LY2AEAMXC2X4GDBD7BHBHGHSHMUREBALF3H2GDGHB2G2BDB2D2BG3HFGFLUEGOCH2CB2DHB2DB2(DH)B4DG3HCFMCU2EM2(CG)CX4HG2DBDEB2D2G4CWQAiLYEUAcFCFHCGHDCHBHC4BDGD4CTQAhLAcWYQ2FGD2G2BDHD4BGBDGBHG4CMQLRMW3FH2C3GFHDG2DGHCHG2F4CF4WFCF2G3CGFC2FGCB3FCDF2CFC2H4C3F3CFC2FCGC2FG4FH3F2CHBXFGC3FCFGFH2(CFG)FGHFC5FHFEF2CGC3FCF3C3FCF4CGCH3CDG3BD2H4F2(2D2K)JKBD5BDBK6B5KD
