model
size = 27 13 20, scale = 0.05, origin = -y
material 
  colors = A:#111 B:#CF3
voxels
---------------AAAA-------- --------------AAAAAA------- --------------AABBAA------- --------------AABBAA------- --------------AAAAAA------- ---------------AAAA-------- --------------------------- --------------------------- --------------------------- --------------------------- --------------------------- --------------------------- --------------------------- 
---------------AAAA-------- --------------AAAAAA------- -----BBBBBBBBBAAAAAABB----- ------------BBAAAAAABB----- ------------BBAAAAAABB----- ------------BBBAAAABBB----- -------------BBBBBBBB------ --------------BBBBBB------- --------------------------- --------------------------- --------------------------- --------------------------- --------------------------- 
--------------------------- --------------------------- ---BBAAAAAAAAA-----AAABB--- ----------AAAAAAAAAAAAAA--- -----------AAAAAAAAAAAA---- -----------AAAAAAAAAAAA---- -----------AAAAAAAAAAAA---- ------------AAAAAAAAAA----- -------------AAABBAAA------ ----------------BB--------- --------------------------- --------------------------- --------------------------- 
--------------------------- --------------------------- --BAAAAAAAAA---------AAAB-- ---------BAAAA-----AAAAAA-- ----------AAAAAAAAAAAAAA--- ----------AAAAAAAAAAAAAA--- ----------AAAAAAAAAAAAAA--- -----------AAAAAAAAAAAA---- ------------AAAAAAAAAA----- -------------AAAAAAAA------ ----------------BB--------- --------------------------- --------------------------- 
--------------------------- --------------------------- -BAAAAAAAA-------------AB-- ---------BAA---------AAAA-- ---------BAAAA-----AAAAAA-- ---------BAAAA-----AAAAAA-- ---------BAAAA-----AAAAAA-- ----------AAAA-----AAAAA--- -----------AAA-----AAAA---- ------------AAAAAAAAAA----- -------------AAABBAAA------ --------------------------- --------------------------- 
--------------------------- --------------------------- -BAAAAAAAA-------------AAB- --------AAA-----------AAAA- --------AAAA---------AAAAA- --------AAAA---------AAAAA- ---------BAA---------AAAA-- ---------BAA---------AAAA-- ----------AA---------AAA--- -----------AAA-----AAAA---- ------------AAAAAAAAAA----- --------------AABBAA------- --------------------------- 
--------------------------- --------------------------- BAAAAAAAA---------------AB- --------AA-------------AAA- --------AAA-----------AAAA- --------AAA-----------AAAA- --------AAA-----------AAAA- ---------BA-----------AAA-- ---------BA-----------AAA-- ----------AAA-------AAAA--- -----------AAAAAAAAAAAA---- -------------AAABBAAA------ --------------------------- 
--------------------------- --------------------------- BAAAAAAAA---------------AAB -------BAA-------------AAAB -------BAAA-----------AAAAB --------AAA-----------AAAA- --------AAA-----------AAAA- --------AAA-----------AAAA- ---------BA-----------AAA-- ----------AA---------AAA--- -----------AAAAAAAAAAAA---- ------------AAAAAAAAAA----- ---------------BBBB-------- 
--------------------------- --------------------------- BAAAAAAA-----------------AB -------BA---------------AAB -------BAA-------------AAAB -------BAA-------------AAAB --------AA-------------AAA- --------AA-------------AAA- ---------B-------------AA-- ----------A-----------AA--- -----------AAAAAAAAAAAA---- ------------AAAAAAAAAA----- --------------BBBBBB------- 
--------------------------- --------------------------- BAAAAAAA-----------------AA -------AA---------------AAA -------BAA-------------AAAB -------BAA-------------AAAB --------AA-------------AAA- --------AA-------------AAA- ---------B-------------AA-- ---------BA-----------AAA-- ----------AAAAAAAAAAAAAA--- ------------AAAAAAAAAA----- --------------BBAABB------- 
--------------------------- --------------------------- BAAAAAAA-----------------AA -------AA---------------AAA -------BAA-------------AAAB -------BAA-------------AAAB --------AA-------------AAA- --------AA-------------AAA- ---------B-------------AA-- ---------BA-----------AAA-- ----------AAAAAAAAAAAAAA--- ------------AAAAAAAAAA----- --------------BBAABB------- 
--------------------------- --------------------------- BAAAAAAA-----------------AB -------BA---------------AAB -------BAA-------------AAAB -------BAA-------------AAAB --------AA-------------AAA- --------AA-------------AAA- ---------B-------------AA-- ----------A-----------AA--- -----------AAAAAAAAAAAA---- ------------AAAAAAAAAA----- --------------BBBBBB------- 
--------------------------- --------------------------- BAAAAAAA-----------------AB -------BA---------------AAB -------BAA-------------AAAB --------AA-------------AAA- --------AA-------------AAA- --------AA-------------AAA- ---------B-------------AA-- ----------A-----------AA--- -----------AAAAAAAAAAAA---- ------------AAAAAAAAAA----- ---------------BBBB-------- 
--------------------------- --------------------------- BAAAAAAAA---------------AB- --------AA-------------AAA- --------AAA-----------AAAA- --------AAA-----------AAAA- --------AAA-----------AAAA- ---------BA-----------AAA-- ---------BA-----------AAA-- ----------AA---------AAA--- -----------AAAAAAAAAAAA---- -------------AAABBAAA------ --------------------------- 
--------------------------- --------------------------- -BAAAAAAA---------------AB- --------AA-------------AAA- --------AAA-----------AAAA- --------AAA-----------AAAA- ---------BA-----------AAA-- ---------BA-----------AAA-- ----------A-----------AA--- -----------AA-------AAA---- ------------AAAAAAAAAA----- --------------AABBAA------- --------------------------- 
--------------------------- --------------------------- -BAAAAAAAA-------------AB-- ---------BA-----------AAA-- ---------BAA---------AAAA-- ---------BAA---------AAAA-- ---------BAA---------AAAA-- ----------AA---------AAA--- -----------A---------AA---- ------------AA-----AAA----- -------------AAABBAAA------ --------------------------- --------------------------- 
--------------------------- --------------------------- --BAAAAAAA-------------AB-- ---------BAA---------AAAA-- ----------AAAA-----AAAAA--- ----------AAAA-----AAAAA--- ----------AAAA-----AAAAA--- -----------AAA-----AAAA---- ------------AA-----AAA----- -------------AAAAAAAA------ ----------------BB--------- --------------------------- --------------------------- 
--------------------------- --------------------------- ---BBAAAAAAA---------ABB--- ----------AAAA-----AAAAA--- -----------AAAAAAAAAAAA---- -----------AAAAAAAAAAAA---- -----------AAAAAAAAAAAA---- ------------AAAAAAAAAA----- -------------AAABBAAA------ ----------------BB--------- --------------------------- --------------------------- --------------------------- 
---------------AAAA-------- --------------AAAAAA------- -----BBBBBBBBBAAAAAABB----- ------------BBAAAAAABB----- ------------BBAAAAAABB----- ------------BBBAAAABBB----- -------------BBBBBBBB------ --------------BBBBBB------- --------------------------- --------------------------- --------------------------- --------------------------- --------------------------- 
---------------AAAA-------- --------------AAAAAA------- --------------AABBAA------- --------------AABBAA------- --------------AAAAAA------- ---------------AAAA-------- --------------------------- --------------------------- --------------------------- --------------------------- --------------------------- --------------------------- --------------------------- 
