model
size = 31 30 9, scale = 0.05, origin = -y
material 
  colors = A:#777 B:#956D95 C:#222 D:#0FC E:#C0FF61 F:#555 G:#8BFFD0 H:#8CCCCC I:#CC8FB7 J:#3CF K:#399 L:#EEE M:#DCEFDC
voxels
------------------------------- ------------------------------- ----------C---------C---------- ----------C---------C---------- ---------AC---------CA--------- ---------AC---------CA--------- ---------AC---------CA--------- ---------AC---------CA--------- ---------ACC-------CCA--------- ---------ACCC-----CCCA--------- ----------BCCC---CCCB---------- ----------BBCCCCCCCBB---------- -----------BCBCKCBCB----------- -----------BBBCKCBBB----------- ------------BBCKCBB------------ ------------BCKKKCB------------ ------------BBCKCBB------------ ------------BCKKKCB------------ ------------CKKDKKC------------ ------------FCDDDCF------------ ------------CFDDDFC------------ -----------FFCDJDCFF----------- -----------FCDDJDDCF----------- -----------CFDJJJDFC----------- -----------FDDJ-JDDF----------- -------------J---J------------- ------------------------------- ------------------------------- ------------------------------- ------------------------------- 
------------------------------- ------------------------------- ------------------------------- ------------------------------- ------------------------------- ---------A-----------A--------- ---------A-----------A--------- ---------A-----------A--------- ---------A-----------A--------- ---------AA---------AA--------- ---------AA---------AA--------- ---------ALA-------ALA--------- ----------FAA-----AAA---------- ----------FLA-----AMA---------- -----------AA-----AA----------- -----------AA-----AA----------- -----------AA-----AA----------- -----------AA-----AA----------- -----------AA-----AA----------- -----------AA-----AA----------- -----------AA------A----------- -----------A-------A----------- -----------A-------A----------- -----------A-------A----------- -----------AAA---AAA----------- -----------FDJ---JDF----------- -----------DJ-----JD----------- ------------------------------- ------------------------------- ------------------------------- 
------------------------------- ------------------------------- ------------------------------- ------------------------------- ------------------------------- ------------------------------- ------------------------------- ------------------------------- ---------A-----------A--------- ---------A-----------A--------- ------------------------------- ---------AA---------AA--------- ---------AA---------AA--------- ----------AA-------AA---------- ----------AA-------AA---------- ----------AA-------AA---------- -----------A-------A----------- -----------A-------A----------- -----------A-------A----------- -----------A-------A----------- -----------A-------A----------- -----------A-------A----------- ----------AA-------AA---------- ----------AA-------AA---------- ----------AA-------AA---------- ----------AA-------AA---------- ----------ALA-----AAA---------- ----------ADJ-----JDA---------- ------------------------------- ------------------------------- 
------------------------------- ------------------------------- ------------------------------- ------------------------------- ------------------------------- ------------------------------- ------------------------------- ------------------------------- ------------------------------- ---------A-----------A--------- ---------A-----------A--------- ------------------------------- ---------AA---------AA--------- ---------AA---------AA--------- ----------A---------A---------- ----------AA--------A---------- ----------AA-------AA---------- -----------A-------A----------- -----------A-------A----------- -----------A-------A----------- -----------A-------A----------- ----------AA-------AA---------- ----------AA--------A---------- ----------A---------A---------- ------------------------------- ------------------------------- ------------------------------- ----------AAA-----AAA---------- ----------FDJ-----JDF---------- ------------------------------- 
------------------------------- ------------------------------- ------------------------------- ------------------------------- ------------------------------- ------------------------------- ------------------------------- ------------------------------- ------------------------------- ---------A-----------A--------- ------------------------------- ---------A-----------A--------- ------------------------------- ---------AA---------AA--------- ----------A---------A---------- ----------AA--------A---------- ----------AA-------AA---------- -----------A-------A----------- -----------A-------A----------- -----------A-------A----------- ----------AA-------AA---------- ----------AA--------A---------- ----------A---------A---------- ------------------------------- ------------------------------- ------------------------------- ------------------------------- ------------------------------- ----------AAA-----AAA---------- ----------FDJ-----JDF---------- 
------------------------------- ------------------------------- ------------------------------- ------------------------------- ------------------------------- ------------------------------- ------------------------------- ------------------------------- ------------------------------- ---------A-----------A--------- ---------A-----------A--------- ------------------------------- ---------AA---------AA--------- ---------AA---------AA--------- ----------AA--------A---------- ----------AA-------AA---------- ----------AA-------AA---------- -----------A-------A----------- -----------A-------A----------- -----------A-------A----------- ----------AA-------AA---------- ----------AA-------AA---------- ----------A---------A---------- ------------------------------- ------------------------------- ------------------------------- ------------------------------- ------------------------------- ----------A---------A---------- ----------FFJ-----JFF---------- 
------------------------------- ------------------------------- ------------------------------- ------------------------------- ------------------------------- ------------------------------- ------------------------------- ------------------------------- ---------A-----------A--------- ---------A-----------A--------- ------------------------------- ---------AA----------A--------- ---------AA---------AA--------- ----------AA-------AA---------- ----------AA-------AA---------- ----------AA-------AA---------- -----------A-------A----------- -----------A-------A----------- -----------A-------A----------- -----------A-------A----------- -----------A-------A----------- ----------AA-------AA---------- ----------AA-------AA---------- ----------AA-------AA---------- ----------AA--------A---------- ------------------------------- ------------------------------- ----------A---------A---------- ----------AAA-----AAA---------- ----------FFFJ---JFFF---------- 
------------------------------- ------------------------------- ---------A-----------A--------- ---------A-----------A--------- ---------A-----------A--------- ---------A-----------A--------- ---------A-----------A--------- ---------A-----------A--------- ---------A-----------A--------- ---------A-----------A--------- ---------A-----------A--------- ---------AA----------A--------- ----------A---------A---------- ----------AAF-----FAA---------- -----------AFF---FFA----------- -----------ABFFFFFBA----------- -----------ABFFFFFBA----------- ------------BBBBBBB------------ ------------BBBBBBB------------ ------------BBB-BBB------------ -----------ABBBBBBBA----------- -----------ABBB-BBBA----------- -----------ABBBBBBBA----------- -----------ABBBBBBBA----------- ----------AMBBBBBBBBA---------- ----------BBBBBBBBBBB---------- ----------BBBBBBBBBBB---------- ----------ABBBB-BBBBA---------- ----------AAA-BBB-AAA---------- ------------BBBBBBB------------ 
------------AAA-AAA------------ -----------AA-A-A-AA----------- ----------AAAA-A-AAAA---------- ----------A-A-A-A-A-A---------- ---------AAAAA---AAAAA--------- ---------A-AA-A-A-AA-A--------- ---------AA-AA-A-AA-AA--------- ---------AAA-AAAAA-AAA--------- ---------AA-AA-A-AA-AA--------- ---------AAAAAA-AAAAAA--------- ----------AA-AAAAA-AA---------- ----------A-AAA-AAA-A---------- -----------AAA-A-AAA----------- -----------A-AAAAA-A----------- ------------AAA-AAA------------ -------------A-A-A------------- ------CCDDE--AAAAA--EDDCC------ -----CCDDEEG-------GEEDDCC----- ----CCDDEEGGH-----HGGEEDDCC---- ----CCDDEEGGHH---HHGGEEDDCC---- ---CCDDEEGGHHI---IHHGGEEDDCC--- ---CCDDEEGGHHI---IHHGGEEDDCC--- ---CCDDEEGGHHI---IHHGGEEDDCC--- ---CCDDEEGGHHI---IHHGGEEDDCC--- --CCDDEEGGHHII---IIHHGGEEDDCC-- -CCDDEEGGHHIII---IIIHHGGEEDDCC- CCDDEEGGHHIII-----IIIHHGGEEDDCC CCDDEEGGHHI---------IHHGGEEDDCC CCDDEEGGH-------------HGGEEDDCC -CCDDE-------------------EDDCC- 
