model
size = 27 24 27, scale = 0.05, origin = -y
material 
  colors = A:#001 B:#004 C:#002 D:#FF0 E:#60F F:#700 G:#A00 H:#00F I:#0D0 J:#3F6
voxels
----------BBBBBBB---------- --------------------------- --------------------------- --------------------------- --------------------------- --------------------------- --------------------------- --------------------------- --------------------------- --------------------------- --------------------------- --------------------------- --------------------------- --------------------------- --------------------------- --------------------------- --------------------------- --------------------------- --------------------------- --------------------------- --------------------------- --------------------------- --------------------------- --------------------------- 
-------BBBBBBBBBBBBB------- --------------------------- --------------------------- --------------------------- --------------------------- --------------------------- --------------------------- --------------------------- --------------------------- --------------------------- --------------------------- --------------------------- --------------------------- --------------------------- --------------------------- --------------------------- --------------------------- --------------------------- --------------------------- --------------------------- --------------------------- --------------------------- --------------------------- --------------------------- 
------BBEBBBBBBBBBBBB------ --------------------------- --------------------------- --------------------------- --------------------------- --------------------------- --------------------------- --------------------------- --------------------------- --------------------------- --------------------------- --------------------------- --------------------------- --------------------------- --------------------------- --------------------------- --------------------------- --------------------------- --------------------------- --------------------------- --------------------------- --------------------------- --------------------------- --------------------------- 
----BBBBEBBBBBBBBBBBBBB---- --------------------------- --------------------------- --------------------------- --------------------------- --------------------------- --------------------------- --------------------------- --------------------------- --------------------------- --------------------------- --------------------------- --------------------------- --------------------------- --------------------------- --------------------------- --------------------------- --------------------------- --------------------------- --------------------------- --------------------------- --------------------------- --------------------------- --------------------------- 
---BBBBBEBBBBBBBBBBBBBBB--- --------------------------- --------------------------- --------------------------- --------------------------- --------------------------- --------------------------- --------------------------- --------------------------- --------------------------- --------------------------- --------------------------- --------------------------- --------------------------- --------------------------- --------------------------- --------------------------- --------------------------- --------------------------- --------------------------- --------------------------- --------------------------- --------------------------- --------------------------- 
---BBBBBEBBBBBBBBBBBBBBB--- ----------DDDDDDD---------- ----------AAAAAAA---------- ----------AAAAAAA---------- ----------AAAAAAA---------- ----------AAAAAAA---------- ----------AAAAAAA---------- ----------AAAAAAA---------- ----------AAAAAAA---------- ----------AAAAAAA---------- ----------EEAAAAA---------- ----------EEEEAAA---------- ----------AAEAAAA---------- ----------EEEAAAA---------- ----------EAAAAAA---------- ----------AAAAAAA---------- ----------AAAAAAA---------- ----------AAAAAAA---------- ----------AAAAAAA---------- ----------AAAAAAA---------- ----------AAAAAAA---------- ----------CCCCCCC---------- --------------------------- --------------------------- 
--BBBBBBBB-------BBBBBBBB-- --------DD-------DD-------- --------AA-------AA-------- --------AA-------AA-------- --------AA-------AA-------- --------AA-------AA-------- --------AA-------AA-------- --------AA-------AA-------- --------AA-------AA-------- --------AA-------AA-------- --------EE-------AA-------- --------EE-------AA-------- --------AA-------AA-------- --------AA-------AA-------- --------AA-------AA-------- --------AA-------AA-------- --------AA-------AA-------- --------AA-------AA-------- --------FA-------AA-------- --------AA-------AA-------- --------AA-------AA-------- --------CCCCCCCCCCC-------- --------------------------- --------------------------- 
-BBBBBBB-----------BBBBBBB- -------D-----------D------- -------A-----------A------- -------A-----------A------- -------A-----------A------- -------A-----------A------- -------A-----------A------- -------A-----------A------- -------A-----------A------- -------A-----------A------- -------E-----------A------- -------E-----------A------- -------F-----------A------- -------F-----------A------- -------F-----------A------- -------F-----------A------- -------A-----------A------- -------F-----------A------- -------A-----------A------- -------A-----------A------- -------A-----------A------- -------CCCCCCCCCCCCC------- --------------------------- --------------------------- 
-BBBBBB-------------BBBBBB- ------D-------------D------ ------A-------------A------ ------A-------------A------ ------A-------------A------ ------A-------------A------ ------A-------------I------ ------A-------------A------ ------A-------------A------ ------A-------------A------ ------A-------------A------ ------F-------------A------ ------F-------------A------ ------A-------------A------ ------F-------------H------ ------F-------------H------ ------A-------------A------ ------A-------------H------ ------A-------------A------ ------A-------------A------ ------A-------------A------ ------CCCCCCCCCCCCCCC------ --------------------------- --------------------------- 
-BBBBB---------------BBBBB- -----D---------------D----- -----A---------------A----- -----A---------------A----- -----A--------------AA----- -----A--------------AI----- -----A--------------AI----- -----A--------------AI----- -----A--------------AA----- -----A--------------AA----- -----F--------------AA----- -----F--------------AA----- -----A--------------AA----- -----A--------------AH----- -----A--------------AH----- -----F--------------AH----- -----F--------------AA----- -----A--------------AH----- -----A--------------AA----- -----A--------------AA----- -----A--------------AA----- -----CCCCCCCCCCCCCCCCC----- --------------------------- --------------------------- 
BBBBBB---------------BBBBBB -----D---------------D----- -----A---------------A----- -----A---------------A----- -----A---------------A----- -----A---------------A----- -----A---------------A----- -----A---------------A----- -----A---------------A----- -----A---------------A----- -----A---------------A----- -----A---------------A----- -----A---------------A----- -----F---------------A----- -----A---------------A----- -----F---------------A----- -----F---------------H----- -----F---------------H----- -----A---------------A----- -----A---------------A----- -----A---------------A----- -----CCCCCCCCCCCCCCCCC----- --------------------------- --------------------------- 
BBBBB-----------------BBBBB ----D-----------------D---- ----A-----------------A---- ----A-----------------A---- ----A-----------------A---- ----A-----------------A---- ----A-----------------A---- ----A-----------------A---- ----A-----------------A---- ----A-----------------A---- ----A-----------------A---- ----A-----------------A---- ----A-----------------A---- ----F-----------------A---- ----F-----------------A---- ----F-----------------A---- ----A-----------------H---- ----F-----------------A---- ----A-----------------A---- ----A-----------------A---- ----A-----------------A---- --------------------------- ----CCCCCCCCCCCCCCCCCCC---- --------------------------- 
BBBBB-----------------BBBBB ----D-----------------D---- ----A-----------------A---- ----A-----------------A---- ----A-----------------A---- ----A-----------------A---- ----A-----------------A---- ----A-----------------A---- ----A-----------------A---- ----A-----------------A---- ----A-----------------A---- ----A-----------------A---- ----A-----------------A---- ----A-----------------A---- ----F-----------------A---- ----A-----------------A---- ----A-----------------A---- ----A-----------------A---- ----A-----------------A---- ----A-----------------A---- ----A-----------------A---- --------------------------- ----CCCCCCCCCJCCCCCCCCC---- --------------------------- 
BBBBB-----------------BBBBJ ----D-----------------D---- ----A-----------------A---- ----A-----------------A---- ----A-----------------A---- ----A-----------------A---- ----A-----------------A---- ----A-----------------A---- ----A-----------------A---- ----A-----------------A---- ----A-----------------A---- ----A-----------------A---- ----A-----------------A---- ----A-----------------A---- ----F-----------------A---- ----A-----------------A---- ----A-----------------A---- ----A-----------------A---- ----A-----------------A---- ----A-----------------A---- ----A-----------------A---- --------------------------- ----CCCCCCCCCJECCCCCCCC---- --------------------------- 
BBBBB-----------------BBBBB ----D-----------------D---- ----A-----------------A---- ----A-----------------A---- ----A-----------------A---- ----A-----------------A---- ----A-----------------A---- ----A-----------------A---- ----A-----------------A---- ----A-----------------A---- ----A-----------------A---- ----A-----------------A---- ----A-----------------A---- ----A-----------------A---- ----F-----------------A---- ----A-----------------A---- ----A-----------------A---- ----A-----------------A---- ----A-----------------A---- ----A-----------------A---- ----A-----------------A---- --------------------------- ----CCCCCCCCEEECCCCCCCC---- --------------------------- 
BBBBB-----------------BBBBB ----D-----------------D---- ----A-----------------A---- ----A-----------------A---- ----A-----------------A---- ----A-----------------A---- ----A-----------------A---- ----A-----------------A---- ----A-----------------A---- ----A-----------------A---- ----A-----------------A---- ----A-----------------A---- ----A-----------------A---- ----A-----------------A---- ----F-----------------A---- ----A-----------------A---- ----A-----------------A---- ----A-----------------A---- ----A-----------------A---- ----A-----------------A---- ----A-----------------A---- --------------------------- ----CCCCCCEEECEECCCCCCC---- --------------------------- 
BBBBBB---------------BBBBBB -----D---------------D----- -----A---------------A----- -----A---------------A----- -----A---------------A----- -----A---------------A----- -----A---------------A----- -----A---------------A----- -----A---------------A----- -----A---------------A----- -----A---------------A----- -----A---------------A----- -----A---------------A----- -----A---------------A----- -----A---------------A----- -----A---------------A----- -----A---------------A----- -----A---------------A----- -----A---------------A----- -----A---------------A----- -----A---------------A----- --------------------------- --------------------------- -----CCCCCCCCCCCCCCCCC----- 
-BBBBB---------------BBBBB- -----D---------------D----- -----A---------------A----- -----A---------------A----- -----A---------------A----- -----A---------------A----- -----A---------------A----- -----A---------------A----- -----A---------------A----- -----A---------------A----- -----A---------------H----- -----A---------------A----- -----A---------------A----- -----A---------------A----- -----A---------------A----- -----A---------------A----- -----A---------------A----- -----A---------------A----- -----A---------------A----- -----A---------------A----- -----A---------------A----- --------------------------- --------------------------- -----CCCCCCCCCCCCCCCCC----- 
-BBBBBB-------------BBBBBB- ------D-------------D------ ------A-------------A------ ------A-------------A------ ------A-------------A------ ------A-------------A------ ------A-------------A------ ------A-------------A------ ------A-------------A------ ------A-------------A------ ------A-------------A------ ------A-------------A------ ------A-------------A------ ------A-------------A------ ------A-------------A------ ------A-------------A------ ------A-------------A------ ------A-------------A------ ------A-------------A------ ------A-------------G------ ------A-------------A------ --------------------------- --------------------------- ------CCCCCCCCCCCCCCC------ 
-BBBBBBB-----------BBBBBBB- -------D-----------D------- -------A-----------A------- -------A-----------A------- -------A-----------A------- -------A-----------A------- -------A-----------A------- -------A-----------A------- -------A-----------A------- -------A-----------A------- -------A-----------A------- -------A-----------A------- -------A-----------A------- -------A-----------A------- -------A-----------A------- -------A-----------A------- -------A-----------A------- -------A-----------A------- -------A-----------G------- -------A-----------G------- -------A-----------A------- --------------------------- --------------------------- -------CCCCCCCCCCCCC------- 
--BBBBBBBB-------BBBBBBBB-- --------DD-------DD-------- --------AA-------AA-------- --------AA-------AA-------- --------AA-------AA-------- --------AA-------AA-------- --------AA-------AA-------- --------AA-------AA-------- --------AA-------AA-------- --------AA-------AA-------- --------AA-------AA-------- --------AA-------AA-------- --------AA-------AA-------- --------AA-------AA-------- --------AA-------AA-------- --------AA-------AA-------- --------AA-------AA-------- --------AA-------AA-------- --------AA-------GG-------- --------AA-------AG-------- --------AA-------AA-------- --------------------------- --------------------------- --------CCCCCCCCCCC-------- 
---GBBBBBBBBBBBBBBBBBBBB--- ----------DDDDDDD---------- ----------AAAAAAA---------- ----------AAAAAAA---------- ----------AAAAAAA---------- ----------AAAAAAA---------- ----------AAAAAAA---------- ----------AAAAAAA---------- ----------AAAAAAA---------- ----------AAAAAAA---------- ----------AAAAAAA---------- ----------AAGGGAA---------- ----------AAAGGAA---------- ----------AAAAAAA---------- ----------AAAAAAA---------- ----------AAAAAAG---------- ----------AAAAAAG---------- ----------AAAAAAG---------- ----------AAAAAAA---------- ----------AAAAAAA---------- ----------AAAAAAA---------- --------------------------- --------------------------- --------------------------- 
---BBBBBBBBBBBBBBBBBBBBB--- --------------------------- --------------------------- --------------------------- --------------------------- --------------------------- --------------------------- --------------------------- --------------------------- --------------------------- --------------------------- --------------------------- --------------------------- --------------------------- --------------------------- --------------------------- --------------------------- --------------------------- --------------------------- --------------------------- --------------------------- --------------------------- --------------------------- --------------------------- 
----BBBBBBBBBBBBBBBBBBB---- --------------------------- --------------------------- --------------------------- --------------------------- --------------------------- --------------------------- --------------------------- --------------------------- --------------------------- --------------------------- --------------------------- --------------------------- --------------------------- --------------------------- --------------------------- --------------------------- --------------------------- --------------------------- --------------------------- --------------------------- --------------------------- --------------------------- --------------------------- 
------BBBBBBBBBBBBBBB------ --------------------------- --------------------------- --------------------------- --------------------------- --------------------------- --------------------------- --------------------------- --------------------------- --------------------------- --------------------------- --------------------------- --------------------------- --------------------------- --------------------------- --------------------------- --------------------------- --------------------------- --------------------------- --------------------------- --------------------------- --------------------------- --------------------------- --------------------------- 
-------BBBBBBBBBBBBB------- --------------------------- --------------------------- --------------------------- --------------------------- --------------------------- --------------------------- --------------------------- --------------------------- --------------------------- --------------------------- --------------------------- --------------------------- --------------------------- --------------------------- --------------------------- --------------------------- --------------------------- --------------------------- --------------------------- --------------------------- --------------------------- --------------------------- --------------------------- 
----------BBBBBBB---------- --------------------------- --------------------------- --------------------------- --------------------------- --------------------------- --------------------------- --------------------------- --------------------------- --------------------------- --------------------------- --------------------------- --------------------------- --------------------------- --------------------------- --------------------------- --------------------------- --------------------------- --------------------------- --------------------------- --------------------------- --------------------------- --------------------------- --------------------------- 
