model
size = 19 31 25, scale = 0.05, origin = -y
material 
  colors = A:#EEE B:#FAD689 C:#E87A90 D:#66BAB7
voxels
------------------- ------------------- ------------------- ------------------- ------------------- ------------------- ------------------- ------------------- ------------------- ------------------- ------------------- ------------------- ------------------- ------------------- ------------------- ------------------- ------------------- ------------------- ------AA----------- -----AAAA---------- -----AAAA---------- ------AA----------- ------------------- ------------------- ------------------- ------------------- ------------------- ------------------- ------------------- ------------------- ------------------- 
------------------- ------------------- ------------------- ------------------- ------------------- ------------------- ------------------- ------------------- ------------------- ------------------- ------------------- ------------------- ------------------- ------------------- ------------------- ------------------- ------------------- -----AAAA---------- ----AAAAAA--------- ----AAAAAA--------- ----AAAAAA--------- ----AAAAAA--------- -----AAAA---------- ------------------- ------------------- ------------------- ------------------- ------------------- ------------------- ------------------- ------------------- 
------------------- ------------------- ------------------- ------------------- ------------------- ------------------- ------------------- ------------------- ------------------- ------------------- ------------------- ------------------- ------------------- ------------------- ------------------- ------------------- ------AA----------- ----AAAAAA--------- ----AAAAAA--------- ---AAAAAAAA--AA---- ---AAAAAAAA-AAAA--- ----AAAAAA--AAAA--- ----AAAAAA---AA---- ------AA----------- ------------------- ------------------- ------------------- ------------------- ------------------- ------------------- ------------------- 
------------------- ------------------- ------------------- ------------------- ------------------- ------------------- ------------------- ------------------- ------------------- ------------------- ----------D-------- ----------D-------- ----------D-------- ----------D-------- ----------D-------- ----------D-------- -----AAAA-D-------- ----AAAAAAD-------- ---AAAAAAAA-AAAA--- ---AAAAAAAAAAAAAA-- ---AAAAAAAAAAAAAA-- ---AAAAAAAAAAAAAA-- ----AAAAAAAAAAAAA-- -----AAAAAA-AAAA--- ------------------- ------------------- ------------------- ------------------- ------------------- ------------------- ------------------- 
------------------- ------------------- ------------------- ------------------- ------------------- ------------------- ----------D-------- ----------D-------- ----------D-------- ----------D-------- ----------D-------- ------------------- ------------------- ------------------- ------------------- ------------------- -----AAAA---------- ----AAAAAA---AA---- ---AAAAAAAAAAAAAA-- ---AAAAAAAAAAAAAA-- ---AAAAAAAAAAAAAAA- ---AAAAAAAAAAAAAAA- ----AAAAAAAAAAAAA-- -----AAAAAAAAAAAA-- --------AAAA-AA---- ------------------- ------------------- ------------------- ------------------- ------------------- ------------------- 
------------------- ------------------- ------------------- ------------------- ------------------- ----------D-------- ----------D-------- ------------------- ------------------- ------------------- ------------------- ------------------- ------------------- ------------------- ------------------- ------------------- ------AA----------- ----AAAAAA--AAAA--- ----AAAAAAAAAAAAA-- ---AAAAAAAAAAAAAAA- ---AAAAAAAAAAAAAAA- ----AAAAAAAAAAAAAA- ----AAAAAAAAAAAAAA- ------AAAAAAAAAAA-- -------AAAAAAAAA--- ---------AA-------- ------------------- ------------------- ------------------- ------------------- ------------------- 
------------------- ------------------- ------------------- ------------------- ----------D-------- ----------D-------- ------------------- ------------------- ------------------- ------------------- ------------------- ------------------- ------------------- ------------------- ------------------- ------------------- ------------------- -----AAAA---AAAA--- ----AAAAAAAAAAAAA-- ----AAAAAAAAAAAAAA- ----AAAAAAAAAAAAAA- ----AAAAAAAAAAAAAA- ----AAAAAAAAAAAAAA- ----AAAAAAAAAAAAA-- -----AAAAAAAAAAA--- --------AAAA------- ------------------- ------------------- ------------------- ------------------- ------------------- 
------------------- ------------------- ------------------- ------------------- ----------D-------- ------------------- ------------------- ------------------- ------------------- ------------------- ------------------- ------------------- ------------------- ------------------- ------------------- ------------------- ------------------- -----------AAAA---- ------AAAAAAAAAAA-- ----AAAAAAAAAAAAA-- ----AAAAAAAAAAAAAA- ---AAAAAAAAAAAAAAA- ---AAAAAAAAAAAAAA-- ----AAAAAAAAAAAAA-- ----AAAAAAAAAAA---- ------AAAAAAA------ ------------------- ------------------- ------------------- ------------------- ------------------- 
------------------- ------------------- ------------------- ------------------- ----------D-------- ------------------- ------------------- ------------------- ------------------- ------------------- -------------C----- -------------C----- -------------C----- -------------C----- -------------C----- -------------C----- ------------AA----- ----------AAAAAA--- -----AAAAAAAAAAA--- ----AAAAAAAAAAAAA-- ---AAAAAAAAAAAAAA-- ---AAAAAAAAAAAAAA-- --AAAAAAAAAAAAAAA-- --AAAAAAAAAAAAAA--- ---AAAAAAAAAAAA---- -----AAAAAAAAAA---- -------AA-AAAA----- ------------------- ------------------- ------------------- ------------------- 
------------------- ------------------- ------------------- ------------------- ----------D-------- ------------------- -------------C----- -------------C----- ------B------C----- ------B------C----- ------B------C----- ------B------------ ------B------------ ------B------------ ------B------------ ------B------------ ------B--AAAAAA---- ------B-AAAAAAAA--- -----AAAAAAAAAAAA-- ----AAAAAAAAAAAAA-- --AAAAAAAAAAAAAAA-- -AAAAAAAAAAAAAAAA-- -AAAAAAAAAAAAAAA--- -AAAAAAAAAAAAAAA--- -AAAAAAAAAAAAAAA--- --AAAAAAAAAAAAA---- -----AAAAAAAAAA---- ------AAAA-AA------ ------------------- ------------------- ------------------- 
------------------- ------------------- ------B------------ ------B------------ ------B---D--C----- ------B------C----- ------B------C----- ------B------------ ------B------------ ------------------- ------------------- ------------------- ------------------- ------------------- ------------------- --------AAAA------- -------AAAAAAAA---- -------AAAAAAAAA--- ------AAAAAAAAAAA-- ---AAAAAAAAAAAAAA-- -AAAAAAAAAAAAAAAA-- -AAAAAAAAAAAAAAAA-- AAAAAAAAAAAAAAAAA-- AAAAAAAAAAAAAAAAA-- -AAAAAAAAAAAAAAA--- -AAAAAAAAAAAAAAA--- ---AAAAAAAAAAAA---- -----AAAAAAAAA----- -------AA---------- ------------------- ------------------- 
------------------- ------B------------ ------B------------ -------------C----- ----------D--C----- ----------D-------- ------------------- ------------------- ------------------- ------------------- ------------------- ------------------- ------------------- ------------------- ---------AA-------- -------AAAAAA------ -------AAAAAAA----- ------AAAAAAAAAA--- ------AAAAAAAAAA--- --AAAAAAAAAAAAAAA-- -AAAAAAAAAAAAAAAA-- AAAAAAAAAAAAAAAAAA- AAAAAAAAAAAAAAAAAA- AAAAAAAAAAAAAAAAAA- AAAAAAAAAAAAAAAAAA- -AAAAAAAAAAAAAAAA-- --AAAAAAAAAAAAA---- -----AAAAAAAAA----- ------AAAAAA------- ------------------- ------------------- 
------B------------ ------B------------ ------------------- -------------C----- ------------------- ----------D-------- ----------D-------- ------------------- ------------------- ------------------- ------------------- ------------------- ------------------- ------------------- --------AAAA------- -------AAAAAA------ ------AAAAAAAA----- ------AAAAAAAAA---- ------AAAAAAAAAA--- --AAAAAAAAAAAAAA--- -AAAAAAAAAAAAAAAAA- AAAAAAAAAAAAAAAAAA- AAAAAAAAAAAAAAAAAAA AAAAAAAAAAAAAAAAAAA AAAAAAAAAAAAAAAAAA- -AAAAAAAAAAAAAAAAA- --AAAAAAAAAAAAAA--- -----AAAAAAAAA----- ------AAAAAAAA----- ---------AAAA------ ------------------- 
------B------------ ------------------- ------------------- -------------C----- ------------------- ------------------- ----------D-------- ----------D-------- ----------D-------- ----------D-------- ----------D-------- ----------D-------- ----------D-------- ----------D-------- --------AAAA------- -------AAAAAA------ ------AAAAAAAA----- ------AAAAAAAA----- ----AAAAAAAAAA----- ---AAAAAAAAAAAAAA-- -AAAAAAAAAAAAAAAAA- -AAAAAAAAAAAAAAAAAA AAAAAAAAAAAAAAAAAAA AAAAAAAAAAAAAAAAAAA -AAAAAAAAAAAAAAAAAA -AAAAAAAAAAAAAAAAA- ---AAAAAAAAAAAAAA-- -----AAAAAAAAAA---- -------AAAAAAA----- --------AAAAAA----- ----------AA------- 
------B------------ ------------------- ------------------- -------------C----- ------------------- ------------------- ------------------- ------------------- ------------------- ------------------- ------------------- ------------------- ------------------- ------------------- ---------AA-------- -------AAAAAA------ -------AAAAAA------ ---AAAAAAAAAAA----- --AAAAAAAAAAAAA---- --AAAAAAAAAAAAAAA-- --AAAAAAAAAAAAAAAA- -AAAAAAAAAAAAAAAAAA -AAAAAAAAAAAAAAAAAA -AAAAAAAAAAAAAAAAAA -AAAAAAAAAAAAAAAAAA --AAAAAAAAAAAAAAAA- ------AAAAAAAAAAA-- -----AAAAAAAAAA---- -------AAAAAAAA---- --------AAAAAA----- ---------AAAA------ 
------B------------ ------------------- ------------------- -------------C----- -------------C----- ------------------- ------------------- ------------------- ------------------- ------------------- ------------------- ------------------- ------------------- ------------------- ------------------- --------AAAA------- ----AA-AAAAAA------ --AAAAAAAAAAAA----- --AAAAAAAAAAAAA---- -AAAAAAAAAAAAAAA--- -AAAAAAAAAAAAAAAAA- --AAAAAAAAAAAAAAAA- --AAAAAAAAAAAAAAAAA --AAAAAAAAAAAAAAAAA ---AAAAAAAAAAAAAAA- ------AAAAAAAAAAAA- -------AAAAAAAAA--- -------AAAAAAAA---- ------AAAAAAAAA---- --------AAAAAA----- ---------AAAA------ 
------B------------ ------------------- ------------------- ------------------- -------------C----- -------------C----- -------------C----- ------------------- ------------------- ------------------- ------------------- ------------------- ------------------- ------------------- ------------------- ------------------- ---AAAA--AA-------- --AAAAAAAAAAAA----- -AAAAAAAAAAAAAA---- -AAAAAAAAAAAAAAA--- -AAAAAAAAAAAAAAAA-- -AAAAAAAAAAAAAAAAA- --AAAAAAAAAAAAAAAA- ---AAAAAAAAAAAAAAA- -----AAAAAAAAAAAAA- ------AAAAAAAAAAA-- -------AAAAAAAA---- -------AAAAAAAA---- ------A-AAAAAA----- --------AAAAAA----- ----------AA------- 
------B------------ ------B------------ ------------------- ------------------- ------------------- ------------------- -------------C----- -------------C----- -------------C----- -------------C----- -------------C----- ------------------- ------------------- ------------------- ------------------- ------------------- ---AAAA------------ --AAAAAA---AA------ -AAAAAAAAAAAAAA---- -AAAAAAAAAAAAAA---- -AAAAAAAAAAAAAAA--- -AAAAAAAAAAAAAAA--- --AAAAAAAAAAAAAAA-- ---AAAAAAAAAAAAAA-- -----AAAAAAAA-AA--- ------AAAAAAAA----- -------AAAAAAA----- --------AAAAAA----- --------AAAAAA----- ---------AAAA------ ------------------- 
------------------- ------B------------ ------B------------ ------B------------ ------------------- ------------------- ------------------- ------------------- ------------------- ------------------- -------------C----- -------------C----- -------------C----- -------------C----- -------------C----- -------------C----- ----AA-------C----- --AAAAAAAAAA-C----- --AAAAAAAAAAAA----- -AAAAAAAAAAAAAA---- -AAAAAAAAAAAAAA---- --AAAAAAAAAAAAA---- --AAAAAAAAAAAAA---- ----AAAAAAAAAA----- -----AAAAAAAA------ ------AAAAAA------- -------AAAAAA------ ---------AAAA------ ----------AA------- ------------------- ------------------- 
------------------- ------------------- ------------------- ------B------------ ------B------------ ------B------------ ------B------------ ------------------- ------------------- ------------------- ------------------- ------------------- ------------------- ------------------- ------------------- ------------------- ---------AA-------- ---AAAAAAAAAA------ --AAAAAAAAAAA------ --AAAAAAAAAAAA----- --AAAAAAAAAAAA----- --AAAAAAAAAAAA----- ---AAAAAAAAAA------ -----AAAAAAAA------ ------AAAAAA------- ------AAAAAA------- --------AA--------- ------------------- ------------------- ------------------- ------------------- 
------------------- ------------------- ------------------- ------------------- ------------------- ------------------- ------B------------ ------B------------ ------B------------ ------B------------ ------B------------ ------B------------ ------B------------ ------B------------ ------B------------ ------B------------ ------B-AAAA------- ------BAAAAAA------ ----AAAAAAAAAA----- ---AAAAAAAAAAA----- ---AAAAAAAAAAA----- ----AAAAAAAAAA----- ------AAAAAAA------ ------AAAAAA------- ------AAAAAA------- -------AAAA-------- ------------------- ------------------- ------------------- ------------------- ------------------- 
------------------- ------------------- ------------------- ------------------- ------------------- ------------------- ------------------- ------------------- ------------------- ------------------- ------------------- ------------------- ------------------- ------------------- ------------------- ------------------- --------AAAA------- -------AAAAAA------ ------AAAAAAAA----- ------AAAAAAAA----- ------AAAAAAAA----- ------AAAAAAAA----- -------AAAAAA------ -------AAAAA------- --------AA--------- ------------------- ------------------- ------------------- ------------------- ------------------- ------------------- 
------------------- ------------------- ------------------- ------------------- ------------------- ------------------- ------------------- ------------------- ------------------- ------------------- ------------------- ------------------- ------------------- ------------------- ------------------- ------------------- ---------AA-------- -------AAAAAA------ -------AAAAAA------ ------AAAAAAAA----- ------AAAAAAAA----- -------AAAAAA------ -------AAAAAA------ ---------AA-------- ------------------- ------------------- ------------------- ------------------- ------------------- ------------------- ------------------- 
------------------- ------------------- ------------------- ------------------- ------------------- ------------------- ------------------- ------------------- ------------------- ------------------- ------------------- ------------------- ------------------- ------------------- ------------------- ------------------- ------------------- --------AAAA------- -------AAAAAA------ -------AAAAAA------ -------AAAAAA------ -------AAAAAA------ --------AAAA------- ------------------- ------------------- ------------------- ------------------- ------------------- ------------------- ------------------- ------------------- 
------------------- ------------------- ------------------- ------------------- ------------------- ------------------- ------------------- ------------------- ------------------- ------------------- ------------------- ------------------- ------------------- ------------------- ------------------- ------------------- ------------------- ------------------- ---------AA-------- --------AAAA------- --------AAAA------- ---------AA-------- ------------------- ------------------- ------------------- ------------------- ------------------- ------------------- ------------------- ------------------- ------------------- 
