model
size = 31 32 17, scale = 0.05, origin = -y
material 
  colors = A:#FF00FE B:#111 C:#CF0
voxels
9-5(13A18-13B18-)2(13A18-)4A5B4A18-3A7B3A18-2A9B2A18-A4B3C4BA18-A3B5C3BA18-A3B2CB2C3BA18-A3B5C3BA18-A4B3C4BA18-2A9B2A17-4A7B4A15-6A5B6A14-8AB8A15-6AB-B6A17-4AB3-B4A202-5(2A13-2A14-2B13-2B14-)3(2A13-2A14-)3A11-3A14-3A11-3A15-4(2A11-2A16-)2A11-2A14-2B2A11-2A2B11-4A13-4A2(10-3A15-3A)11-2A15-2(2A13-)2A15-5AB3-B5A16-4AB5-B4A138-4(A17-A12-B17-B12-)A17-A12-2B15-2B3(12-2A15-2A)13-2(A15-A14-)3(2A13-2A14-)2A13-2A15-A13-A11-3B2-A13-A2-3B3(6-3A19-3A)7-2A19-2A8-4A15-4A9-3A15-3A12-2(A15-)4AB5-B4A106-4(A19-A10-B19-B10-)A19-A11-B17-B5(12-A17-A)13-4(A15-A14-)A15-A9-B4-A15-A4-B2(4-A25-A)4-2A23-2A4-3A21-3A5-3A19-3A6-4A17-4A7-4A15-4A10-2A15-2A14-3AB7-B3A75-4(A19-A10-B19-B10-)A19-A10-2B17-2B2(10-2A17-2A)11-3(A17-A12-)2A15-2A12-2A15-2A13-2(A15-A14-)A15-A8-B5-A15-A5-B2(2-A27-A)2-2A25-2A3-2A23-2A4-3A21-3A4-4A19-4A5-4A17-4A7-4A15-4A11-2A13-2A16-2AB7-B2A45-5(A19-A10-B19-B10-)4(A19-A10-)A19-A11-3(A17-A12-)A17-A13-A15-A8-B5-A15-A5-B3(2-A27-A)2-2A25-2A2-3A23-3A3-3A21-3A4-4A19-4A5-4A17-4A8-3A15-3A2(13-A)17-2B9-2B14-5(A19-A10-B19-B10-)5(A19-A10-)2A17-2A10-2A17-2A11-2(A17-A12-)2A15-2A6-B6-A15-A6-BA2(28-3A)28-2A-A26-2A2-2A25-2A2-3A23-3A3-3A21-3A5-3A19-3A7-4A15-4A11-2(A15-)2(B13-)5(A19-A10-B19-B10-)5(A19-A10-)2(2A17-2A10-)2A17-2A11-A17-A12-2A15-2A6-B5-2A15-2A5-BA3(28-3A)28-2A-A26-2A2-2A25-2A3-2A23-2A4-3A21-3A6-2A19-2A10-2A15-2A14-2(B13-)5(A19-A10-B19-B10-)5(A19-A10-)4(2A17-2A10-)3A15-3A5-B5-2A15-2B5-BA4(28-3A)28-2A-A26-2A2-2A25-2A3-2A23-2A5-3A19-3A9-2A15-2A14-2(B13-)5(A19-A10-B19-B10-)5(A19-A10-)2(2A17-2A10-)2A17-2A11-A17-A12-2A15-2A6-B5-2A15-2A5-BA4(28-3A)28-2A-A26-2A2-2A25-2A3-2A23-2A5-3A19-3A9-2A15-2A14-2(B13-)5(A19-A10-B19-B10-)5(A19-A10-)2A17-2A10-2A17-2A11-2(A17-A12-)2A15-2A6-B6-A15-A6-BA3(28-3A)28-2A-A26-2A2-2A25-2A3-2A23-2A4-3A21-3A6-2A19-2A10-2A15-2A14-2(B13-)5(A19-A10-B19-B10-)4(A19-A10-)A19-A11-3(A17-A12-)A17-A13-A15-A7-B6-A15-A6-BA2(28-3A)28-2A-A26-2A2-2A25-2A2-3A23-3A3-3A21-3A5-4A17-4A7-4A15-4A11-2A14-A16-B12-B13-4(A19-A10-B19-B10-)A19-A10-2B17-2B2(10-2A17-2A)11-2(A17-A12-)A17-A13-4(A15-A14-)A15-A8-B5-A15-A5-B2(2-A27-A)2-A26-2A2-2A25-2A2-3A23-3A3-3A21-3A4-4A19-4A5-4A17-4A8-3A15-3A2(13-A)17-B11-B14-4(A19-A10-B19-B10-)A19-A11-B17-B5(12-A17-A)13-4(A15-A14-)A15-A8-B5-A15-A5-B2(2-A27-A)2-2A25-2A3-2A23-2A4-3A21-3A4-4A19-4A5-4A17-4A7-4A15-4A11-2(A15-)A13-A17-2B9-2B15-4(A17-A12-B17-B12-)A17-A12-2B15-2B3(12-2A15-2A)13-5(A15-A14-)2(A15-)A13-A10-B5-A13-A5-B4-A4-2A13-2A2(4-A)25-A4-2A23-2A4-3A21-3A5-3A19-3A6-4A17-4A7-4A16-3A10-2A15-2A14-2A11-2A17-2A9-2A20-B7-B18-A15-A14-B15-B14-A15-A4(14-17B14-17A)4(14-17A)15-4(15A16-)15A11-4B-15A-4B3(6-25A)7-23A8-23A9-21A12-17A15-15A17-13A19-11A22-7B20-5(15A16-15B16-)2(15A16-)15A17-3(13A18-)5AB2AB4A18-5A2(BA)B3A18-4A2B2(AB)3A18-3A3(BA)B3A18-4A2B2(AB)3A17-15A14-6AB2A2(B4A)12-6A2(BA)B3AB4A12-5A2B2(AB)2A2B4A13-3A5(BA)B3A15-3A2B2AB3A2B2A16-15A18-11A20-11A21-9A42-
