model
size = 14 17 20, scale = 0.05, origin = -y
material 
  colors = A:#E00
voxels
-------------- -------------- -------------- -------------- -------------- -------------- -------------- -------------- -------------- ------A------- ------A------- ------A------- -----AAA------ ------AA------ -------A------ -------------- -------------- 
-------------- -------------- -------------- ------A------- ------A------- ------A------- ------AA------ -----AAA------ -----AAA------ -----AAA------ -----AAA------ ----AAAA------ ----AAAAA----- ---AAAAAAA---- -----AAAA----- ------AA------ ------AA------ 
------A------- ------AA------ -----AAAA----- -----AAAA----- ----AAAAA----- ----AAAAAA---- ----AAAAAA---- ----AAAAAA---- ----AAAAAA---- ----AAAAAA---- ----AAAAAA---- ----AAAAAA---- ---AAAAAAAA--- ---AAAAAAAA--- ----AAAAAA---- ----AAAAA----- ------AA------ 
-------------- -------------- -------------- -------------- -------------- -------------- ---A---------- ---A------A--- ---A------A--- ---A------A--- ---A------A--- ---A------A--- --AA------AA-- --AA------AA-- ---A------A--- -------------- -------------- 
-------------- -------------- -------------- -------------- -------------- -------------- -------------- -------------- --A----------- --A--------A-- --A--------A-- -AA--------AA- -AA--------AA- -AA--------AA- --A--------A-- -------------- -------------- 
-------------- -------------- -------------- -------------- -------------- -------------- -------------- -------------- -------------- -------------- -------------- -------------- -A----------A- -A----------A- -------------- -------------- -------------- 
-------------- -------------- -------------- -------------- -------------- -------------- -------------- -------------- -------------- -------------- -------------- -------------- AA----------AA AA----------AA -------------- -------------- -------------- 
-------------- -------------- -------------- -------------- -------------- -------------- -------------- -------------- -------------- -------------- -------------- -------------- A------------A A------------A -------------- -------------- -------------- 
-------------- -------------- -------------- -------------- -------------- -------------- -------------- -------------- -------------- -------------- -------------- -------------- A------------A A------------A -------------- -------------- -------------- 
-------------- -------------- -------------- -------------- -------------- -------------- -------------- -------------- -------------- -------------- -------------- -------------- A------------A A------------A -------------- -------------- -------------- 
-------------- -------------- -------------- -------------- -------------- -------------- -------------- -------------- -------------- -------------- -------------- -------------- AA----------AA AA----------AA -------------- -------------- -------------- 
-------------- -------------- -------------- -------------- -------------- -------------- -------------- -------------- -------------- -------------- -------------- -------------- -A----------A- -A----------A- -------------- -------------- -------------- 
-------------- -------------- -------------- -------------- -------------- -------------- -------------- -------------- -------------- -------------- -------------- -------------- -AA--------AA- -AA--------AA- -------------- -------------- -------------- 
-------------- -------------- -------------- -------------- -------------- -------------- -------------- -------------- -------------- -------------- -------------- -------------- --A--------A-- --A--------A-- -------------- -------------- -------------- 
-------------- -------------- -------------- -------------- -------------- -------------- -------------- -------------- -------------- -------------- -------------- -------------- --AA------AA-- --AA------AA-- -------------- -------------- -------------- 
-------------- -------------- -------------- -------------- -------------- -------------- -------------- -------------- -------------- -------------- -------------- -------------- ---AA----AA--- ---AA----AA--- -------------- -------------- -------------- 
-------------- -------------- -------------- -------------- -------------- -------------- -------------- -------------- -------------- -------------- -------------- -------------- ----AAAAAA---- ----AAAAAA---- -------------- -------------- -------------- 
-------------- -------------- -------------- -------------- -------------- -----A-------- -----A-------- ----AA-------- ----AA-------- ----AA-------- ----AA-------- ----AAAA------ ----AAAAA----- ----AAAAA----- ------AA------ -------------- -------------- 
-------------- -------------- -------------- -------------- -------------- -------------- -------------- -------------- -----A--A----- -----A--AA---- -----A--AA---- -----AAAAA---- -----AAAAA---- -----AAAAA---- ------AA------ -------------- -------------- 
-------------- -------------- -------------- -------------- -------------- -------------- -------------- -------------- -------------- -------------- --------A----- --------A----- ------AAA----- ------AAA----- -------------- -------------- -------------- 
