model
size = 9 13 32, scale = 0.05, origin = -y
material 
  colors = A:#C00 B:#E40003 C:#D90000 D:#111 E:#222 F:#444
voxels
20-4B6-AC96-AC2B4-2B2-BA4-B2-B6-AC86-CA2(BC)2-C2-B2-C3-AB2-BA4-2C2B84-2(2AC)BA2(-B)-CA-C-A2-AC2-A2-2AB2CA75-B2ABAC2-A2BCB2CB-BA4-BC2(-A)2-B-C2-2A2BAB74-C2ABABCB-C3(BA)C2AC4-B-A2C3-B-A2-AB2A-C4-DE2D66-2CB6AC-2CBAC-ABC5-3BA4-CA-B-C2-CA3-ED2-2D65-B2(3DC)AB2ABAB-2A6-CB2A4-C-CAC3-C-C2-D4-D65-B2DC4D2CA2C3A-BC6-C3A4-A-ABA4-AB2-D4-E65-C3DBDCDBA2CB2CA-2C6-ACBA5-AC2A4-2B2-FE2-2D65-CADBABD2BCBA2-AB-AC6-A3C5-BCBA4-2B3-DEFE66-CDBDA3DA2B5-ABC6-CABA5-3AB5-C73-C4DB2DAC-C4-2ACB6-B2A5-AC-B5-2A72-B3DA3DCB-B3-CBACA6-A-C5-2B-B5-BC72-ACABC2BABC-2ACBACB-B6-B-B5-AC-B5-CB-A5-2B64-CABCA2B2-B-ABC2(A-)2B4-2C-A5-2C-2A4-AC-2C4-CA73-ABCB2AC2(B-)C2-A2B-BA5-A-2C4-2C2-C4-CB7-B65-ACBCA3C-B-A2CBCA-BC5-B-CA4-CB2-B4-AC2-C4-A66-ACBA2C2-C2-2A2-B-A-B2-ABA-AB4-2A2-C4-2B2-B4-B74-ACBAB2C2(B-)A2B2(C-)2C2(4-AC2-C)B3-BC2-BC3-C66-BAB2AC2-A-2BAC-B-AB4-BA2-C4-CB2-AC3-2B2-2B3-C74-C3ACABC2(-A)BC2(A-)2C4-BC2-BA3-2(CB2-)CA3-BC2-2A65-3A2C2B2(C-)2ACB2(-C)B4-CB-AC4-2C2-CA2-A-C2-CA2-AB4-A2-B58-2BCBA2(B2-)ABC-B-A-C3-2B-2A4-BC2-BA2-B-A2(2-2A)4-A2-A59-2AC4-BA3-ACB-C-4A-B-AC4-CA2-BA3-AB2-BA2-2B4-B2-2B4-C2-C24-2D7-BA6-3A6-B2-C3-2B4-B2(C-)B2C2(A-)AC4-2A-B-C3-CA2-2C2-2B3-AB2-CB4-A2-C24-2D7-2A6-C-C6-A2-A3-BA4-2A-C-3CB2(-A)B4-BA-CB4-CA2-2C2-AB3-BC2-BC4-B2-C5-B27-BA7-2C6-A2-A3-2B4-A2-C6-B-A-CB2A-A-CB4-A3-AC2-2A3-CA2-2B4-A2BC5-A2CB41-A2B5-B3-2A2-B5-B2-B-ACB-B2-AC3-AB3-CA2-AB3-A2(C-)A4-2B-C5-B2-B6-2B41-B2(AC)3-B5-C2-B2-AB-B3-2B2-AC3-BA2-CA3-AB2(-A)4-CA-C5-C2-B6-CA43-2A5-CB2-B4-2(B-)C4-AB-A-C3-AC-B-A3-C-B-A5-A2-A5-B2-C6-BA51-A2B5-A2CBC4-2C2BA4-2(BC)B5-BCBA5-AC2A6-2A12-
