model
size = 28 25 20, scale = 0.05, origin = -y
material 
  colors = A:#D00 B:#111
voxels
---------------------------- ---------------------------- ------A--------------A------ -----AAB------------BAA----- -----BBA------------ABB----- ----ABBA------------ABBA---- ----BAAB------------BAAB---- ----BAABB----------BBAAB---- ----ABBAA----------AABAA---- ----ABBAA----------AABAA---- ----BAABB----------BBAAB---- -----AABB----------BBAA----- -----BBAA--AABBAA--AABB----- -----BBAABBAABBAABBAABB----- -----AABBAABBAABBAABBAA----- -----AABBAABBAABBAABBAA----- -----BBAABBAABBAABBAABB----- ------BAABBAABBAABBAAB------ ------ABBAABBAABBAABBA------ -------BBAABBAABBAABB------- --------ABBAABBAABBA-------- ---------------------------- ---------------------------- ---------------------------- ---------------------------- 
-----BBA------------ABB----- ----ABBAA----------AABBA---- ---BBAABB----------BBAABB--- ---BBAABBA--------ABBAABB--- ---AAAAAAB--------BAAAAAA--- ---AAAAAAB--------BAAAAAA--- ---BBAABBA--------ABBAABB--- ---BBAABBA--------ABBAABB--- ---AAAAAAB--------BAAAAAA--- ---AAAAAAB--------BAAAAAA--- ---BBAAAAA--------AAAAABB--- ---BBAAAAA--BAAB--AAAAABB--- ----AAAAABBAAAAAABBAAAAA---- ----AAAAAAAAAAAAAAAAAAAA---- ----BAAAAAAAAAAAAAAAAAAB---- -----AAAAAAAAAAAAAAAAAA----- -----AAAAAAAAAAAAAAAAAA----- -----BAAAAAAAAAAAAAAAAB----- ------AAAAAAAAAAAAAAAA------ ------AAAAAAAAAAAAAAAA------ -------AABBAABBAABBAA------- --------ABBAABBAABBA-------- ---------------------------- ---------------------------- ---------------------------- 
---AAAAAAB--------BAAAAAA--- --BAAAAAAB--------BAAAAAAB-- --AAAAAAAA--------AAAAAAAA-- --AAAAAAAA--------AAAAAAAA-- --BAAAAAAB--------BAAAAAAB-- --BAAAAAAB--------BAAAAAAB-- --AAAAAAAAA------AAAAAAAAA-- --AAAAAAAAA------AAAAAAAAA-- --BAAAAAABB------BBAAAAAAB-- --BAAAAAABB------BBAAAAAAB-- --AAAAAAAAA------AAAAAAAAA-- --AAAAAAAAABBAABBAAAAAAAAA-- --BAAAAAAAAAAAAAAAAAAAAAAB-- ---AAAAAAAAAAAAAAAAAAAAAA--- ---BBAAAAAAAAAAAAAAAAAABB--- ---BBAAAAAAAAAAAAAAAAAABB--- ----AAAAAAAAAAAAAAAAAAAA---- ----AAAAAAAAAAAAAAAAAAAA---- ----BAAAAAAAAAAAAAAAAAAB---- -----AAAAAAAAAAAAAAAAAA----- -----BBAAAAAAAAAAAAAABB----- ------BAAAAAAAAAAAAAAB------ -------BBAABBAABBAABB------- ---------------------------- ---------------------------- 
-BBAAAAAABB------BBAAAAAABB- -BBAAAAAABB------BBAAAAAABB- -AAAAAAAAAA------AAAAAAAAAA- -AAAAAAAAAA------AAAAAAAAAA- -BBAAAAAABB------BBAAAAAABB- -BBAAAAAABB------BBAAAAAABB- -AAAAAAAAAA------AAAAAAAAAA- -AAAAAAAAAA------AAAAAAAAAA- -BBAAAAAAAAA----AAAAAAAAABB- -BBAAAAAAAAA----AAAAAAAAABB- -AAAAAAAAAABBAABBAAAAAAAAAA- -AAAAAAAAAAAAAAAAAAAAAAAAAA- -BBAAAAAAAAAAAAAAAAAAAAAABB- --BAAAAAAAAAAAAAAAAAAAAAAB-- --AAAAAAAAAAAAAAAAAAAAAAAA-- --AAAAAAAAAAAAAAAAAAAAAAAA-- --BAAAAAAAAAAAAAAAAAAAAAAB-- ---AAAAAAAAAAAAAAAAAAAAAA--- ---BBAAAAAAAAAAAAAAAAAABB--- ---BBAAAAAAAAAAAAAAAAAABB--- ----ABBAAAAAAAAAAAAAABBA---- ----ABBAAAAAAAAAAAAAABBA---- -----AABBAABBAABBAABBAA----- -----AABBAABBAABBAABBAA----- ---------------------------- 
AAA--------A----A--------AAA AAA--------A----A--------AAA BAA--------B----B--------AAB BAA--------B----B--------AAB AAA--------A----A--------AAA AAA--------A----A--------AAA BAA--------B----B--------AAB BAA--------B----B--------AAB AAA--------A----A--------AAA AAA--------A----A--------AAA -BA--------AAAAAA--------AB- -BA----------------------AB- -BB----------------------BB- -BB----------------------BB- -AA----------------------AA- --A----------------------A-- -BBAAAAAAAAAAAAAAAAAAAAAABB- -BBAAAAAAAAAAAAAAAAAAAAAABB- --AAAAAAAAAAAAAAAAAAAAAAAA-- --AAAAAAAAAAAAAAAAAAAAAAAA-- ---AAAAAAAAAAAAAAAAAAAAAA--- ---AAAAAAAAAAAAAAAAAAAAAA--- ----BAAAAAAAAAAAAAAAAAAB---- -----AAAAAAAAAAAAAAAAAA----- ------BAABBAABBAABBAAB------ 
AAA--------A----A--------AAA AAA--------A----A--------AAA BAA--------B----B--------AAB BAA--------B----B--------AAB AAA--------A----A--------AAA AAA--------A----A--------AAA BAA--------A----A--------AAB BAA--------A----A--------AAB AAA--------A----A--------AAA AAA--------A----A--------AAA BBA--------AAAAAA--------ABB -BA----------------------AB- -AA----------------------AA- -AA----------------------AA- -BA----------------------AB- -BA----------------------AB- -AB----------------------BA- -AB----------------------BA- -BBA--------------------ABB- --BA--------------------AB-- --AA--------------------AA-- --AA--------------------AA-- ---BB------------------BB--- ----BAAA------------AAAB---- -----BBA------------ABB----- 
BA----------A--A----------AB BA----------A--A----------AB AA----------B--B----------AA AA----------B--B----------AA BA---------AA--AA---------AB BA---------A----A---------AB AA---------A----A---------AA AA---------A----A---------AA BA---------A-BB-A---------AB BA---------AABBAA---------AB AA----------AAAA----------AA AA------------------------AA BA------------------------AB BA------------------------AB -B------------------------B- -B------------------------B- -B------------------------B- -B------------------------B- -AAA--------------------AAA- -AAA--------------------AAA- --BA--------------------AB-- --BA--------------------AB-- ---AA------------------AA--- ----AA----------------AA---- ----BA----------------AB---- 
BA----------A--A----------AB BA----------A--A----------AB AA----------B--B----------AA AA----------B--B----------AA BA----------A--A----------AB BA----------A--A----------AB AA----------B--B----------AA AA----------B--B----------AA BA----------ABBA----------AB BA----------AAAA----------AB AA----------AAAA----------AA AA------------------------AA BA------------------------AB BA------------------------AB AA------------------------AA -A------------------------A- -B------------------------B- -B------------------------B- -AAA--------------------AAA- -AAA--------------------AAA- -BBA--------------------ABB- --BA--------------------AB-- ---AA------------------AA--- ----A------------------A---- ----B------------------B---- 
AA----------B--B----------AA AA----------B--B----------AA BA----------A--A----------AB BA----------A--A----------AB AA----------B--B----------AA AA----------B--B----------AA BA----------A--A----------AB BA----------A--A----------AB AA----------AAAA----------AA AA----------AAAA----------AA BA----------AAAA----------AB BA------------------------AB AA------------------------AA AA------------------------AA BB------------------------BB -B------------------------B- -A------------------------A- -A------------------------A- -BAA--------------------AAB- -BAA--------------------AAB- -AAA--------------------AAA- --AA--------------------AA-- ---BB------------------BB--- ----B------------------B---- ----A------------------A---- 
AA----------B--B----------AA AA----------B--B----------AA BA----------A--A----------AB BA----------A--A----------AB AA----------B--B----------AA AA----------B--B----------AA BA----------A--A----------AB BA----------A--A----------AB AA----------AAAA----------AA AA----------AAAA----------AA BA----------AAAA----------AB BA------------------------AB AA------------------------AA AA------------------------AA BB------------------------BB -B------------------------B- -A------------------------A- -A------------------------A- -BAA--------------------AAB- -BAA--------------------AAB- -AAA--------------------AAA- --AA--------------------AA-- ---BB------------------BB--- ----B------------------B---- ----A------------------A---- 
BA----------A--A----------AB BA----------A--A----------AB AA----------B--B----------AA AA----------B--B----------AA BA----------A--A----------AB BA----------A--A----------AB AA----------B--B----------AA AA----------B--B----------AA BA----------ABBA----------AB BA----------AAAA----------AB AA----------AAAA----------AA AA------------------------AA BA------------------------AB BA------------------------AB AA------------------------AA -A------------------------A- -B------------------------B- -B------------------------B- -AAA--------------------AAA- -AAA--------------------AAA- -BBA--------------------ABB- --BA--------------------AB-- ---AA------------------AA--- ----A------------------A---- ----B------------------B---- 
BA----------A--A----------AB BA----------A--A----------AB AA----------B--B----------AA AA----------B--B----------AA BA----------A--A----------AB BA----------A--A----------AB AA----------B--B----------AA AA----------B--B----------AA BA----------ABBA----------AB BA----------AAAA----------AB AA----------AAAA----------AA AA------------------------AA BA------------------------AB BA------------------------AB AA------------------------AA -A------------------------A- -B------------------------B- -B------------------------B- -AAA--------------------AAA- -AAA--------------------AAA- -BBA--------------------ABB- --BA--------------------AB-- ---AA------------------AA--- ----A------------------A---- ----B------------------B---- 
AAA---------B--B---------AAA AAA---------B--B---------AAA BBA---------A--A---------ABB BBA---------A--A---------ABB AAA---------B--B---------AAA AAA---------B--B---------AAA BBA---------A--A---------ABB BBA---------A--A---------ABB AAA---------AAAA---------AAA AAA---------AAAA---------AAA BBA---------AAAA---------ABB BBA----------------------ABB AAA----------------------AAA AAA----------------------AAA -BA----------------------AB- -BA----------------------AB- -AA----------------------AA- -AA----------------------AA- -BB----------------------BB- -BBB--------------------BBB- --AA--------------------AA-- --AA--------------------AA-- ---BBA----------------ABB--- ----BA----------------AB---- ----AA----------------AA---- 
-AAA------AAB--BAA------AAA- -AAA------AAB--BAA------AAA- -BAA------AAA--AAA------AAB- -BAA------AAA--AAA------AAB- -AAA------AAB--BAA------AAA- -AAA------AAB--BAA------AAA- -BAA------AAA--AAA------AAB- -BAA------AAA--AAA------AAB- -AAA------AAAAAAAA------AAA- -AAA------AAAAAAAA------AAA- -BAA------AAAAAAAA------AAB- -BAA--------------------AAB- -AAA--------------------AAA- -AAA--------------------AAA- -BAA--------------------AAB- -BAA--------------------AAB- --AA--------------------AA-- --AA--------------------AA-- ---B--------------------B--- ---B--------------------B--- ---A--------------------A--- ---A--------------------A--- ---BBA----------------ABB--- ----BA----------------AB---- ----AA----------------AA---- 
--BB------AAA--AAA------BB-- --BB------AAA--AAA------BB-- --AA------ABB--BBA------AA-- --AA------ABB--BBA------AA-- --BB------AAA--AAA------BB-- --BB------AAA--AAA------BB-- --AA------AAA--AAA------AA-- --AA------AAA--AAA------AA-- --BB------AAABBAAA------BB-- --BB------AAAAAAAA------BB-- --AA------AAAAAAAA------AA-- --AA--------------------AA-- --BB--------------------BB-- --BB--------------------BB-- --AA--------------------AA-- --AA--------------------AA-- --BB--------------------BB-- ---B--------------------B--- ---A--------------------A--- ---AA------------------AA--- ---BB------------------BB--- ---BB------------------BB--- ---AA------------------AA--- ----AAA--------------AAA---- -----BB--------------BB----- 
----A----ABA----ABA----A---- ---BB----ABA----ABA----BB--- ---AA----AAB----BAA----AA--- ---AA----AAB----BAA----AA--- ---BA----AAA----AAA----AB--- ---BA----AAA----AAA----AB--- ---AA----AAAA--AAAA----AA--- ---AA----AAAABBAAAA----AA--- ---AA----AAAAAAAAAA----AA--- ---AA----AAAAAAAAAA----AA--- ---AA----AAAAAAAAAA----AA--- ---AA----AAAAAAAAAA----AA--- ---AA----AAAAAAAAAA----AA--- ---AA----AAAAAAAAAA----AA--- ---AA----AAAAAAAAAA----AA--- ---AA----AAAAAAAAAA----AA--- ---AA----AAAAAAAAAA----AA--- ---AA----AAAAAAAAAA----AA--- ---AB----AAAAAAAAAA----BA--- ---AB----AAAAAAAAAA----BA--- ----B----AAAAAAAAAA----B---- ----BA---AAAAAAAAAA---AB---- ----AA---AAAAAAAAAA---AA---- -----AAAAAAAAAAAAAAAAAA----- ------BAABBAABBAABBAAB------ 
-----BBAAB--------BAABB----- ----ABBAABB------BBAABBA---- ----BAAAAAA------AAAAAAB---- ----BAAAAAA------AAAAAAB---- ----AAAAAAB------BAAAAAA---- ----AAAAAAB------BAAAAAA---- ----BAAAAAABBAABBAAAAAAB---- ---ABAAAAAAAAAAAAAAAAAABA--- ---BAAAAAAAAAAAAAAAAAAAAB--- ---BAAAAAAAAAAAAAAAAAAAAB--- ---AAAAAAAAAAAAAAAAAAAAAA--- ---AAAAAAAAAAAAAAAAAAAAAA--- ---BAAAAAAAAAAAAAAAAAAAAB--- ---BAAAAAAAAAAAAAAAAAAAAB--- ---AAAAAAAAAAAAAAAAAAAAAA--- ---AAAAAAAAAAAAAAAAAAAAAA--- ----AAAAAAAAAAAAAAAAAAAA---- -----AAAAAAAAAAAAAAAAAA----- -----AAAAAAAAAAAAAAAAAA----- -----AAAAAAAAAAAAAAAAAA----- -----BBAAAAAAAAAAAAAABB----- -----BBAAAAAAAAAAAAAABB----- ------ABBAABBAABBAABBA------ -------BBAABBAABBAABB------- ---------------------------- 
---------------------------- ---------B--------B--------- ------ABBA--------ABBA------ ------ABBA--------ABBA------ -----BBAAB--------BAABB----- -----BBAAB--------BAABB----- -----AAABAA------AABAAA----- ----BAAAAAABBAABBAAAAAAB---- ----AAAAAAAAAAAAAAAAAAAA---- ----AAAAAAAAAAAAAAAAAAAA---- ----BAAAAAAAAAAAAAAAAAAB---- ----BAAAAAAAAAAAAAAAAAAB---- ----AAAAAAAAAAAAAAAAAAAA---- ----AAAAAAAAAAAAAAAAAAAA---- ----BAAAAAAAAAAAAAAAAAAB---- ----BAAAAAAAAAAAAAAAAAAB---- -----AAAAAAAAAAAAAAAAAA----- -----BAAAAAAAAAAAAAAAAB----- ------AAAAAAAAAAAAAAAA------ ------AAAAAAAAAAAAAAAA------ -------AABBAAAAAABBAA------- --------ABBAAAAAABBA-------- ---------AABBAABBAA--------- ---------------------------- ---------------------------- 
---------------------------- ---------------------------- ---------------------------- ---------------------------- ---------------------------- ------B--------------B------ -----AAB------------BAA----- -----AABBAABBAABBAABBAA----- -----BBAAAAAAAAAAAAAABB----- -----BBAAAAAAAAAAAAAABB----- -----AAAAAAAAAAAAAAAAAA----- -----AAAAAAAAAAAAAAAAAA----- -----BBAAAAAAAAAAAAAABB----- -----BBAAAAAAAAAAAAAABB----- -----AAAAAAAAAAAAAAAAAA----- -----AAAAAAAAAAAAAAAAAA----- -----BBAAAAAAAAAAAAAABB----- ------BAAAAAAAAAAAAAAB------ -------BBAAAAAAAAAABB------- -------BBAAAAAAAAAABB------- --------ABBAABBAABBA-------- ----------BAABBAAB---------- ---------------------------- ---------------------------- ---------------------------- 
---------------------------- ---------------------------- ---------------------------- ---------------------------- ---------------------------- ---------------------------- ---------------------------- ---------------------------- ------BA-BBAABBAABB-AB------ ------BAABBAABBAABBAAB------ ------ABBAABBAABBAABBA------ ------ABBAABBAABBAABBA------ ------BAABBAABBAABBAAB------ ------BAABBAABBAABBAAB------ ------ABBAABBAABBAABBA------ ------ABBAABBAABBAABBA------ -------AABBAABBAABBAA------- -------AABBAABBAABBAA------- -------BBAABBAABBAABB------- ---------AABBAABBAA--------- ---------BBAABBAABB--------- ---------------------------- ---------------------------- ---------------------------- ---------------------------- 
