model
size = 31 32 17, scale = 0.05, origin = -y
material 
  colors = A:#0A0A0A B:#0F3 C:#00A320 D:#00350A
voxels
9-C3ACAB3AB2A18-BACAD3AB2(AC)18-2(BACA)B2(AD)18-D3A2(CABA)C18-DABACAB3ABAC18-2AB5ACAC2A18-2(CA)2(BACA)B18-B3AC3AD3AC18-2ACAB3(AC)2A18-CAD3ACAD2(AC)18-CABAC3ABAC2A18-2A2(BA)CAC3AC18-CADAB5ADAC18-D2(AC)ABACAB2A18-B5AC3ABAC18-CABADAB3(AC)18-2A2(BA)2(DA)BAD18-2(CA)C3ABADAC18-B3AD2(AB)3AC18-DAC3AB3AD2A18-4ACADACABAC17-AB3(AC)AD5A15-CABAC7ABACAB14-2AC3AB2(AC)ABAC2A15-2(AD)ABA-2(AD)3A17-2(DA)C3-4AC202-BA13-AD14-2A13-AC14-DA13-AC14-CA13-2A14-CA13-AB14-2A13-AC14-BA13-AC14-CA13-AD14-2A13-AB14-BA13-AB14-DA13-2A14-BA13-AC14-CA13-2A2(14-3A11-2AB)15-4(2A11-2A16-)2A11-2A14-AC2A2(11-2ACA)13-AB2A2(10-3A15-3A)11-AC15-2(CA13-)AC15-2(AC)2A3-CABACA16-5A5-ACABA138-9(A17-A12-)3(2A15-2A12-)2A15-2A13-2(A15-A14-)CA13-AD14-BA13-2A14-DA13-AC14-2A13-AD15-A13-A11-3A2-A13-A2-3(3A6-3A19-)3A7-2A19-2A8-4A15-4A9-2AD15-3A12-2(B15-)2(AC)A5-3ABA106-8(A19-A10-)A19-A11-5(A17-A12-)A17-A13-4(A15-A14-)B15-A9-A4-C15-2(A4-)2(A25-A4-)2A23-2A4-3A21-3A5-3A19-3A6-4A17-4A7-4A15-4A10-2A15-DA14-3AB7-C3A75-9(A19-A10-)2(2A17-2A10-)2A17-2A11-3(A17-A12-)2A15-2A12-2A15-2A13-2(A15-A14-)A15-A8-A5-A15-A5-2(A2-A27-)A2-2A25-2A3-2A23-2A4-3A21-3A4-4A19-4A5-4A17-4A7-4A15-4A11-DA13-AC16-CAB7-CAC45-14(A19-A10-)A19-A11-3(A17-A12-)A17-A13-A15-A8-A5-A15-A5-3(A2-A27-)A2-2A25-2A2-3A23-3A3-3A21-3A4-4A19-4A5-4A17-4A8-3A15-C2A2(13-A)17-CA9-AD14-15(A19-A10-)2A17-2A10-2A17-2A11-2(A17-A12-)2A15-2A2(6-A)15-A6-2A2(28-3A)28-2A-A26-2A2-2A25-2A2-3A23-3A3-3A21-3A5-3A19-3A7-4A15-4A11-C15-B15-2(A13-)15(A19-A10-)2(2A17-2A10-)2A17-2A11-A17-A12-2A15-2A6-A5-2A15-2A5-2A3(28-3A)28-2A-A26-2A2-2A25-2A3-2A23-2A4-3A21-3A6-2A19-2A10-2A15-BA14-2(A13-)15(A19-A10-)4(2A17-2A10-)3A15-3A5-A5-2A15-2A5-2A4(28-3A)28-2A-A26-2A2-2A25-2A3-2A23-2A5-3A19-3A9-AB15-2A14-2(A13-)15(A19-A10-)2(2A17-2A10-)2A17-2A11-A17-A12-2A15-2A6-A5-2A15-2A5-2A4(28-3A)28-2A-A26-2A2-2A25-2A3-2A23-2A5-3A19-3A9-AB15-BA14-2(A13-)15(A19-A10-)2A17-2A10-2A17-2A11-2(A17-A12-)2A15-2A2(6-A)15-A6-2A3(28-3A)28-2A-A26-2A2-2A25-2A3-2A23-2A4-3A21-3A6-2A19-2A10-2A15-2A14-2(A13-)14(A19-A10-)A19-A11-3(A17-A12-)A17-A13-A15-A7-A6-A15-A6-2A2(28-3A)28-2A-A26-2A2-2A25-2A2-3A23-3A3-3A21-3A5-4A17-4A7-4A15-4A11-CA14-C16-A12-A13-9(A19-A10-)2(2A17-2A10-)2A17-2A11-2(A17-A12-)A17-A13-4(A15-A14-)A15-A8-A5-A15-A5-2(A2-A27-)A2-A26-2A2-2A25-2A2-3A23-3A3-3A21-3A4-4A19-4A5-4A17-4A8-2AC15-3A2(13-A)17-A11-A14-8(A19-A10-)A19-A11-5(A17-A12-)A17-A13-4(A15-A14-)B15-C8-A5-C15-B5-2(A2-A27-)A2-2A25-2A3-2A23-2A4-3A21-3A4-4A19-4A5-4A17-4A7-4A15-4A11-D15-B15-A13-A17-2A9-AC15-9(A17-A12-)3(2A15-2A12-)2A15-2A13-2(A15-A14-)C15-A14-D15-B14-A15-A14-B15-D15-A13-A10-A5-A13-A5-2(A4-)2A13-2A2(4-A)25-A4-2A23-2A4-3A21-3A5-3A19-3A6-4A17-4A7-4A16-3A10-2A15-2A14-2A11-2A17-BA9-AD20-B7-C18-B15-B14-C15-B14-A15-C14-D16A14-B15AD14-D15AB14-B15AB14-C15AD14-16AC14-C15AB14-17A14-B15AC14-B16A14-16AD14-C15AB15-4(15A16-)15A11-4A-15A-4A6-4AD15AB4A2(6-25A)7-23A8-23A9-2AB15AB2A12-D15AB15-AB11ACA17-D11AB19-11A22-3AB3A20-3AB3AD3AB3A16-AD2(AC)ABAC2(AD)A16-AB3AB5ACABA16-ACABADACAB3ACA16-3ACAB3ABACABA16-AB3A2(CA)C3ABA16-ACA2(B3A)DABA16-3A2(CA)BACABADA16-AC2(ADAB)AB3A16-AD7AD3ABA16-ACADAC2(AB)AC3A16-AD2(AB)ACADABACA16-3AB7A2(BA)17-B12A18-D11AC18-C11AD18-4A5B4A18-3AB5AB3A18-2AB7AB2A18-13A18-3A3(BA)B3A17-5AB3AB5A14-AB4A3(BA)B4ACA12-ACAB11AC3A12-3AB11ABACA13-BADAC7ABAB2A15-3A2(BA)CAD3ADA16-ABAD2(AB)ACAB3A18-ACAD5ABA20-3ACADABACA21-BADABAD2A42-
