model
size = 31 32 17, scale = 0.05, origin = -y
material 
  colors = A:#060606 B:#930 C:#630 D:#F8F8F8 E:#FFF F:#00E G:#E00 H:#0D0 I:#D00 J:#939 K:#633 L:#0F3 M:#00F N:#FC0 O:#906
voxels
9-10B3C2(18-A8B3CA)4(18-2A7B2C2A)18-3A6BC3A18-3A2B3KBC3A18-3A3(BK)C3A18-3A3BK3C3A18-3A2BCO3C3A18-3ABC2JO2C3A18-3AC4JOC3A18-3A2B2JOBC3A18-3A6BC3A18-2A7B2C2A18-2A3D3B3D2A18-A5DB5DA18-2(A2D)B2(2DA)18-A5DB5DA17-ABA3D3B3DACA15-3A8B3C3A14-5AIA3BAI5A15-2AIM3AB3AMI2A17-L2AN2A-2AN2AL202-13(2A13-2A14-)3A11-3A14-3A11-3A15-4(2A11-2A16-)2A11-2A14-2ABA11-AC2A11-4A13-4A2(10-3A15-3A)11-2A15-2(2A13-)2A15-M5A3-5AM16-5A5-5A138-9(A17-A12-)3(2A15-2A12-)2A15-2A13-2(A15-A14-)4(2A13-2A14-)2A13-2A10-3A2-A13-A2-3(3A6-3A19-)3A7-2A19-2A8-4A15-4A9-3A15-3A12-2(A15-)5A5-5A106-8(A19-A10-)A19-A11-5(A17-A12-)A17-A13-4(A15-A14-)A15-A9-A4-A15-2(A4-)2(A25-A4-)2A23-2A4-3A21-3A5-3A19-3A6-4A17-4A7-4A15-4A10-2A15-2A14-4A7-4A75-9(A19-A10-)2(2A17-2A10-)2A17-2A11-3(A17-A12-)2A15-2A12-2A15-2A13-2(A15-A14-)A15-A8-A5-A15-A5-2(A2-A27-)A2-2A25-2A3-2A23-2A4-3A21-3A4-4A19-4A5-4A17-4A7-4A15-4A11-2A13-2A16-3A7-3A45-14(A19-A10-)A19-A11-3(A17-A12-)A17-A13-A15-A8-A5-A15-A5-3(A2-A27-)A2-2A25-2A2-3A23-3A3-3A21-3A4-4A19-4A5-4A17-4A8-3A15-3A2(13-A)17-2E9-2E14-15(A19-A10-)2A17-2A10-2A17-2A11-2(A17-A12-)2A15-2A2(6-A)15-A6-2A2(28-3A)28-2A-A26-2A2-2A25-2A2-3A23-3A3-3A21-3A5-3A19-3A7-4A15-4A11-2(A15-)2(E13-)15(A19-A10-)2(2A17-2A10-)2A17-2A11-A17-A12-2A15-2A6-A5-2A15-2A5-2A3(28-3A)28-2A-A26-2A2-2A25-2A3-2A23-2A4-3A21-3A6-2A19-2A10-2A15-2A14-2(E13-)15(A19-A10-)4(2A17-2A10-)3A15-3A5-A5-2A15-2A5-2A4(28-3A)28-2A-A26-2A2-2A25-2A3-2A23-2A5-3A19-3A9-2A15-2A14-2(E13-)15(A19-A10-)2(2A17-2A10-)2A17-2A11-A17-A12-2A15-2A6-A5-2A15-2A5-2A4(28-3A)28-2A-A26-2A2-2A25-2A3-2A23-2A5-3A19-3A9-2A15-2A14-2(E13-)15(A19-A10-)2A17-2A10-2A17-2A11-2(A17-A12-)2A15-2A2(6-A)15-A6-2A3(28-3A)28-2A-A26-2A2-2A25-2A3-2A23-2A4-3A21-3A6-2A19-2A10-2A15-2A14-2(E13-)14(A19-A10-)A19-A11-3(A17-A12-)A17-A13-A15-A7-A6-A15-A6-2A2(28-3A)28-2A-A26-2A2-2A25-2A2-3A23-3A3-3A21-3A5-4A17-4A7-4A15-4A11-2A14-A16-E12-E13-9(A19-A10-)2(2A17-2A10-)2A17-2A11-2(A17-A12-)A17-A13-4(A15-A14-)A15-A8-A5-A15-A5-2(A2-A27-)A2-A26-2A2-2A25-2A2-3A23-3A3-3A21-3A4-4A19-4A5-4A17-4A8-3A15-3A2(13-A)17-E11-E14-8(A19-A10-)A19-A11-5(A17-A12-)A17-A13-4(A15-A14-)A15-A8-A5-A15-A5-2(A2-A27-)A2-2A25-2A3-2A23-2A4-3A21-3A4-4A19-4A5-4A17-4A7-4A15-4A11-2(A15-)A13-A17-2E9-2E15-9(A17-A12-)3(2A15-2A12-)2A15-2A13-5(A15-A14-)2(A15-)A13-A10-A5-A13-A5-2(A4-)2A13-2A2(4-A)25-A4-2A23-2A4-3A21-3A5-3A19-3A6-4A17-4A7-4A16-3A10-2A15-2A14-2A11-2A17-2A9-2A20-E7-E18-3(A15-A14-)11(17A14-)17A15-4(15A16-)15A11-4A-B13AC-4A3(6-25A)7-23A8-23A9-21A12-17A15-15A17-13A19-11A22-7E20-A10B3CA2(16-2A8B3C2A)2(16-3A3BFBGB2C3A)2(16-3A3BFHGB2C3A)6(16-4A2BFHGBC4A)17-3A2BFHGBC3A18-3ABCFHG2C3A18-3A2CFHG2C3A18-2A3BFHG3C2A18-2A3BFHGB2C2A3(18-A4BFHGB3CA)17-ABA4BH2B2CACA14-4A5BH2B3C4A12-6AIA3BAI6A12-4AIF3AB3AFI4A13-2AL2AN5AN2AL2A15-F13AF16-15A18-11A20-11A21-9A42-
