model
size = 31 32 17, scale = 0.05, origin = -y
material 
  colors = A:#FF0068 B:#F8F8F8 C:#E61669 D:#FF3787
voxels
9-19(9A3BA18-)13A18-9A2(BA)17-11AB3A15-11ABAB3A14-17A15-7AB7A17-5AB-B5A202-13(2A13-2A14-)3A11-3A14-3A11-3A15-4(2A11-2A16-)2A11-2A14-2(4A11-)4A13-4A2(10-3A15-3A)11-2A15-2(2A13-)2A15-5AB3-B5A16-4AB5-B4A138-9(C17-C12-)3(CA15-AC12-)CA15-AC13-2(A15-A14-)4(2A13-2A14-)2A13-2A10-B2A2-A13-A2-3(2AB6-B2A19-)2AB7-2A19-2A8-3AB15-B3A9-3A15-3A12-2(A15-)4AB5-B4A106-8(C19-C10-)C19-C11-4(D17-D12-)C17-C12-C17-C13-4(A15-A14-)A15-A9-A4-A15-2(A4-)2(A25-A4-)2A23-BA4-ABA21-ABA5-3B19-3B6-BA2B17-2BAB7-4A15-4A10-2A15-2A14-3AB7-B3A75-9(D19-D10-)2(CA17-AC10-)CA17-AC11-3(D17-D12-)CA15-AC12-CA15-AC13-2(A15-A14-)A15-A8-B5-A15-A5-2(B2-B27-)B2-2B25-2B3-2A23-2A4-3A21-3A4-4A19-4A5-4B17-4B7-4A15-4A11-2A13-2A16-A2B7-2BA45-B19-A10-A2(19-A10-B19-B10-B)19-B10-B2(19-B10-A)19-B3(10-D19-D)3(10-C19-C)11-2(D17-D12-)C17-C12-C17-C13-A15-A8-A5-A15-A5-3(A2-A27-)A2-2B25-2B2-3B23-3B3-3A21-3A4-4A19-4A5-BA2B17-2BAB8-3A15-3A2(13-A)17-2B9-2B14-2(B19-B10-A19-A10-)A19-B2(10-A19-A10-B19-A)10-B2(19-A10-A)19-A3(10-D19-D)2(10-CA17-AC)11-2(D17-D12-)CA15-AC6-B6-A15-A6-2B2(28-3B)28-2B-A26-2A2-2A25-2A2-3B23-3B3-3A21-3A5-3B19-3B7-4A15-4A11-2(A15-)2(B13-)B19-A3(10-A19-A10-B19-B)10-A19-B10-B3(19-B10-A)19-A3(10-A19-B)2(10-DA17-AD)10-CA17-AC11-D17-D12-DA15-AD6-A5-CA15-AC5-2A2(28-3A)28-2AB28-2B-A26-2A2-2B25-2B3-2A23-2A4-3B21-3B6-2A19-2A10-2A15-2A14-2(B13-)3(A19-B10-)A19-A10-A2(19-B10-A19-A10-B)19-A10-A2(19-A10-B19-B10-B)19-A10-B19-A2(10-2A17-2A)10-DA17-AD10-CA17-AC10-C2A15-2AC5-B5-2A15-2A5-2B2(28-3B)28-2BA28-2AB28-2B-A26-2A2-2B25-2B3-2B23-2B5-3A19-3A9-2A15-2A14-2(B13-)5(B19-A10-)3(A19-A10-B19-B10-)2(A19-A10-A19-B10-)2A17-2A10-2A17-2B10-2A17-2A11-A17-A12-2A15-2A6-B5-2A15-2A5-2B2(28-3B)28-2BA28-2AB28-2B-A26-2A2-2B25-2B3-2B23-2B5-3A19-3A9-2A15-2A14-2(B13-)B19-A3(10-A19-B)10-B19-B2(10-A19-A10-B19-A)2(10-A19-A10-B19-B)2(10-B19-A)10-BA17-2A10-2B17-2B11-A17-A12-A17-B12-2A15-AB2(6-A)15-B6-2A2(28-3A)28-2AB28-2B-A26-2A2-2B25-2B3-2A23-2A4-3B21-3B6-2A19-2A10-2A15-2A14-2(B13-)2(B19-A10-A19-A10-)A19-B10-A19-A4(10-A19-B)10-B19-B10-A19-A10-B2(19-B10-A)19-B11-A17-B12-B17-B12-A17-A12-B17-B13-B15-A7-B6-B15-A6-2B2(28-3B)28-2B-A26-2A2-2A25-2A2-3B23-3B3-3A21-3A5-4B17-4B7-4A15-4A11-2A14-A16-B12-B13-B3(19-B10-A)19-A10-B19-B4(10-B19-A)10-2A17-2A10-BA17-2A10-2A17-2A11-B17-A12-A17-A12-B17-A13-A15-A14-B2(15-A14-A)15-B14-A15-A8-A5-A15-B5-2(A2-A27-)A2-A26-2A2-2B25-2B2-3B23-3B3-3A21-3A4-4A19-4A5-BA2B17-2BAB8-3A15-3A2(13-A)17-B11-B14-2(A19-A10-)2(B19-B10-A19-A10-)A19-A2(10-A19-B)11-A17-B12-A17-A12-A17-B12-B2(17-B12-A)17-B13-C15-A2(14-C15-B)14-A15-B14-B15-A8-B5-B15-A5-2(B2-B27-)B2-2B25-2B3-2A23-2A4-3A21-3A4-4A19-4A5-4B17-4B7-4A15-4A11-C2(15-A)13-A17-2B9-2B15-B17-B12-B2(17-A12-B17-B12-A)17-B12-B17-A12-A17-B12-B17-A2(12-BA15-2A)12-AC15-AB12-AC15-2A13-C2(15-A14-B)2(15-C14-B)15-C14-2(D15-)A13-C10-A5-A13-C5-2(A4-)2A13-2A2(4-A)25-A4-2A23-2A4-3A21-3A5-3B19-3B6-4B17-4B7-4A16-3A10-CB15-2A14-2A11-2A17-2A9-2A20-B7-B18-3(C15-A14-)2(C16A14-)3A11B2(3A14-3AB9AB)3A14-3AB2A5B2AB3A14-2(3AB2AB)2AB14-3AB2A2(BA)2(B2A)B14-CBAB2AB3A2(B2A)B14-CBAB2A5B2AB3A14-CBAB9A2(BA)14-2BAB9ABABC15-2A11BA2(B16-C13A)B16-C14A16-C14B11-B3A-C14B-3AB6-B3ABA5BABA6BC3AB6-B3A8BA8B3AB6-B2AC7BABA7B3AB7-BAC17B2AB8-BAC17B2AB9-ACB13AB4A12-DAB11AB2A15-CB11ABC17-B11AB19-B10A22-7B20-BAB3ABAB6A16-4(BA)7B16-B5AB7AB16-B2(A5B)AB16-B5ABAB6A16-4AB3ABA5B16-3BABA3BAB3AB16-B3AB5A2(BA)B16-BA5B2(AB)4A16-8ABA4BA16-2A5BAB4ABA16-BAB3ABA4BABA16-3(BA)B8A17-AB3A2(BA)4B18-A5B2(AB)3A18-7A3(BA)18-2(BA)4B5A18-BAB4A2(BA)2B18-BA4BAB5A18-B6A5BA18-6B5ABA17-AB7A2B2(AB)14-3ABA5BA2B2(AB)CA12-C2(BA)B3AB4ABABCA12-C6(BA)2BABCA13-2(B3A)2(BA)B2ABC15-2BA5B3(AB)D16-CB7A2(BA)BD18-ABA5BABA20-11A21-9B42-
