model
size = 31 32 17, scale = 0.05, origin = -y
material 
  colors = A:#FFF B:#111 C:#FC9 D:#F30 E:#FFC F:#FC3 G:#070707 H:#F66 I:#060606 J:#F00 K:#050 L:#F8F8F8 M:#888 N:#C63 O:#630 P:#C33
voxels
9-4(13A18-)4AH8A18-3A2H4C4A18-2AC2H6C2A18-A2C3H2J4CA18-A2C5J4CA2(18-B11CB)18-B4C3B4CB18-B2C2A3B2A2CB18-2BC2(B2A)BC2B18-ABC3(AB)ACBA18-ABC3AB3ACBA18-2A2(B3C)B2A18-A11BA18-5B3A5B18-6BA4BLB18-6BA3B3L17-A5B3A3BLBA15-3A3B5A3B3A14-17A15-15A17-6A-6A202-10(2A13-2A14-)3(AB13-BA14-)3A11-3A14-3A11-3A15-4(2A11-2A16-)BA11-AB14-2ABA11-AB2A11-4A13-4A2(10-3A15-3A)11-2A15-2(2A13-)2A15-6A3-6A16-5A5-5A138-9(A17-A12-)3(2A15-2A12-)2A15-2A13-2(A15-A14-)4(2A13-2A14-)2A13-2A10-3A2-A13-A2-3(3A6-3A19-)3A7-2A19-2A8-4A15-4A9-3A15-3A12-2(A15-)5A5-5A106-8(A19-A10-)A19-A11-5(A17-A12-)A17-A13-4(A15-A14-)A15-A9-A4-A15-2(A4-)2(A25-A4-)2A23-2A4-3A21-3A5-3A19-3A6-4A17-4A7-4A15-4A10-2A15-2A14-4A7-4A75-4(A19-A10-)N19-A10-A19-A10-N19-P10-A19-A10-A19-M10-2A17-AM2(10-2A17-2A)11-3(A17-A12-)2A15-2A12-2A15-2A13-2(A15-A14-)A15-A8-A5-A15-A5-2(A2-A27-)A2-2A25-2A3-2A23-2A4-3A21-3A4-4A19-4A5-4A17-4A7-4A15-4A11-2A13-2A16-3A7-3A45-6(A19-A10-)A19-O10-A19-A10-K2(19-A10-A)19-M4(10-A19-A)11-3(A17-A12-)A17-A13-A15-A8-A5-A15-A5-3(A2-A27-)A2-2A25-2A2-3A23-3A3-3A21-3A4-4A19-4A5-4A17-4A8-3A15-3A2(13-A)17-2A9-2A14-6(A19-A10-)A19-O2(10-K19-E)10-E2(19-A10-A)19-M3(10-A19-A)2(10-2A17-2A)11-2(A17-A12-)2A15-2A2(6-A)15-A6-2A2(28-3A)28-2A-A26-2A2-2A25-2A2-3A23-3A3-3A21-3A5-3A19-3A7-4A15-4A11-2(A15-)2(A13-)6(A19-A10-)4(E19-E10-)5(A19-A10-)2(2A17-2A10-)2A17-2A11-A17-A12-2A15-2A6-A5-2A15-2A5-2A3(28-3A)28-2A-A26-2A2-2A25-2A3-2A23-2A4-3A21-3A6-2A19-2A10-2A15-2A14-2(A13-)6(A19-A10-)E19-E2(10-I19-I)10-E19-E4(10-G19-G)10-A19-A4(10-2A17-2A)10-3A15-3A5-A5-2A15-2A5-2A4(28-3A)28-2A-A26-2A2-2A25-2A3-2A23-2A5-3A19-3A9-2A15-2A14-2(A13-)6(A19-A10-)4(E19-E10-)4(G19-G10-)A19-A3(10-2A17-2A)11-A17-A12-2A15-2A6-A5-2A15-2A5-2A4(28-3A)28-2A-A26-2A2-2A25-2A3-2A23-2A5-3A19-3A9-2A15-2A14-2(A13-)6(A19-A10-)E19-E2(10-I19-I)10-E19-E5(10-A19-A)2(10-2A17-2A)11-2(A17-A12-)2A15-2A2(6-A)15-A6-2A3(28-3A)28-2A-A26-2A2-2A25-2A3-2A23-2A4-3A21-3A6-2A19-2A10-2A15-2A14-2(A13-)7(A19-A10-)2(K19-A10-)5(A19-A10-)A19-A11-3(A17-A12-)A17-A13-A15-A7-A6-A15-A6-2A2(28-3A)28-2A-A26-2A2-2A25-2A2-3A23-3A3-3A21-3A5-4A17-4A7-4A15-4A11-2A14-A16-A12-A13-7(A19-A10-)2(K19-A10-)2(2A17-2A10-)2A17-2A11-2(A17-A12-)A17-A13-4(A15-A14-)A15-A8-A5-A15-A5-2(A2-A27-)A2-A26-2A2-2A25-2A2-3A23-3A3-3A21-3A4-4A19-4A5-4A17-4A8-3A15-3A2(13-A)17-A11-A14-8(A19-A10-)A19-A11-5(A17-A12-)A17-A13-4(A15-A14-)A15-A8-A5-A15-A5-2(A2-A27-)A2-2A25-2A3-2A23-2A4-3A21-3A4-4A19-4A5-4A17-4A7-4A15-4A11-2(A15-)A13-A17-2A9-2A15-9(A17-A12-)3(2A15-2A12-)2A15-2A13-5(A15-A14-)2(A15-)A13-A10-A5-A13-A5-2(A4-)2A13-2A2(4-A)25-A4-2A23-2A4-3A21-3A5-3A19-3A6-4A17-4A7-4A16-3A10-2A15-2A14-2A11-2A17-2A9-2A20-A7-A18-3(A15-A14-)11(17A14-)17A15-4(15A16-)15A11-4A-15A-4A3(6-25A)7-23A8-23A9-21A12-17A15-15A17-13A19-11A22-7A20-3(15A16-)2A3F5A3F2A2(16-A4F5A4FA)3(16-3A2B5A2B3A)16-4A2B3D2B4A16-4A3BD3B4A16-3A2D2BD2B2D3A16-2A3D2BD2B3D2A17-2(A11DA18-)2A4DB4D2A18-3A2DBDB2D3A18-4A5D4A3(18-13A)17-15A14-2(19A12-)19A13-17A15-15A16-15A18-5AB5A20-11A21-9A42-
