model
size = 31 32 17, scale = 0.05, origin = -y
material 
  colors = A:#FFF B:#111 C:#F30 D:#FC9 E:#FFC F:#FC3 G:#070707 H:#060606 I:#030 J:#960 K:#E00 L:#777 M:#888 N:#009 O:#FF0 P:#630 Q:#C33 R:#B00
voxels
9-4(13A18-)3AMAQ7A18-2AM2AP7A18-2AMADP3D4A18-2A3D3K3D2A18-A7DK3DA18-B11DB18-BD2ND3B4DB18-BDN2D3B4DB18-B2DABADABA2DB18-2B2(D3B)D2B18-A5BD5BA18-A5(BD)BA18-2AC7DC2A18-AB2C5BCABA18-2BCAC3B3C2B18-2B4CR2CAC2B18-2BA2CBAB3C2B17-A2B2CB3ABCA2BA15-3ABCB5ABCB3A14-17A15-15A17-6A-6A202-10(2A13-2A14-)3(AB13-BA14-)3A11-3A14-3A11-3A15-4(2A11-2A16-)BA11-AB14-2ABA11-AB2A11-4A13-4A2(10-3A15-3A)11-2A15-2(2A13-)2A15-6A3-6A16-5A5-5A138-9(A17-A12-)3(2A15-2A12-)2A15-2A13-2(A15-A14-)4(2A13-2A14-)2A13-2A10-3A2-A13-A2-3(3A6-3A19-)3A7-2A19-2A8-4A15-4A9-3A15-3A12-2(A15-)5A5-5A106-8(A19-A10-)A19-A11-5(A17-A12-)A17-A13-4(A15-A14-)A15-A9-A4-A15-2(A4-)2(A25-A4-)2A23-2A4-3A21-3A5-3A19-3A6-4A17-4A7-4A15-4A10-2A15-2A14-4A7-4A75-2(A19-A10-)2(A19-L10-)5(A19-A10-)2(2A17-2A10-)2A17-2A11-3(A17-A12-)2A15-2A12-2A15-2A13-2(A15-A14-)A15-A8-A5-A15-A5-2(A2-A27-)A2-2A25-2A3-2A23-2A4-3A21-3A4-4A19-4A5-4A17-4A7-4A15-4A11-2A13-2A16-3A7-3A45-A19-A10-A19-L13(10-A19-A)11-3(A17-A12-)A17-A13-A15-A8-A5-A15-A5-3(A2-A27-)A2-2A25-2A2-3A23-3A3-3A21-3A4-4A19-4A5-4A17-4A8-3A15-3A2(13-A)17-2A9-2A14-2(A19-A10-)2(A19-I10-)2(A19-J10-A19-I10-)A19-J6(10-A19-A)2(10-2A17-2A)11-2(A17-A12-)2A15-2A2(6-A)15-A6-2A2(28-3A)28-2A-A26-2A2-2A25-2A2-3A23-3A3-3A21-3A5-3A19-3A7-4A15-4A11-2(A15-)2(A13-)4(A19-A10-)2(E19-I10-)E2(19-E10-H)19-E10-E19-E5(10-A19-A)3(10-2A17-2A)11-A17-A12-2A15-2A6-A5-2A15-2A5-2A3(28-3A)28-2A-A26-2A2-2A25-2A3-2A23-2A4-3A21-3A6-2A19-2A10-2A15-2A14-2(A13-)5(A19-A10-)A19-J10-E19-E2(10-E19-H)10-E19-E4(10-G19-G)10-A19-A4(10-2A17-2A)10-3A15-3A5-A5-2A15-2A5-2A4(28-3A)28-2A-A26-2A2-2A25-2A3-2A23-2A5-3A19-3A9-2A15-2A14-2(A13-)6(A19-A10-)E2(19-E10-H)19-E10-E19-E4(10-G19-G)10-A19-A3(10-2A17-2A)11-A17-A12-2A15-2A6-A5-2A15-2A5-2A4(28-3A)28-2A-A26-2A2-2A25-2A3-2A23-2A5-3A19-3A9-2A15-2A14-2(A13-)4(A19-A10-)2(E19-A10-)E19-E2(10-E19-H)10-E19-E5(10-A19-A)2(10-2A17-2A)11-2(A17-A12-)2A15-2A2(6-A)15-A6-2A3(28-3A)28-2A-A26-2A2-2A25-2A3-2A23-2A4-3A21-3A6-2A19-2A10-2A15-2A14-2(A13-)14(A19-A10-)A19-A11-3(A17-A12-)A17-A13-A15-A7-A6-A15-A6-2A2(28-3A)28-2A-A26-2A2-2A25-2A2-3A23-3A3-3A21-3A5-4A17-4A7-4A15-4A11-2A14-A16-A12-A13-9(A19-A10-)2(2A17-2A10-)2A17-2A11-2(A17-A12-)A17-A13-4(A15-A14-)A15-A8-A5-A15-A5-2(A2-A27-)A2-A26-2A2-2A25-2A2-3A23-3A3-3A21-3A4-4A19-4A5-4A17-4A8-3A15-3A2(13-A)17-A11-A14-8(A19-A10-)A19-A11-5(A17-A12-)A17-A13-4(A15-A14-)A15-A8-A5-A15-A5-2(A2-A27-)A2-2A25-2A3-2A23-2A4-3A21-3A4-4A19-4A5-4A17-4A7-4A15-4A11-2(A15-)A13-A17-2A9-2A15-9(A17-A12-)3(2A15-2A12-)2A15-2A13-5(A15-A14-)2(A15-)A13-A10-A5-A13-A5-2(A4-)2A13-2A2(4-A)25-A4-2A23-2A4-3A21-3A5-3A19-3A6-4A17-4A7-4A16-3A10-2A15-2A14-2A11-2A17-2A9-2A20-A7-A18-3(A15-A14-)11(17A14-)17A15-15A2(16-12A2DA)2(16-15A)11-4A-15A-4A3(6-25A)7-23A8-23A9-21A12-17A15-15A17-13A19-11A22-7A20-3(15A16-)2(3A3F)3A2(16-2AFC2F3A2FCF2A)4(16-4A2B3A2B4A)16-4A2BC2A2B4A16-2ACE2B3C2BC3A16-A2C2(E3B)AC2A17-CA2(E3B)E2C18-2C2E2BE2B2ECA18-CA8EA2C18-A3CA2CA4CA18-2ACA2CO2CAC2A18-3A2COCO2C3A2(18-13A)17-15A14-2(19A12-)19A13-17A15-15A16-15A18-5AB5A20-11A21-9A42-
