model
size = 31 32 17, scale = 0.05, origin = -y
material 
  colors = A:#000 B:#C095FE C:#5931B3 D:#8856E7 E:#7745DE F:#B88BFF G:#6531D4 H:#3000BB I:#4F29E7 J:#3F12A1 K:#7E5BBF L:#FFF7FF M:#F7DDFF N:#EEC5FF O:#511DCA P:#5427D1 Q:#8659E0 R:#9065EF S:#453AA3 T:#9F6AEC U:#BB90FF V:#4410C2 W:#8854E5 X:#C298FE Y:#B888FF Z:#32238A Aa:#281E98 Ab:#2B00BA Ac:#2F25A1 Ad:#D4B1FF Ae:#4F26A6 Af:#A776F5 Ag:#1E00B6 Ah:#3A1EB6 Ai:#F8C5FF Aj:#C097FF Ak:#A777F7 Al:#9D71F7 Am:#B384F9 An:#9A6AF0 Ao:#804FDD Ap:#260091 Aq:#3521B4 Ar:#814FDE As:#BB8EFF At:#3A0CA8 Au:#A172F4 Av:#B48DFE Aw:#7B49DE Ax:#E8CAFF Ay:#9263EF Az:#8463C7 Ba:#A477F4 Bb:#8058CE Bc:#6F3DE0 Bd:#E4C2FF Be:#723DD9 Bf:#FAECFF Bg:#4136A4 Bh:#2F2092 Bi:#8E63F2 Bj:#3F309D Bk:#5621CE Bl:#FFF2FF Bm:#D8B3FF Bn:#BA8DFE Bo:#312390 Bp:#B89BF2 Bq:#FFFAFF Br:#FFECFF Bs:#4C27A2 Bt:#D3B7FF Bu:#9F6CEF Bv:#4E18B5 Bw:#E8C9FF Bx:#5E36B0 By:#3425A7 Bz:#B384FF Ca:#230093 Cb:#33049B Cc:#352E8E Cd:#5621CC Ce:#40139F Cf:#4A15C9 Cg:#9D71F5 Ch:#3600BB Ci:#B88BFC Cj:#CFABFF Ck:#A16DED Cl:#B388FF Cm:#7242DD Cn:#BF93FE Co:#AB7BF9 Cp:#3F0AC2 Cq:#AC80FC Cr:#987CCF Cs:#D1A9FF Ct:#5822CE Cu:#7C59BB Cv:#633FB0 Cw:#A674F4 Cx:#BFA6E8 Cy:#BA8BFF Cz:#6A3BDB Da:#8D6CCC Db:#E5C7FF Dc:#CAA2FF Dd:#A274F5 De:#7B4FCF Df:#AE8EE8 Dg:#C9A2FF Dh:#9063EC Di:#2A00AB Dj:#C098FF Dk:#3A06B8 Dl:#AB90DD Dm:#AB90F7 Dn:#8E5BE7 Do:#9D80D3 Dp:#9C6CF0 Dq:#8667C5 Dr:#BD92FC Ds:#B68DFF Dt:#E0CFFF Du:#D8B5FF Dv:#3A05C2 Dw:#B588FA Dx:#3300BA Dy:#EAC9FF Dz:#3D08C4 Ea:#B588FF Eb:#A271F4 Ec:#7445E0 Ed:#3803C2 Ee:#D4AEFF Ef:#AE7EFA Eg:#9F6DF2 Eh:#5D33B1 Ei:#1200A6 Ej:#BFA7EA Ek:#B183FE El:#9867EF Em:#B186FF En:#3B05B6 Eo:#FAE0FF Ep:#AB7CFC Eq:#3B00B1 Er:#4417A1 Es:#6C38CC Et:#D6B3FF Eu:#A983F5 Ev:#5327A7 Ew:#BD95FF Ex:#BD9FF2 Ey:#8D5DE8 Ez:#673FB8 Fa:#7B4ACC Fb:#713DD8 Fc:#906FCF Fd:#B38EEC Fe:#8E63EA Ff:#724EBF Fg:#CAA7FA Fh:#3C2098 Fi:#BFA4EC Fj:#511DAC Fk:#CCA3FF Fl:#6740C9 Fm:#420BB0 Fn:#8662D4 Fo:#E1BBFF Fp:#EACCFF Fq:#EDDDFF Fr:#DBBAFF Fs:#FFE7FF Ft:#4E18C5 Fu:#7B4CE5 Fv:#531CC7 Fw:#5126A6 Fx:#A989E7 Fy:#724CC2 Fz:#DAB1FF Ga:#562CB1 Gb:#FEE8FF Gc:#EFD8FF Gd:#9F80E8 Ge:#FEF0FF Gf:#5B30B1 Gg:#B083FA Gh:#B894FC Gi:#C9A1FF Gj:#794CCE Gk:#C4A2FF Gl:#CFB1FF Gm:#D59BFF
voxels
9-4ADgDhDiBxCgDjDkDlA18-4AFDnByDoBxDpByDqA18-4ADrBzAbBxChDsChCaDt18-4ADuAfDvCbADwCgDxCc18-4ADyBzDzCa2AEaEbEc18-4ABmTEdCb3AEeEf18-4AUEgAhEh4ABn18-3ACiAfCdEiEj4AEk18-ACjCkClCmAgCe4ABEl18-CnCoWCpBgJ4ABmEmEn18-CqOBgZCr4AEoEpEqEr18-CtAaCu6ABEsCeA18-ICv6AEtEuEv2A18-IK6AEwBsAdAEx18-BcBhCx5AEyEz2AFa18-BuCzBjBsDa3AFbFc2AFd18-AiDcDdBeCfBh2AFeFf2AFg18-3ABwBnGGa2AFhFiDFj18-4ABcDGf2AFkDBhFl18-4AGgFmGh6A18-3ABwFnGi7A17-4A2Bc9A15-4AGjBcBu6AKN2A14-3AGkFmBu8AKCK15-AGlGm4A-7A17-5A3-5A202-DmA8-FpDjDkDl2ADm14-SA8-FrDpByDq2AS14-SA8-NDsChCaDtAS14-AcA8-ADwCgDxCcAAc14-CcA8-AFsEaEbEcBjA14-AeA8-3AEeEfFtA14-BfA8-4ABnFuA14-2A8-4AEkFvA14-2A8-3ABElBjA14-2A8-2ABmEmEnFwA14-ACs8-AEoEpEqEr2A14-AY8-ABEsCe3A14-ACw8-EtEuEv4A14-AAfA7-EwBsAdAEx2A14-ACyA7-EyEz2AFa2A15-DbA7-FbFc2AFdFxA15-2A7-FeFf2AFgFyA15-2A7-GbFhFiGcFjGdA15-2A7-AFkDBhFl2A15-2A7-7A13-2(4A11-)4A13-4A10-3A15-3A10-3A15-ACG11-2A15-CD2(13-2A)15-6A3-6A16-5A5-5A138-2Q15-2Q12-2R15-2R12-2W15-2W12-2Bi15-2Bi12-2Bk15-2Bk12-2Ah15-2Ah12-2Bo15-2Bo12-2Bp15-2Bp12-A17-4(A12-2A15-L)A13-2(A15-A14-)3(2A13-2A14-)2A13-2A15-A13-A11-3A2-A13-A2-3(3A6-3A19-)AGA7-2A19-CD8-4A15-ACKB9-3A15-3A12-2(A15-)5A5-5A106-3M15-3M10-3Aj15-3Aj10-3X15-3X10-3Y15-3Y10-3Ak15-3Ak10-3Al15-3Al10-3H15-3H10-3Z15-3Z10-3Ad15-3Ad11-5(A17-A12-)A17-A13-A15-A14-Fz15-A14-Ge2(15-A14-A)15-A9-A4-A15-2(A4-)2(A25-A4-)2A23-2A4-3A21-A2G5-3A19-2AC6-4A17-2ACB7-4A15-4A10-2A15-2A14-4A7-4A75-4(A19-A10-)3Bl15-2BlA10-3Am15-3Am10-3An15-3An10-3I15-3I10-3Ap15-3Ap3(10-2A17-LA)11-A17-A12-2Bt15-2Bt12-2C15-2C12-2P15-2P12-2Bv15-2Bv13-De15-De14-Bb15-Bb14-Df15-Df8-A5-A15-A5-2(A2-A27-)A2-2A25-2A3-2A23-2A4-3A21-2AE4-4A19-3AK5-4A17-3AG7-4A15-4A11-2A13-2A16-3A7-3A45-6(A19-A10-)3B15-3B10-3Ao15-3Ao10-3Aq15-3Aq10-3At15-3At10-3Av15-3Av10-3Bf15-2BfA10-3Az15-3Az10-3P15-3P10-3E15-3E10-3Bd15-3Bd11-2(A17-A12-)A17-A13-A15-A8-A5-Fo15-A5-3(A2-A27-)A2-2A25-AG2-3A23-2AD3-3A21-2AD4-4A19-3AG5-4A17-4A8-3A15-3A2(13-A)17-2A9-2A14-7(A19-A10-)3B15-3B10-3Ar15-3Ar10-3Ab15-3Ab10-3Ac15-3Ac10-3Aa15-3Aa10-3V15-3V10-3Ba15-3Ba10-A19-A2(10-2A17-2A)11-2(A17-A12-)2A15-2A2(6-A)15-A6-2A2(28-3A)28-2A-A26-AC2-2A25-AE2-3A23-2AN3-Ax2A21-3A5-Ax2A19-3A7-J3A15-4A11-2(A15-)2(A13-)7(A19-A10-)3Bq15-2BqA10-3As15-3As10-3Au15-3Au10-3Aw15-3Aw10-3Ay15-3Ay10-3F15-3F2(10-A19-A)3(10-2A17-2A)11-A17-A12-2A15-2A6-A5-2A15-2A5-2A2(28-3A)28-ABA28-AE-A26-AE2-JA25-AG3-BeA23-2A4-WCA21-3A6-FBw19-2A10-JA15-2A14-2(A13-)9(A19-A10-)3Br15-2BrA10-3Ax15-2AxA10-3Ai15-2Ai3(A10-A19-)A4(10-2A17-2A)10-3A15-3A5-A5-2A15-2A5-2A28-3A28-ACA28-AHA28-ADJ28-AB-W26-2A2-OA25-2A3-BA23-2A5-3A19-3A9-AJ15-2A14-2(A13-)10(A19-A10-)Cs19-Cs10-Y19-Y10-Cw19-Cw10-Af19-Af10-Cy19-Cy10-DbA17-ADb2(10-2A17-2A)11-A17-A12-2A15-2A6-A5-2A15-2A5-2A28-AGA28-AHA28-ADC28-ACF28-2A-Be26-2A2-DA25-2A3-2A23-2A5-3A19-3A9-2A15-2A14-2(A13-)9(A19-A10-)Cn19-Cn10-Cq19-Cq10-Ct19-Ct2(10-I19-I)10-Bc19-Bc10-BuA17-ABu10-AiA17-AAi11-2(A17-A12-)2A15-2A2(6-A)15-A6-GA28-AHN28-AKO28-ABBe28-2A-O26-2A2-BA25-2A3-2A23-2A4-3A21-3A6-2A19-2A10-2A15-2A14-2(A13-)8(A19-A10-)Cj19-Cj10-Co19-Co10-O19-O10-Aa19-Aa10-Cv19-Cv10-K19-K10-KBh17-BhK11-Cz17-Cz12-Dc17-Dc2(12-A17-A)13-A15-A7-A6-A15-A6-BCf28-AKF28-AGBe28-AG-O26-2A2-NA25-2A2-3A23-3A3-3A21-3A5-4A17-4A7-4A15-4A11-2A14-A16-A12-A13-8(A19-A10-)Ck19-Ck10-WA17-LW10-BgA17-LBg10-CuA17-LCu11-2(A17-A12-)Cx17-Cx13-Bj15-Bj14-Dd15-Dd14-A15-E2(14-A15-A)8-A5-A15-A5-K2-C27-K2-J27-N2-O26-2A2-DA25-2A2-3A23-3A3-3A21-3A4-4A19-4A5-4A17-4A8-3A15-3A2(13-A)17-A11-A14-7(A19-A10-)Ci19-Ci10-Cl19-Cl11-Cp17-Cp12-Z17-Z4(12-A17-A)13-Bs15-Bs14-Be15-Be14-Bw15-Bw14-A15-E14-Fn15-N8-Cf5-C15-A5-K2-J27-N2-O27-C2-BA25-2A3-2A23-2A4-3A21-3A4-4A19-4A5-4A17-4A7-4A15-4A11-2(A15-)A13-A17-2A9-2A15-Dg17-A12-F17-A12-Dr17-A12-Du17-A12-Dy17-A12-Bm17-Bm12-U17-U12-Af17-Af12-Cm17-Cm12-BgA15-LBg12-CrA15-LCr2(12-2A15-LA)13-2(A15-A14-)Da15-Da14-Cf15-E14-Bn15-Bn14-N15-E15-Cd13-E10-D5-F13-B5-K4-F4-DA13-2A4-D4-O25-C4-NA23-2A4-3A21-3A5-3A19-3A6-4A17-4A7-4A15-4A10-2A15-2A14-2A11-2A17-2A9-2A20-A7-A18-Dh-Fq13-A14-Dn15-A14-Bz15-A14-Af16A14-Bz15AU14-T15AU14-Eg15AT14-Cd15AAg14-Ag15AAg14-J15AJ5(14-17A)15-15A16-F11AD2A16-G11AD2A16-D13AE16-F13AC11-ODFD-Cd13AC-2BGE6-FAhODC15A3IBI6-DCB19AB2N6-B24A7-23A8-23A9-21A12-17A15-15A17-13A19-11A22-7A20-Di5AMRQS2TU2A16-ByDo3AMRSHEJTU2A16-AbBx3AXQHAeAJT2UA16-DvCb3AXRSV2AAgTUA16-DzCa3AXQHAe2AJ2TU16-EdCb3AMRQSV2AJAgT16-AhEh4AMQRHAe2AJAg16-EiEj5AMQSV3AAg16-Ce6AMRHAe3AJ16-7AMQSE4A16-7AAjRHAe4A16-7AXWSV4A16-7AYBiHAe4A17-5ABbAkBkCc4A18-5AAmAlAhAe4A18-4ABAnHBo5A18-3ABAoIZBp5A18-2AAsArAqApAd6A18-2AAuAbAt8A18-2AAwAcAv8A18-2AAyAa9A17-3AFVAz8AG14-6ABaPBt8A2G12-7AEC10A12-7ABdPBb9A13-7ABvBb8A15-6ADeBb7A16-6ABb8A18-4ADf6A20-3AFo7A21-9A42-
