model
size = 31 32 17, scale = 0.05, origin = -y
material 
  colors = A:#222 B:#111 C:#0F3 D:#063 E:#020 F:#040 G:#EEE H:#0E0 I:#AAA J:#0D0 K:#070 L:#BBB
voxels
9-13C18-13B18-3BAB3ABA3B18-2BK3AH3AK2B18-3(B3A)B18-K2A2BAHA2B2AK18-2ABDB3ABDB2A18-ABFDBAHABDFBA18-BEFDB3ABDFEB18-2EFDBAHABDF2E18-EFD2B3A2BDFE18-FDB2(H2A)HBDF18-DB9ABD18-B3A5B3AB18-3AB5JB3A18-HABJ5GJBAH18-2AJ7GJ2A18-2AJLG3BGLJ2A18-H2AJL3BLJ2AH18-4A5J4A18-2B9A2B17-B2DB3AH3AB2DB15-BD2FE2B3A2BE2FDB14-D3FE2(B2A)BE3FD15-F2EB2ABCB2AB2EF17-2B2ABC-CB2A2B202-2C13-2C3(14-2B13-2B)14-AB13-BA14-2B13-2B14-BA13-AB14-KA13-AK14-2A13-2A4(14-AB13-BA)2(14-3A11-3A)15-4(2A11-2A16-)2A11-2A14-2(4A11-)4A13-4A10-3A15-3A10-2BA15-A2B11-DF15-FD2(13-2E)15-B3ABC3-CB3AB16-AHABC5-CBAHA138-C17-C7(12-B17-B)12-A17-A4(12-2A15-2A)13-2(A15-A14-)4(2A13-2A14-)2A13-2A10-3D2-A13-A2-3D2(6-3A19-3A)6-3B19-3B7-2D19-2D8-4E15-4E9-3B15-3B12-2(A15-)3ABC5-CB3A106-C19-C10-B19-B10-A19-A6(10-B19-B)11-5(A17-A12-)A17-A13-4(A15-A14-)A15-A9-D4-A15-A4-D2(4-A25-A)4-2B23-2B4-3D21-3D5-3E19-3E6-4B17-4B7-4A15-4A10-HA15-AH14-HABC7-CBAH75-C19-C6(10-B19-B)10-A19-A10-B19-3(B10-BA17-A)B11-3(A17-A12-)2A15-2A12-HA15-AH13-2(A15-A14-)A15-A8-D5-A15-A5-D2(2-A27-A)2-2B25-2B3-2D23-AD4-3E21-3E4-4B19-4B5-4A17-4A7-4A15-4A11-2A13-2A16-2BC7-C2B45-C19-C5(10-B19-B)10-A19-A10-I19-I10-A19-A6(10-B19-B)11-3(A17-A12-)A17-A13-A15-A8-D5-A15-A5-D2(2-A27-A)2-B27-B2-2D25-AD2-3E23-3E3-3B21-3B4-4A19-4A5-H3A17-3AH8-H2A15-2AH2(13-B)17-2C9-2C14-C19-C4(10-B19-B)10-A19-A3(10-I19-I)10-A19-A5(10-B19-B)2(10-BA17-AB)11-2(A17-A12-)2A15-2A6-B6-A15-A6-CB2(28-A2B)28-AB-D26-AD2-EA25-AE2-3B23-3B3-3A21-3A5-3A19-3A7-4A15-4A11-2(B15-)2(C13-)C19-C4(10-B19-B)10-A19-A10-I19-I2(10-B19-B)10-A19-A5(10-B19-B)3(10-BA17-AB)11-A17-A12-2A15-2A6-B5-2A15-2A5-GB28-ACB2(28-A2B)28-AB-E26-AE2-BA25-AB3-2A23-2A4-3A21-3A6-2A19-2A10-AB15-BA14-2(C13-)C19-C2(10-B19-B)10-A19-A10-B19-B10-A19-A10-I19-I2(10-B19-B)3(10-A19-A10-B19-B)4(10-BA17-AB)10-B2A15-2A2(B5-)2A15-2A5-AB28-ACB3(28-A2B)28-AB-B26-2B2-2B25-2B3-2B23-2B5-3B19-3B9-2B15-2B14-2(C13-)C19-C4(10-B19-B)10-A19-A10-I19-I2(10-B19-B)10-A19-A5(10-B19-B)3(10-BA17-AB)11-A17-A12-2A15-2A6-B5-2A15-2A5-AB28-ACB3(28-A2B)28-AB-B26-2B2-2B25-2B3-2B23-2B5-3B19-3B9-2B15-2B14-2(C13-)C19-C4(10-B19-B)10-A19-A3(10-I19-I)10-A19-A5(10-B19-B)2(10-BA17-AB)11-2(A17-A12-)2A15-2A6-B6-A15-A6-GB28-ACB2(28-A2B)28-AB-E26-2E2-2B25-2B3-2A23-2A4-3A21-3A6-2A19-2A10-AB15-BA14-2(C13-)C19-C5(10-B19-B)10-A19-A10-I19-I10-A19-A6(10-B19-B)11-3(A17-A12-)A17-A13-A15-A7-B6-A15-A6-CB2(28-A2B)28-AB-D26-2D2-2E25-2E2-3B23-A2B3-3A21-3A5-4A17-4A7-4A15-4A11-2B14-B16-C12-C13-C19-C6(10-B19-B)10-A19-A10-B19-3(B10-BA17-A)B11-2(A17-A12-)A17-A13-4(A15-A14-)A15-A8-D5-A15-A5-D2(2-A27-A)2-B26-2B2-DA25-2D2-3E23-3E3-2BA21-2AB4-4A19-4A5-4A17-3AC8-C2A15-2AC2(13-B)17-C11-C14-C19-C10-B19-B10-A19-A6(10-B19-B)11-5(A17-A12-)C17-C13-4(A15-A14-)A15-A8-D5-A15-A5-D2(2-A27-A)2-2B25-2B3-2D23-2D4-3E21-3E4-2B2A19-4B5-4A17-4A7-C3A15-4A11-2(A15-)B13-B17-2C9-2C15-C17-C7(12-B17-B)12-A17-A3(12-2A15-2A)12-CA15-AC13-2(B15-B14-)3(A15-A14-)2(A15-)A13-A10-D5-A13-A5-D4-A4-2A13-2A2(4-A)25-A4-2B23-2B4-3D21-3D5-3E19-3E6-4B17-4B7-4A16-3A10-2A15-2A14-2A11-2A17-2B9-2B20-C7-C18-C15-C2(14-B15-B)14-2B11A4B14-2B13A2B2(14-B15AB)7(14-17A)14-2B13A2B15-15A2(16-B13AB)16-C13AC16-15A11-4D-15A-4D2(6-25A)6-3B18A4B7-3D18A2D8-5E13A5E9-4B13A4B12-17A15-C13AC17-13A19-2B7A2B22-7C20-15C16-15B16-4BAB3ABA4B16-3B4AC4A3B16-2B3AC3BC3A2B16-B2AC3AB3AC2AB16-3AB7AB3A16-AC3B2AC2A3BCA16-4AB5AB4A16-3A4BA4B3A16-3AB2ABCB2AB3A16-3AB7AB3A16-3A2BC3AC2B3A17-2ABA2BC2BAB2A18-2BC7AC2B18-B11AB18-2(C5A)C18-2(3A2B)3A18-2ABDB3ABDB2A18-ABDF2BC2BFDBA18-BD2FB3AB2FDB17-BD2FEB3ABE2FDB14-2BD2FEB2AC2ABE2FD2B12-2D2FEB7ABE2F2D12-D2FEB2A5B2ABEFAD13-2EB2AB5GB2AB2E15-B2AB2G3B2GB2AB16-4ABG3BGB4A18-3A5B3A20-11A21-9B42-
