model
size = 31 32 17, scale = 0.05, origin = -y
material 
  colors = A:#00FF5D B:#0F9 C:#0FC D:#0F7 E:#0FF F:#111 G:#C6C H:#EEE I:#6F6 J:#DDD K:#E00 L:#00F M:#FF0
voxels
9-4(13E18-)4(13C18-)2(13B18-)2(2B9F2B18-)2D3HKML3H2D18-2D3JKML3J2D18-2D3H3F3H2D18-2DHKHFDF3H2D18-2A3H3F3H2A18-2A7HFH2A18-2A9H2A2(18-3AF5AF3A)17-3A2F5A2F3A15-4AF7AF4A14-4AF7AF4A15-2A2F7A2F2A17-AF4A-4AFA202-4(2E13-2E14-)4(2C13-2C14-)4(2B13-2B14-)2D13-2D2(14-3D11-3D)15-2D11-2D4(16-2A11-IA)14-2(4A11-)4A13-4A2(10-3A15-3A)11-2A15-2(2A13-)2A15-2AF3A3-3AF2A16-2AF2A5-2AF2A138-4(E17-E12-)4(C17-C12-)B17-B3(12-2B15-2B)12-2D15-2D13-2(D15-D14-)2D13-2D4(14-2A13-2A)10-3A2-A13-A2-3(3A6-3A19-)3A7-2A19-2A8-4A15-4A9-3A15-3A12-2(A15-)2AF2A5-2AF2A106-4(E19-E10-)4(C19-C10-)B19-B11-3(B17-B12-)2(D17-D12-)D17-D13-D15-D4(14-A15-A)9-A4-A15-2(A4-)2(A25-A4-)2A23-2A4-3A21-3A5-3A19-3A6-4A17-4A7-4A15-4A10-2A15-2A14-AF2A7-2AFA75-4(E19-E10-)4(C19-C10-)B19-B3(10-2B17-2B)11-3(D17-D12-)2D15-2D12-2A15-2A13-2(A15-A14-)A15-A8-A5-A15-A5-2(A2-A27-)A2-2A25-2A3-2A23-2A4-3A21-3A4-4A19-4A5-4A17-4A7-4A15-4A11-2A13-2A16-F2A7-2AF45-4(E19-E10-)4(C19-C10-)4(B19-B10-)2(D19-D10-)D19-D11-D17-D3(12-A17-A)13-A15-A8-A5-A15-A5-3(A2-A27-)A2-2A25-2A2-3A23-3A3-3A21-3A4-4A19-4A5-4A17-4A8-3A15-3A2(13-A)17-FA9-AF14-4(E19-E10-)4(C19-C10-)4(B19-B10-)3(D19-D10-)2D17-2D10-2A17-2A11-2(A17-A12-)2A15-2A2(6-A)15-A6-2A2(28-3A)28-2A-A26-2A2-2A25-2A2-3A23-3A3-3A21-3A5-3A19-3A7-4A15-4A11-2(A15-)2(F13-)4(E19-E10-)4(C19-C10-)4(B19-B10-)3(D19-D10-)2D17-2D2(10-2A17-2A)11-A17-A12-2A15-2A6-A5-2A15-2A5-2A3(28-3A)28-2A-A26-2A2-2A25-2A3-2A23-2A4-3A21-3A6-2A19-2A10-2A15-2A14-2(F13-)4(E19-E10-)4(C19-C10-)4(B19-B10-)3(D19-D10-)2D17-2D3(10-2A17-2A)10-3A15-3A5-A5-2A15-2A5-2A4(28-3A)28-2A-A26-2A2-2A25-2A3-2A23-2A5-3A19-3A9-2A15-2A14-2(F13-)4(E19-E10-)4(C19-C10-)4(B19-B10-)3(D19-D10-)2D17-2D2(10-2A17-2A)11-A17-A12-AI15-2A6-A5-AI15-2A5-2A4(28-3A)28-2A-A26-2A2-2A25-2A3-2A23-2A5-3A19-3A9-2A15-2A14-2(F13-)4(E19-E10-)4(C19-C10-)4(B19-B10-)3(D19-D10-)2D17-2D10-2A17-2A11-2(A17-A12-)2A15-2A2(6-A)15-A6-2A3(28-3A)28-2A-A26-2A2-2A25-2A3-2A23-2A4-3A21-3A6-2A19-2A10-2A15-2A14-2(F13-)4(E19-E10-)4(C19-C10-)4(B19-B10-)2(D19-D10-)D19-D11-D17-D3(12-A17-A)13-A15-A7-A6-A15-A6-2A2(28-3A)28-2A-A26-2A2-2A25-2A2-3A23-3A3-A2I21-3A5-AI2A17-4A7-4A15-4A11-2A14-A16-F12-F13-4(E19-E10-)4(C19-C10-)B19-B3(10-2B17-2B)11-2(D17-D12-)D17-D13-D15-D4(14-A15-A)8-A5-A15-A5-2(A2-A27-)A2-A26-2A2-2A25-2A2-3A23-3A3-3A21-3A4-4A19-4A5-4A17-4A8-3A15-3A2(13-A)17-F11-F14-4(E19-E10-)4(C19-C10-)B19-B11-3(B17-B12-)2(D17-D12-)D17-D13-D15-D4(14-A15-A)8-A5-A15-A5-2(A2-A27-)A2-2A25-2A3-2A23-2A4-3A21-3A4-4A19-AI2A5-4A17-4A7-4A15-4A11-2(A15-)A13-A17-2F9-2F15-4(E17-E12-)4(C17-C12-)B17-B3(12-2B15-2B)12-2D15-2D13-3(D15-D14-)2(A15-A14-)2(A15-)A13-A10-A5-A13-A5-2(A4-)2A13-2A2(4-A)25-A4-2A23-2A4-3A21-3A5-3A19-AIA6-4A17-4A7-4A16-3A10-2A15-2A14-2A11-2A17-2A9-2A20-F7-F18-2(E15-E14-)2(17E14-)4(17C14-)4(17B14-)2(17D14-)17D15-15D4(16-15A)11-4A-15A-4A3(6-25A)7-23A8-23A9-21A12-17A15-15A17-13A19-11A22-7F20-2(15E16-)6E3G6E16-7E2G6E16-6C3G6C16-15C16-7C2G6C16-7CG7C16-6B2G7B16-15B16-6B3G6B16-7B2G6B16-6D3G6D17-13D18-5D3G5D18-6D2G5D18-5A3G5A18-13A18-5AGAG5A18-5A3G5A18-5AGAG5A17-15A14-8A3G8A12-10AG8A12-8A3G8A13-17A15-3AG2A2(GA)2G3A16-3AG2A3GAG4A18-3G2(AG)2AGA20-GA2GAG2A2GA21-9A42-
