model
size = 31 32 17, scale = 0.05, origin = -y
material 
  colors = A:#F0C B:#99F C:#CC0 D:#CC3 E:#C3F F:#C0F G:#6C6 H:#CF9 I:#0FF J:#F9F K:#C99 L:#CFF M:#CFC N:#C03 O:#CF6 P:#C9C Q:#3CF R:#F6F S:#F69DFF T:#6F6 U:#30F V:#F6C W:#C00 X:#960
voxels
9-4EKCABA2F2B18-MA4MABA3BA18-4EKC2K2M3K18-5KC4K2BC18-4K4B5K18-3G2KC2KAF2KA18-G2AEK2HKA3KA18-E2AE4CA3CA18-E2AEA2CB2H3B18-4BACK6B18-2G4F2AK4L18-2M4F2AM2KPK18-5M3HMKAPK18-A3EK3H2KA2F18-AB4FBK2BAPK18-7B4KPK18-2GA2G3F3CPC18-FEA2PC4KAPM18-E2H2PCA3BA2B18-2P2M2BA2BPA2H18-2E2MA2M2D2SPM17-A2FAPACS2D3FMA15-2B2F2HA2H2FA2K2MK14-11BA5B15-4H2PK-5K2M17-GA3G3-3GFM202-2(EC13-CX14-)EA13-CX14-EA13-2C14-BC13-CB14-2G13-MB14-2G13-2M14-AC13-2C14-AC13-MA14-AB2(13-LA14-AC)13-MC14-2P13-2P14-3P11-2FP14-3B11-3C15-2B11-2C16-2G11-2C16-2F11-2M16-BC11-2B16-2P11-2H14-2E2C11-2MCS11-4G13-M3F10-D2S15-3F10-3M15-2BD11-SA15-DA13-AD13-MD15-DCAS2P3-2DCFAG16-CFA2F5-DCFAB138-I17-A12-I17-F12-S17-X12-S17-C12-B17-B12-G17-H12-G17-M12-E17-C12-E17-B12-2B15-2L12-2E15-2L2(12-AE15-CK)13-E15-C14-B15-A14-AB13-CA14-AG13-CA14-AF13-2C14-2B13-2C15-P13-H11-A2S2-C13-C2-3S6-2AG19-2FS6-DAD19-2FD6-MAM19-3D7-AD19-2D8-A3D15-DA2D9-BDA15-CAD12-A15-C15-A2FAF5-DC2AB106-I19-K10-I19-F10-V19-B10-V19-C10-B19-B10-T19-H10-T19-M10-A19-C10-A19-A11-A17-A12-T17-A3(12-A17-K)12-M17-K13-2(G15-C14-)F15-C14-B15-C14-P15-H9-J4-J15-J4-2(A4-E25-)A4-2J23-2A4-2EN21-D2A5-3D19-2DA6-2J2G17-IDFA7-S2GO15-C3I10-GO15-CI14-U2FA7-CACF75-A19-K10-H19-C10-H19-H10-G19-C10-B19-B10-N19-H2(10-E19-C)10-D19-C10-DT17-LF10-DT17-LG10-2A17-KB11-2(A17-K12-)M17-2(K12-2G15-C)A13-F15-C14-B15-C14-S15-H8-T5-S15-C5-2(A2-A27-)A2-AJ25-DA3-2E23-2B4-3E21-NED4-3JG19-U3F5-AE2G17-2I2A7-F2GU15-CIBA11-OA13-FC16-2FA7-CAC45-A19-K10-H19-C10-H19-A10-G2(19-A10-N)19-H2(10-E19-C)10-D19-B10-D19-F10-N19-G10-A19-B10-A19-K10-A19-U10-D19-G11-V17-K12-M2(17-A12-B)17-K13-J15-H8-J5-J15-C5-I2-T27-I2-I27-D2-J27-A2-IE25-BA2-2OE23-NDA3-O2J21-2UD4-2A2E19-I2AI5-AF2U17-IB2A8-UAO15-C2A2(13-A)17-2I9-2B14-B19-K10-H19-B10-H19-H10-G19-C10-N19-X10-A19-H10-A19-W10-E19-C10-D19-A10-F19-A10-N19-G10-M19-B10-M19-M10-B19-A10-D19-A10-2V17-KA10-2B17-BA11-2(B17-K12-)2J15-2H6-T6-J15-C6-IT28-3I28-2DA28-2D-A26-2B2-2A25-2G2-3A23-U2D3-3A21-2AI5-3A19-I2A7-4A15-C3A11-A15-C15-2(A13-)A19-A10-N19-A10-B19-H10-G19-C10-D2(19-D10-A)19-D10-J19-D10-D19-B10-F19-F10-L19-G10-L19-B10-M19-M10-B19-B10-D19-G10-2V17-TA10-2B17-CA10-AB17-2T11-B17-T12-2J15-2H6-A5-2J15-CU5-2B28-2IB28-2DA28-DFA28-2D-A26-GD2-2A25-2G3-2A23-2B4-3A21-I2B6-2A19-AF10-2A15-CA14-2(A13-)B19-A10-N19-A10-B19-B10-G19-C10-D19-X10-H19-H10-E19-W10-V19-C10-D19-C10-F19-L10-A19-G2(10-A19-A)10-N19-B10-D19-F10-2J17-2T10-2B17-2C2(10-AB17-2T)10-A2B15-3H5-A5-2J15-CT5-2B28-IAB28-NAI28-GAF28-N2D28-GD-O26-2G2-2O25-BI3-2O23-OB5-OJO19-3O9-2A15-CO14-O13-A13-B19-A10-N19-C10-B19-B10-N19-C10-D19-H10-N19-A10-B19-A10-G19-A10-D19-A10-F19-L10-A19-G10-A19-B10-A19-M10-E19-B10-G19-F10-2J17-2I10-2B17-2R10-2L17-2I11-J17-I12-2B15-2H6-G5-2D15-CI5-2B28-2IH28-NDH28-G2F28-N2D28-GD-B26-GF2-GA25-2A3-AO23-AO5-OJO19-O2A9-2A15-CO14-I13-A13-B19-K10-J19-C10-B19-H10-J19-B10-B19-B10-J19-C10-F19-W10-F19-H10-D19-C10-D19-L10-L19-G10-L19-B10-D19-A10-E19-A10-G19-A10-2J17-IA10-2B17-2R11-L17-I12-J17-I12-2B15-2H6-G6-D15-C6-2B28-2IA28-MDA28-GFA28-MD-A26-2G2-2A25-GF3-2A23-BA4-3A21-2AO6-2A19-IA10-2A15-CA14-2(A13-)B19-Q10-N19-C10-B19-H10-V19-B10-B19-B10-N19-C10-F19-W10-F19-H10-D19-W10-A19-I10-L19-R10-L19-B2(10-A19-A)10-G19-A11-J17-I12-A17-R2(12-A17-A)13-F15-H7-I6-D15-C6-IB28-IOA28-MOA28-GO-G26-2M2-EO25-2M2-FAO23-U2M3-AOB21-IBA5-2OUA17-AI2A7-2O2A15-CAGA11-AI14-C16-H12-A13-N19-Q10-N19-C10-A19-H10-V19-B10-B19-C10-N19-B10-F19-W10-F2(19-D10-D)I17-ID10-2L17-LD10-2L17-2H11-V17-M12-F17-M12-I17-I13-J15-C14-B15-R14-H15-F14-F15-C14-F15-H8-J5-D15-J5-2(A2-B27-)A2-E26-GA2-GO25-NA2-E2O23-2NO3-AOE21-3I4-AO2B19-3IA5-2OIA17-AI2A8-I2A15-CAG13-U13-A17-A11-C14-U19-A10-U19-C10-D19-H10-V19-B10-B19-C10-U19-B10-F19-L10-F19-H10-D19-W11-A17-I12-A17-L12-A17-H12-A17-M12-A17-B12-I17-I13-J15-C14-J15-R14-H15-F14-J15-C14-J15-H8-J5-D15-R5-A2-E27-A2-A27-A2-2A25-DA3-2A23-ND4-3A21-2ND4-4A19-4I5-4A17-O3R7-4A15-2(RA)11-A15-C15-F13-A17-AH9-2C15-I17-B12-B17-C12-B17-B12-V17-B12-S17-C12-E2(17-A12-F)17-N12-B17-D12-IE15-CN12-2B15-2L12-2L15-2H12-VI15-2M13-F15-B14-Q15-C14-J15-A14-B15-A14-H15-A14-J15-C15-J13-H10-J5-D13-R5-M4-E4-2D13-2J4-O4-B25-O4-2E23-NO4-2OL21-MNO5-O2N19-NMN6-O3I17-2TMI7-3BI16-O2R10-AI15-RA14-FA11-FA17-AI9-2C20-H7-C18-A15-B14-A15-C14-A15-B14-3F4EC4E4CB14-E2C4EC3E4L2C14-2A4BEC4E4CB14-2A13J2C14-2A2(C4E)5C14-2A2(C4E)3C2D14-E2C4EC4E5C14-4B3EC4E4LA14-2F2(C4E)4LA14-5BIQC4Q2C2FA14-5B2QC4Q4CM14-Q2CIQ2PC4Q5C15-4J2P2J3N4C16-3BJ2P2J3N4C16-A2B2L2AJ3Q4C16-A3LB2A8B16-J3RB2A4B4H11-A2JD-5D2A3DB2A2B-AO2M6-A2I9DA2DG2A3G3AJ6-10DADA2DG2A3G3AB6-3N7DADA2DG2A3G3AN7-A8DAD2ADE2A3CAOA8-A6BNPAO2A2E2A3CAOA9-I4F2IPAI2A2D2A3C2T12-IFA2IPAI2A2D2AR2G15-F2A2HAI2A2D2A2R17-2AIPAI2A2D2CF19-3GAI2A2D2C22-GAI2AHE20-C2H2A3B4F2BA16-3B2A3B4H2BA16-3B2ASCST2N3IA16-2FS2AEC3E2A2FI16-2C4SCSTN2A2LC16-A2B3HCE6DN16-A13JN16-AC4EC3E5N16-AC5HNTN3HEA16-2C4NC3DN3EA16-3B2IQ4D4FA16-FC3IQC2Q2NL2AL16-3BA8G2AF17-2BA2ECE3LE2A18-2FA3F2H2LE2A18-6FL2ALN2Q18-2B5J2A3HQ18-2B4LJ2AL3Q18-3L4B2A3FB18-3R5H4FH18-2R2A9B17-2CI2AJ2L2(2GA)G14-5BN2A2J3G2H2A2O12-2N2C2EDA2D5H2A2O12-2D2C3LAL2AEANMDA2O13-4B2LAL2AFANMNAO15-2FA2HAH4AIMIA16-F2AELAL4AI2RG18-2ELAB4ABR20-2EIAH4A2I21-2GAI3AEI42-
