model
size = 31 32 17, scale = 0.05, origin = -y
material 
  colors = A:#FFF B:#CDCDD7 C:#D5D5DF D:#C6C6CF E:#DDDDE7 F:#B6B6BE G:#BEBEC7 H:#E5E5EF I:#AEAEB6 J:#A6A6AE K:#77777E L:#7E7E86 M:#37373D N:#3F3F46 O:#96969E P:#18181D Q:#47474E R:#28282D S:#4F4F56 T:#202025 U:#6F6F76 V:#2F2F35 W:#57575E X:#000005 Y:#08080D Z:#86868E Aa:#5F5F66 Ab:#DCDCDC Ac:#9E9EA6 Ad:#67676E Ae:#6F6F6F Af:#101015 Ag:#8E8E96 Ah:#EDEDF7 Ai:#000 Aj:#DEDEDE Ak:#0FBE8F Al:#E41FDA Am:#787878 An:#385DFF Ao:#EDB92A Ap:#DF2150 Aq:#FAFAFA Ar:#B1E419 As:#5A5A5A
voxels
9-13X18-13Y18-13Af18-5P3A5P18-4TAApAiApA4T18-4RAAo2ApA4R18-3VA3Ao2ApA3V18-3MAAn3AoAkA3M18-3NA2AnAo2AkA3N18-2QA4An3AkA2Q18-SAAk3An4AkAlAS18-A3AkAiAo2AkAi3AlA18-A3AkAi3AoAi3AlA18-A2AlAkAi3AoAiAn2AlA18-A3AlAiAr2AoAi2AnAlA18-KA2Al3ArAo3AnAK18-LA3Al3Ar3AnAL18-ZAAk2Al2Ar3ApAnAZ18-AgA2AkAl3A3ApAAg18-OA2AkA3OA2ApAO18-A2AkA5AcA2ApA17-JAAkA7JAApAJ15-2I2A9I2A2I14-17F15-6G3Ae6G17-4D2Ae-2Ae4D202-2X13-2X14-2Y13-2Y14-2Af13-2Af14-2P13-2P14-2T13-2T14-2R13-2R14-2V13-2V14-2M13-2M14-2N13-2N14-2Q13-2Q14-2S13-2S14-2W13-2W14-2Aa13-2Aa14-3Ad11-3Ad14-3U11-3U15-2K11-2K16-2L11-2L16-2Z11-2Z16-2Ag11-2Ag16-2O11-2O14-2Aj2Ac11-2Ac2Aj11-4J13-4J10-3I15-3I10-3F15-3F11-2G15-2G2(13-2D)15-4B2Ae3-2Ae4B16-4CAe5-Ae4C138-X17-X12-Y17-Y12-Af17-Af12-P17-P12-T17-T12-R17-R12-V17-V12-M17-M12-N17-N12-2Q15-2Q12-2S15-2S12-2W15-2W12-2Aa15-2Aa13-Ad15-Ad14-U15-U14-2K13-2K14-2L13-2L14-2Z13-2Z14-2Ag13-2Ag14-2O13-2O10-3Aj2-Ac13-Ac2-3Aj6-3J19-3J6-3I19-3I6-3F19-3F7-2G19-2G8-4D15-4D9-3B15-3B12-2(C15-)3E2Ae5-2Ae3E106-X19-X10-Y19-Y10-Af19-Af10-P19-P10-T19-T10-R19-R10-V19-V10-M19-M10-N19-N11-Q17-Q12-S17-S12-W17-W12-Aa17-Aa12-Ad17-Ad12-U17-U13-K15-K14-L15-L14-Z15-Z14-Ag15-Ag14-O15-O9-Aj4-Ac15-Ac4-Aj4-J25-J4-I25-I4-2F23-2F4-3G21-3G5-3D19-3D6-4B17-4B7-4C15-4C10-2E15-2E14-3HAe7-Ae3H75-X19-X10-Y19-Y10-Af19-Af10-P19-P10-T19-T10-R19-R10-V19-V10-M19-M10-N19-N10-2Q17-2Q10-2S17-2S10-2W17-2W11-Aa17-Aa12-Ad17-Ad12-U17-U12-2K15-2K12-2L15-2L13-Z15-Z14-Ag15-Ag14-O15-O8-Aj5-Ac15-Ac5-Aj2-J27-J2-I27-I2-2F25-2F3-2G23-2G4-3D21-3D4-4B19-4B5-4C17-4C7-4E15-4E11-2H13-2H16-Ah2Ae7-2AeAh45-X19-X10-Y19-Y10-Af19-Af10-P19-P10-T19-T10-R19-R10-V19-V10-M19-M10-N19-N10-Q19-Q10-S19-S10-W19-W10-Aa19-Aa10-Ad19-Ad10-U19-U11-K17-K12-L17-L12-Z17-Z12-Ag17-Ag13-O15-O8-Aj5-Ac15-Ac5-Aj2-J27-J2-I27-I2-F27-F2-2G25-2G2-3D23-3D3-3B21-3B4-4C19-4C5-4E17-4E8-3H15-3H2(13-Ah)17-2Ae9-2Ae14-X19-X10-Y19-Y10-Af19-Af10-P19-P10-T19-T10-R19-R10-V19-V10-M19-M10-N19-N10-Q19-Q10-S19-S10-W19-W10-Aa19-Aa10-Ad19-Ad10-U19-U10-2K17-2K10-2L17-2L11-Z17-Z12-Ag17-Ag12-2O15-2O6-Aj6-Ac15-Ac6-AjJ28-2JI28-2IF28-2F-G26-2G2-2D25-2D2-3B23-3B3-3C21-3C5-3E19-3E7-4H15-4H11-2(Ah15-)2(Ae13-)X19-X10-Y19-Y10-Af19-Af10-P19-P10-T19-T10-R19-R10-V19-V10-M19-M10-N19-N10-Q19-Q10-S19-S10-W19-W10-Aa19-Aa10-Ad19-Ad10-U19-U10-2K17-2K10-2L17-2L10-2Z17-2Z11-Ag17-Ag12-2O15-2O6-Aj5-2Ac15-2Ac5-AjJ28-2JI28-2IF28-2FG28-2G-D26-2D2-2B25-2B3-2C23-2C4-3E21-3E6-2H19-2H10-2Ah15-2Ah14-2(Ae13-)X19-X10-Y19-Y10-Af19-Af10-P19-P10-T19-T10-R19-R10-V19-V10-M19-M10-N19-N10-Q19-Q10-S19-S10-W19-W10-Aa19-Aa10-Ad19-Ad10-U19-U10-2K17-2K10-2L17-2L10-2Z17-2Z10-2Ag17-2Ag10-3O15-3O5-Aj5-2Ac15-2Ac5-AjJ28-2JI28-2IF28-2FG28-2GD28-2D-B26-2B2-2C25-2C3-2E23-2E5-3H19-3H9-2Ah15-2Ah14-2(Ae13-)X19-X10-Y19-Y10-Af19-Af10-P19-P10-T19-T10-R19-R10-V19-V10-M19-M10-N19-N10-Q19-Q10-S19-S10-W19-W10-Aa19-Aa10-Ad19-Ad10-U19-U10-2K17-2K10-2L17-2L10-2Z17-2Z11-Ag17-Ag12-2O15-2O6-Aj5-2Ac15-2Ac5-AjJ28-2JI28-2IF28-2FG28-2GD28-2D-B26-2B2-2C25-2C3-2E23-2E5-3H19-3H9-2Ah15-2Ah14-2(Ae13-)X19-X10-Y19-Y10-Af19-Af10-P19-P10-T19-T10-R19-R10-V19-V10-M19-M10-N19-N10-Q19-Q10-S19-S10-W19-W10-Aa19-Aa10-Ad19-Ad10-U19-U10-2K17-2K10-2L17-2L11-Z17-Z12-Ag17-Ag12-2O15-2O6-Aj6-Ac15-Ac6-AjJ28-2JI28-2IF28-2FG28-2G-D26-2D2-2B25-2B3-2C23-2C4-3E21-3E6-2H19-2H10-2Ah15-2Ah14-2(Ae13-)X19-X10-Y19-Y10-Af19-Af10-P19-P10-T19-T10-R19-R10-V19-V10-M19-M10-N19-N10-Q19-Q10-S19-S10-W19-W10-Aa19-Aa10-Ad19-Ad10-U19-U11-K17-K12-L17-L12-Z17-Z12-Ag17-Ag13-O15-O7-Aj6-Ac15-Ac6-AjJ28-2JI28-2IF28-2F-G26-2G2-2D25-2D2-3B23-3B3-3C21-3C5-4E17-4E7-4H15-4H11-2Ah14-Ah16-Ae12-Ae13-X19-X10-Y19-Y10-Af19-Af10-P19-P10-T19-T10-R19-R10-V19-V10-M19-M10-N19-N10-2Q17-2Q10-2S17-2S10-2W17-2W11-Aa17-Aa12-Ad17-Ad12-U17-U13-K15-K14-L15-L14-Z15-Z14-Ag15-Ag14-O15-O8-Aj5-Ac15-Ac5-Aj2-J27-J2-I27-I2-F26-2F2-2G25-2G2-3D23-3D3-3B21-3B4-4C19-4C5-4E17-4E8-3H15-3H2(13-Ah)17-Ae11-Ae14-X19-X10-Y19-Y10-Af19-Af10-P19-P10-T19-T10-R19-R10-V19-V10-M19-M10-N19-N11-Q17-Q12-S17-S12-W17-W12-Aa17-Aa12-Ad17-Ad12-U17-U13-K15-K14-L15-L14-Z15-Z14-Ag15-Ag14-O15-O8-Aj5-Ac15-Ac5-Aj2-J27-J2-I27-I2-2F25-2F3-2G23-2G4-3D21-3D4-4B19-4B5-4C17-4C7-4E15-4E11-2(H15-)Ah13-Ah17-2Ae9-2Ae15-X17-X12-Y17-Y12-Af17-Af12-P17-P12-T17-T12-R17-R12-V17-V12-M17-M12-N17-N12-2Q15-2Q12-2S15-2S12-2W15-2W12-2Aa15-2Aa13-Ad15-Ad14-U15-U14-K15-K14-L15-L14-Z15-Z14-2(Ag15-)O13-O10-Aj5-Ac13-Ac5-Aj4-J4-2J13-2J4-J4-I25-I4-2F23-2F4-3G21-3G5-3D19-3D6-4B17-4B7-4C16-3C10-2E15-2E14-2H11-2H17-2Ah9-2Ah20-Ae7-Ae18-X15-X14-Y15-Y14-Af15-Af14-16PA14-16TA14-16RA14-A15VA14-17M14-17N14-A16Q14-16SA14-A15WA14-A15AaA14-AdA14AdA14-17U15-15K16-15L16-15Z16-15Ag16-15O11-4Aj-15Ac-4Aj6-25J6-25I6-25F7-23G8-23D9-21B12-17C15-15E17-13H19-11Ah22-7Ae20-15X16-15Y16-AfAAf3A2AfA3AfAAfA16-PA3P5(AP)16-2A3T5(AT)16-RA3R3(AR)A3R16-2A3V2(A2V)A3V16-15M16-15N16-3(QA)Q3A2QAQA16-2AS3A3S3(AS)16-3(WA)2W2A2(WA)W16-AaAAa3A3AaAAaA3Aa17-2(A2Ad)3AAdA2Ad18-13U18-13K18-4L5Ai4L18-2Z2Ai2Am3Ab2Ai2Z18-Ag2Ai7Ab2AiAg18-OAiAb2(2Aq2Ab)AiO18-Ai6Ab2Aq3AbAi17-JAiAm2(4AbAq)AiJ14-3IAiAb2Am4AbAm3AbAi3I12-3FAi2AbAsAmAbAqAb2Am2AbAi3F12-3GAiAmAbAsAmAbAqAm2AsAmAbAi3G13-3DAi2AbAmAbAm3AsAmAi3D15-2B2Ai2Ab2Am2AsAm2Ai2B16-3C2Ai3Ab2Am2Ai3C18-3E5Ai3E20-11H21-9Ah42-
