model
size = 31 32 17, scale = 0.05, origin = -y
material 
  colors = A:#000 B:#FFF
voxels
9-4BA3B2A3B18-BA8BA2B18-3BA2BA6B18-2BABA2BA3BAB18-4B4A2BA2B18-6BA5BA18-2A2BA2B3AB2A18-B2A2BA3BA2BA18-2(2BA)2B2AB2A18-3B2A4B2A2B18-B2AB4A3BAB18-7B3AB2A18-BA4BAB3ABA18-2(BA)3B2A2(BA)18-2B3A4B3AB18-A3BAB2AB4A18-3AB3A3B3A18-B3A2B4AB2A18-2B2AB8A18-AB3A2B6A18-AB3AB7A17-AB13A15-17A14-17A15-15A17-6A-6A202-2B13-BA14-2B13-2B14-AB13-AB14-2B13-2A14-2A13-2B14-2B13-BA14-2B13-2B14-AB13-AB14-2A13-2A14-BA13-BA14-BA13-2A14-2B13-2B14-2B13-2A14-A2B11-3A14-2AB11-3A15-3(2B11-2A16-)AB11-2A16-AB11-2A14-B2AB11-4A11-3AB13-4A10-2AB15-3A10-BAB15-3A11-2A15-2(2A13-)2A15-6A3-6A16-5A5-5A138-B17-A12-A17-A12-B17-B2(12-B17-A)2(12-B17-B)12-A17-A12-B17-A12-2B3(15-2A12-AB)15-2A13-2(A15-A14-)AB2(13-2A14-2B)13-2A14-AB13-2A14-2B13-2A10-A2B2-B13-A2-3A6-A2B19-B2A6-BAB19-B2A6-2AB19-B2A7-2A19-2A8-3AB15-B3A9-3A15-3A12-2(A15-)5A5-5A106-A19-B10-A19-A2(10-B19-B)5(10-B19-A)11-3(B17-A12-)A17-A12-B17-A12-A17-A13-B2(15-A14-A)15-A14-B15-A14-A15-A9-A4-A15-2(A4-)A25-A4-B25-A4-2B23-BA4-2AB21-B2A5-3B19-2BA6-2A2B17-2B2A7-3AB15-B3A10-2A15-2A14-4A7-4A75-A19-B10-A2(19-A10-B)19-B2(10-B19-A)10-A19-B10-A19-A10-B19-A10-2B17-2A10-AB17-2A10-2B17-2A11-A2(17-A12-B)17-A12-2B15-2A12-AB15-2A13-2(B15-A14-)A15-A8-A5-B15-A5-A2-B2(27-A2-A)B25-BA3-AB23-BA4-A2B21-2BA4-A3B19-3BA5-A3B17-3BA7-3AB15-B3A11-2A13-2A16-3A7-3A45-A19-B10-B19-B10-A2(19-A10-B)19-B2(10-A19-A)2(10-B19-A)10-B19-B2(10-B19-A)10-A2(19-A10-B)19-A11-3(B17-A12-)B17-A13-B15-A8-B5-B15-A5-3(A2-A27-)A2-AB25-BA2-A2B23-2BA3-A2B21-2BA4-A3B19-3BA5-2A2B17-2B2A8-3A15-3A2(13-A)17-2A9-2A14-2(A19-B10-)3(B19-A10-)2(B19-B10-A19-B2(10-B19-A)10-)2(B19-A10-)2B17-2A10-2B17-2A11-2(B17-A12-)2B15-2A2(6-A)15-A6-3(2A28-B)A-A26-BA2-AB25-BA2-A2B23-2BA3-A2B21-2BA5-A2B19-2BA7-3AB15-B3A11-2(A15-)2(A13-)A19-A2(10-A19-B)3(10-A19-A)3(10-B19-A)10-A5(19-A10-B)19-A3(10-2B17-2A)11-B17-A12-2B15-2A6-B5-AB15-2A5-4(2A28-B)A-A26-BA2-AB25-BA3-AB23-BA4-2AB21-B2A6-2A19-2A10-2A15-2A14-2(A13-)2(A19-A10-)B2(19-A10-A)2(19-A10-B)2(19-B10-B)19-A10-A5(19-A10-B)19-A2(10-AB17-2A)2(10-2B17-2A)10-3B15-3A2(5-B)A15-2A5-AB28-3A3(28-B2A)28-BA-A26-BA2-AB25-BA3-AB23-BA5-3A19-3A9-2A15-2A14-2(A13-)A19-B2(10-A19-A)2(10-A19-B)10-B3(19-A10-A)4(19-A10-B)19-A10-A19-A10-B19-A10-2B17-2A10-AB17-2A10-2B17-2A11-B17-A12-2B15-2A6-A5-2A15-2A5-AB28-3A3(28-B2A)28-BA-A26-BA2-AB25-BA3-AB23-BA5-3A19-3A9-2A15-2A14-2(A13-)A19-B3(10-A19-A)10-B2(19-B10-A)6(19-A10-B)19-A10-A19-A10-B19-A2(10-2B17-2A)11-2(B17-A12-)2B15-2A6-A6-B15-A6-2A28-3A2(28-B2A)28-BA-A26-BA2-2A25-BA3-2A23-BA4-3A21-B2A6-2A19-2A10-2A15-2A14-2(A13-)4(A19-A10-)2(A19-B10-)3(B19-B10-)2(B19-A10-)A3(19-A10-B)19-A11-3(B17-A12-)B17-A13-B15-A7-B6-B15-A6-AB28-3A28-BAB28-BA-A26-BA2-2A25-BA2-3A23-2BA3-3A21-2BA5-4A17-3BA7-3AB15-4A11-2A14-A16-A12-A13-A19-A10-B19-B2(10-A19-A)10-B19-A10-B2(19-B10-A)2(19-A10-B)A17-2A10-BA17-2A10-2A17-2A11-2(B17-A12-)B17-A13-3(B15-A14-)A15-A14-A15-A8-B5-B15-A5-2(A2-A27-)A2-A26-BA2-2A25-BA2-3A23-2BA3-3A21-2BA4-4A19-3BA5-4A17-AB2A8-3A15-3A2(13-A)17-A11-A14-B19-A10-A19-A10-B19-B10-A4(19-A10-B)19-A10-A19-A11-2(A17-A12-B17-A12-)A17-A12-B17-A13-A15-A14-B2(15-A14-A)15-A14-B15-A8-A5-B15-A5-2(A2-A27-)A2-2A25-BA3-BA23-BA4-3A21-2BA4-4A19-A2BA5-4A17-A2BA7-4A15-4A11-2(A15-)A13-A17-2A9-2A15-2(B17-B3(12-B17-A)12-)B17-A4(12-BA15-2A)13-B15-A14-A2(15-A14-B)15-A14-A15-A14-B15-A15-B13-A10-A5-A13-A5-A2(4-B)A13-2A2(4-A)25-A4-2A23-BA4-ABA21-B2A5-3A19-ABA6-4A17-AB2A7-3AB16-3A10-2A15-2A14-2A11-2A17-2A9-2A20-A7-A18-B15-B14-A15-A14-B15-B14-B16A14-17A14-B16A2(14-B15AB)14-17A3(14-B16A)14-17A14-B16A14-2B15A15-15A2(16-B14A)16-15A16-B14A11-B3A-B14A-4A6-AB23A6-AB5AB17A6-2AB4AB17A7-23A8-23A9-21A12-17A15-15A17-13A19-11A22-7A20-BA6BA5BA16-5B2A2(2BA)2B16-2A5BA2(B2A)B16-2(BA)9BAB16-3BA5BA2B3A16-3B2A2(2BA)2B2A16-2A2BA3BA2(B2A)16-2B4A5B2ABA16-5B2AB2A2B3A16-2A3B2A2B6A16-3BA2B2AB3AB2A16-B2AB11A16-A2BAB4AB5A17-3(BA)B6A18-B2A3B7A18-A2(B5A)18-3B3AB6A18-4AB8A18-B4AB7A18-AB11A18-B6AB5A17-2AB12A14-2B3AB13A12-AB17A12-19A13-17A15-15A16-15A18-11A20-11A21-9A42-
