model
size = 31 32 17, scale = 0.05, origin = -y
material 
  colors = A:#06F B:#060606 C:#FFF D:#F09 E:#0F0 F:#33F G:#0FC H:#0F6 I:#E00 J:#306 K:#CF0 L:#800 M:#F8F8F8 N:#A00 O:#7EBDFD P:#B00 Q:#D00
voxels
9-E10ADE18-B10ADE18-EB9ADE18-EAB8ADE18-E2AB7ADE18-E3AB6ADB18-E4AB5ADB18-E3AB6ABE18-E2AB6ABDE18-3B6ABADE18-E2ABAB4ABDE18-E3ABAB4ABE18-E2A2(B3A)DB18-EAB5AB2ABE18-E8A2BDE18-E2A4K3ABDE18-E2D4K2ABADE18-E2D4KAB2ADE18-E2D4KB3ADE18-E5D2AB2ADE18-E5D3ABADE17-3EGD3GAB2A3E15-4E3D2G2AB5E14-5ED3G3AB3ED15-3EDGD2G4ABED17-ED3GD-4ABA202-FB4(13-DC14-FE)13-DB14-FE13-2B14-F2(E13-DC14-B)E2(13-DC14-2B)13-DC14-B2(E13-DC14-F)EC11-CDC14-FEC11-CDC15-4(EC11-CD16-)EC11-CD14-2FEC11-C3D11-2FEA13-E2DK2(10-FEF15-3D)11-2E15-2D13-EG13-2A15-6G3-3AB2A16-5G5-2AB2A138-3(C17-C12-)2(C17-B12-)4(C17-C12-)2(CF15-AC12-)BF15-AC12-BF15-AC13-2(F15-C14-)FC13-AC4(14-FC13-CD)10-3F2-F13-C2-3K6-G2F19-3K2(6-3F19-3D)7-2H19-2D8-3HF15-4D9-H2G15-3D12-G15-D15-5A5-2ADBD106-2(H19-C10-)H19-B10-E19-B10-D2(19-C10-C)19-C10-B19-C10-C19-C11-2(C17-C12-)2(B17-C12-)C17-C12-C17-B13-2(F15-C14-)B2(15-C14-F)15-C9-G4-F15-C4-D4-F25-D4-G25-D4-2F23-2D4-3H21-3D5-3H19-2DE6-HG2H17-3DE7-4G15-4D10-2G15-2D14-4A7-A2DB75-G19-C10-G19-E10-G19-B10-D2(19-E10-E)19-E10-B19-E10-C19-E10-B19-3(C10-BC17-A)C11-C17-C12-C17-B12-C17-C12-2C15-CB12-BC15-2C13-2(F15-C14-)F15-C8-F5-F15-C5-D2-G27-D2-F27-D2-2F25-2E3-2H23-AE4-3H21-DAE4-G2OA19-2D2E5-4G17-3DE7-4G15-4D11-GA13-BD16-A2B7-2BD45-G19-C2(10-B19-E)10-D19-E10-H19-C10-B2(19-C10-D)19-E10-B2(19-C10-D)19-C10-C19-C10-B19-B2(10-B19-C)11-B17-C12-C17-B2(12-C17-C)13-F15-C8-G5-F15-C5-D2-F27-D2-G27-D2-F27-E2-2H25-2E2-3H23-A2E3-HOA21-D2E4-H3G19-2D2E5-4G17-3DE8-3G15-3D13-A13-B17-2B9-2B14-2(B19-C10-)B19-B10-D19-B10-B2(19-C10-D)19-C10-B19-E10-B19-C10-C19-C10-D19-C10-C19-B3(10-C19-C)10-2C17-AC10-BC17-AC11-C17-B12-C17-C12-2C15-2C6-H6-F15-C6-DG2(28-2DH)28-2E-H26-2E2-GA25-2E2-GHA23-A2E3-3G21-2AE5-3G19-2AE7-4G15-A3E11-F15-A15-2(B13-)B19-C3(10-B19-E)10-D19-C10-B19-C10-E19-B10-C19-E10-C19-B10-C19-C10-D19-B4(10-C19-C)2(10-2C17-AC)10-BC17-AC11-C17-B12-2C15-2C6-G5-CF15-OC5-KH28-ADG2(28-ADH)28-AE-H26-AE2-2H25-AE3-HG23-AE4-H2G21-A2E6-2G19-2E10-2F15-2A14-2(B13-)2(B19-C10-B19-E10-)2(B19-E10-)E2(19-E10-C)19-C10-C19-B10-D4(19-C10-C)19-4(C10-2C17-A)B10-CAC15-COC5-H5-CF15-OC5-KG4(28-ADH)28-AD-H26-AE2-2H25-AE3-HG23-AE5-3G19-3E9-2F15-2A14-2(B13-)4(B19-C10-)D2(19-C10-B)19-B2(10-B19-C)10-C19-C10-D19-B10-C4(19-C10-B)2(C17-AC10-B)C17-AC11-C17-C12-2C15-CB6-G5-CF15-OC5-KH28-ADG3(28-ADH)28-2D-H26-2D2-GH25-2D3-2G23-2D5-3G19-3E9-2F15-2A14-2(B13-)B19-C10-B19-G10-B19-C10-D19-G10-B2(19-G10-D)2(19-G10-C)19-C10-B19-C10-D19-C10-C19-B3(10-C19-C)10-2C17-AC10-BC17-AC11-2(C17-C12-)2C15-CB6-H6-F15-C6-KG3(28-ADH)28-AD-H26-2D2-2H25-2D3-HA23-2D4-2GA21-A2D6-2F19-2E10-2F15-2A14-2(B13-)G19-C2(10-B19-G)10-D19-G10-H19-C10-E2(19-C10-D)19-G2(10-D19-C)10-B2(19-C10-C)19-B2(10-C19-C)11-B3(17-C12-C)17-C13-F15-C7-G6-F15-B6-KH28-ADG28-AKH28-AK-B26-AB2-BH25-DB2-BHA23-2DB3-BOA21-ADB5-B3A17-3AB7-3BA15-A3B11-2B14-B16-B12-B13-3(G19-C10-)D2(19-C10-E)19-C3(10-B19-B)10-2C17-CB10-BC17-2C10-2C17-2C11-C17-B2(12-C17-C)13-A15-C14-B2(15-C14-A)15-C14-F15-C8-H5-F15-B5-D2-G27-K2-H27-D2-B26-AB2-BO25-AB2-FHA23-3A3-FOA21-3A4-F2OA19-4A5-2F2A17-4A8-FBH15-DBA13-H13-D17-B11-B14-H19-C2(10-H19-G)10-E19-G10-D19-C10-C19-C10-B19-B10-C19-G10-B19-C11-C17-B12-B17-B12-C17-C12-B17-B2(12-B17-C)13-3(B15-C14-)F15-C14-F15-C8-G5-F15-C5-K2-H27-D2-G27-K2-BO25-AB3-BA23-AB4-F2A21-3A4-F3A19-4A5-F3A17-4A7-2FBA15-4A11-2(B15-)H13-D17-2B9-2B15-C17-C12-C17-G12-C17-B2(12-C17-G)2(12-B17-B)12-C17-G12-B17-2(C12-BA15-A)2(B12-CA15-A)B13-5(F15-D14-)F15-D15-F13-D10-H5-F13-D5-D4-G4-AF13-AD4-A4-H25-D4-2B23-AB4-3B21-A2B5-F2A19-3A6-2F2A17-4A7-3FA16-3A10-FB15-BA14-HA11-AD17-2H9-2D20-B7-B18-3(F15-D14-)F15AB14-F15AD14-B2(15AB14-F)2A2(2EA)2DA2D2AD14-F3AEAE3ADAD3AD14-F2A2(2EA)2DA2D3(2AD14-F2AE3AEAD3AD)2AD14-2FA5EA5DA2D14-2F13A2D15-F8A3B2AD16-F7AB3ABAD16-F6AB5ABD16-F5AB2ABAB2AD16-F5A2(B3A)D11-2(GH)-FB4AB2ABAB2AD-2(DA)6-2(HG)HOAB3AB8A2(DA)D6-GHG2O3ABA6B7ADA6-6B3ABAB4AB5A3B7-5B4AB6AB4A2B8-3F7AB5AB6A9-3F7AB4AB5A12-F8AB2AB4A15-BH7A3BADB17-H11AD19-2H7A2D22-7B20-5A5B5A16-4AB5CB4A16-3ABC2(ML)MCB3A16-2ABCN2LM2LNCB2A16-ABCP2(M2L)MPCBA16-BCQPN2LM2LNPQCB16-ABCPNM3LMNPCBA16-2AB2C2LM2L2CB2A16-3A2BCLMLC2B3A16-3ABJB3LBJB3A16-3ABJBLMLBJB3A16-3ABJB3LBJB3A16-3ABJBNMNBJB3A17-2(2ABJB3NBJB2A18-)2ABJBNMN2(BJB2A18-2ABJBPMP)BJB2A18-2ABJB3PBJB2A18-2ABJBPMPBJB2A18-AB2JB3IB2JBA17-FB2JB2IM2IB2JBD14-3FB2JB5IB2JB3D12-4B2JB2IM2IB2J4B12-4B2J2B3I2B2J4B13-3FB2JBIMIB2JB3A15-FBIBJBIMIBJBIBA16-BHI2B2IM2I2BIDB18-5IM5I20-3ICIMIC3I21-ICI3CICI42-
