model
size = 31 32 17, scale = 0.05, origin = -y
material 
  colors = A:#FFDD01 B:#8A7000 C:#BE9E00 D:#000 E:#EDC900 F:#FFF
voxels
9-5BCBDBC3B18-2(BD)3BDBCBDB18-BDB3DBD3BDB18-BD3BDB2D2BDB18-B2D2(2BD)B2DB18-2BDB2D2BDBD2B18-2BDBD3BDB2DB18-3(B2D)2BDB18-BD3B2(DB)CBDB18-BDBC2(BD)3BDB18-13D18-2(D5F)D18-2(DF3DF)D18-6(DF)D18-2(DF3DF)D18-2(D5F)D18-13D18-3BD5FD3B18-2CBDF3DFDB2C18-ECB3(DF)DBCE18-ECBDF3DFDBCE17-AECBD5FDBCEA15-2AECB7DBCE2A14-2AEC9BCE2A15-AE5CB5CEA17-2E2C2B-2B2C2E202-8(EC13-CE14-)2C13-2C4(14-CB13-BC)2(14-CBA11-ABC)15-2(BA11-AB16-)2B11-2B16-2C11-2C16-EA11-AE14-3BA11-A3B11-3CA13-A3C10-2EA15-A2E10-3A15-3A11-2A15-2(2A13-)2A15-A2EC2B3-2BC2EA16-AE2CB5-B2CEA138-7(C17-C12-)2(E17-E12-)3(2E15-CE12-)2E15-CE13-2(E15-C14-)4(CA13-AC14-)EA13-AE10-3B2-A13-A2-3B6-3C19-3C6-3E19-3E6-3A19-3A7-2A19-2A8-4A15-4A9-3A15-3A12-2(A15-)2EC2B5-2BC2E106-6(B19-B10-)C19-C2(10-E19-E)11-5(E17-E12-)E17-E13-4(E15-E14-)E15-E9-B4-A15-A4-B4-C25-C4-E25-E4-2A23-2A4-3A21-3A5-3A19-3A6-4A17-4A7-4A15-4A10-2A15-2A14-E2CB7-B2CE75-5(D19-D10-)B19-B3(10-C19-C)3(10-CE17-EC)11-3(E17-E12-)EA15-2E12-EA15-2E13-2(A15-E14-)A15-E8-B5-A15-A5-B2-C27-C2-E27-E2-2A25-2A3-2A23-2A4-3A21-3A4-4A19-4A5-4A17-4A7-4A15-4A11-2E13-CE16-C2B7-2BC45-11(B19-B10-)C19-C3(10-E19-E)11-3(E17-E12-)E17-E13-A15-E8-B5-A15-A5-B2-C27-C2-E27-E2-A27-A2-2A25-2A2-3A23-3A3-3A21-3A4-4A19-4A5-4A17-4A8-A2E15-CEA2(13-C)17-2B9-2B14-10(D19-D10-)B19-B3(10-C19-C)10-E19-E2(10-AE17-EA)11-E17-E12-E17-E13-A15-AE6-B6-A15-A6-BC28-2CE28-2EA28-2A-A26-2A2-2A25-2A2-3A23-3A3-3A21-3A5-3A19-3A7-2AEA15-AE2A11-2(C15-)2(B13-)13(B19-B10-)C19-C10-E19-E3(10-2A17-2A)11-A17-A12-2A15-2A6-B5-2A15-2A5-BC28-ACE28-2EA28-3A28-2A-A26-2A2-2A25-2A3-2A23-2A4-3A21-3A6-2A19-2A10-EC15-CE14-2(B13-)12(D19-D10-)B19-B10-C19-C10-E19-E4(10-2A17-2A)10-3A15-3A5-B5-2A15-2A5-BC28-ACE28-2EA2(28-3A)28-2A-A26-2A2-2A25-2A3-2A23-2A5-3A19-3A9-EC15-CE14-2(B13-)13(B19-B10-)C19-C10-E19-E3(10-2A17-2A)11-A17-A12-2A15-2A6-B5-2A15-2A5-BC28-ACE28-2EA2(28-3A)28-2A-A26-2A2-2A25-2A3-2A23-2A5-3A19-3A9-EC15-CE14-2(B13-)10(D19-D10-)B19-B3(10-C19-C)10-E19-E2(10-2A17-2A)11-2(A17-A12-)2A15-2A6-B6-A15-A6-BC28-ACE28-2EA28-3A28-2A-A26-2A2-2A25-2A3-2A23-2A4-3A21-3A6-2A19-2A10-EC15-CE14-2(B13-)11(B19-B10-)C19-C3(10-E19-E)11-3(A17-A12-)A17-A13-A15-A7-B6-A15-A6-BC28-ACE28-2EA28-2A-A26-2A2-2A25-2A2-3A23-3A3-3A21-3A5-4A17-4A7-2AEA15-AE2A11-2C14-C16-B12-B13-6(D19-D10-)B19-B2(10-C19-C)3(10-CA17-AC)11-E17-E2(12-A17-A)13-4(A15-A14-)A15-A8-B5-A15-A5-B2-C27-C2-E27-E2-A26-2A2-2A25-2A2-3A23-3A3-3A21-3A4-4A19-4A5-4A17-4A8-A2E15-2EA2(13-C)17-B11-B14-7(B19-B10-)C19-C10-E19-E11-4(E17-E12-)A17-A12-A17-A13-4(A15-A14-)A15-A8-B5-A15-A5-B2-C27-C2-E27-E2-2A25-2A3-2A23-2A4-3A21-3A4-4A19-4A5-4A17-4A7-4A15-4A11-2(E15-)C13-C17-2B9-2B15-8(C17-C12-)E17-E4(12-2A15-2A)13-5(A15-A14-)2(A15-)A13-A10-B5-A13-A5-B4-C4-2A13-2A4-C4-E25-E4-2A23-2A4-3A21-3A5-3A19-3A6-4A17-4A7-4A16-3A10-AE15-EA14-EA11-AE17-2C9-2C20-B7-B18-3(A15-E14-)10(E15AE14-)2E13A2E14-AE13A2E15-4(E13AE16-)E13AE11-4B-E13AE-4B6-5C10A10C6-3E19A3E6-2AE22A7-AE21A8-A2E17AE2A9-A2E15A2EA12-E15AE15-2E11A2E17-E11AE19-2C7E2C22-7B20-E7C7E16-EC5B8C16-ECB4D2C5BC16-ECBD2BD2CB3DBC16-2CBD2BD2C2DBD2B16-C2BDB2D2CD2B2DB16-CB2D3B2CD2B2DB16-CB2D5CD3BDB16-CBDBC2E2CDBCBDB16-CBDB4C2DBCBDB16-CBD4BCDCBE3B16-CB5DCDC4BC16-C4B2(CD)C3DBC17-4B3(CD)BDB18-B3D2(CD)C2BDB18-2(BD)2(CD)ECBDB18-BD2BC3DECBDB18-BDB2C3DECBDB18-BDBCE3DECBDB18-BD2BC3DC2BDB18-B11DB17-5CD3FD5C14-C6B2(DF)D6BC12-CB6D3F6DBC12-CBD4C5D4CDBC13-2B3C2EDBD2E3C2B15-2C2(B4D)B2C16-2CBD7BDB2C18-3BC3AC3B20-4C3A4C21-9C42-
