model
size = 31 32 17, scale = 0.05, origin = -y
material 
  colors = A:#780078 B:#820082 C:#A000A0 D:#910091 E:#060606 F:#B400B4 G:#777 H:#C800C8 I:#FD0 J:#E20000 K:#00C110 L:#0FF M:#FF5900 N:#1500FF O:#B300A1
voxels
9-13G8(18-13A)18-2(AM)2AL2A3IA18-B2M3BL4BIB18-2(BM)2BL2B3IB18-2(BM)2BL2BI3B18-B2M3BL2B3IB18-13B18-2BJ2B3K2BN2B18-2BJ2BK4BN2B18-2DJ2D2K3DN2D18-2DJ2DK4DN2D18-D3JD3KD3ND18-13D17-15D15-17C14-8CG8C15-6CG-G6C17-4CG3-G4C202-2G13-2G9(14-2A13-2A)3(14-2B13-2B)2(14-3B11-A2B)15-2(2B11-AB16-)2(2D11-2D16-)2D11-2D14-2(4D11-)4D13-4D2(10-3C15-3C)11-2C15-2(2C13-)2C15-5FG3-G5F16-4FG5-G4F138-G17-G8(12-A17-A)12-2A15-2A3(12-2B15-2B)13-2(B15-B14-)2(2B13-AB14-)2D13-2D14-2D13-2D15-D13-D11-3D2-D13-D2-3D6-3D19-3D2(6-3C19-3C)7-2C19-2C8-4C15-4C9-3F15-3F12-2(F15-)4FG5-G4F106-G19-G8(10-A19-A)11-A17-A5(12-B17-B)13-2(B15-B14-)2(D15-D14-)D15-D9-D4-D15-2(D4-)D25-D4-C25-C4-2C23-2C4-3C21-3C5-CAC19-CAC6-2FAF17-FA2F7-4F15-4F10-2F15-2F14-3HG7-G3H75-G19-G8(10-A19-A)10-2A17-2A2(10-2B17-2B)11-3(B17-B12-)2B15-AB12-2B15-AB13-2(D15-D14-)D15-D8-D5-D15-D5-D2-D27-D2-C27-C2-2C25-2C3-2C23-2C4-CAC21-CAC4-F2AF19-F2AF5-F2AF17-F2AF7-4F15-4F11-2H13-2H16-2HG7-G2H45-G19-G9(10-A19-A)5(10-B19-B)11-2(B17-B12-)D17-D12-D17-D13-D15-D8-D5-D15-D5-D2-D27-D2(2-C27-C)2-2C25-2C2-CAC23-CAC3-FAF21-FAF4-F2AF19-F2AF5-2FAF17-FA2F8-3H15-3H2(13-H)17-2G9-2G14-G19-G9(10-A19-A)5(10-B19-B)2(10-2B17-2B)11-2(D17-D12-)2D15-2D2(6-D)15-D6-2D28-2DC28-3C28-2C-C26-2C2-2C25-2C2-FAF23-FAF3-FAF21-FAF5-FAF19-FAF7-4H15-4H11-2(H15-)2(G13-)G19-G9(10-A19-A)5(10-B19-B)2(10-2B17-2B)10-2D17-2D11-D17-D12-2D15-2D6-D5-2D15-2D5-2D28-2DC2(28-3C)28-2C-C26-2C2-2F25-2F3-2F23-2F4-3F21-3F6-2H19-2H10-2H15-2H14-2(G13-)G19-G9(10-A19-A)5(10-B19-B)2(10-2B17-2B)2(10-2D17-2D)10-DAD15-DA2(D5-)2D15-2D5-2D28-2DC3(28-3C)28-2C-F26-2F2-2F25-2F3-2F23-2F5-3H19-3H9-2H15-2H14-2(G13-)G19-G9(10-A19-A)5(10-B19-B)2(10-2B17-2B)10-2D17-2D11-D17-D12-2D15-2D6-D5-2D15-2D5-2D28-2DC3(28-3C)28-2C-F26-2F2-2F25-2F3-2F23-2F5-3H19-3H9-2H15-2H14-2(G13-)G19-G9(10-A19-A)5(10-B19-B)2(10-2B17-2B)11-2(D17-D12-)2D15-2D2(6-D)15-D6-2D28-2DC2(28-3C)28-2C-C26-2C2-2F25-2F3-2F23-2F4-3F21-3F6-2H19-2H10-2H15-2H14-2(G13-)G19-G9(10-A19-A)5(10-B19-B)11-2(B17-B12-)D17-D12-D17-D13-D15-D7-D6-D15-D6-2D28-2DC28-3C28-2C-C26-2C2-2C25-2C2-FAF23-FAF3-FAF21-FAF5-FA2F17-2FAF7-4H15-4H11-2H14-H16-G12-G13-G19-G8(10-A19-A)10-2A17-2A2(10-2B17-2B)11-2(B17-B12-)B17-B13-2(B15-B14-)2(D15-D14-)D15-D8-D5-D15-D5-D2-D27-D2-C27-C2-C26-2C2-2C25-2C2-CAC23-CAC3-FAF21-FAF4-F2AF19-F2AF5-2FAF17-FA2F8-3H15-3H2(13-H)17-G11-G14-G19-G8(10-A19-A)11-A17-A5(12-B17-B)13-2(B15-B14-)2(D15-D14-)D15-D8-D5-D15-D5-D2-D27-D2-C27-C2-2C25-2C3-2C23-2C4-CAC21-CAC4-F2AF19-F2AF5-F2AF17-F2AF7-4F15-4F11-2(H15-)H13-H17-GE9-EG15-G17-G8(12-A17-A)12-2A15-2A3(12-2B15-2B)13-4(B15-B14-)D15-D14-2(D15-)D13-D10-D5-D13-D5-2(D4-)2D13-2D4-D4-C25-C4-2C23-2C4-3C21-3C5-CAC19-CAC6-2FAF17-FA2F7-F2CF16-3F10-2F15-2F14-HG11-GH17-GE9-EG20-E7-E18-GAGELJ3I2N3LGAG14-2AGELJN2I2NMLIG2A14-2AGELJ2NONK2MIG2A14-2AGELJNM2O2KMIG2A14-2AGE2MJ2MOKEJIG2A14-2AGEOM2JM3N2JG2A14-2AGEOM2JEINELJG2A14-2AGEOE3K2I2LKG2A14-2AGEO2LKOIMLOKG2A14-2AGE2J2LO3MOKG2A14-2BGE2JIJO2J2OKG2B14-2BG2E2IJON2J2IG2B14-2BGEKI2JE2N2EIG2B14-2BGE2K2E2IN2KIG2B14-2BG2EKI2N2IL2KG2B15-BG2E2I2NK2L2MGB16-BGEMI2JEKL2OMGB16-DGE2M2J2K2OEMGD16-DGEML2E2IE2NIGD16-DGE2L3E2I2NIGD11-4D-DGEL4E4OIGD-4D6-5DAG10EIGA5D2(6-6CG11EG6C)7-5CGL10EG5C8-5CGL10EG5C9-4FGL10EG4F12-CFGL10EG2F15-FG11EGF17-G11EG19-11E22-7E20-2GELJ3I2N3L2G16-AGELJN2I2NMLIGA16-AGELJ2NONK2MIGA16-AGELJNM2O2KMIGA16-AGE2MJ2MOKEJIGA16-AGEOM2JM3N2JGA16-AGEOM2JEINELJGA16-AGEOE3K2I2LKGA16-AGEO2LKOIMLOKGA16-AGE2J2LO3MOKGA16-BGE2JIJO2J2OKGB16-BG2E2IJON2J2IGB16-BGEKI2JE2N2EIGB17-GE2K2E2IN2KIG18-G2EKI2N2IL2KG18-G2E2I2NK2L2MG18-GEMI2JEKL2OMG18-GE2M2J2K2OEMG18-GEMLKE2IE2NIG18-GE2L2KE2I2NIG18-GEL2EK2E3OIG17-DG8EOEIGD14-2(3CG11EG3C12-)3CGL10EG3C13-2CGL10EG2C15-FGL10EGF16-FGL10EGF18-11E20-11E21-9E42-
