model
size = 31 32 17, scale = 0.05, origin = -y
material 
  colors = A:#090909 B:#111 C:#FFF D:#663 E:#330 F:#630 G:#963 H:#200 I:#300 J:#633 K:#C96 L:#070707 M:#400 N:#660 O:#993 P:#333 Q:#960 R:#100
voxels
9-4(13A18-)4C5A4C18-2C9A2C18-CAC7ACAC18-C2AC5AC2AC18-4AC3AC4A18-5ACAC5A18-6AC6A18-5ACAC5A18-4AC3AC4A18-C2AC5AC2AC18-CAC7ACAC18-2C9A2C18-4C5A4C18-13A2(18-13C)17-A13CA16-A13CA15-2A13C2A14-2A13C2A15-15A17-6A-6A202-13(2A13-2A14-)3A11-3A14-3A11-3A15-4(2A11-2A16-)2A11-2A14-2(4A11-)4A13-4A2(10-3A15-3A)11-2A15-2(2A13-)2A15-6A3-6A16-5A5-5A138-9(A17-A12-)3(2A15-2A12-)2A15-2A13-2(A15-A14-)4(2A13-2A14-)2A13-2A10-3A2-A13-A2-3(3A6-3A19-)3A7-2A19-2A8-4A15-4A9-3A15-3A12-2(A15-)5A5-5A106-8(A19-A10-)A19-A11-5(A17-A12-)A17-A13-4(A15-A14-)A15-A9-A4-A15-2(A4-)2(A25-A4-)2A23-2A4-3A21-3A5-3A19-3A6-4A17-4A7-4A15-4A10-2A15-2A14-4A7-4A75-9(A19-A10-)2(2A17-2A10-)2A17-2A11-3(A17-A12-)2A15-2A12-2A15-2A13-2(A15-A14-)A15-A8-A5-A15-A5-2(A2-A27-)A2-2A25-2A3-2A23-2A4-3A21-3A4-4A19-4A5-4A17-4A7-4A15-4A11-2A13-2A16-3A7-3A45-14(A19-A10-)A19-A11-3(A17-A12-)A17-A13-A15-A8-A5-A15-A5-3(A2-A27-)A2-2A25-2A2-3A23-3A3-3A21-3A4-4A19-4A5-4A17-4A8-3A15-3A2(13-A)17-2A9-2A14-15(A19-A10-)2A17-2A10-2A17-2A11-2(A17-A12-)2A15-2A2(6-A)15-A6-2A2(28-3A)28-2A-A26-2A2-2A25-2A2-3A23-3A3-3A21-3A5-3A19-3A7-4A15-4A11-2(A15-)2(A13-)15(A19-A10-)2(2A17-2A10-)2A17-2A11-A17-A12-2A15-2A6-A5-2A15-2A5-2A3(28-3A)28-2A-A26-2A2-2A25-2A3-2A23-2A4-3A21-3A6-2A19-2A10-2A15-2A14-2(A13-)15(A19-A10-)4(2A17-2A10-)3A15-3A5-A5-2A15-2A5-2A4(28-3A)28-2A-A26-2A2-2A25-2A3-2A23-2A5-3A19-3A9-2A15-2A14-2(A13-)15(A19-A10-)2(2A17-2A10-)2A17-2A11-A17-A12-2A15-2A6-A5-2A15-2A5-2A4(28-3A)28-2A-A26-2A2-2A25-2A3-2A23-2A5-3A19-3A9-2A15-2A14-2(A13-)15(A19-A10-)2A17-2A10-2A17-2A11-2(A17-A12-)2A15-2A2(6-A)15-A6-2A3(28-3A)28-2A-A26-2A2-2A25-2A3-2A23-2A4-3A21-3A6-2A19-2A10-2A15-2A14-2(A13-)14(A19-A10-)A19-A11-3(A17-A12-)A17-A13-A15-A7-A6-A15-A6-2A2(28-3A)28-2A-A26-2A2-2A25-2A2-3A23-3A3-3A21-3A5-4A17-4A7-4A15-4A11-2A14-A16-A12-A13-9(A19-A10-)2(2A17-2A10-)2A17-2A11-2(A17-A12-)A17-A13-4(A15-A14-)A15-A8-A5-A15-A5-2(A2-A27-)A2-A26-2A2-2A25-2A2-3A23-3A3-3A21-3A4-4A19-4A5-4A17-4A8-3A15-3A2(13-A)17-A11-A14-8(A19-A10-)A19-A11-5(A17-A12-)A17-A13-4(A15-A14-)A15-A8-A5-A15-A5-2(A2-A27-)A2-2A25-2A3-2A23-2A4-3A21-3A4-4A19-4A5-4A17-4A7-4A15-4A11-2(D15-)A13-A17-2A9-2A15-9(A17-A12-)3(2A15-2A12-)2A15-2A13-2(A15-A14-)F15-M14-F15-E14-E2(15-E14-F)A13-AE9-A4-FA13-AE2(4-A)4-2A13-2A2(4-A)25-A4-2A23-2A4-3A21-3A5-3A19-3A6-4A17-4A7-3A16-4A10-AD15-DA14-DA11-AD17-2A9-2A20-A7-A18-A15-A2(14-B15-B)7(14-B15AB)14-E15AB14-E15AE14-E15AI14-2I13AFE14-EI13AEM15-F13AF16-F13AE16-E2(13AE16-F)13AE11-4A-F13AE-4A6-4AN15AE4A2(6-25A)7-23A8-23A9-2AD15AD2A12-D15AD15-2D11A2D17-D11AD19-11A22-7A20-15A16-15B16-11BE3B16-5BHI2MHFGE2B16-4BE3FQ2FGE2B16-3BEFDJF2GNE3B16-8BJ2GD2FB16-8BLE2GDGE16-10BLBJDE2(16-15B)16-E12BHE16-I12BEM17-5BEDFH3BF18-H2B2EG2KG2B2F18-EB2EFO2KGBE2F18-FEBLFO2KFHIEF18-2E2BEDGJH2E2F18-EHEB3EHRP2DF18-F2EBHIFDHEJEI18-3FEHEDGFI2FE17-4DELJ3GI4F14-A3D2NEBFDGJEDF2JFA12-A5DPLFDGJEO4DA12-A6DLEGK2D4GDA13-6DBHDGJ6G15-6DBIE6D16-15D18-11D20-11D21-9A42-
