model
size = 31 32 17, scale = 0.05, origin = -y
material 
  colors = A:#FFF B:#C7CBD1 C:#243650 D:#D62C2C E:#595959
voxels
9-6(BA)B18-3(BA)EABACEC18-5(BA)DCA2(18-6(BA)B)3(18-3(BA)E3(AB)3(18-6(BA)B))18-3(BA)E3(AB)2(18-4(BA)2(BD)B)18-4(BA)B2DAB17-3(AB)AE3(AB)A15-C7(AB)AC14-3(BA)B3C3(BA)B15-2(AB)A2C-2C2(AB)A17-2(BA)C3-C2(AB)202-13(BA13-AB14-)BAB11-2AB14-BAB11-2AB15-4(AB11-2A16-)AB11-2A14-2CAB11-2A2C11-2(BA)13-2(AB)10-3C15-3C10-BAB15-BAB11-AB15-2(BA13-)AB15-2(AB)2C3-2C2(BA)16-2(AB)C5-C2(BA)138-9(A17-A12-)3(AB15-BA12-)AB15-BA13-A2(15-B14-B)3(A13-AB14-B)A13-AB15-A13-A11-3C2-A13-A2-3C6-BAB19-BAB6-3C19-3C6-BAB19-BAB7-AB19-BA8-2(AB)15-2(BA)9-BAB15-BAB12-2(B15-)ABA2C5-2CABA106-8(B19-B10-)B19-B11-5(A17-A12-)A17-A13-3(A15-A14-)B15-B14-B15-B9-C4-B15-B4-C4-A25-A4-C25-C4-AB23-BA4-ABA21-ABA5-BAB19-BAB6-2(BA)17-2(AB)7-2(AB)15-2(BA)10-AB15-BA14-ABAC7-CABA75-9(B19-B10-)2(BA17-AB10-)BA17-AB11-3(A17-A12-)2A15-2A12-2A15-2A13-2(A15-A14-)A15-A8-C5-A15-A5-C2-B27-B2-C27-C2-BA25-AB3-AB23-BA4-ABA21-ABA4-2(AB)19-2(BA)5-2(BA)17-2(AB)7-2(AB)15-2(BA)11-BA13-AB16-B2C7-2CB45-11(A19-A10-)3(B19-B10-)B19-B11-3(A17-A12-)A17-A13-A15-A8-C5-A15-A5-C2-A27-A2-C27-C2-B27-B2-BA25-AB2-BAB23-BAB3-ABA21-ABA4-2(AB)19-2(BA)5-2(BA)17-2(AB)8-BAB15-BAB2(13-A)17-2C9-2C14-15(B19-B10-)BA17-AB10-BA17-AB11-2(A17-A12-)2A15-2A6-C6-A15-A6-CA28-BAC28-2CA28-BA-A26-2A2-BA25-AB2-BAB23-BAB3-ABA21-ABA5-B2A19-2AB7-2(AB)15-2(BA)11-2(B15-)2(C13-)15(A19-A10-)2A17-2A2(10-BA17-AB)11-A17-A12-2A15-2A6-C5-2A15-2A5-CA28-BAC28-2CA28-B2A28-BA-A26-2A2-BA25-AB3-AB23-BA4-ABA21-ABA6-AB19-BA10-AB15-BA14-2(C13-)15(B19-B10-)4(BA17-AB10-)B2A15-2AB5-C5-2A15-2A5-CA28-BAC28-2CD2(28-B2A)28-BA-B26-AB2-BA25-AB3-AB23-BA5-BAB19-BAB9-AB15-BA14-2(C13-)15(A19-A10-)2A17-2A2(10-BA17-AB)11-A17-A12-2A15-2A6-C5-2A15-2A5-CA28-2AC28-2CD28-2AD28-3A28-2A-B26-AB2-BA25-AB3-2A23-2A5-BAB19-BAB9-AB15-BA14-2(C13-)15(B19-B10-)BA17-AB10-BA17-AB11-2(A17-A12-)2A15-2A6-C6-A15-A6-CA28-2AC28-2CA28-3A28-2A-A26-2A2-BA25-AB3-AB23-2A4-ABA21-ABA6-AB19-BA10-AB15-BA14-2(C13-)11(A19-A10-)3(B19-B10-)B19-B11-3(A17-A12-)A17-A13-A15-A7-C6-A15-A6-CA28-2AC28-2CA28-2A-A26-2A2-BA25-AB2-BAB23-2AB3-ABA21-3A5-B3A17-3AB7-AB2A15-2ABA11-BA14-B16-C12-C13-9(B19-B10-)2(BA17-AB10-)BA17-AB11-2(A17-A12-)A17-A13-4(A15-A14-)A15-A8-C5-A15-A5-C2-A27-A2-C27-C2-B26-AB2-BA25-AB2-BAB23-2AB3-ABA21-3A4-AB2A19-4A5-B3A17-3AB8-BAB15-BAB2(13-A)17-C11-C14-8(B19-B10-)B19-B11-5(A17-A12-)A17-A13-3(A15-A14-)B15-B14-B15-B8-C5-B15-B5-C2-B27-B2-C27-C2-BA25-AB3-AB23-2A4-ABA21-3A4-2(AB)19-4A5-2(BA)17-3AB7-2(AB)15-2ABA11-2(B15-)A13-A17-2C9-2C15-9(A17-A12-)3(2A15-2A12-)2A15-2A13-A15-A5(14-B15-B)15-A13-A10-C5-A13-A5-C4-A4-2A13-2A4-A4-C25-C4-AB23-2A4-ABA21-ABA5-BAB19-2AB6-2(BA)17-3AB7-2(AB)16-ABA10-AB15-BA14-AB11-BA17-BA9-AB20-C7-C18-3(B15-B14-)11(B15AB14-)B15AB15-4(15A16-)15A11-4C-15A-4C6-2(BA)B15A2(BA)B6-4CB16A4C6-2(BA)B17ABAB7-2(AB)17ABA8-2(AB)17ABA9-BAB15ABAB12-B15AB15-AB4ADAD4ABA17-B4A2D5AB19-11A22-7C20-12(7(AB)A16-)7(AB)A17-2(6(BA)B18-)B5DBA3DAB18-BA3DAB5D4(B18-BA3DAB2DA2D)B17-ABA3DAB2DA2DBA14-C2(BA)4DB5DBABC12-2(AB)2(A3DAB)ABA12-9(AB)A13-8(BA)B15-7(AB)A16-7(AB)A18-5(AB)A20-5(AB)A21-4(BA)B42-
