model
size = 31 32 17, scale = 0.05, origin = -y
material 
  colors = A:#0FF B:#F9FFFF C:#FFF D:#5F5F5F E:#F9F9F9 F:#A7A7A7 G:#868686 H:#D5D5D5 I:#C6C6C6 J:#C2FFFF K:#A9FFFF L:#7BFFFF M:#4DFFFF N:#E1E1E1 O:#E3FFFF P:#EBEBEB Q:#6B6B6B
voxels
9-2(13D18-)13Q18-13G18-13F18-13I18-13H18-13N18-13P18-13E18-13C3(18-13B)18-13O18-13J18-13K18-13L18-13M2(18-13A)17-15A15-17A14-17A15-15A17-6A-6A202-2(2D13-2D14-)2Q13-2Q14-2G13-2G14-2F13-2F14-2I13-2I14-2H13-2H14-2N13-2N14-2P13-2P14-2E13-2E14-2C13-2C2(14-2B13-2B)14-2BC11-3B14-2OC11-C2O15-2J11-CJ16-KC11-2K16-2L11-2L16-2M11-AM16-2A11-2A14-2(4A11-)4A13-4A2(10-3A15-3A)11-2A15-2(2A13-)2A15-6A3-6A16-5A5-5A138-2(D17-D12-)Q17-Q12-G17-G12-F17-F12-I17-I12-H17-H12-N17-N12-P17-P12-2E15-2E12-2C15-2C2(12-2B15-2B)13-B15-B14-O15-O14-2J13-2J14-2K13-2K14-2L13-2L14-2M13-2M14-2A13-2A10-3A2-A13-A2-3(3A6-3A19-)3A7-2A19-2A8-4A15-4A9-3A15-3A12-2(A15-)5A5-5A106-2(D19-D10-)Q19-Q10-G19-G10-F19-F10-I19-I10-H19-H10-N19-N10-P19-P11-E17-E12-C17-C3(12-B17-B)12-O17-O13-J15-J14-K15-K14-L15-L14-M15-M14-A15-A9-A4-A15-2(A4-)2(A25-A4-)2A23-2A4-3A21-3A5-3A19-3A6-4A17-4A7-4A15-4A10-2A15-2A14-4A7-4A75-2(D19-D10-)Q19-Q10-G19-G10-F19-F10-I19-I10-H19-H10-N19-N10-P19-P10-2E17-2E10-2C17-2C10-2B17-2B11-2(B17-B12-)O17-O12-2J15-2J12-2K15-2K13-L15-L14-M15-M14-A15-A8-A5-A15-A5-2(A2-A27-)A2-2A25-2A3-2A23-2A4-3A21-3A4-4A19-4A5-4A17-4A7-4A15-4A11-2A13-2A16-3A7-3A45-2(D19-D10-)Q19-Q10-G19-G10-F19-F10-I19-I10-H19-H10-N19-N10-P19-P10-E19-E10-C19-C3(10-B19-B)10-O19-O11-J17-J12-K17-K12-L17-L12-M17-M13-A15-A8-A5-A15-A5-3(A2-A27-)A2-2A25-2A2-3A23-3A3-3A21-3A4-4A19-4A5-4A17-4A8-3A15-3A2(13-A)17-2A9-2A14-2(D19-D10-)Q19-Q10-G19-G10-F19-F10-I19-I10-H19-H10-N19-N10-P19-P10-E19-E10-C19-C3(10-B19-B)10-O19-O10-2J17-2J10-2K17-2K11-L17-L12-M17-M12-2A15-2A2(6-A)15-A6-2A2(28-3A)28-2A-A26-2A2-2A25-2A2-3A23-3A3-3A21-3A5-3A19-3A7-4A15-4A11-2(A15-)2(A13-)2(D19-D10-)Q19-Q10-G19-G10-F19-F10-I19-I10-H19-H10-N19-N10-P19-P10-E19-E10-C19-C3(10-B19-B)10-O19-O10-2J17-2J10-2K17-2K10-2L17-2L11-M17-M12-2A15-2A6-A5-2A15-2A5-2A3(28-3A)28-2A-A26-2A2-2A25-2A3-2A23-2A4-3A21-3A6-2A19-2A10-2A15-2A14-2(A13-)2(D19-D10-)Q19-Q10-G19-G10-F19-F10-I19-I10-H19-H10-N19-N10-P19-P10-E19-E10-C19-C3(10-B19-B)10-O19-O10-2J17-2J10-2K17-2K10-2L17-2L10-2M17-2M10-3A15-3A5-A5-2A15-2A5-2A4(28-3A)28-2A-A26-2A2-2A25-2A3-2A23-2A5-3A19-3A9-2A15-2A14-2(A13-)2(D19-D10-)Q19-Q10-G19-G10-F19-F10-I19-I10-H19-H10-N19-N10-P19-P10-E19-E10-C19-C3(10-B19-B)10-O19-O10-2J17-2J10-2K17-2K10-2L17-2L11-M17-M12-2A15-2A6-A5-2A15-2A5-2A4(28-3A)28-2A-A26-2A2-2A25-2A3-2A23-2A5-3A19-3A9-2A15-2A14-2(A13-)2(D19-D10-)Q19-Q10-G19-G10-F19-F10-I19-I10-H19-H10-N19-N10-P19-P10-E19-E10-C19-C3(10-B19-B)10-O19-O10-2J17-2J10-2K17-2K11-L17-L12-M17-M12-2A15-2A2(6-A)15-A6-2A3(28-3A)28-2A-A26-2A2-2A25-2A3-2A23-2A4-3A21-3A6-2A19-2A10-2A15-2A14-2(A13-)2(D19-D10-)Q19-Q10-G19-G10-F19-F10-I19-I10-H19-H10-N19-N10-P19-P10-E19-E10-C19-C3(10-B19-B)10-O19-O11-J17-J12-K17-K12-L17-L12-M17-M13-A15-A7-A6-A15-A6-2A2(28-3A)28-2A-A26-2A2-2A25-2A2-3A23-3A3-3A21-3A5-4A17-4A7-4A15-4A11-2A14-A16-A12-A13-2(D19-D10-)Q19-Q10-G19-G10-F19-F10-I19-I10-H19-H10-N19-N10-P19-P10-2E17-2E10-2C17-2C10-2B17-2B11-2(B17-B12-)O17-O13-J15-J14-K15-K14-L15-L14-M15-M14-A15-A8-A5-A15-A5-2(A2-A27-)A2-A26-2A2-2A25-2A2-3A23-3A3-3A21-3A4-4A19-4A5-4A17-4A8-3A15-3A2(13-A)17-A11-A14-2(D19-D10-)Q19-Q10-G19-G10-F19-F10-I19-I10-H19-H10-N19-N10-P19-P11-E17-E12-C17-C3(12-B17-B)12-O17-O13-J15-J14-K15-K14-L15-L14-M15-M14-A15-A8-A5-A15-A5-2(A2-A27-)A2-2A25-2A3-2A23-2A4-3A21-3A4-4A19-4A5-4A17-4A7-4A15-4A11-2(A15-)A13-A17-2A9-2A15-2(D17-D12-)Q17-Q12-G17-G12-F17-F12-I17-I12-H17-H12-N17-N12-P17-P12-2E15-2E12-2C15-2C2(12-2B15-2B)13-B15-B14-O15-O14-J15-J14-K15-K14-L15-L14-2(M15-)A13-A10-A5-A13-A5-2(A4-)2A13-2A2(4-A)25-A4-2A23-2A4-3A21-3A5-3A19-3A6-4A17-4A7-4A16-3A10-2A15-2A14-2A11-2A17-2A9-2A20-A7-A18-2(D15-D14-)Q15-Q14-17G14-17F14-17I14-17H14-2N12D3N14-P13D3P14-17E14-17C2(14-2B13C2B)14-17B14-3O11C3O15-2J11C2J16-2K11C2K16-L12A2L16-2M11A2M16-15A11-4A-15A-4A3(6-25A)7-23A8-23A9-21A12-17A15-15A17-13A19-11A22-7A20-2(15D16-)15Q16-15G16-15F16-15I16-15H16-15N16-15P16-15E16-15C2(16-15B)17-13B18-13O18-13J18-13K18-13L18-13M2(18-13A)17-15A14-2(19A12-)19A13-17A15-15A16-15A18-11A20-11A21-9A42-
