model
size = 31 32 17, scale = 0.05, origin = -y
material 
  colors = A:#CFF B:#070707 C:#6CC D:#2F2F2F E:#FFF F:#F60 G:#C9C98D H:#9CC I:#959559 J:#BEBEBE K:#777
voxels
9-AC8BCDB18-2CBD3BD2BHBD18-CD4BD3BC2B18-HD8BH2D18-BD8BH2B18-C3BD5BCBD18-BD8BC2B18-10BCBD18-CD5BD2BCDB18-3BD6BC2B18-10BC2B18-3B2EI2E2BC2B18-BDB2EG2EBDCEI18-CE2(G2E)BHCEG18-CDE2IG2I3CIG18-C2E2BG2BCACDG2(18-CAC5BCAC2E)17-3AC5ECA4C16-3AC5EC5A16-3AH6C5A15-2(17A14-)17A15-15A17-6A-6A202-CB13-BD14-BC13-DB14-CH13-BD14-2B13-2B14-DB2(13-2B14-BD)13-BD14-2D13-2B14-DB13-DB14-BD13-2B14-2B13-BD14-BD13-2B14-2B13-EB14-GEA11-EGC14-GEA11-2EC15-DA11-ED16-EA11-2E16-CA11-2E16-2A11-AC16-2A11-2A14-2(4A11-)4A13-4A2(10-3A15-3A)11-2A15-2(2A13-)2A15-6A3-6A16-5A5-5A138-A17-C12-C17-C12-B17-H12-C17-C12-B2(17-C12-D)2(17-C12-B)17-3(C12-DA15-A)C12-BD15-AC13-E15-A14-E15-C14-BA13-AC14-EA13-AC14-CA2(13-AC14-2A)13-2A10-3F2-A13-A2-3F3(6-3A19-3A)7-2A19-2A8-4A15-4A9-3A15-3A12-2(A15-)5A5-5A106-2(A19-C10-)2(C19-C10-)C19-H10-D19-B10-B19-B10-C19-C10-C19-H11-B17-B2(12-D17-C)12-B17-C12-D17-C12-C17-C13-3(C15-C14-)A15-A14-A15-A9-F4-A15-A4-F2(4-A25-A)4-2A23-2A4-3A21-3A5-3A19-3A6-4A17-4A7-4A15-4A10-2A15-2A14-4A7-4A75-C19-H10-A19-B10-D19-C2(10-C19-B)10-D19-B10-C19-D2(10-C19-B)2(10-DA17-AB)10-CA17-AD11-C17-E12-C17-I12-C17-B2(12-2A15-AE)13-A15-C2(14-A15-A)8-F5-A15-A5-F2(2-A27-A)2-2A25-2A3-2A23-2A4-3A21-3A4-4A19-4A5-4A17-4A7-4A15-4A11-2A13-2A16-A2F7-2FA45-A19-C10-B19-B10-J2(19-B10-B19-B10-C)19-B10-D2(19-B10-J)19-B10-B19-D10-B19-B10-E19-I10-B19-G10-E19-G11-C2(17-E12-A)17-C12-A17-A13-A15-A8-F5-A15-A5-F3(2-A27-A)2-2A25-2A2-3A23-3A3-3A21-3A4-4A19-4A5-4A17-4A8-3A15-3A2(13-A)17-2F9-2F14-A19-H10-C2(19-B10-D)3(19-B10-B)19-D10-B19-D2(10-D19-B)10-D19-D10-B19-B10-G19-I10-G19-G10-E19-E10-CA17-2E10-2A17-2E11-A17-C12-A17-A12-2A15-2A6-F6-A15-A6-F2A2(28-3A)28-A-2A26-A2-2A25-2A2-3A23-3A3-3A21-3A5-3A19-3A7-4A15-4A11-2(A15-)2(F13-)C2(19-B10-J)2(19-B10-B)19-D10-D2(19-B10-B)19-B10-D19-D10-B19-D10-D19-B10-B19-B10-I19-E10-B19-E10-E19-B10-CA2(17-AE10-2A)17-2C11-A17-A12-2A15-2A6-F5-2A15-2A5-F2A3(28-3A)28-A-2A26-A2-2A25-2A3-2A23-2A4-3A21-3A6-2A19-2A10-2A15-2A14-2(F13-)B19-B10-A19-H10-C19-B2(10-D19-D)10-J5(19-B10-B)19-D2(10-D19-B)2(10-C19-C)10-CA3(17-AC10-2A)17-2A10-3A15-3A5-F5-2A15-2A5-F2A4(28-3A)28-A-2A26-A2-2A25-2A3-2A23-2A5-3A19-3A9-2A15-2A14-2(F13-)C19-C10-A19-C10-B19-C10-C19-D2(10-C19-B)2(10-C19-C)10-C19-B10-C19-D10-C19-B2(10-C19-C)10-A19-C10-A19-A3(10-2A17-2A)11-A17-A12-2A15-2A6-F5-2A15-2A5-F2A4(28-3A)28-A-2A26-A2-2A25-2A3-2A23-2A5-3A19-3A9-2A15-2A14-2(F13-)A19-B10-A19-A2(10-A19-B)10-C19-B10-D19-D3(10-C19-B)10-J19-B10-D19-D10-D2(19-B10-C)2(19-C10-C)A17-AC10-CA17-AC11-C17-C12-A17-A12-2A15-2A6-F6-A15-A6-F2A3(28-3A)28-A-2A26-A2-2A25-2A3-2A23-2A4-3A21-3A6-2A19-2A10-2A15-2A14-2(F13-)C19-B10-A19-B10-C19-B10-B19-B10-J19-D10-B19-B10-D19-B10-B19-D10-J4(19-B10-B)19-E10-B19-E10-E19-B11-G17-B12-B17-E12-E17-C12-C17-A13-A15-A7-F6-A15-A6-F2A2(28-3A)28-A-2A26-A2-2A25-2A2-3A23-3A3-3A21-3A5-4A17-4A7-4A15-4A11-A14-2A15-F12-F14-A19-D10-C2(19-B10-J)3(19-B10-B)19-B10-D19-B10-B19-3(B10-2B17-A)D11-B17-I12-B17-G12-I17-G13-G15-B14-G15-E14-E15-C14-C15-A14-A15-A8-F5-A15-A5-F2(2-A27-A)2-2A26-A2-2A25-2A2-3A23-3A3-3A21-3A4-4A19-4A5-4A17-4A8-3A15-3A2(13-A)17-F11-F14-A19-B10-B19-B10-C19-D10-D19-B10-A19-B10-D19-D3(10-B19-B)11-B17-D12-D2(17-B12-B)17-E12-B17-E12-E17-B13-I15-B14-B15-E14-E15-C14-C15-A14-A15-A8-F5-A15-A5-F2(2-A27-A)2-2A25-2A3-2A23-2A4-3A21-3A4-4A19-4A5-4A17-4A7-4A15-4A11-2(A15-)A13-A17-2F9-2F15-2(A17-B12-)2(B17-B12-)C17-B12-B17-B12-D17-B2(12-J17-D)12-DA15-AB12-JA15-AB12-2A15-AB12-DA15-AB13-5(C15-C14-)A15-C15-A13-H10-F5-A13-A5-F4-A4-2A13-2A2(4-A)25-A4-2A23-2A4-3A21-3A5-3A19-3A6-4A17-4A7-3A16-4A10-2A15-2A14-2A11-2A17-2A9-2A20-F7-F18-3(A15-B14-)2(16AB14-)7(C15AB14-)C15AD14-AC11A4B14-AC11A3EC15-K11A3E16-C11A2EI16-C11A2ED16-C11A3E16-C12A2C11-4F-C14A-4F3(6-25A)7-23A8-23A9-21A12-17A15-15A17-13A19-11A22-7F20-3AHBABH3ACBAB16-4A2(BC)HCACD2B16-CA2C4BCBAC3B16-KBKACJDC2BHC2BD16-ACBDC2BD2BC4B16-AKBH3BHBHC2(BD)16-CBKC4BD5BD16-CBA7BCH3B16-KDBHC6BC3B16-K3BDBD2BDC2BDB16-KBKHCBD2BCH4B16-A9BCD3B16-2(KB)D4BDC2BDB17-D2BDBD2BCHC2B18-3BC5B2CEI18-3BD4BD2C2G18-3B2D5BCEG18-EIE2D3BDCHDG18-2GIB2D4BC2E18-BGBC3BDB4C18-3ECHBE2G2ECA17-7C2E2IEC2A14-8AC3GIGC4A12-8ACBDGBDC4A12-8AC5BC4A13-7AC5EC3A15-6A7C2A16-15A18-11A20-11A21-9A42-
