model
size = 28 32 28, scale = 0.05, origin = -y
material 
  colors = A:#F60 B:#CF0 C:#EF5F00 D:#111 E:#FFF F:#400 G:#FF6999
voxels
504-2A2D2C2A2C2D5BC2D2A4C4AC2D3C2DA6B2A5DAC2A3CA5D2A6B2(2AC)2A3C2ACA7C6B7CAC4A2(CA)C4A6B4A2(CA)C2A253-2(C2A)C3A6B3A2(C2A)C2-10CB4DB10C2-C5AC3AD4ED3AC5AC2-CA8CD4-D8CAC2-CA2(C3A)D-2E-D2(3AC)AC2-2(CA)5C6DB6C2(AC)2-5C3ACA6BAC3A5C2-AC2A6C6B6C2ACA2-4C5DC6BC5D4C2-ACAD5-D6BD5-DACA2-2CAD6-D5BD5-DA2C2(2-ACD7-D4BD7-DCA)2-2CD7-D5B7D3C2-CACD5-D6B4C3(AC)2-2(CA)D3-DA6B3A3(CA)C2-5C3DCA5BDA3CA5C2-AC2AC3ACA6BDC3AC2ACA-11A6B22A6B11AC10A6B10A2C10A6B10A4CACA5C6B5CACA3C253-10C6B10C2-10A6B10A2-A10B4E10BA2-A10B4G10BA2-C10BG2EG10B2(C2-A24BA2-C24B)C2-A3B5E8B5E3BA2-C3B6E6B6E3BC2(2-A2B2E3D2E6B2E3D2E2BA)2-C2B2E3D2E7B2E2A4BC2-A3B5E8B2E2A4BA2-A4B3E10BEA5BA2(2-C24BC)-C2(A24BA2C)A24BAC2A24B4ACAC6A6B6ACAC2A253-2(C2A)2(CA)6B2(AC)2(2AC)2-10A6B10A2-A13BE10BA2-A10BE13B2(A2-C24BC2-A24B)A3(2-C24BC)2(2(2-A24BA)2-C24BC)2-A24BA-2A24B4A24B2ACA24BAC2A24B2A5CA5C6B5CA5C130-B27-2B26-2B65-2(C2A)2(CA)6B2(AC)2(2AC)2-C9A6B9A3(C2-C2B7A6B7A2B)C2(2-A2B7A6B7A2BA3(2-C2B7A6B7A2BC))5(2-C2B7A6B7A2BC)-C2(A2B7A6B7A2BA2C)2(A24BA2C)5AC4A6B4AC5AC102-2(B28-)B27-B24-3B37-10C6B10C2-10A6B10A2(2-A2B7A6B7A2BA)3(2-C2B7A6B7A2BC2-A2B7A6B7A2BA)2-A2B7A6B7A2BA2-C2B7A6B7A2BC4(2-A2B7A6B7A2BA)2-C2B7A6B7A2BC2-A2B7A6B7A2BA-2A2(2B7A6B7A2B4A)24B4A24B2A5CA5C6B5CA5C102-2B2(28-B)27-B26-B24-3B9-C4AC3AC6BC3AC4AC2-10A6B10A5(2-C2B7A6B7A2BC)2-A2B7A6B7A2BA10(2-C2B7A6B7A2BC)-C2(A2B7A6B7A2BA2C)2(A24BA2C)3AC5AC6BC5AC3AC73-B28-3B2(28-B)27-B26-B23-4B8-4CAC3AC6BC3ACA4C2-10A6B10A2-C2B7A6B7A2BC3(2-A2B7A6B7A2BA)2-C2B7A6B7A2BC2(2-A2B7A6B7A2BA)2(2-C2B7A6B7A2BC2-A2B7A6B7A2BA)3(2-A2B7A6B7A2BA)2-C2B7A6B7A2BC2-A2B7A6B7A2BA-2A2B7A6B7A2B4A2B7A6B7A2B2ACA24BAC2A24B3A4CA3CAC6BCA3CA4CA73-2B28-3B2(28-B)27-B20-2B4-B23-4B7-C2A7C6B7C2AC2-10A6B10A2-C2B7A6B7A2BC2-A2B7A6B7A2BA13(2-C2B7A6B7A2BC)2-A2B7A6B7A2BA-2A2B7A6B7A2B4A2B7A6B7A2B2ACA24BAC2A24B3AC4A2(CA)C6B2(CA)C4ACA44-B2(28-3B)2(28-B)18-2B7-B20-2B4-B23-4B6-2(C2A)C3A6B3A2(C2A)C2-C9A6B9AC2(2-C2B7A6B7A2BC2-A2B7A6B7A2BA)2-A2B7A6B7A2BA3(2-C2B7A6B7A2BC2(2-A2B7A6B7A2BA))2(2-C2B7A6B7A2BC)-C2(A2B7A6B7A2BA2C)A24BA2CA24BA6C2(AC)2A6B2A2(CA)5C43-3(3B28-)B17-2B8-B19-2B6-B21-2B3-B24-3B6-4C2AC3A6B3AC2A4C2-10A6B10A2(2-C2B7A6B7A2BC2-A2B7A6B7A2BA)2-A2B7A6B7A2BA3(2-C2B7A6B7A2BC2(2-A2B7A6B7A2BA))2-C2B7A6B7A2BC2-A2B7A6B7A2BA-2A2(2B7A6B7A2B4A)24B4A24B2AC3A2(CA)3C6B3C2(AC)3AC43-4B28-3B48-B3(28-2B)2-B25-2B6-2(26B2-)15(3B20A3B2-)3B20A3B-4B20A8B20A88B13-3B28-4B50-2(B28-)2(2B28-)B36-2(26B2-)15(3B20A3B2-)3B20A3B-4B20A8B20A88B12-5B24-B3-2B23-3(B28-)2B28-B65-2(26B2-)15(3B20A3B2-)3B20A3B-4B20A8B20A88B11-6B23-3B26-3B3(28-B)94-2(26B2-)15(3B20A3B2-)3B20A3B-4B20A8B20A88B11-6B2(24-3B)24-2(B26-)B103-2(26B2-)15(3B20A3B2-)3B20A3B-4B20A8B20A88B11-5B21-2B3-3(B26-)B25-2B25-B76-2(26B2-)15(3B20A3B2-)3B20A3B-4B20A8B20A88B12-3B21-4B57-B26-B25-2B24-2B25-B49-4C2AC3A6B3AC2A4C2-10A6B10A2(2-C2B7A6B7A2BC2-A2B7A6B7A2BA)2-A2B7A6B7A2BA3(2-C2B7A6B7A2BC2(2-A2B7A6B7A2BA))2-C2B7A6B7A2BC2-A2B7A6B7A2BA-2A2(2B7A6B7A2B4A)24B4A24B2AC3A2(CA)3C6B3C2(AC)3AC37-4B21-3B60-B25-2B24-2B21-B2-2B24-2B22-2(C2A)C3A6B3A2(C2A)C2-C9A6B9AC2(2-C2B7A6B7A2BC2-A2B7A6B7A2BA)2-A2B7A6B7A2BA3(2-C2B7A6B7A2BC2(2-A2B7A6B7A2BA))2(2-C2B7A6B7A2BC)-C2(A2B7A6B7A2BA2C)A24BA2CA24BA6C2(AC)2A6B2A2(CA)5C38-2(3B22-)3B24-B27-B8-2B17-B6-2B20-B3-2B23-3B21-C2A7C6B7C2AC2-10A6B10A2-C2B7A6B7A2BC2-A2B7A6B7A2BA13(2-C2B7A6B7A2BC)2-A2B7A6B7A2BA-2A2B7A6B7A2B4A2B7A6B7A2B2ACA24BAC2A24B3AC4A2(CA)C6B2(CA)C4ACA39-B24-3B22-3B24-B26-B27-B7-2B19-B4-2B22-4B20-4CAC3AC6BC3ACA4C2-10A6B10A2-C2B7A6B7A2BC3(2-A2B7A6B7A2BA)2-C2B7A6B7A2BC2(2-A2B7A6B7A2BA)2(2-C2B7A6B7A2BC2-A2B7A6B7A2BA)3(2-A2B7A6B7A2BA)2-C2B7A6B7A2BC2-A2B7A6B7A2BA-2A2B7A6B7A2B4A2B7A6B7A2B2ACA24BAC2A24B3A4CA3CAC6BCA3CA4CA65-2B23-3B24-B26-B27-B28-B4-2B22-4B19-C4AC3AC6BC3AC4AC2-10A6B10A5(2-C2B7A6B7A2BC)2-A2B7A6B7A2BA10(2-C2B7A6B7A2BC)-C2(A2B7A6B7A2BA2C)2(A24BA2C)3AC5AC6BC5AC3AC66-B24-3B24-B26-B27-2(B28-)4B18-10C6B10C2-10A6B10A2(2-A2B7A6B7A2BA)3(2-C2B7A6B7A2BC2-A2B7A6B7A2BA)2-A2B7A6B7A2BA2-C2B7A6B7A2BC4(2-A2B7A6B7A2BA)2-C2B7A6B7A2BC2-A2B7A6B7A2BA-2A2(2B7A6B7A2B4A)24B4A24B2A5CA5C6B5CA5C92-2B25-B26-B27-2(B28-)3B18-2(C2A)2(CA)6B2(AC)2(2AC)2-C9A6B9A3(C2-C2B7A6B7A2B)C2(2-A2B7A6B7A2BA3(2-C2B7A6B7A2BC))5(2-C2B7A6B7A2BC)-C2(A2B7A6B7A2BA2C)2(A24BA2C)5AC4A6B4AC5AC93-2(B26-)B27-B28-3B46-2(C2A)2(CA)6B2(AC)2(2AC)2-10A6B10A2(2-A24BA)2(2-C24BC2-A24BA)3(2-C24BC)2(2(2-A24BA)2-C24BC)2-A24BA-2A24B4A24B2ACA24BAC2A24B2A5CA5C6B5CA5C121-B2(26-2B)75-10C6B10C2-10AB4FB10A2-A9B6F9BA2(2-A9B6A9BA2-C9B6A9BC)2-A24BA2-C3B5A8B5A3BC2-A2B7A6B7A2BA2-CB9A4B9ABC2-AB9A4B9ABA2-AB4A2E3A4B3A2E4ABA2-CB9A4B9ABC2-AB9A4B9ABA2-A2B7A6B7A2BA2-C3B5A8B5A3BC2-C24BC-C2(A24BA2C)A24BAC2A24B4ACAC6A6B6ACAC2A253-2(C2A)C3A6B3A2(C2A)C2-10C6B10C2-C5AC3A6B3AC5AC2-CA8C6B8CAC2-CA2(C3A)6B2(3AC)AC2-2(CA)6C6B6C2(AC)2-5C3ACA6BAC3A5C2-AC2A6C6B6C2ACA2-5C2ACAC6BCAC2A5C2-AC2A5CA6BA5C2ACA2-2C2A3(CA)6B3(AC)2A2C2-A6CACA6BACA6CA2-A2C3A2(CA)6B2(AC)3A2CA2-2(3CA)CA6BAC2(A3C)2-3(CA)4C6B4C3(AC)2-3(CA)C3A6B3A3(CA)C2-5CA3CA6BA3CA5C2-AC2AC3ACA6BAC3AC2ACA-11A6B22A6B11AC10A6B10A2C10A6B10A4CACA5C6B5CACA3C756-2A4C2A3C6B3C2A4C4AC2A4C2A6B2A4C2AC2A3C2(2AC)2A6B2(2AC)2A3C2ACA7C6B7CAC4A2(CA)C4A6B4A2(CA)C2A252-
