model
size = 28 32 28, scale = 0.05, origin = -y
material 
  colors = A:#C36 B:#0FF C:#FFF D:#111 E:#FF6999 F:#400
voxels
504-4AD4A2D6B2D4AD9A4D2A6B2A4D16A2(6B22A)6B11A253-10A6B10A2-10A6D10A2-9AD6CD9A3(2-8AD8-D8A)2-9AD6CD9A2-10A6D10A2-10A6B10A2-6A4D6B4D6A2-4A2D4-D4BD4-2D4A4(2-3AD6-D4BD6-D3A)2-3AD5-D6BD5-D3A2-4A5DA6BA5D4A2-2AD7AD4BD7AD2A-11A4(6B22A)6B11A253-10A6B10A2-10AB4FB10A2-A9B6E9B3(A2-A8B8E8B)A2-A9B6E9BA2-A24BA2-A3B5A8B5A3BA2-A2B7A6B7A2BA2-AB4A4CA4BA4C4ABA2-AB2A6CA4BA6C2(2ABA2-AB2A2C2D2CA4BA2C2D2C)2ABA2-AB2A6CA4BA6C2ABA2-A2BA5CA6BA5CA2BA2-A3B5A8B5A3BA2-A24BA-2A3(24B4A)24B13A6B11A253-2(10A6B10A2-)15(A24BA2-)A24BA-2A3(24B4A)24B13A6B11A121-B2(26-2B)75-2(10A6B10A2-)15(A2B7A6B7A2BA2-)A2B7A6B7A2BA-2A2(2B7A6B7A2B4A)24B4A24B13A6B11A93-2(B26-)B27-B28-3B46-2(10A6B10A2-)15(A2B7A6B7A2BA2-)A2B7A6B7A2BA-2A2(2B7A6B7A2B4A)24B4A24B13A6B11A92-2B25-B26-B27-2(B28-)3B18-2(10A6B10A2-)15(A2B7A6B7A2BA2-)A2B7A6B7A2BA-2A2(2B7A6B7A2B4A)24B4A24B13A6B11A66-B24-3B24-B26-B27-2(B28-)4B18-2(10A6B10A2-)15(A2B7A6B7A2BA2-)A2B7A6B7A2BA-2A2(2B7A6B7A2B4A)24B4A24B13A6B11A65-2B23-3B24-B26-B27-B28-B4-2B22-4B19-2(10A6B10A2-)15(A2B7A6B7A2BA2-)A2B7A6B7A2BA-2A2(2B7A6B7A2B4A)24B4A24B13A6B11A39-B24-3B22-3B24-B26-B27-B7-2B19-B4-2B22-4B20-2(10A6B10A2-)15(A2B7A6B7A2BA2-)A2B7A6B7A2BA-2A2(2B7A6B7A2B4A)24B4A24B13A6B11A38-2(3B22-)3B24-B27-B8-2B17-B6-2B20-B3-2B23-3B21-2(10A6B10A2-)15(A2B7A6B7A2BA2-)A2B7A6B7A2BA-2A2(2B7A6B7A2B4A)24B4A24B13A6B11A37-4B21-3B60-B25-2B24-2B21-B2-2B24-2B22-2(26B2-)15(3B20A3B2-)3B20A3B-4B20A8B20A88B12-3B21-4B57-B26-B25-2B24-2B25-B49-2(26B2-)15(3B20A3B2-)3B20A3B-4B20A8B20A88B11-5B21-2B3-3(B26-)B25-2B25-B76-2(26B2-)15(3B20A3B2-)3B20A3B-4B20A8B20A88B11-6B2(24-3B)24-2(B26-)B103-2(26B2-)15(3B20A3B2-)3B20A3B-4B20A8B20A88B11-6B23-3B26-3B3(28-B)94-2(26B2-)15(3B20A3B2-)3B20A3B-4B20A8B20A88B12-5B24-B3-2B23-3(B28-)2B28-B65-2(26B2-)15(3B20A3B2-)3B20A3B-4B20A8B20A88B12-3B29-4B50-2(B28-)2(2B28-)B36-2(10A6B10A2-)15(A2B7A6B7A2BA2-)A2B7A6B7A2BA-2A2(2B7A6B7A2B4A)24B4A24B13A6B11A43-4B28-3B48-B3(28-2B)2-B25-2B6-2(10A6B10A2-)15(A2B7A6B7A2BA2-)A2B7A6B7A2BA-2A2(2B7A6B7A2B4A)24B4A24B13A6B11A43-3(3B28-)B17-2B8-B19-2B6-B21-2B3-B24-3B6-2(10A6B10A2-)15(A2B7A6B7A2BA2-)A2B7A6B7A2BA-2A2(2B7A6B7A2B4A)24B4A24B13A6B11A44-B2(28-3B)2(28-B)18-2B7-B20-2B4-B23-4B6-2(10A6B10A2-)15(A2B7A6B7A2BA2-)A2B7A6B7A2BA-2A2(2B7A6B7A2B4A)24B4A24B13A6B11A73-2B28-3B2(28-B)27-B20-2B4-B23-4B7-2(10A6B10A2-)15(A2B7A6B7A2BA2-)A2B7A6B7A2BA-2A2(2B7A6B7A2B4A)24B4A24B13A6B11A73-B28-3B2(28-B)27-B26-B23-4B8-2(10A6B10A2-)15(A2B7A6B7A2BA2-)A2B7A6B7A2BA-2A2(2B7A6B7A2B4A)24B4A24B13A6B11A102-2B2(28-B)27-B26-B24-3B9-2(10A6B10A2-)15(A2B7A6B7A2BA2-)A2B7A6B7A2BA-2A2(2B7A6B7A2B4A)24B4A24B13A6B11A102-2(B28-)B27-B24-3B37-2(10A6B10A2-)15(A24BA2-)A24BA-2A3(24B4A)24B13A6B11A130-B27-2B26-2B65-2(10A6B10A2-)15(A24BA2-)A24BA-2A3(24B4A)24B13A6B11A253-7(10A6B10A2-)10A6B7C3A2-10A5B2C4D3C2A2-10A5B9C2A2-10A5B2(C3D)C2A2-10A5B9C2A2-10A5BC2DC4DC2A2-10A5B9C2A2-10A5B2(C3D)C2A2-10A5B9C2A2-10A5B2C5D2C2A2-10A5B9C2A-11A3(5B9C14A)6B22A6B11A756-11A5BC7DC14A5B9C14A6B7C15A6B22A6B11A252-
