model
size = 30 32 28, scale = 0.05, origin = -y
material 
  colors = A:#90C B:#63F C:#5F2AFF D:#FC9 E:#001 F:#EEE G:#FFE3C7 H:#7348FF I:#FF6999 J:#9837B9 K:#4B0082
voxels
C2BCB2(C2B)6A3CBCBH4B2-2B2CBCB2C7EA4BC4-2H2-3C2BC2B2E5F3E2CBCB7-C3B3CBE8-2EC3BH6-2(2BC)2BE9-3ECBCH5-4CB2CB2E10-2E2(BC)H3-6BCBC2E10FE2CBCB3-B6CBCB12E2(BC)2B2-3BC4BCBC6A2BC3BCB3C2-2CBCB5EB6AC5E4BC2-3BCE5-E6AE5-E2CBC2-B2CE7-E4AE7-E2BC2-BCBE7-E4AE7-E3C2-BCBE7-E4AE7-E3B2-3BE7-E4AE7-EB2C2-3CE7-E4AE7-EBCB2-3BE7-E4AE7-EBCB2-BCBE7-E4AE7-EBCB2-B3CE5-E6AE5-ECB2C2-3BCB5EC6AC5EBC3B2-2(BC)ECB3CE6AE4BCE3CB2-2C3BEBCBEB6ACE2CBE5B2-B3CBC3E2C6ACB3E6C272-2C3B6C6A2B2(CB)5C2-B21A2G3DB2-B9A5K8A4D3-C8A8I6A4D3-B8A9I5A2D2G3-C9A10I3A4D3-B10A10K5AD3-C13A5K8AH2(2-C26AB)2-C4A2F3E8A2F3E4AB2-C3A3F4E6A3F4E3AC2(2-C3A3F4E6A3F4E3AB)2-C3A4F3E6A4F3E3AC2-C3A6FE6A7F3AB2-C3A7F6A7F3AC2-C3A7F6A7F3AB2-C4A5F8A5F4AC2-C26AC2-B26AC2-C26AC2-5B3CBCB6A4BC5BC272-2(C2B)C3BC6ACBC3BC4B2-C21A5DH2-3(B22A4D3-)C22A4D3-B26AH2-C26AH5(2-B26AC)2-B2(26AB2-C)26AB2-B26AC2(2-B26AB)2-C26AB2-B26AB2-C26AB2-2CB3C2(BC)B6AB2CBCB3C2B272-2B3C3BC2B6ACB3C3(BC)2-3(C25AD3-B25AD3-)C25ADB2-B4(25ADB2-C)2(25ADC2-C)25AD2(C2-B26A)C2-C26AB3(2-B26AC)2-B26AB2-2(BC)3B3CB6ABC2BC3B3C131-A2(28-2A)80-B2CBCB5C6AC3B3CBC2B2-C25AG2(3-C25AD)3-B25AD3-C25AD3-B25AD3-C25AG3-3(B25ADC2-)B25ADB2-B25ADC2(2-B25ADB)2(2-B26AB)3(2-C26AB)2-C26AC2-C26AB2-BC3BCBC3B6ABCB4CBC2B101-2(A28-)A29-A30-3A49-B2(C4B)6A3CBC3B3C2-4(B25AD3-)C25AD3-B25AD3-2(C25ADB2-)C25ADC2(2-C25ADB)2-C25ADC2-C25ADB2-C25AD2(C2-C26AC2-B26A)C2-B26AB2-B26AC2-C26AC2-6CBCB2C6ABC4BCB2CB100-2A27-A28-A29-2(A30-)3A19-2CBCB2CB3C6A4B2CB3CB2-C25AG4(3-C25AD)2(3-B25AG)3-B25ADB2-B25ADC2-C2(25ADC2-B25ADB2-B)25AD2(B2-B26A)B2-C26AB2-B26AC2-C2(26AC2-B)26AB2-7BC3B6A5CBC2BCB72-A26-3A26-A28-A29-2(A30-)4A19-C2BCBC3BCB6AB5CBC3B2-B25AG3(3-B25AD)2(3-C25AD)3-B25AG3-2(C25ADB2-B25ADB2-)3(C25ADC2-)B2(26AC2-C)2(26AB2-C26AC2-C)26AB2-CB4CB3CB6A3BC2B2CB2C71-2A25-3A26-A28-A29-A30-A4-2A24-4A20-C2BC3B2(CB)6AB2(C3B)CB2-B2(25AD3-C)2(25AD3-B)25AD3-C25AD3-B25AG3-C25ADH2(2-B25ADC)2-B25ADB2-B25ADC2-C2(25ADB2-B)26AB2-C3(26AC2-B)2(26AB2-B)26AB2-C4BC3BCB6A2(BC)B2C3BC43-A26-3A24-3A26-A28-A29-A7-2A21-A4-2A24-4A21-CB9C6A2(BC)B3CBCH2-2(B25AD3-)2(C25AD3-)3(B25AD3-)C25AD3-C25ADH2(2-C25ADB)2-B2(25ADB2-C)25ADC2-C26AB2-C26AC2-B3(26AB2-C)26AC2-B26AB2-2CBCB3CBCB6A2(BC)4B3C42-2(3A24-)3A26-A29-A8-2A19-A6-2A22-A3-2A25-3A22-CBC5BC2B6A5(BC)H2-C2(25AG3-B)25AG3(3-C25AD3-B25AD)3-2(B25ADH2-)B25ADC2-C2(25ADC2-B)2(26AB2-B)26AB2-C3(26AC2-B)26AB2-2CB2(C3B)6ABC3B2C2(BC)41-4A23-3A64-A27-2A26-2A23-A2-2A26-2A23-28A2(2-26ADA)-J26AD2A-3(26AD3-)2(26ADJ2-)27AJ12(2-28A)2-12A3B13A14-3A23-4A61-A28-A27-2A26-2A27-A52-28A3(2-26ADA)-27ADAJ-26AG3(3-26AD)A13(2-28A)2-12A3B13A13-5A23-2A3-3(A28-)A27-2A27-A81-28A2-26AG3(A2-26AD)A-J26ADAJ-3(26AD3-)27AJ12(2-28A)2-12A5B11A13-6A2(26-3A)26-2(A28-)A110-28A2-26AG3(A2-26AD)A-J26AD2A-3(26AD3-)26AG3-12(28A2-)12A5B11A13-6A25-3A28-3A3(30-A)101-28A2-26AG4(A2-26AD)A-J26AD2A-2(26AD3-)26AG3-27AJ12(2-28A)14-5A26-A3-2A25-3(A30-)2A30-A70-28A2(2-26ADA)2(2-26ADJ)2-26ADA-27ADAJ-4(26AD3-)27AJ11(2-28A)15-3A30-4A54-2(A30-)2(2A30-)A39-2BC3BCB3C6A5(BC)H2-C25ADH2-2(B25AD3-)2(C25AD3-B25AD3-)3(B25AD3-)B25ADH2(2-B25ADB)2-C25ADB2-B2(26AB2-C26AC2-C)26AB2-B26AC2-C26AC2-BC3BC2B3C6A2(CB)C3BCBC47-4A30-3A52-A3(30-2A)2-A27-2A7-2(CB)3CBC2B6A3BC3B3CB2-C25ADB2-B2(25AD3-C)3(25AD3-B)25AD3-C24A2D2(3-B25AD3-C25AD)2(C2-C25AD)C3(2-B26AB)2-B26AC2-C26AB2-B26AB2-C26AB2-B5CB2C2B6A2B5C2(BC)47-3(3A30-)A19-2A8-A21-2A6-A23-2A3-A26-3A7-CBC3B2(CB)C6A6CBC3B2-B25ADH2-B2(25AG3-C)2(25AD3-C)2(16A10D3-C)16A10D3-B16A9DG3-C16A9DG3-B25AG3-C2(25ADB2-B)25ADC2-B2(26AC2-C)2(26AC2-B26AC2-C)26AB2-3B2(CB)2CBC6A3C3B2(CB)C48-A2(30-3A)2(30-A)20-2A7-A22-2A4-A25-4A7-5(CB)C6A5B6C2-B25ADB2-C25AGH2-C25AG2(3-B25AD)3-B4(16A10D3-C)16A9D2(G3-C25A)GC2-B25ADH2-C25ADC2(2-C26AB)2(2-B26AB)2-C26AB2-B26AC2-C26AB2-4C4BCBC6A4B3(CB)C79-2A30-3A2(30-A)29-A22-2A4-A25-4A8-3CBC3BCBC6A6C5B2-B25ADB2-B25ADC2-B25AD3-B25AG3-C25AD2(3-B16A10D)3-C3(16A10D3-B)25AD3-C25AG3-B25ADC2-C25AD2(C2-B26A)B2-B2(26AC2-C)26AB2-B26AC2-C26AB2-5B2C3BC6A5C3(BC)79-A30-3A2(30-A)29-A28-A25-4A9-C3B7C6A2BC4B4C2-C25ADB2-C25ADC2-C25ADB2-C25AD3-C25AG2(3-C16A10D3-B16A10D)3-C16A10D3-B25AD3-C25AG3-B25AG3-C25AGH2-B2(26AB2-C)26AC2-C2(26AB2-B)26AC2-C26AB2-BCB5CB2C6A2BC3BCB3C110-2A2(30-A)29-A28-A26-3A10-2BCBC6B6A2(CB)2CBC2B2(C2-B25ADB2-B25AD)H2-C25AD2(3-B16A10D)3-C16A10D3-B16A10D3-C16A10D3-B25AD3-C25AD3-B25AG3-C25AG2(H2-B26A)B2-B26AC2-B26AB2-B2(26AC2-C)26AB2-BC5BC3B6A2(CB)3C3BC110-2(A30-)A29-A26-3A40-3CBCB4CB6ACB4CB2CBC2-C25ADB2-C2(25ADC2-B)25ADB2-C25A2G2-B2(16A10D3-C)16A10D3-B16A10D3-C16A10D3-B2(25AD3-C)2(25AG3-C)26AC2-C26AC2-B26AC3(2-C26AB)2-B26AB2-B5CB4C6A2BC3B3CBC140-A29-2A28-2A70-2(CB)C2BC3B6A2(C3B)CBC2-B25ADB2-C25ADC2-C25ADB2-B25ADB2-C25AH3-B16A10D3-B16A9DG2(3-B16A10D)3-C16A10D3-B7AD17A3(D3-B25A)G3-B26AH2-B26AB2-B26AC2-C3(26AC2-B)26AB2-2C3BCBC3B6A3CBC5BC272-2BCB2CBCB2C6A3C4(BC)2-B26AH2-B26AC2-C16A4D3GDGAB2-B11A5DG7D2GH2-C11A4D2G8D2(G3-C10A15D)G3-C6A19DG3-C6A6D2G12D3-C6A7D2G11D3-C6A8D2G10D3-C8A7DG10D3-C10A6DG3D3G3D3-C10A13DG2D3-C10A16D3-C17A8DG3-3(C26AB2-)C26AC2-C26AB2-C2B4(CB)6A4B5CBC272-C4BC3BCB6A2B4(CB)C2-CB2CB5CB6ACH2B3C2(BC)2-C2B3C5B6ACHCBCH2BCBC2-2CBC3B4C6A2C2H5-2H2-2(BC)B3C3B5AJ-H2B9-3(BC)3B2C5A14-5(BC)B4AJ14-BC3B3(CB)3AJ15-B5CBC3B2AJ16-BC3BCB4C2A17-3(BC)5B2AJ16-2(BC)B5CB4A15-3(BC)3BCB4AJ14-2(BC)3B2(CB)5AJ-G11-BCB5CBCB5AJH2B3HB6-BC5B2(CB)6AH3C3BHB4-B5C2(BC)B6AH2BCB5C3-BC3B3(CB)6A2CBC2BC3BC2-5(BC)B6A3B2CBCB3C2-2(BC)3BC3B6A2(BC)2BCBC2B2-2(BC)B6C6A2(2CBCB)C2-B3CBC3BCB6A3BC2B2(CB)C2-2B2C3(BC)B6A5C3BCBC272-
