model
size = 28 32 28, scale = 0.05, origin = -y
material 
  colors = A:#FF6999 B:#600 C:#F56193 D:#111 E:#FFF F:#F99 G:#F06 H:#400
voxels
504-CAC2D2(AC)AD6BD2(AC)A2D4(CA)2DCADA6BADAC2D6(AC)2DAC6BCA2D9(CA)6B11(AC)6B5(CA)C253-5(AC)6B5(CA)2-5(CA)6D5(AC)2-4(AC)AD6ED4(AC)A2-4(CA)D8-D4(AC)2-3(AC)AD10-D3(AC)A2-G2(AC)GCD-8E-D3(CA)C2-ACG2(CA)C10D2(CACG)2-2(CA)G2(AC)A6B2(ACAG)AC2-AG2(AC)GCAC6B2(CA)CG2(CA)2-2(CA)6D6B6DACGC2-ACAD6-D4BD6-DACA2-CACD6-D4BD6-DCAC2-ACAD6-D4BD5-2DACA2-CACD5-D6BD4-D2(AC)2-2(AC)D4-D6BD4-D2(CA)2-2(CA)CD2-2D6BAD2-2D2(AC)2-3(AC)3DC6BCA3D2(AC)A2-5(CA)6B5(AC)-2(11A6B11AC10A6B10AC)5(AC)A6B5(AC)A253-5(CA)6B5(AC)2-10A5BF10A2-C9B7F8BC2-A7BF8AF7BA2-C7B10A7BC2-A7B2A6F2A7B2(A2-C24BC2-A24B)A2-C3B6E6B6E3BC2-A3B6E6B6E3BA2-C3B4E2D6B4ED4BC2-A3B3E2D8B2E2D4BA2-C4B2E2D8B2E2D4BC2-A5BED10BED5BA2-C24BC2-A24BA-2(CA24BAC2A24B2A)5(CA)C6B5(CA)C253-5(AC)6B5(CA)2-C9A6B9A8(C2-A24BA2-C24B)C-2(2A24B2ACA24BAC)5(AC)A6B5(AC)A130-B27-2B26-2B65-5(CA)6B5(AC)2-10A6B10A8(2-C2B7A6B7A2BC2-A2B7A6B7A2BA)-CA2B7A6B7A2BAC2A2B7A6B7A2B2ACA24BAC2A24B2A5(CA)C6B5(CA)C102-2(B28-)B27-B24-3B37-5(AC)6B5(CA)2-C9A6B9A8(C2-A2B7A6B7A2BA2-C2B7A6B7A2B)C-2A2B7A6B7A2B2ACA2B7A6B7A2BAC2A24B2ACA24B6(AC)A6B5(AC)A102-2B2(28-B)27-B26-B24-3B9-5(CA)6B5(AC)2-10A6B10A8(2-C2B7A6B7A2BC2-A2B7A6B7A2BA)-CA2B7A6B7A2BAC2A2B7A6B7A2B2ACA24BAC2A24B2A5(CA)C6B5(CA)C73-B28-3B2(28-B)27-B26-B23-4B8-5(AC)6B5(CA)2-C9A6B9A8(C2-A2B7A6B7A2BA2-C2B7A6B7A2B)C-2A2B7A6B7A2B2ACA2B7A6B7A2BAC2A24B2ACA24B6(AC)A6B5(AC)A73-2B28-3B2(28-B)27-B20-2B4-B23-4B7-5(CA)6B5(AC)2-10A6B10A8(2-C2B7A6B7A2BC2-A2B7A6B7A2BA)-CA2B7A6B7A2BAC2A2B7A6B7A2B2ACA24BAC2A24B2A5(CA)C6B5(CA)C44-B2(28-3B)2(28-B)18-2B7-B20-2B4-B23-4B6-5(AC)6B5(CA)2-C9A6B9A8(C2-A2B7A6B7A2BA2-C2B7A6B7A2B)C-2A2B7A6B7A2B2ACA2B7A6B7A2BAC2A24B2ACA24B6(AC)A6B5(AC)A43-3(3B28-)B17-2B8-B19-2B6-B21-2B3-B24-3B6-5(CA)6B5(AC)2-10A6B10A8(2-C2B7A6B7A2BC2-A2B7A6B7A2BA)-CA2B7A6B7A2BAC2A2B7A6B7A2B2ACA24BAC2A24B2A5(CA)C6B5(CA)C43-4B28-3B48-B3(28-2B)2-B25-2B6-2(26B2-)15(3B20A3B2-)3B20A3B-4B20A8B20A88B13-3B28-4B50-2(B28-)2(2B28-)B36-2(26B2-)15(3B20A3B2-)3B20A3B-4B20A8B20A88B12-5B24-B3-2B23-3(B28-)2B28-B65-2(26B2-)15(3B20A3B2-)3B20A3B-4B20A8B20A88B11-6B23-3B26-3B3(28-B)94-2(26B2-)15(3B20A3B2-)3B20A3B-4B20A8B20A88B11-6B2(24-3B)24-2(B26-)B103-2(26B2-)15(3B20A3B2-)3B20A3B-4B20A8B20A88B11-5B21-2B3-3(B26-)B25-2B25-B76-2(26B2-)15(3B20A3B2-)3B20A3B-4B20A8B20A88B12-3B21-4B57-B26-B25-2B24-2B25-B49-5(CA)6B5(AC)2-10A6B10A8(2-C2B7A6B7A2BC2-A2B7A6B7A2BA)-CA2B7A6B7A2BAC2A2B7A6B7A2B2ACA24BAC2A24B2A5(CA)C6B5(CA)C37-4B21-3B60-B25-2B24-2B21-B2-2B24-2B22-5(AC)6B5(CA)2-C9A6B9A8(C2-A2B7A6B7A2BA2-C2B7A6B7A2B)C-2A2B7A6B7A2B2ACA2B7A6B7A2BAC2A24B2ACA24B6(AC)A6B5(AC)A38-2(3B22-)3B24-B27-B8-2B17-B6-2B20-B3-2B23-3B21-5(CA)6B5(AC)2-10A6B10A8(2-C2B7A6B7A2BC2-A2B7A6B7A2BA)-CA2B7A6B7A2BAC2A2B7A6B7A2B2ACA24BAC2A24B2A5(CA)C6B5(CA)C39-B24-3B22-3B24-B26-B27-B7-2B19-B4-2B22-4B20-5(AC)6B5(CA)2-C9A6B9A8(C2-A2B7A6B7A2BA2-C2B7A6B7A2B)C-2A2B7A6B7A2B2ACA2B7A6B7A2BAC2A24B2ACA24B6(AC)A6B5(AC)A65-2B23-3B24-B26-B27-B28-B4-2B22-4B19-5(CA)6B5(AC)2-10A6B10A8(2-C2B7A6B7A2BC2-A2B7A6B7A2BA)-CA2B7A6B7A2BAC2A2B7A6B7A2B2ACA24BAC2A24B2A5(CA)C6B5(CA)C66-B24-3B24-B26-B27-2(B28-)4B18-5(AC)6B5(CA)2-C9A6B9A8(C2-A2B7A6B7A2BA2-C2B7A6B7A2B)C-2A2B7A6B7A2B2ACA2B7A6B7A2BAC2A24B2ACA24B6(AC)A6B5(AC)A92-2B25-B26-B27-2(B28-)3B18-5(CA)6B5(AC)2-10A6B10A8(2-C2B7A6B7A2BC2-A2B7A6B7A2BA)-CA2B7A6B7A2BAC2A2B7A6B7A2B2ACA24BAC2A24B2A5(CA)C6B5(CA)C93-2(B26-)B27-B28-3B46-5(AC)6B5(CA)2-C9A6B9A8(C2-A24BA2-C24B)C-2(2A24B2ACA24BAC)5(AC)A6B5(AC)A121-B2(26-2B)75-5(CA)6B5(AC)2-10AB4HB10A2-C9B6H2(9BC2-A9B6A9BA2-C9B6A)9BC2-A24BA2-C3B5A8B5A3BC2-A2B7A6B7A2BA2-CB9A4B9ABC2-AB9A4B9ABA2-CB4A2E3A4B3A2E4ABC2-AB9A4B9ABA2-CB9A4B9ABC2-A2B7A6B7A2BA2-C3B5A8B5A3BC2-A24BA-2(CA24BAC2A24B2A)5(CA)C6B5(CA)C253-8(5(AC)6B5(CA)2-5(CA)6B5(AC)2-)5(AC)6B5(CA)2-5(CA)6B5(AC)-2(11A6B11AC10A6B10AC)5(AC)A6B5(AC)A756-5(CA)C2(6B11(CA)6B11(AC))6B5(CA)C252-
