model
size = 28 32 28, scale = 0.05, origin = -y
material 
  colors = A:#E20000 B:#FF0 C:#111 D:#FFF E:#FF6999 F:#400
voxels
504-9A2C6B2C16A3CA6BA3C18A2(6B22A)6B11A253-10A6B10A2-10AB4CB10A2-10AC4DC10A4(2-9AC6-C9A)2-4A5CAC4DCA5C4A2-3AC5-CB4CBC5-C3A2-2AC7-C4BC7-C2A4(2-AC8-C4BC8-CA)2-AC7-C6BC7-CA2-2AC5-CABC2BCBAC5-C2A2-3AC3-C2A2C2B2C2AC3-C3A2-4A3C2A2C4B2C2A3C4A-11A4(6B22A)6B11A253-10A6B10A2-10AB4FB10A2-A9B6F9BA2-A9BC4EC2(9BA2-A9B6E)9BA2-A9BC4EC9BA2-A24BA2-A3B5D8B5D3BA2-A2B2D3C2D6B2D3C2D2BA2-AB2D5C2D4B2D5C2D2(BA2-ABD6C2D4B2D6CD)BA2-ABD5C3D4B3D5CDBA2-AB2D3C4D4B4D3C2DBA2-A2B2DC4D6B4DC2D2BA2-A3B5D8B5D3BA2-A24BA-2A3(24B4A)24B13A6B11A253-2(10A6B10A2-)15(A24BA2-)A24BA-2A3(24B4A)24B13A6B11A130-B27-2B26-2B65-2(10A6B10A2-)15(A2B7A6B7A2BA2-)A2B7A6B7A2BA-2A2(2B7A6B7A2B4A)24B4A24B13A6B11A102-2(B28-)B27-B24-3B37-2(10A6B10A2-)15(A2B7A6B7A2BA2-)A2B7A6B7A2BA-2A2(2B7A6B7A2B4A)24B4A24B13A6B11A102-2B2(28-B)27-B26-B24-3B9-2(10A6B10A2-)15(A2B7A6B7A2BA2-)A2B7A6B7A2BA-2A2(2B7A6B7A2B4A)24B4A24B13A6B11A73-B28-3B2(28-B)27-B26-B23-4B8-2(10A6B10A2-)15(A2B7A6B7A2BA2-)A2B7A6B7A2BA-2A2(2B7A6B7A2B4A)24B4A24B13A6B11A73-2B28-3B2(28-B)27-B20-2B4-B23-4B7-2(10A6B10A2-)15(A2B7A6B7A2BA2-)A2B7A6B7A2BA-2A2(2B7A6B7A2B4A)24B4A24B13A6B11A44-B2(28-3B)2(28-B)18-2B7-B20-2B4-B23-4B6-2(10A6B10A2-)15(A2B7A6B7A2BA2-)A2B7A6B7A2BA-2A2(2B7A6B7A2B4A)24B4A24B13A6B11A43-3(3B28-)B17-2B8-B19-2B6-B21-2B3-B24-3B6-2(10A6B10A2-)15(A2B7A6B7A2BA2-)A2B7A6B7A2BA-2A2(2B7A6B7A2B4A)24B4A24B13A6B11A43-4B28-3B48-B3(28-2B)2-B25-2B6-2(26B2-)15(3B20A3B2-)3B20A3B-4B20A8B20A88B13-3B28-4B50-2(B28-)2(2B28-)B36-2(26B2-)15(3B20A3B2-)3B20A3B-4B20A8B20A88B12-5B24-B3-2B23-3(B28-)2B28-B65-2(26B2-)15(3B20A3B2-)3B20A3B-4B20A8B20A88B11-6B23-3B26-3B3(28-B)94-2(26B2-)15(3B20A3B2-)3B20A3B-4B20A8B20A88B11-6B2(24-3B)24-2(B26-)B103-2(26B2-)15(3B20A3B2-)3B20A3B-4B20A8B20A88B11-5B21-2B3-3(B26-)B25-2B25-B76-2(26B2-)15(3B20A3B2-)3B20A3B-4B20A8B20A88B12-3B21-4B57-B26-B25-2B24-2B25-B49-2(10A6B10A2-)15(A2B7A6B7A2BA2-)A2B7A6B7A2BA-2A2(2B7A6B7A2B4A)24B4A24B13A6B11A37-4B21-3B60-B25-2B24-2B21-B2-2B24-2B22-2(10A6B10A2-)15(A2B7A6B7A2BA2-)A2B7A6B7A2BA-2A2(2B7A6B7A2B4A)24B4A24B13A6B11A38-2(3B22-)3B24-B27-B8-2B17-B6-2B20-B3-2B23-3B21-2(10A6B10A2-)15(A2B7A6B7A2BA2-)A2B7A6B7A2BA-2A2(2B7A6B7A2B4A)24B4A24B13A6B11A39-B24-3B22-3B24-B26-B27-B7-2B19-B4-2B22-4B20-2(10A6B10A2-)15(A2B7A6B7A2BA2-)A2B7A6B7A2BA-2A2(2B7A6B7A2B4A)24B4A24B13A6B11A65-2B23-3B24-B26-B27-B28-B4-2B22-4B19-2(10A6B10A2-)15(A2B7A6B7A2BA2-)A2B7A6B7A2BA-2A2(2B7A6B7A2B4A)24B4A24B13A6B11A66-B24-3B24-B26-B27-2(B28-)4B18-2(10A6B10A2-)15(A2B7A6B7A2BA2-)A2B7A6B7A2BA-2A2(2B7A6B7A2B4A)24B4A24B13A6B11A92-2B25-B26-B27-2(B28-)3B18-2(10A6B10A2-)15(A2B7A6B7A2BA2-)A2B7A6B7A2BA-2A2(2B7A6B7A2B4A)24B4A24B13A6B11A93-2(B26-)B27-B28-3B46-2(10A6B10A2-)15(A24BA2-)A24BA-2A3(24B4A)24B13A6B11A121-B2(26-2B)75-2(10A6B10A2-)15(A24BA2-)A24BA-2A3(24B4A)24B13A6B11A253-17(10A6B10A2-)10A6B10A-11A4(6B22A)6B11A756-11A4(6B22A)6B11A252-
