model
size = 14 17 26, scale = 0.05, origin = -y
material 
  colors = A:#EEE B:#111 C:#DDD
voxels
----CCCCCC---- ----CCCCCC---- ----CCCCCC---- ----AAAAAA---- ----AAAAAA---- -------------- -------------- -------------- -------------- -------------- -------------- -------------- -------------- -------------- -------------- -------------- -------------- 
---CA-A-A-CC-- ---CA-A-A-CC-- ---CAAAAAACC-- ---AAAAAAAAB-- ---ABBBBBBAB-- ----AAAAAA---- -------------- -------------- -------------- -------------- -------------- -------------- -------------- -------------- -------------- -------------- -------------- 
--CA-A-A-A-AC- --CA-A-A-A-AC- --CAAAAAAAAAC- --BAAAAAAAAAB- --BBBBBBBBBBB- ---AABBBBAAB-- -----AAAA----- -------------- -------------- -------------- -------------- -------------- -------------- -------------- -------------- -------------- -------------- 
--C-A-A-A-A-AC --C-A-A-A-A-AC --CAAAAAAAAAAC --BAAAAAAAAAAB --BBBBBBBBBBBB ---B-------BB- ----AAAAAAB--- -------------- -------------- -------------- -------------- -------------- -------------- -------------- -------------- -------------- -------------- 
-C-A-A-A-A-A-C -C-A-A-A-A-A-C -CAAAAAAAAAAAC -BAAAAAAAAAAAB -BBBBBBBBBBBBB --B---------B- ---BB-----BB-- -----AAAAB---- -------------- -------------- -------------- -------------- -------------- -------------- -------------- -------------- -------------- 
-CA-A-A-A-A-AC -CA-A-A-A-A-AC -CAAAAAAAAAAAC -BAAAAAAAAAAAB -BBBBBBBBBBBBB --B---------B- ---B-------B-- ----BBBBBBB--- ------BB------ -------------- -------------- -------------- -------------- -------------- -------------- -------------- -------------- 
-C-A-A-A-A-A-C -C-A-A-A-A-A-C -CAAAAAAAAAAAC -BAAAAAAAAAAAB -BBBBBBBBBBBBB --B---------B- ---B-------B-- ----BBBBBBB--- -----BBBB----- -------------- -------------- -------------- -------------- -------------- -------------- -------------- -------------- 
-CA-A-A-A-A-AC -CA-A-A-A-A-AC -CAAAAAAAAAAAC -BAAAAAAAAAAAB -BBBBBBBBBBBBB --B---------B- --BB-------B-- ---BBBBBB-B--- ----BBBBBB---- ------BB------ -------------- -------------- -------------- -------------- -------------- -------------- -------------- 
CA-A-A-A-A-A-C CA-A-A-A-A-A-C CAAAAAAAAAAAAC BAAAAAAAAAAAAB BBBBBBBBBBBBBB -B----------B- --B--------B-- ---ABBBBB-A--- ---BBBBBBB---- ----BBBBB----- -------------- -------------- -------------- -------------- -------------- -------------- -------------- 
C-A-A-A-A-A-C- C-A-A-A-A-A-C- CAAAAAAAAAAAC- BAAAAAAAAAAAB- BBBBBBBBBBBBB- -B---------BB- --A--------A-- --AB------A--- ---B-----B---- ---BBBBBB----- -------------- -------------- -------------- -------------- -------------- -------------- -------------- 
CA-A-A-A-A-AC- CA-A-A-A-A-AC- CAAAAAAAAAAAC- BAAAAAAAAAAAB- ABBBBBBBBBBBA- -A---------A-- -AB--------A-- --BB------B--- --BB-----B---- ---B----BB---- ----BBBBB----- -------------- -------------- -------------- -------------- -------------- -------------- 
C-A-A-A-A-A-C- C-A-A-A-A-A-C- CAAAAAAAAAAAC- AAAAAAAAAAAAA- ABBBBBBBBBBBA- -A---------A-- -B---------B-- -B---------B-- --B-------B--- --B------B---- ---BBBBBBB---- -----BBB------ -------------- -------------- -------------- -------------- -------------- 
CA-A-A-A-A-AC- CA-A-A-A-A-AC- CAAAAAAAAAAAC- AAAAAAAAAAAAA- BBBBBBBBBBBBB- BB---------B-- -B---------B-- -B---------B-- --A-------A--- --B-------B--- ---BBBBBBB---- ----BBBBB----- -----BBB------ -------------- -------------- -------------- -------------- 
C-A-A-A-A-A-C- C-A-A-A-A-A-C- CAAAAAAAAAAAC- BAAAAAAAAAAAB- BBBBBBBBBBBBB- BB---------B-- -B---------B-- -A---------A-- --A-------A--- --B-------B--- ---BBBBBBB---- ----BBBBB----- ----BBBBB----- -----BBB------ -------------- -------------- -------------- 
CA-A-A-A-A-AC- CA-A-A-A-A-AC- CAAAAAAAAAAAC- BAAAAAAAAAAAB- BBBBBBBBBBBBB- BB---------B-- -A---------A-- -A---------A-- -BB-------B--- --B-------B--- ---B-----B---- ---BB---BB---- ----BBBBB----- ----BBBBB----- -----BBB------ -------------- -------------- 
C-A-A-A-A-A-C- C-A-A-A-A-A-C- CAAAAAAAAAAAC- BAAAAAAAAAAAB- ABBBBBBBBBBBA- AB---------A-- AB---------A-- -B---------B-- -BB-------BB-- --B-------B--- ---B-----BB--- ---BB---BB---- ---BB---BB---- ----BBBBB----- -----BBB------ -----BBB------ -------------- 
CA-A-A-A-A-AC- CA-A-A-A-A-AC- CAAAAAAAAAAAC- AAAAAAAAAAAAA- ABBBBBBBBBBBA- AB---------A-- BB---------B-- -B---------B-- -BB-------BB-- --B-------B--- ---B-----BB--- ---B-----BB--- ---BB---BB---- ----B---B----- ----BBBBB----- -----BBB------ -----BBB------ 
C-A-A-A-A-A-AC C-A-A-A-A-A-AC CAAAAAAAAAAAAC AAAAAAAAAAAAAA BBBBBBBBBBBBBB BB----------B- BB----------B- BB----------B- -B---------B-- -B---------B-- --B-------B--- ---B-----BB--- ---B-----B---- ---B-----B---- ---BB---BB---- ----B---B----- -------------- 
CA-A-A-A-A-A-C CA-A-A-A-A-A-C CAAAAAAAAAAAAC BAAAAAAAAAAAAB BBBBBBBBBBBBBB BB----------B- BB----------B- BB----------B- BB----------B- -B---------BB- -B---------B-- --B-------B--- --B-------B--- --B-------B--- -------------- -------------- -------------- 
C-A-A-A-A-A-AC C-A-A-A-A-A-AC CAAAAAAAAAAAAC BAAAAAAAAAAAAB BBBBBBBBBBBBBB BB----------B- BB----------B- BB----------B- BB----------B- BB----------B- -B----------B- --B--------B-- --B--------B-- -------------- -------------- -------------- -------------- 
CA-A-A-A-A-A-C CA-A-A-A-A-A-C CAAAAAAAAAAAAC BAAAAAAAAAAAAB BBBBBBBBBBBBBB BB----------B- BB----------B- BB----------B- BB----------B- BB----------B- -B----------B- --B--------B-- --B--------B-- -------------- -------------- -------------- -------------- 
C-A-A-A-A-A-AC C-A-A-A-A-A-AC CAAAAAAAAAAAAC BAAAAAAAAAAAAB BBBBBBBBBBBBBB -B----------B- -B----------B- -B----------B- -B----------B- -B----------B- -B----------B- --B--------B-- --B--------B-- -------------- -------------- -------------- -------------- 
-C-A-A-A-A-AC- -C-A-A-A-A-AC- -CAAAAAAAAAAC- -BAAAAAAAAAAB- -BBBBBBBBBBBB- --B--------B-- --B--------B-- --B--------B-- --B--------B-- --B--------B-- --B--------B-- ---B------B--- ---B------B--- ---B------B--- -------------- -------------- -------------- 
-CA-A-A-A-A-C- -CA-A-A-A-A-C- -CAAAAAAAAAAC- -BAAAAAAAAAAB- -BBBBBBBBBBBB- --B--------B-- --B--------B-- --B--------B-- --B--------B-- --B--------B-- --B--------B-- ---BBBBBBBB--- ----BBBBBB---- ----BBBBBB---- -----BBBB----- -------------- -------------- 
--CA-A-A-A-C-- --CA-A-A-A-C-- --CAAAAAAAAC-- --BAAAAAAAAB-- --BBBBBBBBBB-- ---BBBBBBBB--- ---BBBBBBBB--- ---BBBBBBBB--- ---BBBBBBBB--- ---BBBBBBBB--- ---BBBBBBBB--- -----BBBB----- ------BB------ -------------- -------------- -------------- -------------- 
---CCCCCCCC--- ---CCCCCCCC--- ---CCCCCCCC--- ---BBBBBBBB--- ---BBABBABB--- ----BBABAB---- ----BBABAB---- ----BABBAB---- -----ABBA----- ------AA------ -------------- -------------- -------------- -------------- -------------- -------------- -------------- 
