model
size = 14 17 26, scale = 0.05, origin = -y
material 
  colors = A:#EEE B:#111 C:#DDD
voxels
----CCCCCC---- ----CCCCCC---- ----CCCCCC---- ----AAAAAA---- ----AAAAAA---- -------------- -------------- -------------- -------------- -------------- -------------- -------------- -------------- -------------- -------------- -------------- -------------- 
--CC-A-A-AC--- --CC-A-A-AC--- --CCAAAAAAC--- --BAAAAAAAA--- --BABBBBBBA--- ----AAAAAA---- -------------- -------------- -------------- -------------- -------------- -------------- -------------- -------------- -------------- -------------- -------------- 
-CA-A-A-A-AC-- -CA-A-A-A-AC-- -CAAAAAAAAAC-- -BAAAAAAAAAB-- -BBBBBBBBBBB-- --BAABBBBAA--- -----AAAA----- -------------- -------------- -------------- -------------- -------------- -------------- -------------- -------------- -------------- -------------- 
CA-A-A-A-A-C-- CA-A-A-A-A-C-- CAAAAAAAAAAC-- BAAAAAAAAAAB-- BBBBBBBBBBBB-- -BB-------B--- ---BAAAAAA---- -------------- -------------- -------------- -------------- -------------- -------------- -------------- -------------- -------------- -------------- 
C-A-A-A-A-A-C- C-A-A-A-A-A-C- CAAAAAAAAAAAC- BAAAAAAAAAAAB- BBBBBBBBBBBBB- -B---------B-- --BB-----BB--- ----BAAAA----- -------------- -------------- -------------- -------------- -------------- -------------- -------------- -------------- -------------- 
CA-A-A-A-A-AC- CA-A-A-A-A-AC- CAAAAAAAAAAAC- BAAAAAAAAAAAB- BBBBBBBBBBBBB- -B---------B-- --B-------B--- ---BBBBBBB---- ------BB------ -------------- -------------- -------------- -------------- -------------- -------------- -------------- -------------- 
C-A-A-A-A-A-C- C-A-A-A-A-A-C- CAAAAAAAAAAAC- BAAAAAAAAAAAB- BBBBBBBBBBBBB- -B---------B-- --B-------B--- ---BBBBBBB---- -----BBBB----- -------------- -------------- -------------- -------------- -------------- -------------- -------------- -------------- 
CA-A-A-A-A-AC- CA-A-A-A-A-AC- CAAAAAAAAAAAC- BAAAAAAAAAAAB- BBBBBBBBBBBBB- -B---------B-- --B-------BB-- ---B-BBBBBB--- ----BBBBBB---- ------BB------ -------------- -------------- -------------- -------------- -------------- -------------- -------------- 
C-A-A-A-A-A-AC C-A-A-A-A-A-AC CAAAAAAAAAAAAC BAAAAAAAAAAAAB BBBBBBBBBBBBBB -B----------B- --B--------B-- ---A-BBBBBA--- ----BBBBBBB--- -----BBBBB---- -------------- -------------- -------------- -------------- -------------- -------------- -------------- 
-C-A-A-A-A-A-C -C-A-A-A-A-A-C -CAAAAAAAAAAAC -BAAAAAAAAAAAB -BBBBBBBBBBBBB -BB---------B- --A--------A-- ---A------BA-- ----B-----B--- -----BBBBBB--- -------------- -------------- -------------- -------------- -------------- -------------- -------------- 
-CA-A-A-A-A-AC -CA-A-A-A-A-AC -CAAAAAAAAAAAC -BAAAAAAAAAAAB -ABBBBBBBBBBBA --A---------A- --A--------BA- ---B------BB-- ----B-----BB-- ----BB----B--- -----BBBBB---- -------------- -------------- -------------- -------------- -------------- -------------- 
-C-A-A-A-A-A-C -C-A-A-A-A-A-C -CAAAAAAAAAAAC -AAAAAAAAAAAAA -ABBBBBBBBBBBA --A---------A- --B---------B- --B---------B- ---B-------B-- ----B------B-- ----BBBBBBB--- ------BBB----- -------------- -------------- -------------- -------------- -------------- 
-CA-A-A-A-A-AC -CA-A-A-A-A-AC -CAAAAAAAAAAAC -AAAAAAAAAAAAA -BBBBBBBBBBBBB --B---------BB --B---------B- --B---------B- ---A-------A-- ---B-------B-- ----BBBBBBB--- -----BBBBB---- ------BBB----- -------------- -------------- -------------- -------------- 
-C-A-A-A-A-A-C -C-A-A-A-A-A-C -CAAAAAAAAAAAC -BAAAAAAAAAAAB -BBBBBBBBBBBBB --B---------BB --B---------B- --A---------A- ---A-------A-- ---B-------B-- ----BBBBBBB--- -----BBBBB---- -----BBBBB---- ------BBB----- -------------- -------------- -------------- 
-CA-A-A-A-A-AC -CA-A-A-A-A-AC -CAAAAAAAAAAAC -BAAAAAAAAAAAB -BBBBBBBBBBBBB --B---------BB --A---------A- --A---------A- ---B-------BB- ---B-------B-- ----B-----B--- ----BB---BB--- -----BBBBB---- -----BBBBB---- ------BBB----- -------------- -------------- 
-C-A-A-A-A-A-C -C-A-A-A-A-A-C -CAAAAAAAAAAAC -BAAAAAAAAAAAB -ABBBBBBBBBBBA --A---------BA --A---------BA --B---------B- --BB-------BB- ---B-------B-- ---BB-----B--- ----BB---BB--- ----BB---BB--- -----BBBBB---- ------BBB----- ------BBB----- -------------- 
-CA-A-A-A-A-AC -CA-A-A-A-A-AC -CAAAAAAAAAAAC -AAAAAAAAAAAAA -ABBBBBBBBBBBA --A---------BA --B---------BB --B---------B- --BB-------BB- ---B-------B-- ---BB-----B--- ---BB-----B--- ----BB---BB--- -----B---B---- -----BBBBB---- ------BBB----- ------BBB----- 
CA-A-A-A-A-A-C CA-A-A-A-A-A-C CAAAAAAAAAAAAC AAAAAAAAAAAAAA BBBBBBBBBBBBBB -B----------BB -B----------BB -B----------BB --B---------B- --B---------B- ---B-------B-- ---BB-----B--- ----B-----B--- ----B-----B--- ----BB---BB--- -----B---B---- -------------- 
C-A-A-A-A-A-AC C-A-A-A-A-A-AC CAAAAAAAAAAAAC BAAAAAAAAAAAAB BBBBBBBBBBBBBB -B----------BB -B----------BB -B----------BB -B----------BB -BB---------B- --B---------B- ---B-------B-- ---B-------B-- ---B-------B-- -------------- -------------- -------------- 
CA-A-A-A-A-A-C CA-A-A-A-A-A-C CAAAAAAAAAAAAC BAAAAAAAAAAAAB BBBBBBBBBBBBBB -B----------BB -B----------BB -B----------BB -B----------BB -B----------BB -B----------B- --B--------B-- --B--------B-- -------------- -------------- -------------- -------------- 
C-A-A-A-A-A-AC C-A-A-A-A-A-AC CAAAAAAAAAAAAC BAAAAAAAAAAAAB BBBBBBBBBBBBBB -B----------BB -B----------BB -B----------BB -B----------BB -B----------BB -B----------B- --B--------B-- --B--------B-- -------------- -------------- -------------- -------------- 
CA-A-A-A-A-A-C CA-A-A-A-A-A-C CAAAAAAAAAAAAC BAAAAAAAAAAAAB BBBBBBBBBBBBBB -B----------B- -B----------B- -B----------B- -B----------B- -B----------B- -B----------B- --B--------B-- --B--------B-- -------------- -------------- -------------- -------------- 
-CA-A-A-A-A-C- -CA-A-A-A-A-C- -CAAAAAAAAAAC- -BAAAAAAAAAAB- -BBBBBBBBBBBB- --B--------B-- --B--------B-- --B--------B-- --B--------B-- --B--------B-- --B--------B-- ---B------B--- ---B------B--- ---B------B--- -------------- -------------- -------------- 
-C-A-A-A-A-AC- -C-A-A-A-A-AC- -CAAAAAAAAAAC- -BAAAAAAAAAAB- -BBBBBBBBBBBB- --B--------B-- --B--------B-- --B--------B-- --B--------B-- --B--------B-- --B--------B-- ---BBBBBBBB--- ----BBBBBB---- ----BBBBBB---- -----BBBB----- -------------- -------------- 
--C-A-A-A-AC-- --C-A-A-A-AC-- --CAAAAAAAAC-- --BAAAAAAAAB-- --BBBBBBBBBB-- ---BBBBBBBB--- ---BBBBBBBB--- ---BBBBBBBB--- ---BBBBBBBB--- ---BBBBBBBB--- ---BBBBBBBB--- -----BBBB----- ------BB------ -------------- -------------- -------------- -------------- 
---CCCCCCCC--- ---CCCCCCCC--- ---CCCCCCCC--- ---BBBBBBBB--- ---BBABBABB--- ----BBABAB---- ----BBABAB---- ----BABBAB---- -----ABBA----- ------AA------ -------------- -------------- -------------- -------------- -------------- -------------- -------------- 
