model
size = 18 8 12, scale = 0.05, origin = -y
material 
  colors = A:#595959 B:#9F5B17
voxels
-AA---AA--AA---AA- -ABA-ABA--ABA-ABA- --ABABA----ABABA-- --ABBBA----ABBBA-- -ABBBBBA--ABBBBBA- AAABBBAAAAAABBBAAA --AABAA----AABAA-- ----A--------A---- 
------------------ ------------------ ------------------ ------------------ ------------------ --A------------A-- ------------------ ------------------ 
------------------ ------------------ ------------------ ------------------ ------------------ --A------------A-- ------------------ ------------------ 
------------------ ------------------ ------------------ ------------------ ------------------ --A------------A-- ------------------ ------------------ 
------------------ ------------------ ------------------ ------------------ ------------------ --A------------A-- ------------------ ------------------ 
------------------ ------------------ ------------------ ------------------ ------------------ --A------------A-- ------------------ ------------------ 
------------------ ------------------ ------------------ ------------------ ------------------ --A------------A-- ------------------ ------------------ 
------------------ ------------------ ------------------ ------------------ ------------------ --A------------A-- ------------------ ------------------ 
------------------ ------------------ ------------------ ------------------ ------------------ --A------------A-- ------------------ ------------------ 
------------------ ------------------ ------------------ ------------------ ------------------ --A------------A-- ------------------ ------------------ 
------------------ ------------------ ------------------ ------------------ --A------------A-- --A------------A-- ------------------ ------------------ 
------------------ ------------------ --A------------A-- --A------------A-- --A------------A-- ------------------ ------------------ ------------------ 
