model
size = 9 8 27, scale = 0.05, origin = -y
material 
  colors = A:#EEE B:#444 C:#500 D:#200 E:#700 F:#DDD G:#888 H:#222
voxels
--------- --------- --------- --------- --------- --------- ---CCC--- ---BDB--- 
--------- --------- --------- --------- --------- --------- --CCCCC-- --BDBDB-- 
--------- --------- --------- --------- --------- --------- -CCCCCCC- -BDBDBDB- 
--------- AA-----AA AA-----AA AA-----AA --------- --------- -CCCCCCC- -DBDBDBD- 
AA-----AA A-------A A-------A A-------A AA-----AA --------- -CCCCCCC- -BDBDBDB- 
AA-----AA A-------A CBBBBBBBC A--BBB--A AA--B--AA ----B---- -CCHBHCC- -DBDBDBD- 
AA-----AA A-------A A-------A A---B---A AA--B--AA ----B---- -CCBBBCC- -BDBDBDB- 
--------- AA-----AA AA-----AA AA-----AA ----B---- ----B---- -GCHBHGG- -DBDBDBD- 
--------- --------- --------- --------- --------- --------- -GCGCGCC- -BDBDBDB- 
--------- --------- --------- --------- --------- --------- -CGGCGGG- -DBDBDBD- 
--------- --------- --------- --------- --------- --------- -GCGCCCG- -BDBDBDB- 
--------- --------- --------- --------- --------- --------- -GCGCGGG- -DBDBDBD- 
--------- --------- --------- --------- --------- --------- -CCAAACC- -BDBDBDB- 
--------- --------- --------- --------- --------- --------- -CCDDDCC- -DBDBDBD- 
--------- --------- --------- --------- --------- --------- -CFFFFFC- -BDBDBDB- 
--------- --------- --------- --------- --------- --------- -CFCFCFC- -DBDBDBD- 
--------- --------- --------- --------- --------- --------- -CFFFFFC- -EEEEEEE- 
--------- --------- --------- --------- --------- --------- -CFFFFFC- -EEEEEEE- 
--------- --------- --------- --------- --------- --------- -CCFFFCC- -EEEEEEE- 
--------- AA-----AA AA-----AA AA-----AA ----B---- ----B---- -CCHBHCC- -EEEEEEE- 
AA-----AA A-------A A-------A A---B---A AA--B--AA ----B---- -CCBBBCC- -BDBDBDB- 
AA-----AA A-------A CBBBBBBBC A--BBB--A AA--B--AA ----B---- -CCHBHCC- -DBDBDBD- 
AA-----AA A-------A A-------A A-------A AA-----AA --------- -CCCCCCC- -BDBDBDB- 
--------- AA-----AA AA-----AA AA-----AA --------- --------- -CCCCCCC- -DBDBDBD- 
--------- --------- --------- --------- --------- --------- -CCCCCCC- -BDBDBDB- 
--------- --------- --------- --------- --------- --------- --CCCCC-- --BDBDB-- 
--------- --------- --------- --------- --------- --------- ---CCC--- ---BDB--- 
