model
size = 31 32 17, scale = 0.05, origin = -y
material 
  colors = A:#639 B:#111 C:#777
voxels
9-15(13A18-)4A7B2(2A18-4A2(B2C)B)2A18-A10B2A2(18-AB2CB8A)17-2A4B9A15-3AB2CB10A14-3AB2CB10A15-2A10B3A17-4A2(B2C)B2A19-3A2(B2C)BA21-2A7B24-5A27-2(3A28-)3A21-14(17A14-)17A15-4(15A16-)15A14-19A11-21A2(10-3A-17A)11-2A-16A13-17A15-15A16-15A21-3(5A26-)5A19-9(A17-A12-)3(2A15-2A12-)2A15-2A13-A15-A5(14-17A)15-15A11-3A2-15A3(2-3A6-3A3-14A)2-3A7-2A19-2A8-4A15-4A9-3A15-3A12-2(A15-)5A5-5A20-2(A5-A24-)A5-A17-8(A19-A10-)A19-A11-5(A17-A12-)A17-A13-4(A15-A14-)A15-A9-A4-A15-2(A4-)2(A25-A4-)2A23-2A4-3A21-3A5-3A19-3A6-4A17-4A7-4A15-4A10-2A15-2A14-4A7-4A19-A7-A22-A7-A16-9(A19-A10-)2(2A17-2A10-)2A17-2A11-3(A17-A12-)2A15-2A12-2A15-2A13-2(A15-A14-)A15-A8-A5-A15-A5-2(A2-A27-)A2-2A25-2A3-2A23-2A4-3A21-3A4-4A19-4A5-4A17-4A7-4A15-4A11-2A13-2A16-3A7-3A18-3A7-3A14-14(A19-A10-)A19-A11-3(A17-A12-)A17-A13-A15-A8-A5-A15-A5-3(A2-A27-)A2-2A25-2A2-3A23-3A3-3A21-3A4-4A19-4A5-4A17-4A8-3A15-3A2(13-A)16-2(A13-)15(A19-A10-)2A17-2A10-2A17-2A11-2(A17-A12-)2A15-2A2(6-A)15-A6-2A2(28-3A)28-2A-A26-2A2-2A25-2A2-3A23-3A3-3A21-3A5-3A19-3A7-4A15-4A11-A15-A14-A15-A12-15(A19-A10-)2(2A17-2A10-)2A17-2A11-A17-A12-2A16-A6-A5-2A16-A5-2A3(28-3A)28-2A-A26-2A2-2A25-2A3-2A23-2A4-3A21-3A6-2A19-2A10-2A16-A13-A16-A11-15(A19-A10-)4(2A17-2A10-)3A16-2A5-A5-2A16-A5-2A23-A4-4(3A28-)2A-A26-2A2-2A25-2A3-2A23-2A5-3A19-3A9-2A16-A13-A16-A11-15(A19-A10-)2(2A17-2A10-)2A17-2A11-A17-A12-2A16-A6-A5-2A16-A5-2A23-A4-4(3A28-)2A-A26-2A2-2A25-2A3-2A23-2A5-3A19-3A9-2A16-A13-A16-A11-15(A19-A10-)2A17-2A10-2A17-2A11-2(A17-A12-)2A16-2(A6-)A22-2A3(28-3A)28-2A-A26-2A2-2A25-2A3-2A23-2A4-3A21-3A6-2A19-2A10-2A16-A13-A16-A11-14(A19-A10-)A19-A11-3(A17-A12-)A17-A13-A15-A7-A6-A15-A6-2A2(28-3A)28-2A-A26-2A2-2A25-2A2-3A23-3A3-3A21-3A5-4A17-4A7-4A15-4A11-2A14-A14-2A14-A12-9(A19-A10-)2(2A17-2A10-)2A17-2A11-2(A17-A12-)A17-A13-4(A15-A14-)A15-A8-A5-A15-A5-2(A2-A27-)A2-A26-2A2-2A25-2A2-3A23-3A3-3A21-3A4-4A19-4A5-4A17-4A8-3A15-3A2(13-A)16-2(A13-)8(A19-A10-)A19-A11-5(A17-A12-)A17-A13-4(A15-A14-)A15-A8-A5-A15-A5-2(A2-A27-)A2-2A25-2A3-2A23-2A4-3A21-3A4-4A19-4A5-4A17-4A7-4A15-4A11-2(A15-)A13-A16-A13-A14-9(A17-A12-)3(2A15-2A12-)2A15-2A13-5(A15-A14-)2(A15-)A13-A10-A5-A13-A5-2(A4-)2A13-2A2(4-A)25-A4-2A23-2A4-3A21-3A5-3A19-3A6-4A17-4A7-4A16-3A10-2A15-2A14-2A11-2A17-2A9-2A18-2A9-2A16-2(A-15A14-)12(17A14-)17A15-4(15A16-)15A11-4A-15A-4A3(6-25A)7-23A8-23A9-21A12-17A15-15A17-13A19-11A21-10A18-5AB2A3B4A2(16-5AB3AB5A)16-4A3BA3B4A16-15A16-5AB3AB5A16-6ABAB6A16-7AB7A16-6ABAB6A16-5AB3AB5A16-15A16-5A5B5A16-5AB3AB5A17-2(4AB3AB4A18-)4A5B4A18-13A18-6AB6A2(18-5ABAB5A)18-4AB3AB4A17-5AB3AB5A14-19A12-3AB2A3BA3B2A3BA12-3AB2AB3ABAB2A2(BA)13-2AB2A3B2(AB)2AB2A15-AB4A2(BA)B2ABA16-2(3BA)2(BA)3B18-11A20-11A21-9A22-9A11-
