model
size = 13 16 14, scale = 0.05, origin = -y
material 
  colors = A:#111 B:#EEE
voxels
---AAAAA----- ---AAAAA----- ---AAAAA----- ---AAAAA----- ---AAAAA----- ---AAAAA----- ---AAAAA----- ---AAAAA----- ---AAAAA----- ---AAAAA----- ----AAAA----- ----AAA------ ----A-------- ------------- ------------- ------------- 
--A-----AA--- -AA-----AA--- -AA---A-AA--- -AA-----AA--- -AA-----AA--- AAA-----AA--- AAA-----A---- AAA-----A---- -AAA--AAA---- --AA--AAA---- ----AAAAA---- ----AAAAA---- ----AAAA----- ----AAAA----- ----AAA------ ----AA------- 
----------A-- ---------AA-- A---------A-- A---------A-- A--------A--- B--------A--- B--------A--- BA-------A--- AAAAA-AA-A--- -AAAA-AA-A--- ---AAAA-A---- ------------- ------------- ------------- ------------- ------------- 
----------AA- ----------A-- AA--------A-- A---------A-- A---------A-- B---------A-- B--------A--- B--------A--- AAA-AAAAAA--- -AA-AAAAAA--- ---AAAAAAA--- -----AA------ ------------- ------------- ------------- ------------- 
----------AA- ----------AA- -A--------AA- A---------A-- A---------A-- B---------A-- B---------A-- A--------A--- AAAAAAAAAA--- AAAAAAAAAA--- -AAAAAAAAA--- ---AAAAAA---- ------------- ------------- ------------- ------------- 
------------A ------------A ----------AA- A---------AA- A---------AA- B---------AA- A---------AA- A---------A-- AAAAAAAAA-A-- AAAAAAAAA-A-- -AAAAAAAAAA-- --AAAAAAA---- ------------- ------------- ------------- ------------- 
------------A ------------A ------------A A-----------A A---------AA- A---------AA- A---------AA- A---------A-- AAAAAAA-AAA-- AAAAAAA-AAA-- -AAAAAA-AAA-- --AAAAAAAA--- ------------- ------------- ------------- ------------- 
------------A ------------A ------------A A-----------A A-----------A A---------AA- A---------AA- AA-AA-----AA- AAAAA---AAA-- AAAAA---AAA-- -AAAA---AA--- --AAAAAAAA--- ------------- ------------- ------------- ------------- 
------------A ------------A ------------A A-----------A A-----------A B---------AA- A---------AA- A---------AA- AAA------AA-- AAAA-----AA-- -AAA-----A--- --AAAAAAAA--- ------------- ------------- ------------- ------------- 
----------AA- ----------AA- ----------AA- A---------AA- A---------AA- B---------AA- B---------AA- AAA-------AA- AAAA------A-- AAAA------A-- -AAAAAAAAA--- -----AAAA---- ------------- ------------- ------------- ------------- 
----------AA- ----------AA- A---------AA- A---------AA- A---------AA- B---------AA- B---------AA- B---------AA- AAAAA-----A-- -AAAAAAAAA--- ---AAAAAA---- -----AA------ ------------- ------------- ------------- ------------- 
----------A-- ----------A-- AA--------A-- A---------A-- A--------A--- B--------A--- B--------AA-- B--------AA-- AAAAAA---A--- -AAAAAAAA---- ---AAA--A---- ------------- ------------- ------------- ------------- ------------- 
--AAAAAAAA--- -AAAAAAAAA--- -AAAAAAAAA--- -AAAAAAAAA--- -AAAAAAAAA--- AAAAAAAAA---- AAAAAAAAA---- AAAAAAAAA---- -AAAAAAAA---- --AAAAAAA---- --AAAAAA----- ---AAAAA----- ---AAAA------ ---AAA------- ---AAA------- ---AA-------- 
------------- ------AA----- ----AAAA----- ---AAAAA----- ---AAAAA----- ---AAAAA----- ---AAAAA----- ---AAAAA----- ---AAAAA----- ---AAAAA----- ---AAAA------ ---AA-------- ---A--------- ------------- ------------- ------------- 
