model
size = 20 17 11, scale = 0.05, origin = -y
material 
  colors = A:#FFFFFB B:#967249 C:#3A3226 D:#855B32 E:#3D2715 F:#111 G:#EEE H:#787D7B I:#222 J:#E03C8A
voxels
-------------------- -------------------- -------------------- -------------------- ---------JJ--------- --------HFFH-------- -------DHFFHD------- ------CDBGGBDC------ ------CDBBBBDC------ ------CBFBBFBC------ ------CEBBBBEC------ ------CCC--CCC------ -------------------- -------------------- -------------------- -------------------- -------------------- 
--------AAAA-------- -----AAAAAAAAAA----- ----AAAAAAAAAAAA---- ----AAAAAAAAAAAA---- ----AAAAAAAAAAAA---- -----AAAAAAAAAA----- ------AAAAAAAA------ ------CDBGGBDC------ ------CDBBBBDC------ ------CBIBBIBC------ ------CEBBBBEC------ ------CCC--CCC------ -------------------- -------------------- -------------------- -------------------- -------------------- 
---AAAAAAAAAAAAAA--- ---AAAAAAAAAAAAAA--- ---AAAAAAAAAAAAAA--- ---AAAAA----AAAAA--- ---AAAAA----AAAAA--- ---AAAAAAAAAAAAAA--- ---AAAAAAAAAAAAAA--- ----AACDBGGBDCAA---- ------CDBBBBDC------ ------CBIBBIBC------ ------CEBBBBEC------ ------CCC--CCC------ -------------------- -------------------- -------------------- -------------------- -------------------- 
---AAAAAAAAAAAAAA--- ---AABBBBBBBBBBAA--- --AA-BBBBBBBBBB-AA-- --AA-BBBBBBBBBB-AA-- --AA-BBBBBBBBBB-AA-- --AAABBBBBBBBBBAAA-- --AAAABBBBBBBBAAAA-- --AAAAAABBBBAAAAAA-- ---AAAAABBBBAAAAA--- ----AAAABBBBAAAA---- ------AA----AA------ -------------------- -------------------- -------------------- -------------------- -------------------- -------------------- 
---AAAAAAAAAAAAAA--- --AABBBBBBBBBBBBAA-- --AABBBBBBBBBBBBAA-- --AABBBBBBBBBBBBAA-- -AA-BBBBBBBBBBBBBAA- -AA-BBBBBBBBBBBBBAA- -AAABBBBBBBBBBBBAAA- -AAAABBBBBBBBBBAAAA- -AAAAA--BBBBBBAAAAA- -AAAAAAABBBBAAAAAAA- --AAAAAA----AAAAAA-- ----AAA------AAA---- ------AA----AA------ -------------------- -------------------- -------------------- -------------------- 
---AAAAAAAAAAAAAA--- --AABBBBBBBBBBBBAA-- --AABBBBBBBBBBBBAA-- -AA-BBBBBBBBBBBB-AA- -AA-BBBBBBBBBBBB-AA- -AA-BBBBBBBBBBBB-AA- AA--BBBBBBBBBBBB--AA AAA-BBBBBBBBBBBB-AAA AAA--------------AAA AAAA------------AAAA --AAAAA------AAAAA-- ----AAA------AAA---- ------AA----AA------ ------AA----AA------ -------AA--AA------- -------AAAAA-------- --------AAAA-------- 
---AAAAAAAAAAAAAA--- --AABBBBBBBBBBBBAA-- --AABBBBBBBBBBBBAA-- -AA-BBBBBBBBBBBB-AA- -AA-BBBBBBBBBBBB-AA- -AA-BBBBBBBBBBBB-AA- AAA-BBBBBBBBBBBB-AAA AAA-BBBBBBBBBBBB-AAA AAA--------------AAA AAAAA----------AAAAA --AAAAA------AAAAA-- ----AAA------AAA---- ------AA----AA------ ------AA----AA------ -------AA--AA------- -------AAAAA-------- --------AAAA-------- 
---AAAAAAAAAAAAAA--- --AABBBBBBBBBBBBAA-- --AABBBBBBBBBBBBAA-- --AABBBBBBBBBBBBAA-- -AA-BBBBBBBBBBBB-AA- -AAABBBBBBBBBBBBAAA- -AAABBBBBBBBBBBBAAA- -AAAABBBBBBBBBBAAAA- -AAAAAA------AAAAAA- -AAAAAAA----AAAAAAA- --AAAAAA----AAAAAA-- ----AAA------AAA---- -------------------- -------------------- -------------------- -------------------- -------------------- 
---AAAAAAAAAAAAAA--- ---AABBBBBBBBBBAA--- --AA-BBBBBBBBBB-AA-- --AA-BBBBBBBBBB-AA-- --AA-BBBBBBBBBB-AA-- --AAABBBBBBBBBBAAA-- --AAAAABBBBBBAAAAA-- --AAAAAAABBAAAAAAA-- ---AAAAAA--AAAAAA--- ----AAAA----AAAA---- ------AA----AA------ -------------------- -------------------- -------------------- -------------------- -------------------- -------------------- 
---AAAAAAAAAAAAAA--- ---AAAAAAAAAAAAAA--- ---AAAAAAAAAAAAAA--- ---AAAAAAAAAAAAAA--- ---AAAAAAAAAAAAAA--- ---AAAAAAAAAAAAAA--- ---AAAAAAAAAAAAAA--- ----AAAAAAAAAAAA---- ------AAA--AAA------ -------------------- -------------------- -------------------- -------------------- -------------------- -------------------- -------------------- -------------------- 
-------------------- ------AAAAAAAA------ -----AAAAAAAAAA----- -----AAAAAAAAAA----- -----AAAAAAAAAA----- ------AAAAAAAA------ --------AAAA-------- -------------------- -------------------- -------------------- -------------------- -------------------- -------------------- -------------------- -------------------- -------------------- -------------------- 
