model
size = 11 32 13, scale = 0.05, origin = -y
material 
  colors = A:#594127 B:#5E432C C:#000 D:#141211 E:#3B2B2C F:#3E302D G:#533D28 H:#412B1D I:#362B25 J:#928167 K:#9F8B72 L:#7E664A M:#7F6954 N:#F0D9B9 O:#3C2D26 P:#CAB797 Q:#3A2826 R:#3E2F28 S:#DBC4A4 T:#DCC5A3 U:#372928 V:#C7B494 W:#3B2C27
voxels
312-CD10-D339-2(DC9-)2C263-E7-B-HMU6-Q-PLV9-C43-D9-2D10-D208-A10-B9-B2A8-B2A6-LFHFTR5-2JCGCLJ3-W-EGEPRL3-2C5-C50-2C9-2C153-A10-A9-2AB8-3A8-ABA7-2A3B5-2BAB3A4-7A4-BAB-ABA4-OGE-LBO4-SIG-PQS3-KF5-O3-C6-C50-DC9-2D87-A9-AB9-3B8-ABA7-4A7-B2A2B2(6-3ABA)6-2AB2A6-B3AB6-BA2BA6-BA-AB5-2A3-2A2(4-A)B4-B5-A4-K5-K4-N5-N62-C9-CD10-D21-A10-B9-2(3A8-)ABA8-B2A8-2AB8-3A7-BAB2A6-2BA2B6-A2BAB6-AB2AB6-2(AB)A6-ABA2B5-2A2(BA)5-A2(B-)2B4-AB-A-2A4-2A-B-2B4-2A-A-3A2-A3-A2-2A2-B3-A2-2B2-2F2-D2-2F-2H3-D2-2H-2F3-C3-2F5-2(D10-)C10-C9-2C9-CD21-A10-B9-2A9-BAB8-3A8-A2B8-B-A8-ABA7-4A7-2A2BA6-2AB2A6-2ABAB6-2(AB)A6-5A5-AB4A5-2A-B2AB4-B2(A-)BA4-2A-A-2A4-2A-A-BA3-2A2-A2-2A2-AB2-A2-BA2-2A2-A2-2B2-2G2-C2-2G-3I2-D3-2I2J3-D3-2JC3-CD4-C4-2(DC9-)2C10-D76-B9-B2A8-A2B8-2BA8-2AB8-3A7-2B2A7-5A6-B4A6-2AB2A6-2BABA6-5A6-2B-2A6-A3-A5-2(2A3-2A4-)A4-2A3-2A5-BA2-2E5-2E2-2G5-2G2-2E6-E193-A2(9-2A)B8-ABA7-4AB6-B2ABA6-2(AB)A6-3A2B6-B2ABA5-3A-B2A4-3A-2AB4-2A3-2A4-M5-M4-H5-H4-M5-M260-A10-A9-B2A8-ABA6-3B4A4-AB5A5-OKFGKE5-IN-IEG3-Q-H3-PE3-2C5-2C292-A9-AB9-KFN8-NHI8-KFJ350-E10-C71-
