model
size = 31 31 17, scale = 0.05, origin = -y
material 
  colors = A:#CFF B:#080 C:#060 D:#100 E:#724540 F:#996 G:#960 H:#363 I:#050
voxels
---------AAAAAAAAAAAAA--------- ---------AAAAAAAAAAAAA--------- ---------AAAAAAAAAAAAA--------- ---------AAAAAAAAAAAAA--------- ---------AAAAAAAAAAAAA--------- ---------AAAAAAAAAAAAA--------- ---------AAAAAAAAAAAAA--------- ---------AAAAAAAAAAAAA--------- ---------AAAAAAAAAAAAA--------- ---------AAAAAAAAAAAAA--------- ---------AAAAAAAAAAAAA--------- ---------AAAAAFFFAAAAA--------- ---------AAAAAAEAAAAAA--------- ---------AAAAAAEAAAAAA--------- ---------AAAAAAEAAAAAA--------- ---------AAAAAAEAAAAAA--------- ---------AAACAAEACCAAA--------- ---------AACCCCICGICAA--------- ---------AAACCCCCCCGCA--------- ---------AACGCBCCCICAA--------- ---------ACHCCCCCGCAAA--------- --------AAACCHCCCCCCAAA-------- -------AAAAAHCGCCBCAAAAA------- -------AAAAAACCCCCAAAAAA------- --------AAAAAAAHAAAAAAA-------- ---------AAAAAAAAAAAAA--------- ----------AAAAAAAAAAA---------- -----------AAAAAAAAA----------- ------------------------------- ------------------------------- ------------------------------- 
-------AA-------------AA------- -------AA-------------AA------- -------AA-------------AA------- -------AA-------------AA------- -------AA-------------AA------- -------AA-------------AA------- -------AA-------------AA------- -------AA-------------AA------- -------AA-------------AA------- -------AA-------------AA------- -------AA-------------AA------- -------AA-------------AA------- -------AA-------------AA------- -------AAA-----------AAA------- -------AAA-----------AAA------- --------AA-----------AA-------- --------AA-----------AA-------- --------AA-----------AA-------- --------AA-----------AA-------- --------AA-----------AA-------- ------BBBB-----------BBBB------ -----AAAA-------------AAAA----- -----AAA---------------AAA----- -----AAA---------------AAA----- ------AA---------------AA------ -------AA-------------AA------- --------AAAAAAAAAAAAAAA-------- --------AAAAAAAAAAAAAAA-------- -------------AAAAA------------- -------------AAAAA------------- -------------BBBBB------------- 
------A-----------------A------ ------A-----------------A------ ------A-----------------A------ ------A-----------------A------ ------A-----------------A------ ------A-----------------A------ ------A-----------------A------ ------A-----------------A------ ------A-----------------A------ ------AA---------------AA------ ------AA---------------AA------ ------AA---------------AA------ ------AA---------------AA------ -------A---------------A------- -------A---------------A------- -------AA-------------AA------- -------AA-------------AA------- -------AA-------------AA------- -------AA-------------AA------- --------A-------------A-------- ---BBB--B-------------B--BBB--- ---AAA-------------------AAA--- ---AAA-------------------AAA--- ---AAA-------------------AAA--- ----AA-------------------AA---- ----AAAA---------------AAAA---- -----AAA---------------AAA----- -------A---------------A------- --------AAAAA-----AAAAA-------- ------------A-----A------------ ------------B-----B------------ 
-----A-------------------A----- -----A-------------------A----- -----A-------------------A----- -----A-------------------A----- -----A-------------------A----- -----A-------------------A----- -----A-------------------A----- -----A-------------------A----- -----A-------------------A----- ------A-----------------A------ ------A-----------------A------ ------A-----------------A------ ------A-----------------A------ ------A-----------------A------ ------A-----------------A------ -------A---------------A------- -------A---------------A------- -------A---------------A------- -------A---------------A------- -------A---------------A------- --B----B---------------B----B-- --A-------------------------A-- --A-------------------------A-- --AA-----------------------AA-- --AAA---------------------AAA-- ---AAA-------------------AAA--- ---AAAA-----------------AAAA--- ----AAAA---------------AAAA---- ------AA---------------AA------ --------AAAA-------AAAA-------- -----------B-------B----------- 
-----A-------------------A----- -----A-------------------A----- -----A-------------------A----- -----A-------------------A----- -----A-------------------A----- -----A-------------------A----- -----A-------------------A----- -----A-------------------A----- -----A-------------------A----- -----AA-----------------AA----- -----AA-----------------AA----- -----AA-----------------AA----- ------A-----------------A------ ------A-----------------A------ ------A-----------------A------ ------AA---------------AA------ ------AA---------------AA------ -------A---------------A------- -------A---------------A------- -------A---------------A------- -B-----B---------------B-----B- -A---------------------------A- -A---------------------------A- -AA-------------------------AA- --AA-----------------------AA-- --AAA---------------------AAA-- --AAAA-------------------AAAA-- ---AAAA-----------------AAAA--- ----AAAA---------------AAAA---- -------AA-------------AA------- ---------BBB-------BBB--------- 
-----A-------------------A----- -----A-------------------A----- -----A-------------------A----- -----A-------------------A----- -----A-------------------A----- -----A-------------------A----- -----A-------------------A----- -----A-------------------A----- -----A-------------------A----- -----A-------------------A----- -----A-------------------A----- -----A-------------------A----- -----A-------------------A----- -----A-------------------A----- -----A-------------------A----- ------A-----------------A------ ------A-----------------A------ ------A-----------------A------ ------A-----------------A------ -------A---------------A------- -B-----B---------------B-----B- -A---------------------------A- -A---------------------------A- -A---------------------------A- -AA-------------------------AA- -AAA-----------------------AAA- --AAA---------------------AAA-- --AAAA-------------------AAAA-- ---AAAA-----------------AAAA--- -----AAA---------------AAA----- --------B-------------B-------- 
-----A-------------------A----- -----A-------------------A----- -----A-------------------A----- -----A-------------------A----- -----A-------------------A----- -----A-------------------A----- -----A-------------------A----- -----A-------------------A----- -----A-------------------A----- -----A-------------------A----- -----A-------------------A----- -----A-------------------A----- -----A-------------------A----- -----A-------------------A----- -----A-------------------A----- -----AA-----------------AA----- -----AA-----------------AA----- ------A-----------------A------ ------A-----------------A------ ------AA---------------AA------ B------B---------------B------B A----------------------------AA A----------------------------AA A----------------------------AA -A--------------------------AA- -AA-------------------------AA- -AAA-----------------------AAA- --AAA---------------------AAA-- ---AAA-------------------AAA--- ----AAAA---------------AAAA---- -------B---------------B------- 
-----A-------------------A----- -----A-------------------A----- -----A-------------------A----- -----A-------------------A----- -----A-------------------A----- -----A-------------------A----- -----A-------------------A----- -----A-------------------A----- -----A-------------------A----- -----A-------------------A----- -----A-------------------A----- -----A-------------------A----- -----A-------------------A----- -----A-------------------A----- -----A-------------------A----- -----AA-----------------AA----- -----AA-----------------AA----- -----AA-----------------AA----- ------A-----------------A------ ------AA----------------A------ B-----BB----------------B-----B A----------------------------AA A----------------------------AA A----------------------------AA A----------------------------AA -A--------------------------AA- -AA-------------------------AA- --AA-----------------------AA-- --AAA---------------------AAA-- ----AA-------------------AA---- ------BB----------------B------ 
-----A-------------------A----- -----A-------------------A----- -----A-------------------A----- -----A-------------------A----- -----A-------------------A----- -----A-------------------A----- -----A-------------------A----- -----A-------------------A----- -----A-------------------A----- -----A-------------------A----- -----A-------------------A----- -----A-------------------A----- -----A-------------------A----- -----A-------------------A----- -----A-------------------A----- -----AA-----------------AA----- -----AA-----------------AA----- -----AA-----------------AA----- -----AA-----------------AA----- -----AAA----------------AA----- B-----BB----------------B-----B A----------------------------AA A----------------------------AA A----------------------------AA A----------------------------AA A----------------------------AA -A--------------------------AA- -AA-------------------------AA- --AA-----------------------AA-- ---AAA-------------------AAA--- ------BB----------------B------ 
-----A-------------------A----- -----A-------------------A----- -----A-------------------A----- -----A-------------------A----- -----A-------------------A----- -----A-------------------A----- -----A-------------------A----- -----A-------------------A----- -----A-------------------A----- -----A-------------------A----- -----A-------------------A----- -----A-------------------A----- -----A-------------------A----- -----A-------------------A----- -----A-------------------A----- -----AA-----------------AA----- -----AA-----------------AA----- -----AA-----------------AA----- ------A-----------------A------ ------AA----------------A------ B-----BB----------------B-----B A----------------------------AA A----------------------------AA A----------------------------AA A----------------------------AA A----------------------------AA -A--------------------------AA- -AA-------------------------AA- --AA-----------------------AA-- ---AAA-------------------AAA--- ------BB----------------B------ 
-----A-------------------A----- -----A-------------------A----- -----A-------------------A----- -----A-------------------A----- -----A-------------------A----- -----A-------------------A----- -----A-------------------A----- -----A-------------------A----- -----A-------------------A----- -----A-------------------A----- -----A-------------------A----- -----A-------------------A----- -----A-------------------A----- -----A-------------------A----- -----A-------------------A----- -----AA-----------------AA----- -----AA-----------------AA----- ------A-----------------A------ ------A-----------------A------ ------AA----------------A------ B------B----------------B-----B A----------------------------AA A----------------------------AA A----------------------------AA A----------------------------AA -A--------------------------AA- -AA-------------------------AA- --AA-----------------------AA-- --AAA---------------------AAA-- ----AA-------------------AA---- ------BB----------------B------ 
-----A-------------------A----- -----A-------------------A----- -----A-------------------A----- -----A-------------------A----- -----A-------------------A----- -----A-------------------A----- -----A-------------------A----- -----A-------------------A----- -----A-------------------A----- -----A-------------------A----- -----A-------------------A----- -----A-------------------A----- -----A-------------------A----- -----A-------------------A----- -----A-------------------A----- ------A-----------------A------ ------A-----------------A------ ------A-----------------A------ ------A-----------------A------ -------A---------------A------- B------B---------------B------B A----------------------------AA A----------------------------AA A----------------------------AA -A--------------------------AA- -AA-------------------------AA- -AAA-----------------------AAA- --AAA---------------------AAA-- ---AAAA-----------------AAAA--- ----AAAA---------------AAAA---- -------BB--------------B------- 
-----A-------------------A----- -----A-------------------A----- -----A-------------------A----- -----A-------------------A----- -----A-------------------A----- -----A-------------------A----- -----A-------------------A----- -----A-------------------A----- -----A-------------------A----- -----AA-----------------AA----- -----AA-----------------AA----- -----AA-----------------AA----- ------A-----------------A------ ------A-----------------A------ ------A-----------------A------ -------A---------------A------- -------A---------------A------- -------A---------------A------- -------A---------------A------- -------A---------------A------- -B-----B---------------B-----B- -A---------------------------A- -A---------------------------A- -A--------------------------AA- -AA-------------------------AA- -AAA-----------------------AAA- --AAA---------------------AAA-- --AAAA-------------------AAAA-- ---AAAA-----------------AAAA--- -----AAA---------------AAA----- --------B-------------B-------- 
-----A-------------------A----- -----A-------------------A----- -----A-------------------A----- -----A-------------------A----- -----A-------------------A----- -----A-------------------A----- -----A-------------------A----- -----A-------------------A----- -----A-------------------A----- ------A-----------------A------ ------A-----------------A------ ------A-----------------A------ ------A-----------------A------ ------A-----------------A------ ------A-----------------A------ -------A---------------A------- -------A---------------A------- -------A---------------A------- -------A---------------A------- -------A---------------A------- -B-----B---------------B-----B- -A---------------------------A- -A---------------------------A- -AA-------------------------AA- --AA-----------------------AA-- --AAA---------------------AAA-- --AAAA-------------------AAAA-- ---AAAA-----------------AAAA--- ----AAAA---------------AAAA---- -------A---------------A------- --------B-------------B-------- 
------A-----------------A------ ------A-----------------A------ ------A-----------------A------ ------A-----------------A------ ------A-----------------A------ ------A-----------------A------ ------A-----------------A------ ------A-----------------A------ ------A-----------------A------ ------AA---------------AA------ ------AA---------------AA------ ------AA---------------AA------ ------AA---------------AA------ -------A---------------A------- -------A---------------A------- -------A---------------A------- -------A---------------A------- -------A---------------A------- -------A---------------A------- --------A-------------A-------- --B-----B-------------B-----B-- --A----AA-------------AA----A-- --A-------------------------A-- --AA-----------------------AA-- --AAA---------------------AAA-- ---AAA-------------------AAA--- ---AAAA-----------------AAAA--- ----AAAA----------------AAA---- ------AA---------------AA------ --------AA-----------AA-------- ---------BB---------BB--------- 
-------A---------------A------- -------A---------------A------- -------A---------------A------- -------AAAAAAAAAAAAAAAAA------- -------AAAAAAAAAAAAAAAAA------- -------AAAAAAAAAAAAAAAAA------- -------AAAAAAAAAAAAAAAAA------- -------AAAAAAAAAAAAAAAAA------- -------AAAAAAAAAAAAAAAAA------- -------AAAAAAAAAAAAAAAAA------- -------AAAAAAAAAAAAAAAAA------- -------AAAAAAAAAAAAAAAAA------- -------AAAAAAAAAAAAAAAAA------- -------AAAAAAAAAAAAAAAAA------- -------AAAAAAAAAAAAAAAAA------- --------AAAAAAAAAAAAAAA-------- --------AAAAAAAAAAAAAAA-------- --------AAAAAAAAAAAAAAA-------- --------AAAAAAAAAAAAAAA-------- --------AAAAAAAAAAAAAAA-------- ---BBBBBBAAAAAAAAAAAAABBBBBB--- ---AAAAAAAAAAAAAAAAAAAAAAAAA--- ---AAAAAAAAAAAAAAAAAAAAAAAAA--- ---AAAAAAAAAAAAAAAAAAAAAAAAA--- ----AAAAAAAAAAAAAAAAAAAAAAA---- ----AAAAAAAAAAAAAAAAAAAAAAA---- -----AAAAAAAAAAAAAAAAAAAAA----- -------AAAAAAAAAAAAAAAAA------- --------AAAAAAAAAAAAAAA-------- ---------AAAAAAAAAAAAA--------- ----------BBBBBBBBBBB---------- 
--------AAAAAAAAAAAAAAA-------- --------AAAAAAAAAAAAAAA-------- --------AAAAAAAAAAAAAAA-------- --------AAAAAAAAAAAAAAA-------- --------AAAAAAAAAAAAAAA-------- --------AAAAAAAAAAAAAAA-------- --------AAAAAAAAAAAAAAA-------- --------AAAAAAAAAAAAAAA-------- --------AAAAAAAAAAAAAAA-------- --------AAAAAAAAAAAAAAA-------- --------AAAAAAAAAAAAAAA-------- --------AAAAAAAAAAAAAAA-------- --------AAAAAAAAAAAAAAA-------- ---------AAAAAAAAAAAAA--------- ---------AAAADAAADDDAA--------- ---------AAAADAAAADAAA--------- ---------AAAADAAAADAAA--------- ---------AADDDAAAADAAA--------- ---------ADAAAAAAADAAA--------- ---------ADAAAAAAADAAA--------- ---------ADDDDDAAADDAA--------- --------AAAAAAAAAAAAAAA-------- ------AAAAAAAAFFFAAAAAAAA------ ------AAAAAAAAAEAAAAAAAAA------ ------AAAAAAAAAEAAAAAAAAA------ -------AAAAAAACCCAAAAAAA------- --------AAAAAAACAAAAAAA-------- --------AAAAAAAAAAAAAAA-------- ----------AAAAAAAAAAA---------- ----------AAAAAAAAAAA---------- -----------BBBBBBBBB----------- 
