model
size = 24 25 30, scale = 0.05, origin = -y
material 
  colors = A:#FFFFFB B:#F5F5F5 C:#D5D9D3 D:#FFFDE0 E:#FCFAF2 F:#EEE G:#B3C9EF H:#DCDCDC I:#C1DCDA J:#EAE7C8 K:#FBF5D4
voxels
------------------------ ------------------------ ------------------------ ------------------------ ------------------------ ------------------------ ------------------------ ------------------------ ------------------------ ------------------------ ------------------------ ------------------------ ------------------------ ------------------------ ------------------------ ------------------------ --------BBBB------------ --------BBBB------------ --------BBBB------------ ------------------------ ------------------------ ------------------------ ------------------------ ------------------------ ------------------------ 
------------------------ ------------------------ ------------------------ ------------------------ ------------------------ ------------------------ ------------------------ ------------------------ ------------------------ ------------------------ ------------------------ ------------------------ ------------------------ ------------------------ ------------------------ ------------------------ -------BAAAAB----------- ------BBA--AB----------- ------BBAAAAB----------- -------BBBBBB----------- --------BBBB------------ ------------------------ ------------------------ ------------------------ ------------------------ 
------------------------ ------------------------ ------------------------ ------------------------ ------------------------ ------------------------ ------------------------ ------------------------ ------------------------ ------------------------ ------------------------ ------------------------ ------------------------ ------------------------ ------------------------ -----BBBBBBB------------ -----BBAAAAAFBBBB------- ----BBAA----ABBBB------- ----BBAAA---ABBBB------- ----BBBAAAAAABB--------- ------BBAAAABB---------- --------BBBBB----------- ---------BBB------------ ------------------------ ------------------------ 
------------------------ ------------------------ ------------------------ -----I------------------ ------------------------ -----H------------------ ------------------------ ------------------------ ------------------------ -----G------------------ ------------------------ ------------------------ ------------------------ ------------------------ ------DDDDD------------- ----BA--AAADBBBBB------- ----BA-----AABBBBBB----- ---BAA----------BBB----- ---BA---------BBBBB----- ----BAA------BBBB------- -----BAAA---BB---------- -------BBB-BBB---------- --------BBBBB----------- ------------------------ ------------------------ 
------------------------ ------------------------ ------------------------ ------------------------ ------------------------ ------------------------ ------------------------ ------------------------ ------------------------ ------------------------ ------------------------ ------------------------ ------------------------ ------------------------ -----DDDDDDDDDD--------- ----A-----AAADDFFB------ ---BA------------AB----- ---BA-------------B----- ---BA-----------BAB----- ----BA-------BBAFB------ -----BAA-----BBB-------- ------BAB---BB---------- -------BEBBBB----------- ---------AA------------- ------------------------ 
------------------------ ------------------------ --------G--------------- ------------------------ ----------------G------- ------------------------ ----------------G------- --------G--------------- ------------------------ ----------------H------- ------------------------ ------------------------ ----------------G------- ------------------------ -----DDDDDDDDDDD-------- ----A-----A-AAADFB------ --BAA------------AB----- --BA--------------BB---- ---BA------------AAB---- ----BA---------AAFA----- ----BAA------AAAB------- -----AAA----AAB--------- -------BEEEEBE---------- --------BAAA------------ ------------------------ 
------------------------ ------------------------ ------------------------ ------------------------ ------------------------ ------------------------ ------------------------ ------------------------ ------------------------ ------------------------ ------------------------ ------------------------ ------------------------ ----------CCCC---------- -----DDDDDAAAADDD------- --BBAA--------AADB------ --AAA------------ABB---- --BA--------------AFB--- --BAA-------------AAB--- ---BA-----------AAFA---- ---BAA--------AAAF------ ----BAAA----AAAB-------- -------BEEEEBB---------- --------BAAA------------ ------------------------ 
------------------------ ------------------------ ------------------------ ------------------------ -----------G------------ ------------------------ ------------------------ ------------------------ ------------------------ -----------I------------ ------------------------ -----------G------------ ------------------------ --------CCCCCCC--------- ---DDDDDDAA--AADD------- -BAAAA---------AAB------ -BA--------------AFFFB-- --BA--------------AAAB-- --BA---------------AAB-- --BA-------------AAFB--- ---BA----------AAFF----- ---BAAAA----AAAAB------- ----BBEEEEEEBEEE-------- --------BAAA------------ ------------------------ 
------------------------ ------------------------ ------------------------ ------------------------ ---G-------------------- ------------------------ ------------------------ ------------------------ ---I-------------------- ------------------------ ---G-------------------- ------------------------ ------------------------ -------CCCCCCCC--------- --DDDDDDAA----ADD------- -BAAAA----------AFFFB--- -BA--------------AAAAB-- -BA------------------AB- --BA-----------------AB- --BA--------------AAFBB- --BA------------AABF---- --BAA-------A--AAB------ ---BEAAEEEEEBAAEB------- -----BBAAAAAAEB--------- ------------------------ 
------------------------ ------------------------ ------------------------ -----H--------------H--- ------------------------ -----G----G------------- ------------------------ --------------------G--- -----G----H------------- ------------------------ ----------G---------G--- ------------------------ -----G--------------H--- ------CCCCCCCCC--------- --DDDDDDAA---AADDDD----- -B-------------AAADFFB-- -B------------------AAB- -BA------------------AB- -BA-------------------B- -BA----------------AAFB- -BA--------------AAFF--- -BAA------------AAB----- --BEAAAAAEEEBA--EB------ ----BEEEBAAAEEEB-------- ---------BBB------------ 
------------------------ ------------------------ ------------------------ ------------------------ ------------------------ ----------------H------- ------------------------ ------------------------ ------------------------ ----------------I------- ------------------------ ------------------------ ----------------H------- -----CCCCCCCCCCC-------- --DDDDDDDAA-AADDDDDD---- -BA--------------AADFB-- -B-------------------AB- BAA-------------------B- BA--------------------B- -B------------------AFB- -B----------------AFF--- -BA--------------AB----- --BAA---AEEEBA---B------ ---BBBBBBAAABBBBB------- -------BBBBBB----------- 
------------------------ ------------------------ ------------------------ ------------------------ ------------------------ ------------------------ ------------------------ ------------------------ ------------------------ ------------------------ ------------------------ ------------------------ ------------------------ -----CCCCCCCCCCCC------- --DDDAAADDAAADDDDDDD---- -BAA--------------AAFB-- -BA------------------AB- BA--------------------B- BA--------------------B- BA------------------AFB- -B----------------AAF--- -BA--------------AAB---- -BEA----AAAABAAA-EB----- ---BBBBBBBBBBBBBB------- -----BBBBBBBBB---------- 
------------------------ ------------------------ ------------------------ ------------------------ ------------------------ ------------------------ ------------------------ ------------------------ ------------------------ ------------------------ ------------------------ ------------------------ ------------------------ ----CCCCCCCCCCCCCC------ --DDAA-AADDDDDAAAADD---- -BDA---------------AFB-- -BA------------------AB- BD-------------------AB- BA-------------------AB- BA------------------AFB- -B-----------------AF--- -B---------------AAF---- -BEA----AA--BAAAAEB----- ---BBBBBBBBBBBBBB------- -----BBBBBEEBB---------- 
------------------------ ------------------------ ------------------------ ------------------------ -------I---------------- ------------------------ ------------------------ ------------------------ ------------------------ ------------------------ -------G---------------- ------------------------ -------I---------------- ----CCCKCCCCCCCCCCC----- --DDA---AADDDAA--AAD---- -BAA---------------AFB-- BAA-----------------AB-- BA-------------------AB- BA-------------------AB- BA------------------AB-- BA-----------------AF--- -BA--------------AAF---- -BEAA---------AAAEB----- ---BBBBBBBBBBBBBB------- ------BBEEEEEE---------- 
------------------------ -----------------G------ ------------------------ ------------------------ ------------------------ ------------------------ -----------------G------ ------------------------ -----------------H------ ------------------------ ------------------------ -----------------G------ ------------------------ ----CCCCCCCCCCCCCCC----- ---DA----AADDA----AD---- -BBA---------------AFB-- BA------------------AB-- BA-------------------B-- BA-------------------B-- BA------------------AB-- BA-----------------AF--- -BAA-------------AAF---- --BEAA---------AABB----- ----BBBBB----BBBB------- -------BEEEEEEE--------- 
------------------------ -----H------------------ ------------------------ ------------------------ ------------------------ -----G------------------ ------------------------ ------------------------ ------------------------ ------------------------ ------------------------ ------------------------ ------------------------ ----CCCCCCCCCCCCCCC----- ---DA-----ADAA--A-AD---- -BBA-----------AA--AFB-- B--------------A-----AB- B-------------AA-----AB- BA-------------------AB- BA------------------AB-- -BA----------------AAB-- -BAA--------------AAB--- ---BAA----------ABEEB--- ----BBBBB-----BBB------- -------EEEEEEEE--------- 
------------------------ ------------------------ ------------------------ ----------G------------- ------------------------ --------------G--------- ----------H------------- ------------------------ ------------------------ ------------------------ ----------G---G--------- ------------------------ ------------------------ ----CCCCCCCCCCCCCCC----- ---DA-----ADA-----AD---- -BBA---------------AFFF- -B-------------------AAB BA--------------------AB BA-------------------AB- -B-------------------B-- -BA-----------------AB-- --BA----------------AB-- ---BAA---------AABEEB--- ----BBBBB-----BBB------- ------EEEEEEEEEB-------- 
------------------------ ------------------------ ------------------------ ------------------------ ------------------------ ------------------------ ------------------------ ------------------------ ------------------------ ------------------------ ------------------------ ------------------------ ------------------------ ----CCCCCCCCCCCCCCC----- ---DAA----AAA----AADD--- -BBA---------------AAFF- -BA-------------------AB -BA-------------------AB -BA------------------AB- -B-------------------AB- -BA------------------B-- --BA----------------AB-- --BAA-----------ABEEB--- ---BBBBBB-----BBB------- ------EEEEEEAEEB-------- 
------------------------ ------------------------ ------------------------ ------------------------ ------------------------ ------------------------ ------------------------ --------------------G--- ------------------------ ------------------------ ------------------------ ------------------------ --------------------G--- -----CCCCCCCCCCCCC------ ---DDAAA--ADA----ADDDD-- --BAA---------------AAFB -BDA------------------AB -BA-------------------AB BAA-------------------B- BAA------------------AB- -AA------------------B-- --A-----------------AB-- --EA-----------AABEEB--- ---BBBBBBB----BBB------- ------BEEEEEEEE--------- 
--------G--------------- ------------------------ ------------------------ ------------------------ ------------------------ --------G--------------- ------------------------ ------------------------ --------G--------------- ------------------------ ------------------------ ------------------------ ------------------------ ------CCCCCCCCCCCC------ ----DDDAAAADA--AAADDDD-- ---BAA---------------AFB -BBA------------------AB BAA-------------------AB BA--------------------B- BAA------------------AB- --A-----------------AB-- --A-------------AAAAAB-- --EA----A------AEBEEB--- ---EEEEAAAAAAAAB-------- -------BEEEEEEE--------- 
------H----------------- ------------------------ ------------------------ ------------------------ ------------------------ ------------------G----- ------G----------------- ------------------H----- ------------------------ ------------------------ ------G----------------- ------------------G----- ------------------------ ------CCCCCCCCCCCC------ ----DDJDDDDDAAAADDDDDD-- ---BAAA------------AAAF- -BBA------------------AB BA--------------------AB B--------------------AB- BAA-----------------AAB- --BA---------------AAB-- --AA------------AAAAB--- --EEAAAAAAAABAAAEB------ ----BBEEAAAAAEEB-------- --------EEEEB----------- 
------------------------ ------------------------ -----------G------------ ------------------------ -----------H------------ ------------------------ ------------------------ ------------------------ ------------------------ ------------------------ ------------------------ -----------H------------ ------------------------ -------CCCCCCCCCCC------ ----DDDDDDDDDDDDDDDD---- ---BA-------------AAFFF- -BBA------------------AB BA-------------------AAB BA-------------------AB- -AA-----------------AB-- --BA---------------AAB-- ---BAA---------AAAAF---- ---BBEAAAAAABAEEE------- ------BEEAAAEB---------- ---------BBB------------ 
------------------------ ------------------------ ------------------------ ------------------------ ------------------------ ------------------------ ------------------------ ------------------------ ------------------------ ------------------------ ------------------------ ------------------------ ------------------------ ------CCCCCCCCCCCC------ ----DDAAAADDDAAAAADD---- ---BA-------------AAFFF- -BBA---------------AAAF- -BA------------------AF- -BA------------------B-- -BAA-----------------B-- --BAA--------------AAB-- ---BAAA--------AAAAF---- -----BEAAAAABEEB-------- -------EEEEEE----------- ------------------------ 
------------------------ ------------------------ ------------------------ ------------------------ ------------------------ ------------------------ ----------------G---G--- ------------------------ ------------------------ ------------------------ ------------------------ ----------------H------- ------------------------ ------CCCCCCCCCCCC------ ----DDA--AADAA---ADD---- ---BA--------------AF--- --BA---------------AAB-- -BAA----------------AB-- -BAA-----------------B-- --BAA----------------B-- ---BAA-------------AAB-- ----BAB-------AAAAAAF--- ------BEAA-ABEEB-------- --------EEEEE----------- ------------------------ 
------------------------ ------------------------ -------G---------------- --------------G--------- ------------------------ ----I------------------- -------G---------------- ------------------------ --------------H--------- -------H---------------- --------------G--------- ----H--G---------------- ------------------------ ------CCCCCCCCCCCC------ ----DDAA--ADAA--AADD---- ---BA-------------ABB--- ---AA--------------AF--- --BA---------------AAB-- --BAA---------------AB-- ---BA---------------AB-- ----BAA--------AAAAAAB-- -----BBA-----AAAAAAF---- ------BEEAAABEE--------- ---------BBB------------ ------------------------ 
------------------------ ---------I-------------- ------------------------ ------------------------ ------------------------ ------------------------ ---------G-------------- ------------------------ ---------H-------------- ------------------------ ------------------------ ---------G-------------- ------------------------ -------CCCCC---CC------- ----DDDAAAADDAAAADD----- ----BA-----------AABB--- ---BAA------------AB---- ---AA--------------AB--- ---AA--------------AB--- ----AAA------------AB--- ----BBAA------AAAAAAB--- ------BAAA--AAAA-AA----- -------BBEEEBE---------- ------------------------ ------------------------ 
------------------------ ------------------------ ------------------------ ------------------------ ------------------------ ------------------------ ------------------------ ------------------------ ------------------------ ------------------------ ------------------------ ------------------------ ------------------------ --------CC-------------- -----DDDAADDDDDDDD------ ----BDAA--AAAAAAAABB---- ----BAA----------ABB---- ---BA------------AAB---- ---BAA------------ABB--- ----BAAAA-----AAAAABB--- ------BBAAA-AAABBBBB---- -------BBBAAAAB--------- ---------BBBB----------- ------------------------ ------------------------ 
------------------------ ------------------------ ------------------------ ------------------------ ------------------------ ------------------------ ------------------------ ------------------------ ------------------------ ------------------------ ------------------------ ------------------------ ------------------------ ------------------------ -------DDDD------------- ----BBBBAAABBBBBBB------ ----BBAAA-----AABB------ ----BA--A------ABBB----- ----BAAAAA----AAAAB----- -----BBBBAAAAAAAAAA----- --------BBBBBBB--------- ----------BBB----------- ------------------------ ------------------------ ------------------------ 
------------------------ ------------------------ ------------------------ ------------------------ ------------------------ ------------------------ ------------------------ ------------------------ ------------------------ ------------------------ ------------------------ ------------------------ ------------------------ ------------------------ ------------------------ -------BBBBBBBB--------- -----BBBBBA--AAB-------- -----BBBBBA--AAB-------- -----BBBBBAAAABB-------- ---------BBBBBB--------- ------------------------ ------------------------ ------------------------ ------------------------ ------------------------ 
------------------------ ------------------------ ------------------------ ------------------------ ------------------------ ------------------------ ------------------------ ------------------------ ------------------------ ------------------------ ------------------------ ------------------------ ------------------------ ------------------------ ------------------------ ----------BBBB---------- ----------BBBBB--------- ----------BBBBB--------- ----------BBBB---------- ------------------------ ------------------------ ------------------------ ------------------------ ------------------------ ------------------------ 
