model
size = 10 32 10, scale = 0.05, origin = -y
material 
  colors = A:#D00 B:#B00 C:#A00 D:#800 E:#700 F:#BBB G:#E00 H:#500 I:#400 J:#EE2424 K:#EE4848 L:#EE6C6C M:#200 N:#EE1212 O:#EE3636
voxels
223-4B5-4A2B4-5AB2(4-6A)4-GK4A4-GLK3A5-2G2A226-4D5-5CD3-6B2C2-6A2B3(2-7AB)3(2-8A)3-6A205-4E5-6D3-6C2D2-6B2C-B6A4B2(8ABJ)8ABG8ANB8AN-8A2-8A4-4A187-2H6-6E3-7DE2-6C2D-C6B3CB6A3BJ8ABL8ABG28AOB8AG-8A3-6A166-I9-2I7-4H5-6E3-7DE2-6C2D-C6B3CB6A3BG8AB49AG-8A3-6A6-4(F9-)F8-2F8-6(F9-)2F3(9-F)8-MFI7-M2I7-4H5-6E3-7DE2-6C2D-C6B3CB6A3B9AB40AJ9A-8A3-6A166-I9-M9-2H6-6E3-7DE2-6C2D-C6B3CB6A3B9AB30AL9AK9A-8A3-6A195-4E5-6D3-6C2D2-6B2C-B6A4B8AB9AB10AJ9AK9A-8A2-8A4-4A206-4D5-5CD3-6B2C2-B5A2B2(2-B6AB)2-7AB3(2-8A)3-6A235-4B5-B2A3B4-4A2B2(4-5AB)4-5AG4-3A3G5-BA2G23-
