model
size = 30 22 30, scale = 0.05, origin = -y
material 
  colors = A:#8F77B5 B:#FBE251 C:#888 D:#444 E:#F7D94C F:#B1AABE G:#255359 H:#4A225D
voxels
------------------------------ ------------------------------ ------------------------------ ------------------------------ ------------------------------ ------------------------------ ------------------------------ ------------------------------ ------------------------------ ------------------------------ ------------------------------ ------------------------------ ------------------------------ ------------------------------ ------------------------------ -------------AAAA------------- --------------AA-------------- ------------------------------ ------------------------------ ------------------------------ ------------------------------ ------------------------------ 
------------------------------ ------------------------------ ------------------------------ ------------------------------ ------------------------------ ------------------------------ ------------------------------ ------------------------------ ------------------------------ ------------------------------ ------------------------------ ------------------------------ ------------------------------ ------------------------------ ------------------------------ -----------AAAAAAAA----------- ------------AAAAAA------------ -------------AAAA------------- ------------------------------ ------------------------------ ------------------------------ ------------------------------ 
------------------------------ ------------------------------ ------------------------------ ------------------------------ ------------------------------ ------------------------------ ------------------------------ ------------------------------ ------------------------------ ------------------------------ ------------------------------ ------------------------------ ------------------------------ ------------------------------ ------------------------------ ---------AAA------AAA--------- ----------AAAAAAAAAA---------- -----------AAAAAAAA----------- -------------AAAA------------- ------------------------------ ------------------------------ ------------------------------ 
------------------------------ ------------------------------ ------------------------------ ------------------------------ ------------------------------ ------------------------------ ------------------------------ ------------------------------ ------------------------------ ------------------------------ ------------------------------ ------------------------------ ------------------------------ ------------------------------ ------------------------------ ------AAAA----------AAAA------ -------AAAAA------AAAAA------- ---------AAAAAAAAAGAA--------- -----------AAAAAAAA----------- ------------------------------ ------------------------------ ------------------------------ 
------------------------------ ------------------------------ ------------------------------ ------------------------------ ------------------------------ ------------------------------ ------------------------------ ------------------------------ ------------------------------ ------------------------------ ------------------------------ ------------------------------ ------------------------------ ------------------------------ ------------------------------ -----AAA--------------AAA----- -----AAAAA----------AAAAA----- ------AAAAAAA----AAAAAAA------ ---------AAAAAAAAAAAA--------- -------------AAAA------------- ------------------------------ ------------------------------ 
------------------------------ ------------------------------ ------------------------------ ------------------------------ ------------------------------ ------------------------------ ------------------------------ ------------------------------ ------------------------------ ------------------------------ ------------------------------ ------------------------------ ------------------------------ ------------------------------ ------------------------------ ----A--------------------A---- ----AAA----------------AAA---- -----AAAAAA--------AAAAAA----- -------AAAAAAA--AAAAAAA------- -----------AAABBAAA----------- ------------------------------ ------------------------------ 
------------------------------ ------------------------------ ------------------------------ ------------------------------ ------------------------------ ------------------------------ ------------------------------ ------------------------------ ------------------------------ ------------------------------ ------------------------------ ------------------------------ ------------------------------ ------------------------------ ------------------------------ ---AA--------------------AA--- ----AA------------------AA---- ----AAAA--------------AAAA---- ------AAAAAA------AAAAAA------ --------AAAABBBBBBAAAA-------- ------------------------------ ------------------------------ 
------------------------------ ------------------------------ ------------------------------ ------------------------------ ------------------------------ ------------------------------ ------------------------------ ------------------------------ ------------------------------ ------------------------------ ------------------------------ ------------------------------ ------------------------------ ------------------------------ ------------------------------ ---AA--------------------AA--- ---AA-------------------AAA--- ----AAA----------------AGA---- -----AAAAA----------AAAAA----- -------AAABBBBBBBBBBAAA------- -------------AAAA------------- ------------------------------ 
------------------------------ ------------------------------ ------------------------------ ------------------------------ ------------------------------ ------------------------------ ------------------------------ ------------------------------ ------------------------------ ------------------------------ ------------------------------ ------------------------------ ------------------------------ ------------------------------ ------------------------------ ---A----------------------A--- ---AA--------------------AA--- ----AA------------------AA---- -----AAA--------------AAA----- ------AABBBBBBBBBBBBBBAA------ -----------AAEAAEAA----------- ------------------------------ 
------------------------------ ------------------------------ ------------------------------ ------------------------------ ------------------------------ ------------------------------ ------------------------------ ------------------------------ ------------------------------ ------------------------------ ------------------------------ ------------------------------ ------------------------------ ------------------------------ ------------------------------ --AA----------------------AA-- ---AA--------------------AA--- ---AAA------------------AAA--- ----AAAA--------------AAAA---- ------AABBBBB-BB-BBBBBAA------ ---------AAAFEAAEFAAA--------- ------------------------------ 
------------------------------ ------------------------------ ------------------------------ ------------------------------ ------------------------------ ------------------------------ ------------------------------ ------------------------------ ------------------------------ ------------------------------ ------------------------------ ------------------------------ ------------------------------ ------------------------------ ------------------------------ --A------------------------A-- --AA----------------------AA-- ---AAA------------------AAA--- ----AAA----------------AAA---- ------ABBBBB--BB--BBBBBA------ ---------AAAFAAAAFAAA--------- ------------------------------ 
------------------------------ ------------------------------ ------------------------------ ------------------------------ ------------------------------ ------------------------------ ------------------------------ ------------------------------ ------------------------------ ------------------------------ ------------------------------ ------------------------------ ------------------------------ ------------------------------ ------------------------------ -AA------------------------AA- --AA----------------------AA-- --AGA--------------------AGA-- ---AAAA-------BB-------AAAA--- -----AABBBBBB-AA-BBBBBBAA----- --------AAAHAAAAAAHAAA-------- ------------------------------ 
------------------------------ ------------------------------ ------------------------------ ------------------------------ ------------------------------ ------------------------------ ------------------------------ ------------------------------ ------------------------------ ------------------------------ ------------------------------ ------------------------------ ------------------------------ ------------------------------ ------------------------------ -A--------------------------A- -AA------------------------AA- --AAA--------------------AAA-- ---AAA------BBBBBB------AAA--- -----ABBBB-BAAAAAAB-BBBBA----- --------AFFAAAAAAAAFFA-------- ------------------------------ 
------------------------------ ------------------------------ ------------------------------ ------------------------------ ------------------------------ ------------------------------ ------------------------------ ------------------------------ ------------------------------ ------------------------------ ------------------------------ ------------------------------ ------------------------------ ------------------------------ ------------------------------ AA--------------------------AA -AA------------------------AA- -AAA----------------------AAA- --AAAA------BBBBBB------AAAA-- ----AABBB---AAAAAA---BBBAA---- -------AEEAAAAAAAAAAEEA------- ------------------------------ 
------------------------------ --------------CC-------------- --------------CC-------------- --------------CC-------------- --------------CC-------------- --------------CC-------------- --------------CC-------------- --------------CC-------------- --------------CC-------------- --------------CC-------------- --------------CC-------------- --------------CC-------------- --------------CC-------------- --------------CC-------------- --------------CC-------------- AA------------CC------------AA AAA-----------CC-----------AAA -AAA----------CC----------AAA- --AAA------BBBAABBB-----AAAA-- ----ABBBBBBAAAAAAAABBBBBEA---- -------AAAAAAAAAAAAAAAA------- --------------AA-------------- 
--------------CC-------------- --------------CC-------------- --------------DD-------------- --------------DD-------------- --------------DD-------------- --------------DD-------------- --------------DD-------------- --------------DD-------------- --------------DD-------------- --------------DD-------------- --------------DD-------------- --------------DD-------------- --------------DD-------------- --------------DD-------------- --------------DD-------------- AA------------DD------------AA AAA-----------DD-----------AAA -AAA----------DD----------AAA- --AAA------BBBAABBB-----AAAA-- ----ABBBBBBAAAAAAAABBBBBEA---- -------AAAAAAAAAAAAAAAA------- --------------AA-------------- 
--------------CC-------------- --------------CC-------------- ------------------------------ ------------------------------ ------------------------------ ------------------------------ ------------------------------ ------------------------------ ------------------------------ ------------------------------ ------------------------------ ------------------------------ ------------------------------ ------------------------------ ------------------------------ AA--------------------------AA -AA------------------------AA- -AAA----------------------AAA- --AAAA------BBBBBB------AAAA-- ----AABBB---AAAAAA---BBBAA---- -------AEEAAAAAAAAAAEEA------- ------------------------------ 
--------------DD-------------- --------------CC-------------- --------------CC-------------- --------------CC-------------- ------------------------------ ------------------------------ ------------------------------ ------------------------------ ------------------------------ ------------------------------ ------------------------------ ------------------------------ ------------------------------ ------------------------------ ------------------------------ -A--------------------------A- -AA------------------------AA- --AAA--------------------AAA-- ---AAA------BBBBBB------AAA--- -----ABBBB-BAAAAAAB-BBBBA----- --------AFFAAAAAAAAFFA-------- ------------------------------ 
------------------------------ --------------DD-------------- --------------DD-------------- --------------DD-------------- ------------------------------ ------------------------------ ------------------------------ ------------------------------ ------------------------------ ------------------------------ ------------------------------ ------------------------------ ------------------------------ ------------------------------ ------------------------------ -AA------------------------AA- --AA----------------------AA-- --AAA--------------------AAA-- ---AAAA-------BB-------AAAA--- -----AABBBBBB-AA-BBBBBBAA----- --------AAAHAAAAAAHAAA-------- ------------------------------ 
------------------------------ ------------------------------ ------------------------------ ------------------------------ ------------------------------ ------------------------------ ------------------------------ ------------------------------ ------------------------------ ------------------------------ ------------------------------ ------------------------------ ------------------------------ ------------------------------ ------------------------------ --A------------------------A-- --AA----------------------AA-- ---AAA------------------AAA--- ----AAA----------------AAA---- ------ABBBBB--BB--BBBBBA------ ---------AAAFAAAAFAAA--------- ------------------------------ 
------------------------------ ------------------------------ ------------------------------ ------------------------------ ------------------------------ ------------------------------ ------------------------------ ------------------------------ ------------------------------ ------------------------------ ------------------------------ ------------------------------ ------------------------------ ------------------------------ ------------------------------ --AA----------------------AA-- ---AA--------------------AA--- ---AAA------------------AAA--- ----AAAA--------------AAAA---- ------AABBBBB-BB-BBBBBAA------ ---------AAAFEAAEFAAA--------- ------------------------------ 
------------------------------ ------------------------------ ------------------------------ ------------------------------ ------------------------------ ------------------------------ ------------------------------ ------------------------------ ------------------------------ ------------------------------ ------------------------------ ------------------------------ ------------------------------ ------------------------------ ------------------------------ ---A----------------------A--- ---AA--------------------AA--- ----AA------------------AA---- -----AAA--------------AAA----- ------AABBBBBBBBBBBBBBAA------ -----------AAEAAEAA----------- ------------------------------ 
------------------------------ ------------------------------ ------------------------------ ------------------------------ ------------------------------ ------------------------------ ------------------------------ ------------------------------ ------------------------------ ------------------------------ ------------------------------ ------------------------------ ------------------------------ ------------------------------ ------------------------------ ---AA--------------------AA--- ---AAA------------------AAA--- ----AAA----------------AGA---- -----AAAAA----------AAAAA----- -------AAABBBBBBBBBBAAA------- -------------AAAA------------- ------------------------------ 
------------------------------ ------------------------------ ------------------------------ ------------------------------ ------------------------------ ------------------------------ ------------------------------ ------------------------------ ------------------------------ ------------------------------ ------------------------------ ------------------------------ ------------------------------ ------------------------------ ------------------------------ ---AA--------------------AA--- ----AA------------------AA---- ----AAAA--------------AAAA---- ------AAAAAA------AAAAAA------ --------AAAABBBBBBAAAA-------- ------------------------------ ------------------------------ 
------------------------------ ------------------------------ ------------------------------ ------------------------------ ------------------------------ ------------------------------ ------------------------------ ------------------------------ ------------------------------ ------------------------------ ------------------------------ ------------------------------ ------------------------------ ------------------------------ ------------------------------ ----A--------------------A---- ----AAAA--------------AAAA---- -----AAAAAA--------AAAAAA----- -------AAAAAAAAAAAAAAAA------- -----------AAAEEAAA----------- ------------------------------ ------------------------------ 
------------------------------ ------------------------------ ------------------------------ ------------------------------ ------------------------------ ------------------------------ ------------------------------ ------------------------------ ------------------------------ ------------------------------ ------------------------------ ------------------------------ ------------------------------ ------------------------------ ------------------------------ -----AAA--------------AAA----- -----AAAAA----------AAAAA----- ------AAAAAAA----AAAAAAA------ ---------AAAAAAAAAAAA--------- -------------AAAA------------- ------------------------------ ------------------------------ 
------------------------------ ------------------------------ ------------------------------ ------------------------------ ------------------------------ ------------------------------ ------------------------------ ------------------------------ ------------------------------ ------------------------------ ------------------------------ ------------------------------ ------------------------------ ------------------------------ ------------------------------ ------AAAA----------AAAA------ -------AAAAA------AAAAA------- ---------AAAAAAAAAGAA--------- -----------AAAAAAAA----------- ------------------------------ ------------------------------ ------------------------------ 
------------------------------ ------------------------------ ------------------------------ ------------------------------ ------------------------------ ------------------------------ ------------------------------ ------------------------------ ------------------------------ ------------------------------ ------------------------------ ------------------------------ ------------------------------ ------------------------------ ------------------------------ ---------AAA------AAA--------- ----------AAAAAAAAAA---------- -----------AAAAAAAA----------- -------------AAAA------------- ------------------------------ ------------------------------ ------------------------------ 
------------------------------ ------------------------------ ------------------------------ ------------------------------ ------------------------------ ------------------------------ ------------------------------ ------------------------------ ------------------------------ ------------------------------ ------------------------------ ------------------------------ ------------------------------ ------------------------------ ------------------------------ -----------AAAAAAAA----------- ------------AAAAAA------------ -------------AAAA------------- ------------------------------ ------------------------------ ------------------------------ ------------------------------ 
------------------------------ ------------------------------ ------------------------------ ------------------------------ ------------------------------ ------------------------------ ------------------------------ ------------------------------ ------------------------------ ------------------------------ ------------------------------ ------------------------------ ------------------------------ ------------------------------ ------------------------------ -------------AAAA------------- --------------AA-------------- ------------------------------ ------------------------------ ------------------------------ ------------------------------ ------------------------------ 
