model
size = 31 32 13, scale = 0.05, origin = -y
material 
  colors = A:#607FA0 B:#728DB9 C:#E00 D:#FFFF1E E:#647393 F:#111 G:#C0F H:#966 I:#AAA J:#960 K:#9F0 L:#FF6
voxels
8-8A2B5A16-15E16-5AB9A16-A2B2AB9A16-A2(B3A)3B3A3(16-A13CA)16-A4C5D4CA16-A3C7D3CB16-A2C3D3F3D2CB16-BC2(3DF)3DCB16-BC2DF5DF2DCB16-BC11D2(CA16-AC2(3DF)3D)CA15-2A2C9D2C2B14-2A3C7D3C2A13-2AB4C5D4C2(3A12-3A13C)B2A11-4A13C2B2A10-2AB3AB10A2B2A11-4A2B7AB2A2BA13-3A2B7AB4A17-B5A2BA2B203-2A13-2A14-EA13-AE14-2A13-2A2(14-2A13-AB)4(14-BA13-2A)3(14-2A13-2A)14-2A2(13-AB14-BA)13-2A2(14-A15-A)13-AE15-2A12-AE15-2A11-2AE15-3A9-2(3AE15-4A8-)5A13-5A10-4A11-5A11-6A7-6A13-17A16-7A2B2ABA20-5AB3A83-11A47-A17-A12-E17-E2(12-A17-A)12-B17-A2(12-B17-B)12-A17-B9(12-A17-A)133-3A19-3A5-A-3A17-5A7-3A15-4A9-4A13-4A11-19A13-17A16-13A21-4AB2A52-13A20-9A16-A19-A10-E19-E2(10-A19-A)3(10-A19-B)9(10-A19-A)193-3A21-3A3-4A21-4A6-A19-3A7-B3A15-4A2(9-6A)12-6A5-6A16-4A5-4A21-7A20-3A-11A17-4A5-4A14-A19-A10-E19-E4(10-A19-A)3(10-B19-A)3(10-A19-A)10-A19-B10-A19-A285-3A23-3A-5A21-5A2-3A21-3A6-5A13-5A9-5A11-4AB13-2A11-2A18-2A7-2A17-A2-2A7-2A2-A15-4A7-4A13-A19-A10-E19-E6(10-A19-A)3(10-B19-B)2(10-A19-B)10-A19-A285-3A23-3A-5A21-5A-4A21-4A4-B2A19-2AB7-B5A11-5AB10-4A11-4A16-A9-A17-A2-A9-A2-A15-3A9-3A13-A19-A10-E19-E10-A19-A3(10-A19-B)6(10-A19-A)10-A19-B10-A19-A285-3A23-3A-5A21-5A-4A21-4A4-3A19-3A7-B5A11-6A10-4A11-4A16-A9-A17-A2-A9-A2-A15-3A9-3A13-A19-A10-E19-E10-A3(19-A10-B)19-A10-A19-A10-F19-A10-L19-A10-F3(19-A10-A)19-B2(10-A19-A)254-3A23-3A-5A21-5A2-3A21-ABA6-5A13-4AB9-5A11-4AB13-2A11-2A18-A9-A17-A2-A9-A2-A15-3A9-3A14-A17-A12-E17-E4(12-A17-A)12-A2(17-B12-F)17-B12-L3(17-B12-A)4(17-A12-A)181-3A21-3A3-5A19-5A4-6A13-6A7-6A11-6A9-5A11-5A12-4A9-4A16-2A9-2A19-A9-A17-A2-A9-A2-A15-3A9-3A15-2A13-2A14-EA13-AE4(14-BA13-AB)14-2A13-2A14-FJ13-2A14-LJ13-2A14-FJ4(13-2A14-2A)2(13-2A)2(15-A13-2A)15-2A133-4A17-4A5-5A17-5A6-4A15-3AC9-B4A11-4AC11-B3A11-4A13-4A9-4A16-2A9-2A19-A9-A20-A9-A17-A2-A9-A2-A15-3A9-3A16-2A11-2A16-EA11-AE3(16-2A11-2A)2(16-2A11-AG)2(16-FJ11-AG)16-LJ11-2A16-2A2(11-2A15-3A)11-3A14-3A11-3A2(14-2A13-2A)14-A15-A13-AE15-2A12-AE15-2A11-2AE15-3A9-2(3AE15-4A8-)4A15-4A9-B3A13-3AC11-B4A9-5A13-B6A4-6A16-5A4-4A20-2A6-2A21-A7-2A20-A9-A17-A2-A9-A2-A15-3A9-3A17-4A4-AHB2A18-3EA4-A4E18-5A3-3ABA18-AB3A3-3ABA18-A2B2A3-AH3A18-A2B2A3-3A2G18-2AB2A3-3AKG18-FAB2A3-3AGK18-F4A3-AHA2G18-F4A3-3AK2G16-6A3-3AGKG16-4ABA3-3A3G16-3A2B2A2-AHA3G16-3A2B2A3-5A16-2B2AB2A3-4AB16-B3AB2A3-4AB16-3E3A4-AH2ABA14-E3BE2A4-AB4A13-AE3BE2A4-ABAC3A12-A5E2A4-2A3C2A12-B2EI2E2A3-4A3CA11-AB2EH2E3A2-5A3CA10-7B3A3-AHB2A3C11-4AB4A3-2A2B2AC13-3A2B2A4-2A2B2A15-3AB2A4-3AB2A18-B2A4-3A22-A6-A22-A7-A21-A9-A20-A9-A19-2A9-2A21-A4-I25-E4-E2(26-B3-A)2(26-B3-I3(26-B3-A))27-A2-I27-2(A3-A26-)A3-A25-A4-I3(25-A4-A)25-A3-A27-A2-A27-A3-I26-A3-2(A25-A4-)A30-A167-
