model
size = 30 31 19, scale = 0.05, origin = -y
material 
  colors = A:#4C1566 B:#4F1869 C:#97E2A7 D:#87EB95
voxels
--------BBBBBADCAABABA-------- --------AAAABACCBAAAAA-------- --------ABABAB--ABAABB-------- ---------AABAACDBBABA--------- ---------AABBB--AABBB--------- ---------ABABBCDABAAA--------- ----------AAAB--AABB---------- ----------ABABCDABAB---------- ----------AABA--ABBB---------- ----------ABBBDCBBBB---------- -----------AAA--BBB----------- -----------BAACCAAB----------- -----------ABA--ABB----------- -----------ABADCBAB----------- -----------AAB--ABB----------- ------------ABCDBB------------ ------------AA--BA------------ ------------ABDCAB------------ ------------BA--BA------------ ------------ABDDBB------------ ------------BA--BB------------ ------------ABDDBB------------ -------------A--A------------- --------------DC-------------- ------------------------------ --------------CD-------------- ------------------------------ --------------CC-------------- ------------------------------ ------------------------------ ------------------------------ 
-----BBAAA----------BBAAA----- -----BAAAAA--------ABAAAA----- ------ABBBAAAAABABABBBBA------ ------AABBBAABBBAABBAABB------ ------AABAAABBBBBBAABAAB------ ------BAAAAAABABBABBABAB------ ------ABABAABBAABBABBABB------ -------BBBAAABBBAABBBAA------- -------BBBBABAABBABBBAA------- -------ABABBBABABAAAABB------- -------AABBBABABAABABBA------- -------BBAAABABAAAAABBB------- -------BABAABBABBBABBAA------- -------ABAAABABAAAABBAA------- --------AABBABBBBABBBA-------- --------AABABABABABBBB-------- --------BBABABAABBBAAA-------- --------ABAABABAAABBBB-------- --------BAABABBABABABA-------- --------ABABBABBAAAAAA-------- --------ABABAAABBBABBA-------- ---------AAAABBBBBABB--------- ---------BBAABBBAABBA--------- ---------BBAAAAAABBAA--------- ----------ABABBAABAA---------- ----------AAAAABABAB---------- -----------BABBAAAA----------- -------------ABBB------------- --------------BB-------------- ------------------------------ ------------------------------ 
---ABAABBB----------BAABBBB--- ---BABBBBAB--------AAAABABB--- ----ABAAABBBBABBBBABBBBBAA---- ----AABBAAAABBAAABABBBABBB---- ----AAABBBBBABAABBBABBBBAB---- ----ABAAAAABABAAAABBAABBAB---- ----AABBAABBBAAABBABBBABBB---- -----BBABBABBABABAABBBBAB----- -----ABAAAAABABAABBBBBBBA----- -----AABAAAAABAABAAAABBBA----- -----AABABBABBBBBAAAABABA----- -----BAAABAABAABBAABBBBAB----- -----BBABBBBBABAABAABABAA----- -----BABBBAAABAABBAABBBBA----- -----ABAAABAAAABBBBBBBBAB----- -----BAAAABBAABBAAAAAAAAA----- ------AAAABAAAABAAABBABB------ ------BBABBAABABAABABBBB------ ------ABBAABAAABAABBBABA------ ------AAABBAABABBAABABAA------ ------BBAAAAAABABAAABBBA------ -------AABBABBBBBABBBBB------- -------BABABBABABBBBAAA------- -------BBAABBABBBBBAABB------- --------BBBBAAAABABABB-------- --------AAAABBABABBBBB-------- --------ABAAABABBABBAB-------- ---------ABBBAABBAAAB--------- ----------BBABABBAAA---------- ------------CCCCCC------------ ------------CCCDDD------------ 
--BB----------------------BB-- --AB----------------------AA-- --AA----------------------AA-- ---B----------------------A--- ---B----------------------A--- ---B----------------------B--- ---B----------------------A--- ---BB--------------------AB--- ---AB--------------------BB--- ---BB--------------------AB--- ---AA--------------------BB--- ----B--------------------A---- ----B--------------------A---- ----A--------------------B---- ----A--------------------A---- ----B--------------------A---- ----AA------------------AB---- ----BB------------------AA---- ----BA------------------AB---- -----B------------------B----- -----A------------------A----- -----AB----------------BA----- ------A----------------B------ ------B----------------B------ -------B--------------B------- -------A--------------B------- -------B--------------A------- -------BA------------BA------- --------BABA------BBAB-------- ----------DD------CD---------- ----------DC------DC---------- 
-A--------------------------A- -B--------------------------A- -B--------------------------A- --B------------------------A-- --A------------------------B-- --A------------------------A-- --A------------------------B-- --B------------------------A-- --B------------------------A-- --A------------------------B-- --A------------------------B-- ---B----------------------A--- ---B----------------------B--- ---A----------------------A--- ---A----------------------A--- ---A----------------------A--- ---B----------------------A--- ---B----------------------B--- ----B--------------------B---- ----A--------------------A---- ----B--------------------B---- ----B--------------------B---- -----B------------------B----- -----A------------------B----- ------A----------------B------ ------A----------------B------ ------B----------------B------ -------BAB----------BAA------- -------ABB----------AAA------- --------DC----------CD-------- --------CC----------CC-------- 
BA--------------------------BB BB--------------------------AB AB--------------------------BA AB--------------------------BA -B--------------------------A- -B--------------------------B- -A--------------------------A- -A--------------------------A- -B--------------------------A- --A------------------------B-- --A------------------------B-- --A------------------------A-- --B------------------------B-- --A------------------------A-- --A------------------------A-- --B------------------------A-- --B------------------------B-- ---B----------------------A--- ---B----------------------B--- ---A----------------------A--- ---A----------------------B--- ----B--------------------B---- ----A--------------------B---- -----B------------------B----- -----A------------------B----- ------B----------------B------ ------A----------------B------ ------A----------------A------ -------B--------------B------- -------D--------------C------- -------C--------------C------- 
AA--------------------------BA AA--------------------------BB BA--------------------------BB BA--------------------------AB AB--------------------------AA BB--------------------------BB -A--------------------------A- -A--------------------------A- -B--------------------------A- -B--------------------------A- -A--------------------------B- -B--------------------------A- -A--------------------------A- --B------------------------B-- --B------------------------B-- --A------------------------A-- --A------------------------B-- --B------------------------A-- --B------------------------A-- ---A----------------------B--- ---A----------------------B--- ---A----------------------B--- ----A--------------------B---- ----A--------------------B---- -----B------------------B----- -----B------------------A----- ------B----------------A------ ------A----------------B------ ------BB--------------AA------ -------C--------------C------- -------C--------------D------- 
BA--------------------------AA AA--------------------------AB AA--------------------------AA AA--------------------------AA BB--------------------------AB AA--------------------------AA BA--------------------------AA BA--------------------------AB -B--------------------------B- -A--------------------------B- -B--------------------------B- -B--------------------------A- -A--------------------------B- -B--------------------------B- -B--------------------------B- -A--------------------------B- --A------------------------B-- --B------------------------A-- --A------------------------A-- --A------------------------A-- ---A----------------------B--- ---B----------------------A--- ----A--------------------B---- ----A--------------------B---- -----A------------------A----- -----B------------------B----- ------B----------------A------ ------A----------------A------ ------AA--------------AB------ -------C--------------C------- -------D--------------D------- 
AB--------------------------AB BA--------------------------BB AA--------------------------BA AB--------------------------AA AB--------------------------AB AB--------------------------BA BB--------------------------BB BA--------------------------AB AA--------------------------AA -B--------------------------A- -A--------------------------A- -A--------------------------A- -B--------------------------A- -A--------------------------B- -A--------------------------A- -B--------------------------B- -A--------------------------A- --A------------------------B-- --B------------------------B-- --A------------------------B-- ---B----------------------B--- ---A----------------------B--- ----A--------------------B---- ----A--------------------A---- -----A------------------B----- -----A------------------B----- ------A----------------B------ ------A----------------A------ ------A----------------B------ ------D----------------D------ ------C----------------D------ 
BB--------------------------BA BB--------------------------AA BB--------------------------BB BA--------------------------AB AA--------------------------BA AB--------------------------AB AB--------------------------AA AB--------------------------BB AB--------------------------BB AA--------------------------BB -A--------------------------B- -B--------------------------B- -B--------------------------A- -A--------------------------B- -B--------------------------A- -B--------------------------A- -A--------------------------B- --A------------------------A-- --A------------------------A-- --A------------------------A-- ---A----------------------A--- ---B----------------------A--- ----B--------------------A---- ----A--------------------B---- -----A------------------A----- ------B----------------B------ ------B----------------A------ ------B----------------B------ ------B----------------A------ ------C----------------C------ ------C----------------D------ 
BA--------------------------AB BB--------------------------BB AA--------------------------AA BA--------------------------BB AB--------------------------AA AA--------------------------AA AB--------------------------AB AB--------------------------AB AA--------------------------AA -B--------------------------B- -B--------------------------B- -A--------------------------B- -A--------------------------B- -A--------------------------B- -B--------------------------A- -A--------------------------B- --B------------------------B-- --A------------------------A-- --A------------------------A-- ---A----------------------B--- ---A----------------------A--- ---B----------------------B--- ----B--------------------B---- -----A------------------A----- -----A------------------B----- ------A----------------A------ ------B----------------B------ ------A----------------A------ ------A----------------B------ -------D--------------D------- -------D--------------C------- 
BB--------------------------BB BB--------------------------AB BB--------------------------AB AA--------------------------BA BA--------------------------AB BA--------------------------AB BB--------------------------BB -A--------------------------B- -B--------------------------A- -A--------------------------A- -B--------------------------A- -A--------------------------A- -A--------------------------B- -A--------------------------A- -B--------------------------A- -A--------------------------B- --A------------------------A-- --A------------------------A-- --A------------------------A-- ---A----------------------B--- ---B----------------------A--- ----A--------------------A---- ----B--------------------B---- -----B------------------A----- ------B----------------A------ ------B----------------A------ -------AAA----------ABA------- -------BBB----------BAA------- -------BAA----------BBA------- --------CD----------CD-------- --------CC----------DC-------- 
AB--------------------------BB AA--------------------------AA AB--------------------------BA AB--------------------------AA AB--------------------------AB -B--------------------------B- -B--------------------------A- -B--------------------------B- -B--------------------------A- -A--------------------------B- -B--------------------------B- -B--------------------------A- -B--------------------------B- --B------------------------B-- --A------------------------A-- --A------------------------A-- --B------------------------B-- --A------------------------B-- ---A----------------------B--- ---A----------------------A--- ---A----------------------B--- ----B--------------------B---- -----A------------------A----- ------B----------------A------ ------B----------------B------ -------AB-BBBAAAAAAA-BA------- --------AABAABBBBBABAB-------- --------ABABABBBBBBBAB-------- --------BAAABAAABBAABB-------- ----------CCCBABBDDD---------- ----------CDCDCDCDDC---------- 
-A--------------------------A- -A--------------------------A- -A--------------------------A- -A--------------------------A- -A--------------------------A- -A--------------------------B- -A--------------------------A- -A--------------------------B- -A--------------------------A- -AA------------------------AB- --B------------------------B-- --B------------------------B-- --A------------------------B-- --B------------------------A-- --B------------------------A-- --B------------------------A-- --A------------------------A-- ---A----------------------A--- ---B----------------------A--- ----B--------------------B---- ----B--------------------B---- -----A------------------A----- -----B------------------B----- ------AABAABBABBAABAAAAA------ -------BABABBBABBAABAAB------- ---------ABABBBBAABAB--------- ----------BAABBBAABA---------- -----------ABAABBBB----------- -----------AAAAABAA----------- ------------DCCCDC------------ -------------CCDD------------- 
-BBBA--------------------BBAB- -AAABB------------------BAAAA- -ABABAA----------------ABBAAA- --ABAAB----------------ABABA-- --BABBAA--------------BBBABB-- --BAAABAB------------ABBBABB-- --ABBBBAAAA--------AAAABBBAA-- --BAAABAABBBBAABBABBBBAABAAB-- --BBBBAABBBABBAABBAAAAAABAAA-- --AAAABBABBAAABABABABBBBAABB-- --BABBAABAABAAAABAAAAABBABAB-- --ABBABAABBBAAAABABAABAAAAAB-- --BAABABBBBBABAAABABBBBBBABA-- ---ABBBABABABBBBABBABBAABAB--- ---BAAAAABBAAABABAABABAAABB--- ---AABBAAABBBBBABABBBAAABAA--- ---ABAABABBBAAAABABBABABABA--- ---ABBABAABAAAABBABBABABABA--- ----AAAABBBBBAABABBABAAABA---- ----ABBABBBABBBAABABAABABA---- -----ABBBBAABBABAAABAAAAA----- -----BAABBAABBBAABBAAAAAA----- ------BBAAAAABBBABABBABB------ --------BABBABBABBBBAB-------- ----------BAABBBABBB---------- -------------BAAA------------- ------------------------------ ------------------------------ ------------------------------ ------------------------------ ------------------------------ 
--ABB--------------------BAA-- --BBAB------------------BAAB-- --AABAB----------------ABBBB-- ---BAAA----------------BAAA--- ---ABABA--------------ABAAB--- ---ABBAAA------------BBBAAA--- ---BBBABBBB--------BAABABBB--- ---BAAAAABBAABBBAAABBABBBAB--- ---AAABABABBAABBAABAAABABBA--- ---BBBBBAAAABABBBBBAABBABAB--- ---BBBBAAAABAAABABABAAAAAAB--- ---ABBBBABAABBBBBBBBABABAAA--- ---AAABBAAAAAAABBABABBBBBAA--- ---ABBBAABAABBBBBAAAAAAABAA--- ---ABAAABABBBBBABBBABABBBBA--- ----ABABAAABABBABABABBBAAA---- ----BABAABBABAABBAAABAABAB---- ----BBAABABBBBBBABAAABBAAA---- -----ABBBBBABBAAAAAAAABBA----- -----ABAAAABBBABBAABBBABB----- ------AAABBAAABABABBABAA------ ------ABBBAABBAAABBBBBAB------ --------BAAABBAABBBAAA-------- -----------BBAABABB----------- ------------------------------ ------------------------------ ------------------------------ ------------------------------ ------------------------------ ------------------------------ ------------------------------ 
---BAAA----------------BAAB--- ---AAAAA--------------BBABB--- ---BAABBBA----------AABAAAA--- ---BAAABAAA--------BBBABABB--- ---BBAAABBBBAABBABABAAABAAA--- ----BBABABAABABBBABAABABAB---- ----BAABAB-AAAAAABB-BAAAAA---- ----ABAAAB-AAABBABB-BBABAA---- ----ABBAABABBABBBBABBBABAA---- ----AABBAAAAABBABAABBAABBA---- ----ABABBAABBABBAAAAAABAAB---- ----BABBBAAABBAABBBAABBABA---- ----BAABBBBABBBBABAAABBBBB---- -----ABBAAABBABAABAABAAAA----- -----BBBBBAAABBAAABABABBB----- -----AABBABBBBBABBAAABABA----- ------AAAAABAAABBBBAAABB------ ------BBABAAAABBBBBBBBBA------ -------BBABBABABABBABAA------- -------AABBBBBBAABAAABA------- --------ABAABBAABABABA-------- -----------AABBBABA----------- -------------AABA------------- ------------------------------ ------------------------------ ------------------------------ ------------------------------ ------------------------------ ------------------------------ ------------------------------ ------------------------------ 
----BBAAAAB--------BAABAAA---- ----BBABABAAABABBBBABAAABA---- ----ABBBA-BABAAABBBA-BABBA---- ----BABBBA-AABBABBA-AAABAA---- ----AAABAABBAABBAAAABBAABA---- ----ABBAAABAAAABBAABBBBABA---- ----AAAABBAAABBAABABAABABA---- -----BBABABBBBBBBAAAAAAAB----- -----BBBABBAABAAAABBBBBBA----- ------BBABABAAAABBAABBAA------ ------AAABBAAABBBBABAABB------ -------BAABAAAABBABBABA------- -------ABABAABAABAABABB------- --------BBBBBAABAABABB-------- --------BAAABABBABAAAA-------- ---------BABABBAAAAAB--------- ----------BBAAABBAAB---------- ------------ABABBA------------ -------------AABA------------- ------------------------------ ------------------------------ ------------------------------ ------------------------------ ------------------------------ ------------------------------ ------------------------------ ------------------------------ ------------------------------ ------------------------------ ------------------------------ ------------------------------ 
---------BBABBAAAABBA--------- ---------BABBBAAAABBA--------- ---------BAABABBAAAAA--------- ----------BBAABBBABB---------- ----------BBAABBABAB---------- ----------BBBBABBBBA---------- -----------BABBBABB----------- -----------BBBABBBA----------- ------------AAABAB------------ -------------AAAB------------- --------------BA-------------- ------------------------------ ------------------------------ ------------------------------ ------------------------------ ------------------------------ ------------------------------ ------------------------------ ------------------------------ ------------------------------ ------------------------------ ------------------------------ ------------------------------ ------------------------------ ------------------------------ ------------------------------ ------------------------------ ------------------------------ ------------------------------ ------------------------------ ------------------------------ 
