model
size = 32 32 23, scale = 0.05, origin = -y
material 
  colors = A:#E83015 B:#222 C:#111 D:#444 E:#FCFAF2 F:#FFB11B
voxels
168-4B8-4B2(16-B2-B8-B2-B)16-4B8-4B176-4B8-4B2(16-B2-B8-B2-B)16-4B8-4B591-2(6B6-6B14-)2(2B2E2B6-2B2E2B14-)6B6-6B14-6B6-6B110-2(6B6-6B14-)2(2B2E2B6-2B2E2B14-)6B6-6B14-6B6-6B1101-A18-A12-2A16-2A13-2A14-2A15-2A12-2A17-2A10-2A19-2A8-2A21-2A6-2A23-A6-A57-F4-F83-2(3(8A4-8A12-)8A4-8A7-5B8A4-8A5B6-2(B8A4-8AB10-)B8A4-8AB6-5B8A4-8A5B7-)3(8A4-8A12-)8A4-8A7-5B8A4-8A5B6-B-7A4-7A-B10-B2-6A4-6A2-B10-B3-5A4-5A3-B6-5B4-3A6-3A4-5B12-2A2-2B2-2A26-2B27-2F4B2F25-6B50-9A4-9A10-9A4-9A7-3B9A4-9A3B4-3B9A4-9A3B3-4B9A4-9A4B3-2(3B9A4-9A3B4-)3B9A4-9A3B3-4B9A4-9A4B3-3B9A4-9A3B7-9A4-9A7-3B9A4-9A3B4-3B9A4-9A3B3-4B9A4-9A4B3-2(3B9A4-9A3B4-)3B9A4-9A3B3-4B9A4-9A4B3-3B9A-2A-9A3B7-9A-2A-9A7-3B9A-2A-9A3B4-3B9A-2A-9A3B3-4B9A-2A-9A4B3-2(3B9A-2A-9A3B4-)3B9A-2A-9A3B3-4B9A-2A-9A4B3-3B9A-2A-9A3B7-5A5-2A5-5A10-5A-10A-5A16-10A16-9A4-9A8-11A4-11A6-11A4-11A5-B11A4-11AB4-B11A4-11AB3-2B11A4-11A2B3-2(B11A4-11AB4-)B11A4-11AB3-2B11A4-11A2B3-B11A4-11AB5-11A4-11A5-B11A4-11AB4-B11A4-11AB3-2B11A4-11A2B3-B11A4-11A2(B4-B12A2-12A)B3-2B26A2B3-B26AB5-26A5-B26AB4-B26AB3-2B26A2B3-2(B26AB4-)B26AB3-2B26A2B3-B26AB5-26A6-26A10-18A10-2(3A7-A4-A7-3A6-)3A7-A4-A7-3A5-B3A7BA4-A7B3AB4-B11A4-11AB3-2B11A4-11A2B3-2(B11A4-11AB4-)B11A4-11AB3-2B11A4-11A2B3-B11A4-11AB5-11A4-11A5-B11A4-11AB4-B11A4-11AB3-2B11A4-11A2B3-2(B12A2-12AB4-)B12A2-12AB3-2B26A2B3-B26AB5-26A5-B26AB4-B26AB3-2B26A2B3-2(B26AB4-)B26AB3-2B26A2B3-B26AB5-26A6-5A16B5A10-A16-A10-A9-A4-A9-A5-2(2A9-A4-A9-2A4-)2A3B5CBA4-AB5C3B2A2(4-12A)3-4(B12A4-12AB2-)B12A4-12AB3-3AD8A4-8AD3A2(4-12A)4-13A2-13A4-11ACA2-AC11A3-3(B13A2-13AB2-)B28AB2-B28AB3-3AD20AD3A4-28A4-11AD4AD11A4-28A3-B11AC4AC11A4(B2-B28A)B3-28A4-4A7D6A7D4A4-6AB14CB6A9-A16-A2(9-2A)2(2-2A9-2A4-2A9-2A)2-2A9-2A4-2AB7CB2A2-2AB7CB2A13(4-13A2-13A)12(4-28A)4-2(4A8B)4A4-6AB14CB6A4-6A16-6A3(4-A11-A2-A11-A)4-A2B7C2BA2-A2B7C2BA5(4-13A2-13A)3-B13A2-13AB2-B13A2-13AB3-6(13A2-13A4-)28A4-28A3-B28AB2-B28AB3-7(28A4-)28A3-B2(4A8C)4AB2-BA6B14C6BAB3-A26-3(A4-A11-A2-A11-)A4-AB9CBA2-AB9CBA2(3-B13A2-13AB2-B13A2-13AB3-2(13A2-13A4-)13A2-13A)3-B13A2-13AB2-B13A2-13AB3-13A2-13A2(4-28A)2(3-B28AB2-B28AB3-2(28A4-)28A)3-B28AB2-BAB24CBAB3-A26-3(A4-A11-A2-A11-)A4-AB9CBA2-AB8C2BA3-B13A2-13AB2-B13A2-13AB3-2(13A2-13A4-)13A2-13A3-B13A2-13AB2-B13A2-13AB3-13A2-13A4-3A9CA2-A9C3A4-13A2-13A3-B13A2-13AB2-B13A2-13AB3-13A2-13A2(4-28A)3-B28AB2-B28AB3-2(4A8C)4A4-28A4-3AD20AD3A3-B28AB2-B28AB3-2(28A4-)28A3-B28AB2-BAB24CBAB3-A26-3(A4-A11-A2-A11-)A4-AB9CBA2-AB8C2BA3-B13A2-13AB2-B13A2-13AB3-2(13A2-13A4-)13A2-13A3-B13A2-13AB2-B13A2-13AB3-13A2-13A4-3A9CA2-A9C3A4-13A2-13A3-B13A2-13AB2-B13A2-13AB3-13A2-13A2(4-28A)3-B28AB2-B28AB3-3A9C4A9C3A2(4-28A)3-B28AB2-B28AB3-2(28A4-)28A3-B28AB2-BAB24CBAB3-A26-3(A4-A11-A2-A11-)A4-AB9CBA2-AB8C2BA3-B13A2-13AB2-B13A2-13AB3-2(13A2-13A4-)13A2-13A3-B13A2-13AB2-B13A2-13AB3-13A2-13A4-5A7BA2-A7B5A4-3A2B8A2-8A2B3A3-B13A2-13AB2-B13A2-13AB3-13A2-13A2(4-28A)3-B28AB2-B28AB3-5A7B4A7B5A4-28A4-3A2B18A2B3A3-B28AB2-B28AB3-2(28A4-)28A3-B28AB2-BA2B22C2BAB3-A26-3(A4-A11-A2-A11-)A4-A2B8CBA2-AB8C2BA3-B13A2-13AB2-B13A2-13AB3-2(13A2-13A4-)2(13A2-)2B13A2-13A4B13A2-13A2B2(2-13A)4-6A6DA2-A6D6A4-3A3D7A2-7A3D3A3-B13A2-13AB2-B13A2-13AB3-13A2-13A2(4-28A)2-2B28A4B28A2B2-6A6D4A6D6A4-28A4-3A3D16A3D3A3-B28AB2-B28AB3-2(28A4-)28A2-2B28A4B2AB8C6B8CB2A2B2-2A24-2A4-2A10-A2-A10-2A5-2(A10-A2-A10-A6-)A3B6CBA2-AB6C3BA4-2B12A2-12A2B2-2B12A2-12A2B4-12A2-12A6-8A-3A2-3A-8A6-8A2(2-2A)2-8A3-3B12A2-12A6B12A2-12A3B3-12A2-12A5-13A2-13A5-12A2-12A4-2B12A2-12A2B2-2B12A2-12A2B4-12A2-12A6-8A2-6A2-8A6-26A3-3B26A6B26A3B3-26A5-28A5-26A4-2B26A2B2-2B26A2B4-2(26A6-)26A3-3B26A6BA3B6CB4AB6C3BA3B3-A10-4A10-A6-3A8-A2-A8-3A7-2A8-A2-A2(8-2A)8-A2-A8-2A7-3AB6CBA2-AB6CB3A4-2B12A2-12A2B2-2B12A2-12A2B4-12A2-12A6-8A-3A2-3A-8A6-5A-3(2A2-)2A-5A3-3B12A2-12A6B4A-7A2-7A-4A3B3-2(12A2-12A6-)12A2-12A4-2B12A2-12A2B2-2B12A2-12A2B4-12A2-12A6-8A2(2-2A)2-8A6-12A2-12A3-3B12A2-12A6B4A-7A2-7A-4A3B3-2(12A2-12A6-)12A2-12A4-2B12A2-12A2B2-2B12A2-12A2B4-2(12A2-12A6-)12A2-12A3-3B12A2-12A6B3AB6CBA2-AB6CB3A3B3-3A8-A2-A8-3A2(8-A)2(2-A8-A10-A8-A)2-A8-A10-AB5C2BA2-A2B5CBA6-4B10A2-10A4B2-4B10A2-10A4B6-2(10A2-10A10-)10A2-10A5-5B10A2-10A10B10A2-10A5B5-2(10A2-10A10-)10A2-10A6-4B10A2-10A4B2-4B10A2-10A4B6-10A2-10A10-7A-2A2-2A-7A10-10A2-10A5-5B10A2-10A10B10A2-10A5B5-2(10A2-10A10-)10A2-10A6-4B10A2-10A4B2-4B10A2-10A4B6-2(10A2-10A10-)10A2-10A5-5B10A2-10A10BA2B4C2BA2-A2B4C2BA5B5-A8-A2-A8-3(A10-A7-2A2-2A7-)A10-AB5CB2A2-2AB5CBA2(6-5B9A2-9A5B2-5B9A2-9A5B6-2(10A2-10A10-)10A2-10A5-6B9A2-9A11B10A2-10A5B5-2(10A2-10A10-)10A2-10A)6-5B9A2-9A5B2-5B9A2-9A5B6-2(10A2-10A10-)10A2-10A5-6B9A2-9A11B2A4BCB2A2-2ABC4B2A5B5-2A6-2A2-2A6-2A3(10-A7-A4-A7-A)10-A3B2C2BA4-A2B2C3BA2(7-4B8A4-8A4B4-4B8A4-8A4B7-2(9A4-9A10-)9A4-9A6-5B8A4-8A5B2-5B8A4-8A5B6-2(9A4-9A10-)9A4-9A)7-4B8A4-8A4B4-4B8A4-8A4B7-2(9A4-9A10-)9A4-9A6-5B8A4-8A5B2-5B4ABCBA4-ABCB4A5B7-4A3-A4-A3-4A11-3(3A2(4-2A)4-3A10-)3A4B2A4-2A4B3A5(11-8A4-8A12-8A4-8A11-2(9A4-9A10-)9A4-9A)11-8A4-8A12-4A3BA4-A3B4A15-A3-A4-A3-A16-17(6A6-6A14-)6A6-6A13-12(8A4-8A12-)8A4-8A15-5A4-5A19(18-2A10-2A)15-11(8A4-8A12-)8A4-8A38-
