model
size = 11 10 14, scale = 0.05, origin = -y
material 
  colors = A:#222 B:#673115 C:#2A2A2A D:#7A7A7A E:#9D9DA3 F:#BB5016
voxels
---AAAAA--- ----------- ----------- ----------- ----------- ----------- ----------- ----------- ----------- ----------- 
---AAAAA--- ---AAAAA--- ----------- ----------- ----------- ----------- ----------- ----------- ----AA----- ----AC----- 
----------- -AAAAAAAAA- -AAAAAAAA-- ----------- ----------- ----------- ----------- ----AA----- ----AA----- ----CC----- 
----------- -AAAAAAAAA- AAAAAAAAAAA --AAAABBBB- ---BBBBBB-- ----AAAA--- ----AAA---- ----AA----- ----AC----- ----------- 
----------- AAAAAAAAAA- AAAAAAAAAAA -AAAAAAAAD- --AAAAAAD-- ---BAAAAD-- ----AAAA--- ----AAA---- ----AC----- ----------- 
----------- -AAAAAAAAA- AAAAAAAAAAA -AAAAAAAAD- --AAAAAAA-- ---BAAAAE-- ----AAAA--- -----AC---- ----------- ----------- 
----------- -AAAAAAAAA- AAAAAAAAAAA -AAAAAAAAA- --AAAAAAE-- ---BAAAE--- -----AC---- ----------- ----------- ----------- 
----------- -AAAAAAAA-- AAAAAAAAAAA --AAAAAAA-- ---AAAAAC-- ----BAAF--- ----------- ----------- ----------- ----------- 
----------- ----------- -AAAAAAAAA- ---AAAAAA-- ----AAAC--- -----BF---- ----------- ----------- ----------- ----------- 
----------- ----------- --AAAAAAA-- ---AAAAA--- ----AAC---- ----------- ----------- ----------- ----------- ----------- 
----------- ----------- ----------- --AAAAAAA-- ----AAC---- ----------- ----------- ----------- ----------- ----------- 
----------- ----------- ----------- ---AAAAA--- ----AAC---- ----------- ----------- ----------- ----------- ----------- 
----------- ----------- ----------- ----------- ----AAA---- ----------- ----------- ----------- ----------- ----------- 
----------- ----------- ----------- ----------- -----A----- ----------- ----------- ----------- ----------- ----------- 
