model
size = 12 15 32, scale = 0.05, origin = -y
material 
  colors = A:#400 B:#111 C:#EEE D:#444 E:#777 F:#555 G:#BBB H:#DDD
voxels
4-5C7-5B7-5A150-7C5-7B5-7A6-5A137-8C4-8B4-8A5-7A136-9C3-9B2(3-9A)4-6A124-10C2-10B2(2-10A)3-8A123-11C-11B2(-11A)2-8A6-4A113-11C-11B2(-11A)2-9A4-5A112-12C12B12A-11A-10A4-6A111-12C12B24A-10A3-7A7-3A101-12C12B24A-10A2-9A5-5A100-12C12B23A-11A2-9A4-6A100-11C-11B3(-11A)2-9A3-8A99-11C-11B3(-11A)2-9A3-9A4-7C87-3C2-C2-3C-11B2(-11A)-10A2-3A5-2A3-9A3-8A87-5C-4C2-10B3(2-10A)2-3A5-2A3-2A5-2A3-8A5-7A75-3C5-2C2-10B3(2-10A)2(2-3A5-2A)3-2A5-A4-8A5-7C63-3C-6C2-10B2-10A2-9AF2-10A2-3A5-AF2(2-3A5-2A)3-2A5-A4-8A5-7A51-4C3-3C2-10B2-10A2-9AF2-10A2-3A5-AF2(2-3A5-2A)2(3-2A5-2A)3-8A5-7C39-3C-6C2-10B2(2-10A)2-9AF2-3A5-AF3(2-3A5-2A)2(3-2A5-2A)3-8A5-2A3E2A5-A2(E-)EA5-A5EA3-3C5-2C2-10B2-10A2-9AF2-10A2-3A5-AF4(2-3A5-2A)2(3-2A5-2A)3-B7AB4-7A5-7A3-5C-4C2-10B2-10A2-9AF2-10A2-2A7-F3(2-CA7-A)2(2-2A7-A)3-A7-A3-B7-B4-2(A5-)7A3-3C2-C2-2C2-10B2-10A2(2-C9A)2(2-CA7-A)2-GA7-A2-HA7-A2-CA7-A2-2A7-A3-A7-A3-B7-B26-11C-11B2(-11A)-C10A2(-CA7-2A)-BA7-2A-2A7-A2-CA7-A2-2A7-A3-A7-A3-B7-B26-11C-11B-11A2(-C10A)4(-CA7-2A)-CA7-A2-2A7-A3-A7-A3-B7-B26-11C-11B2(-11A)-C10A2(-CA7-2A)-BA7-2A-2A7-2A-CA7-2A-2A7-A3-A7-A3-B7-B26-11C-11B-11A2(-C10A)2(-CA7-2A)-GA7-2A-HA7-2A-CA7-2A-2A7-A3-A7-A3-B7-B26-11C-11B3(-11A)-2A3(7-2A-CA)7-2A-2A7-A2-2A7-A3-A7-A3-B7-B26-11C-4B5A2B3(-11A)3(-2A7-2A)-2A7-A2-2A2(7-A3-A)7-A3-B7-B27-9C3-9B3(3-9A)7(3-2A5-2A)3-2B5-2B27-9C3-9B3(3-9A)11(3-3A)3-2A4-3A3-2A5-2B3-2B29-7C5-7B7(5-7A)6-3(5A7-)5B31-5C7-5B2(7-2(AD)A)7-2A2D2(A7-2(AD))A7-5A8-3A33-BDB9-3B29-
