model
size = 31 31 17, scale = 0.05, origin = -y
material 
  colors = A:#939 B:#111 C:#060 D:#FF0
voxels
---------AAAAAAAAAAAAA--------- ---------AAAACAAAAAAAA--------- ---------AAAAACBBAAAAA--------- ---------ABACAACABBAAA--------- ---------BABCAAACAABBA--------- ---------BBAACAAACACCC--------- ---------ABBACBBACCAAA--------- ---------ABBBACABBABAC--------- ---------AABABCAABBAAC--------- ---------AABBACAAAABBC--------- ---------AAABBBCBAAACB--------- ---------AAABABCABBACA--------- ---------BAABBBACABBBA--------- ---------BAAABABCAABAA--------- ---------ABAAABACAAABA--------- ---------ABAAABAACAAAB--------- ---------AABAAABACBAAA--------- ---------AABAAABAACAAA--------- ---------AABAAAAAAABAA--------- ---------AAAADDADDACBA--------- ---------CAAAAADAAACAB--------- --------AACAADDDDDACABA-------- -------AAACAADAAADAACABA------- -------AABACADADADAACAAB------- --------AABCADADADABACA-------- ---------AAAADADADABAC--------- ----------AAAADADAAAB---------- -----------AAAAAAAAA----------- ------------------------------- ------------------------------- ------------------------------- 
-------AA-------------AA------- -------AA-------------AA------- -------BA-------------AA------- -------AB-------------AA------- -------BB-------------AA------- -------AB-------------CC------- -------AA-------------AA------- -------AA-------------AA------- -------AA-------------AA------- -------AA-------------AA------- -------AA-------------BA------- -------AB-------------AA------- -------AA-------------AA------- -------AAA-----------AAA------- -------AAA-----------AAA------- --------AA-----------AB-------- --------AA-----------AB-------- --------AA-----------AA-------- --------AA-----------AA-------- --------CA-----------AA-------- ------BACA-----------AAAA------ -----AAAA-------------AAAA----- -----AAA---------------AAA----- -----AAA---------------AAA----- ------AA---------------BB------ -------AA-------------AA------- --------AAAAAAAAAAAAAAC-------- --------BAAAAAAAAAAABAC-------- -------------CABAA------------- -------------ACBAA------------- -------------ACAAA------------- 
------A-----------------A------ ------B-----------------A------ ------B-----------------A------ ------A-----------------A------ ------A-----------------C------ ------A-----------------C------ ------A-----------------A------ ------A-----------------A------ ------A-----------------C------ ------AA---------------AA------ ------AA---------------AA------ ------AA---------------AA------ ------AA---------------AA------ -------A---------------A------- -------A---------------A------- -------AA-------------AB------- -------AA-------------AB------- -------AA-------------AA------- -------CA-------------AA------- --------A-------------A-------- ---AAA--A-------------A--AAA--- ---AAA-------------------AAA--- ---AAA-------------------AAA--- ---BAA-------------------AAA--- ----BA-------------------AA---- ----ABAA---------------ABAA---- -----ABC---------------AAB----- -------B---------------A------- --------BBAAA-----AAABB-------- ------------A-----A------------ ------------A-----A------------ 
-----A-------------------A----- -----A-------------------A----- -----A-------------------C----- -----A-------------------A----- -----A-------------------A----- -----A-------------------A----- -----A-------------------C----- -----A-------------------A----- -----C-------------------C----- ------C-----------------A------ ------A-----------------A------ ------A-----------------A------ ------B-----------------A------ ------A-----------------A------ ------A-----------------B------ -------A---------------A------- -------A---------------A------- -------A---------------A------- -------A---------------A------- -------A---------------A------- --A----A---------------A----A-- --A-------------------------A-- --B-------------------------A-- --BA-----------------------AA-- --ABA---------------------AAB-- ---AAA-------------------AAA--- ---AAAA-----------------AABA--- ----AAAC---------------AAAA---- ------AA---------------CB------ --------ABBA-------AABA-------- -----------A-------A----------- 
-----A-------------------A----- -----A-------------------A----- -----A-------------------A----- -----A-------------------C----- -----A-------------------A----- -----A-------------------A----- -----C-------------------A----- -----C-------------------C----- -----A-------------------A----- -----AA-----------------AA----- -----AA-----------------AA----- -----BA-----------------AA----- ------A-----------------A------ ------A-----------------A------ ------A-----------------A------ ------AA---------------AA------ ------AA---------------AB------ -------A---------------A------- -------A---------------A------- -------A---------------A------- -A-----A---------------A-----A- -A---------------------------A- -B---------------------------A- -AA-------------------------AA- --AA-----------------------AA-- --AAA---------------------AAB-- --AAAA-------------------AAAA-- ---AAAA-----------------AAAA--- ----AAAA---------------AAAB---- -------AA-------------AA------- ---------ABA-------AAA--------- 
-----A-------------------A----- -----A-------------------A----- -----B-------------------C----- -----C-------------------C----- -----A-------------------A----- -----C-------------------A----- -----A-------------------A----- -----A-------------------C----- -----A-------------------A----- -----B-------------------A----- -----B-------------------A----- -----A-------------------A----- -----A-------------------A----- -----A-------------------A----- -----A-------------------A----- ------A-----------------A------ ------A-----------------A------ ------B-----------------A------ ------A-----------------A------ -------A---------------A------- -B-----A---------------A-----A- -A---------------------------A- -C---------------------------A- -A---------------------------B- -AA-------------------------AA- -AAA-----------------------AAA- --AAA---------------------AAA-- --AAAA-------------------AAAA-- ---AAAA-----------------AAAB--- -----AAA---------------AAA----- --------A-------------A-------- 
-----A-------------------A----- -----B-------------------A----- -----B-------------------A----- -----B-------------------A----- -----B-------------------A----- -----B-------------------A----- -----C-------------------A----- -----A-------------------B----- -----C-------------------A----- -----B-------------------A----- -----A-------------------A----- -----A-------------------A----- -----A-------------------B----- -----A-------------------A----- -----B-------------------A----- -----BA-----------------AA----- -----BA-----------------AB----- ------B-----------------A------ ------A-----------------A------ ------AA---------------AA------ B------A---------------A------A A----------------------------AA C----------------------------AA A----------------------------AB -A--------------------------AA- -AA-------------------------AA- -AAA-----------------------AAA- --AAA---------------------AAA-- ---AAA-------------------AAA--- ----AAAA---------------AAAA---- -------A---------------A------- 
-----A-------------------A----- -----A-------------------A----- -----A-------------------A----- -----A-------------------B----- -----A-------------------A----- -----A-------------------A----- -----A-------------------A----- -----A-------------------B----- -----B-------------------A----- -----A-------------------B----- -----C-------------------A----- -----C-------------------A----- -----B-------------------A----- -----B-------------------A----- -----B-------------------A----- -----AA-----------------AA----- -----BA-----------------AA----- -----AA-----------------AB----- ------A-----------------A------ ------AA----------------A------ B-----AA----------------A-----B A----------------------------AA C----------------------------AA A----------------------------AB A----------------------------AB -A--------------------------AA- -AA-------------------------AA- --AA-----------------------AA-- --AAA---------------------AAA-- ----AA-------------------AA---- ------AA----------------A------ 
-----A-------------------A----- -----A-------------------A----- -----B-------------------A----- -----A-------------------A----- -----A-------------------B----- -----A-------------------B----- -----A-------------------B----- -----B-------------------A----- -----A-------------------B----- -----A-------------------A----- -----C-------------------A----- -----C-------------------B----- -----A-------------------A----- -----A-------------------A----- -----A-------------------A----- -----AA-----------------AA----- -----BA-----------------AA----- -----AA-----------------AA----- -----AA-----------------AC----- -----AAA----------------AC----- A-----AA----------------A-----A B----------------------------AA C----------------------------AA A----------------------------AB A----------------------------AA A----------------------------AB -A--------------------------AB- -AA-------------------------AA- --AA-----------------------AA-- ---AAA-------------------AAA--- ------AA----------------A------ 
-----A-------------------A----- -----A-------------------A----- -----A-------------------A----- -----B-------------------A----- -----A-------------------B----- -----A-------------------A----- -----B-------------------C----- -----A-------------------A----- -----A-------------------A----- -----A-------------------A----- -----A-------------------A----- -----A-------------------A----- -----A-------------------B----- -----C-------------------A----- -----A-------------------A----- -----BA-----------------AA----- -----AA-----------------AA----- -----AA-----------------AA----- ------A-----------------A------ ------AA----------------A------ C-----AA----------------A-----A B----------------------------AB A----------------------------AA A----------------------------AA A----------------------------AA A----------------------------AB -A--------------------------AB- -AA-------------------------AB- --AA-----------------------AA-- ---AAA-------------------AAA--- ------AA----------------A------ 
-----A-------------------A----- -----A-------------------A----- -----A-------------------A----- -----A-------------------A----- -----A-------------------A----- -----C-------------------A----- -----C-------------------A----- -----A-------------------C----- -----C-------------------A----- -----A-------------------B----- -----A-------------------A----- -----A-------------------A----- -----A-------------------A----- -----A-------------------B----- -----C-------------------A----- -----BA-----------------AA----- -----AA-----------------AA----- ------A-----------------A------ ------A-----------------A------ ------AA----------------A------ C------A----------------------A A----------------------------AB A----------------------------AB A----------------------------AB A----------------------------AB -A--------------------------AA- -BA-------------------------AA- --AA-----------------------AB-- --AAA---------------------AAA-- ----AA-------------------AA---- ------AA----------------A------ 
-----A-------------------A----- -----A-------------------A----- -----A-------------------A----- -----B-------------------A----- -----A-------------------A----- -----A-------------------A----- -----B-------------------A----- -----B-------------------A----- -----B-------------------B----- -----B-------------------A----- -----B-------------------A----- -----B-------------------A----- -----B-------------------A----- -----B-------------------A----- -----B-------------------A----- ------A-----------------A------ ------A-----------------A------ ------A-----------------A------ ------A-----------------A------ -------A---------------A------- A------A---------------A------A B----------------------------AA A----------------------------AA A----------------------------AA -B--------------------------AA- -BA-------------------------AA- -AAA-----------------------CAA- --AAA---------------------AAA-- ---AAAA-----------------AAAB--- ----AAAA---------------AAAA---- -------AA--------------A------- 
-----A-------------------A----- -----A-------------------A----- -----A-------------------A----- -----A-------------------A----- -----B-------------------A----- -----A-------------------A----- -----A-------------------A----- -----A-------------------A----- -----A-------------------A----- -----AA-----------------AA----- -----AA-----------------AA----- -----AA-----------------AA----- ------A-----------------A------ ------B-----------------A------ ------B-----------------A------ -------A---------------A------- -------A---------------A------- -------A---------------A------- -------A---------------A------- -------A---------------A------- -A-----A---------------A-----A- -A---------------------------A- -A---------------------------A- -A--------------------------AA- -AA-------------------------AA- -AAA-----------------------AAA- --AAA---------------------CAA-- --AAAA-------------------AAAA-- ---AAAA-----------------AAAB--- -----AAA---------------AAA----- --------A-------------A-------- 
-----A-------------------A----- -----A-------------------A----- -----A-------------------A----- -----A-------------------A----- -----B-------------------A----- -----A-------------------A----- -----A-------------------A----- -----A-------------------A----- -----A-------------------A----- ------A-----------------A------ ------A-----------------A------ ------A-----------------A------ ------A-----------------A------ ------B-----------------A------ ------A-----------------A------ -------A---------------A------- -------A---------------A------- -------A---------------A------- -------A---------------A------- -------A---------------A------- -A-----A---------------A-----A- -A---------------------------A- -A---------------------------B- -AA-------------------------AA- --AA-----------------------AA-- --AAA---------------------AAA-- --AAAA-------------------CAAA-- ---AAAA-----------------AAAA--- ----AAAA---------------AAAA---- -------A---------------A------- --------A-------------A-------- 
------A-----------------A------ ------C-----------------A------ ------C-----------------A------ ------A-----------------A------ ------A-----------------A------ ------A-----------------A------ ------A-----------------A------ ------A-----------------A------ ------A-----------------A------ ------BA---------------AA------ ------AA---------------AA------ ------AA---------------AA------ ------AA---------------AA------ -------B---------------A------- -------A---------------A------- -------A---------------A------- -------A---------------A------- -------A---------------A------- -------A---------------A------- --------A-------------A-------- --A-----A-------------A-----A-- --A----AA-------------AA----B-- --A-------------------------A-- --AA-----------------------AA-- --AAA---------------------AAA-- ---AAA-------------------CAA--- ---AAAA-----------------CAAA--- ----AAAA----------------AAA---- ------AA---------------AA------ --------AA-----------AA-------- ---------AA---------AA--------- 
-------A---------------A------- -------A---------------A------- -------C---------------A------- -------AAAAAAAAAAAAAAAAA------- -------AAAAAAAAAAAAAAAAA------- -------AAAAAAAAAAAAAAAAA------- -------AAAAAAAAAAAAAAAAA------- -------AAAAAAAAAAAAAAAAA------- -------AAAAAAAAAAAAAAAAA------- -------AAAAAAAAAAAAAAAAA------- -------AAAAAAAAAAAAAAAAA------- -------AAAAAAAAAAAAAAAAA------- -------AAAAAAAAAAAAAAAAA------- -------BAAAAAAAAAAAAAAAA------- -------AAAAAAAAAAAAAAAAA------- --------AAAAAAAAAAAAAAA-------- --------AAAAAAAAAAAAAAA-------- --------AAAAAAAAAAAAAAA-------- --------AAAAAAAAAAAAAAA-------- --------AAAAAAAAAAAAAAA-------- ---AACC-AAAAAAAAAAAAAAC-CAAA--- ---AACAAAAAAAAAAAAAAAAACACCA--- ---ACAAAAAAAAAAAAAAAAAAAACAA--- ---ACCAAAAAAAAAAAAAAAAAAAAAA--- ----AAAAAAAAAAAAAAAAAAAAAAA---- ----AAAAAAAAAAAAAAAAAAAACAA---- -----AAAAAAAAAAAAAAAAAAAAA----- -------AAAAAAAAAAAAAAAAA------- --------AAAAAAAAAAAAAAA-------- ---------AAAAAAAAAAAAA--------- ----------AAAAAAAAAAA---------- 
--------ABBBBBBBBAAAAAC-------- --------AAAAACAACAAAAAC-------- --------ABAAAACCCBAAACA-------- --------ABCCCBAACBAAABA-------- --------BAABBAACAACAAAA-------- --------BAAACAACAACABBB-------- --------ACAAABAAAACBAAC-------- --------AAAACBAAACABAAA-------- --------AAACABCAACBBACA-------- --------AACAAABAABBAACA-------- --------ACAAAABABAAACAA-------- --------AAAAAABABAACCAA-------- --------AAAAAABBCCACAAA-------- ---------ACAAABBAACCAA--------- ---------AACABCBAACAAA--------- ---------AACABABAAABAA--------- ---------AAABBAAAABCAA--------- ---------AABCBAAABAAAA--------- ---------ABAABAABAABAA--------- ---------ABAAAAAAAABAC--------- ---------BAAADDADDABAC--------- --------AAAAAAADAAABBCA-------- ------AAAAAAADDDDDABBCCCC------ ------CCAAAAADAAADAAABAAA------ ------AAAAACADADADAAABCAA------ -------AAAACADADADAAABCA------- --------AACAADADADAACAB-------- --------ACABAADADAACAAB-------- ----------AAAAAAACCAA---------- ----------AAABBACAAAA---------- -----------AAAAAAAAA----------- 
