model
size = 12 15 32, scale = 0.05, origin = -y
material 
  colors = A:#EEE
voxels
3-2(5A7-)5A150-2(7A5-)7A6-5A138-3(8A4-)7A136-3(9A3-)9A5-6A124-3(10A2-)10A3-8A122-3(11A-)11A3-8A6-4A112-3(11A-)11A2-9A6-5A111-47A2-10A4-6A111-48A-10A4-7A7-3A100-48A-10A3-9A5-5A99-36A2(-11A)2-9A5-6A99-4(11A-)11A2-9A4-8A98-4(11A-)11A2-9A3-9A5-5A88-3(11A-)11A2-10A2-2A5-3A2-9A4-8A87-5(10A2-)2A5-3A2-2A5-2A4-8A4-7A76-5(10A2-)2A5-3A2-2A5-3A3-A5-2A4-8A4-7A64-5(10A2-)2(2A5-3A2-)2A5-3A3-A5-2A4-8A4-7A52-5(10A2-)3(2A5-3A2-)2A5-2A3-2A5-2A4-8A4-7A40-5(10A2-)4(2A5-3A2-)2A5-2A3-2A5-2A4-8A4-7A5-7A16-5(10A2-)5(2A5-3A2-)2(2A5-2A3-)9A2(4-7A5-7A4-5(10A2-)5(2A5-3A2-)2(2A5-2A3-)2A5-2A)4-3(A5-)A3-5(11A-)2(2A8-A-)2A3(7-2A2-A)2(7-A3-A)7-A26-5(11A-)2(2A8-A-)2A7-2A-2A2(7-2A2-A)2(7-A3-A)2(7-A26-5(11A-)2(2A8-A-)2(2A7-2A-)2A7-2A2-2(A7-A3-)A)7-A26-5(11A-)2(2A8-A-)2A7-2A-2A2(7-2A2-A)2(7-A3-A)7-A26-5(11A-)2(2A7-2A-)2A3(7-2A2-A)2(7-A3-A)7-A27-5(9A3-)7(2A5-2A3-)2A5-2A27-5(9A3-)2(3A4-2A3-)5(3A3-)3(3A4-2A3-)2A29-8(7A5-)7A6-3(5A7-)5A31-7(5A7-)5A8-3A45-3A28-
