model
size = 26 31 9, scale = 0.05, origin = -y
material 
  colors = A:#FFF B:#DFDFDF C:#F6F6F6 D:#C1C1C1 E:#F3F3F3 F:#F9F9F9
voxels
-------------------------- --------AA---------------- ------AAAAAA-------------- ------AAAAAAA------------- ------AAAAAAA------------- ------AAAAAAA------------- -------AAAAA-------------- -------------------------- -------------------------- -------------------------- -------------------------- -------------------AAB---- ------------------AAAB---- -----------------AAAA----- -------------------AAAB--- -------------------AAAB--- -------------------------- -------------------------- -------------------AAA---- ------------------AAAAA--- ------------------AAAAA--- ------------------AAAAA--- -----------------AAAAAA--- -----------------AAAAAA--- ------------------AAAAA--- ------------------AAAAA--- ------------------AAAA---- -------------------AA----- -------------------AA----- -------------------------- -------------------------- 
---AAAAAAAA--------------- --AAAAAA--AAAA------------ --CAAA------AAB----------- --CAAA-------AA----------- --CAAA-------AAB---------- --CAAA-------AAB---------- --CCAAA-----AAB----------- ----BBACAAAAAA-BAA-------- ------BBBBCAA--AAAAB------ ---------------BAAAAB----- ----------------BAAAABB--- ----------------BAA---B--- -----------------B----AB-- ----------------BA---BBB-- ------------------B----AB- ------------------B----B-- -------------------BAAAB-- ------------------AAAAAB-- ------------------B---AB-- ------------------C----B-- -----------------C-----B-- -----------------A-----A-- -----------------B-----A-- -----------------B-----A-- -----------------B-----A-- -----------------B-----A-- -----------------B----AA-- -----------------AA--AAA-- -----------------AA--AAA-- ------------------AAAAA--- -------------------A------ 
-DAAAAAAAAAAA------------- -A-----------AA----------- BC-------------B---------- BA-------------B---------- BA-------------A---------- -B-------------A---------- -B-------------AABF------- --AA----------B---BBA----- --AACCC------AA-----BB---- -------CCABBA-B------ABA-- ---------------B-------B-- ---------------B-------AB- ----------------B-------A- ----------------B-------A- -----------------B-------A ------------------B-----B- ------------------B-----A- ------------------B-----A- ------------------C-----A- -----------------A------A- -----------------A------B- ----------------A-------B- ----------------A-------B- ----------------A-------B- ----------------A-------B- ----------------A-------A- ----------------A-------A- ----------------A-------A- ----------------A------A-- -----------------A-----A-- ------------------AAAAA--- 
-ADDADAAAAAAAA------------ A---DD--------A----------- A---DD---------A---------- A----DD--------B---------- A---DD---------B---------- A---------------BB-------- A-----------------F------- -AA----------------AA----- --AAAAA------A-------AAA-- -------A---AA-A--------A-- --------ACA---C--------A-- ---------------C--------A- ----------------C-------A- ----------------C--------A ----------------CA-------A ------------------C-----A- ------------------C-----A- -----------------C------A- -----------------A------A- -----------------A------A- ----------------A-------A- ----------------A-------A- ----------------A-------A- ----------------A-------A- ----------------A-------A- ----------------A-------A- ----------------A-------A- ----------------A-------A- ----------------A-------A- -----------------A-----A-- ------------------AAAAA--- 
-AD----AAAAAAA------------ CCCD--DCCC----A----------- AADD--ACCC----A----------- AAADD--CCC-----B---------- A-AD--DAAA-----B---------- A-DDDDDAA-------EE-------- AADAADDAA---------FF------ A--AA---A-----------AB---- -AA--A-------A--------AA-- -----AA----AA-A--------A-- ------AA--A---A--------A-- -------AAA-----A--------A- ---------------A--------A- ----------------A--------A ----------------AA-------A ------------------A-----A- ------------------A-----A- -----------------A------A- -----------------A------A- -----------------A------A- ----------------A-------A- ----------------A-------A- ----------------A-------A- ----------------A-------A- ----------------A-------A- ----------------A-------A- ----------------A-------A- ----------------A-------A- ----------------A-------A- -----------------A-----A-- ------------------AAAAA--- 
----------AA-------------- ----------CACC------------ ----------CCA-A----------- ----------AC--A----------- -A--------A---CC---------- AA-------A--A---E--------- AD-------AA------EE------- A----AAD-AA--------FF----- -----A--AAAAAA-------BBA-- -----A----AAA-A--------A-- ------A---A---A--------A-- -------AAA-----A--------A- ----------------A-------A- ----------------A--------A ----------------A--------A -----------------A------A- ------------------A-----A- ------------------A-----A- -----------------A------A- -----------------A------A- -----------------A------A- -----------------A------A- ----------------A-------A- ----------------A-------A- ----------------A-------A- ----------------A-------A- ----------------A-------A- ----------------A-------A- ----------------A-------A- -----------------A-----A-- ------------------AAAAA--- 
-------------------------- -------------------------- -------------A------------ ------------CA------------ -----------AAC------------ ----------AA-AAA---------- -----------AAAAAAE-------- -----AAA---AAAAAAAEE------ -----AAAA-----AA---AEE---- -----AAAAA----AA------BA-- ------AAAA-----A-------B-- ---------------A-------A-- ----------------A-------A- ----------------A--------A -----------------A-------A ------------------A-----A- -------------------A----A- ------------------A-----A- ------------------A-----A- -----------------A------A- -----------------A------A- -----------------A------A- -----------------A------A- ----------------A-------A- ----------------A-------A- ----------------A-------A- ----------------A-------A- ----------------A-------A- -----------------A-----A-- ------------------AAAAA--- --------------------A----- 
-------------------------- -------------------------- -------------------------- -------------------------- -------------------------- -------------------------- -------------------------- -------------------------- ----------------AAA------- ----------------AAAAAE---- ----------------AAAAAAE--- ----------------AAAA--A--- -----------------AA---AA-- -----------------A---AAAA- ------------------AA-----A ------------------AA---AA- -------------------AAAAA-- ------------------BAA-AA-- ------------------AA---A-- ------------------A----A-- -----------------AA----A-- -----------------AA----AA- -----------------AA----AA- -----------------AA----AA- -----------------AA----AA- -----------------AA----AA- -----------------AA---AA-- -----------------AA---AA-- ------------------AAAAA--- -------------------------- -------------------------- 
-------------------------- -------------------------- -------------------------- -------------------------- -------------------------- -------------------------- -------------------------- -------------------------- -------------------------- -------------------------- -------------------------- --------------------AA---- -------------------AAA---- ------------------BAA----- --------------------AAAAA- --------------------BAA--- -------------------------- ---------------------A---- --------------------AAA--- -------------------AAAA--- -------------------AAAA--- -------------------AAAA--- -------------------AAAA--- -------------------AAAA--- -------------------AAAA--- -------------------AAAA--- -------------------AAA---- -------------------AAA---- -------------------------- -------------------------- -------------------------- 
