model
size = 21 31 9, scale = 0.05, origin = -y
material 
  colors = A:#E00 B:#111 C:#FCC D:#222
voxels
--------------------- --------------------- --------------------- --------------------- --------------------- --------------------- --------------------- --------------------- --------------------- --------------------- --------------------- --------------------- --------------------- --------------------- --------------------- --------------------- --------------------- --------------------- --------------------- --------------------- --------------------- --------------------- --------------------- BAAAAAAAAAABBBBBBBBBB BAAAAAAAAAABBBBBBBBBB BAAAAAAAAAABBBBBBBBBB BAAAAAAAAAABBBBBBBBBB BBBBBBBBBBBAAAAAAAAAB BBBBBBBBBBBAAAAAAAAAB BBBBBBBBBBBAAAAAAAAAB --------------------- 
--------------------- --------------------- --------------------- --------------------- --------------------- --------------------- --------------------- --------------------- --------------------- --------------------- --------------------- --------------------- --------------------- --------------------- --------------------- --------------------- --------------------- --------------------- --------------------- --------------------- --------------------- --------------------- BAAAAAAAAAABBBBBBBBBB BAAAAAAAAAAAAAAAAAAAB BAAAAAAAAAAAAAAAAAAAB BAAAAAAAAAAAAAAAAAAAA BAAAAAAAAAAAAAAAAAAAB BAAAAAAAAAAAAAAAAAAAB BAAAAAAAAAAAAAAAAAAAB BAAAAAAAAAAAAAAAAAAAB BBBBBBBBBBBAAAAAAAAAB 
---------CCC--------- ---------CCC--------- ---------CCC--------- --------------------- --------------------- --------------------- --------------------- --------------------- --------------------- --------------------- --------------------- --------------------- --------------------- --------------------- --------------------- --------------------- --------------------- --------------------- --------------------- --------------------- --------------------- --------------------- BAAAAAAAAAABBBBBBBBBB BAAAAAAAAAAAAAAAAAAAB AAAAAAAAAAAAAAAAAAAAA BAAAAAAAAAAAAAAAAAAAA BAAAAAAAAAAAAAAAAAAAA BAAAAAAAAAAAAAAAAAAAB BAAAAAAAAAAAAAAAAAAAB BAAAAAAAAAAAAAAAAAAAB BBBBBBBBBBBAAAAAAAAAB 
--------CBCBC-------- --------CCCCC-------- --------CCCCC-------- ---------DDD--------- ---------CCC--------- ---------DDD--------- ---------CCC--------- ---------DDD--------- ---------CCC--------- ---------DDD--------- ---------CCC--------- ---------CCC--------- ---------CCC--------- ---------CCC--------- ---------CCC--------- ---------CCC--------- ---------CCC--------- ---------CCC--------- ---------CCC--------- ---------CCC--------- ---------CCC--------- ---------CCC--------- BAAAAAAAA---BBBBBBBBB BAAAAAAAAAAAAAAAAAAAB BAAAAAAAAAAAAAAAAAAAB AAAAAAAAAAAAAAAAAAAAA BBAAAAAAAAAAAAAAAAAAB AAAAAAAAAAAAAAAAAAAAB AAAAAAAAAAAAAAAAAAAAA BAAAAAAAAAAAAAAAAAAAB BBBBBBBBBBBAAAAAAAAAB 
---------CCC--------- ---------C-C--------- ---------C-C--------- ---------D-D--------- ---------C-C--------- ---------D-D--------- ---------C-C--------- ---------D-D--------- ---------C-C--------- ---------D-D--------- ---------C-C--------- ---------C-C--------- ---------C-C--------- ---------C-C--------- ---------C-C--------- ---------C-C--------- ---------C-C--------- ---------C-C--------- ---------C-C--------- ---------C-C--------- ---------C-C--------- ---------C-C--------- BBBBBBBBB---BBBBBBBBB BAAAAAAAAAAAAAAAAAAAB BAAAAAAAAAAAAAAAAAAAB ABAAAAAAAAAAAAAAAAAAB BAAAAAAAAAAAAAAAAAABB BAAAAAAAAAAAAAAAAAA-A BAAAAAAAAAAAAAAAAAAAA BAAAAAAAAAAAAAAAAAAAA BBBBBBBBBBBBBBBBBBBBB 
---------CCC--------- ---------CCC--------- ---------CCC--------- ---------DDD--------- ---------CCC--------- ---------DDD--------- ---------CCC--------- ---------DDD--------- ---------CCC--------- ---------DDD--------- ---------CCC--------- ---------CCC--------- ---------CCC--------- ---------CCC--------- ---------CCC--------- ---------CCC--------- ---------CCC--------- ---------CCC--------- ---------CCC--------- ---------CCC--------- ---------CCC--------- ---------CCC--------- BBBBBBBBB---AAAAAAAAB BAAAAAAAAAAAAAAAAAAAB BAAAAAAAAAAAAAAAAAAAB AAAAAAAAAAAAAAAAAAAAA BAAAAAAAAAAAAAAAAAABB AAAAAAAAAAAAAAAAAAAAB AAAAAAAAAAAAAAAAAAAAA BAAAAAAAAAAAAAAAAAAAB BAAAAAAAAABBBBBBBBBBB 
--------------------- --------------------- --------------------- --------------------- --------------------- --------------------- --------------------- --------------------- --------------------- --------------------- --------------------- --------------------- --------------------- --------------------- --------------------- --------------------- --------------------- --------------------- --------------------- --------------------- --------------------- --------------------- BBBBBBBBBBBAAAAAAAAAB BAAAAAAAAAAAAAAAAAAAB AAAAAAAAAAAAAAAAAAAAA BAAAAAAAAAAAAAAAAAAAA BAAAAAAAAAAAAAAAAAAAA BAAAAAAAAAAAAAAAAAAAB BAAAAAAAAAAAAAAAAAAAB BAAAAAAAAAAAAAAAAAAAB BAAAAAAAAABBBBBBBBBBB 
--------------------- --------------------- --------------------- --------------------- --------------------- --------------------- --------------------- --------------------- --------------------- --------------------- --------------------- --------------------- --------------------- --------------------- --------------------- --------------------- --------------------- --------------------- --------------------- --------------------- --------------------- --------------------- BBBBBBBBBBBAAAAAAAAAB BAAAAAAAAAAAAAAAAAAAB BAAAAAAAAAAAAAAAAAAAB BAAAAAAAAAAAAAAAAAAAA BAAAAAAAAAAAAAAAAAAAB BAAAAAAAAAAAAAAAAAAAB BAAAAAAAAAAAAAAAAAAAB BAAAAAAAAAAAAAAAAAAAB BAAAAAAAAABBBBBBBBBBB 
--------------------- --------------------- --------------------- --------------------- --------------------- --------------------- --------------------- --------------------- --------------------- --------------------- --------------------- --------------------- --------------------- --------------------- --------------------- --------------------- --------------------- --------------------- --------------------- --------------------- --------------------- --------------------- --------------------- BBBBBBBBBBBAAAAAAAAAB BBBBBBBBBBBAAAAAAAAAB BBBBBBBBBBBAAAAAAAAAB BBBBBBBBBBBBBBBBBBBBB BAAAAAAAAABBBBBBBBBBB BAAAAAAAAABBBBBBBBBBB BAAAAAAAAABBBBBBBBBBB --------------------- 
