model
size = 32 32 27, scale = 0.05, origin = -y
material 
  colors = A:#E83015 B:#222 C:#FCFAF2 D:#111 E:#FFB11B F:#BDC0BA G:#777
voxels
174-4B28-B2-B28-4B124-4B28-B2-B26-B-4B-B81-2B30-2B7-4B7-2B10-2B5-B-B2-B-B5-2B10-2B4-2B-B2-B-2B4-2B10-2B2(2-6B)3(2-2B10-2B2-2(B-)2B2-2B2(-B))2-2B10-2B2(2-6B)2-2B10-2B6-2B2-2B6-2B10-2B7-4B7-2(2B10-2(2B8-))2(2B10-2B18-)2B83-4A21-5B2-4A2-5B14-3B4-4A4-3B19-8A24-2A4B2A24-2AB2CB2A18-4B2-2A4B2A2-4B12-4B2-8A2-4B18-2(8A24-)2A4B2A19-3B2-2AB2CB2A2-3B14-3B-ABA4BABA-3B18-10A22-10A16-2B4-10A5-B10-2B4-3A4B3A4-2B10-2B4-2(AB)2E2(BA)4-2B10-2B2-2A2BAB2EBA2B2A2-2B10-2B2-6B2E6B3(2-2B10-2B2-2(BE)2B2E2B2(EB))2-2B10-2B2-6B2E6B2-2B10-2B-5A2B2E2B5A-2B10-2B2-2A-3A2B3A-2(2A2-2B10-2B2-2A4-2B4-)2A2-2B10-2B2-2(2A4-)2A2-2(2B10-2B18-)2B19-4A23-14A15-3B6A2B6A3B12-3B6A2B6A3B15-2(4A6B4A18-)4A6B4A14-4B4A6B4A4B10-4B4A6B4A4B14-6A2B6A2(18-4A6B4A)15-3B4A2B2C2B4A3B12-3B4A6B4A3B15-4A6B4A18-6A2B6A14-2B2-4A6B4A2-2B7-4(11A6B11A4-)13A2B13A5(4-11A6B11A)4-13A2B13A5-12A2B12A7-24A10-B2-2(2A4-)2A3-B10-2B18-2B14-14A16-18A12-2B18A2B10-2B18A2B12-2(18A14-)18A11-3B6A6E6A3B8-3B6AE4CE6A3B11-5A2E4C2E2(5A14-5A8C)5A11-3B5A2(2CB)2C5A2B9-3B5A2C4B2C5A2B12-5A8C5A14-5A8C5A12-2B5A2C4B2C5A2B6-11A2C4B5(2C11A2-11A2CB2AB)2C11A2-8A3E2CB2AB2C3B2(8A2-8AE4CB2AB4CB)8A2-8A6B2A6B8A3-28A4-28A5-26A9-B2-2(2A4-)2A3-B10-2B18-2B12-18A14-18A12-2B18A2B10-2B18A2B12-2(2(18A14-)18A11-3B18A3B8-3B18A3B11-)18A14-18A12-2B18A2B5-288A-30A2-30A3-28A4-28A5-26A8-2B2-2(2B4-)2B2-2B12-2A14-2A13-20A11-B20AB10-B20AB11-2(2(20A12-)20A10-2B20A2B8-2B20A2B10-)20A12-20A11-B20AB5-320A-30A2-30A3-28A5-26A8-2(6B2-)6B12-2A14-2A13-4A12B4A11-B20AB10-B20AB11-2(2(20A12-)20A10-2B20A2B8-2B20A2B10-)20A12-20A11-B20AB6-8(30A2-)30A-64A-30A3-28A5-26A7-4B7-2B7-4B11-2A14-2A13-4AB10DB4A2(11-B20AB10-B20AB11-2(20A12-)20A)10-2B20A2B8-2B20A2B10-20A12-20A11-B20AB7-8(28A4-)28A3-30A-32A-30A3-28A5-26A8-6B-8A-6B12-2A14-2A13-4AB10DB4A2(11-B20AB10-B20AB11-2(20A12-)20A)10-2B20A2B8-2B20A2B10-20A12-20A11-B20AB11-5(20B12-)20B10-24A7-26A5-28A3-30A-32A-30A3-28A4-B26AB4-6B4-A6BA4-6B9-2A14-2A13-4AB10DB4A2(11-B20AB10-B20AB11-2(20A12-)20A)10-2B20A2B8-2B20A2B10-20A12-20A11-B19A2B11-4(B18AB12-)20B12-20B10-24A7-26A5-28A3-30A-32A-30A3-28A5-26A7-7B-AB4DBA-7B11-2A14-2A13-4AB10DB4A2(11-B20AB10-B20AB11-2(20A12-)20A)10-2B20A2B8-2B20A2B10-20A12-20A11-B19A2B11-4(B18AB12-)20B12-20B10-24A7-26A5-28A3-30A-32AB30A3B28A2B-2B26A2B3-6B4-AB4DBA4-6B9-2A14-2A13-4AB10DB4A5(12-20A)11-B20AB10-B20AB11-2(20A12-)20A11-B20AB10-B20AB11-20A12-20A11-B19A2B11-4(B18AB12-)20B12-20B10-24A7-26A5-28A3-30A-32A-30A3-28A5-26A7-7B-AB4DBA-7B11-2A14-2A13-4AB10DB4A10(12-20A)11-B20AB10-B20AB11-20A12-20A11-B20AB11-5(20B12-)20B10-24A7-26A5-28A3-30A-32A-30A3-28A4-B26AB4-6B4-A6BA4-6B9-2A14-2A13-4AB10DB4A10(12-20A)2(11-B20A)2(12-20A)11-B20AB7-8(28A4-)28A3-30A-32A-30A3-28A5-26A8-6B-8A-6B12-2A14-2A13-4A12B4A14(12-20A)11-B20AB6-8(30A2-)30A-64A-30A3-28A5-26A7-4B7-2B7-4B11-2A14-2A13-3(20A12-)20A11-4(B20AB10-)B20AB11-5(20A12-)20A11-B20AB5-320A-30A2-30A3-28A5-26A8-2(6B2-)6B12-2(18A14-)18A13-B18AB12-B18AB11-2B18A2B11-2(20A12-)20A11-2B18A2B11-B18AB12-B2(18A14-)18A13-B18AB13-18A12-2B18A2B5-288A-30A2-30A3-28A4-28A5-26A3(8-2B)14-14A16-18A14-18A13-B18AB12-B18AB11-2B18A2B11-2(20A12-)20A11-2B18A2B11-B18AB12-B2(18A14-)18A13-B18AB13-18A12-2B18A2B6-9(30A2-)30A3-28A4-28A5-26A3(8-2B)10-2B18-2B20-2B24-14A18-14A15-3B14A3B12-3B14A3B11-4B14A4B11-2(20A12-)20A11-4B14A4B11-3B14A3B12-3B2(14A18-)14A15-3B14A3B15-14A14-2B2-14A2-2B7-10(28A4-)28A5-26A7-24A9-2(2B8-)2B84-2B29-4B83-5B4-4B4-5B14-2(B4-B2CB4-B18-)B4-4B4-B14-5B12-5B147-4B28-B2CB19-2B7-B2CB7-2B10-2B7-4B7-2B10-2B18-2(2B10-2B2-2A10-2A2-)2B10-2B-G2BG8-G2BG-2B10-2B2-2A10-2A2-2B10-2B2-2A3-4B3-2A2-2B10-2B2-2A3-B2CB3-2A2-2B10-2B-G2BG2-B2CB2-G2BG-2B10-2B2-2A3-4B3-2A2-2B10-2B2-2A4-2B4-2A2-2(2B10-2(2B8-))2B10-2B18-2B115-4B59-2(6B26-)2(2B2C2B26-)6B26-6B122-2(6B26-)2(2B2C2B26-)6B26-6B22-2A10-2A18-2A10-2A17-G2BG8-G2BG17-2(2A2-6B2-2A18-)2A2-2B2C2B2-2A17-G2BG-2B2C2B-G2BG17-2A2-6B2-2A18-2A2-6B2-2A215-4B92-4B2(28-B2CB)28-4B188-4B2(28-B2CB)28-4B55-2(2A10-2A18-)ABG8-GBA18-2A10-2A18-2A3-4B3-2A18-2A3-B2CB3-2A18-ABG2-B2CB2-GBA18-2A3-4B3-2A18-2A10-2A184-2B29-4B29-2B28-2(6B26-)2(2B2C2B26-)6B26-6B28-2(2B30-)2B28-2(6B26-)2(2B2C2B26-)6B26-6B22-2(2A4-2B4-2A18-)ABG3-2B3-GBA2(18-2A2-6B2-2A)18-2A2-2B2C2B2-2A18-ABG-2B2C2B-GBA2(18-2A2-6B2-2A)24-2B158-2B29-4B29-2B28-2(6B26-)2(2B2C2B26-)6B26-6B28-2(2B30-)2B28-2(6B26-)2(2B2C2B26-)6B26-6B22-3(2A4-2B4-2A18-)2(2A2-6B2-2A18-)2(2A2-2B2C2B2-2A18-)2A2-6B2-2A18-2F2-6B2-2F24-2B189-4B59-2(6B26-)2(2B2C2B26-)6B26-6B122-6B19-2A5-6B2(5-2A12-2A5-2B2C2B)5-2A9-2A-2A5-6B5-2A-2A3-2(2A-)2A5-6B5-2(2A-)3(4A3(-2A)10-3(2A-))2(4A3(-2A)2-6B2-3(2A-))2(4A3(-2A)2-2B2C2B2-3(2A-))4A3(-2A)2-6B2-3(2A-)2A3(2F-)2F2-6B2-3(2F-)2F231-2(A16-A14-)A6-4B6-A14-A6-B2CB6-A11-A-2A6-B2CB6-2A-A8-A-2A6-4B6-2A-A8-A-2A16-2A-A5-A2-A-2A16-2A-2(A2-)2(A2(-2A)16-2(2A-)A2-)A2(-2A)16-2(2A-)A2(-2A)-AB6-4B6-2(2A-)4A-2A-AB6-B2CB6-2(2A-)4A-2A-A2B5-B2CB5-2BA-2A-4A-AB-A2B5-4B5-2BA-2A-3A2(B-A)2B14-2BA2(-2A)-4(9BA10-A9B2-)9BA3-4B2(3-A9B2-9BA3-B2CB)3-A9B2-9BA3-4B3-A9B2(10-2F)344-2E30-2E86-3(A16-A14-)A16-A11-A-2A16-2A-A8-A-2A7-2E7-2A-A5-A2-A-2A7-2E7-2A-2(A2-)A2(-2A)16-2(2A-)A3(-2A)16-2(2A-)5(4A3(-2A)10-3(2A-))2(4A3(-2A)4-2E4-3(2A-))4A3(-2A)10-3(2A-)2A3(2F-)2F10-3(2F-)2F128-
