model
size = 28 30 32, scale = 0.05, origin = -y
material 
  colors = A:#555 B:#222 C:#E83015 D:#FFB11B E:#FCFAF2 F:#111 G:#261E47 H:#005CAF
voxels
32-B27-6(2B2-2B3-3B3-2B2-2B7-)2B2-2B3-3B3-2B2-2B11-7(2B3-3B3-2B15-)13B15-13B17-9B272-6B22-6B43-2B2-2B3-3B3-2B2-2B5-8B3D3B3D8B3(3-2(2C2A)3D2AB3D2(2A2C))3-2(2C2A)2(3D2AB3D2A2C2AC5-C2A2C2A)3D2AB3D2A2C2AC5-5C2A3D2AB3D2A5C5-5C2A3D2AB3D2A4C9-5(2C2A3D2AB3D2AC12-)2(2C13AC12-)4C9A3C14-12C16-12C131-6B50-6B21-8B20-8B42-2B2-2B3-3B3-2B2-2B5-25B3(3-C23AC)3-C22A3(C5-C21A)C5-2C18A2C8-7(C16AC10-)C16AC11-2C12A2C12-4C8A4C16-4(8C20-)C6BC22-4C22-8B19-2B6-2B18-2B6-2B11-3(25B3-)C2B18A2BA2(C3-C23A)C3-C22A3(C5-C21A)C5-2C18A2C8-2(C16AC10-)C16AC9-C18A2C7-3(C18AC8-)C18AC9-C16AC10-4C10A4C14-4(C8BC18-)C8BC20-C4BC20-3B4F3B17-2B8-2B16-2B8-2B38-25D3-25B3-C2B18A2BA2(C3-C23A)C3-C22AC4-C22A2(C5-C21A)C5-C20A2C6-3(B18AB8-)C19AC7-3(C18AC8-)C18AC9-C16AC10-4C10A4C14-3(C8BC18-)C8BC17-12B18-C6BC18-3B6F3B15-2B10-2B14-2B10-2B9-3(25B3-)C2B18A2BA2(C3-C23A)C3-C22AC4-C22A2(C5-C21A)C5-C20A2C6-3(B18AB8-)C19AC7-2(C18AC8-)C18AC7-BC18ACB8-C16AC10-4C10A4C14-3(C8BC18-)C8BC17-12B17-C8BC17-2B8F2B15-2B10-2B14-2B10-2B35-28D35B14A7B-6B14A6B4-2(2B18A2B6-)B20AB6-B20AB5-2B20A2B5-B20AB2(6-B19A2B)7-C18A2B7-C19AB7-2(C18AC8-)C18AC7-2B18A2B8-2C14A2C12-2C10A2C16-C3B2E3B3(C18-C8B)C17-12B17-C8BC17-2B8F2B15-2B10-2B14-2B10-2B35-28D35B14A7B-6B14A6B4-2(2B18A2B6-)B20AB6-B20AB5-2B20A2B5-2(B20AB6-)B20A2(B7-C19A)B7-2(C18AC8-)C18AC9-C16AC10-2C14A2C12-2C10A2C16-C3B2E3B3(C18-C8B)2(C17-12B17-C8BC17-2B8F2B15-2B10-2B14-2B10-2B7-91B14A7B-6B14A6B5-B18AB9-D16AD9-C18AC7-B20AB5-2B20A2B5-B20AB7-6(C18AC8-)C18AC9-C16AC10-2C14A2C12-2C10A2C16-3(C8BC18-)C8B)C17-12B18-C6BC18-3B6F3B15-2B10-2B14-2B10-2B35-28D35B14A7B-6B14A6B5-B18AB9-D16AD9-C18AC7-B20AB5-2B20A2B5-B20AB7-6(C18AC8-)C18AC9-C16AC10-2C14A2C12-2C10A2C16-4(C8BC18-)C8BC20-C4BC20-3B4F3B17-2B8-2B16-2B8-2B18-8B10-10D8B10D35B14A7B-6B14A6B5-B18AB9-D16AD9-C18AC7-B20AB5-2B20A2B5-B20AB7-7(C18AC8-)B17AC9-B16A2C9-3B3C8A3C17-4(8C20-)C6BC22-4C22-8B19-2B6-2B18-2B6-2B9-9B-8B-18BD8BD44B14A7B-6B14A6B5-B18AB9-D16AD9-C18AC7-2(B20AB6-)B20AB7-7(C18AC8-)2(B18AB8-)3B14C3B127-6B50-6B21-8B20-8B10-9B-2B4-2B-18BD2B4E2BD44B14A7B-6B14A6B5-B18AB9-D16AD9-9(C18AC8-)C18AC7-B20AB2(6-2B18A2B)6-4BA3C6A3CA4B6-5B3-6B3-5B182-6B22-6B21-2B4-2B10-10D2B4E2B10D36B12A8B-6B14A6B3-2(3B18A3B4-)2B20A2B4-2B5(20AB6-B)19A3(C8-C18A)C7-B20AB7-2(E18AE8-)3EA3C6A3CA3E11-B3-6B3-B19-4C218-2B4-2B10-10D2B4E2B10D36B12A8B-6B14A6B3-2(3B18A3B4-)2B20A2B4-2B5(20AB6-B)19A3(C8-C18A)C7-B20AB7-2(E18AE8-)3EA3C6A3CA3E11-B3-2B2E2B3-B19-C2-C208-9B-2B4-2B-18BD2B4E2BD44B14A7B-6B14A6B5-B18AB9-D16AD9-9(C18AC8-)C18AC7-B20AB7-2(E18AE8-)3EA3C6A3CA3E11-B3-2B2E2B3-B19-C2-C208-9B-8B-18BD8BD44B14A7B-6B14A6B5-B18AB9-D16AD9-9(C18AC8-)C18AC7-B20AB2(6-2B18A2B)6-4BA3C6A3CA4B6-5B3-6B3-5B15-4C218-8B10-10D8B10D35B14A7B-6B14A6B5-B18AB9-D16AD9-11(C18AC8-)2(B18AB8-)3B4C6A4C3B15-6B263-28D36B12A8B-6B14A6B4-2(2B18A2B6-)5(B20AB6-)B19A5(C8-C18A)C2(8-B18AB)8-3B14C3B256-92B12A8B-6B14A6B4-2(2B18A2B6-)5(B20AB6-)B19A5(C8-C18A)C9-C16AC10-2C14A2C12-14C259-91B14A7B-6B14A6B5-B18AB9-C16AD9-2(2C17AC8-)6(2C16A2C8-)C17A2C2(8-C18AC)9-C16AC10-2C14A2C12-14C261-3(24B4-)5B14A5B4-5B14A5B6-4B13A3B9-C17AB10-2(E15AC11-)5(E14AC12-)E14AC11-G15AC11-C16AC10-C16AC11-C14AC13-14C318-22D6-22B7-2(3B14A3B8-)4B13A3B9-C17AB10-E15AC10-G16AC10-7(G15AC11-)2(C16AC10-)B16AB10-2B4C6A4C2B16-6B266-2(22B6-)22B7-2(3B14A3B8-)4B13A3B9-C17AB9-GC15AC10-G16AC11-H14AC11-G15A5(C12-E14A)C11-C16AC9-B18AB8-2B17AB8-3BA3C6A3CA3B8-4B3-6B3-4B16-4C267-22D6-22B7-2(3B14A3B8-)4B13A3B9-C17AB9-GC15AC10-G16AC11-H14AC11-G15A5(C12-E14A)C11-C16AC9-B18AB9-E16AE10-2EA3C6A3CA2E12-B3-2B2E2B3-B19-C2-C239-2(22B6-)22B7-2(3B14A3B8-)4B13A3B9-C17AB10-E15AC10-G16AC10-7(G15AC11-)C16AC9-B18AB9-E16AE10-2EA3C6A3CA2E12-B3-2B2E2B3-B19-C2-C267-22D6-22B7-2(3B14A3B8-)4B13A3B9-C17AB10-2(E15AC11-)5(E14AC12-)E14AC11-G15AC11-C16AC9-B18AB8-2B17AB8-3BA3C6A3CA3B8-4B3-6B3-4B16-4C240-3(20B8-)2(3B14A3B8-)4B13A3B9-C17AB9-8(C16AC10-)2(2C14A2C10-)7C4A7C10-B16CB10-2B14C2B16-6B296-2(18B10-)3(2B3A2C4A2C3A2B10-)2B3A2C4A2C3A2B11-7(B3A2C4A2C3AB12-)B3A2C4A2C3AB13-5C4A5C14-5C4A5C19-4B17-B16-B10-2B14-2B319-5(B2-)B11-18B11-11(2(4B2-)4B12-)2(4B2-)4B18-4B24-4B438-11(2(B2DB2-)B2DB12-)4B2-B2DB2-4B18-4B24-4B404-
