model
size = 18 14 8, scale = 0.05, origin = -y
material 
  colors = A:#FCF B:#0FF C:#001 D:#111 E:#222 F:#0F6 G:#EEE H:#F90 I:#396
voxels
--------GBBG------ ------------------ ------------------ ------------------ ------------------ ------------------ ------------------ ------------------ ------------------ ------------------ ------------------ ------------------ ------------------ ------------------ 
-------B----B----- --------BBBB------ ------------------ -------BBBBBB----- ------------------ -------BBBBBB----- -------BB--BB----- -------BBBBBB----- -------BCFFCB----- -------BFFFFB----- -------BBBBBB----- ------------------ ------------------ ------------------ 
------B------B---- ------BBEEEEBB---- -------BBBBBB----- -------BDDDDB----- --------CGGD------ -------BBBBBB----- -------ABAABA----- -------ABAABA----- -------ACAACA----- -------AHAAHA----- -------AAAAAA----- ------------------ ------------------ ------------------ 
------B-D--D-B---- ------BBEEEEBB---- -------BBAABB----- -------BAAAIB----- -----CCCDDDD------ ----CC-BAABAB----- ---CC--AAAAAA----- --CC---AAAAAA----- -CC----ACAAAA----- CC-----AAAAAA----- C------AAAAAA----- C----------------- ------------------ ------------------ 
------B------B---- ------BBEEEEBB---- -------BBBBBB----- -------BDDDDB----- --------DDDD------ -------BAAAAB----- -------AAAAAA----- -------AAAAAA----- -------AAAAAA----- -------AAAAAA----- -------AAAAAA----- ------AAB--BAA---- ------AB----BA---- ------B------B---- 
------BB----B----- -------BBBBB------ -------BBBBBB----- -------BBBBBB----- ------------------ -------BAAAAB----- -------AAAAAA----- -------AAAAAA----- -------AAAAAA----- -------AAAAAA----- --------AAAA------ ------------------ ------------------ ------------------ 
--------BBBB------ ----------B------- ------------------ ------------------ ------------------ ------------------ --------AAAA------ -------AAAAAA----- -------AAAAAA----- --------AAAA------ ------------------ ------------------ ------------------ ------------------ 
------------------ ----------BB------ -----------BBBB--- --------------BB-- ---------------BB- ----------------B- ----------------B- --------AAAA-----B --------AAAA----B- ------------------ ------------------ ------------------ ------------------ ------------------ 
