model
size = 9 8 27, scale = 0.05, origin = -y
material 
  colors = A:#C39 B:#0CC C:#AAA D:#BBB E:#EEE F:#222 G:#444 H:#500 I:#63F J:#636 K:#D00 L:#800 M:#200 N:#939 O:#A00 P:#639 Q:#400
voxels
--------- --------- --------- --------- --------- --------- ---BBB--- ---CDC--- 
--------- --------- --------- --------- --------- --------- --BBBBB-- --CDCDC-- 
--------- --------- --------- --------- --------- --------- -BBBBBBB- -CDCDCDC- 
--------- AA-----AA AA-----AA AA-----AA --------- --------- -BBBBBBB- -DCDCDCD- 
AA-----AA A-------A A-------A A-------A AA-----AA --------- -BBBBBBB- -CDCDCDC- 
AA-----AA A-------A NCCCCCCCN A--CCC--A AA--C--AA ----C---- -BBFGFBB- -DCDCDCD- 
AA-----AA A-------A A-------A A---C---A AA--C--AA ----C---- -BBCGCBB- -CDCDCDC- 
--------- AA-----AA AA-----AA AA-----AA ----C---- ----C---- -BBFGFBB- -DCDCDCD- 
--------- --------- --------- --------- --------- --------- -BKBKKKB- -CDCDCDC- 
--------- --------- --------- --------- --------- --------- -BOBOBOB- -DCDCDCD- 
--------- --------- --------- --------- --------- --------- -BLLLBLB- -CDCDCDC- 
--------- --------- --------- --------- --------- --------- -BBBBBBB- -DCDCDCD- 
--------- --------- --------- --------- --------- --------- -BHHHHHB- -CDCDCDC- 
--------- --------- --------- --------- --------- --------- -BBBQBBB- -DCDCDCD- 
--------- --------- --------- --------- --------- --------- -BMMBMMB- -CDCDCDC- 
--------- --------- --------- --------- --------- --------- -BBBBBBB- -DCDCDCD- 
--------- --------- --------- --------- --------- --------- -BIIIIIB- -EEEEEEE- 
--------- --------- --------- --------- --------- --------- -BPBPBPB- -EEEEEEE- 
--------- --------- --------- --------- --------- --------- -BJJJJJB- -EEEEEEE- 
--------- AA-----AA AA-----AA AA-----AA ----C---- ----C---- -BBFGFBB- -EEEEEEE- 
AA-----AA A-------A A-------A A---C---A AA--C--AA ----C---- -BBCGCBB- -CDCDCDC- 
AA-----AA A-------A NCCCCCCCN A--CCC--A AA--C--AA ----C---- -BBFGFBB- -DCDCDCD- 
AA-----AA A-------A A-------A A-------A AA-----AA --------- -BBBBBBB- -CDCDCDC- 
--------- AA-----AA AA-----AA AA-----AA --------- --------- -BBBBBBB- -DCDCDCD- 
--------- --------- --------- --------- --------- --------- -BBBBBBB- -CDCDCDC- 
--------- --------- --------- --------- --------- --------- --BBBBB-- --CDCDC-- 
--------- --------- --------- --------- --------- --------- ---BBB--- ---CDC--- 
