model
size = 16 6 11, scale = 0.05, origin = -y
material 
  colors = A:#000308 B:#4B4B4B C:#646464 D:#07121E E:#0E2338
voxels
-AAAAA----AAAAA- AAAAAAA--AAAAAAA AAAAAAA--AAAAAAA AAAAAAA--AAAAAAA AAAAAAAAAAAAAAAA --AADDEEEDDDAA-- 
---------------- ---------------- ---------------- ---------------- C--------------C ---------------- 
---------------- ---------------- ---------------- ---------------- C--------------C ---------------- 
---------------- ---------------- ---------------- ---------------- C--------------C ---------------- 
---------------- ---------------- ---------------- ---------------- B--------------B ---------------- 
---------------- ---------------- ---------------- ---------------- B--------------B ---------------- 
---------------- ---------------- ---------------- ---------------- B--------------B ---------------- 
---------------- ---------------- ---------------- ---------------- B--------------B ---------------- 
---------------- ---------------- ---------------- ---------------- B--------------B ---------------- 
---------------- ---------------- ---------------- B--------------B B--------------B ---------------- 
---------------- B--------------B B--------------B B--------------B ---------------- ---------------- 
