model
size = 31 32 17, scale = 0.05, origin = -y
material 
  colors = A:#222 B:#609 C:#F60 D:#111 E:#FFF F:#EEE G:#444 H:#FC9
voxels
9-2(5D2CG5D18-5DCGC5D18-)5D2CG5D18-5DC2G5D2(18-2B3D3G3D2B)18-4B5G4B18-2B2DB3HB2D2B18-B4D3H4DB2(18-2D2C5D2C2D)18-B5DG5DB18-2B4DG4D2B18-2B2H5D2H2B18-2B3H3D3H2B18-B11FB2(18-F8DC2DF)18-B11FB17-A13BA15-B2A11B2AB14-B3A9B3AB15-7A-7A17-5A3-5A202-2(2(2A13-2A14-)2(CA13-AC14-)2(BA13-AB14-))2A13-2A14-3A11-3A14-C2A11-2AC15-4(2A11-2A16-)2A11-2A14-2C2A11-2A2C11-3CA13-4C10-3B15-A2B10-3B15-3B11-2A15-2(2A13-)2A15-6C3-6C16-5C5-5C138-2(A17-A12-)2(C17-C12-)2(B17-B12-)2(A17-A12-)C17-C12-2C15-2C2(12-2B15-2B)12-2A15-2A13-A15-A14-C15-C14-CA13-AC2(14-BA13-AB)14-2A13-2A15-A13-A11-3C2-C13-C2-3C6-3C19-A2C2(6-3B19-3B)7-2A19-2A8-4A15-4A9-3C15-3C12-2(C15-)5B5-5B106-2(A19-A10-)2(C19-C10-)2(B19-B10-)2(A19-A10-)C19-C11-C17-C2(12-B17-B)2(12-A17-A)12-C17-C13-C15-C2(14-B15-B)2(14-A15-A)9-C4-C15-2(C4-)C25-C4-B25-B4-2B23-2B4-3A21-3A5-3A19-3A6-4C17-4C7-4C15-4C10-2B15-2B14-4B7-4B75-2(A19-A10-)2(C19-C10-)2(B19-B10-)2(A19-A10-)C19-C10-2C17-2C2(10-2B17-2B)11-2(A17-A12-)C17-C12-2C15-2C12-2B15-2B13-B15-B2(14-A15-A)8-C5-C15-C5-C2-C27-C2-B27-B2-2B25-2B3-2A23-2A4-3A21-3A4-4C19-4C5-4C17-4C7-3BA15-4B11-2B13-2B16-3A7-3A45-2(2(A19-A10-)2(C19-C10-)2(B19-B10-))2(A19-A10-)C19-C11-C17-C2(12-B17-B)12-A17-A13-A15-A8-C5-C15-C5-C2-C27-C2(2-B27-B)2-2A25-2A2-3A23-3A3-C2A21-2AC4-C3A19-3AC5-4B17-4B8-3B15-3B2(13-A)17-2A9-2A14-2(2(A19-A10-)2(C19-C10-)2(B19-B10-))2(A19-A10-)C19-C10-2C17-2C10-2B17-2B11-B17-B12-A17-A12-2A15-2A2(6-C)15-C6-2C28-2CB28-3B28-2B-A26-2A2-2A25-2A2-2CA23-A2C3-C2A21-2AC5-3B19-3B7-3BA15-4B11-2(A15-)2(A13-)2(2(A19-A10-)2(C19-C10-)2(B19-B10-))2(A19-A10-)C19-C10-2C17-2C2(10-2B17-2B)11-A17-A12-2A15-2A6-C5-2C15-2C5-2C28-2CB28-3B28-2BA28-2A-A26-2A2-2C25-2C3-CA23-AC4-3B21-3B6-2B19-2B10-2A15-2A14-2(A13-)2(2(A19-A10-)2(C19-C10-)2(B19-B10-))2(A19-A10-)C19-C10-2C17-2C2(10-2B17-2B)10-2A17-2A10-3A15-3A5-C5-2C15-2C5-2C28-2CB28-3B28-2BA28-3A28-2A-C26-2C2-2C25-2C3-2B23-2B5-3B19-3B9-2A15-2A14-2(A13-)2(2(A19-A10-)2(C19-C10-)2(B19-B10-))2(A19-A10-)C19-C10-2C17-2C2(10-2B17-2B)11-A17-A12-2A15-2A6-C5-2C15-2C5-2C28-2CB28-3B28-2BA28-3A28-2A-C26-2C2-2C25-2C3-2B23-2B5-3B19-3B9-2A15-2A14-2(A13-)2(2(A19-A10-)2(C19-C10-)2(B19-B10-))2(A19-A10-)C19-C10-2C17-2C10-2B17-2B11-B17-B12-A17-A12-2A15-2A2(6-C)15-C6-2C28-2CB28-3B28-2BA28-2A-A26-2A2-2C25-2C3-CA23-AC4-3B21-3B6-2B19-2B10-2A15-2A14-2(A13-)2(2(A19-A10-)2(C19-C10-)2(B19-B10-))2(A19-A10-)C19-C11-C17-C2(12-B17-B)12-A17-A13-A15-A7-C6-C15-C6-2C28-2CB28-3B28-2B-A26-2A2-2A25-2A2-2CA23-A2C3-C2A21-2AC5-3BA17-4B7-3BA15-4B11-2A14-A15-2(A13-)2(A19-A10-)2(C19-C10-)2(B19-B10-)2(A19-A10-)C19-C10-2C17-2C2(10-2B17-2B)11-2(A17-A12-)C17-C13-C15-C2(14-B15-B)2(14-A15-A)8-C5-C15-C5-C2-C27-C2-B27-B2-B26-2B2-2A25-2A2-3A23-3A3-C2A21-2AC4-C3A19-3AC5-3BA17-4B8-3B15-3B2(13-A)17-A11-A14-2(A19-A10-)2(C19-C10-)2(B19-B10-)2(A19-A10-)C19-C11-C17-C2(12-B17-B)2(12-A17-A)12-C17-C13-C15-C2(14-B15-B)2(14-A15-A)8-C5-C15-C5-C2-C27-C2-B27-B2-2B25-2B3-2A23-2A4-3A21-3A4-3CA19-3AC5-3CA17-3AC7-3BA15-4B11-2(B15-)A13-A17-2A9-2A15-2(A17-A12-)2(C17-C12-)2(B17-B12-)2(A17-A12-)C17-C12-2C15-2C2(12-2B15-AB)12-2A15-2A13-A15-A2(14-C15-C)2(14-B15-B)14-2(A15-)A13-A10-C5-C13-C5-2(C4-)CA13-2C4-C4-B25-B4-2B23-2B4-3A21-3A5-3A19-3A6-3CA17-2A2C7-3CA16-3C10-2B15-2B14-BA11-AB17-2A9-2A20-A7-A18-2(A15-A14-)C15-C14-17C2(14-17B)2(14-17A)2(14-17C)2(14-17B)2(14-17A)14-17C15-15C2(16-15B)2(16-15A)11-4C-15C-4C6-25C2(6-4B14A7B)7-23A8-23A9-3C15A3C12-C15AC15-2B11A2B17-B11AB19-11A22-7A20-2(2(15A16-)2(15C16-)2(15B16-))15A17-13A2(18-13C)2(18-13B)2(18-13A)18-13C17-15C14-4B2(3EB)3E4B12-5BE2BEBE2BE5B12-5AE2AEAE2AE5A13-4AE2AEAE2AE4A15-3C2EC3E2C2E2C16-15C18-11B20-11B21-9A42-
