model
size = 20 32 19, scale = 0.05, origin = -y
material 
  colors = A:#FFC635 B:#876522 C:#111 D:#D9AB42 E:#A92B46 F:#882429 G:#CB2F53 H:#FFF
voxels
147-3A3B13-4A4B11-6A4B10-3AB3A3B10-6A4B10-5A5B10-4A6B11-2A3BA2B12-3A5B13-3A3B15-2A2B414-4A4B11-4A2-4B9-5A2-5B8-4A-4(A6B8-3A2-)A6B2(8-6A2-4B)9-5A-4B10-4A2-4B2(10-5A5B)10-2A6F2B10-A8EB10-AGH4GHGB11-4A4B12-3CAB3C12-CHCABCHC13-2CAB2C213-3A2-3B11-A2D2A5B9-3A6-3B8-2A8-2B7-3A3-3(2A6B6-2A4-)2A6B6-3A3-2A6B7-2(2A2-2A4-2B8-)3A-2A3-4(3B8-3A6-)A2B8-3A6-A3(2B8-4A4-2A)2B9-4A2-3AB10-AC2A2-2ACB11-4A4B170-5A2-5B8-6A6B7-4A6-4B6-3A8-3B6-2A10-2B6-2A4-2A6B3(6-A5-2A4B-B)6-2A4-2A6B3(6-2A3-2A5-2B)6-2A10-2B7-7(2A8-2B8-)3A6-A2B8-4A3-3A2B9-4A2-4B11-4A4B88-5A6-5B4-6A4-6B4-7A2-7B4-8A8B2(4-3A10-3B)2(4-2A12-2B)5(4-2A5-2A4B-2B)2(4-2A)6-2B5-2(A4-2A6-B6-)8(2A10-2B6-)2A10-2B7-2A8-2B8-3A5-4B9-4A2-4B11-4A4B48-5A6-5B3-7A4-7B2-2A3-3A2-3B3-2B2-2A4-3A3B4-2B2-2A14-2B3-3(A14-B4-)A7-3A4-5(B4-A6-6A2-)3(B2(4-2A)6-A)2(B4-2A12-A)B4(4-2A12-2B)5-2(A12-B6-)2(2A10-2B6-)3A8-A2B6-4A6-4B6-C6A6BC44-7A4-2B3C2B2-2A3-3A2-3B3-2B2-A-7A3B5-B2-A-7A-B6-B2(2-5A2D2A7-2B)3-2(4A2D2A7-B4-)8A7-5(B4-13A2-)2(B4-8A7-)B2(4-2A)7-5(B4-A14-)B4-2A12-AB4(4-2A12-2B)4-2A12-AB3-2CA12-A2C-B2C6A2-4B2A2C3B3C2-3A3B2-3C5B14-3B-7A4-2BC4B2-A5-2A2-2B5-B2-A-7A2B6-B2-A-7A8-B2-A-3A2D2A8-B3(2-5A2D2A7-2B)2-9A7-4(2B2-14A2-)2B3-13A2-2(B4-8A7-)B4-A5-2A7-10(B4-A14-)B3-CA14-AC2-CA14-AC-B2A-4A4-3BA-2A2B2A2C2-3A3B2-2C2A4B14-3B-7A4-2B3C2B2-A5-2A2-2B5-B2-A-7A2B6-3(B2-A-D6A8-)B2-A-7A8-B2-9A7-2B2-A-7A8-3(B2-A-12A3-)B2(2-14A2-2B)3-2(8A7-B4-)A5-2A7-10(B4-A14-)B3-CA14-AC2-CA14-AC-B2A-3A6-2BA-2A2B2A2C2-3A3B2-2C2A4B14-3B-7A4-4BC2B2-A5-2A2-2B5-B2-A-2D5A2B6-2(B2-A-D6A8-)B2-2AD6A3(7-2B2-9A)7-4(2B2-14A2-)2B3-13A2-2(B4-8A7-)B4-A5-2A7-11(B4-A14-)B3-C2A12-2AC-B2C5A4-3B2A2C3B3C2-3A3B2-3C5B14-3B-7A4-2B3C2B2-2A4-2A2-2B4-2B2-A-2D5A3B5-B2-A-D6A2B6-B2-2AD6A7-2B2-2A7D7-2B3-3(8A7-B4-)5(13A2-B4-)2(8A7-B4-)A5-2A7-7(B4-A14-)B3(4-2A12-2B)4-3A10-3B4-4A8-4B5-4AB4-5B10-3A3B29-6A4-6B2(3-2A)4-2B3-2B2-2A2D5A3B4-2B2-2AD4A2D-B5-2B2-2AD4A2D7-2B3-A7D7-B2(4-A7D6-2B)4-8A7-5(B4-13A2-)B2(4-8A6-2B)2(4-2A)6-8(2B4-2A12-)2B5-A12-B6-2A10-2B6-3A8-3B7-3A6-3B9-2AB4-3B12-3A3B29-5A6-5B4-6A4-6B4-8A4B2-2B4-8A-3B2-5(2B4-8A6-)5(2B4-13A-)2B4-8A6-2B5-7A6-B6-A4-2A6-B6-A12-B3(6-2A10-2B)3(6-A12-B)3(6-2A10-2B)7-2A8-2B9-2A6-2B11-AB-B2-2B13-3A3B50-2(4A6-4B6-)7A7B2(6-6A2-6B)6-3A8-3B2(6-2A10-2B)2(6-2A4-A2B3A2B)2(6-A5-A2B3A-B)6-2A4-A2B3A3(2B6-2A3-2A5-)2(2B6-2A10-)2B7-A10-B7-4(2A10-2B6-)2A10-2B7-2(2A8-2B8-)3A6-3B9-2A6-2B11-AB4-2B13-3A3B115-2A2B13-5A5B9-6A6B8-4A4-4B8-3A6-3B8-2A8-2B7-3A8-3B2(6-2A10-2B)6-3A8-3B7-3(2A2-2A4-2B8-)8(3A6-3B8-)3A6-3B9-2A6-2B10-2A6-2B11-A6-B12-AB2(-2B)13-3A3B15-2A2B135-3A3B13-4A4B11-4A2-4B10-3A4-3B9-3(3A6-3B8-)3A6-3B9-2(5A2-3B10-)5A-4B10-4A2-4B11-5(4A4B12-)2(2AB2-3B12-)A2B2-3B3(12-AB4-2B)12-AB-B2-2B13-3A3B15-2A2B175-3A3B13-5(4A4B12-)4A4B13-3A3B14-3A3B15-2A2B116-2A2B16-2A2B15-3A3B14-2A2-AB14-3A-A2(B14-A-A2-)B14-3A3B15-2A2B536-2A2B15-3(3A3B14-)3A3B15-2A2B576-3(2A2B16-)2A2B8-
