model
size = 29 31 32, scale = 0.05, origin = -y
material 
  colors = A:#E00 B:#FC9 C:#400 D:#222 E:#FFF F:#06F G:#D00 H:#500
voxels
216-3B26-3B24-7B22-7B23-5B750-3B24-2B3-2B21-3B3-3B2(20-B7-B)20-2B5-2B22-5B225-9A21-7A459-3B24-2B3-2B21-3(B7-B20-)B7-B21-7B193-3A7-3A16-2A-7A-2A18-9A458-3B24-2B3-2B21-3(B7-B20-)B7-B21-7B191-7A3-7A13-2(3A3-)3A17-9A458-3B24-2B3-2B21-3(B7-B20-)B7-B21-7B162-A15-A12-17A12-3A11-3A15-11A428-3D24-2B3-2B2(22-B5-B)21-2(B7-B20-)B7-B21-7B161-2A14-3A10-A-14A2-A2(11-3A)15-4A3-4A22-3A346-B28-D25-3D-3D20-3(2D7-2D18-)D9-D19-B7-B21-B5-B23-5B162-3A13-3A10-A2-13A2-A2(11-3A)15-2A7-2A20-7A314-3B23-4B-4B20-4D-4D20-D7-D19-4(D9-D18-)2B7-2B20-2B3-2B24-B-B4(26-3B)17-2A7-3B7-2A8-A-3A5-B5-3A-A9-A3-5A-5A3-A11-2A13-2A14-2A9-2A18-A7-A21-7E22-EG3EGE22-3(EG)E2(22-2EGEG2E)22-7E110-5B22-3B3-3B19-B9-B18-B9-B17-BD9-DB16-B11-B3(16-D11-D)16-DB9-BD18-B7-B20-3B3-3B2(20-F2D3-2DF)20-3F3-3F20-3E3-3E14-2A4-2BH3-H2B4-2A8-A-3A-2H2B-2B2H-3A-2(A9-A3-)A11-2A13-2A14-A11-A16-2A9-2A4(16-3A7-3A)17-2A7-2A18-2A7-2A20-7A80-7B21-B7-B19-B9-B17-B11-B15-B13-B14-2(B13-)2B13-2B2(12-2D13-2D)13-2D11-2D16-5(B9-B18-)B9-B13-2A3-B9-B3-2A8-A-3AB9-4B-A9-A17-A11-A15-2(A13-)2(A14-A13-)A2(13-2A)12-2(2A13-)A13-A15-A11-A17-A9-A19-3A3-3A23-3A25-5B22-2B5-2B19-B9-B16-2B11-2(2B13-)2B12-B15-B11-2B15-2B3(10-B17-B)10-BD15-DB2(11-3B)13-3(2B11-2B14-)2B11-2B13-3B11-3B10-A4B11-3B2A8-A19-A9-A17-A11-A15-A11-3(2A15-2A10-)A17-A10-A17-A11-A15-2(A13-)A15-A11-A17-A9-A19-9A22-5B22-2B5-2B18-2B9-2B14-2B13-2B12-B15-B11-7(B17-B10-)2B15-2B10-2B15-2B11-B15-B11-2B15-2B9-2B17-2B2(8-A19-A)9-A17-A10-A17-A9-3(A19-A8-)A19-A9-A17-A10-A17-A11-A15-A12-2A13-2A14-2A9-2A18-9A22-5B21-3B5-3B16-2B11-2B13-B15-B11-2(B17-B10-)B17-B9-2(B19-B8-)B19-B9-5(B17-B10-)B17-B9-B19-B4(8-A19-A)7-2(A21-A6-)A21-A7-A19-A8-A19-A9-A17-A10-A17-A11-2A13-2A14-2A9-2A18-9A22-5B21-3B5-3B16-2B11-2B13-B15-B11-2(B17-B10-)B17-B9-5(B19-B8-)B19-B9-2(B17-B10-)B17-B9-B19-B2(8-A19-A)7-A21-A5-2A21-3(A5-A22-)A6-A21-A7-A19-A9-A17-A10-A17-A11-2A13-2A14-3A7-3A19-7A23-5B21-3B5-3B16-2B11-2B13-B15-B11-B17-B10-B17-B9-10(B19-B8-)B19-B7-A21-A6-A21-A5-A22-A5-3(A23-A4-)A22-A6-A21-A7-A19-A8-A19-A9-A17-A11-2A13-2A14-3A7-3A19-7A24-3B22-4B3-4B16-2B11-2B13-B15-B11-B17-B10-B17-B9-3(B19-B8-)B19-B7-5(C21-C6-)2(C21-C5-A)22-A5-5(A23-A4-)A22-2(A6-A21-)A7-A19-A9-A17-A11-2A13-2A14-3A7-3A19-7A50-9B17-3B9-3B13-B15-B11-B17-B10-B17-B9-3(B19-B8-)B19-B7-4(C21-C6-)C21-C5-A22-C5-A23-A4-A23-A3-2(A25-A2-)A25-A3-2(A23-A4-)A22-2(A6-A21-)A7-2A17-2A10-A15-A13-2A11-2A16-5A-5A23-A54-7B19-3B7-3B14-2B13-2B12-B15-B11-B17-B9-4(B19-B8-)B19-B7-3(C21-C6-)C21-C5-A23-A3-4(A25-A2-)A25-A3-2(A23-A4-)A22-A6-A21-A7-A19-A9-A17-A11-2A13-2A14-2A9-2A18-9A81-3B21-5B3-5B14-2B13-2B12-B15-B11-B17-B8-CB19-2B6-C21-B4(6-C21-C)3(5-C22-C)5-A23-A3-4(A25-A2-)A25-A3-2(A23-A4-)A22-A6-2A19-2A8-A17-A11-2A13-2A14-A11-A17-11A110-B22-6B-6B15-B13-B14-2(B13-)B15-B8-C3B17-3B5-3(C23-B4-)C22-B5-C22-B4-2(B24-2B2-)A24-2B3-A23-A3-5(A25-A2-)A25-A3-A23-A4-2A21-A7-A19-A9-A17-A11-2A13-2A14-3A7-3A18-9A136-9B18-2B9-2B16-B11-B15-2(B13-)B15-B7-5B17-5B2(2-B25-B)-2B24-5B24-4B2(27-2B)A25-AB2-A23-A3-5(A25-A2-)A24-2A3-A22-A6-A21-A7-2A17-2A10-2A13-2A14-3A7-3A19-7A168-5B21-3B5-3B17-B11-B14-2B13-2B11-B17-B6-4B19-4B2-4B19-4B-B-3B19-3B-2(2B3-B19-B3-)2B2-B24-2B-2C21-2C-2B2A23-2AB2-A22-A4-A24-2A3(2-A25-A)3-A23-A4-A23-A5-A21-A7-A19-A9-2A15-2A12-2A11-2A16-11A197-B22-C5B-6B14-2C13-2C11-3(C17-C10-)C17-C5-2B3-C17-C3-6B-C17-C-8B-C17-C-7B-C19-C5BC2-C19-C2-2B3-A21-A5-A22-A5-4(A23-A4-)A23-A5-A21-A7-A19-A9-A17-A11-2A13-2A14-13A245-5C11B3C8(10-C17-C)9-C19-C8-C19-C7-A21-5(A5-A22-)A5-2A21-A7-A19-A9-A17-A10-2A15-2A12-3A9-3A17-9A247-5C11B3C10-C17-C9-C19-C8-C19-C9-C17-C11-C15-C12-C15-C11-2(C17-C10-)C18-C8-C19-C7-3(A21-A6-)A21-A5-A22-A5-2A21-A7-A19-A9-A17-A11-2(2A13-)2A11-2A16-11A276-4C4B-3B5C11-4C5-B5-4C9-2C17-2C8-2C17-2C9-C17-C11-2(2C13-2C12-)C15-C12-C15-C11-C17-C9-A19-A7-4(A21-A6-)A21-A7-A19-A9-A17-A2(11-3A)14-13A17-11A309-4C-4C19-C3-C-C3-C15-3C5-C5-2(3C12-3C11-)3C14-C11-C16-C11-C15-2(C13-)2C13-2C11-C17-C10-A17-A9-4(A19-A8-)A19-A9-A17-A2(11-3A)15-11A367-4C-4C19-2(C3-C-C3-C18-)2(C4-)C18-C9-C18-11C18-C9-C17-C11-C16-C11-C14-CA13-AC12-A15-A11-A17-A10-A17-A9-A19-A9-A17-A10-A17-A2(11-3A)15-4A3-4A22-3A371-4C-4C19-5C-5C18-C3-C-C3-C18-3C2(-C)-3C18-11C47-11C18-C9-C17-C11-C15-2(A13-)A15-A12-A15-A11-2(A17-A10-)A17-A11-A15-A13-3A9-3A17-9A455-4C-4C22-2C-2C109-9C19-11C17-A11-A15-2A11-2A14-2(A13-)2(2A13-2A12-)2(2A13-)A13-A15-6A-6A22-A661-11A18-4A3-4A17-4A5-4A2(16-2A9-2A)2(16-3A7-3A)18-9A719-3A25-5A22-9A20-9A21-7A22-7A24-3A332-
