model
size = 22 31 15, scale = 0.05, origin = -y
material 
  colors = A:#4F1869 B:#4C1566 C:#97E2A7 D:#87EB95
voxels
---------------------- ---------------------- ---------------------- ---------------------- ---------------------- ----------AB---------- ---------AABB--------- ---------ABBB--------- ---------BBAA--------- --------BAABAA-------- --------BBABAA-------- --------BABBBA-------- -------BBBAAAAB------- ------BAABAAABAB------ ------ABBAAABBAA------ ------BABBBAABAA------ ------ABABABBBBB------ -------ABABAAAB------- --------ABBBBB-------- --------BAAAAA-------- ---------ABAB--------- ---------------------- ---------------------- ---------------------- ---------------------- ---------------------- ---------------------- ---------------------- ---------------------- ---------------------- ---------------------- 
---------------------- ----------BB---------- ---------BBBA--------- --------ABABAB-------- -------BAAAAABB------- ------ABBAABBBBA------ ------ABAABAABAB------ ------BAABABBAAB------ -----AAABBBABBBAA----- -----BBABBABABABA----- ----BABBAABBBABBBB---- ----BBBAAAAABBAABB---- ----AABAABBBABAABA---- ----BABBBBAAAAABBA---- ---BBBABAABBAAAABAA--- ---AABAAAAAAABBBAAB--- ---ABAABABAAABBBBBA--- ---BBABABABAAAAAAAA--- ---BBAABBBBAAAABABB--- ----ABBAABBABAABAA---- -----BABBBBBBABBA----- ------ABBBABABAA------ -------BBA--BBB------- ---------------------- ---------------------- ---------------------- ---------------------- ---------------------- ---------------------- ---------------------- ---------------------- 
---------CDCC--------- --------AABBBA-------- -------BBBABBAB------- ------BAAAAAABBA------ -----BBBAAABABABA----- ----AAABBBBAAABABB---- ---AABABABBABABABBA--- ---BAAABBABBBBAAAAA--- ---ABABAAAAAAABBBAA--- ---BABAAAABABBBBABB--- --BAAABABBAABBAAAABA-- --AABBAAABAAABABAAAA-- --BBAABABAAAAABBABBA-- -ABABBBBBBBBBBABAAABB- -ABBABBBBAAABBBAAAABA- -ABBBAABBABABBBABBABB- -AABAAABBAABBBAAAABBA- -ABABABAABABBAABBABBB- AAAAABBABAABABBAAAAAAA BABBBAABBBBBBBABBBABBB ABAABBABBBABAAAAAABBBB -BAAABAABAAABBAAAAABB- --BBAABBBBBBBAABAAAA-- ---ABBBAAB--ABBABAB--- ---BBBAA------BABAB--- ---------------------- ---------------------- ---------------------- ---------------------- ---------------------- ---------------------- 
----DCDDDDDCCCDCDD---- ----BBBABBBBABAABA---- ----AABABAABBAABBB---- ----BBAAABAABBAAAB---- ---BABAAABBBABAABBB--- ---AABBAABAABBAAABA--- ---ABBAAABAABBAAAAB--- ---AABBAAABBBBBABAA--- --AAAABABBABBAABAABB-- --BBAAABBAAABAABBBBA-- --AAABABBBBAABBBAABA-- -ABBAABABAAAABAABAAAA- -ABAAAAAABBAAABABBABB- -BBBBABBABAAAABBAAABB- -BAAAABABABABBAAABBAA- BBABBAABBBAAAAABBAAAAB AABABABBABAABBBBABBBBA BBBBABBBBBBAAABAAABBAB BBABBBABAABBAAAABBBABA ABAABBABABABAABBABBBAB ABAAAAABABABBBABBBBABA BAAAABBAAAABABABAAABAB ABBBBABAABBABAABBBABBA -AABAABAAAAABAABBBBBA- --B-BAAAB----BBBBB-A-- ---ABABB------ABBBB--- ---------------------- ---------------------- ---------------------- ---------------------- ---------------------- 
---DD------------CC--- ---AA------------AA--- ---AB------------BA--- ---AB------------BA--- ---AA------------AB--- --ABB------------AAB-- --ABA------------BAB-- --AAB------------AAA-- --AB--------------BB-- -ABB--------------AAB- -ABB--------------ABB- -ABB--------------ABB- -BB----------------AB- BB------------------AB AB------------------AA BA------------------AA A--------------------B A--------------------B A--------------------B A--------------------B B--------------------A A--------------------B AA------------------BB AB------------------AB -BAB--------------BAB- --B-B------------A-A-- --BBB------------BAB-- ----B------------A---- ---------------------- ---------------------- ---------------------- 
---C--------------C--- ---B--------------B--- ---A--------------A--- --BB--------------AA-- --AB--------------AB-- --AA--------------AA-- -AAB--------------BBA- -BBB--------------BAB- -AA----------------AB- -AA----------------AA- AB------------------AB BA------------------AB BB------------------AA BB------------------BA B--------------------B B--------------------B A--------------------B B--------------------B A--------------------A A--------------------A B--------------------B B--------------------A -A------------------A- -B------------------A- -B------------------B- -BAA--------------BAA- -BAAA------------BBAA- --BA--------------BA-- ----A------------B---- ---------------------- ---------------------- 
--C----------------D-- --B----------------A-- --A----------------B-- --B----------------A-- -BB----------------BB- -AA----------------AB- -BA----------------AA- -AB----------------AB- AA------------------AA BA------------------BA BA------------------BB BB------------------AA B--------------------A B--------------------A B--------------------A B--------------------A A--------------------A A--------------------B A--------------------B ---------------------- ---------------------- ---------------------- ---------------------- ---------------------- ---------------------- ---------------------- -B------------------A- -BBAA------------BBBA- --AB--------------AB-- ---AA------------AA--- ---------------------- 
--C----------------C-- --A----------------A-- --A----------------B-- --B----------------A-- -AA----------------BB- -BA----------------BA- -BB----------------AA- -B------------------BA BA------------------BB BB------------------AA AA------------------BB B--------------------A A--------------------A B--------------------A A--------------------B A--------------------B A--------------------A ---------------------- ---------------------- ---------------------- ---------------------- ---------------------- ---------------------- ---------------------- ---------------------- ---------------------- ---------------------- -A------------------A- -ABAB------------AABA- --AB--------------AA-- ----A------------B---- 
--D----------------D-- --B----------------A-- --A----------------A-- --B----------------A-- -BA----------------AB- -AB----------------BA- -BA----------------BB- -B------------------AB -A------------------AA BA------------------AB A--------------------A A--------------------B B--------------------B B--------------------B A--------------------B A--------------------B -B------------------B- ---------------------- ---------------------- ---------------------- ---------------------- ---------------------- ---------------------- ---------------------- ---------------------- ---------------------- ---------------------- ---------------------- -A------------------B- -BBAB------------BABB- --ABA------------BAA-- 
---D--------------C--- ---B--------------B--- ---A--------------B--- --AA--------------BB-- --BA--------------AB-- --BB--------------BB-- --AA--------------BA-- --BB--------------BB-- -BAB--------------ABA- -B------------------A- -B------------------B- -B------------------B- BB------------------BA AB------------------AA AA------------------BB AA------------------BA -B------------------A- -B------------------A- ---------------------- ---------------------- ---------------------- ---------------------- ---------------------- ---------------------- ---------------------- ---------------------- ---------------------- ---------------------- -A------------------B- -BBAB------------AABB- -ABAA------------ABAA- 
----D------------C---- ----A------------B---- ---AB------------AA--- ---BB------------AA--- ---BA------------BB--- ---BA------------AB--- ---AA------------BA--- --BAA------------ABA-- --BBB------------AAB-- --A----------------A-- -BA----------------BA- -BA----------------AB- -BB----------------BA- -BA----------------AA- -BA----------------AA- -AB----------------AB- -BA----------------AA- -A------------------A- -A------------------A- ---------------------- ---------------------- ---------------------- ---------------------- ---------------------- ---------------------- ---------------------- ---------------------- -A------------------B- -BAAB------------BBAA- -ABBA------------AAAB- -ABAA------------BBBA- 
-----DDCCDCDCCCDC----- -----BABABBBABBBB----- ----BAAABAABBAAABA---- ----AAABABBBABABBB---- ----BABBABBBABBABB---- ---BBAABBABBBBBBAAB--- ---AAABBAABAAAAAAAB--- ---ABAAAABBAAAAABBA--- --BBBBABBBABBBBABAAA-- --BBBBAAAABBAABBAAAB-- --ABABBBAAABBBAAAABB-- -BBABBAAAABBBBAABBABB- -BBBABBAAAAABBBABABBA- -BAAAAAAAABAABBAABBBA- -ABBBAABBAAABAAAAAAAB- -AABABBAABAABBABBABBA- -BBABBBBBBAAABAABBBAB- -BAAABBBBABABABABABAB- -AAABAAABBABAABABBBBA- -B------------------B- -A------------------A- ---------------------- ---------------------- ---------------------- ---------------------- -A------------------B- -B------------------A- -ABBB------------AABB- -ABAB------------BBAA- -BABA------------BBBB- --AB--------------BB-- 
---------CDDD--------- -------BBBBAAAA------- -------BAAABAAB------- ------ABBAAABABA------ ------BBAABAABAB------ -----BBBBBBBABBBB----- -----AABBAAAABAAA----- ----ABAABABAABAAAA---- ----AAABBAAAABAAAB---- ---BBAABBABBBBAAAAA--- ---BAAAABBBABBABBBA--- ---BBABAAAABAABBABB--- --BAAAAABBBAABABBAAA-- --BAAAABBBBABAAABBBA-- --BBABBBABAAABBBABAB-- -AABBABBBBBBAAAAABAAB- -BABBBAAABBBBBAABBABA- -ABAAAAAAAAABAABAABBB- -AABBBBBABBAABAAABBBA- -ABBBBABABBBBAABBBBAA- -AABBBABABBABABBBAABA- -AABAAABBAABABAABBAAA- -AAABAAABBBBABBAABABA- -AAABAABBAAABBBAAAAAB- -BABBABABAABABBBBBABA- -BAAABAAAAAAABABBAABA- -ABBABABBAAAABBBABBBB- -ABABAB--------BBABAA- -AAABA----------AAABA- --BB--------------AA-- ---------------------- 
---------------------- ---------------------- ---------------------- ---------------------- ---------------------- ---------------------- ---------------------- ---------------------- ----------BA---------- --------BABABA-------- ------BBBAABABBA------ ------ABABABABAA------ -----BAABABAABBBA----- -----BBBABAAAABBB----- ----ABABBABABABBBA---- ----BBABABBBABAABB---- ---BAAABBBBBBABAAAB--- ---BAABABBBAAAAABAA--- --AABBABAABABABABAAA-- --AAABABAAABABAAAAAB-- -BBBAAAAAAAABABAABBAB- -BABAABAAAABAABBAABBB- -AAAAABABBAABAAAABABB- -BABBAAABBABBBBAABBBA- -ABBBABABABBBAAAABABB- -BABABBAABBBBAAAAAABA- -BBBAABA------BBAABAA- --AAAA----------ABBA-- --AA--------------BA-- ---------------------- ---------------------- 
---------------------- ---------------------- ---------------------- ---------------------- ---------------------- ---------------------- ---------------------- ---------------------- ---------------------- ---------------------- ---------------------- ---------------------- ---------------------- ---------------------- ---------------------- ---------------------- -------BAA--BAA------- -----BBBAABBABAAB----- -----ABAAAABBABAA----- ----BBABABBBABBABA---- ----BBBBBAAABABBAB---- ---ABABAAABABBBABAB--- ---BAABAAAAAABAABAA--- --ABAABABB--BAABABBA-- --BAAAAAB----BBBABAB-- --BABBB--------AAABB-- --ABB------------BBA-- --BB--------------BB-- ---------------------- ---------------------- ---------------------- 
