model
size = 32 19 20, scale = 0.05, origin = -y
material 
  colors = A:#FF0 B:#960 C:#000
voxels
34C5(28-4C)3(13-2C13-4C)28-4C28-68C28-4C28-2C128-33C12(30B2C)30B3C28-4C28-2C96-2C28-2C-30B7(2-B28AB)2-B-A18-A7-B2-B28-B-CB28-B2CB28-BC-30B-C30B3C28-4C28-2C64-2C28-2C-30B7(2-B28AB)2-B-4A2(-A)2(2-A)5-A3-2A2(2-B)6-A21-B-CB28-B2CB28-BC-B28-B2-30B-C30B3C28-4C28-2C32-2C28-2C-30B7(2-B28AB)2-B2-2(A3-)2A4-A2-A-A6-B2-B28-B-CB28-B2CB28-BC-2(B28-B2-)30B-C30B3C2(28-4C)28-2C-30B7(2-B28AB)2-B5-2A-5A11-A3-B2-B28-B-CB28-B2CB28-BC-3(B28-B2-)30B-C30B3C28-4C28-2C-30B7(2-B28AB)2-B5-A6-A4-2(A3-)A2(2-B)28-B-CB28-B2CB28-BC-3(B28-B2-)B28-B-C30B-2C28-4C28-2C-30B7(2-B28AB)2-B-A2-A8-2A13-B2-B28-B-CB28-B2CB28-BC-3(B28-B2-)B28-B-C30B-2C28-4C28-2C-30B7(2-B28AB)2-B4-2(A2-)A3-A4-A3-A2-A-B2-B14-A13-B-CB28-B2CB28-BC-3(B28-B2-)B28-B-C30B-2C28-4C28-2C-30B7(2-B28AB)2-B2-A3-2A5-2(A3-)A4-A-B2-B28-B-CB28-B2CB28-BC-3(B28-B2-)B28-B-C30B-2C28-4C28-2C-30B7(2-B28AB)2-B2-A2-2A3-A2-2A-3A2-A-A4-B2-B6-A10-A5-A4-B-CB28-B2CB28-BC-3(B28-B2-)B28-B-C30B-2C28-4C28-2C-30B7(2-B28AB)2-BA5-2A4-2A3-2(2A2-)A2(2-B)21-A6-B-CB28-B2CB28-BC-3(B28-B2-)B28-B-C30B-2C28-4C28-2C-30B7(2-B28AB)2-B13-2A2-A4-A3-A-B2-B13-A14-B-CB28-B2CB28-BC-3(B28-B2-)B28-B-C30B-2C28-4C28-2C-30B7(2-B28AB)2-B3(-A)2-2A2(-A)-3A-A4-2A2(2-B)17-A10-B-CB28-B2CB28-BC-3(B28-B2-)B28-B-C30B-2C28-4C28-2C-30B7(2-B28AB)2-B3-A6-2(A2-A5-)B2-B22-A5-B-CB28-B2CB28-BC-3(B28-B2-)30B-C30B3C28-4C28-2C-30B7(2-B28AB)2-B4-4A5-A-2A-A7-A-B2-B5-A22-B-CB28-B2CB28-BC-2(B28-B2-)30B-C30B3C2(28-4C)28-2C-30B7(2-B28AB)2-B-A7-2A-2(A4-)2(A2-)B2-B17-A10-B-CB28-B2CB28-BC-B28-B2-30B-C30B3C28-4C28-2C32-2C28-2C-30B7(2-B28AB)2(2-B28-B)-CB28-B2CB28-BC-30B-C30B3C28-4C28-2C64-33C12(30B2C)30B3C28-4C28-2C96-34C9(28-4C)28-68C28-4C28-2C128-
