model
size = 4 24 24, scale = 0.05, origin = -y
material 
  colors = A:#008 B:#800 C:#444 D:#777 E:#555 F:#AAA G:#300 H:#222 I:#00E
voxels
---- ---- ---- ---- ---- ---- ---- ---- ---- -B-- -B-- -B-- -B-- -B-- -B-- ---- ---- ---- ---- ---- ---- ---- ---- ---- 
---- ---- ---- ---- ---- ---- ---- -B-- -B-- --B- --B- --B- --B- --B- --B- -B-- -B-- ---- ---- ---- ---- ---- ---- ---- 
---- ---- ---- ---- ---- -B-- -B-- --B- --B- --C- --D- --D- --C- --C- --H- --H- --B- -B-- -B-- ---- ---- ---- ---- ---- 
---- ---- ---- ---- -B-- --B- --B- --C- --H- --C- --C- --D- --C- --H- --C- --H- --C- --B- --B- -B-- ---- ---- ---- ---- 
---- ---- ---- -B-- --B- --D- --C- --H- --H- --DH --DC --DD --DD --DD --DC --C- --D- --D- --C- --B- -B-- ---- ---- ---- 
---- ---- -B-- --B- --F- --F- --F- --DH --DC --AB --AB --AB --AB --AB --AB --DC --DD --C- --C- --D- --B- -B-- ---- ---- 
---- ---- -B-- --B- --D- --C- --DD --AF --AF --AB --AB --AB --AB --AB --AB --AB --AB --DD --D- --D- --B- -B-- ---- ---- 
---- -B-- --B- --D- --F- --DC --AB -CIB -CIB --AA --AA --AA --AA --AE --AA -CIB -CIB --AB --CC --C- --C- --B- -B-- ---- 
---- -B-- --F- --F- --C- --DF -CIF CGIF CGIA -CIA --AA --AA --AA --AE -CAA CGIA CGIB -CIB --CC --C- --C- --C- -B-- ---- 
-B-- --B- --D- --D- --DC --AB --AB G-AA G-AE --AE --AA --AA --AE --AE --AA G-AA G-AA --AB --AC --DH --C- --H- --C- -B-- 
-B-- --F- --D- --C- --DD --AF --AF G-AF G-AA --AA --AE --AE --AE --AE --AE G-AA G-AA --AB --AB --DC --H- --H- --C- -B-- 
-B-- --B- --F- --F- --DF --AB --AF G-AA G-AA --AA --AA --AE --AE --AE --AE G-AE G-AE --AB --AB --DH --C- --C- --B- -B-- 
-B-- --B- --C- --C- --DC --AB --AB G-AA G-AA --AA --AA --AE --AE --AE --AE G-AE G-AE --AB --AB --DC --H- --C- --C- -B-- 
-B-- --B- --D- --F- --DD --AB --AF G-AF G-AA --AA --AE --AE --AE --AE --AE G-AA G-AA --AB --AB --DC --H- --C- --B- -B-- 
-B-- --F- --F- --C- --DF --AF --AB G-AA G-AE --AE --AA --AA --AE --AE --AA G-AA G-AA --AB --AC --DD --C- --D- --B- -B-- 
---- -B-- --B- --C- --D- --DC -CIB CGIB CGIA -CIA --AA --AA --AA --AE -CAA CGIA CGIB -CIB --DD --D- --D- --B- -B-- ---- 
---- -B-- --F- --F- --C- --DD --AF -CIF -CIF --AA --AA --AA --AA --AE --AA -CIB -CIB --AB --DC --C- --D- --B- -B-- ---- 
---- ---- -B-- --B- --D- --F- --DC --AB --AC --AC --AB --AB --AB --AB --AB --AB --AB --DD --D- --C- --B- -B-- ---- ---- 
---- ---- -B-- --B- --C- --H- --C- --DH --DH --AC --AB --AB --AB --AB --AC --DC --DD --C- --C- --D- --B- -B-- ---- ---- 
---- ---- ---- -B-- --B- --C- --H- --C- --C- --DC --DC --DD --DD --DC --HH --H- --C- --H- --C- --B- -B-- ---- ---- ---- 
---- ---- ---- ---- -B-- --B- --B- --C- --H- --C- --D- --C- --D- --D- --H- --C- --H- --C- --C- -B-- ---- ---- ---- ---- 
---- ---- ---- ---- ---- -B-- -B-- --B- --B- --D- --D- --C- --C- --D- --C- --C- --B- -B-- -B-- ---- ---- ---- ---- ---- 
---- ---- ---- ---- ---- ---- ---- -B-- -B-- --B- --B- --B- --B- --B- --B- -B-- -B-- ---- ---- ---- ---- ---- ---- ---- 
---- ---- ---- ---- ---- ---- ---- ---- ---- -B-- -B-- -B-- -B-- -B-- -B-- ---- ---- ---- ---- ---- ---- ---- ---- ---- 
