model
size = 13 21 30, scale = 0.05, origin = -y
material 
  colors = A:#571212 B:#F7D94C C:#FFFC56 D:#DDD23B E:#350606 F:#36563C
voxels
---AAA-AAA--- ---AA---AA--- ------------- ------------- ------------- ------------- ------------- ------------- ------------- ------------- ------------- ------------- ------------- -----AEA----- -----AAA----- -----AAA----- ------------- ------------- ------------- ------------- ------------- 
---EAA-AAE--- ---AAA-AAA--- ------------- ------------- ------------- ---AAAEAAA--- ---AEAAAEA--- ---AAEAEAA--- ---AEAAAEA--- ---AAEAEAA--- ----AAAAA---- ------A------ ------------- -----AAA----- -----AAA----- -----AAA----- -----FAF----- -----AAA----- ------------- ------------- ------------- 
---AAA-AAA--- ---EAA-AAE--- ---AA---AA--- ---EA---AE--- ---AEAAAEA--- --AAAAAAAAA-- --EAAA-AAAE-- --AA-----AA-- --EA----AAE-- ---AA---AA--- ----AAAAA---- ----EAAAE---- -----EAE----- -----AAA----- -----AAA----- -----AAA----- -----AAA----- ----AAAAA---- ----AA-AA---- ------------- ------------- 
---AA---AA--- ---AA---AA--- ---EA---AE--- ---AA---AA--- ---AAAAAAA--- --AA-A-A-AA-- --A------AA-- --E------AE-- --AA-----AA-- ---AA---AA--- ----E--AE---- ----AA-AA---- -----A-A----- -----AAA----- -----AAA----- -----EAE----- -----A-A----- -----AAA----- ----AA-AA---- ----AA-AA---- ----A---A---- 
---AA---AA--- ---AA---AA--- ---AA---AA--- ---EA---AE--- ---AAAAAAA--- --EAA---AAE-- --AA-----AA-- --A------AA-- --EA-----AE-- ---AA---AA--- ----AAAAA---- ----AAAAA---- -----AAA----- -----AAA----- -----EAE----- -----A-A----- -----EAE----- -----AAA----- ------------- ------------- ------------- 
------------- ------------- ------------- ------------- ----AAAAA---- ---AAA-AAA--- --EA-----AE-- --AA-----AA-- --AA----AAA-- ---AAAA-AA--- ----AAAAA---- ----AA-AA---- ------------- ------------- -----AAA----- -----AAA----- -----AAA----- ------------- ------------- C-----------C DD---------DD 
------------- ------------- ------------- ------------- -----AAA----- ---AAAAAAA--- ---A----AA--- ---A-----A--- ---A----AA--- ---AAAAAAA--- ---AAAAAAA--- ---AAA-AAA--- ---AA---AA--- ------------- ------------- ------------- ------------- ------------- ------------- DD---------DD BB---------BB 
------------- ------------- ------------- ------------- ------------- ----AAAAA---- ---AA---AA--- ---A-----A--- ---AA---AA--- ---AAAAAAA--- ---AAA-AAA--- --EAAA-AAAE-- --AAA---AAA-- --CC-----CC-- -BB-------BB- -DD-------DD- -C---------C- -B---------B- DD---------DD BB---------BB C-----------C 
------------- ------------- ------------- ------------- ------------- ----AAAAA---- ---EA---AE--- ---A-----A--- ---EA---AE--- ----AEAEA---- ---AA---AA--- --AAA---AAA-- --CCC---CCC-- -BBB-----BBB- -DD-------DD- -CC-------CC- -BB-------BB- DD---------DD BB---------BB CC---------CC ------------- 
------------- ------------- ------------- ------------- ---AA---AA--- ---AAAAAAA--- ---AA---AA--- ---E-----E--- ---AA--AAA--- ----AAEAA---- ---A-----A--- --CC-----CC-- -BBB-----BBB- -DDD-----DDD- -CC-------CC- -BB-------BB- DDD-------DDD BBB-------BBB CC---------CC BB---------BB ------------- 
---AA---AA--- ---AA---AA--- ------------- ---AA---AA--- ---AA---AA--- ---AAAAAAA--- ---A-----A--- ---A-----A--- ---EAAAAAE--- ----AAAAA---- ------------- -BBB-----BBB- -DDD-----DDD- -CCC-----CCC- -BB-------BB- -DD-------DD- BBB-------BBB CCC-------CCC BB---------BB DD---------DD ------------- 
---AA---AA--- ---AA---AA--- ------------- ---AA---AA--- ---EA---AE--- ---AAAAA-A--- ---E-----E--- ---A-----A--- ---AAAAAAA--- ----AE-EA---- ------------- -DD-------DD- -CC------CCC- -BB------BBB- -DD-------DD- BBB-------BBB CCC-------CCC BBB-------BBB DD---------DD CC---------CC ------------- 
---AA---AA--- ---AA---AA--- ---AA---AA--- ---AA---AA--- ---AA---AA--- ---EAAAAAE--- ---A-----A--- ---A-----A--- ---AAAEAAA--- -----A-A----- ------------- -CC-------CC- -BB-------BB- -DD-------DD- -BB-------BB- CCC-------CCC BBB-------BBB DDD-------DDD CC---------CC -B---------B- ------------- 
---AA---AA--- ---AA---AA--- ---AA---AA--- ---AA---AA--- ---AA---AA--- ---AAAAAAA--- ---EAAAAAE--- ---AA---AA--- ---AAEAEAA--- ------------- ------------- -BB-------BB- -DD-------DD- -BB-------BB- CCC-------CCC BBB-------BBB DDD-------DDD CC---------CC -B---------B- -D---------D- ------------- 
------------- ------------- ------------- ---AA---AA--- ------------- ----AAAAA---- ---AAAAAAA--- ---AAAAAAA--- ----AAEAA---- ------------- ------------- -DD-------DD- -BB-------BB- -CC-------CC- BBB-------BBB DDD-------DDD CCC-------CCC BB---------BB -D---------D- -C---------C- ------------- 
------------- ------------- ------------- ------------- ----AAAAA---- ----AAAAA---- ----AAAAA---- ----EAEAE---- ------------- ------------- ------------- -BB-------BB- -CC-------CC- BBB-------BBB DDD-------DDD CCC-------CCC BB---------BB -D---------D- -C---------C- -B---------B- ------------- 
------------- ------------- ------------- ----AAAAA---- ----AAAAA---- ----EAAAE---- -----AEA----- ------------- ------------- ------------- ------------- -CC-------CC- -BB-------BB- DDD-------DDD CCC-------CCC BB---------BB DD---------DD -C---------C- -B---------B- ------------- ------------- 
------------- ------------- ----AAAAA---- ----AAAAA---- ----EAAAE---- -----AEA----- ------------- ------------- ------------- ------------- ------------- -BB-------BB- -DD-------DD- CCC-------CCC BBB-------BBB DD---------DD CC---------CC -B---------B- -D---------D- ------------- ------------- 
------------- -----AAA----- ----AAAAA---- ----EAAAE---- -----AEA----- ------------- ------------- ------------- ------------- ------------- ------------- -DD-------DD- -CC-------CC- BBB-------BBB DD---------DD CC---------CC -B---------B- -D---------D- -C---------C- ------------- ------------- 
------------- -----AAA----- -----AAA----- -----AEA----- ------------- ------------- ------------- ------------- ------------- ------------- --D-------D-- -CC-------CC- -BB-------BB- DD---------DD CC---------CC BB---------BB -D---------D- -C---------C- ------------- ------------- ------------- 
------------- -----AAA----- -----EAE----- ------------- ------------- ------------- ------------- ------------- ------------- ------------- --C-------C-- -BB-------BB- -DD-------DD- CC---------CC BB---------BB DD---------DD -C---------C- -B---------B- ------------- ------------- ------------- 
-----AAA----- -----AAA----- -----AEA----- ------------- ------------- ------------- ------------- ------------- ------------- ------------- ------------- -DD-------DD- -C---------C- BB---------BB DD---------DD -C---------C- -B---------B- ------------- ------------- ------------- ------------- 
-----AAA----- -----A-A----- -----AAA----- ------------- ------------- ------------- ------------- ------------- ------------- ------------- -D---------D- -C---------C- -B---------B- DD---------DD CC---------CC -B---------B- -D---------D- ------------- ------------- ------------- ------------- 
-----AAA----- -----AAA----- -----EAE----- ------------- ------------- ------------- ------------- ------------- ------------- ------------- -C---------C- -B---------B- -D---------D- CC---------CC -B---------B- -D---------D- ------------- ------------- ------------- ------------- ------------- 
-----AAA----- -----AAA----- -----AEA----- ------------- ------------- ------------- ------------- ------------- ------------- ------------- ------------- ------------- -C---------C- BB---------BB -D---------D- ------------- ------------- ------------- ------------- ------------- ------------- 
------------- -----AAA----- -----AAA----- ------------- ------------- ------------- ------------- ------------- ------------- ------------- ------------- -C---------C- -B---------B- -D---------D- -C---------C- ------------- ------------- ------------- ------------- ------------- ------------- 
------------- -----AAA----- -----EAE----- ------------- ------------- ------------- ------------- ------------- ------------- ------------- ------------- -B---------B- -D---------D- -C---------C- ------------- ------------- ------------- ------------- ------------- ------------- ------------- 
------------- -----AAA----- -----AEA----- ------------- ------------- ------------- ------------- ------------- ------------- ------------- -B---------B- -D---------D- -C---------C- ------------- ------------- ------------- ------------- ------------- ------------- ------------- ------------- 
------------- ------------- -----AAA----- ------A------ ------------- ------------- ------------- ------------- ------------- ------------- -C---------C- ------------- ------------- ------------- ------------- ------------- ------------- ------------- ------------- ------------- ------------- 
------------- ------------- ------A------ ------E------ ------------- ------------- ------------- ------------- ------------- ------------- ------------- ------------- ------------- ------------- ------------- ------------- ------------- ------------- ------------- ------------- ------------- 
