model
size = 31 31 17, scale = 0.05, origin = -y
material 
  colors = A:#036 B:#FF0 C:#FF3 D:#039
voxels
---------AAAAAAAAAAAAA--------- ---------AAAAAAAAAAAAA--------- ---------AAAAAAAAAAAAA--------- ---------AAAAAAAAAAAAA--------- ---------AAAAAAAAAAAAA--------- ---------AAAAAAAAAAAAA--------- ---------AAAAAAAAAAAAA--------- ---------AAAAAAAAAAAAA--------- ---------AAAAAAAAAAAAA--------- ---------AAAAAAAAAAAAA--------- ---------AAAAAAAAAAAAA--------- ---------AAAAAAAAAAAAA--------- ---------AAAAAAAAAAAAA--------- ---------AAAAAAAAAAAAA--------- ---------AAAAAAAAAAAAA--------- ---------AAAAAAAAAAAAA--------- ---------AAAABBBBBAAAA--------- ---------AAABAAAAABAAA--------- ---------AABAABBAAABAA--------- ---------ABAABAAAAAABA--------- ---------ABABAABAAAABA--------- --------AABABAAAAAAABAA-------- -------AAABBBBBBBBBBBAAA------- -------AAAAAAAAAAAABBAAA------- --------AAAAAAAAAABBAAA-------- ---------AAAAAAAABBAAA--------- ----------AAAAABBBAAA---------- -----------AAAAAAAAA----------- ------------------------------- ------------------------------- ------------------------------- 
-------AA-------------AA------- -------AA-------------AA------- -------AA-------------AA------- -------AA-------------AA------- -------AA-------------AA------- -------AA-------------AA------- -------AA-------------AA------- -------AA-------------AA------- -------AA-------------AA------- -------AA-------------AA------- -------AA-------------AA------- -------AA-------------AA------- -------AA-------------AA------- -------AAA-----------AAA------- -------AAA-----------AAA------- --------AA-----------AA-------- --------AA-----------AA-------- --------AA-----------AA-------- --------AA-----------AA-------- --------AA-----------AA-------- ------AAAA-----------AAAA------ -----AAAA-------------AAAA----- -----AAA---------------AAA----- -----AAA---------------AAA----- ------AA---------------AA------ -------AA-------------AA------- --------AAAAAAAAAAAAAAA-------- --------AAAAAAAAAAAAAAA-------- -------------AAAAA------------- -------------AAAAA------------- -------------AAAAA------------- 
------A-----------------A------ ------A-----------------A------ ------A-----------------A------ ------A-----------------A------ ------A-----------------A------ ------A-----------------A------ ------A-----------------A------ ------A-----------------A------ ------A-----------------A------ ------AA---------------AA------ ------AA---------------AA------ ------AA---------------AA------ ------AA---------------AA------ -------A---------------A------- -------A---------------A------- -------AA-------------AA------- -------AA-------------AA------- -------AA-------------AA------- -------AA-------------AA------- --------A-------------A-------- ---AAA--A-------------A--AAA--- ---AAA-------------------AAA--- ---AAA-------------------AAA--- ---AAA-------------------AAA--- ----AA-------------------AA---- ----AAAA---------------AAAA---- -----AAA---------------AAA----- -------A---------------A------- --------AAAAA-----AAAAA-------- ------------A-----A------------ ------------A-----A------------ 
-----A-------------------A----- -----A-------------------A----- -----A-------------------A----- -----A-------------------A----- -----A-------------------A----- -----A-------------------A----- -----A-------------------A----- -----A-------------------A----- -----A-------------------A----- ------A-----------------A------ ------A-----------------A------ ------A-----------------A------ ------A-----------------A------ ------A-----------------A------ ------A-----------------A------ -------A---------------A------- -------A---------------A------- -------A---------------A------- -------A---------------A------- -------A---------------A------- --A----A---------------A----A-- --A-------------------------A-- --A-------------------------A-- --AA-----------------------AA-- --AAA---------------------AAA-- ---AAA-------------------AAA--- ---AAAA-----------------AAAA--- ----AAAA---------------AAAA---- ------AA---------------AA------ --------AAAA-------AAAA-------- -----------A-------A----------- 
-----A-------------------A----- -----A-------------------A----- -----A-------------------A----- -----A-------------------A----- -----A-------------------A----- -----A-------------------A----- -----A-------------------A----- -----A-------------------A----- -----A-------------------A----- -----AA-----------------AA----- -----AA-----------------AA----- -----AA-----------------AA----- ------A-----------------A------ ------A-----------------A------ ------A-----------------A------ ------AA---------------AA------ ------AA---------------AA------ -------A---------------A------- -------A---------------A------- -------A---------------A------- -A-----A---------------A-----A- -A---------------------------A- -A---------------------------A- -AA-------------------------AA- --AA-----------------------AA-- --AAA---------------------AAA-- --AAAA-------------------AAAA-- ---AAAA-----------------AAAA--- ----AAAA---------------AAAA---- -------AA-------------AA------- ---------AAA-------AAA--------- 
-----A-------------------A----- -----A-------------------A----- -----A-------------------A----- -----A-------------------A----- -----A-------------------A----- -----A-------------------A----- -----A-------------------A----- -----A-------------------A----- -----A-------------------A----- -----A-------------------A----- -----A-------------------A----- -----A-------------------A----- -----A-------------------A----- -----A-------------------A----- -----A-------------------A----- ------A-----------------A------ ------A-----------------A------ ------A-----------------A------ ------A-----------------A------ -------A---------------A------- -A-----A---------------A-----A- -A---------------------------A- -A---------------------------A- -A---------------------------A- -AA-------------------------AA- -AAA-----------------------AAA- --AAA---------------------AAA-- --AAAA-------------------AAAA-- ---AAAA-----------------AAAA--- -----AAA---------------AAA----- --------A-------------A-------- 
-----A-------------------A----- -----A-------------------A----- -----A-------------------A----- -----A-------------------A----- -----A-------------------A----- -----A-------------------A----- -----A-------------------A----- -----A-------------------A----- -----A-------------------A----- -----A-------------------D----- -----D-------------------A----- -----D-------------------D----- -----D-------------------D----- -----D-------------------D----- -----A-------------------A----- -----AA-----------------AA----- -----AA-----------------AA----- ------A-----------------A------ ------A-----------------A------ ------AA---------------AA------ A------A---------------A------A A----------------------------AA A----------------------------AA A----------------------------AA -A--------------------------AA- -AA-------------------------AA- -AAA-----------------------AAA- --AAA---------------------AAA-- ---AAA-------------------AAA--- ----AAAA---------------AAAA---- -------A---------------A------- 
-----A-------------------A----- -----A-------------------A----- -----A-------------------A----- -----A-------------------A----- -----A-------------------A----- -----A-------------------A----- -----A-------------------A----- -----A-------------------A----- -----A-------------------A----- -----D-------------------D----- -----A-------------------A----- -----A-------------------D----- -----A-------------------A----- -----A-------------------D----- -----A-------------------A----- -----AA-----------------AA----- -----AA-----------------AA----- -----AA-----------------AA----- ------A-----------------A------ ------AA----------------A------ A-----AA----------------A-----A A----------------------------AA A----------------------------AA A----------------------------AA A----------------------------AA -A--------------------------AA- -AA-------------------------AA- --AA-----------------------AA-- --AAA---------------------AAA-- ----AA-------------------AA---- ------AA----------------A------ 
-----A-------------------A----- -----A-------------------A----- -----A-------------------A----- -----A-------------------A----- -----A-------------------A----- -----A-------------------A----- -----A-------------------A----- -----A-------------------A----- -----A-------------------A----- -----A-------------------D----- -----D-------------------A----- -----D-------------------D----- -----A-------------------A----- -----A-------------------D----- -----A-------------------A----- -----AA-----------------AA----- -----AA-----------------AA----- -----AA-----------------AA----- -----AA-----------------AA----- -----AAA----------------AA----- A-----AA----------------A-----A A----------------------------AA A----------------------------AA A----------------------------AA A----------------------------AA A----------------------------AA -A--------------------------AA- -AA-------------------------AA- --AA-----------------------AA-- ---AAA-------------------AAA--- ------AA----------------A------ 
-----A-------------------A----- -----A-------------------A----- -----A-------------------A----- -----A-------------------A----- -----A-------------------A----- -----A-------------------A----- -----A-------------------A----- -----A-------------------A----- -----A-------------------A----- -----D-------------------D----- -----A-------------------A----- -----A-------------------D----- -----A-------------------A----- -----A-------------------D----- -----A-------------------A----- -----AA-----------------AA----- -----AA-----------------AA----- -----AA-----------------AA----- ------A-----------------A------ ------AA----------------A------ A-----AA----------------A-----A A----------------------------AA A----------------------------AA A----------------------------AA A----------------------------AA A----------------------------AA -A--------------------------AA- -AA-------------------------AA- --AA-----------------------AA-- ---AAA-------------------AAA--- ------AA----------------A------ 
-----A-------------------A----- -----A-------------------A----- -----A-------------------A----- -----A-------------------A----- -----A-------------------A----- -----A-------------------A----- -----A-------------------A----- -----A-------------------A----- -----A-------------------A----- -----A-------------------D----- -----D-------------------D----- -----D-------------------D----- -----D-------------------A----- -----D-------------------D----- -----A-------------------A----- -----AA-----------------AA----- -----AA-----------------AA----- ------A-----------------A------ ------A-----------------A------ ------AA----------------A------ A------A----------------------A A----------------------------AA A----------------------------AA A----------------------------AA A----------------------------AA -A--------------------------AA- -AA-------------------------AA- --AA-----------------------AA-- --AAA---------------------AAA-- ----AA-------------------AA---- ------AA----------------A------ 
-----A-------------------A----- -----A-------------------A----- -----A-------------------A----- -----A-------------------A----- -----A-------------------A----- -----A-------------------A----- -----A-------------------A----- -----A-------------------A----- -----A-------------------A----- -----A-------------------A----- -----A-------------------A----- -----A-------------------A----- -----A-------------------A----- -----A-------------------A----- -----A-------------------A----- ------A-----------------A------ ------A-----------------A------ ------A-----------------A------ ------A-----------------A------ -------A---------------A------- A------A---------------A------A A----------------------------AA A----------------------------AA A----------------------------AA -A--------------------------AA- -AA-------------------------AA- -AAA-----------------------AAA- --AAA---------------------AAA-- ---AAAA-----------------AAAA--- ----AAAA---------------AAAA---- -------AA--------------A------- 
-----A-------------------A----- -----A-------------------A----- -----A-------------------A----- -----A-------------------A----- -----A-------------------A----- -----A-------------------A----- -----A-------------------A----- -----A-------------------A----- -----A-------------------A----- -----AA-----------------AA----- -----AA-----------------AA----- -----AA-----------------AA----- ------A-----------------A------ ------A-----------------A------ ------A-----------------A------ -------A---------------A------- -------A---------------A------- -------A---------------A------- -------A---------------A------- -------A---------------A------- -A-----A---------------A-----A- -A---------------------------A- -A---------------------------A- -A--------------------------AA- -AA-------------------------AA- -AAA-----------------------AAA- --AAA---------------------AAA-- --AAAA-------------------AAAA-- ---AAAA-----------------AAAA--- -----AAA---------------AAA----- --------A-------------A-------- 
-----A-------------------A----- -----A-------------------A----- -----A-------------------A----- -----A-------------------A----- -----A-------------------A----- -----A-------------------A----- -----A-------------------A----- -----A-------------------A----- -----A-------------------A----- ------A-----------------A------ ------A-----------------A------ ------A-----------------A------ ------A-----------------A------ ------A-----------------A------ ------A-----------------A------ -------A---------------A------- -------A---------------A------- -------A---------------A------- -------A---------------A------- -------A---------------A------- -A-----A---------------A-----A- -A---------------------------A- -A---------------------------A- -AA-------------------------AA- --AA-----------------------AA-- --AAA---------------------AAA-- --AAAA-------------------AAAA-- ---AAAA-----------------AAAA--- ----AAAA---------------AAAA---- -------A---------------A------- --------A-------------A-------- 
------A-----------------A------ ------A-----------------A------ ------A-----------------A------ ------A-----------------A------ ------A-----------------A------ ------A-----------------A------ ------A-----------------A------ ------A-----------------A------ ------A-----------------A------ ------AA---------------AA------ ------AA---------------AA------ ------AA---------------AA------ ------AA---------------AA------ -------A---------------A------- -------A---------------A------- -------A---------------A------- -------A---------------A------- -------A---------------A------- -------A---------------A------- --------A-------------A-------- --A-----A-------------A-----A-- --A----AA-------------AA----A-- --A-------------------------A-- --AA-----------------------AA-- --AAA---------------------AAA-- ---AAA-------------------AAA--- ---AAAA-----------------AAAA--- ----AAAA----------------AAA---- ------AA---------------AA------ --------AA-----------AA-------- ---------AA---------AA--------- 
-------AAAAAAAAAAAAAAAAA------- -------AAAAAAAAAAAAAAAAA------- -------AAAAAAAAAAAAAAAAA------- -------AAAAAAAAAAAAAAAAA------- -------AAAAAAAAAAAAAAAAA------- -------AAAAAAAAAAAAAAAAA------- -------AAAAAAAAAAAAAAAAA------- -------AAAAAAAAAAAAAAAAA------- -------AAAAAAAAAAAAAAAAA------- -------AAAAAAAAAAAAAAAAA------- -------AAAAAAAAAAAAAAAAA------- -------AAAAAAAAAAAAAAAAA------- -------AAAAAAAAAAAAAAAAA------- -------AAAAAAAAAAAAAAAAA------- -------AAAAAAAAAAAAAAAAA------- --------AAAAAAAAAAAAAAA-------- --------AAAAAAAAAAAAAAA-------- --------AAAAAAAAAAAAAAA-------- --------AAAAAAAAAAAAAAA-------- --------AAAAAAAAAAAAAAA-------- ---AAAA-AAAAAAAAAAAAAAA-AAAA--- ---AAAAAAAAAAAAAAAAAAAAAAAAA--- ---AAAAAAAAAAAAAAAAAAAAAAAAA--- ---AAAAAAAAAAAAAAAAAAAAAAAAA--- ----AAAAAAAAAAAAAAAAAAAAAAA---- ----AAAAAAAAAAAAAAAAAAAAAAA---- -----AAAAAAAAAAAAAAAAAAAAA----- -------AAAAAAAAAAAAAAAAA------- --------AAAAAAAAAAAAAAA-------- ---------AAAAAAAAAAAAA--------- ----------AAAAAAAAAAA---------- 
--------AAACAAAAAAACAAA-------- --------AACAABBBBBAACAA-------- --------AACAAAAAABAACAA-------- --------AACAAABBBBAACAA-------- --------AACAAAAAABAACAA-------- --------AACAABBBBBAACAA-------- --------AACAAAAAAAAACAA-------- --------AACAABBBBBAACAA-------- --------AACAAAAAABAACAA-------- --------AACAAAAAABAACAA-------- --------AACAAAAAABAACAA-------- --------AACAAAAAABAACAA-------- --------AACAAAAAAAAACAA-------- ---------ACAABAAABAACA--------- ---------ACAABBBBBAACA--------- ---------ACAABAAABAACA--------- ---------ACAAABABAAACA--------- ---------ACAAAABAAAACA--------- ---------ACAAAAAAAAACA--------- ---------ACAABAAABAACA--------- ---------ACAABAAABAACA--------- --------AACAABBBBBAACAA-------- ------AAAACAABAAABAACAAAA------ ------AAAACAABAAABAACAAAA------ ------AAAACAAAAAAAAACAAAA------ -------AAACAAABABAAACAAA------- --------AACAABABABAACAA-------- --------AACAABABABAACAA-------- ----------CAABAAABAAC---------- ----------CAABAAABAAC---------- -----------CAAAAAAAC----------- 
