model
size = 16 6 16, scale = 0.05, origin = -y
material 
  colors = A:#FCFAF2 B:#F6C555 C:#FFF D:#111 E:#FFD556
voxels
--BBBBB--BBBBB-- -BAAACB--BAAAAB- BAAAACBBBBCAAAAB BAAAAAAAAAAAAAAB BAAAAAAAAAAAAAAB CBBBBBDEEDBBBBBC 
---------------- ---------------- ---------------- ---------------- ---------------- C--------------C 
---------------- ---------------- ---------------- ---------------- ---------------- C--------------C 
---------------- ---------------- ---------------- ---------------- ---------------- C--------------C 
---------------- ---------------- ---------------- ---------------- ---------------- C--------------C 
---------------- ---------------- ---------------- ---------------- ---------------- C--------------C 
---------------- ---------------- ---------------- ---------------- ---------------- C--------------C 
---------------- ---------------- ---------------- ---------------- ---------------- C--------------C 
---------------- ---------------- ---------------- ---------------- ---------------- C--------------C 
---------------- ---------------- ---------------- ---------------- ---------------- C--------------C 
---------------- ---------------- ---------------- ---------------- ---------------- C--------------C 
---------------- ---------------- ---------------- ---------------- ---------------- C--------------C 
---------------- ---------------- ---------------- ---------------- ---------------- A--------------C 
---------------- ---------------- ---------------- ---------------- ---------------- A--------------C 
---------------- ---------------- ---------------- ---------------- A--------------C ---------------- 
---------------- ---------------- ---------------- A--------------C ---------------- ---------------- 
