model
size = 26 30 22, scale = 0.05, origin = -y
material 
  colors = A:#EEE B:#9B90C2 C:#B28FCE D:#66327C E:#986DB2 F:#6E75A4 G:#DB4D6D H:#DA8FBE I:#F8C3CD J:#E9CD4C K:#66BAB7 L:#A5DEE4 M:#0D5661 N:#B69451 O:#FBE251 P:#0089A7 Q:#A8497A R:#DDD
voxels
-------------------------- -------------------------- -------------------------- -------------------------- -------------------------- -------------------------- -------------------------- -------------------------- -------------------------- -------------------------- -------------------------- -------------------------- -------------------------- -------------------------- ------------HN------------ -----------JNNJ----------- -----------JNNJ----------- ------------JJ------------ -------------------------- -------------------------- -------------------------- -------------------------- -------------------------- -------------------------- -------------------------- -------------------------- -------------------------- -------------------------- -------------------------- -------------------------- 
-------------------------- -------------------------- -------------------------- -------------------------- -------------------------- ------------MM------------ -------------------------- -------------------------- -------------------------- -------------------------- ------------MM------------ -----------NLLN----------- -----------LLLL----------- ------------LL------------ -----------JAA------------ ----------JAAAAJ---------- -----------PAAP----------- -----------JJJJ----------- ------------JJ------------ -------------------------- -------------------------- -------------------------- -------------------------- -------------------------- -------------------------- -------------------------- -------------------------- -------------------------- -------------------------- -------------------------- 
-------------------------- -------------------------- -------------------------- -------------------------- -------------------------- ------------CC------------ ----------MLLLLM---------- ----------KMLLMK---------- ----------KKMMKK---------- -----------KKKK----------- -----------KAAK----------- -----------IAAA----------- -----------AAAA----------- ----------JOAAOJ---------- ----------JRAAJJ---------- ----------HAAAAH---------- ----------OAAAAO---------- -----------IJJI----------- -----------JJJJ----------- -------------------------- -------------------------- -------------------------- -------------------------- -------------------------- -------------------------- -------------------------- -------------------------- -------------------------- -------------------------- -------------------------- 
-------------------------- -------------------------- -------------------------- -------------------------- -------------------------- ------------CC------------ ------------CC------------ -----------CCCC----------- -----------CAAC----------- ------------AAC----------- -----------GAAG----------- ----------GAAAAG---------- ----------JAAAAJ---------- ---------CLAAAALC--------- ---------EAAAAAAE--------- ---------EAAAAAAE--------- ---------EAAAAAAE--------- ---------CJAJJAJC--------- ---------CHJJJJHC--------- -------------------------- -------------------------- -------------------------- -------------------------- -------------------------- -------------------------- -------------------------- -------------------------- -------------------------- -------------------------- -------------------------- 
-------------------------- -------------------------- -------------------------- -------------------------- -------------------------- -------------------------- -------------------------- -------------------------- ------------CC------------ -----------CAAC----------- ---------GGAKKAGG--------- ---------HAAKKAAH--------- --------CCAAKKAACC-------- --------EAAAKKAAAE-------- --------EAAAAAAAAE-------- --------EAAAAAAAAE-------- -------EEAAABBAAAEE------- -------EEAAB--BAAEE------- -------ECAAB--BAACE------- -------CCHGG--GGHCC------- --------HGG----GGH-------- -------------------------- -------------------------- -------------------------- -------------------------- -------------------------- -------------------------- -------------------------- -------------------------- -------------------------- 
-------------------------- -------------------------- -------------------------- -------------------------- -------------------------- -------------------------- -------------------------- -------------------------- ----------CCCCCC---------- ---------GGAKKAGG--------- --------HAAE--EAAH-------- -------CCAAD--DAACC------- -------EAAAB--BAAAE------- -------EAABB--BBAAE------- ------EEAABKKKKBAAEE------ ------DEAAABKKBA-BED------ ------DQAAAB--BAAAAD------ ------EAAAAB--BAAAAE------ ------EAAAAB--BAAAAE------ ------EAAAAG--GAAAAE------ ------CCAAAD--DAAACC------ --------GGD----DGG-------- -------------------------- -------------------------- -------------------------- -------------------------- -------------------------- -------------------------- -------------------------- -------------------------- 
-------------------------- -------------------------- -------------------------- -------------------------- -------------------------- -------------------------- -------------------------- ----------CCCCCC---------- ----------CAKKAC---------- --------GGAC--CAGG-------- --------HAE----EAH-------- -------C-AD----DAAC------- ------EAAAB----BAAAE------ ------EAAB------BAAE------ ------D-AB------B-BD------ ------B-AAB----BA-BB------ ------BA-AAB--BAA-IB------ ------DA-AAB--BAAAAD------ ------EAAAAB--BAAAAE------ ------EAAAAG--GAAAAE------ ------CA-AAG--GA-AAC------ ------CHADDD--DDDAHC------ ------HGG--------GGH------ -------------------------- -------------------------- -------------------------- -------------------------- -------------------------- -------------------------- -------------------------- 
-------------------------- -------------------------- -------------------------- -------------------------- -------------------------- -------------------------- -------------------------- ---------DCCCCCCD--------- -------GGDAC--CADGG------- -------HAAE----EAAH------- -------CAAE----EA-C------- -------EAAD----DAAE------- -----EE-AAB----BAAAEE----- -----DAAAB------BABAD----- -----B--AB------BI-BB----- -----F--AB------BI-AF----- -----FA-AAB----BA--AF----- -----BA-AAAB--BAA-BAB----- -----DAAAAAB--BAAAAAD----- -----EBAAAB----BAAAAE----- -----E-BAAB----BAA-IE----- -----C---AAD--DAAIIIC----- -----CIADDD----DDDAIC----- -----HGG----------GGH----- -----G--------------G----- -------------------------- -------------------------- -------------------------- -------------------------- -------------------------- 
-------------------------- -------------------------- -------------------------- -------------------------- -------------------------- -------------------------- ---------CCC--CCC--------- --------DAAC--CAAD-------- ------HGAAC----CAAGH------ ------C-AE------EAAC------ ------C-AE------EA-C------ ------EAAD------DA-E------ ----DEAAAB------BA-IED---- ----BAAAB--------BBBAB---- ----F-AAB--------B--AF---- ----FAAAAB------BI-BAF---- -----BAAAB------BB-AF----- -----FAAAAB----BAB-AF----- -----BAAAAAB--BAAABAB----- ---DDBBAABB----BAAABADD--- ---DE--IAB------BBB-BED--- ----E--BABD----DB---BE---- ----C--BDDD----DDDB-BC---- ----C-ID--C----C--DGBC---- ----HGGD----------DGAH---- ----GGD------------DGG---- -------------------------- -------------------------- -------------------------- -------------------------- 
-------------------------- -------------------------- -------------------------- -------------------------- -------------------------- ---------CC----CC--------- --------CAC----CAC-------- -------DAAC----CAAD------- -----CCAAC------CA-CC----- -----CAAE--------E--C----- ----EE-AE--------E--EE---- -----DAAD--------DDID----- ---DDAAABB------BBB-ADD--- ---BAAAAB--------BABAAB--- ---FABAAB--------BB-BAF--- ----FBAAB--------BB-BF---- -----BAAB--------B-BB----- -----B-AAB------BB-BF----- -----F-AABB----BAB-BF----- ---BBBBAB-B----BAABBBBB--- --DA---HB-------BAB--FFD-- --DEC---B-------BG---IED-- ----C---DBD----DAD---C---- ----C----DD----DD----C---- ----H---------------GH---- ----G---------------GG---- ----GD--------------DG---- -------------------------- -------------------------- -------------------------- 
-------------------------- -------------------------- -------------------------- -------------------------- -------------------------- --------CCC----CCC-------- --------CAC----CAC-------- ----CHDCAC------CACDHC---- ----CAAAE--------EIIIC---- ----EAAAE--------EI--E---- ----EAAAE--------EI--E---- ----DIAAD--------DDF-D---- --BDDAAB----------B-DDDB-- --FFFFAB----------B-FFFF-- ---FF-BB----------B--FF--- ------BIB--------BB------- -----BAAB--------BB------- -----BAAAB------BB--B----- -----FAAAB------BB--F----- -----FAABBB----BBABBF----- ---E--BB---------BIF------ DDEEE--HB--------GH--EEEDD -DDEE--GAD------DGG--EEDD- ---CC---DAD----DAD---CC--- ---CC----CC----CC----CC--- ---HH----------------HH--- ---GGD--------------DGG--- ----DD--------------DD---- ----D----------------D---- -------------------------- 
-------------------------- -------------------------- -------------------------- -------------------------- ---------CC----CC--------- --------CAC----CAC-------- ----HDD-CC------CC-DDH---- ---CAAACC--------CCIIIC--- ---EAAAE----------EDDIE--- ---EAAAE----------EIIIE--- ----DDAE----------EDDD---- -----DDD----------DB------ --BD-BAB----------BF--DB-- --F---BB----------B----F-- ------BB----------B------- ------BB----------B------- ------BIB--------BB------- ----B-BAB--------BB-BB---- ----F-BAAB------BB--BF---- ----FBAAAAB----BAABBAF---- -----FBABBB----BBAAFF----- -------HH--------HH------- -------GH--------GG------- --------GD------DG-------- --------DDD----DDD-------- -------------------------- -------------------------- -------------------------- -------------------------- -------------------------- 
-------------------------- -------------------------- -------------------------- -------------------------- --------CCC----CCC-------- ----D--CAC------CAC--D---- ---CC--CC--------CC--CC--- ---CCCCC----------CCCCC--- ---EDAE-----------E--CE--- ---EEEE-----------EEDEE--- -----DE-----------ED------ -----BD-----------DB------ -----FB------------F------ -----FAB----------BF------ ------B-----------B------- ------BB----------B------- ------BB----------B------- ------BIB--------BB------- ---BB-BAB--------BB--BB--- ---FB-BAAB------BAB-BBF--- -----FF-IB------B-AFF----- -------FH--------HF------- -------HH--------HH------- -------GH-------DAG------- --------DD------DD-------- ---------C------C--------- -------------------------- -------------------------- -------------------------- -------------------------- 
-------------------------- -------------------------- -------------------------- -------CCC------CCC------- ---D---CCC------CCC---D--- --CHC--CC--------CC--CHC-- --CCC--C----------C--CCC-- --EC-CC-----------CC--CE-- --EC-EE-----------EE--CE-- ----DEE-----------EED----- ----DEE-----------EDD----- -----BD-----------DB------ -----F-------------F------ -----FB-----------BF------ -------------------------- ------B-----------B------- ------B-----------B------- ------BB----------B------- ---BB-BIB--------BB--BB--- ---FB--BIB------BAB--BF--- -------FBB------BBF------- -------F----------F------- -------HH--------HH------- -------GH--------HG------- -------DHD------DAD------- --------CD------DC-------- -------------------------- -------------------------- -------------------------- -------------------------- 
-------------------------- -------------------------- -------CCC------CCC------- ---D---CCC------CCC---D--- ---C---C----------C---C--- --CC---C----------C---CC-- --C----C----------C----C-- -----C-------------C------ -------------------------- ----D---------------D----- ----BE-------------EB----- ----BD-------------DB----- -----F-------------F------ -----F-------------F------ -------------------------- -------------------------- -------B----------B------- -------B----------B------- --BB---BB--------BB---BB-- --FB---BB--------BB---BF-- -------FBB------BBF------- -------F----------F------- -------H----------H------- -------GH--------HG------- -------GH--------HG------- -------CID------DAC------- -------CCC------CCC------- -------------------------- -------------------------- -------------------------- 
-------------------------- -------CC--------CC------- -------CC--------CC------- ---C---C----------C---C--- ---C---C----------C---C--- -------C----------C------- -------C----------C------- -------------------------- -------------------------- ----D---------------D----- ----B---------------B----- ----BB-------------BB----- -------------------------- -------------------------- -------------------------- -------------------------- -------B----------B------- -------B----------B------- --B----B----------B----B-- --F----BB--------BB----F-- --------B--------B-------- ------FF----------FF------ ------FF----------FF------ -------H----------H------- -------H----------H------- -------GD--------DG------- -------GD--------DG------- -------CC--------CC------- -------CC--------CC------- -------------------------- 
-------C----------C------- -------C----------C------- -------C----------C------- -------C----------C------- -------C----------C------- -------------------------- -------------------------- -------------------------- -------------------------- -------------------------- -------------------------- -------------------------- -------------------------- -------------------------- -------------------------- -------------------------- -------------------------- ------BB----------BB------ ------BB----------BB------ --F---BIB--------BAB---F-- -------BB--------BB------- ------FF----------FF------ ------FF----------FF------ -------H----------H------- -------H----------H------- -------H----------H------- -------GD--------DG------- -------GD--------DG------- -------GD--------DG------- --------C--------C-------- 
-------------------------- -------------------------- -------------------------- -------------------------- -------------------------- -------------------------- -------------------------- -------------------------- -------------------------- -------------------------- -------------------------- -------------------------- -------------------------- -------------------------- -------------------------- -------------------------- -------------------------- ------B------------B------ ------B------------B------ ------BB----------BB------ -------BB--------BB------- -------------------------- ------FF----------FF------ ------FF----------FF------ -------------------------- -------H----------H------- -------H----------H------- -------GD--------DG------- -------GD--------DG------- --------D--------D-------- 
-------------------------- -------------------------- -------------------------- -------------------------- -------------------------- -------------------------- -------------------------- -------------------------- -------------------------- -------------------------- -------------------------- -------------------------- -------------------------- -------------------------- -------------------------- -------------------------- -------------------------- -------------------------- ------B------------B------ ------BB----------BB------ -------B----------B------- -------------------------- ------F------------F------ ------FF----------FF------ -------------------------- -------------------------- -------------------------- -------------------------- -------------------------- -------------------------- 
-------------------------- -------------------------- -------------------------- -------------------------- -------------------------- -------------------------- -------------------------- -------------------------- -------------------------- -------------------------- -------------------------- -------------------------- -------------------------- -------------------------- -------------------------- -------------------------- -------------------------- -------------------------- -----BB------------BB----- -----BB------------BB----- -------------------------- -------------------------- ------F------------F------ ------FF----------FF------ -------------------------- -------------------------- -------------------------- -------------------------- -------------------------- -------------------------- 
-------------------------- -------------------------- -------------------------- -------------------------- -------------------------- -------------------------- -------------------------- -------------------------- -------------------------- -------------------------- -------------------------- -------------------------- -------------------------- -------------------------- -------------------------- -------------------------- -------------------------- -------------------------- -----B--------------B----- -----BB------------BB----- -------------------------- -------------------------- ------F------------F------ ------F------------F------ -------------------------- -------------------------- -------------------------- -------------------------- -------------------------- -------------------------- 
-------------------------- -------------------------- -------------------------- -------------------------- -------------------------- -------------------------- -------------------------- -------------------------- -------------------------- -------------------------- -------------------------- -------------------------- -------------------------- -------------------------- -------------------------- -------------------------- -------------------------- -------------------------- -------------------------- -----B--------------B----- -------------------------- -------------------------- -------------------------- ------F------------F------ -------------------------- -------------------------- -------------------------- -------------------------- -------------------------- -------------------------- 
