model
size = 30 25 11, scale = 0.05, origin = -y
material 
  colors = A:#E00 B:#222
voxels
---------AAAAAAAAAAAA--------- ---------AAAAAAAAAAAA--------- ---------AAAAAAAAAAAA--------- ---------AAAAAAAAAAAA--------- ---------AAABBBBBBBAA--------- ---------AABBBBBBBBBA--------- ---------ABBBBAABBBBB--------- ---------BBBBAABABBBB--------- ---------ABBABAABBBBB--------- ---------BBBAABABBABB--------- ---------BBBAAABBAABB--------- --------BBBBAAAABAABBB-------- --------ABBBBBAABBABBB-------- --------AABBBBBABBBBBA-------- --------AAABBAAAAAAABB-------- -------AAABBBAAAAABBBBA------- -------AAABBBBBBBBBBBAA------- -------AAAABBBBABBBBAAA------- -------AAAAABBBBBBBAAAA------- --------AAAAABBBBBAAAA-------- --------AAAAAAAAAAAAAA-------- ------------------------------ ------------------------------ ------------------------------ ------------------------------ 
--------AAAA------AAAA-------- --------AA----------AA-------- --------AA----------AA-------- --------AA----------AA-------- --------AA----------AA-------- --------AA----------AA-------- --------AA----------AA-------- --------AA----------AA-------- --------AA----------AA-------- --------AA----------AA-------- --------AA----------AA-------- --------AA----------AA-------- --------A------------A-------- -------AA------------AA------- -------AA------------AA------- -------AA------------AA------- ------AA--------------AA------ ------AA--------------AA------ ------AAA------------AAA------ -------AA------------AA------- -------AAAAAAAAAAAAAAAA------- --------AAAAAAAAAAAAAA-------- ------------------------------ ------------------------------ ------------------------------ 
--------A------------A-------- --------A------------A-------- --------A------------A-------- --------A------------A-------- --------A------------A-------- --------A------------A-------- --------A------------A-------- --------A------------A-------- --------A------------A-------- --------A------------A-------- --------A------------A-------- --------A------------A-------- --------A------------A-------- -------AA------------AA------- -------A--------------A------- --AAAAAA--------------AAAAAA-- --AAAAAA--------------AAAAAA-- --AAAAA----------------AAAAA-- ---AAAAA--------------AAAAA--- -----AAA--------------AAA----- ------AAA------------AAA------ -------AAAAAAAAAAAAAAAA------- --------AAAAAAAAAAAAAA-------- -------------AAAA------------- ------------------------------ 
--------A------------A-------- --------A------------A-------- --------A------------A-------- --------A------------A-------- --------A------------A-------- --------A------------A-------- --------A------------A-------- --------A------------A-------- --------A------------A-------- --------A------------A-------- --------A------------A-------- --------A------------A-------- --------A------------A-------- -------AA------------AA------- ---AA--A--------------A--AA--- ---AAAAA--------------AAAAA--- -AA------------------------AA- -AAA----------------------AAA- --AAAA------------------AAAA-- ---AAAA----------------AAAA--- ----AAAA--------------AAAA---- ------AAA------------AAA------ -------AAAAAAA--AAAAAAA------- --------AAAAAAAAAAAAAA-------- -----------AAAAAAAA----------- 
--------A------------A-------- --------A------------A-------- --------A------------A-------- --------A------------A-------- --------A------------A-------- --------A------------A-------- --------A------------A-------- --------A------------A-------- --------A------------A-------- --------A------------A-------- --------A------------A-------- --------A------------A-------- --------A------------A-------- -------AA------------AA------- ---AA--A--------------A--AA--- ----AAAA--------------AAAA---- ------------------------------ AAA------------------------AAA AAAA----------------------AAAA --AAA--------------------AAA-- ---AAAA----------------AAAA--- -----AAA--------------AAA----- ------AAA------------AAA------ -------AAAAA------AAAAA------- ---------AAAA----AAAA--------- 
--------A------------A-------- --------A------------A-------- --------A------------A-------- --------A------------A-------- --------A------------A-------- --------A------------A-------- --------A------------A-------- --------A------------A-------- --------A------------A-------- --------A------------A-------- --------A------------A-------- --------A------------A-------- --------A------------A-------- -------AA------------AA------- ---AA--A--------------A--AA--- ----AAAA--------------AAAA---- ------------------------------ ------------------------------ AAA------------------------AAA -AAA----------------------AAA- --AAAA------------------AAAA-- ----AAA----------------AAA---- -----AAA--------------AAA----- -------AAA----------AAA------- ---------AA--------AA--------- 
--------A------------A-------- --------A------------A-------- --------A------------A-------- --------A------------A-------- --------A------------A-------- --------A------------A-------- --------A------------A-------- --------A------------A-------- --------A------------A-------- --------A------------A-------- --------A------------A-------- --------A------------A-------- --------A------------A-------- -------AA------------AA------- ---AAA-A--------------A-AAA--- ----AAAA--------------AAAA---- ------------------------------ ------------------------------ AA--------------------------AA -AA------------------------AA- --AAA--------------------AAA-- ----AA------------------AA---- -----AAA--------------AAA----- -------AAA----------AAA------- ---------A----------A--------- 
--------A------------A-------- --------A------------A-------- --------A------------A-------- --------A------------A-------- --------A------------A-------- --------A------------A-------- --------A------------A-------- --------A------------A-------- --------A------------A-------- --------A------------A-------- --------A------------A-------- --------A------------A-------- --------A------------A-------- -------AA------------AA------- ---AAA-A--------------A-AAA--- ----AAAA--------------AAAA---- ------------------------------ ------------------------------ AA--------------------------AA -AAA----------------------AAA- --AAA--------------------AAA-- ----AAA----------------AAA---- -----AAA--------------AAA----- -------AAA----------AAA------- ---------AA--------AA--------- 
--------A------------A-------- --------A------------A-------- --------A------------A-------- --------A------------A-------- --------AA----------AA-------- --------AA----------AA-------- --------AA----------AA-------- --------AA----------AA-------- --------AA----------AA-------- --------AA----------AA-------- --------AA----------AA-------- --------AA----------AA-------- --------A------------A-------- -------AA------------AA------- ---AA--AA------------AA--AA--- --AAAAAA--------------AAAAAA-- --A--AAA--------------AAA--A-- AA--------------------------AA AAA------------------------AAA -AAAA--------------------AAAA- --AAAA------------------AAAA-- ----AAA----------------AAA---- -----AAAA------------AAAA----- -------AAA----------AAA------- ---------AAA------AAA--------- 
--------A------------A-------- --------AA----------AA-------- --------AA----------AA-------- --------AAAAAAAAAAAAAA-------- --------AAAAAAAAAAAAAA-------- ---------AAAAAAAAAAAA--------- ---------AAAAAAAAAAAA--------- ---------AAAAAAAAAAAA--------- ---------AAAAAAAAAAAA--------- ---------AAAAAAAAAAAA--------- ---------AAAAAAAAAAAA--------- --------AAAAAAAAAAAAAA-------- --------AAAAAAAAAAAAAA-------- --------AA----------AA-------- -------AA------------AA------- --AAAA-AA------------AA-AAAA-- --AAAAAAA------------AAAAAAA-- -AAAAAAA--------------AAAAAAA- -AAAAAAA--------------AAAAAAA- --AAAAAA--------------AAAAAA-- ----AAAA--------------AAAA---- -----AAAA------------AAAA----- ------AAA------------AAA------ --------AAAAAAAAAAAAAA-------- ---------AAAAAAAAAAAA--------- 
--------AAAAAAAAAAAAAA-------- --------AAAAAAAAAAAAAA-------- --------AAAAAAAAAAAAAA-------- --------AAAAAAAAAAAAAA-------- ------------------------------ ------------------------------ ------------------------------ ------------------------------ ------------------------------ ------------------------------ ------------------------------ ------------------------------ ---------AAAAAAAAAAAA--------- --------AAAAAAAAAAAAAA-------- --------AAAAAAAAAAAAAA-------- --------AAAAAAAAAAAAAA-------- -------AAAAAAAAAAAAAAAA------- -------AAAAAAAAAAAAAAAA------- -------AAAAAAAAAAAAAAAA------- -------AAAAAAAAAAAAAAAA------- -------AAAAAAAAAAAAAAAA------- -------AAAAAAAAAAAAAAAA------- --------AAAAAAAAAAAAAA-------- --------AAAAAAAAAAAAAA-------- ------------------------------ 
