model
size = 10 32 17, scale = 0.05, origin = -y
material 
  colors = A:#4C1566 B:#4F1869 C:#97E2A7 D:#87EB95
voxels
5-D2C7-2AB306-2CDCD5-B2-2A6-BA296-C2D3CD4-B-2AB5-AB2A295-2C2DC2D3-B5-A4-ABA2B294-3D2CDC3-B5-B2(4-A)5-2(BA)7-2B276-6C3-AB4-B3-B4(A4-)2A2-A6-3B176-DC8-DC78-2(C2D)2(4-A)2(3-2A4-B)4-B2A-B5-A2B-B5-2B2A7-2BA145-3D7-D2-C5-DC2-DC4-DC3DC3-2CD-2D2C2-CD3-D2C2-D5-CD35-2C2D2C2(4-A4-B)3-A2B2A-A3-BA2-BA5-B2-AB5-4B6-AB-A6-AB2A7-BA8-AB8-BA8-2A8-BA8-2B8-BA8-2A8-AB8-BA7-2AB6-BA2B5-CB2AB4-2C2-A2D3-2D-3BD3-DA-BABD3-D-3BA-D2-C-AC2A-D2-C-D3C-C2-2C3-D-D8-CD9-D16-3CD5-2(DC)DA4-A-2A-A4-2A2-B4-2A3-B4-BA2-AB5-B2-2A5-A-2A6-3AB6-4A6-4B5-A2BAB5-2AB-B5-ABA-A5-2BABA5-B2ABA5-A4B5-2ABAB5-ABA2B5-B4A4-3A-3A2-D-2B3AB-CB-BA-CDC-DA-B3-DC-DB-A3-CD-DBA4-2C-C-B4-C-2C-B4-D-2DCD4-C-C6-C-C8-CD9-D25-3D2C5-B-B2A5-2B2-A4-2B3-B2(4-2B2-2A)4-AB2-2B4-2B2(-B)4-AB2-2A4-AB2-AB4-B2(A-)B4-2A-A-B4-BA2-2A4-BA2-BA3-2A3-2B3-AB3-2B3-BA3-A4-AB3-2B2-2AB3-AB-2CD5-C-D-B5-D-CAB5-DCDBA5-3DA6-2DCB6-2DCA6-4D5-2(C-C7-)D-D7-2C25-CD3C5-DCD2C5-2B2-A5-B2(3-B4-2B)2-2A4-AB2-2B4-BA2-2B4-2A2-2A4-2B2-BA4-2A2-AB4-2A2-2B4-AB2-2B4-B3-2B3-AB4-B3-2B4-A3-A5-B3-A5-A2-AB5-A-D-C5-2(D-)B5-D2CA6-2DCA6-2CDA6-CDC2(A6-DCD)C6-CD8-CD7-D-C7-D2C34-5C5-2(AB)A5-A2-AB5-A2-2A5-A2-2B5-A2-2A5-A2-BA4-BA2(2-A5-AB)2-A5-2A2-2A4-2B2-2A4-A3-2B2(4-B)3-BA4-A3-2B4-A3-A4-AB2-2B5-A2C-D5-D2CA6-DCDB2(7-DCA)7-2CA7-CDA7-3C6-2D2(8-CD)8-2C34-C3D6-3BA6-A2(2-BA5-B)2-AB5-AB-B6-A3B6-BA-B6-2B2A6-2BAB5-A-2BA5-B-ABA5-AB2A-A4-BA2-2A4-2B2-2B3-AB3-BA3-2A3-AB2-BA5-BC-BA5-3C-D5-2DCDC5-D2(2CA7-DCA7-)D2C6-2C2(8-2D)8-DC5-DC8-2C8-CD7-CD-C6-A2-B6-A2BA6-A2-B6-B2-A6-2B2A6-A2-B6-2(BA)6-4A6-BA2B6-2A2B6-A2-A6-B-2B6-2(BA)5-A-BA-A4-BA2-2B3-B-A2-2(BA3-)AB2-A-B4-D2-CD5-2C-CD5-2DC-A5-2CD2(7-2DC)B6-2C-C6-DC7-D-C7-C-D7-CD6-2(CD8-)2D8-2D7-2(A2-A6-)2B2A6-B3A6-2(AB)7-AB9-A38-2(2B8-)2A7-A2BA6-2BAB5-2A2BA5-A4B4-B-2BAD3-D-BA2-CD2-DCB3-2D2-C-B3-2D2-2C4-2(D-)C5-C-D-C5-D-C3(7-D-D)8-C46-BA7-2A2B6-2(AB)136-ABA6-A2BAB4-D4AB4-C-2ABA3-2C-2DC-C2-D-4C-D2-CD3C2DC6-CA-C7-D-C7-3D8-2D234-DC8-DCD6-2D4C4-3D2CD4-2C2DCDC6-2C2D7-2C32-
