model
size = 24 27 32, scale = 0.05, origin = -y
material 
  colors = A:#1D44EE B:#DDD C:#000 D:#FAFAFA E:#E00 F:#111
voxels
560-2(10A14-)10A567-8A15-A8-A10-4CB8-B4C10-10A15-8A544-8A11-4CA7-2A4C5-5CB8-B5C5-4C10A4C11-8A563-C3-10A3-C5-3C2-10A2-3C5-C3-10A3-C229-D2-D20-D2-D19-3(6A18-)6A68-2F22-FA44-3(6A18-)6A12-C16-C5-3C14-3C5-C16-C227-2(D6-D16-)2A4-2A3(16-8A)17-6C19-2(4E20-)4E19-6C17-3(8A16-)2A4-2A9-5A13-4A2-A3BA13-AB2A2-5A13-4A57-3(8A16-)D-D2-D-D16-D-D2-D-D111-3(3A4-3A14-)3A4-3A15-2C4A2C18-E2BE19-C3BE20-E2BE18-C6AC16-2(A6-2A15-)A6-2A9-3A3-A6-2(2A3-)3A-A13-AB2A2-A2B-A13-A-2A2-A3BA13-4A3-3A15-2A11-6A17-8A16-A6BA16-8A17-6A136-2A6-2A14-3A4-B2A14-3A-2A-B2A14-3A3B2-2A14-3C5A2C15-2AB2-BA17-2AB3-A17-2AB2-BA17-CA3C2A2C14-2A-4A-2A14-2(2A2-)2A14-2A6-2A9-3A2-2A7-A3-2A3-5A2(13-AB2A2-A3BA)13-4A3-3A15-2A11-6A17-A6-A14-2CB6-B2C14-A6-A17-6A135-2A8-2A12-3A6-3A12-3A2-2A2-3A12-4A4B-3A12-8CA2C15-2(2A4-A17-)2A4-A16-2CA2C-2A2C14-2A-4A-3A13-2(2A2-)3A13-2A6-3A8-3A2-A8-2A2-2A3-5A13-2(A2-)A3BA13-2(A2-)A2B-A13-4A3-3A15-2A11-6A15-2C8A2C11-3CB6-B3C11-2C8A2C15-6A135-3(A10-A12-)A3-4A3-A12-C2-A4BA-2C15-AB3-A18-A4-A18-AB3-A16-C2A3B2A-2C13-2A-4A2-2(2A13-2A7-)2A8-3A2-A8-2A2-2A3-5A2(13-2(A2-)A3BA)13-4A3-3A15-2A32-C-8A-C11-2C-8A-2C11-C-8A-C233-2A21-A2(2B2A18-2A)2-BA18-2AB-BA18-2A2B2A20-2A61-3A15-2A3-5A2(13-A-2A2-A3BA)13-4A3-3A15-2A32-C10-C11-2C10-2C11-C10-C257-2C22-2C21-4C20-4C21-2C85-3A20-5A13-4A2-A2B-A13-AB2A2-A3BA13-4A3-3A47-3(4A8-)A2BA2(8-4A)86-7(4A20-)4A45-2C22-2C13-3A6-2C13-3A21-3A68-5A14-C4-A3BA14-2C3-5A14-C32-2A10-2A9-AB2A8-4A3(8-A2BA)8-4A9-2A10-2A39-4A19-7(6A18-)6A20-2A21-3(4A12-3A5-)4A12-3A70-C22-3C22-C49-2A10-2A9-AB2A3(8-A2-A)8-A2BA8-4A9-2A10-2A16-2A21-4A19-7(6A18-)6A17-8A14-A3-4A12-3A-A2-6A9-DA3B-A2-6A9-DA2B2-A3-4A10-D4A22-2C22-C22-3C22-C73-2A10-2A9-AB2A3(8-A2-A)8-A2BA8-4A9-2A-11A13-8A16-8A17-7(6A18-)6A16-10A9-3A-11A8-4A-11A7-D3A-B11A6-5A-B11A7-D6A3-5A11-3C21-3C22-C97-2A10-2A9-AB2A3(8-A2-A)8-A2BA-2C2-2C-4A9-2A-11A10-2A-8A16-8A17-6A13-2(13A11-)13A16-6A17-2(8A16-)8A15-10A13-10ABA8-3A-10ABA6-D5A-11A6-D16A7-D5A-10A10-C6-5A12-C144-2(4A8-)A-BA8-A2BA8-A-BA-2C2-2C-4A8-2AB9A12-A2B9A16-8A11-14A9-DA-2B11AD7-DA-3B10AD7-DA4B10AD9-13A15-2(8A16-)8A15-11A13-9AB2AD6-3A-10AB2AD6-3A-13AD6-3A-12A8-3A-11A17-5A157-3A21-A2BA9-2C9-A-BA20-A2-9A12-A2-9A13-2C-8A11-2A2B10A9-D15AD6-4A2B13A6-D15AD9-13A15-2(8A16-)8A15-11A13-9AB2AD11-9ABAB2A5-3A-13AD6-3A-12A8-3A2-10A17-5A181-3A21-4A20-12A12-12A16-8A11-3A2B9A9-2(D15AD7-)DA4B10AD9-13A15-2(8A16-)8A15-11A13-2(9AB2AD11-)12AD11-11A13-10A17-5A210-2C2-2C14-2A-8A13-2A-8A16-8A12-3(13A11-)13A39-3(8A16-)9A14-11A2(13-9ABA)13-10A15-9A17-5A210-2C2-2C17-11(8A16-)9A15-8A16-2(9A15-)9A16-7A18-5A233-11(8A16-)2A6BA16-5ABA16-6A-BA15-6A-BA16-A2B2ABA18-5A20-3A261-3A21-3A20-5A18-2A2-3A15-3A4-4A13-AB6AB2A13-3A4-4A15-AB3-BA18-A3BA19-A2B2A18-AB2A2BA17-5ABA16-6A-BA15-6A-BA16-A2B2ABA18-A2B2A20-3A285-3A20-5A18-A5BA17-A4-BA15-2AB4-2B2A15-A4-BA17-AB2-2BA18-A3BA19-A2B2A18-AB2A2BA17-5ABA16-6A-2A15-6A-2A16-A2B2ABA18-A2B2A20-3A309-3A19-2(7A17-)2A2-3A17-3A-3A17-7A18-5A19-A2B2A18-AB2A2BA17-5ABA16-6A-2A16-5A-A17-A2B2ABA18-A2B2A20-3A333-3C20-C3DC19-CDADC19-C3DC20-3C44-5A18-AB2A2BA17-5AB2(A17-5A-)A17-A2B2ABA18-AB-2A20-3A357-3D21-D-D21-3D68-5A18-AB2A2BA17-5ABA17-5A-A17-A3BA-A17-A5BA18-A2B2A20-3A476-5A18-2(A2B)A17-AB3ABA17-AB3A-A17-A3BA-A17-A2B2-BA18-A2B2A20-3A477-3A19-2ABAB2A17-AB3AB2(A17-5A-)A17-AB3-BA18-A2B2A20-3A477-3A19-2A3B2A3(17-AB3ABA)17-2A3B2A19-ABA22-A479-A22-3A20-5D19-D3-D19-5D20-3A22-A154-
