model
size = 17 11 28, scale = 0.05, origin = -y
material 
  colors = A:#131313
voxels
----------------- ----------------- ----------------- ------AAAAA------ ----------------- ----------------- ----------------- ----------------- ----------------- ----------------- ----------------- 
----------------- ----------------- ----AA-----AA---- ------AAAAA------ ----------------- ----------------- ----------------- ----------------- ----------------- ----------------- ----------------- 
----------------- ---A---------A--- ----AA-----AA---- ------AAAAA------ ----------------- ----------------- ----------------- ----------------- ----------------- ----------------- ----------------- 
----------------- --AA---------AA-- ----AA-----AA---- ------AAAAA------ ----------------- ----------------- ----------------- ----------------- ----------------- ----------------- ----------------- 
-A-------------A- --AA---------AA-- ----AA-----AA---- ------AAAAA------ ----------------- ----------------- ----------------- ----------------- ----------------- ----------------- ----------------- 
-A-------------A- --AA---------AA-- ----AA-----AA---- ------AAAAA------ ----------------- ----------------- ----------------- ----------------- ----------------- ----------------- ----------------- 
-A-------------A- --AA---------AA-- ----AA-----AA---- ------AAAAA------ ----------------- ----------------- ----------------- ----------------- ----------------- ----------------- ----------------- 
-A-------------A- --AA---------AA-- ----AA-----AA---- ------AAAAA------ ----------------- ----------------- ----------------- ----------------- ----------------- ----------------- ----------------- 
-A-------------A- --AA---------AA-- ----AA-----AA---- ------AAAAA------ ----------------- ----------------- ----------------- ----------------- ----------------- ----------------- ----------------- 
-A-------------A- --AA---------AA-- ----AA-----AA---- ------AAAAA------ -------AAA------- ----------------- ----------------- ----------------- ----------------- ----------------- ----------------- 
AA-------------AA --AA---------AA-- ---AAA-----AAA--- ----AAAAAAAAA---- ----AAAAAAAAA---- -----AAAAAAA----- -------AAA------- ----------------- ----------------- ----------------- ----------------- 
AA-------------AA --AA---------AA-- --AAAA-----AAAA-- --AAAA-----AAAA-- ---AAAAAAAAAAA--- ---AAAAAAAAAAA--- ----AAAAAAAAA---- ------AAAAA------ ----------------- ----------------- ----------------- 
AA-------------AA -AAA---------AAA- -AAA---------AAA- -AAA---------AAA- --AAAA-----AAAA-- --AAAA-----AAAA-- ---AAAAAAAAAAA--- ----AAAAAAAAA---- ------AAAAA------ ----------------- ----------------- 
AAA------------AA AAA-----------AAA AAAA---------AAAA -AAA---------AAA- -AAA---------AAA- -AAA---------AAA- --AAAAAAAAAAAAA-- ---AAAAAAAAAAA--- ----AAAAAAAAA---- -------AAA------- ----------------- 
AA-------------AA A---------------A AA-------------AA AA-------------AA AAA-A-------A-AAA -AA-A-------A-AA- -AAAA-------AAAA- --AAAA-----AAAA-- ---AAAAAAAAAAA--- -----AAAAAAA----- ----------------- 
AA-------------AA A---------------A AA-------------AA AA-------------AA AAA-----------AAA AAA-----------AAA -AAA-A-----A-AAA- --AAAA-----AAAA-- ---AAA-----AAA--- ----AAAAAAAAA---- -------AAA------- 
AA-------------AA A---------------A A---------------A A---------------A AA-------------AA AA-------------AA -AAA---------AAA- -AAA---------AAA- --AAA-A---A-AAA-- ----AAAAAAAAA---- ------AAAAA------ 
AA-------------AA A---------------A A---------------A A---------------A AA-------------AA AA-------------AA AAAA---------AAAA -AAA---------AAA- --AAA--AAA--AAA-- ---AAAAAAAAAAA--- -----AAAAAAA----- 
AA-------------AA A---------------A A---------------A A---------------A AA-------------AA AA-------------AA AAAA---------AAAA -AAA---------AAA- --AAA--AAA--AAA-- ---AAAAAAAAAAA--- -----AAAAAAA----- 
AA-------------AA A---------------A A---------------A A---------------A AA-------------AA AA-------------AA AAAA---------AAAA -AAA---------AAA- --AAA--AAA--AAA-- ---AAAAAAAAAAA--- -----AAAAAAA----- 
AA-------------AA A---------------A A---------------A A---------------A AA-------------AA AA-------------AA -AAA---------AAA- -AAA---------AAA- --AAA-A---A-AAA-- ----AAAAAAAAA---- ------AAAAA------ 
AA-------------AA A---------------A AA-------------AA AA-------------AA AAA-----------AAA AAA-----------AAA -AAA-A-----A-AAA- --AAAA-----AAAA-- ---AAA-----AAA--- ----AAAAAAAAA---- -------AAA------- 
AA-------------AA A---------------A AA-------------AA AA-------------AA AAA-A-------A-AAA -AA-A-------A-AA- -AAAA-------AAAA- --AAAA-----AAAA-- ---AAAAAAAAAAA--- -----AAAAAAA----- ----------------- 
AAA-----------AAA AAA-----------AAA AAAA---------AAAA -AAA---------AAA- -AAA---------AAA- -AAA---------AAA- --AAAAAAAAAAAAA-- ---AAAAAAAAAAA--- ----AAAAAAAAA---- -------AAA------- ----------------- 
-AAA---------AAA- -AAA---------AAA- -AAA---------AAA- -AAA---------AAA- --AAAA-----AAAA-- --AAAA-----AAAA-- ---AAAAAAAAAAA--- ----AAAAAAAAA---- ------AAAAA------ ----------------- ----------------- 
--AAA-------AAA-- --AA---------AA-- --AAAA-----AAAA-- --AAAA-----AAAA-- ---AAAAAAAAAAA--- ---AAAAAAAAAAA--- ----AAAAAAAAA---- ------AAAAA------ ----------------- ----------------- ----------------- 
---AA-------AA--- ---AA-------AA--- ---AAA-----AAA--- ----AAA---AAA---- ----AAAAAAAAA---- -----AAAAAAA----- -------AAA------- ----------------- ----------------- ----------------- ----------------- 
-----AAAAAAA----- ----------------- ----------------- ----------------- ----------------- ----------------- ----------------- ----------------- ----------------- ----------------- ----------------- 
