model
size = 28 12 18, scale = 0.05, origin = -y
material 
  colors = A:#111 B:#369 C:#336 D:#036 E:#339 F:#366
voxels
-----AAAAAAAAAAAAAAAAAA----- -----AAAAAAAAAAAAAAAAAA----- -----AAAAAAAAAAAAAAAAAA----- -----AAAAAAAAAAAAAAAAAA----- -----AAAAAAAAAAAAAAAAAA----- -----AAAAAAAAAAAAAAAAAA----- -----AAAAAAAAAAAAAAAAAA----- -----AAAAAAAAAAAAAAAAAA----- -----AAAAAAAAAAAAAAAAAA----- -----AAAAAAAAAAAAAAAAAA----- -----BEEBBBBBEDCCCDDCCC----- -----BBFCAAAACAAAAAACAD----- 
---AAAAAAAAAAAAAAAAAAAAAA--- ---AAAAAAAAAAAAAAAAAAAAAA--- ---AAAAAAAAAAAAAAAAAAAAAA--- ---AAAAAAAAAAAAAAAAAAAAAA--- ---AAAAAAAAAAAAAAAAAAAAAA--- ---AAAAAAAAAAAAAAAAAAAAAA--- ---AAAAAAAAAAAAAAAAAAAAAA--- ---AAAAAAAAAAAAAAAAAAAAAA--- ---AAAAAAAAAAAAAAAAAAAAAA--- ---AAAAAAAAAAAAAAAAAAAAAA--- ---BBAAAAAAAAAAAAAAAAAADA--- ---ABAAAAAAAAAAAAAAAAAAAA--- 
--AAAAAAAAAAAAAAAAAAAAAAAA-- --AAAAAAAAAAAAAAAAAAAAAAAA-- --AAAAAAAAAAAAAAAAAAAAAAAA-- --AAAAAAAAAAAAAAAAAAAAAAAA-- --AAAAAAAAAAAAAAAAAAAAAAAA-- --AAAAAAAAAAAAAAAAAAAAAAAA-- --AAAAAAAAAAAAAAAAAAAAAAAA-- --AAAAAAAAAAAAAAAAAAAAAAAA-- --AAAAAAAAAAAAAAAAAAAAAAAA-- --AAAAAAAAAAAAAAAAAAAAAAAA-- --AAAAAAAAAAAAAAAAAAAAAAAA-- --AAAAAAAAAAAAAAAAAAAAAAAA-- 
-AAAA------------------AAAA- -AAAA------------------AAAA- -AAAA------------------AAAA- -AAAA------------------AAAA- -AAAA------------------AAAA- -AAAA------------------AAAA- -AAAA------------------AAAA- -AAAA------------------AAAA- -AAAA------------------AAAA- -AAAA------------------AAAA- -AAAA------------------AAAA- -AAAA------------------AAAA- 
AAAAA------------------AAAAA AAAAA------------------AAAAA AAAAA------------------AAAAA AAAAA------------------AAAAA AAAAA------------------AAAAA AAAAA------------------AAAAA AAAAA------------------AAAAA AAAAA------------------AAAAA AAAAA------------------AAAAA AAAAA------------------AAAAA AAAAA------------------AAAAA AAAAA------------------AAAAA 
AAAA--------------------AAAA AAAA--------------------AAAA AAAA--------------------AAAA AAAA--------------------AAAA AAAA--------------------AAAA AAAA--------------------AAAA AAAA--------------------AAAA AAAA--------------------AAAA AAAA--------------------AAAA AAAA--------------------AAAA AAAA--------------------AAAA AAAA--------------------AAAA 
AAAA--------------------AAAA AAAA--------------------AAAA AAAA--------------------AAAA AAAA--------------------AAAA AAAA--------------------AAAA AAAA--------------------AAAA AAAA--------------------AAAA AAAA--------------------AAAA AAAA--------------------AAAA AAAA--------------------AAAA AAAA--------------------AAAA AAAA--------------------AAAA 
AAAA--------------------AAAA AAAA--------------------AAAA AAAA--------------------AAAA AAAA--------------------AAAA AAAA--------------------AAAA AAAA--------------------AAAA AAAA--------------------AAAA AAAA--------------------AAAA AAAA--------------------AAAA AAAA--------------------AAAA AAAA--------------------AAAA AAAA--------------------AAAA 
AAAA--------------------AAAA AAAA--------------------AAAA AAAA--------------------AAAA AAAA--------------------AAAA AAAA--------------------AAAA AAAA--------------------AAAA AAAA--------------------AAAA AAAA--------------------AAAA AAAA--------------------AAAA AAAA--------------------AAAA AAAA--------------------AAAA AAAA--------------------AAAA 
AAAA--------------------AAAA AAAA--------------------AAAA AAAA--------------------AAAA AAAA--------------------AAAA AAAA--------------------AAAA AAAA--------------------AAAA AAAA--------------------AAAA AAAA--------------------AAAA AAAA--------------------AAAA AAAA--------------------AAAA AAAA--------------------AAAA AAAA--------------------AAAA 
AAAA--------------------AAAA AAAA--------------------AAAA AAAA--------------------AAAA AAAA--------------------AAAA AAAA--------------------AAAA AAAA--------------------AAAA AAAA--------------------AAAA AAAA--------------------AAAA AAAA--------------------AAAA AAAA--------------------AAAA AAAA--------------------AAAA AAAA--------------------AAAA 
AAAA--------------------AAAA AAAA--------------------AAAA AAAA--------------------AAAA AAAA--------------------AAAA AAAA--------------------AAAA AAAA--------------------AAAA AAAA--------------------AAAA AAAA--------------------AAAA AAAA--------------------AAAA AAAA--------------------AAAA AAAA--------------------AAAA AAAA--------------------AAAA 
AAAAA------------------AAAAA AAAAA------------------AAAAA AAAAA------------------AAAAA AAAAA------------------AAAAA AAAAA------------------AAAAA AAAAA------------------AAAAA AAAAA------------------AAAAA AAAAA------------------AAAAA AAAAA------------------AAAAA AAAAA------------------AAAAA AAAAA------------------AAAAA AAAAA------------------AAAAA 
-AAAA------------------AAAA- -AAAA------------------AAAA- -AAAA------------------AAAA- -AAAA------------------AAAA- -AAAA------------------AAAA- -AAAA------------------AAAA- -AAAA------------------AAAA- -AAAA------------------AAAA- -AAAA------------------AAAA- -AAAA------------------AAAA- -AAAA------------------AAAA- -AAAA------------------AAAA- 
--AAAA----------------AAAA-- --AAAA----------------AAAA-- --AAAA----------------AAAA-- --AAAA----------------AAAA-- --AAAA----------------AAAA-- --AAAA----------------AAAA-- --AAAA----------------AAAA-- --AAAA----------------AAAA-- --AAAA----------------AAAA-- --AAAA----------------AAAA-- --AAAA----------------AAAA-- --AAAA----------------AAAA-- 
---AAAAA------------AAAAA--- ---AAAAA------------AAAAA--- ---AAAAA------------AAAAA--- ---AAAAA------------AAAAA--- ---AAAAA------------AAAAA--- ---AAAAA------------AAAAA--- ---AAAAA------------AAAAA--- ---AAAAA------------AAAAA--- ---AAAAA------------AAAAA--- ---AAAAA------------AAAAA--- ---AAAAA------------AAAAA--- ---AAAAA------------AAAAA--- 
----AAAAAAAAAAAAAAAAAAAA---- ----AAAAAAAAAAAAAAAAAAAA---- ----AAAAAAAAAAAAAAAAAAAA---- ----AAAAAAAAAAAAAAAAAAAA---- ----AAAAAAAAAAAAAAAAAAAA---- ----AAAAAAAAAAAAAAAAAAAA---- ----AAAAAAAAAAAAAAAAAAAA---- ----AAAAAAAAAAAAAAAAAAAA---- ----AAAAAAAAAAAAAAAAAAAA---- ----AAAAAAAAAAAAAAAAAAAA---- ----AAAAAAAAAAAAAAAAAAAA---- ----AAAAAAAAAAAAAAAAAAAA---- 
------AAAAAAAAAAAAAAAA------ ------AAAAAAAAAAAAAAAA------ ------AAAAAAAAAAAAAAAA------ ------AAAAAAAAAAAAAAAA------ ------AAAAAAAAAAAAAAAA------ ------AAAAAAAAAAAAAAAA------ ------AAAAAAAAAAAAAAAA------ ------AAAAAAAAAAAAAAAA------ ------AAAAAAAAAAAAAAAA------ ------AAAAAAAAAAAAAAAA------ ------AAAAAAAAAAAAAAAA------ ------AAAAAAAAAAAAAAAA------ 
