model
size = 12 19 12, scale = 0.05, origin = -y
material 
  colors = A:#1C1D20
voxels
---AAAAAA--- ---AAAAAA--- ---AAAAAA--- ---AAAAAA--- ---AAAAAA--- ---AAAAAA--- ---AAAAAA--- ---AAAAAA--- ---AAAAAA--- ---AAAAAA--- ---AAAAAA--- ---AAAAAA--- ---AAAAAA--- ---AAAAAA--- ------------ ------------ ------------ ------------ ------------ 
-AA------AA- -AA------AA- -AA------AA- -AA------AA- -AA------AA- -AA------AA- -AA------AA- -AA------AA- -AA------AA- -AA------AA- -AA------AA- -AA------AA- -AA------AA- -AA------AA- ---AAAAAA--- ---AAAAAA--- ---AAAAAA--- ---AAAAAA--- ------------ 
-A--------A- -A--------A- -A--------A- -A--------A- -A--------A- -A--------A- -A--------A- -A--------A- -A--------A- -A--------A- -A--------A- -A--------A- -A--------A- -A--------A- --A------A-- --A------A-- --A------A-- --A------A-- ---AAAAAA--- 
A----------A A----------A A----------A A----------A A----------A A----------A A----------A A----------A A----------A A----------A A----------A A----------A A----------A A----------A -A--------A- -A--------A- -A--------A- -A--------A- --AA----AA-- 
A----------A A----------A A----------A A----------A A----------A A----------A A----------A A----------A A----------A A----------A A----------A A----------A A----------A A----------A -A--------A- -A--------A- -A--------A- -A--------A- --A------A-- 
A----------A A----------A A----------A A----------A A----------A A----------A A----------A A----------A A----------A A----------A A----------A A----------A A----------A A----------A -A--------A- -A--------A- -A--------A- -A--------A- --A------A-- 
A----------A A----------A A----------A A----------A A----------A A----------A A----------A A----------A A----------A A----------A A----------A A----------A A----------A A----------A -A--------A- -A--------A- -A--------A- -A--------A- --A------A-- 
A----------A A----------A A----------A A----------A A----------A A----------A A----------A A----------A A----------A A----------A A----------A A----------A A----------A A----------A -A--------A- -A--------A- -A--------A- -A--------A- --A------A-- 
A----------A A----------A A----------A A----------A A----------A A----------A A----------A A----------A A----------A A----------A A----------A A----------A A----------A A----------A -A--------A- -A--------A- -A--------A- -A--------A- --AA----AA-- 
-A--------A- -A--------A- -A--------A- -A--------A- -A--------A- -A--------A- -A--------A- -A--------A- -A--------A- -A--------A- -A--------A- -A--------A- -A--------A- -A--------A- --A------A-- --A------A-- --A------A-- --A------A-- ---AAAAAA--- 
-AA------AA- -AA------AA- -AA------AA- -AA------AA- -AA------AA- -AA------AA- -AA------AA- -AA------AA- -AA------AA- -AA------AA- -AA------AA- -AA------AA- -AA------AA- -AA------AA- ---AAAAAA--- ---AAAAAA--- ---AAAAAA--- ---AAAAAA--- ------------ 
---AAAAAA--- ---AAAAAA--- ---AAAAAA--- ---AAAAAA--- ---AAAAAA--- ---AAAAAA--- ---AAAAAA--- ---AAAAAA--- ---AAAAAA--- ---AAAAAA--- ---AAAAAA--- ---AAAAAA--- ---AAAAAA--- ---AAAAAA--- ------------ ------------ ------------ ------------ ------------ 
