model
size = 14 31 14, scale = 0.05, origin = -y
material 
  colors = A:#1C1D20
voxels
-------------- -------------- -------------- -------------- ------AA------ ----AAAAAA---- ----AAAAAA---- ----AAAAAA---- ----AAAAAA---- ----AAAAAA---- ----AAAAAA---- ----AAAAAA---- ----AAAAAA---- ----AAAAAA---- ----AAAAAA---- ----AAAAAA---- ----AAAAAA---- ----AAAAAA---- ----AAAAAA---- ----AAAAAA---- ----AAAAAA---- ----AAAAAA---- ----AAAAAA---- ----AAAAAA---- ----AAAAAA---- ----AAAAAA---- ------AA------ -------------- -------------- -------------- -------------- 
-------------- -------------- -------------- ----AAAAAA---- ---AAAAAAAA--- ---AA----AA--- --AA-----AAA-- --AA------AA-- --AA------AA-- --AA------AA-- --AA------AA-- --AA------AA-- --AA------AA-- --AA------AA-- --AA------AA-- --AA------AA-- --AA------AA-- --AA------AA-- --AA------AA-- --AA------AA-- --AA------AA-- --AA------AA-- --AA------AA-- --AA------AA-- --AA-----AAA-- ---AA----AA--- ---AAAAAAAA--- ----AAAAAA---- -------------- -------------- -------------- 
-------------- -------------- ----AAAAAA---- ---AA----AA--- --AAA----AAA-- --AAA----AAA-- -A--------AAA- -A----------A- -A----------A- -A----------A- -A----------A- -A----------A- -A----------A- -A----------A- -A----------A- -A----------A- -A----------A- -A----------A- -A----------A- -A----------A- -A----------A- -A----------A- -A----------A- -A---------AA- -A--------AA-- --AAA----AAA-- --AAA----AAA-- ---AA----AA--- ----AAAAAA---- -------------- -------------- 
-------------- -------------- ---AAAAAAAA--- --AAA----AAA-- --AAA----AAA-- -AAA------AAA- -A---------AA- -A----------A- -A----------A- -A----------A- -A----------A- -A----------A- -A----------A- -A----------A- -A----------A- -A----------A- -A----------A- -A----------A- -A----------A- -A----------A- -A----------A- -A----------A- -A----------A- -A----------A- -A---------AA- -AAA------AAA- --AAA----AAA-- --AAA----AAA-- ---AAAAAAAA--- -------------- -------------- 
-------------- ----AAAAAA---- ---AA----AA--- --AAA----AAA-- -AAA------AAA- -AA--------AA- A-----------AA A------------A A------------A A------------A A------------A A------------A A------------A A------------A A------------A A------------A A------------A A------------A A------------A A------------A A------------A A------------A A------------A A------------A A-----------A- -AA--------AA- -AAA------AAA- --AAA----AAA-- ---AA----AA--- ----AAAAAA---- -------------- 
------AA------ ----AAAAAA---- --AAA----AAA-- --AA------AA-- -AA--------AA- -A----------A- A------------A A------------A A------------A A------------A A------------A A------------A A------------A A------------A A------------A A------------A A------------A A------------A A------------A A------------A A------------A A------------A A------------A A------------A A------------A -A----------A- -AA--------AA- --AA------AA-- --AAA----AAA-- ----AAAAAA---- ------AA------ 
-----AAAA----- ---AAAAAAAA--- --AA------AA-- -AA--------AA- -A----------A- A------------A A------------A A------------A A------------A A------------A A------------A A------------A A------------A A------------A A------------A A------------A A------------A A------------A A------------A A------------A A------------A A------------A A------------A A------------A A------------A A------------A -A----------A- -AA--------AA- --AA------AA-- ---AAAAAAAA--- -----AAAA----- 
-----AAAA----- ---AAAAAAAA--- --AA------AA-- -AA--------AA- -A----------A- A------------A A------------A A------------A A------------A A------------A A------------A A------------A A------------A A------------A A------------A A------------A A------------A A------------A A------------A A------------A A------------A A------------A A------------A A------------A A------------A A------------A -A----------A- -AA--------AA- --AA------AA-- ---AAAAAAAA--- -----AAAA----- 
------AA------ ----AAAAAA---- --AAA----AAA-- --AA------AA-- -AA--------AA- -A----------A- A------------A A------------A A------------A A------------A A------------A A------------A A------------A A------------A A------------A A------------A A------------A A------------A A------------A A------------A A------------A A------------A A------------A A------------A A------------A -A----------A- -AA--------AA- --AA------AA-- --AAA----AAA-- ----AAAAAA---- ------AA------ 
-------------- ----AAAAAA---- ---AA----AA--- --AAA----AAA-- -AAA------AAA- -AA--------AA- A-----------AA A------------A A------------A A------------A A------------A A------------A A------------A A------------A A------------A A------------A A------------A A------------A A------------A A------------A A------------A A------------A A------------A A------------A A-----------A- -AA--------AA- -AAA------AAA- --AAA----AAA-- ---AA----AA--- ----AAAAAA---- -------------- 
-------------- -------------- ---AAAAAAAA--- --AAA----AAA-- --AAA----AAA-- -AAA------AAA- -A---------AA- -A----------A- -A----------A- -A----------A- -A----------A- -A----------A- -A----------A- -A----------A- -A----------A- -A----------A- -A----------A- -A----------A- -A----------A- -A----------A- -A----------A- -A----------A- -A----------A- -A----------A- -A---------AA- -AAA------AAA- --AAA----AAA-- --AAA----AAA-- ---AAAAAAAA--- -------------- -------------- 
-------------- -------------- ----AAAAAA---- ---AA----AA--- --AAA----AAA-- --AAA----AAA-- -A--------AAA- -A----------A- -A----------A- -A----------A- -A----------A- -A----------A- -A----------A- -A----------A- -A----------A- -A----------A- -A----------A- -A----------A- -A----------A- -A----------A- -A----------A- -A----------A- -A----------A- -A---------AA- -A--------AA-- --AAA----AAA-- --AAA----AAA-- ---AA----AA--- ----AAAAAA---- -------------- -------------- 
-------------- -------------- -------------- ----AAAAAA---- ---AAAAAAAA--- ---AA----AA--- --AA-----AAA-- --AA------AA-- --AA------AA-- --AA------AA-- --AA------AA-- --AA------AA-- --AA------AA-- --AA------AA-- --AA------AA-- --AA------AA-- --AA------AA-- --AA------AA-- --AA------AA-- --AA------AA-- --AA------AA-- --AA------AA-- --AA------AA-- --AA------AA-- --AA-----AAA-- ---AA----AA--- ---AAAAAAAA--- ----AAAAAA---- -------------- -------------- -------------- 
-------------- -------------- -------------- -------------- ------AA------ ----AAAAAA---- ----AAAAAA---- ----AAAAAA---- ----AAAAAA---- ----AAAAAA---- ----AAAAAA---- ----AAAAAA---- ----AAAAAA---- ----AAAAAA---- ----AAAAAA---- ----AAAAAA---- ----AAAAAA---- ----AAAAAA---- ----AAAAAA---- ----AAAAAA---- ----AAAAAA---- ----AAAAAA---- ----AAAAAA---- ----AAAAAA---- ----AAAAAA---- ----AAAAAA---- ------AA------ -------------- -------------- -------------- -------------- 
