model
size = 28 32 27, scale = 0.05, origin = -y
material 
  colors = A:#111 B:#C36 C:#303 D:#C06 E:#603 F:#369 G:#036 H:#336 I:#FC3 J:#933 K:#906 L:#C66 M:#936 N:#F66 O:#777 P:#669 Q:#F36 R:#F63 S:#FF3 T:#C33 U:#636 V:#399 W:#C96 X:#FC6 Y:#CC6 Z:#069 Aa:#F33 Ab:#699 Ac:#C93 Ad:#366 Ae:#639 Af:#888 Ag:#CC9 Ah:#6CC Ai:#004 Aj:#FF6 Ak:#C63 Al:#339 Am:#36C An:#033 Ao:#100 Ap:#555 Aq:#969 Ar:#966 As:#39C At:#BBB Au:#F96 Av:#633 Aw:#066 Ax:#903 Ay:#C03 Az:#F69 Ba:#C69 Bb:#C99 Bc:#999 Bd:#039 Be:#06C Bf:#9CC Bg:#CF9 Bh:#9C9 Bi:#F93 Bj:#606
voxels
487-A5-A20-2(A5-A21-)A5-A20-2(A7-A19-)A7-2A19-A7-A19-A6-A183-2AlF2Am2FGAdGAnA2Ao2AHA10-3A2Ae2PFGHFZAnAG3A10-2AH2UAvEUG3HF2H2CA10-ACE4KDAeGM4KECA10-CE6DMAwU4DKAxC10-EK6DBGM6DE10-M2B5DBGMDAy4DK10-9BH8B10-5BPBQMH2BP5B10-Q4BFLQOUNApOQ4B10-NQLBNPHAzPAqApAdNQLAqLAa10-LBa3NBb3FHGOLOFAr2Aa10-NAsVBcAfAtAbBdFGH2GHLRTAa10-AuAgAhBe2Z4FGHWAu4R10-L2XAtBfAbFG2FGAiHOArWAfL10-JXY2AgAhZO2VFO2AiGAdWT10-ELBgAhAsVAfAjVBhAbYAc2WBiRE10-CBjAk2AjX2IYAbXY3IAcEC10-ACEAkI2S2IY4IAcECA10-2A2CJAkI4SIAcJEC2A10-4A2CE4J2EC4A10-7A5C6A10-18A10-19A9-18A13-12A17-2A6-2A152-5(22A6-)20ACA6-AC18ACA6-AE18AEC6-CE18AJC6-CM18ABC6-CM2(18ATE6-CJ)18ATC6-CE18AJC6-AE18AEA6-AC18ACA6-20ACA8(6-22A)8-18A12-14A15-2A8-2A16-A10-A94-24(24A4-)24A5-22A7-20A10-6A4-6A13-2A10-2A14-A12-A64-24(4A18-4A2-)4A18-4A3-3A18-3A5-2A18-2A7-3A14-3A9-6A6-6A11-A14-A12-A14-A34-5A23(18-10A)18-5A-4A18-4A2-4A18-4A3-3A18-3A5-4A14-4A7-3A14-3A9-A-3A8-3A-A10-A16-A33-4A24(20-8A)20-4A-4A18-4A2-4A18-4A3-3A18-3A5-4A14-4A7-A2-A12-A2-A8-A18-A32-4A26(20-8A)20-4A-4A18-4A3-4A16-4A5-A2-A14-A2-A7-A18-A32-4A26(20-8A)20-9A18-5A-5A16-5A3-2A2-A14-A2-2A5-A20-A6-A20-A3-4A26(20-8A)20-9A18-5A-5A16-5A2-2A3-A14-A3-2A3-A22-A4-A22-A2-4A26(20-8A)20-9A18-11A16-6A-2A3-A14-A3-2A2-2A22-2A3-A22-A2-4A26(20-8A)20-9A18-11A16-9A3-A14-A3-3A-2A22-2A3-A22-A2-4A24(20-8A)20-9A2(18-10A)18-11A16-9A3-A14-A3-3A-2A22-2A3-A22-A2-5A27(18-10A)18-11A16-9A3-A14-A3-3A-2A22-2A3-A22-A3-26(4A18-4A2-)4A18-4A-5A18-11A16-9A3-A14-A3-3A-2A22-2A3-A22-A26(4-4A16-4A)3-5A16-5A2-5A16-2(5A-)A14-A-8A4-2A10-2A4-3A-2A22-2A3-A22-A5-25(5A12-5A6-)5A12-5A5-6A12-6A3-4A-2A12-2A-2(4A2-)2A10-2A2-4A2-2A5-12A5-2A2-2A22-2A3-A22-A6-25(20A8-)2A-14A-2A7-3A-14A-3A5-3A2-14A2-3A3-4A3-12A3-4A2-2A22-2A3-A22-A4-A22-A8-22(16A12-)3A10-3A2(12-2A)12-A14-A11-A16-A9-2A16-2A6-2(3A18-3A4-)2(2A20-2A4-)A22-A547-2A24-6A20-10A16-2A10-2A13-2(2A12-)A14-A11-A16-A10-A16-A9-A18-A7-2A18-2A3(6-A20-A)602-6A20-10A17-A10-A15-A12-A13-A14-A12-A14-A11-A16-A9-2A16-2A8-A18-A7-2A18-2A6-A20-A656-10A16-2A10-2A13-A14-A12-A14-A11-A16-A10-A16-A9-2(A18-A8-)A18-A685-10A16-2A10-2A14-2A10-2A13-A14-A12-A14-A11-2(A16-A10-)A16-A714-10A18-10A16-2A10-2A14-2A10-2A13-A14-A12-A14-A11-A16-A770-10A18-10A16-2A10-2A14-2A10-2A13-A14-A827-10A18-10A16-2A10-2A884-10A9-
