model
size = 31 32 17, scale = 0.05, origin = -y
material 
  colors = A:#9C51E2 B:#A758ED C:#EA49ED D:#9141ED E:#BD43ED F:#BA3BC1 G:#3D3BDE H:#6E2377 I:#693FDE J:#8F4BDE K:#CF41D4 L:#310F38 M:#043DDE N:#3D1345 O:#A735B0 P:#862B8F Q:#0437D1 R:#5B1D64 S:#022FC4 T:#011DBB U:#0125C6 V:#1E0925 W:#00033D X:#FFF Y:#00064E Z:#001077 Aa:#011587 Ab:#01189A Ac:#230B2A Ad:#501959 Ae:#000445 Af:#1B0822 Ag:#000132 Ah:#000B61 Ai:#000E6F Aj:#000853 Ak:#2B0D32 Al:#15061C Am:#000027 An:#18071F Ao:#000014 Ap:#100417 Aq:#000009 Ar:#000 As:#0B0211 At:#07010C Au:#020004
voxels
9-2Ac2Ak2L2N2AdR2H18-V2AcAk2L2NAdRHPO18-2V2AcAkLNAdRHPFK18-V2AcAkLN2RHPFKC18-VAcAkLNAdRHOFKCE18-AcAkLNAdRHPFKCED18-AcAkLNRHPOFCEDB18-AkLNRHP2FCEDBA18-LNAdRPOFCEDB2A18-NAdRHPFCEDB3A18-NRHPOCEDB4A18-RHPOFCEDB4A18-RPOFCEDB5A18-HOFCEDB5AJ18-P2FCEDB4AJI18-OFCEDB4AJIG18-FCEDB4AJIGM18-CEDB4AJIGMQ18-2XDBXA3XIGXQ18-XDX3AXJIGXQX18-XBX3AXIGMXSX17-D2X3AJIXMQXUXAb15-DB2(XA)JIGMXSXTXAaZ14-DBXAXJIGMQXUXAbXZAi15-B2XAJIG2XSUTXAaZ17-2BJIGMQSUTAbAaZ19-JIGMQSUTAbAaZ23-MQSUT144-2V13-2O14-AfV13-FK14-AfV13-KC14-2Af13-CE14-AfV13-ED14-AfV13-DB14-2V13-BA14-VAc13-2A14-2Ac13-2A14-AcAk2(13-2A14-AkL)13-AJ14-NR13-JI14-2RA11-AIG14-2HA11-AGM15-PA11-AM16-FA11-AQ16-K2(A11-AS16-C)A11-AU14-KCEA11-ATAbAa11-KCEA13-AAaZAi10-CEA15-AAiAh10-CEA15-AAhAj11-DB15-AiAh13-2B13-AiAh15-2B4A3-4AAiAh17-BJIGM3-TAbAaZAi23-QSU113-Af17-F12-Af17-C12-An17-E12-An17-D12-An17-B2(12-Af17-A)2(12-V17-A)12-AcV15-2A12-AkAc15-AJ12-LAk15-AI12-NL15-AG13-Ad15-M14-R15-Q14-HA13-AQ14-OA13-AS14-FA13-AU14-KA13-AU15-C13-T11-O2F2-A13-Ab2-ZAhAj6-OFA19-AAhAj6-FKA19-AAjY6-FKA19-AYAe7-CE19-AjY8-EDBA15-AAjYAe9-D2B15-AjYAe12-2B13-AhAj15-2JIGMQ3-TAbAaZAiAh106-An19-K10-An19-C10-An19-E10-An19-D10-An19-B2(10-An19-A)10-Af19-A10-V19-A11-V17-J12-Ac17-I12-Ak17-G12-L17-M12-N17-Q12-Ad17-S13-H15-S14-P15-U14-O15-T14-K15-T14-C15-Ab9-P4-C15-Aa4-Y4-P25-Y4-O25-Ae4-FA23-AW4-2KA21-AWAg5-C2A19-2AW6-ED2A17-2A2W7-D2BA15-AYAeW10-BJ15-AjY14-2IGM7-ZAiAhAj75-2(Al19-C10-)Al19-E10-Al19-D10-Al19-B10-Al19-A10-An2(19-A10-Af)19-A10-2V17-AJ10-2Ac17-AI10-2Ak17-AG11-L17-M12-N17-Q12-Ad17-S12-RA15-AU12-HA15-AT13-O15-Ab14-F15-Ab14-C15-Aa8-H5-C15-Z5-Y2-H27-Ae2-P27-Ae2-FA25-AW3-KA23-AAg4-C2A21-2AAg4-E3A19-3AAg5-D3A17-3AAg7-2BJA15-AYAeW11-2I13-2Y16-GMQ7-AiAhAj45-Ap19-C10-Ap19-E10-Ap19-D10-Ap19-B10-Ap2(19-A10-Al)19-A10-An19-A10-Af19-J10-V19-I10-V19-G10-Ac19-M10-L19-Q10-L19-S10-N19-U11-Ad17-T12-H17-Ab12-O17-Aa12-F17-Aa13-K15-Z8-R5-C15-Ah5-Y2-R27-Ae2-H27-W2-O27-W2-FA25-AAg2-K2A23-2AAm3-C2A21-2AAm4-E3A19-3AAm5-DB2A17-2AWAg8-BJI15-3Ae13-G13-Y17-MQ9-AhAj14-Au19-C10-Au19-E10-As19-D10-As19-B2(10-Ap19-A)10-Al2(19-A10-An)19-J10-Af19-I10-V19-G10-Ac19-M10-Ac19-Q10-L19-S10-N19-U10-NA17-AT10-HA17-AAb11-P17-Aa12-F17-Z12-KA15-AAi6-Ad6-C15-Ah6-YAd28-AAeH28-AWP28-AAg-O26-AAm2-FA25-AAo2-K2A23-2AAo3-E2A21-2AAo5-D2A19-2AAm7-2BJA15-A2WAg11-I15-Ae15-G13-Y13-Ar19-E10-Ar19-D10-Ar19-B10-At19-A10-As19-A10-Ap19-A10-Al19-A10-An19-J10-An19-I10-Af19-G10-V19-M10-Ac19-Q10-Ac19-S10-L19-U10-L19-T10-NA17-AAb10-HA17-AAa10-HA17-AZ11-F17-Ai12-KA15-AAh6-N5-CA15-AAj5-YN28-AAeAd28-AWH28-AAgP28-AAm-F26-AAo2-KA25-AAq3-CA23-AAq4-EDA21-AAmAo6-BJ19-AgAm10-IG15-2W14-G13-Ae13-Ar19-E10-Ar19-D10-Au19-B10-At19-A10-As19-A10-Ap19-A10-Al19-J10-An19-I10-An19-G10-Af19-M10-V19-Q10-Ac19-S10-Ac19-U10-L19-T10-N19-Ab10-NA17-AAa10-HA17-AZ10-HA17-AAi10-PA17-AAh10-K2A15-2AAj5-L5-CA15-AAj5-YN28-AAeAd28-AWR28-AAgH28-AAmO28-AAo-F26-AAq2-CA25-AAr3-EA23-AAq5-DBJ19-Am2Ao9-IG15-2Ag14-G13-W13-Ar19-E10-Ar19-D10-Au19-B10-At19-A10-As19-A10-Ap19-A10-Al19-J10-An19-I10-An19-G10-Af19-M10-V19-Q10-Ac19-S10-Ac19-U10-L19-T10-N19-Ab10-RA17-AAa10-HA17-AZ10-PA17-AAi11-F17-Ah12-KA15-AAj6-N5-CA15-AAj5-YN28-AAeR28-AWH28-AAgP28-AAmO28-AAo-K26-AAq2-CA25-AAr3-EA23-AAr5-DBJ19-Ao2Aq9-IG15-AgAm14-G13-W13-Au19-E10-Au19-D10-At19-B10-As2(19-A10-Ap)19-J10-Al19-I10-An19-G10-Af19-M2(10-V19-S)10-Ac19-U10-L19-T10-L19-Ab10-N19-Aa10-RA17-AZ10-HA17-AZ11-P17-Ai12-F17-Ah12-KA15-AAi6-N6-C15-Aj6-YAd28-AAeR28-AWH28-AAgP28-AAm-F26-AAo2-KA25-AAq3-CA23-AAq4-EDA21-A2Ar6-BJ19-AoAq10-IG15-AgAm14-G13-W13-At19-E10-At19-D10-As2(19-B10-Ap)19-J10-Al19-I10-Al19-G10-Af19-M10-Af19-Q10-V19-S10-V2(19-U10-L)19-T10-N19-Ab10-Ad19-Aa11-2(H17-Z12-)P17-Ai12-F17-Ai13-K15-Ai7-Ad6-C15-Ah6-YAd28-AAeH28-AWP28-AAg-O26-AAm2-FA25-AAo2-K2A23-2AAo3-E2A21-2AAq5-D3A17-3AAq7-2BJA15-AAm2Ao11-IG14-Ag16-M12-W13-As19-E10-As19-D2(10-Ap19-B)10-Al19-J10-Al19-I10-Af19-G10-Af19-M10-V19-Q10-VAk17-AS10-AcL17-AS10-2L17-AU11-2(N17-T12-)R17-Ab13-H15-Aa14-P15-Aa14-O15-Z14-F15-Z14-K15-Z8-R5-C15-Ai5-Y2-R27-Ae2-P27-W2-O26-AAg2-FA25-AAg2-K2A23-2AAm3-C2A21-2AAo4-E3A19-3AAo5-DB2A17-2A2Ao8-BJI15-2AgAm13-G13-W17-M11-W14-Ap19-E10-Ap19-D10-Al19-B10-Al19-A10-Al19-B10-Af19-J10-Af19-I10-V19-G10-V19-M11-Ak17-Q12-L17-Q12-N17-S12-N17-U12-Ad17-T12-R17-T13-H15-Ab14-P15-Ab14-O15-Aa14-F15-Aa14-K15-Aa8-R5-C15-Z5-Y2-H27-Ae2-P27-Ae2-OA25-AW3-FA23-AAg4-K2A21-2AAm4-C3A19-3AAm5-E3A17-3AAm7-DBJA15-A2AgAm11-I15-W15-G13-Ae17-MQ9-YAe15-Al17-E12-Al17-D12-Al17-B2(12-Af17-A)12-Af17-B12-V17-J12-Ac17-I12-Ak17-G12-LAk15-AM12-NL15-AM12-2N15-AQ12-AdN15-AS13-R15-U2(14-H15-T)14-O15-T14-O15-Ab14-F15-Ab15-K13-Aa10-H5-C13-Z5-Y4-H4-2A13-2A4-Ae4-P25-Ae4-OA23-AW4-FKA21-AWAg5-C2A19-2AAg6-ED2A17-2A2Ag7-D2BA16-AeWAg10-BJ15-AeW14-IA11-AAe17-GQ9-AjY20-S7-Aj18-Af15-E14-Af15-D2(14-Af15-B)14-Af15-A14-V15-A14-Ac15-B14-Ac15-J14-2L13-AI14-LAk13-AG14-NLH11-2AG14-AdNH11-2AM14-Ad3H9-3AQ14-RH13AQS14-HP13ASU15-P13AU16-O13AU2(16-F13AT)16-K13AAb11-HPOK-C13AAa-AiAhAjY6-POFKC15AZAiAhAjY6-OFK19AAjYAe6-FKC19AYAeW7-CE19AYAe8-E2D17AYAeW9-3B15AYAeW12-B15AY15-JI11AAjY17-G11AY19-MQ7AAhAj22-UTAbAaZAiAh20-AcAk4LNAdRHPOFKC16-AcAk3LNAdRHPOFKCE2(16-VAk2LNAdRHPOFKCED)16-VAkLNAdRHPOFKCEDB16-AkLNAdRHPOFKCEDBA16-L2NAdRHPOFKCEDBA16-LNAdRHPOFKCEDBAB16-LNAdRHPOFKCED2BJ16-NAdRHPOFKCED2BJI16-AdRHPOFKCED3BJI16-AdRHPOFKCED2BJIG16-RHPOFKCED2BJIGM17-POFKCED2BJIGM2(18-OFKCED2BJIGMQ)18-FKCED2BJIGMQS18-KCED2BJIGMQSU18-2CED2BJIGMQSU18-CED2BJIGMQSUT18-ED2BJIGMQSUTAb17-ED3BJIGMQSUTAbAa14-CED3BJIGMQSUTAbAaZAiAh12-CED2BJIGMQSUTAbAaZAiAhAj12-ED3BJIGMQSUTAbAaZAiAhAj13-3BJIGMQSUTAbAaZAiAhAj15-BJIGMQSUTAbAaZAiAhAj16-BJIGMQSUTAbAaZAiAhAj18-GMQSUTAbAaZAiAh20-MQSUTAbAaZAiAhAj21-QSUTAbAaZAiAh42-
