model
size = 21 29 21, scale = 0.05, origin = -y
material 
  colors = A:#D65500 B:#EE2424 C:#EA5D00 D:#F60 E:#700 F:#A00 G:#853500 H:#500 I:#AD4500 J:#C24D00 K:#800 L:#EE1212 M:#D00 N:#993D00 O:#040 P:#050 Q:#070 R:#080 S:#0A0
voxels
--------------------- --------------------- --------------------- --------------------- --------------------- --------------------- --------------------- --------------------- ---------DD---------- --------DDDD--------- --------DDDD--------- ---------DD---------- --------DDDD--------- --------DDDD--------- --------DDDD--------- ---------DD---------- --------------------- --------------------- --------------------- --------------------- --------------------- --------------------- --------------------- --------------------- --------------------- --------------------- --------------------- --------------------- --------------------- 
--------------------- --------------------- --------------------- --------------------- --------------------- --------------------- --------------------- --------------------- -----C--ABBA--C------ ----DCAABBBBAACD----- ----D--ABBBBA--D----- --------BBBB--------- --------BBBB--------- -----CAABBBBAAC------ ----DCAABBBBAACD----- -----CAAABBAAAC------ -----CAACCCCAAC------ --------CCCC--------- ---------CC---------- --------------------- --------------------- --------------------- --------------------- --------------------- --------------------- --------------------- --------------------- --------------------- --------------------- 
--------------------- --------------------- --------------------- --------------------- --------------------- --------------------- --------------------- --------------------- -----BBBBBBBBBBC----- ---DBBBB----BBBBD---- ---DB--B----B--BD---- ---D------------D---- ---D------------D---- ----BBBB----BBB------ ---DBBBB----BBBB----- ---DCBBBB--BBBBCD---- ----CLLBBBBBBLLC----- ----CAAJLLLLJAAC----- ----CAAJJMMJJAAC----- -----A--JAAJ--A------ ---------AA---------- --------------------- --------------------- --------------------- --------------------- --------------------- --------------------- --------------------- --------------------- 
--------------------- --------IIII--------- ------IIA--AII------- -----A--------A------ ----A----------A----- ---C------------C---- --------------------- --------------------- -----BBBBBBBB-BL----- ---BB-----------B---- --DB------------BD--- --DB------------BD--- --DB------------BD--- --DB-------------D--- --DB-------------D--- ---CL----------LC---- ---CL----------LC---- ---CMMML----LMMMC---- ---CFFFMM--MMFFFC---- ----AKJIFFFFIJKA----- ----AAJIJKKJIJAA----- -------I-JJ-I-------- --------------------- --------------------- --------------------- --------------------- --------------------- --------------------- --------------------- 
--------------------- ------I--III-I------- -----JIINEENIIJ------ ----AEKKK--KKKEA----- ---AKK-------FKKA---- ---AF----------FA---- --CF-----------MFC--- --CM----------LLMC--- --CLL-----------LC--- --CB------------BC--- --CB------------BC--- --CB------------BC--- --CB------------BC--- --CB------------BC--- --CB------------BC--- --CL------------LC--- --CM------------MC--- --CF------------FC--- ---AF----------FA---- ---AK-FF----FF-KA---- ----AEKKK--KKKEA----- -----JIINEENIIJ------ ------I--II--I------- --------------------- --------------------- --------------------- --------------------- --------------------- --------------------- 
---------GG---------- -----IINGHHGNII------ -----IEEE--EEEI------ ----JE--------EJ----- ---AK----------KA---- --AK------------KA--- --AF------------FA--- --AM------------MA--- --AL------------LA--- --AB------------BA--- --AB------------BA--- --AB------------BA--- --AB------------BA--- --AB------------BA--- --AB------------BA--- --AL------------LA--- --AM------------MA--- --AF------------FA--- --AK------------KA--- ---AK----------KA---- ----JE--------EJ----- -----IEEEEEEEEI------ -----IINGGGGNII------ --------------------- --------------------- --------------------- --------------------- --------------------- --------------------- 
--------GGGG--------- ------NGHHHHGN------- ----IIEE----EEII----- ---JEE--------EEJ---- ---JK----------KJ---- ---JF-----------KJ--- ---JM-----------FJ--- --AM-------------FA-- --AL-------------MA-- --AB-------------LA-- --AB-------------BA-- --AB-------------BA-- --AB-------------BA-- --AB-------------BA-- --AB-------------LA-- --AL-------------MA-- --AM-------------FA-- ---JM-----------FJ--- ---JF-----------KJ--- ---JK----------KJ---- ---JEE--------EEJ---- ----IIEE----EEII----- ------NGHHHHGN------- --------GGGG--------- --------------------- --------------------- --------------------- --------------------- --------------------- 
-------GGGGGG-------- -----NGHHHHHHGN------ ----IHE------EHII---- ---JE----------EEJ--- ---JK-----------EJ--- --AK-------------KA-- --AF-------------FA-- -CF---------------FC- -CM---------------FC- -CL---------------MC- -CB---------------LC- -CB---------------BC- -CB---------------LC- -CB---------------LC- -CL---------------MC- -CM---------------FC- -CF---------------FC- --AF-------------FA-- --AK-------------KA-- ---JK-----------EJ--- ---JE----------EEJ--- ----IHE--EE--EHII---- -----NGHHGGHHGN------ -------GG--GG-------- --------------------- --------------------- --------------------- --------------------- --------------------- 
------GGGGGGGG------- -----GHHHHHHHHGN----- ----IH--------HHI---- ---JE-----------EJ--- --AE-------------EA-- --AK-------------KA-- -CF---------------KC- -CF---------------FC- -CM---------------FC- DM-----------------FD DL-----------------MD DL-----------------LD DL-----------------LD DL-----------------MD DM-----------------FD -CM---------------FC- -CF---------------FC- -CF---------------KC- --AK-------------KA-- --AE-------------EA-- ---JE-----------EJ--- ----IHE-EEEE--HHI---- -----GGHGGGGHHGN----- -------G----GG------- --------------------- --------------------- --------------------- --------------------- --------------------- 
------GGGGGGGGG------ ----INHHHHHHHHBNI---- ---JHH---------HHJ--- --AE-------------HA-- --AE-------------EA-- -CK---------------EC- -CF---------------KC- -CF---------------FC- DF-----------------FD DM-----------------FD DL-----------------MD DL-----------------LD DL-----------------LD DL-----------------MD DM-----------------FD DF-----------------FD -CF---------------FC- -CF---------------KC- -CK---------------EC- --AE-------------EA-- --AE-------------HA-- ---JHH--E---E-HHHJ--- ----INHHGHHHGHGNI---- ------GG-OPO-G------- ---------PPP--------- ----------PQ--------- ----------PQ--------- ----------RS--------- --------------------- 
------GGGGGGGGG------ ----IGHHHHHHHHBNI---- ---JHH---------HHJ--- --AE-------------HA-- --AE-------------EA-- -CK---------------EC- -CF---------------KC- -CF---------------FC- DF-----------------FD DM-----------------FD DL-----------------MD DL-----------------LD DL-----------------LD DL-----------------MD DM-----------------FD DF-----------------FD -CF---------------FC- -CF---------------KC- -CK---------------EC- --AE-------------EA-- --AE-------------HA-- ---JHH-EE---E-HHHJ--- ----IGHGGHHHGHGNI---- ------G--OOO-G------- ---------OOP--------- ---------OBP--------- ---------OBP--------- ---------OLP--------- ---------OOR--------- 
------GGGGGGGG------- -----GHHHHHHHHGN----- ----NH--------HHI---- ---JE-----------EJ--- --JE-------------EA-- --JK-------------KA-- -CF---------------KC- -CF---------------FC- -AM---------------FC- DM-----------------FD DL-----------------MD DL-----------------LD DL-----------------LD DL-----------------MD DM-----------------FD -AM---------------FC- -CF---------------FC- -CF---------------KC- --JK-------------KA-- --JE-------------EA-- ---JE-----------EJ--- ----NH--EEEEE-HHI---- -----GHHGGGGGHGN----- ------GG-----G------- --------------------- ----------OP--------- ---------OBP--------- ---------OLP--------- ---------OOQ--------- 
-------GGGGGGG------- -----NGHHHHHHHN------ ---IIHE-------HII---- ---IE----------EEJ--- ---IK-----------EJ--- --JK-------------KA-- --JF-------------FA-- -AF---------------FC- -AM---------------FC- -AL---------------MC- -AB---------------LC- -AB---------------BC- -AB---------------LC- -AB---------------LC- -AL---------------MC- -AM---------------FC- -AF---------------FC- --JF-------------FA-- --JK-------------KA-- ---IK-----------EJ--- ---IE----------EEJ--- ---IIHE--EEE--HII---- -----NGHHGGGHHN------ -------GG---GG------- --------------------- --------------------- ----------OP--------- ----------OP--------- --------------------- 
--------GGGG--------- ----IINGHHHHGNII----- ----IHEE----EEHI----- ---JE----------EJ---- ---JK-----------EA--- --AK------------KA--- --AF------------FA--- -AF--------------FA-- -AM--------------MA-- -AL--------------LA-- -AB--------------BA-- -AB--------------BA-- -AB--------------BA-- -AB--------------BA-- -AL--------------LA-- -AM--------------MA-- -AF--------------FA-- --AF------------FA--- --AK------------KA--- ---JK----------KJ---- ---JE----------EJ---- ----IHEE-----EHI----- ----IINGHHHHHNII----- --------GGGGG-------- --------------------- --------------------- --------------------- --------------------- --------------------- 
---------GG---------- -----I-NGHHGN-I------ ----JIIEE--EEIIJ----- ---AEEK------KEEA---- --AE------------EA--- --AK------------KA--- --AF------------FA--- -CF--------------FC-- -CM--------------MC-- -CL--------------LC-- -CB--------------BC-- -CB--------------BC-- -CB--------------BC-- -CB--------------BC-- -CL--------------LC-- -CM--------------MC-- -CF--------------FC-- --AF------------FA--- --AK------------KA--- --AE------------EA--- ---AEEK------KEEA---- ----JIIEE--EEIIJ----- -----I-NGHHGN-I------ ---------GG---------- --------------------- --------------------- --------------------- --------------------- --------------------- 
--------------------- --------NNNN--------- ------IIEEEEII------- ---AAJKK----KKJAA---- ---AKKF------FKKA---- --CKF----------FKC--- --CF------------FC--- --CM------------MC--- --CL------------LC--- -DL--------------LD-- -DB--------------BD-- -DB--------------BD-- -DB--------------BD-- -DB--------------BD-- -DL--------------LD-- --CL------------LC--- --CM------------MC--- --CF------------FC--- --CKF----------FKC--- ---AKKF------FKKA---- ---AAJKK----KKJAA---- ------IIEEEEII------- --------NNNN--------- --------------------- --------------------- --------------------- --------------------- --------------------- --------------------- 
--------------------- ---------II---------- -------IIEEII-------- ------JKK--KKJ------- ----AAJF----FJAA----- ---CAFF------FFAC---- ---CMMM------MMMC---- ---CLL--------LLC---- --DCLB--------BLCD--- --DBBB--------BBBD--- --DBBB--------BBBD--- --DBBB--------BBBD--- --DBBB--------BBBD--- --DBBB--------BBBD--- --DBBB--------BBBD--- --DCLB--------BLCD--- ---CLL--------LLC---- ---CMMM------MMMC---- ---CAFF------FFAC---- ----AAJF----FJAA----- ------JKK--KKJ------- -------IIEEII-------- ---------II---------- --------------------- --------------------- --------------------- --------------------- --------------------- --------------------- 
--------------------- --------------------- ---------JJ---------- -------JJKKJJ-------- -------JFFFFJ-------- -----AJMM--MMJA------ ----CAJL----LJAC----- ----CAL------LAC----- ----CAB------BAC----- ---DCAB------BACD---- ---DCAB------BACD---- ---DCAB------BACD---- ---DCAB------BACD---- ---DCAB------BACD---- ---DCAB------BACD---- ----CAB------BAC----- ----CAL------LAC----- ----CAJL----LJAC----- -----AJMM--MMJA------ -------JFFFFJ-------- -------JJKKJJ-------- ---------JJ---------- --------------------- --------------------- --------------------- --------------------- --------------------- --------------------- --------------------- 
--------------------- --------------------- --------------------- ---------AA---------- --------AAAA--------- -------AAMMAA-------- -------ALLLLA-------- ------ABBBBBBA------- ------ABB--BBA------- ------AB----BA------- ------AB----BA------- ------AB----BA------- ------AB----BA------- ------AB----BA------- ------AB----BA------- ------ABB--BBA------- ------ABBBBBBA------- -------ALLLLA-------- -------AAMMAA-------- --------AAAA--------- ---------AA---------- --------------------- --------------------- --------------------- --------------------- --------------------- --------------------- --------------------- --------------------- 
--------------------- --------------------- --------------------- --------------------- --------------------- ---------CC---------- --------CCCC--------- -------CCCCCC-------- -------CCBBCC-------- -------CBBBBC-------- -------CBBBBC-------- -------CBBBBC-------- -------CBBBBC-------- -------CBBBBC-------- -------CBBBBC-------- -------CCBBCC-------- -------CCCCCC-------- --------CCCC--------- ---------CC---------- --------------------- --------------------- --------------------- --------------------- --------------------- --------------------- --------------------- --------------------- --------------------- --------------------- 
--------------------- --------------------- --------------------- --------------------- --------------------- --------------------- --------------------- --------------------- ---------DD---------- --------DDDD--------- --------DDDD--------- --------DDDD--------- --------DDDD--------- --------DDDD--------- --------DDDD--------- ---------DD---------- --------------------- --------------------- --------------------- --------------------- --------------------- --------------------- --------------------- --------------------- --------------------- --------------------- --------------------- --------------------- --------------------- 
