model
size = 13 24 28, scale = 0.05, origin = -y
material 
  colors = A:#181818 B:#62593B C:#101102 D:#FC0 E:#6F6936 F:#6AB3CC
voxels
-----BBB----- -----CCC----- ------------- ------------- ------------- ------------- ------------- ------------- ------------- ------------- ------------- ------------- ------------- ------------- ------------- ------------- ------------- ------------- ------------- ------------- ------------- ------------- ------------- ------------- 
---BBBBBBB--- ---CCCBCCC--- -----CDC----- -----AAA----- ------------- ------------- ------------- ------------- ------------- ------------- ------------- ------------- ------------- ------------- ------------- ------------- ------------- ------------- ------------- ------------- ------------- ------------- ------------- ------------- 
--BBBBBBBBB-- --CCCCBCBCC-- ----DCCCD---- ----ACCCA---- -----AAA----- ------------- ------------- ------------- ------------- ------------- ------------- ------------- ------------- ------------- ------------- ------------- ------------- ------------- ------------- ------------- ------------- ------------- ------------- ------------- 
-BBBBBBBBBBB- -CCCCCBCBCCC- ---CCCCCCC--- ---ACCCCCA--- ---AACCCAA--- ----AAAAA---- ------------- ------------- ------------- ------------- ------------- ------------- ------------- ------------- ------------- ------------- ------------- ------------- ------------- ------------- ------------- ------------- ------------- ------------- 
-BBBBBBBBBBB- -CCCCCBCBCCC- --DCCCCCCCD-- --ACCCAACCA-- ---ACCAACA--- ---AACAAAA--- -----AAA----- ------------- ------------- ------------- ------------- ------------- ------------- ------------- ------------- ------------- ------------- ------------- ------------- ------------- ------------- ------------- ------------- ------------- 
BBBBBBBBBBBBB CCCCCCBCBBBBC -CCCACCCCCCC- --ACAAAACCA-- --ACAAAACCA-- ---ACAAACA--- ----AAAAA---- ------------- ------------- ------------- ------------- ------------- ------------- ------------- ------------- ------------- ------------- ------------- ------------- ------------- ------------- ------------- ------------- ------------- 
BBBBBBBBBBBBB CBBBBBBBBBBBC -DCCCCCCCCCD- -ACCAAAACCCA- --ACAAAACCA-- ---ACAAACA--- ----AAAAA---- ------------- ------------- ------------- ------------- ------------- ------------- ------------- ------------- ------------- ------------- ------------- ------------- ------------- ------------- ------------- ------------- ------------- 
BBBBBBBBBBBBB CBBBBBBBBBBBC -CCCCCCCCCCC- -ACCAAAACCCA- -AACAAAACCAA- ---ACAAACA--- ----AAAAA---- ------------- ------------- ------------- ------------- ------------- ------------- ------------- ------------- ------------- ------------- ------------- ------------- ------------- ------------- ------------- ------------- ------------- 
BBBBBBBBBBBBB CBBBBBBBBBBBC -DCCCCCCCCCD- -ACCAAAACCCA- -AFCAAAACCFA- --AACAAACAA-- ----AAAAA---- ------------- ------------- ------------- ------------- ------------- ------------- ------------- ------------- ------------- ------------- ------------- ------------- ------------- ------------- ------------- ------------- ------------- 
BBBBBBBBBBBBB CBBBBBBBBBBBC -CCCCCCCCCCC- -AFCAAAACCFA- --ACAAAACCA-- --AACAAACAA-- ----AFFFA---- -----AAA----- ------------- ------------- ------------- ------------- ------------- ------------- ------------- ------------- ------------- ------------- ------------- ------------- ------------- ------------- ------------- ------------- 
BBBBBBBBBBBBB CBBBBBBBBBBBC -DCCCCCCCCCD- -ACCAAAAACFA- --ACAAAAAFA-- ---AAAAAAA--- ---AAAAAAA--- ----AAAAA---- ------------- ------------- ------------- ------------- ------------- ------------- ------------- ------------- ------------- ------------- ------------- ------------- ------------- ------------- ------------- ------------- 
BBBBBBBBBBBBB CBBBBBBBBBBBC CAACCCCCCCCCC -ACCAAAAACCA- --ACAAAAACA-- ---AAAAAAA--- ---AAAAAAA--- ---AA---AA--- ----D---D---- ------------- ------------- ------------- ------------- ------------- ------------- ------------- ------------- ------------- ------------- ------------- ------------- ------------- ------------- ------------- 
------------- BBBBBBBBBBBBB CADCCCCCCCCCC -DCCAAAAACCD- -AACAAAAACAA- ---AAAAAAA--- ---AAAAAAA--- ---AAAAAAA--- ---AAD-DAA--- ----A-D-A---- -----D-D----- ------------- ------------- ------------- ------------- ------------- ------------- ------------- ------------- ------------- ------------- ------------- ------------- ------------- 
------------- BBBBBBBBBBBBB CAACCCCCCBBBC -CCCAAAAACCC- -AACAAAAACAA- ---AAAAAAA--- ---AAAAAAA--- ---AAAAAAA--- ---AAAAAAA--- ---AA---AA--- ----A---A---- ----D---D---- ------------- ------------- ------------- ------------- ------------- ------------- ------------- ------------- ------------- ------------- ------------- ------------- 
------------- BBBBBBBBBBBBB CADCCCCCCBBBC -DCCAAAAACCD- -AACAAAAACAA- ---ACCCCCA--- ---ACFFCCA--- ---ACCCCCA--- ---AAAAAAA--- ---AAAAAAA--- ---AA---AA--- ---AA---AA--- ----AD-DA---- ----A-D-A---- ----AD-DA---- ----D---D---- ----AD-DA---- ----A-D-A---- ----AD-DA---- ----D---D---- ------------- ------------- ------------- ------------- 
------------- BBBBBBBBBBBBB CAACCCCCCBBBC -CCCAAAAACCC- -AACAAAAACAA- ---AAAAAAA--- ---A-----A--- ---A-----A--- ---A-----A--- ---A-----A--- ---AAAAAAA--- ---AAAAAAA--- ---AA---AA--- ---AA---AA--- ---AC---CA--- ---AFAAAFA--- ---AFAAAFA--- ---AFAAAFA--- ---AFAAAFA--- ---CAAAAAC--- -----AAA----- ------------- ------------- ------------- 
------------- BBBBBBBBBBBBB CABCCCCCCCBBC -DCCAAAAACCD- -AACAAAAACAA- ---AAAAAAA--- ---A-----A--- ---A-----A--- ---A-----A--- ---A-----A--- ---AAAAAAA--- ---AAAAAAA--- ---AAAAAAA--- ---AAAAAAA--- ---AAAAAAA--- ---AA---AA--- ---AA---AA--- ---AA---AA--- ---AA---AA--- ---CA---AC--- ----A---A---- ------------- ------------- ------------- 
------------- BBBBBBBBBBBBB CAACCCCCEEEBC CAAAAAAABCAAC -AACAAAAACAA- ---AAAAAAA--- ---A-----A--- ---A-----A--- ---A-----A--- ---A-----A--- ---A-----A--- ---A-----A--- ---A-----A--- ---A-----A--- ---A-----A--- ---A-----A--- ---A-----A--- ---A-----A--- ---A-----A--- ---C-----C--- ------------- ------------- ------------- ------------- 
BB----------B BBBBBBBBBBBBB BBBCCCCCEEEEB CAAAAAAABCAAC -DCCAAAAACCD- -AAFAAAAAFAA- ---A-----A--- ---A-----A--- ---A-----A--- ---A-----A--- ---A-----A--- ---A-----A--- ---A-----A--- ---A-----A--- ---A-----A--- ---A-----A--- ---A-----A--- ---A-----A--- ---A-----A--- ---C-----C--- ------------- ------------- ------------- ------------- 
BBBB------BBB BBBBBBBBBBBBB BBBCCCCCEEEEB CAAAAAAABCAAC -CCCAAAAACCC- -AACAAAAACAA- ---A-----A--- ---A-----A--- ---A-----A--- ---A-----A--- ---A-----A--- ---A-----A--- ---A-----A--- ---A-----A--- ---A-----A--- ---A-----A--- ---A-----A--- ---A-----A--- ---A-----A--- ---C-----C--- ------------- ------------- ------------- ------------- 
BBBBBBBBBBBBB BBBBAAAEEEEEB BBBCCCCCEEEEB CAAAAAAABBAAC -DCCAAAAACCD- -ACCAAAAACCA- --AA-----AA-- ---A-----A--- ---A-----A--- ---A-----A--- ---A-----A--- ---A-----A--- ---A-----A--- ---A-----A--- ---A-----A--- ---A-----A--- ---A-----A--- ---A-----A--- ---A-----A--- ---C-----C--- ------------- ------------- ------------- ------------- 
BBBBBBBBBBBBB BBBBABAEEEEEB BBBCCBCCEEEEB CAAAABAABBAAC -CCCABAAACCC- -ACCAAAAACCA- --AA-----AA-- --AA-----AA-- ---AA---AA--- ---A-----A--- ---A-----A--- ---A-----A--- ---A-----A--- ---A-----A--- ---A-----A--- ---A-----A--- ---A-----A--- ---A-----A--- ---A-----A--- ---C-----C--- ------------- ------------- ------------- ------------- 
BBBBBBBBBBBBB BBBEBBAEEEEEB BBBCBBCCEEEEB CACCBBCCCCCCC -DCCBBAAACCD- -ACCAAAAACCA- --AC-----CA-- --AA-----AA-- ---AA---AA--- ---AA---AA--- ---AA---AA--- ---A-----A--- ---A-----A--- ---A-----A--- ---A-----A--- ---A-----A--- ---A-----A--- ---A-----A--- ---A-----A--- ---C-----C--- ------------- ------------- ------------- ------------- 
-BBBBBBBBBBB- -BBEBBBBBEEB- -BBEBCCCEEEB- -CCCBCCCCCCC- --CCBAAACCC-- --ACFAAACCA-- --ACA---ACA-- ---AA---AA--- ---AA---AA--- ---AA---AA--- ---AA---AA--- ---AA---A---- ---AA---A---- ---AA---A---- ---AA---A---- ---AA---A---- ---AA---A---- ---AA---A---- ---AA---A---- ---CC---C---- ------------- ------------- ------------- ------------- 
--BBBBBBBBB-- --BEBBBBBEB-- --BEDCCCEEB-- --CCCCCCCCC-- ---DCAAACD--- ---AAAAAAA--- ---AAAAAAA--- -----AAA----- -----AAA----- -----AAA----- -----AAA----- -----AAA----- -----AAA----- ----AAAAA---- ----AAAAA---- ----A---A---- ----A---A---- ----A---A---- ----A---A---- ----C---C---- ------------- ------------- ------------- ------------- 
--BBBBBBBBB-- --BBBBBBBBB-- --BBBBBBBBB-- --CCCCCCCCC-- -----DCD----- -----AAA----- ------A------ ------------- ------------- ------------- ------------- ------A------ -----AAA----- -----AAA----- -----AAA----- -----AAA----- ----AAAAA---- ----AAAAA---- ----AAAAA---- ----CAAAC---- -----CDC----- -----CDC----- ------------- ------------- 
---BBBBBBB--- ---BBBBBBB--- ----BBBBB---- ----CCCCC---- ------------- ------------- ------------- ------------- ------------- ------------- ------------- ------------- ------------- ------------- ------------- ------------- ------------- ------------- ------------- ------------- ------------- -----CDC----- -----CDC----- ------------- 
------------- ------------- ------------- ------------- ------------- ------------- ------------- ------------- ------------- ------------- ------------- ------------- ------------- ------------- ------------- ------------- ------------- ------------- ------------- ------------- ------------- ------------- -----CDC----- -----CDC----- 
