model
size = 26 6 16, scale = 0.05, origin = -y
material 
  colors = A:#010101 B:#0C0C0C
voxels
-AAAAAAAA--------AAAAAAAA- A--------A------A--------A A---------A----A---------A A---------AA--AA---------A A---------A-AA-A---------A -AAAAAAAAA------AAAAAAAAA- 
-------------------------- -------------------------- A------------------------A A---------B----B---------A A------------------------A -------------------------- 
-------------------------- -------------------------- A---------B----B---------A A----------B--B----------A A------------------------A -------------------------- 
-------------------------- -------------------------- A------------------------A A------------------------A A------------------------A -------------------------- 
-------------------------- -------------------------- -------------------------- A------------------------A A------------------------A -------------------------- 
-------------------------- -------------------------- -------------------------- A------------------------A A------------------------A -------------------------- 
-------------------------- -------------------------- -------------------------- A------------------------A A------------------------A -------------------------- 
-------------------------- -------------------------- -------------------------- A------------------------A A------------------------A -------------------------- 
-------------------------- -------------------------- -------------------------- A------------------------A A------------------------A -------------------------- 
-------------------------- -------------------------- -------------------------- -------------------------- A------------------------A -------------------------- 
-------------------------- -------------------------- -------------------------- -------------------------- A------------------------A -------------------------- 
-------------------------- -------------------------- -------------------------- -------------------------- A------------------------A -------------------------- 
-------------------------- -------------------------- -------------------------- -------------------------- A------------------------A -------------------------- 
-------------------------- -------------------------- -------------------------- -------------------------- A------------------------A -------------------------- 
-------------------------- -------------------------- -------------------------- A------------------------A -------------------------- -------------------------- 
-------------------------- A------------------------A A------------------------A -------------------------- -------------------------- -------------------------- 
