model
size = 30 32 30, scale = 0.05, origin = -y
material 
  colors = A:#EEE
voxels
71-3(8A22-)8A832-8A20-3(2A8-2A18-)2A8-2A800-8A20-2A8-2A16-3(2A12-2A14-)2A12-2A796-12A16-2A2-8A2-2A13-3(A4-8A4-A12-)A4-8A4-A17-13(8A22-)8A23-6A24-6A25-4A290-5A6-5A13-A2-3A6-3A2-A11-3(A3-3A6-3A3-A10-)A3-3A6-3A3-A14-15(3A6-3A18-)3A6-3A19-10A20-10A21-8A24-4A199-4A10-4A11-A-3A10-3A-A9-3(A2-3A10-3A2-A8-)A2-3A10-3A2-A11-13(3A10-3A14-)3A10-3A15-2(2A10-2A16-)14A17-12A18-12A19-10A22-6A167-3A14-3A9-A-2A14-2A-A7-3(A2-2A14-2A2-A6-)A2-2A14-2A2-A9-13(2A14-2A12-)2A14-2A13-4(A14-)16A14-16A15-14A17-12A19-10A21-8A135-3A16-3A7-A-2A16-2A-A5-3(A2-2A16-2A2-A4-)A2-2A16-2A2-A7-13(2A16-2A10-)2A16-2A11-2(A16-A12-)18A12-18A13-16A14-16A15-14A17-12A20-8A105-2A18-2A7-A-A18-A-A5-3(A2-A18-A2-A4-)A2-A18-A2-A7-16(A18-A10-)20A11-18A12-18A13-16A14-16A15-14A18-10A22-6A75-3A18-3A5-A-2A18-2A-A3-A3(2-2A18-2A2(2-A))2-2A18-2A2-A5-15(2A18-2A8-)2A18-2A9-2(20A10-)20A11-18A13-16A14-16A16-12A19-10A23-4A46-2A20-2A5-A-A20-A-A3-A2-3(A20-3(A2-))A20-A2-A5-16(A20-A8-)22A8-22A9-20A10-20A11-18A13-16A15-14A17-12A20-8A43-3A20-3A3-A-2A20-2A2(-A)2-3(2A20-2(2A2-))2A20-2A2-A3-13(2A20-2A6-)2A20-2A7-2(A20-A8-)2(22A8-)22A9-20A11-18A12-18A13-16A16-12A19-10A42-2A22-2A3-A-A22-2(A-)A3(2-A22-A2-2A)2-A22-A2-A3-15(A22-A6-)A22-A7-2(22A8-)22A9-20A10-20A11-18A13-16A15-14A18-10A23-4A15-4(2A22-2A3-A-A22-2(A-)A3(2-A22-A2-2A)2-A22-A2-A3-16(A22-A6-)24A7-2(22A8-)22A9-20A11-18A13-16A15-14A17-12A21-6A14-)2A22-2A3-A-A22-2(A-)A3(2-A22-A2-2A)2-A22-A2-A3-15(A22-A6-)A22-A7-2(22A8-)22A9-20A10-20A11-18A13-16A15-14A18-10A23-4A15-3A20-3A3-A-2A20-2A2(-A)2-3(2A20-2(2A2-))2A20-2A2-A3-13(2A20-2A6-)2A20-2A7-2(A20-A8-)2(22A8-)22A9-20A11-18A12-18A13-16A16-12A19-10A43-2A20-2A5-A-A20-A-A3-A2-3(A20-3(A2-))A20-A2-A5-16(A20-A8-)22A8-22A9-20A10-20A11-18A13-16A15-14A17-12A20-8A44-3A18-3A5-A-2A18-2A-A3-A3(2-2A18-2A2(2-A))2-2A18-2A2-A5-15(2A18-2A8-)2A18-2A9-2(20A10-)20A11-18A13-16A14-16A16-12A19-10A23-4A47-2A18-2A7-A-A18-A-A5-3(A2-A18-A2-A4-)A2-A18-A2-A7-16(A18-A10-)20A11-18A12-18A13-16A14-16A15-14A18-10A22-6A76-3A16-3A7-A-2A16-2A-A5-3(A2-2A16-2A2-A4-)A2-2A16-2A2-A7-13(2A16-2A10-)2A16-2A11-2(A16-A12-)18A12-18A13-16A14-16A15-14A17-12A20-8A106-3A14-3A9-A-2A14-2A-A7-3(A2-2A14-2A2-A6-)A2-2A14-2A2-A9-13(2A14-2A12-)2A14-2A13-4(A14-)16A14-16A15-14A17-12A19-10A21-8A137-4A10-4A11-A-3A10-3A-A9-3(A2-3A10-3A2-A8-)A2-3A10-3A2-A11-13(3A10-3A14-)3A10-3A15-2(2A10-2A16-)14A17-12A18-12A19-10A22-6A169-5A6-5A13-A2-3A6-3A2-A11-3(A3-3A6-3A3-A10-)A3-3A6-3A3-A14-15(3A6-3A18-)3A6-3A19-10A20-10A21-8A24-4A202-12A16-2A2-8A2-2A13-3(A4-8A4-A12-)A4-8A4-A17-13(8A22-)8A23-6A24-6A25-4A294-8A20-2A8-2A16-3(2A12-2A14-)2A12-2A828-8A20-3(2A8-2A18-)2A8-2A860-3(8A22-)8A791-
