model
size = 31 32 17, scale = 0.05, origin = -y
material 
  colors = A:#111 B:#F60 C:#EEE
voxels
9-12(13A18-)2(2AC)ACA3CA18-2(2AC)2(AC)3A18-2AC2A3CA2C2A18-2(2AC)2(AC)3A18-A3C2(AC)A3CA2(18-13A)18-4A2BC2B4A18-3A2B3C2B3A17-3A2B2C2BC2B3A15-4A3B2(C2B)4A14-4A3B3C3B4A15-3A3B2(C2B)3A17-2A2B2C2BC2B2A19-2A2B3C2B2A21-2A2BC2B2A24-5A27-2(3A28-)3A21-14(17A14-)17A15-4(15A16-)15A14-19A11-21A2(10-3A-17A)11-2A-16A13-17A15-15A16-15A21-3(5A26-)5A19-9(A17-A12-)3(2A15-2A12-)2A15-2A13-A15-A5(14-17A)15-15A11-3A2-15A3(2-3A6-3A3-14A)2-3A7-2A19-2A8-4A15-4A9-3A15-3A12-2(A15-)5A5-5A20-2(A5-A24-)A5-A17-8(A19-A10-)A19-A11-5(A17-A12-)A17-A13-4(A15-A14-)A15-A9-A4-A15-2(A4-)2(A25-A4-)2A23-2A4-3A21-3A5-3A19-3A6-4A17-4A7-4A15-4A10-2A15-2A14-4A7-4A19-A7-A22-A7-A16-9(A19-A10-)2(2A17-2A10-)2A17-2A11-3(A17-A12-)2A15-2A12-2A15-2A13-2(A15-A14-)A15-A8-A5-A15-A5-2(A2-A27-)A2-2A25-2A3-2A23-2A4-3A21-3A4-4A19-4A5-4A17-4A7-4A15-4A11-2A13-2A16-3A7-3A18-3A7-3A14-14(A19-A10-)A19-A11-3(A17-A12-)A17-A13-A15-A8-A5-A15-A5-3(A2-A27-)A2-2A25-2A2-3A23-3A3-3A21-3A4-4A19-4A5-4A17-4A8-3A15-3A2(13-A)16-2(A13-)15(A19-A10-)2A17-2A10-2A17-2A11-2(A17-A12-)2A15-2A2(6-A)15-A6-2A2(28-3A)28-2A-A26-2A2-2A25-2A2-3A23-3A3-3A21-3A5-3A19-3A7-4A15-4A11-A15-A14-A15-A12-15(A19-A10-)2(2A17-2A10-)2A17-2A11-A17-A12-2A16-A6-A5-2A16-A5-2A3(28-3A)28-2A-A26-2A2-2A25-2A3-2A23-2A4-3A21-3A6-2A19-2A10-2A16-A13-A16-A11-15(A19-A10-)4(2A17-2A10-)3A16-2A5-A5-2A16-A5-2A23-A4-4(3A28-)2A-A26-2A2-2A25-2A3-2A23-2A5-3A19-3A9-2A16-A13-A16-A11-15(A19-A10-)2(2A17-2A10-)2A17-2A11-A17-A12-2A16-A6-A5-2A16-A5-2A23-A4-4(3A28-)2A-A26-2A2-2A25-2A3-2A23-2A5-3A19-3A9-2A16-A13-A16-A11-15(A19-A10-)2A17-2A10-2A17-2A11-2(A17-A12-)2A16-2(A6-)A22-2A3(28-3A)28-2A-A26-2A2-2A25-2A3-2A23-2A4-3A21-3A6-2A19-2A10-2A16-A13-A16-A11-14(A19-A10-)A19-A11-3(A17-A12-)A17-A13-A15-A7-A6-A15-A6-2A2(28-3A)28-2A-A26-2A2-2A25-2A2-3A23-3A3-3A21-3A5-4A17-4A7-4A15-4A11-2A14-A14-2A14-A12-9(A19-A10-)2(2A17-2A10-)2A17-2A11-2(A17-A12-)A17-A13-4(A15-A14-)A15-A8-A5-A15-A5-2(A2-A27-)A2-A26-2A2-2A25-2A2-3A23-3A3-3A21-3A4-4A19-4A5-4A17-4A8-3A15-3A2(13-A)16-2(A13-)8(A19-A10-)A19-A11-5(A17-A12-)A17-A13-4(A15-A14-)A15-A8-A5-A15-A5-2(A2-A27-)A2-2A25-2A3-2A23-2A4-3A21-3A4-4A19-4A5-4A17-4A7-4A15-4A11-2(A15-)A13-A16-A13-A14-9(A17-A12-)3(2A15-2A12-)2A15-2A13-5(A15-A14-)2(A15-)A13-A10-A5-A13-A5-2(A4-)2A13-2A2(4-A)25-A4-2A23-2A4-3A21-3A5-3A19-3A6-4A17-4A7-4A16-3A10-2A15-2A14-2A11-2A17-2A9-2A18-2A9-2A16-2(A-15A14-)12(17A14-)17A15-4(15A16-)15A11-4A-15A-4A3(6-25A)7-23A8-23A9-21A12-17A15-15A17-13A19-11A21-10A18-3A2BA4CAB3A16-3A2B4ACAB3A16-3A2B2A3CAB3A16-3A2B4ACAB3A16-3A2BA4CAB3A16-3A2B6AB3A16-3A2BA4CAB3A16-3A2BAC4AB3A16-3A2BA4CAB3A16-3A2BAC2ACAB3A16-3A2BA4CAB3A16-3A2B6AB3A16-3A2BAC2ACAB3A17-2A2BA2CACAB2A18-2A2BACA2CAB2A18-2A2BAC2ACAB2A18-2A2B6AB2A18-2A2BA4CAB2A18-2A2BAC2ACAB2A18-2A2BA4CAB2A18-2A2BAC4AB2A17-3A2BA4CAB3A14-5A2B6AB5A12-5A2BAC2ACAB5A12-5A2BA4CAB5A13-4A2BAC2ACAB4A15-3A2BAC2ACAB3A16-3A2B6AB3A18-A2BA4CABA20-A2B4ACABA21-2B4ACAB22-2BA4CAB11-
