model
size = 30 22 30, scale = 0.05, origin = -y
material 
  colors = A:#EEE B:#B6CEDE C:#9AC9DF D:#58B2DC E:#111 F:#3A8FB7 G:#1E72C1 H:#888 I:#274695 J:#444 K:#0B346E L:#255359 M:#FBE251
voxels
------------------------------ ------------------------------ ------------------------------ ------------------------------ ------------------------------ ------------------------------ ------------------------------ ------------------------------ ------------------------------ ------------------------------ ------------------------------ ------------------------------ ------------------------------ ------------------------------ ------------------------------ -------------BBBB------------- --------------BB-------------- ------------------------------ ------------------------------ ------------------------------ ------------------------------ ------------------------------ 
------------------------------ ------------------------------ ------------------------------ ------------------------------ ------------------------------ ------------------------------ ------------------------------ ------------------------------ ------------------------------ ------------------------------ ------------------------------ ------------------------------ ------------------------------ ------------------------------ ------------------------------ -----------CCAAAACE----------- ------------DDAADDE----------- -------------DDDD-E----------- ------------------------------ ------------------------------ ------------------------------ ------------------------------ 
------------------------------ ------------------------------ ------------------------------ ------------------------------ ------------------------------ ------------------------------ ------------------------------ ------------------------------ ------------------------------ ------------------------------ ------------------------------ ------------------------------ ------------------------------ ------------------------------ ------------------------------ ---------CCA------CCC--------- ----------DDAAAAAALD---------- -----------DDAAAADD----------- -------------DDDD-E----------- ------------------------------ ------------------------------ ------------------------------ 
------------------------------ ------------------------------ ------------------------------ ------------------------------ ------------------------------ ------------------------------ ------------------------------ ------------------------------ ------------------------------ ------------------------------ ------------------------------ ------------------------------ ------------------------------ ------------------------------ ------------------------------ ------CCCA----------ACCC------ -------CDDAA------AADFF-E----- ---------DFAAAAAAALFF--------- -----------FFFFFFFE----------- ------------------------------ ------------------------------ ------------------------------ 
------------------------------ ------------------------------ ------------------------------ ------------------------------ ------------------------------ ------------------------------ ------------------------------ ------------------------------ ------------------------------ ------------------------------ ------------------------------ ------------------------------ ------------------------------ ------------------------------ ------------------------------ -----BAA--------------AAC----- -----BCAAA----------AAAFLD---- ------CCDAAAA----AAAAFFFE----- ---------DFGFAAAAFEFF--------- -------------FFFF------------- ------------------------------ ------------------------------ 
------------------------------ ------------------------------ ------------------------------ ------------------------------ ------------------------------ ------------------------------ ------------------------------ ------------------------------ ------------------------------ ------------------------------ ------------------------------ ------------------------------ ------------------------------ ------------------------------ ------------------------------ ----B--------------------C---- ----BAA----------------AAD---- -----BCAAAA--------AAAAGLD---- -------CDDFAAA--AAAGGGG-E----- -----------FGGGGGGE----------- ------------------------------ ------------------------------ 
------------------------------ ------------------------------ ------------------------------ ------------------------------ ------------------------------ ------------------------------ ------------------------------ ------------------------------ ------------------------------ ------------------------------ ------------------------------ ------------------------------ ------------------------------ ------------------------------ ------------------------------ ---BA--------------------AC--- ----BA------------------AD---- ----BBAA--------------AALD---- ------CCAAAA------AAAAGIE----- --------DDFFGIGGGGEGGG-------- ------------------------------ ------------------------------ 
------------------------------ ------------------------------ ------------------------------ ------------------------------ ------------------------------ ------------------------------ ------------------------------ ------------------------------ ------------------------------ ------------------------------ ------------------------------ ------------------------------ ------------------------------ ------------------------------ ------------------------------ ---BA--------------------AC--- ---BA-------------------AAD--- ----BAA----------------ALD---- -----BCAAA----------AAAGE----- -------CDDFFGAAAAIEIIII------- -------------GIII------------- ------------------------------ 
------------------------------ ------------------------------ ------------------------------ ------------------------------ ------------------------------ ------------------------------ ------------------------------ ------------------------------ ------------------------------ ------------------------------ ------------------------------ ------------------------------ ------------------------------ ------------------------------ ------------------------------ ---B----------------------C--- ---BA--------------------AD--- ----BA------------------AD---- -----BAA--------------AAE----- ------CCDDFAAAAAAAEIIKIG------ -----------FGGIKIIE----------- ------------------------------ 
------------------------------ ------------------------------ ------------------------------ ------------------------------ ------------------------------ ------------------------------ ------------------------------ ------------------------------ ------------------------------ ------------------------------ ------------------------------ ------------------------------ ------------------------------ ------------------------------ ------------------------------ --BA----------------------BC-- ---BA--------------------AD--- ---BAA------------------AAD--- ----BBAA--------------AAED---- ------CCDAAAA-AA-AAAAIIG------ ---------DFFGGIIKKEKK--------- ------------------------------ 
------------------------------ ------------------------------ ------------------------------ ------------------------------ ------------------------------ ------------------------------ ------------------------------ ------------------------------ ------------------------------ ------------------------------ ------------------------------ ------------------------------ ------------------------------ ------------------------------ ------------------------------ --B------------------------C-- --BA----------------------BC-- ---BAA------------------AAD--- ----BBA----------------AED---- ------CCDAAA--AA--AAAIIG------ ---------DFFGGIIKKEKK--------- ------------------------------ 
------------------------------ ------------------------------ ------------------------------ ------------------------------ ------------------------------ ------------------------------ ------------------------------ ------------------------------ ------------------------------ ------------------------------ ------------------------------ ------------------------------ ------------------------------ ------------------------------ ------------------------------ -EA------------------------AE- --EA----------------------ALE- --ELA--------------------ALBE- ---EEAA-------AA-------AAEEE-- -----EEEEEAAE-EE-EEEEEEEM----- --------EEEEEEEEEEMEEE-------- ------------------------------ 
------------------------------ ------------------------------ ------------------------------ ------------------------------ ------------------------------ ------------------------------ ------------------------------ ------------------------------ ------------------------------ ------------------------------ ------------------------------ ------------------------------ ------------------------------ ------------------------------ ------------------------------ -B--------------------------C- -BA------------------------AC- --BAA--------------------AAC-- ---BBA------AAAAAA------ADD--- -----BCCAA-AAAAAAAE-AAIGE----- --------DDFFGGIIKKEKKI-------- ------------------------------ 
------------------------------ ------------------------------ ------------------------------ ------------------------------ ------------------------------ ------------------------------ ------------------------------ ------------------------------ ------------------------------ ------------------------------ ------------------------------ ------------------------------ ------------------------------ ------------------------------ ------------------------------ BA--------------------------AC -BA------------------------AC- -BAA----------------------AAC- --BBAA------AAAAAA------AADC-- ----BBCAA---AAAAAA---AAGED---- -------CDDFFGGIIKKEKKII------- ------------------------------ 
------------------------------ --------------HH-------------- --------------HH-------------- --------------HH-------------- --------------HH-------------- --------------HH-------------- --------------HH-------------- --------------HH-------------- --------------HH-------------- --------------HH-------------- --------------HH-------------- --------------HH-------------- --------------HH-------------- --------------HH-------------- --------------HH-------------- BA------------HH------------AC BAA-----------HH-----------AAC -BAA----------HH----------AAC- --BBA------AAAAAAAE-----AADC-- ----BBCAAAAAAAAAAAEAAAAGED---- -------CDDFFGGAAIIEIIKI------- --------------IK-------------- 
--------------HH-------------- --------------HH-------------- --------------JJ-------------- --------------JJ-------------- --------------JJ-------------- --------------JJ-------------- --------------JJ-------------- --------------JJ-------------- --------------JJ-------------- --------------JJ-------------- --------------JJ-------------- --------------JJ-------------- --------------JJ-------------- --------------JJ-------------- --------------JJ-------------- BA------------JJ------------AC BAA-----------JJ-----------AAC -BAA----------JJ----------AAC- --BBA------AAAAAAAE-----AADC-- ----BBCAAAAAAAAAAALAAAAGED---- -------CDDFFGGAAIIEIIII------- --------------II-------------- 
--------------HH-------------- --------------HH-------------- ------------------------------ ------------------------------ ------------------------------ ------------------------------ ------------------------------ ------------------------------ ------------------------------ ------------------------------ ------------------------------ ------------------------------ ------------------------------ ------------------------------ ------------------------------ BA--------------------------AC -BA------------------------AC- -BAA----------------------AAC- --BBAA------AAAAAA------AADC-- ----BBCAA---AAAAAA---AAIED---- -------CDDFFGIGGGGEGGGG------- ------------------------------ 
--------------JJ-------------- --------------HH-------------- --------------HH-------------- --------------HH-------------- ------------------------------ ------------------------------ ------------------------------ ------------------------------ ------------------------------ ------------------------------ ------------------------------ ------------------------------ ------------------------------ ------------------------------ ------------------------------ -B--------------------------C- -BA------------------------AC- --BAA--------------------AAC-- ---BBA------AAAAAA------ADD--- -----BCCAA-AAAAAAAE-AAGGE----- --------DDFFGGGGGGEGGG-------- ------------------------------ 
------------------------------ --------------JJ-------------- --------------JJ-------------- --------------JJ-------------- ------------------------------ ------------------------------ ------------------------------ ------------------------------ ------------------------------ ------------------------------ ------------------------------ ------------------------------ ------------------------------ ------------------------------ ------------------------------ -BA------------------------AC- --BA----------------------AC-- --BAA--------------------ADC-- ---BBAA-------AA-------AAD---- -----BCCAAAAA-AA-AEAAAFFE----- --------DDFGFFFFFFEFFF-------- ------------------------------ 
------------------------------ ------------------------------ ------------------------------ ------------------------------ ------------------------------ ------------------------------ ------------------------------ ------------------------------ ------------------------------ ------------------------------ ------------------------------ ------------------------------ ------------------------------ ------------------------------ ------------------------------ --B------------------------C-- --BA----------------------AC-- ---BAA------------------AAD--- ----BBA----------------AED---- ------CCDAAA--AA--EAAFFF------ ---------DFFFFFFFFEFF--------- ------------------------------ 
------------------------------ ------------------------------ ------------------------------ ------------------------------ ------------------------------ ------------------------------ ------------------------------ ------------------------------ ------------------------------ ------------------------------ ------------------------------ ------------------------------ ------------------------------ ------------------------------ ------------------------------ --BA----------------------BC-- ---BA--------------------AC--- ---BAA------------------AAD--- ----BBAA--------------AAED---- ------CCDAAAA-AA-AEAADDD------ ---------FDDDDDDDDEDD--------- ------------------------------ 
------------------------------ ------------------------------ ------------------------------ ------------------------------ ------------------------------ ------------------------------ ------------------------------ ------------------------------ ------------------------------ ------------------------------ ------------------------------ ------------------------------ ------------------------------ ------------------------------ ------------------------------ ---B----------------------C--- ---BA--------------------AC--- ----BA------------------AD---- -----BAA--------------AAE----- ------CCDDDAAAAAAAEDDDDD------ -----------DDDDDDDE----------- ------------------------------ 
------------------------------ ------------------------------ ------------------------------ ------------------------------ ------------------------------ ------------------------------ ------------------------------ ------------------------------ ------------------------------ ------------------------------ ------------------------------ ------------------------------ ------------------------------ ------------------------------ ------------------------------ ---BA--------------------AC--- ---BAA------------------AAC--- ----BAA----------------ALC---- -----BCAAA----------AAACE----- -------DCCCCCAAAACECCCC------- -------------CCCC------------- ------------------------------ 
------------------------------ ------------------------------ ------------------------------ ------------------------------ ------------------------------ ------------------------------ ------------------------------ ------------------------------ ------------------------------ ------------------------------ ------------------------------ ------------------------------ ------------------------------ ------------------------------ ------------------------------ ---BA--------------------AC--- ----BA------------------AC---- ----BBAA--------------AAEC---- ------CCAAAA------AAAACC------ --------CCCCCCCCCCECCC-------- ------------------------------ ------------------------------ 
------------------------------ ------------------------------ ------------------------------ ------------------------------ ------------------------------ ------------------------------ ------------------------------ ------------------------------ ------------------------------ ------------------------------ ------------------------------ ------------------------------ ------------------------------ ------------------------------ ------------------------------ ----B--------------------C---- ----BAAA--------------AACC---- -----CBAAAA--------AAAABE----- -------BBBBAAAAAAAABBBB------- -----------BBBBBBBE----------- ------------------------------ ------------------------------ 
------------------------------ ------------------------------ ------------------------------ ------------------------------ ------------------------------ ------------------------------ ------------------------------ ------------------------------ ------------------------------ ------------------------------ ------------------------------ ------------------------------ ------------------------------ ------------------------------ ------------------------------ -----BAA--------------BBE----- -----BBBAA----------AABBE----- ------BBBBAAA----AAABBBB------ ---------BBBBAAAABEBB--------- -------------BBBB------------- ------------------------------ ------------------------------ 
------------------------------ ------------------------------ ------------------------------ ------------------------------ ------------------------------ ------------------------------ ------------------------------ ------------------------------ ------------------------------ ------------------------------ ------------------------------ ------------------------------ ------------------------------ ------------------------------ ------------------------------ ------BBBA----------ABBB------ -------BBBAA------AABBB------- ---------BBAAAAAAALBB--------- -----------BBBBBBBE----------- ------------------------------ ------------------------------ ------------------------------ 
------------------------------ ------------------------------ ------------------------------ ------------------------------ ------------------------------ ------------------------------ ------------------------------ ------------------------------ ------------------------------ ------------------------------ ------------------------------ ------------------------------ ------------------------------ ------------------------------ ------------------------------ ---------BBA------ABB--------- ----------BBAAAAAAEB---------- -----------BBAAAABE----------- -------------BBBB------------- ------------------------------ ------------------------------ ------------------------------ 
------------------------------ ------------------------------ ------------------------------ ------------------------------ ------------------------------ ------------------------------ ------------------------------ ------------------------------ ------------------------------ ------------------------------ ------------------------------ ------------------------------ ------------------------------ ------------------------------ ------------------------------ -----------BBAAAABE----------- ------------BBAABB------------ -------------BBBB------------- ------------------------------ ------------------------------ ------------------------------ ------------------------------ 
------------------------------ ------------------------------ ------------------------------ ------------------------------ ------------------------------ ------------------------------ ------------------------------ ------------------------------ ------------------------------ ------------------------------ ------------------------------ ------------------------------ ------------------------------ ------------------------------ ------------------------------ -------------BBBB------------- --------------BB-------------- ------------------------------ ------------------------------ ------------------------------ ------------------------------ ------------------------------ 
