model
size = 16 28 16, scale = 0.05, origin = -y
material 
  colors = A:#EEE B:#393 C:#222 D:#111 E:#444
voxels
---AACCCCCCCC--- ---CCBBBBBBBB--- ---CBBBBBBAAB--- ---BBBBBBBABB--- ---BBAAABBAAA--- ---BABAAABAAA--- ---ABBBBAAAAA--- ---ABBAAABBBB--- ---BBAABABABA--- ---BBABBAABBB--- ---BBABBBABBB--- ---BBBABBBAAA--- ---CBBBBBBBBB--- ---ACBBBBBBBB--- ---AACCCCCCCC--- ---AAAAAAAAAA--- ------AA---AA--- -----A-A-AAAA--- ------AA---AA--- -----A-A-AAAA--- ------AA---D---- ---AAAAAAAAAA--- ---AAAAAAAAAA--- ---------------- ---EEEEEEEEEE--- ---AAAAAAAAAA--- ---AAAAAAAAAA--- ---------------- 
--AAAAAAAAAAAC-- --AAAAAAABBBBB-- --CAAAAAABBBBB-- --BAAAAAABBBBB-- --BAAAAAABBBBB-- --BAAAAAABBBBA-- --BAAAAAABBBBA-- --BAAAAAABBBBA-- --BAAAAAABBBBA-- --BAAAAAABBBBA-- --BAAAAAAAAAAA-- --CAAAAAAAAAAA-- --AAAAAAAAAAAB-- --AAAAAAAAAAAB-- --AAAAAAAAAAAC-- --AAAAAAAAAAAA-- --ADDDAADDDAD--- --ADDADADAAAD--- --ADDDAADDDAD--- --ADDADADAAAD--- --ADDDAADDDAD--- --AAAAAAAAAAAA-- --AAAAAAAAAAAA-- ---CCCCCCCCCC--- --EAAAAAAAAAAE-- --AAAAAAAAAAAA-- --AAAAAAAAAAAA-- ---AAAAAAAAAA--- 
-AAAAAAAAAAAAAC- -AAAAAAAAAAAAAB- -AAAAAAAAAAAAAB- -CAAAAAAAAAAAAB- -CAAAAAAAAAAAAB- -BAAAAAAAAABBBA- -BAAAAAAAAABBBB- -BAAAAAAAAABBBA- -BAAAAAAAAABBBB- -CAAAAAAAAABBBB- -CAAAAAAAAABBBB- -CAAAAAAAAABBBB- -CAAAAAAAAAAAAB- -CAAAAAAAAAAAAB- -AAAAAAAAAAAAAC- -CAAAAAAAAAAAAA- -CAAAAAADAAAADA- -CAAAAAAAAAAADA- -CAAAAAAAAAAADA- -AAAAAAAAAAAADA- -AAAAAAAAAAAAD-- -AAAAAAAAAAAAAA- --AAAAAAAAAAAAA- --CAAAAAAAAAAC-- -EAAAAAAAAAAAAE- -AAAAAAAAAAAAAA- -AAAAAAAAAAAAAA- --AAAAAAAAAAAA-- 
AAAAAAAAAAAAAAAA AAAAAAAAAAAAAAAC AAAAAAAAAAAAAAAB AAAAAAAAAAAAAAAA CAAAAAAAAAAAAAAA CAAAAAAAAAAAAAAB CAAAAAAAAAAAAAAB CAAAAAAAAAAAAAAA CAAAAAAAAAAAAAAA CAAAAAAAAAAAAAAB AAAAAAAAAAAAAAAB AAAAAAAAAAAAAAAB AAAAAAAAAAAAAAAB CAAAAAAAAAAAAAAB AAAAAAAAAAAAAAAC CAAAAAAAAAAAAAAA AAAAAAAAAAAAAAD- AAAAAAAAAAAAAAD- CAAAAAAAAAAAAAD- AAAAAAAAAAAAAAD- AAAAAAAAAAAAAAD- AAAAAAAAAAAAAAAA AAAAAAAAAAAAAAAA --CAAAAAAAAAAAC- -AAAAAAAAAAAAAAE AAAAAAAAAAAAAAAA AAAAAAAAAAAAAAAA -AAAAA-----AAAA- 
AAAAAAAAAAAAAAAA AAAAAAAAAAAAAAAC AAAAAAAAAAAAAAAB AAAAAAAAAAAAAAAB AAAAAAAAAAAAAAAB AAAAAAAAAAAAAAAB AAAAAAAAAAAAAAAB AAAAAAAAAAAAAAAB AAAAAAAAAAAAAAAA CAAAAAAAAAAAAAAA AAAAAAAAAAAAAAAB AAAAAAAAAAAAAAAB AAAAAAAAAAAAAAAB CAAAAAAAAAAAAAAC AAAAAAAAAAAAAAAA CAAAAAAAAAAAAAAA AAAAAAAAAAAAAAD- AAAAAAAAAAAAAAD- CAAAAAAAAAAAAAD- AAAAAAAAAAAAAAD- AAAAAAAAAAAAAAD- AAAAAAAAAAAAAAAA AAAAAAAAAAAAAAAA -CAAAAAAAAAAAAC- EAAAAAAAAAAAAAAE AAAAAAAAAAAAAAAA AAAAAAAAAAAAAAAA -AAAAAAAAAAAAAA- 
AAAAAAAAAAAAAAAA AAAAAAAAAAAAAAAA AAAAAAAAAAAAAAAC AAAAAAAAAAAAAAAB AAAAAAAAAAAAAAAB AAAAAAAAAAAAAAAB AAAAAAAAAAAAAAAB AAAAAAAAAAAAAAAB AAAAAAAAAAAAAAAB CAAAAAAAAAAAAAAB CAAAAAAAAAAAAAAB CAAAAAAAAAAAAAAB CAAAAAAAAAAAAAAB CAAAAAAAAAAAAAAC AAAAAAAAAAAAAAAA CAAAAAAAAAAAAAAA CAAAAAAAAAAAAAAA CAAAAAAAAAAAAAAA CAAAAAAAAAAAAAD- AAAAAAAAAAAAAAAA AAAAAAAAAAAAAAAA AAAAAAAAAAAAAAAA AAAAAAAAAAAAAAAA -CAAAAAAAAAAAAC- EAAAAAAAAAAAAAAE AAAAAAAAAAAAAAAA AAAAAAAAAAAAAAAA -AAAAAAAAAAAAAA- 
AAAAAAAAAAAAAAAA AAAAAAAAAAAAAAAA AAAAAAAAAAAAAAAC AAAAAAAAAAAAAAAB AAAAAAAAAAAAAAAB AAAAAAAAAAAAAAAB AAAAAAAAAAAAAAAB AAAAAAAAAAAAAAAB AAAAAAAAAAAAAAAB AAAAAAAAAAAAAAAB AAAAAAAAAAAAAAAB AAAAAAAAAAAAAAAB AAAAAAAAAAAAAAAC AAAAAAAAAAAAAAAA AAAAAAAAAAAAAAAA AAAAAAAAAAAAAAAA AAAAAAAAAAAAAAD- AAAAAAAAAAAAAAD- AAAAAAAAAAAAAAD- AAAAAAAAAAAAAAD- AAAAAAAAAAAAAAD- AAAAAAAAAAAAAAAA AAAAAAAAAAAAAAAA -CAAAAAAAAAAAAC- EAAAAAAAAAAAAAAE AAAAAAAAAAAAAAAA AAAAAAAAAAAAAAAA -AAAAAAAAAAAAAA- 
AAAAAAAAAAAAAAAA AAAAAAAAAAAAAAAA AAAAAAAAAAAAAAAA AAAAAAAAAAAAAAAC AAAAAAAAAAAAAAAB AAAAAAAAAAAAAAAB AAAAAAAAAAAAAAAB AAAAAAAAAAAAAAAB AAAAAAAAAAAAAAAB AAAAAAAAAAAAAAAB AAAAAAAAAAAAAAAB AAAAAAAAAAAAAAAC AAAAAAAAAAAAAAAA AAAAAAAAAAAAAAAA AAAAAAAAAAAAAAAA AAAAAAAAAAAAAAAA AAAAAAAAAAAAAAAA AAAAAAAAAAAAAAAA AAAAAAAAAAAAAAAA AAAAAAAAAAAAAAAA AAAAAAAAAAAAAAAA AAAAAAAAAAAAAAAA AAAAAAAAAAAAAAAA -CAAAAAAAAAAAAC- EAAAAAAAAAAAAAAE AAAAAAAAAAAAAAAA AAAAAAAAAAAAAAAA -AAAAAAAAAAAAAA- 
AAAAAAAAAAAAAAAA AAAAAAAAAAAAAAAA AAAAAAAAAAAAAAAA AAAAAAAAAAAAAAAA AAAAAAAAAAAAAAAC AAAAAAAAAAAAAAAB AAAAAAAAAAAAAAAB AAAAAAAAAAAAAAAB AAAAAAAAAAAAAAAB AAAAAAAAAAAAAAAB AAAAAAAAAAAAAAAC AAAAAAAAAAAAAAAA AAAAAAAAAAAAAAAA AAAAAAAAAAAAAAAA AAAAAAAAAAAAAAAA AAAAAAAAAAAAAAAA AAAAAAAAAAAAAAAA AAAAAAAAAAAAAAAA AAAAAAAAAAAAAAAA AAAAAAAAAAAAAAAA AAAAAAAAAAAAAAAA AAAAAAAAAAAAAAAA AAAAAAAAAAAAAAAA -CAAAAAAAAAAAAC- EAAAAAAAAAAAAAAE AAAAAAAAAAAAAAAA AAAAAAAAAAAAAAAA -AAAAAAAAAAAAAA- 
AAAAAAAAAAAAAAAA AAAAAAAAAAAAAAAA AAAAAAAAAAAAAAAA AAAAAAAAAAAAAAAA AAAAAAAAAAAAAAAA AAAAAAAAAAAAAAAC AAAAAAAAAAAAAAAC AAAAAAAAAAAAAAAC AAAAAAAAAAAAAAAC AAAAAAAAAAAAAAAC AAAAAAAAAAAAAAAA AAAAAAAAAAAAAAAA AAAAAAAAAAAAAAAA AAAAAAAAAAAAAAAA AAAAAAAAAAAAAAAA AAAAAAAAAAAAAAAA AAAAAAAAAAAAAAAA AAAAAAAAAAAAAAAA AAAAAAAAAAAAAAAA AAAAAAAAAAAAAAAA AAAAAAAAAAAAAAAA AAAAAAAAAAAAAAAA AAAAAAAAAAAAAAAA -CAAAAAAAAAAAAC- EAAAAAAAAAAAAAAE AAAAAAAAAAAAAAAA AAAAAAAAAAAAAAAA -AAAAAAAAAAAAAA- 
AAAAAAAAAAAAAAAA AAAAAAAAAAAAAAAA AAAAAAAAAAAAAAAA AAAAAAAAAAAAAAAA AAAAAAAAAAAAAAAA AAAAAAAAAAAAAAAA AAAAAAAAAAAAAAAA AAAAAAAAAAAAAAAA AAAAAAAAAAAAAAAA AAAAAAAAAAAAAAAA AAAAAAAAAAAAAAAA AAAAAAAAAAAAAAAA AAAAAAAAAAAAAAAA AAAAAAAAAAAAAAAA AAAAAAAAAAAAAAAA AAAAAAAAAAAAAAAA AAAAAAAAAAAAAAAA AAAAAAAAAAAAAAAA AAAAAAAAAAAAAAAA AAAAAAAAAAAAAAAA AAAAAAAAAAAAAAAA AAAAAAAAAAAAAAAA AAAAAAAAAAAAAAAA -CAAAAAAAAAAAAC- EAAAAAAAAAAAAAAE AAAAAAAAAAAAAAAA AAAAAAAAAAAAAAAA -AAAAAAAAAAAAAA- 
AAAAAAAAAAAAAAAA AAAAAAAAAAAAAAAA AAAAAAAAAAAAAAAA AAAAAAAAAAAAAAAA AAAAAAAAAAAAAAAA AAAAAAAAAAAAAAAA AAAAAAAAAAAAAAAA AAAAAAAAAAAAAAAA AAAAAAAAAAAAAAAA AAAAAAAAAAAAAAAA AAAAAAAAAAAAAAAA AAAAAAAAAAAAAAAA AAAAAAAAAAAAAAAA AAAAAAAAAAAAAAAA AAAAAAAAAAAAAAAA AAAAAAAAAAAAAAAA AAAAAAAAAAAAAAAA AAAAAAAAAAAAAAAA AAAAAAAAAAAAAAAA AAAAAAAAAAAAAAAA AAAAAAAAAAAAAAAA AAAAAAAAAAAAAAAA AAAAAAAAAAAAAAAA -CAAAAAAAAAAAAC- EAAAAAAAAAAAAAAE AAAAAAAAAAAAAAAA AAAAAAAAAAAAAAAA -AAAAAA-AAAAAAA- 
AAAAAAAAAAAAAAAA AAAAAAAAAAAAAAAA AAAAAAAAAAAAAAAA AAAAAAAAAAAAAAAA AAAAAAAAAAAAAAAA AAAAAAAAAAAAAAAA AAAAAAAAAAAAAAAA AAAAAAAAAAAAAAAA AAAAAAAAAAAAAAAA AAAAAAAAAAAAAAAA AAAAAAAAAAAAAAAA AAAAAAAAAAAAAAAA AAAAAAAAAAAAAAAA AAAAAAAAAAAAAAAA AAAAAAAAAAAAAAAA AAAAAAAAAAAAAAAA AAAAAAAAAAAAAAAA AAAAAAAAAAAAAAAA AAAAAAAAAAAAAAAA AAAAAAAAAAAAAAAA AAAAAAAAAAAAAAAA AAAAAAAAAAAAAAAA AAAAAAAAAAAAAAAA -CAAAAAAAAAAAAC- EAAAAAAAAAAAAAAE AAAAAAAAAAAAAAAA AAAAAAAAAAAAAAAA -AAAAAAAAAAAAAA- 
-AAAAAAAAAAAAAA- -AAAAAAAAAAAAAA- -AAAAAAAAAAAAAA- -AAAAAAAAAAAAAA- -AAAAAAAAAAAAAA- -AAAAAAAAAAAAAA- -AAAAAAAAAAAAAA- -AAAAAAAAAAAAAA- -AAAAAAAAAAAAAA- -AAAAAAAAAAAAAA- -AAAAAAAAAAAAAA- -AAAAAAAAAAAAAA- -AAAAAAAAAAAAAA- -AAAAAAAAAAAAAA- -AAAAAAAAAAAAAA- -AAAAAAAAAAAAAA- -AAAAAAAAAAAAAA- -AAAAAAAAAAAAAA- -AAAAAAAAAAAAAA- -AAAAAAAAAAAAAA- -AAAAAAAAAAAAAA- -AAAAAAAAAAAAAA- --AAAAAAAAAAAAA- --CAAAAAAAAAAC-- -EAAAAAAAAAAAAE- -AAAAAAAAAAAAAA- -AAAAAAAAAAAAAA- --AAAAAAAAAAAA-- 
--AAAAAAAAAAAA-- --AAAAAAAAAAAA-- --AAAAAAAAAAAA-- --AAAAAAAAAAAA-- --AAAAAAAAAAAA-- --AAAAAAAAAAAA-- --AAAAAAAAAAAA-- --AAAAAAAAAAAA-- --AAAAAAAAAAAA-- --AAAAAAAAAAAA-- --AAAAAAAAAAAA-- --AAAAAAAAAAAA-- --AAAAAAAAAAAA-- --AAAAAAAAAAAA-- --AAAAAAAAAAAA-- --AAAAAAAAAAAA-- --AAAAAAAAAAAA-- --AAAAAAAAAAAA-- --AAAAAAAAAAAA-- --AAAAAAAAAAAA-- --AAAAAAAAAAAA-- --AAAAAAAAAAAA-- ---AAAAAAAAAA--- ---CCCCCCCCCC--- --EAAAAAAAAAAE-- --AAAAAAAAAAAA-- --AAAAAAAAAAAA-- ---AAAAAAAAAA--- 
---AAAAAAAAAA--- ---AAAAAAAAAA--- ---AAAAAAAAAA--- ---AAAAAAAAAA--- ---AAAAAAAAAA--- ---AAAAAAAAAA--- ---AAAAAAAAAA--- ---AAAAAAAAAA--- ---AAAAAAAAAA--- ---AAAAAAAAAA--- ---AAAAAAAAAA--- ---AAAAAAAAAA--- ---AAAAAAAAAA--- ---AAAAAAAAAA--- ---AAAAAAAAAA--- ---AAAAAAAAAA--- ---AAAAAAAAAA--- ---AAAAAAAAAA--- ---AAAAAAAAAA--- ---AAAAAAAAAA--- ---AAAAAAAAAA--- ---AAAAAAAAAA--- ---AAAAAAAA----- ---------------- ---EEEEEEEEEE--- ---AAAAAAAAAA--- ---AAAAAAAAAA--- ---------------- 
