model
size = 24 32 24, scale = 0.05, origin = -y
material 
  colors = A:#A735B0 B:#EA49ED C:#CF41D4 D:#BA3BC1 E:#6E2377 F:#862B8F G:#E869ED H:#8F4BDE I:#693FDE J:#3D3BDE K:#E781ED L:#BD43ED M:#9141ED N:#501959 O:#F677FF P:#5B1D64 Q:#A758ED
voxels
179-2A21-3(4D20-)3(4C20-)2B2C20-3BC6(20-4B)2(20-G2OB)20-G-2B20-B-2(2B22-)B23-B189-4F19-3F3A17-2AF5A16-8A16-2A4D2A2(16-8D)16-2D3CD2C2(16-8C)16-C4B3C16-5B3C3(16-2B4-2B)2(16-2B4-BG)16-2B4-2B3(16-2B5-B)16-KG22-2K2(23-K)23-G2(23-O)49-2E20-2I4E17-2I4F2E15-2IH6FE14-2H4F3AE13-2FAF8A2(12-12A)12-2A2D4A4D12-5D2A5D12-4D4AD3C12-3DC4A4C12-5C2A5C12-4C2BA5C12-C6B5C12-12B12-2B2-4B2-2(2B12-2B8-)GB12-2B8-2G2(12-2B9-G)12-B10-G12-B10-B23-B160-4J19-2JA3E17-2H4A2E15-3H5A2E13-I2H2F5AFE12-IH2F6AFE12-10A-A11-2(14A10-)2D9A3D10-3D7A4D10-4D7AC2D10-3D7A4C10-3C7A4C10-4C6A4C10-C3B6A4C10-C-3BA6B-B10-B2-8B2-B10-B3-6B3-2(B10-B12-)2(B23-)G23-G206-J5E17-J5A2E15-J2H5A2E13-2H-7A2E12-IH9AE12-I10AE11-I6AP6A10-14A9-15A9-2D12ADA8-3D10A3D8-2D12A2D8-2CD11A2C8-2C11A3C8-3C10A3C8-3CB9A3C8-C-3B6A3B-B8-B-6BA5B-B8-B3-8B3-B8-B4-6B4-2(B8-B14-)B8-K14-G8-O14-3(G23-)4(B23-)O23-O13-6E17-J5A2E15-J8AE13-2M8A2E12-HM9AE11-IHF9AFE10-2H11AF10-15A8-D15A7-2D14A2D6-3D13A2D6-2D13A3D6-2C14ACH6-3C12A2CH6-3C12A3C6-I2C12A3C6-I-CB9AB2A-C6-B-4B6A4B-B6-B2-12B2-B6-B3-9B4-B6-B3-B-6B2(5-B6-B3-2(B-)B2-B)5-B6-B3-2(B-)G2-B5-B6-B3-2(B-)2(O2-B5-G6-O7-)B2-B12-O10-J2(23-B)66-6E17-J2A-2A2E15-M7A2E13-2M8A2E12-HM9AE11-FHF9AFE9-FHF11A2F8-F15A7-2D16A6-2D15AD5-3D14A2DI4-2D15A2DI4-2C16AHI4-3C14AC2H4-L2(2C14A2CH4-I)-C14AC-H4-J2-2B9A4B-B4-J2-4B6A4B2-B4-I3-5BA6B3-B4-B5-8B5-B4-B7-4B7-B4-B18-B4-B222-6E17-E5A2E15-J7A2E13-HM8A2E11-FHM9AE11-FH10AFE9-3F11AEF7-D17A5-2D18A4-3D15A2D4-2D16A2D4-D17ADI4-2C17AI4-2C2(16ACH4-LC)16ACH4-QC16ACH4-I-3B10A3B-H4-I2-3B8A3B2-G4-I3-4B4A4B3-B9-9BG4-B9-9B5-2(B9-B13-)B9-J13-B9-B13-G23-G131-6E17-2E3A3E15-J7A2E13-2M3A3N2A2E11-FH3A4N3A2E9-FHF11AFE7-3F13A2F5-2D18A4-2D18A3-3D17A2D2-2D17A3D2-2C18AID2-2C18AIJ2-3C17AHJ2-2C18AHJ2-LB18AHI2-L2B17AHI2-Q-BAB12A3B-H2-Q2-3B10A3B2-G2-L2-4B8A3B3-G2(2-B)-10B2G4-G2(2-B)2-9B2G4-2(B2-)B4-6B2-2(B7-G2-B12-)B7-B2(2-B12-B7-K)15-I7-K23-B2(23-K)32-4E18-2E3A3E15-E7A2E12-2M6AN2A3E9-F2M7A2N2AFE7-F2M13A2F6-2F15AF5-D19A3-3D19A2(2-2D18A2D)2-2C18A2D2-2C19AC2-2C18A2C2-2C18ACJ2-3B17ACJ2-L2B17ACI2-L-2B14ABA-I2-L-3B12A3B-H2-L2-3B9A4B2-H2-B3-4B6A4B3-G2-B5-10B5-G2-B6-8B6-2(B2-G11-B8-)3(B14-B8-)B2(23-O)59-4E18-2E3A3E14-3E6A3E11-3M3A4N2A2E9-FM9AN2AFE7-FMF10AN2A2F5-3F15A2F4-D19A3-2D20A2-2D19AD-CD19A3D2C20A2D3C19AI2(3C20AJ)C3B19A2JB-2B18A-JB-3B17A-JB2-3B12A3B2-IB3-3B10A3B3-2B4-4B6A4B4-2B5-5BA6B5-HO5-O-8B7-BO5-O-B-4B9-2B5-O-B2-K11-BG5-B-B2-K11-KG5-B-K2-L11-K8-K2-M20-K2-Q23-H23-I23-J22-4E18-2E3A3E14-3E6A3E11-EM6AN3A2E9-2F12AFE7-2F14A2F5-3F17A4-D16AP2A3-2D20A2-2D19AD-2(2C20A2D)2C21A3C20A3CB20A2C3B19A2CB-2B18A-CB-3B17A-JB2-2B14ABA2-IB3-3B10A3B3-IB3-4B7A5B3-2B3-B-4B4A4B-B3-2B3-B3-8B3-B3-2B3-B5-4B-B3-G3-2B3-B10-B3-G4-B3-B10-B2(3-B4-B3-B10-O)3-J4-B3-I10-J3-B4-B3-I19-B3-B53-4E18-2E3A3E14-3E6A3E11-E7AN3A2E9-F2AP10AFE7-2F14A2F5-3F17A4-D19A3-2D20A2-2D19AD-C2D19A2(2D2C20A)4C20A2C3B19A2C3B20ACB-2B18A-CB-3B17A-CB2-3B12A3B2-CB3-3B10A3B3-2B4-4B6A4B4-2B5-4B3A5B5-2B7-2BA5B7-2B9-4B2(9-B10-B2-K)2(9-B10-K2-B)9-B10-J2-B92-4E18-8E14-3E6A3E11-2E9A3E9-EA2P5A3N2AFE7-2F2AN8AN2A2F5-AF18A4-20A3-2D20A2-2D19AD-3D18A3D2C19A3D3C19A5C19A2C3B18A3C3B19A2CB-2B17AC-CB-3B16AC-CB2-3B12A3B2-CB3-3B10A3B3-2B4-4B7A3B4-2B5-4B2A6B5-GB7-9B6-GB9-4B2-B6-GB15-B6-2B15-B183-8E15-2E5A3E12-FE9A3E9-3F7AN2AEFE7-3F10APA3F6-2F16A5-20A3-2D20A2(2-2D18A2D)2(2-2C18A2D)2-2C18A2C2-BC18A2(2C2-3B17A)2C2-B-2B16A-C2-B-3B12A3B-2(B2-)3B9A4B2(2-B)3-4B6A4B3-B2-B5-10B-B3-G9-8B2-B3-G8-B3-B6-B3-G8-Q3-A6-B3-G8-H3-B6-B3-B8-I3-B6-B12-J3-B141-6E16-10E13-FE7A3E11-2FP3AN4AE2F9-3F10A3F7-3F10APA2FA5-2AF12AP4A4-D19A3-3D18AD2-2D18A2D2-2C17A3D2-3C17ACD2(2-3C16A3C)2-3B17A2C2-4B15A3C2-B-3B12AB2A-C2-B2-3B10A3B2(2-B)2-4B8A3B3-2(B2-)B-12B4-3(B2-)10B5-3(B2-)B-6B7-G2-B2-G2-B6-B7-G2-A2-G9-B7-G2(5-K9-B7-B)5-I9-4(B23-)B65-8E15-3E3A4E13-2F4AP2A2EF11-2F10A2F9-3F11A2F7-3F15A5-2D18A4-3D16AD4-2D2(16A2D4-2C)2(16A2C4-2C)16A2C4-3B15A2C4-4B14A2C4-B-3B10A3B-C4-B2-3B8A3B2-B4-B3-3B5A4B3-2(B4-)10B2(4-B)5-7B2G2(4-B)13-G2(4-B)2(13-K9-B)13-2(B23-)B161-F3E18-4F4E14-5F3AE3F11-4F2AN3A4F9-4F9A3F8-3F13A7-2DF15A6-2D15AD5-3D15A2D4-2C15A3D4-3C15A2C4-3C14A3C4-3C15A2C4-CBC14A3C4-B-2B14A-C4-B-4B10ABA-C4-B2-4B6A4B2-B4-B3-13B2-B4-B3-B-8B2-A2-B4-2(B3-)4B4-A3(2-B4-2(B3-)B-B5-B)2-B4-2(B3-)B-B5-O7-B3-O3-J-B13-B7-3(K23-)B118-4F2E17-6FEF14-7FAE3F11-4F6A4F10-3F11A9-D2F13A7-3D13ADA6-2D13A3D6-2C13A3D6-3C13A2C3(6-3C12A3C)6-C-3B11A-C6-B-4B10A-B6-C2-4B2A5BA2-B6-C4-8B4-B6-B5-6B5-2(B6-B16-)G6-B16-4(G23-)3(B23-)K23-K108-6F17-8F14-7F2A3F12-2F10A11-2DF11A9-4D10A2D8-3D10A3D8-2C12A2D2(8-3C11A2C)8-3C10A3C8-2C11A3C8-C-3B9A-C8-B-3B2A2B4AB-B8-C3-BA6B3-B8-C4-6B4(4-B8-B9-B)2(13-B9-B)13-G9-J13-G3(23-B)172-6F17-6F2A15-F9A13-2DF9A11-4D7A3D10-3D7A4D10-3C8AC2D10-4C6A3CA2(10-4C6A4C)10-4C7A3C10-C2-C8A-B10-C2-BA4B2A2-B10-C3-5BA3-B10-C3(4-B7-B10-B)4-B3(7-G15-G)23-G2(23-B)2(23-K)23-O167-3FA18-F7A15-4D6A14-5D2A3D13-5D2A5D12-4C4A4C12-5C2A3CLC12-5C2A3C2L12-4C3A3CLC12-4C4ACH2L12-4C4AB2HL12-2C2-A3B2-2B2(12-2C8-LB)12-2C8-2B12-4(2B8-B13-)B9-B13-I9-B13-B314-3D3A17-2(8D16-)3C2DCLC16-6C2L2(16-5C2HM)16-5CJ2(2H16-2C4-)JI16-2C4-JL16-2C4-2L2(17-C4-2B)17-B4-G18-B4-G23-G427-4D20-2CDL20-2C2L20-CMLM20-C2LH20-2CIJ20-2C2H20-CB2(HJ20-2B)2H20-4B20-2B-B20-2B-3(G20-B2-)3(G23-)B82-
