model
size = 22 30 20, scale = 0.05, origin = -y
material 
  colors = A:#13132A B:#03C C:#2A55FF D:#03F
voxels
-------B------B------- -------B------B------- -------B------C------- -------B------B------- -------C------B------- -------C------B------- -------C------B------- -------C------B------- -------C------C------- -------B------C------- -------B------B------- -------B------B------- -------B------C------- -------C------C------- -------C------C------- -------B------C------- -------B------C------- -------B------B------- -------B------B------- -------B------C------- -------C------B------- -------C------C------- ---------------------- ---------------------- ---------------------- ---------------------- ---------------------- ---------------------- ---------------------- ---------------------- 
--------A----A-------- --------A----A-------- --------A----A-------- --------A----A-------- --------A----A-------- --------A----A-------- --------A----A-------- --------A----A-------- --------A----A-------- --------A----A-------- --------A----A-------- --------A----A-------- --------A----A-------- --------A----A-------- --------A----A-------- --------A----A-------- --------A----A-------- --------A----A-------- --------A----A-------- --------A----A-------- --------A----A-------- --------A----A-------- --------C----C-------- ---------------------- ---------------------- ---------------------- ---------------------- ---------------------- ---------------------- ---------------------- 
-----AAA------AAA----- -----AAA------AAA----- -----AAA------AAA----- -----AAA------AAA----- -----AAA------AAA----- -----AAA------AAA----- -----AAA------AAA----- -----AAA------AAA----- -----AAA------AAA----- -----AAA------AAA----- -----AAA------AAA----- -----AAA------AAA----- -----AAA------AAA----- -----AAA------AAA----- -----AAA------AAA----- -----AAA------AAA----- -----AAA------AAA----- -----AAA------AAA----- -----AAA------AAA----- -----AAA------AAA----- -----AAAA----AAAA----- -----AAAA----AAAA----- ------AAA----AAA------ --------D----C-------- ---------------------- ---------------------- ---------------------- ---------------------- ---------------------- ---------------------- 
---AA------------AA--- ---AA------------AA--- ---AA------------AA--- ---AA------------AA--- ---AA------------AA--- ---AA------------AA--- ---AA------------AA--- ---AA------------AA--- ---AA------------AA--- ---AA------------AA--- ---AA------------AA--- ---AA------------AA--- ---AA------------AA--- ---AA------------AA--- ---AA------------AA--- ---AA------------AA--- ---AA------------AA--- ---AA------------AA--- ---AA------------AA--- ---AA------------AA--- ---AA------------AA--- ---AA------------AA--- ---AAA----------AAA--- ----AAAAA----AAAAA---- --------D----D-------- ---------------------- ---------------------- ---------------------- ---------------------- ---------------------- 
--A----------------A-- --A----------------A-- --A----------------A-- --A----------------A-- --A----------------A-- --A----------------A-- --A----------------A-- --A----------------A-- --A----------------A-- --A----------------A-- --A----------------A-- --A----------------A-- --A----------------A-- --A----------------A-- --A----------------A-- --A----------------A-- --A----------------A-- --A----------------A-- --A----------------A-- --A----------------A-- --A----------------A-- --A----------------A-- --A----------------A-- --AA--------------AA-- ---AAAAA------AAAAA--- -------D------D------- ---------------------- ---------------------- -----D----------D----- ---------------------- 
-A------------------A- -A------------------A- -A------------------A- -A------------------A- -A------------------A- -A------------------A- -A------------------A- -A------------------A- -A------------------A- -A------------------A- -A------------------A- -A------------------A- -A------------------A- -A------------------A- -A------------------A- -A------------------A- -A------------------A- -A------------------A- -B------------------B- -B------------------B- -B------------------B- -B------------------B- -B------------------B- -B------------------B- --AA--------------AA-- ----AAAC------DAAA---- -------C------D------- ------C--------C------ -----C----------C----- ---------------------- 
-A------------------A- -A------------------A- -A------------------A- -A------------------A- -A------------------A- -A------------------A- -A------------------A- -A------------------A- -A------------------A- -A------------------A- -A------------------A- -A------------------A- -A------------------A- -A------------------A- -A------------------A- -A------------------A- -A------------------A- -B------------------D- -B-------------------- ---------------------- ---------------------- ---------------------- ---------------------- ---------------------- -BAA--------------AAB- ---A--------------A--- ----AAAA------AAAA---- ------A--------A------ -----D----------C----- ---------------------- 
A--------------------A A--------------------A A--------------------A A--------------------A A--------------------A A--------------------A A--------------------A A--------------------A A--------------------A A--------------------A A--------------------A A--------------------A A--------------------A A--------------------A A--------------------A A--------------------A B--------------------B ---------------------- ---------------------- ---------------------- ---------------------- ---------------------- ---------------------- ---------------------- ---------------------- --BA--------------AB-- ---AA------------AA--- -----A-A------A-A----- ------A--------A------ -----C----------D----- 
A--------------------A A--------------------A A--------------------A A--------------------A A--------------------A A--------------------A A--------------------A A--------------------A A--------------------A A--------------------A A--------------------A A--------------------A A--------------------A A--------------------A A--------------------A A--------------------A B--------------------B ---------------------- ---------------------- ---------------------- ---------------------- ---------------------- ---------------------- ---------------------- ---------------------- --B----------------B-- ---A--------------A--- ----AA----------AA---- ------A--------A------ -----C----------D----- 
A--------------------A A--------------------A A--------------------A A--------------------A A--------------------A A--------------------A A--------------------A A--------------------A A--------------------A A--------------------A A--------------------A A--------------------A A--------------------A A--------------------A A--------------------A A--------------------A B--------------------B ---------------------- ---------------------- ---------------------- ---------------------- ---------------------- ---------------------- ---------------------- ---------------------- --B----------------B-- ---A--------------A--- ----A------------A---- -----A----------A----- ----C------------D---- 
A--------------------A A--------------------A A--------------------A A--------------------A A--------------------A A--------------------A A--------------------A A--------------------A A--------------------A A--------------------A A--------------------A A--------------------A A--------------------A A--------------------A A--------------------A A--------------------A B--------------------B ---------------------- ---------------------- ---------------------- ---------------------- ---------------------- ---------------------- ---------------------- ---------------------- --B----------------B-- ---A--------------A--- ----A------------A---- -----A----------A----- ----D------------C---- 
A--------------------A A--------------------A A--------------------A A--------------------A A--------------------A A--------------------A A--------------------A A--------------------A A--------------------A A--------------------A A--------------------A A--------------------A A--------------------A A--------------------A A--------------------A A--------------------A B--------------------B ---------------------- ---------------------- ---------------------- ---------------------- ---------------------- ---------------------- ---------------------- ---------------------- --B----------------B-- ---A--------------A--- ----A------------A---- -----A----------A----- ----D------------C---- 
A--------------------A A--------------------A A--------------------A A--------------------A A--------------------A A--------------------A A--------------------A A--------------------A A--------------------A A--------------------A A--------------------A A--------------------A A--------------------A A--------------------A A--------------------A A--------------------A B--------------------B ---------------------- ---------------------- ---------------------- ---------------------- ---------------------- ---------------------- ---------------------- ---------------------- --B----------------B-- ---A--------------A--- ----A------------A---- -----A----------A----- ----D------------C---- 
A--------------------A A--------------------A A--------------------A A--------------------A A--------------------A A--------------------A A--------------------A A--------------------A A--------------------A A--------------------A A--------------------A A--------------------A A--------------------A A--------------------A A--------------------A A--------------------A B--------------------B ---------------------- ---------------------- ---------------------- ---------------------- ---------------------- ---------------------- ---------------------- ---------------------- --B----------------B-- ---A--------------A--- ----A------------A---- -----A----------A----- ----C------------D---- 
-A------------------A- -A------------------A- -A------------------A- -A------------------A- -A------------------A- -A------------------A- -A------------------A- -A------------------A- -A------------------A- -A------------------A- -A------------------A- -A------------------A- -A------------------A- -A------------------A- -A------------------A- -A------------------A- -A------------------A- -B------------------B- ---------------------- ---------------------- ---------------------- ---------------------- ---------------------- ---------------------- -B------------------B- --A----------------A-- ---A--------------A--- ----A------------A---- -----AA--------AA----- ----C------------D---- 
-A------------------A- -A------------------A- -A------------------A- -A------------------A- -A------------------A- -A------------------A- -A------------------A- -A------------------A- -A------------------A- -A------------------A- -A------------------A- -A------------------A- -A------------------A- -A------------------A- -A------------------A- -A------------------A- -A------------------A- -A------------------A- -B------------------B- -B------------------B- -B------------------B- -B------------------B- -B------------------B- -B------------------B- --A----------------A-- --A----------------A-- ---A--------------A--- ----AA----------AA---- ------AA------AA------ -----D----------C----- 
--A----------------A-- --A----------------A-- --A----------------A-- --A----------------A-- --A----------------A-- --A----------------A-- --A----------------A-- --A----------------A-- --A----------------A-- --A----------------A-- --A----------------A-- --A----------------A-- --A----------------A-- --A----------------A-- --A----------------A-- --A----------------A-- --A----------------A-- --A----------------A-- --A----------------A-- --A----------------A-- --A----------------A-- --A----------------A-- --A----------------A-- --A----------------A-- --A----------------A-- ---A--------------A--- ----AA----------AA---- -----AAAAAAAAAAAA----- -------AAAAAAAA------- ------D--------C------ 
---AA------------AA--- ---AA------------AA--- ---AA------------AA--- ---AA------------AA--- ---AA------------AA--- ---AA------------AA--- ---AA------------AA--- ---AA------------AA--- ---AA------------AA--- ---AA------------AA--- ---AA------------AA--- ---AA------------AA--- ---AA------------AA--- ---AA------------AA--- ---AA------------AA--- ---AA------------AA--- ---AA------------AA--- ---AA------------AA--- ---AA------------AA--- ---AA------------AA--- ---AA------------AA--- ---AA------------AA--- ---AA------------AA--- ---AA------------AA--- ---AA------------AA--- ----AA----------AA---- -----AAAAAAAAAAAA----- ------AAAAAAAAAA------ ---------------------- -------DCCCCDDD------- 
----AAAAAAAAAAAAAA---- ----AAAAAAAAAAAAAA---- ----AAAAAAAAAAAAAA---- ----AAAAAAAAAAAAAA---- ----AAAAAAAAAAAAAA---- ----AAAAAAAAAAAAAA---- ----AAAAAAAAAAAAAA---- ----AAAAAAAAAAAAAA---- ----AAAAAAAAAAAAAA---- ----AAAAAAAAAAAAAA---- ----AAAAAAAAAAAAAA---- ----AAAAAAAAAAAAAA---- ----AAAAAAAAAAAAAA---- ----AAAAAAAAAAAAAA---- ----AAAAAAAAAAAAAA---- ----AAAAAAAAAAAAAA---- ----AAAAAAAAAAAAAA---- ----AAAAAAAAAAAAAA---- ----AAAAAAAAAAAAAA---- ----AAAAAAAAAAAAAA---- ----AAAAAAAAAAAAAA---- ----AAAAAAAAAAAAAA---- ----AAAAAAAAAAAAAA---- ----AAAAAAAAAAAAAA---- -----AAAAAAAAAAAA----- ------AAAAAAAAAA------ -------AAAAAAAA------- ---------------------- ---------------------- ---------------------- 
------AAAAAAAAAA------ ------AAAAAAAAAA------ ------AAAAAAAAAA------ ------AAAAAAAAAA------ ------AAAAAAAAAA------ ------AAAAAAAAAA------ ------AAAAAAAAAA------ ------AAAAAAAAAA------ ------AAAAAAAAAA------ ------AAAAAAAAAA------ ------AAAAAAAAAA------ ------AAAAAAAAAA------ ------AAAAAAAAAA------ ------AAAAAAAAAA------ ------AAAAAAAAAA------ ------AAAAAAAAAA------ ------AAAAAAAAAA------ ------AAAAAAAAAA------ ------AAAAAAAAAA------ ------AAAAAAAAAA------ ------AAAAAAAAAA------ ------AAAAAAAAAA------ ------AAAAAAAAAA------ ------AAAAAAAAAA------ ------AAAAAAAAAA------ -------AAAAAAAA------- ---------------------- ---------------------- ---------------------- ---------------------- 
