model
size = 19 24 19, scale = 0.05, origin = -y
material 
  colors = A:#9CF B:#3FF C:#2BDCDC D:#29D4D4 E:#2FEDED F:#27CCCC G:#24BEBE H:#EA8B2D I:#F3F J:#FFF K:#F93
voxels
------------------- ------------------- ------------------- ------------------- ------------------- ------------------- ------------------- ------------------- ------------------- ------------------- -------DIIID------- -------DDDDD------- -------CKCKC------- -------CCKCC------- -------CKCKC------- -------CCCCC------- -------EEJEE------- ------------------- ------------------- ------------------- ------------------- ------------------- ------------------- ------------------- 
------------------- ------------------- ------------------- ------------------- ------------------- ------------------- ------------------- ------------------- -------DIIID------- -------DDDID------- -----IDAAAAAII----- -----DDAAAAADD----- -----CCAAAAACC----- -----CCAAAAACC----- -----CCAAAAACC----- -----CCAAAAACC----- -----JJAAAAAJJ----- -------EEJEE------- -------EEJEE------- ------------------- ------------------- ------------------- ------------------- ------------------- 
------------------- ------------------- ------------------- ------------------- ------------------- ------------------- -------FIIIF------- -------FIFFF------- -----IDAAAAAID----- -----DIAAAAAID----- ---DIAAAAAAAAAID--- ---DDAAAAAAAAADD--- ---CCAAAAAAAAACC--- ---CCAAAAAAAAACC--- ---CCAAAAAAAAACC--- ---CCAAAAAAAAACC--- ---EJAAAAAAAAAJE--- -----EJAAAAAJE----- -----EJAAAAAJJ----- -------EJJJE------- -------BJBJB------- ------------------- ------------------- ------------------- 
------------------- ------------------- ------------------- ------------------- ------------------- -------FFFFF------- -----IIAAAAAII----- -----FIAAAAAIF----- ---DIAAAAAAAAAID--- ---DIAAAAAAAAAID--- --DAAAAAAAAAAAAAD-- --DAAAAAAAAAAAAAD-- --CAAAAAAAAAAAAAC-- --CAAAAAAAAAAAAAC-- --CAAAAAAAAAAAAAC-- --CAAAAAAAAAAAAAC-- --EAAAAAAAAAAAAAE-- ---EJAAAAAAAAAJE--- ---EJAAAAAAAAAEE--- -----EEAAAAAJE----- -----JJAAAAAJJ----- -------BBBBB------- ------------------- ------------------- 
------------------- ------------------- ------------------- ------------------- -------FFFFF------- -----FFAAAAAFF----- ----IAAAAAAAAAI---- ----IAAAAAAAAAI---- ---DAAAAAAAAAAAD--- ---DAAAAAAAAAAAD--- --DAAAAAAAAAAAAAD-- --DAAAAAAAAAAAAAD-- --CAAAAAAAAAAAAAC-- --CAAAAAAAAAAAAAC-- --CAAAAAAAAAAAAAC-- --CAAAAAAAAAAAAAC-- --EAAAAAAAAAAAAAE-- ---EAAAAAAAAAAAE--- ---EAAAAAAAAAAAE--- ----JAAAAAAAAAJ---- ----JAAAAAAAAAJ---- -----BBBBBBBBB----- ------------------- ------------------- 
------------------- ------------------- ------------------- -------GGGGG------- ------FAAAAAF------ ----FFAAAAAAAFF---- ---FAAAAAAAAAAAF--- ---FAAAAAAAAAAAF--- --DAAAAAAAAAAAAAD-- --DAAAAAAAAAAAAAD-- -DAAAAAAAAAAAAAAAD- -DAAAAAAAAAAAAAAAD- -CAAAAAAAAAAAAAAAC- -CAAAAAAAAAAAAAAAC- -CAAAAAAAAAAAAAAAC- -CAAAAAAAAAAAAAAAC- -EAAAAAAAAAAAAAAAE- --EAAAAAAAAAAAAAE-- --EAAAAAAAAAAAAAE-- ---EAAAAAAAAAAAE--- ---BAAAAAAAAAAAB--- ----BBBBBBBBBBB---- -------BBBBB------- ------------------- 
------------------- ------------------- --------GGG-------- ------GGAAAGG------ -----FAAAAAAAF----- ----FAAAAAAAAAF---- ---FAAAAAAAAAAAF--- ---FAAAAAAAAAAAF--- --DAAAAAAAAAAAAAD-- --DAAAAAAAAAAAAAD-- -DAAAAAAAAAAAAAAAD- -DAAAAAAAAAAAAAAAD- -CAAAAAAAAAAAAAAAC- -CAAAAAAAAAAAAAAAC- -CAAAAAAAAAAAAAAAC- -CAAAAAAAAAAAAAAAC- -EAAAAAAAAAAAAAAAE- --EAAAAAAAAAAAAAE-- --EAAAAAAAAAAAAAE-- ---EAAAAAAAAAAAE--- ---BAAAAAAAAAAAB--- ----BBBBBBBBBBB---- ------BBBBBBB------ ------------------- 
------------------- --------GGG-------- -------GAAAG------- -----GGAAAAAGG----- ----FAAAAAAAAAF---- ---FAAAAAAAAAAAF--- --FAAAAAAAAAAAAAF-- --FAAAAAAAAAAAAAF-- -DAAAAAAAAAAAAAAAD- -DAAAAAAAAAAAAAAAD- DAAAAAAAAAAAAAAAAAD DAAAAAAAAAAAAAAAAAD CAAAAAAAAAAAAAAAAAC CAAAAAAAAAAAAAAAAAC CAAAAAAAAAAAAAAAAAC CAAAAAAAAAAAAAAAAAC EAAAAAAAAAAAAAAAAAE -EAAAAAAAAAAAAAAAE- -EAAAAAAAAAAAAAAAE- --EAAAAAAAAAAAAAE-- --BAAAAAAAAAAAAAB-- ---BBBBBBBBBBBBB--- -----BBBBBBBBB----- --------BBB-------- 
---------G--------- -------GGAGG------- ------GAAAAAG------ -----GAAAAAAAG----- ----FAAAAAAAAAF---- ---FAAAAAAAAAAAF--- --FAAAAAAAAAAAAAF-- --FAAAAAAAAAAAAAF-- -DAAAAAAAAAAAAAAAD- -DAAAAAAAAAAAAAAAD- DAAAAAAAAAAAAAAAAAD DAAAAAAAAAAAAAAAAAD CAAAAAAAAAAAAAAAAAC CAAAAAAAAAAAAAAAAAC CAAAAAAAAAAAAAAAAAC CAAAAAAAAAAAAAAAAAC EAAAAAAAAAAAAAAAAAE -EEAAAAAAAAAAAAAAE- -EEAAAAAAAAAAAAAAE- --EAAAAAAAAAAAAAE-- --BAAAAAAAAAAAAAB-- ---BBBBBBBBBBBBB--- -----BBBBBBBBB----- -------BBBBB------- 
--------GGG-------- -------GAAAG------- ------GAAAAAG------ -----GAAAAAA-G----- ----FAAAAAAA-AF---- ---FAAAAAAAA-AAF--- --FAAAAAAAAA-AAAF-- --FAAAAAAAAA-AAAF-- -DAAAAAAAAAA-AAAAD- -DAAAAAAAAAA-AAAAD- DAAAAAAAAAAA-AAAAAD DAAAAAAAAAAA-AAAAAD CAAAAAAAAAAA-AAAAAC CAAAAAAAAAAA-AAAAAC CAAAAAAAAAAA-AAAAAC CHHHAAAAAAAA-AAHHHC EHHHHAAAAAAA-AHHHHE -EEHHAAAAAAA-AHHHE- -EEHHHAAAAAA-HHHHE- --EHHHAAAAAA-HHHE-- --BHHHAAAAAA-HHHB-- ---BBHBBBBBB-HBB--- -----BBBBBBBBB----- -------BBBBB------- 
---------G--------- -------GGAGG------- ------GAAAAAG------ -----GAAAAAAAG----- ----FAAAAAAAAAF---- ---FAAAAAAAAAAAF--- --FAAAAAAAAAAAAAF-- --FAAAAAAAAAAAAAF-- -DAAAAAAAAAAAAAAAD- -DAAAAAAAAAAAAAAAD- DAAAAAAAAAAAAAAAAAD DAAAAAAAAAAAAAAAAAD CAAAAAAAAAAAAAAAAAC CAAAAAAAAAAAAAAAAAC CAAAAAAAAAAAAAAAAAC CAAAAAAAAAAAAAAAAAC EAAAAAAAAAAAAAAAAAE -EAAAAAAAAAAAAAAAE- -EAAAAAAAAAAAAAAAE- --EAAAAAAAAAAAAAE-- --BAAAAAAAAAAAAAB-- ---BBBBBBBBBBBBB--- -----BBBBBBBBB----- -------BBBBB------- 
------------------- --------GGG-------- -------GAAAG------- -----GGAAAAAGG----- ----FAAAAAAAAAF---- ---FAAAAAAAAAAAF--- --FAAAAAAAAAAAAAF-- --FAAAAAAAAAAAAAF-- -DAAAAAAAAAAAAAAAD- -DAAAAAAAAAAAAAAAD- DAAAAAAAAAAAAAAAAAD DAAAAAAAAAAAAAAAAAD CAAAAAAAAAAAAAAAAAC CAAAAAAAAAAAAAAAAAC CAAAAAAAAAAAAAAAAAC CAAAAAAAAAAAAAAAAAC EAAAAAAAAAAAAAAAAAE -EAAAAAAAAAAAAAAAE- -EAAAAAAAAAAAAAAAE- --EAAAAAAAAAAAAAE-- --BAAAAAAAAAAAAAB-- ---BBBBBBBBBBBBB--- -----BBBBBBBBB----- --------BBB-------- 
------------------- ------------------- --------GGG-------- ------GGAAAGG------ -----FAAAAAAAF----- ----FAAAAAAAAAF---- ---FAAAAAAAAAAAF--- ---FAAAAAAAAAAAF--- --DAAAAAAAAAAAAAD-- --DAAAAAAAAAAAAAD-- -DAAAAAAAAAAAAAAAD- -DAAAAAAAAAAAAAAAD- -CAAAAAAAAAAAAAAAC- -CAAAAAAAAAAAAAAAC- -CAAAAAAAAAAAAAAAC- -CAAAAAAAAAAAAAAAC- -EAAAAAAAAAAAAAAAE- --EAAAAAAAAAAAAAE-- --EAAAAAAAAAAAAAE-- ---EAAAAAAAAAAAE--- ---BAAAAAAAAAAAB--- ----BBBBBBBBBBB---- ------BBBBBBB------ ------------------- 
------------------- ------------------- ------------------- -------GGGGG------- ------FAAAAAF------ ----FFAAAAAAAFF---- ---FAAAAAAAAAAAF--- ---FAAAAAAAAAAAF--- --DAAAAAAAAAAAAAD-- --DAAAAAAAAAAAAAD-- -DAAAAAAAAAAAAAAAD- -DAAAAAAAAAAAAAAAD- -CAAAAAAAAAAAAAAAC- -CAAAAAAAAAAAAAAAC- -CAAAAAAAAAAAAAAAC- -CAAAAAAAAAAAAAAAC- -EAAAAAAAAAAAAAAAE- --EAAAAAAAAAAAAAE-- --EAAAAAAAAAAAAAE-- ---EAAAAAAAAAAAE--- ---BAAAAAAAAAAAB--- ----BBBBBBBBBBB---- -------BBBBB------- ------------------- 
------------------- ------------------- ------------------- ------------------- -------FFFFF------- -----FFAAAAAFF----- ----FAAAAAAAAAF---- ----FAAAAAAAAAF---- ---DAAAAAAAAAAAD--- ---DAAAAAAAAAAAD--- --DAAAAAAAAAAAAAD-- --DAAAAAAAAAAAAAD-- --CAAAAAAAAAAAAAC-- --CAAAAAAAAAAAAAC-- --CAAAAAAAAAAAAAC-- --CAAAAAAAAAAAAAC-- --EAAAAAAAAAAAAAE-- ---EAAAAAAAAAAAE--- ---EAAAAAAAAAAAE--- ----EAAAAAAAAAE---- ----BAAAAAAAAAB---- -----BBBBBBBBB----- ------------------- ------------------- 
------------------- ------------------- ------------------- ------------------- ------------------- -------FFFFF------- -----FFAAAAAFF----- -----FFAAAAAFF----- ---DDAAAAAAAAADD--- ---DDAAAAAAAAADD--- --DAAAAAAAAAAAAAD-- --DAAAAAAAAAAAAAD-- --CAAAAAAAAAAAAAC-- --CAAAAAAAAAAAAAC-- --CAAAAAAAAAAAAAC-- --CAAAAAAAAAAAAAC-- --EAAAAAAAAAAAAAE-- ---EEAAAAAAAAAEE--- ---EEAAAAAAAAAEE--- -----EEAAAAAEE----- -----BBAAAAABB----- -------BBBBB------- ------------------- ------------------- 
------------------- ------------------- ------------------- ------------------- ------------------- ------------------- -------FFFFF------- -------FFFFF------- -----DDAAAAADD----- -----DDAAAAADD----- ---DDAAAAAAAAADD--- ---DDAAAAAAAAADD--- ---CCAAAAAAAAACC--- ---CCAAAAAAAAACC--- ---CCAAAAAAAAACC--- ---CCAAAAAAAAACC--- ---EEAAAAAAAAAEE--- -----EEAAAAAEE----- -----EEAAAAAEE----- -------EEEEE------- -------BBBBB------- ------------------- ------------------- ------------------- 
------------------- ------------------- ------------------- ------------------- ------------------- ------------------- ------------------- ------------------- -------DDDDD------- -------DDDDD------- -----DDAAAAADD----- -----DDAAAAADD----- -----CCAAAAACC----- -----CCAAAAACC----- -----CCAAAAACC----- -----CCAAAAACC----- -----EEAAAAAEE----- -------EEEEE------- -------EEEEE------- ------------------- ------------------- ------------------- ------------------- ------------------- 
------------------- ------------------- ------------------- ------------------- ------------------- ------------------- ------------------- ------------------- ------------------- ------------------- -------DDDDD------- -------DDDDD------- -------CCCCC------- -------CCCCC------- -------CCCCC------- -------CCCCC------- -------EEEEE------- ------------------- ------------------- ------------------- ------------------- ------------------- ------------------- ------------------- 
