model
size = 29 18 15, scale = 0.05, origin = -y
material 
  colors = A:#3FF B:#F93 C:#26C1C1 D:#2BD9D9 E:#23B0B0 F:#2FEFEF G:#177A7A H:#1F9D9D I:#E78A2E J:#CF7C29 K:#FCC L:#141414
voxels
----------GGGGGGGGGGGGG------ ----------HHHHHHHHHHHH------- ----------EEEEEEEEEE--------- -----------EEEEEE------------ ------------CCC-------------- ----------------------------- ----------------------------- ----------------------------- ----------------------------- ----------------------------- ----------------------------- ----------------------------- ----------------------------- ----------------------------- ----------------------------- ----------------------------- ----------------------------- ----------------------------- 
---------GA-A-A-A-A-A-AG----- ---------HAAAAAAAAAAAAHH----- ---------EAAAAAAAAAAEEE------ ---------EEAAAAAAEEEE-------- ------CCC-CCAAACC------------ -----CCCCC-CCCCC------------- -----CCCCC------------------- -----DDDDD------------------- ------DDD-------------------- ----------------------------- ----------------------------- ----------------------------- ----------------------------- ----------------------------- ----------------------------- ----------------------------- ----------------------------- ----------------------------- 
--------GA-A-A-A-A-A-A-AGG--- --------HAAAAAABABABABAAHH--- ------EEEAAAAABBBBBBBBBBB---- -----EEEEAAAAABBBBBBBBBBBB--- ----CCAAACAAABBBBJJIIBBBBB--- ---CCAAAAACAABBBJJIIBBBBBB--- ---CCAAAAACCCJJJJIIBBB-BB---- ---DDAAAAADD-JJJIIBBBBB------ ----DDAAADD--JIIIBBBBBBB----- -----DDDDD---JIIBBBBBBBB----- ------FFFF----IBBBBBBBBBB---- --------FFF---BBBBBBBBBBB---- --------AAA---BBBBBBB-BB----- ---------AA----BBBBBBB------- ----------A----BBBBBBBB------ ----------A-----BBBBBBB------ ----------------BBBBBB------- -----------------BBBB-------- 
-------GA-A-A-A-A-A-A-A-A-G-- ------HHAAAAAAAAAAAAAAAAAAH-- ---EEEAAAAAAAAAAAAAAAAAAAEE-- --EEEAAAAAAAAAAAAAAAAAEEEEE-- --CCAAAAAAAAAAAAAAAAAACCCCC-- --CAAAAAAAAAAAAAAAAAAACCCCC-- --CAAAAAAAAAAAAAA---AACCCCC-- --DAAAAAAAAADAAA-----ADDDDD-- --DDAAAAAAAD----------DDDDD-- ---DDAAAAADD----------DDDDD-- ----FFAAAAFF----------AAAFF-- ------FFAAAF----------AAAFF-- -------AAAAA--------------A-- --------AAAA----------------- ---------AAA----------------- ---------AAA----------------- ----------AA----------------- ----------------------------- 
------GA-A-A-A-A-A-A-A-A-A-G- ---HHHAAAAAAAAAAAAAAAAAAAAAH- --EAAAAAAAAAAAAAAAAAAAAAAAAE- --EAAAAAAAAAAAAAAAAAAA-----E- --CAAAAAAAAAAAAAAAAAAA-----C- --CAAAAAAAAAAAAAAAAAAA-----C- --CAAAAAAAAAAAAAAAAAAA-----C- --DAAAAAAAAAAAAAA--AAA-----D- --DAAAAAAAAADAA-----AA-----D- --DAAAAAAAAA---------A-----D- ---FAAAAAAAA---------A-----F- -----FAAAAA----------A-----F- --------AAA-----------A----A- ---------AA----------------A- ----------A------------------ ----------A------------------ ----------------------------- ----------------------------- 
---GGGA-A-A-A-A-A-A-A-A-A-A-G --HAAAAAAAAAAAAAAAAAAAAAAAAAH ---KAAAAAAAAAAAAAAAAAAAAAAAAE --EAAAAA--------------------E CCAAAAAA--------------------C CCAAAAAAAAAAAAA-------------C --CAAAAAAAAAAAAAAAA---------C --LAAAAAAAAAAAAAAAAA--------D --LAAAAAAAAAAAAA--AAA-------D --DAAAAAAAAAAA-----AA-------D ---FAAAAAAAA-------AA-------F ----FAAAAAA---------A-------F ------AAA------------A------A ----------------------------A ----------------------------- ----------------------------- ----------------------------- ----------------------------- 
--GAAA-A-A-A-A-A-A-A-A-A-A-AG ---KAAAAAAAAAAAAAAAAAAAAAAAAH --EAAAAAAAAAAAAAAAAAAAAAAAAAE EEAAAAA---------------------E --KAAAA---------------------C --KAAAAAAAAAAAA-------------C CCAAAAAAAAAAAAAAA-----------C --DAAAAAAAAAAAAAAAA---------D --DAAAAAAAAAAAAAAAAA--------D --DAAAAAAAAAAAA--AAAA-------D --FAAAAAAAAAF-----AAA-------F ---FAAAAAAAA-------AA-------F -----AAAAA----------A-------A ---------------------A------A ----------------------------A ----------------------------- ----------------------------- ----------------------------- 
--GAAAA-A-A-A-A-A-A-A-A-A-A-G ---KAAAAAAAAAAAAAAAAAAAAAAAAH --EAAAAAAAAAAAAAAAAAAAAAAAAAE EAAAAAA---------------------E CAAAAAA---------------------C CAAAAAAAAAAAAAA-------------C CAAAAAAAAAAAAAAAA-----------C --DAAAAAAAAAAAAAAAA---------D --DAAAAAAAAAAAAAAAAA--------D --DAAAAAAAAAAAA--AAAA-------D --FAAAAAAAAAA-----AAA-------F ---FAAAAAAAA-------AA-------F -----AAAAA----------A-------A ---------------------A------A ----------------------------A ----------------------------- ----------------------------- ----------------------------- 
--GAAA-A-A-A-A-A-A-A-A-A-A-AG ---KAAAAAAAAAAAAAAAAAAAAAAAAH --EAAAAAAAAAAAAAAAAAAAAAAAAAE EEAAAAA---------------------E --KAAAA---------------------C --KAAAAAAAAAAAA-------------C CCAAAAAAAAAAAAAAA-----------C --DAAAAAAAAAAAAAAAA---------D --DAAAAAAAAAAAAAAAAA--------D --DAAAAAAAAAAAA--AAAA-------D --FAAAAAAAAAF-----AAA-------F ---FAAAAAAAA-------AA-------F -----AAAAA----------A-------A ---------------------A------A ----------------------------A ----------------------------- ----------------------------- ----------------------------- 
---GGGA-A-A-A-A-A-A-A-A-A-A-G --HAAAAAAAAAAAAAAAAAAAAAAAAAH ---KAAAAAAAAAAAAAAAAAAAAAAAAE --EAAAA---------------------E CCAAAAA---------------------C CCAAAAAAAAAAAAA-------------C --CAAAAAAAAAAAAAAAA---------C --LAAAAAAAAAAAAAAAAA--------D --LAAAAAAAAAAAAA--AAA-------D --DAAAAAAAAADA-----AA-------D ---FAAAAAAAA-------AA-------F ----FAAAAAA---------A-------F ------AAA------------A------A ----------------------------A ----------------------------- ----------------------------- ----------------------------- ----------------------------- 
------GA-A-A-A-A-A-A-A-A-A-G- ---HHHAAAAAAAAAAAAAAAAAAAAAH- --EAAAAAAAAAAAAAAAAAAAAAAAAE- --EAAAAAAAAAAAAAAAAAAA-----E- --CAAAAAAAAAAAAAAAAAAA-----C- --CAAAAAAAAAAAAAAAAAAA-----C- --CAAAAAAAAAAAAAAAAAAA-----C- --DAAAAAAAAAAAAAA--AAA-----D- --DAAAAAAAAADAA-----AA-----D- --DAAAAAAAAA---------A-----D- ---FAAAAAAAA---------A-----F- -----FAAAAA----------A-----F- --------AAA-----------A----A- ---------AA----------------A- ----------A------------------ ----------A------------------ ----------------------------- ----------------------------- 
-------GA-A-A-A-A-A-A-A-A-G-- ------HHAAAAAAAAAAAAAAAAAAH-- ---EEEAAAAAAAAAAAAAAAAAAAEE-- --EEEAAAAAAAAAAAAAAAAAEEEEE-- --CCAAAAAAAAAAAAAAAAAACCCCC-- --CAAAAAAAAAAAAAAAAAAACCCCC-- --CAAAAAAAAAAAAAA---AACCCCC-- --DAAAAAAAAADAAA-----AADDDD-- --DDAAAAAAAD----------AADDD-- ---DDAAAAADD----------AADDD-- ----FFAAAAFF----------AAAFF-- ------FFAAAF----------AAAFF-- -------AAAAA--------------A-- --------AAAA----------------- ---------AAA----------------- ---------AAA----------------- ----------AA----------------- ----------------------------- 
--------GA-A-A-A-A-A-A-AGG--- --------HAAAAAABABABABAAHH--- ------EEEAAAAABBBBBBBBBBB---- -----EEEEAAAAABBBBBBBBBBBB--- ----CCAAACAAABBBBJJIIBBBBB--- ---CCAAAAACAABBBJJIIBBBBBB--- ---CCAAAAACCCJJJJIIBBB-BB---- ---DDAAAAADD-JJJIIBBBBB------ ----DDAAADD--JIIIBBBBBBB----- -----DDDDD---JIIBBBBBBBB----- ------FFFF----IBBBBBBBBBB---- --------FFF---BBBBBBBBBBB---- --------AAA---BBBBBBB-BB----- ---------AA----BBBBBBB------- ----------A----BBBBBBBB------ ----------A----BBBBBBBB------ ----------------BBBBBB------- -----------------BBBB-------- 
---------GA-A-A-A-A-A-AG----- ---------HAAAAAAAAAAAAHH----- ---------EAAAAAAAAAAEEE------ ---------EEAAAAAAEEEE-------- ------CCC-CCAAACC------------ -----CCCCC-CCCCC------------- -----CCCCC------------------- -----DDDDD------------------- ------DDD-------------------- ----------------------------- ----------------------------- ----------------------------- ----------------------------- ----------------------------- ----------------------------- ----------------------------- ----------------------------- ----------------------------- 
----------GGGGGGGGGGGGG------ ----------HHHHHHHHHHHH------- ----------EEEEEEEEEE--------- -----------EEEEEE------------ ------------CCC-------------- ----------------------------- ----------------------------- ----------------------------- ----------------------------- ----------------------------- ----------------------------- ----------------------------- ----------------------------- ----------------------------- ----------------------------- ----------------------------- ----------------------------- ----------------------------- 
