model
size = 28 32 27, scale = 0.05, origin = -y
material 
  colors = A:#111 B:#EEE
voxels
487-A5-A20-2(A5-A21-)A5-A20-2(A7-A19-)A7-2A19-A7-A19-A6-A183-7(18A10-)2A4BABA3B2AB3A3(10-2(2AB)2(3AB)AB2A)10-2ABA2B4AB2ABAB2A10-2A2B7A2(BA)B2A10-2ABAB6A2(BA)3(B2A10-2(2AB)3A3(BA))B2A10-2A3B5A2(B3A)5(10-18A)10-19A9-18A13-12A17-2A6-2A152-24(22A6-)22A8-18A12-14A15-2A8-2A16-A10-A94-24(24A4-)24A5-22A7-20A10-6A4-6A13-2A10-2A14-A12-A64-24(4A18-4A2-)4A18-4A3-3A18-3A5-2A18-2A7-3A14-3A9-6A6-6A11-A14-A12-A14-A34-5A23(18-10A)18-5A-4A18-4A2-4A18-4A3-3A18-3A5-4A14-4A7-3A14-3A9-A-3A8-3A-A10-A16-A33-4A24(20-8A)20-4A-4A18-4A2-4A18-4A3-3A18-3A5-4A14-4A7-A2-A12-A2-A8-A18-A32-4A26(20-8A)20-4A-4A18-4A3-4A16-4A5-A2-A14-A2-A7-A18-A32-4A26(20-8A)20-9A18-5A-5A16-5A3-2A2-A14-A2-2A5-A20-A6-A20-A3-4A26(20-8A)20-9A18-5A-5A16-5A2-2A3-A14-A3-2A3-A22-A4-A22-A2-4A26(20-8A)20-9A18-11A16-6A-2A3-A14-A3-2A2-2A22-2A3-A22-A2-4A26(20-8A)20-9A18-11A16-9A3-A14-A3-3A-2A22-2A3-A22-A2-4A24(20-8A)20-9A2(18-10A)18-11A16-9A3-A14-A3-3A-2A22-2A3-A22-A2-5A27(18-10A)18-11A16-9A3-A14-A3-3A-2A22-2A3-A22-A3-26(4A18-4A2-)4A18-4A-5A18-11A16-9A3-A14-A3-3A-2A22-2A3-A22-A26(4-4A16-4A)3-5A16-5A2-5A16-2(5A-)A14-A-8A4-2A10-2A4-3A-2A22-2A3-A22-A5-25(5A12-5A6-)5A12-5A5-6A12-6A3-4A-2A12-2A-2(4A2-)2A10-2A2-4A2-2A5-12A5-2A2-2A22-2A3-A22-A6-25(20A8-)2A-14A-2A7-3A-14A-3A5-3A2-14A2-3A3-4A3-12A3-4A2-2A22-2A3-A22-A4-A22-A8-22(16A12-)3A10-3A2(12-2A)12-A14-A11-A16-A9-2A16-2A6-2(3A18-3A4-)2(2A20-2A4-)A22-A547-2A24-6A20-10A16-2A10-2A13-2(2A12-)A14-A11-A16-A10-A16-A9-A18-A7-2A18-2A3(6-A20-A)602-6A20-10A17-A10-A15-A12-A13-A14-A12-A14-A11-A16-A9-2A16-2A8-A18-A7-2A18-2A6-A20-A656-10A16-2A10-2A13-A14-A12-A14-A11-A16-A10-A16-A9-2(A18-A8-)A18-A685-10A16-2A10-2A14-2A10-2A13-A14-A12-A14-A11-2(A16-A10-)A16-A714-10A18-10A16-2A10-2A14-2A10-2A13-A14-A12-A14-A11-A16-A770-10A18-10A16-2A10-2A14-2A10-2A13-A14-A827-10A18-10A16-2A10-2A884-10A9-
