model
size = 30 25 11, scale = 0.05, origin = -y
material 
  colors = A:#111 B:#52433D C:#A5DEE4 D:#227D51 E:#006284 F:#0F2540 G:#777 H:#60373E I:#91AD70 J:#FBE251 K:#B481BB L:#6699A1 M:#E03C8A N:#08192D O:#CC543A P:#3C2F41 Q:#86C166 R:#4F4F48 S:#305A56
voxels
---------AAAAAAAAAAAA--------- ---------QAKKKKKADDDA--------- ---------QAAAAAAADDDA--------- ---------QAJJJASADDDA--------- ---------QAJJJASADDDA--------- ---------AAAAAAAAAAAA--------- ---------LLLLLAHHHHHH--------- ---------AAAAAAAAAAAA--------- ---------BBBBBAPACCCA--------- ---------BBBBBAPACCCA--------- ---------BBBBBAPACCCA--------- --------ABBBBBAPACCCAA-------- --------AAAAAAAAACCCAA-------- --------GGGGGGGGAAAAAA-------- --------AAAAAAAAAEEEEA-------- -------AAMAFFFAOAAAAEAA------- -------AAMAFFFAOAIIAEAA------- -------AAMAFFFAOAIIAEAA------- -------AAMAAAAAOAIIAEAA------- --------AMARRRAAAAAAEA-------- --------AAAAAAANNNNAAA-------- ------------------------------ ------------------------------ ------------------------------ ------------------------------ 
--------AAAA------AAAA-------- --------AA----------AA-------- --------AA----------AA-------- --------AA----------AA-------- --------AA----------AA-------- --------AA----------AA-------- --------AA----------AA-------- --------AA----------AA-------- --------AA----------AA-------- --------AA----------AA-------- --------AA----------AA-------- --------AA----------AA-------- --------A------------A-------- -------AA------------AA------- -------AA------------AA------- -------AA------------AA------- ------AA--------------AA------ ------AA--------------AA------ ------AAA------------AAA------ -------AA------------AA------- -------AAAAAAAAAAAAAAAA------- --------AAAAAAAAAAAAAA-------- ------------------------------ ------------------------------ ------------------------------ 
--------A------------A-------- --------A------------A-------- --------A------------A-------- --------A------------A-------- --------A------------A-------- --------A------------A-------- --------A------------A-------- --------A------------A-------- --------A------------A-------- --------A------------A-------- --------A------------A-------- --------A------------A-------- --------A------------A-------- -------AA------------AA------- -------A--------------A------- --AAAAAA--------------AAAAAA-- --AAAAAA--------------AAAAAA-- --AAAAA----------------AAAAA-- ---AAAAA--------------AAAAA--- -----AAA--------------AAA----- ------AAA------------AAA------ -------AAAAAAAAAAAAAAAA------- --------AAAAAAAAAAAAAA-------- -------------AAAA------------- ------------------------------ 
--------A------------A-------- --------A------------A-------- --------A------------A-------- --------A------------A-------- --------A------------A-------- --------A------------A-------- --------A------------A-------- --------A------------A-------- --------A------------A-------- --------A------------A-------- --------A------------A-------- --------A------------A-------- --------A------------A-------- -------AA------------AA------- ---AA--A--------------A--AA--- ---AAAAA--------------AAAAA--- -AA------------------------AA- -AAA----------------------AAA- --AAAA------------------AAAA-- ---AAAA----------------AAAA--- ----AAAA--------------AAAA---- ------AAA------------AAA------ -------AAAAAAA--AAAAAAA------- --------AAAAAAAAAAAAAA-------- -----------AAAAAAAA----------- 
--------A------------A-------- --------A------------A-------- --------A------------A-------- --------A------------A-------- --------A------------A-------- --------A------------A-------- --------A------------A-------- --------A------------A-------- --------A------------A-------- --------A------------A-------- --------A------------A-------- --------A------------A-------- --------A------------A-------- -------AA------------AA------- ---AA--A--------------A--AA--- ----AAAA--------------AAAA---- ------------------------------ AAA------------------------AAA AAAA----------------------AAAA --AAA--------------------AAA-- ---AAAA----------------AAAA--- -----AAA--------------AAA----- ------AAA------------AAA------ -------AAAAA------AAAAA------- ---------AAAA----AAAA--------- 
--------A------------A-------- --------A------------A-------- --------A------------A-------- --------A------------A-------- --------A------------A-------- --------A------------A-------- --------A------------A-------- --------A------------A-------- --------A------------A-------- --------A------------A-------- --------A------------A-------- --------A------------A-------- --------A------------A-------- -------AA------------AA------- ---AA--A--------------A--AA--- ----AAAA--------------AAAA---- ------------------------------ ------------------------------ AAA------------------------AAA -AAA----------------------AAA- --AAAA------------------AAAA-- ----AAA----------------AAA---- -----AAA--------------AAA----- -------AAA----------AAA------- ---------AA--------AA--------- 
--------A------------A-------- --------A------------A-------- --------A------------A-------- --------A------------A-------- --------A------------A-------- --------A------------A-------- --------A------------A-------- --------A------------A-------- --------A------------A-------- --------A------------A-------- --------A------------A-------- --------A------------A-------- --------A------------A-------- -------AA------------AA------- ---AAA-A--------------A-AAA--- ----AAAA--------------AAAA---- ------------------------------ ------------------------------ AA--------------------------AA -AA------------------------AA- --AAA--------------------AAA-- ----AA------------------AA---- -----AAA--------------AAA----- -------AAA----------AAA------- ---------A----------A--------- 
--------A------------A-------- --------A------------A-------- --------A------------A-------- --------A------------A-------- --------A------------A-------- --------A------------A-------- --------A------------A-------- --------A------------A-------- --------A------------A-------- --------A------------A-------- --------A------------A-------- --------A------------A-------- --------A------------A-------- -------AA------------AA------- ---AAA-A--------------A-AAA--- ----AAAA--------------AAAA---- ------------------------------ ------------------------------ AA--------------------------AA -AAA----------------------AAA- --AAA--------------------AAA-- ----AAA----------------AAA---- -----AAA--------------AAA----- -------AAA----------AAA------- ---------AA--------AA--------- 
--------A------------A-------- --------A------------A-------- --------A------------A-------- --------A------------A-------- --------AA----------AA-------- --------AA----------AA-------- --------AA----------AA-------- --------AA----------AA-------- --------AA----------AA-------- --------AA----------AA-------- --------AA----------AA-------- --------AA----------AA-------- --------A------------A-------- -------AA------------AA------- ---AA--AA------------AA--AA--- --AAAAAA--------------AAAAAA-- --A--AAA--------------AAA--A-- AA--------------------------AA AAA------------------------AAA -AAAA--------------------AAAA- --AAAA------------------AAAA-- ----AAA----------------AAA---- -----AAAA------------AAAA----- -------AAA----------AAA------- ---------AAA------AAA--------- 
--------A------------A-------- --------AA----------AA-------- --------AA----------AA-------- --------AAAAAAAAAAAAAA-------- --------AAAAAAAAAAAAAA-------- ---------AAAAAAAAAAAA--------- ---------AAAAAAAAAAAA--------- ---------AAAAAAAAAAAA--------- ---------AAAAAAAAAAAA--------- ---------AAAAAAAAAAAA--------- ---------AAAAAAAAAAAA--------- --------AAAAAAAAAAAAAA-------- --------AAAAAAAAAAAAAA-------- --------AA----------AA-------- -------AA------------AA------- --AAAA-AA------------AA-AAAA-- --AAAAAAA------------AAAAAAA-- -AAAAAAA--------------AAAAAAA- -AAAAAAA--------------AAAAAAA- --AAAAAA--------------AAAAAA-- ----AAAA--------------AAAA---- -----AAAA------------AAAA----- ------AAA------------AAA------ --------AAAAAAAAAAAAAA-------- ---------AAAAAAAAAAAA--------- 
--------AAAAAAAAAAAAAA-------- --------AAAAAAAAAAAAAA-------- --------AAAAAAAAAAAAAA-------- --------AAAAAAAAAAAAAA-------- ------------------------------ ------------------------------ ------------------------------ ------------------------------ ------------------------------ ------------------------------ ------------------------------ ------------------------------ ---------AAAAAAAAAAAA--------- --------AAAAAAAAAAAAAA-------- --------AAAAAAAAAAAAAA-------- --------AAAAAAAAAAAAAA-------- -------AAAAAAAAAAAAAAAA------- -------AAAAAAAAAAAAAAAA------- -------AAAAAAAAAAAAAAAA------- -------AAAAAAAAAAAAAAAA------- -------AAAAAAAAAAAAAAAA------- -------AAAAAAAAAAAAAAAA------- --------AAAAAAAAAAAAAA-------- --------AAAAAAAAAAAAAA-------- ------------------------------ 
