model
size = 18 32 32, scale = 0.05, origin = -y
material 
  colors = A:#C4C4C4 B:#F2FF01 C:#00B075 D:#F5003D E:#F4FF25 F:#C700FF G:#001DFF H:#4B4B4B I:#D765CB J:#0087C1 K:#000
voxels
331-4I13-2(6I12-)6I13-4I500-4I13-3(I4AI12-)6I140-2J16-2J339-4A13-3(6A12-)6A122-2J16-2J356-4(6A12-)6A104-2J16-2J374-6A11-8A9-10A8-10A9-8A12-4A51-2(2J16-)2J391-8A9-3(10A8-)10A11-4A33-2(2J16-)2J211-8A9-4(10A8-)10A10-6A13-4A15-2A49-8A9-3(10A8-)10A10-6A13-4A15-2J12-2K2-2J2-2K8-2K6-2K187-12A5-5(14A4-)14A5-12A8-8A12-4A15-2A16-2A13-8A9-3(10A8-)10A10-6A8-4E-4A-4E4-4E2-2J2-4E4-4E6-2(4E4-)F-4E12-F136-12A5-14A3-5(16A2-)16A3-14A4-14A6-10A10-6A13-4A14-4A12-8A9-4(10A8-)10A6-2(3E8A3E4-)4E6A4E4-4E6A4E8-DCGFCD14-2F47-4(3H6-)3(3A6-)3A5-14A3-16A-90A-2(16A2-)16A4-12A8-8A12-4A14-4A12-8A9-4(10A8-)10A6-2(3E8A3E4-)4E6A4E4-4E6A4E7-8A11-DCGFCD14-FG29-2(3H6-)2(HAH6-)3(3A6-)3A5-14A3-16A-126A-16A3-14A6-10A11-4A14-4A12-8A9-4(10A8-)10A6-2(3E8A3E4-)4E6A4E4-4E6A4E6-10A10-DCGFCD12-DCFG-C13-C-G11-4(3H6-)3(3A6-)3A5-14A3-16A-126A-16A3-14A5-12A10-4A14-4A12-8A9-8(10A8-)10A7-D10A8-3DCGFCDC10-2DCFGCD13-CFG82-14A3-16A-126A-16A3-14A5-12A10-4A14-4A12-8A9-4(10A8-)2(10A7-D)2(10AC6-D)10AC7-10AC8-2DCGFCD2C10-DCGBCDG12-CGB-D80-14A3-16A-126A-16A3-14A5-12A11-2A16-2A13-8A10-8A9-2(10A8-)3(10AC7-)10A8-10A7-2(12A6-)3ADCGFCD3A6-2ACDFG2BDG2A7-A6-D-A78-14A3-16A-126A-16A3-14A5-12A45-6A11-9(8A10-)C6AG10-CDCGFCDG12-C3-D98-14A3-16A-126A-16A3-14A5-12A8-2(DCG3-CD10-)DCGB2-CD10-DC4AC5(D10-D6A)D10-2DCGFCD12-2(DCGFCDG11-)DCGFCD134-14A3-16A-126A-16A3-14A5-12A8-DCGBF-CD11-CGBF-C12-CGBF-C11-4(DCGBFB2C10-)DCGBFBC12-C2GFBC13-CG-B14-C174-14A3-16A-126A-16A3-14A5-12A7-D2CGBFB2CD9-2C3(-BFB13-C)-BFB15-B2F2(17-F)225-14A3-16A-126A-16A3-14A4-D12AD5-D2C-GBF2B2CD12-2(F17-)F298-14A3-16A-126A-16A2-D14AD3-C12AC5-C2-GB2-F-B-C276-4(3H6-)3(3A6-)3A5-14A3-16A-126A-16A3-14A4-C12AC7-GB4-FB278-2(3H6-)2(HAH6-)3(3A6-)3A5-14A3-16A-126A-16A3-14A6-10A8-G3-2F3-B277-4(3H6-)3(3A6-)3A5-6A2-6A3-16A2-16A-90A-16A3-14A5-12A7-G8AB11-C2FC15-2F16-2F317-4A4-4A5-6A2-6A3-6(16A2-)16A4-12A7-10A11-G2DG14-C2BC14-C2FC15-2F335-3A6-3A5-2(5A4-)5(14A4-)14A6-10A11-4G13-6D12-6B13-C2BC15-2F16-2F353-2(3A6-)2(5A2-5A6-)12A6-12A7-10A29-4G13-6D12-6B13-C2BC14-C2BC15-2F16-2F483-4G13-6D12-6B13-C2BC15-2F16-2F267-11(4G14-)G2DG13-6D12-6B13-C2BC14-C2BC15-2F16-2F250-2D15-8(4D14-)4D13-2(B4DB12-)6B13-2(C2BC14-)C2BC15-2F16-2F250-2B15-4B13-8(6B12-)6B13-3(C2BC14-)C2FC15-2(2F16-)2F268-2B15-10(C2BC14-)C2FC15-2(2F16-)2F340-10(2F16-)2F350-
