model
size = 30 29 24, scale = 0.05, origin = -y
material 
  colors = A:#CC9F26 B:#2D2723 C:#8A0E2D D:#FFF E:#8A8A8A F:#000
voxels
------------------------------ ------------------------------ ------------------------------ ------------------------------ ------------------------------ ------------------------------ ------------------------------ ------------------------------ ------------------------------ ------------------------------ ------------------------------ ------------------------------ ------------------------------ ------------------------------ ---------B----------B--------- ------------------------------ ------------------------------ ------------------------------ ------------------------------ ------------------------------ ------------------------------ ------------------------------ ------------------------------ ------------------------------ ------------------------------ ------------------------------ ------------------------------ ------------------------------ ------------------------------ 
------------------------------ ------------------------------ ------------------------------ ------------------------------ ------------------------------ ------------------------------ ------------------------------ ------------------------------ ------------------------------ ------------------------------ ------------------------------ ------------------------------ ------------------------------ ------------------------------ ---------B----------B--------- ------------------------------ ------------------------------ ------------------------------ ------------------------------ ------------------------------ ------------------------------ --------------EE-------------- --------------EE-------------- ------------------------------ ------------------------------ ------------------------------ ------------------------------ ------------------------------ ------------------------------ 
------------------------------ ------------------------------ ------------------------------ ------------------------------ ------------------------------ ------------------------------ ------------------------------ ------------------------------ ------------------------------ ------------------------------ ------------------------------ ------------------------------ ------------------------------ ------------------------------ ---------B----------B--------- ------------------------------ ------------------------------ ------------------------------ ------------------------------ ------------------------------ ------------------------------ --------------EE-------------- --------------EE-------------- ------------------------------ -----------FF----FF----------- -----------FF----FF----------- ------------------------------ ------------------------------ ------------------------------ 
------------------------------ ------------------------------ ------------------------------ ------------------------------ ------------------------------ ------------------------------ ------------------------------ ------------------------------ ------------------------------ ------------------------------ ------------------------------ ------------------------------ ------------------------------ ------------------------------ ---------B----------B--------- ------------------------------ ------------------------------ ------------------------------ ------------------------------ ------------------------------ --------------BB-------------- -------------BBBB------------- -------------BBBB------------- ----------DDDDBBDDDD---------- ----------DDDD--DDDD---------- ----------DDDD--DDDD---------- ----------DDDD--DDDD---------- ------------------------------ ------------------------------ 
------------------------------ ------------------------------ ------------------------------ ------------------------------ ------------------------------ ------------------------------ ------------------------------ ------------------------------ ------------------------------ ------------------------------ ------------------------------ ------------------------------ ------------------------------ ------------------------------ ------------------------------ ---------B----------B--------- -------------CCCC------------- -------------CCCC------------- -------------CCCC------------- ------------------------------ ------------BBBBBB------------ -----------BBBBBBBB----------- -----------BBBBBBBB----------- ----------DDBBBBBBDD---------- ----------DDDDBBDDDD---------- ----------DDDDBBDDDD---------- ----------DDDDBBDDDD---------- -------------BBBB------------- ------------------------------ 
------------------------------ ------------------------------ ------------------------------ ------------------------------ ------------------------------ ------------------------------ ------------------------------ ------------------------------ ------------------------------ ------------------------------ ------------------------------ ------------------------------ -------------BBBB------------- -------------BBBB------------- ------------------------------ ---------B--CCCCCC--B--------- -----------CCBBBBCC----------- -----------CCBBBBCC----------- ------------CBBBBC------------ -------------CCCC------------- -----------BBBBBBBB----------- -----------BBBBBBBB----------- -----------BBBBBBBB----------- ----------DDBBBBBBDD---------- ----------DDDBBBBDDD---------- ----------DDDDBBDDDD---------- ----------DDDDBBDDDD---------- ------------BBBBBB------------ --------------BB-------------- 
------------------------------ ------------------------------ ------------------------------ ------------------------------ ------------------------------ ------------------------------ ------------------------------ ------------------------------ -------------BBBB------------- -------------BBBB------------- -------------BBBB------------- ------------------------------ -----------BBBBBBBB----------- -----------BBBBBBBB----------- -------------BBBB------------- -----------CCBBBBCC----------- ---------B-CBBBBBBC-B--------- ----------BBBBBBBBBB---------- -----------CCBBBBCC----------- -------------CBBC------------- -----------BBBBBBBB----------- -----------BBBBBBBB----------- -----------BBBBBBBB----------- ------------BBBBBB------------ -------------BBBB------------- -------------BBBB------------- -------------BBBB------------- ------------BBBBBB------------ -------------BBBB------------- 
------------------------------ ------------------------------ ------------------------------ ------------------------------ ------------------------------ ------------------------------ ------------------------------ ------------BBBBBB------------ --------B---BBBBBB---B-------- --------B---BBBBBB---B-------- ---------B--BBBBBB--B--------- ---------B---BBBB---B--------- ----------BBBBBBBBBB---------- -----------BBBBBBBB----------- ------------BBBBBB------------ -----------CBBBBBBC----------- -----------CBBBBBBC----------- -----------CBBBBBBC----------- -----------CCBBBBCC----------- -------------CBBC------------- ------------BBBBBB------------ -----------BBBBBBBB----------- B----------BBBBBBBB----------B B-----------BBBBBB-----------B B------------BBBB------------B -B---------BBBBBBBB---------B- -B-------BB-BBBBBB-BB-------B- --B----BB----BBBB----BB----B-- ---BBBB-------BB-------BBBB--- 
------------------------------ ------------------------------ ------------------------------ ------------------------------ ------------------------------ --------B------------B-------- --------B----BBBB----B-------- --------B---BBBBBB---B-------- -----------BBBBBBBB----------- -----------BBBBBBBB----------- ------------BBBBBB------------ ------------BBBBBB------------ -----------BBBBBBBB----------- -----------BBBBBBBB----------- ------------BBBBBB------------ -----------CBBBBBBC----------- -----------CBBBBBBC----------- -----------CBBBBBBC----------- -----------CCCBBCCC----------- --------------CC-------------- -------------BBBB------------- ------------BBBBBB------------ ------------BBBBBB------------ ------------BBBBBB------------ -------------BBBB------------- -------------BBBB------------- -------------BBBB------------- --------------BB-------------- ------------------------------ 
------------------------------ ------------------------------ ------------------------------ ------------------------------ ------------------------------ --------------BB-------------- ------------BBBBBB------------ -----------BBBBBBBB----------- -----------BBBBBBBB----------- -----------BBBBBBBB----------- -----------BBBBBBBB----------- ------------BBBBBB------------ -----------B-BBBB-B----------- -----------BBBBBBBB----------- ------------BBBBBB------------ -----------CBBBBBBC----------- -----------CBBBBBBC----------- -----------CBBBBBBC----------- -----------CCCCCCCC----------- ------------------------------ --------------BB-------------- -------------BBBB------------- ------------BBBBBB------------ -------------BBBB------------- -------------BBBB------------- -------------BBBB------------- --------------BB-------------- ------------------------------ ------------------------------ 
------------------------------ ------------------------------ ------------------------------ ------------------------------ ------------------------------ -------------BBBB------------- ------------BBBBBB------------ -----------BB----BB----------- -----------BB----BB----------- -----------BB----BB----------- -----------BB----BB----------- ------------BBBBBB------------ -----------BBBBBBBB----------- -----------BB----BB----------- -------------BBBB------------- ------------CCCCCC------------ -----------CCCCCCCC----------- -----------CCCCCCCC----------- -------------CCCC------------- ------------------------------ ------------------------------ ------------------------------ --------------BB-------------- --------------BB-------------- --------------BB-------------- --------------BB-------------- ------------------------------ ------------------------------ ------------------------------ 
------------------------------ ------------------------------ ------------------------------ ------------------------------ -------------BBBB------------- ---------B--B----B--B--------- ---------B-B------B-B--------- ---------B-BB----BB-B--------- ----------BBB----BBB---------- -----------BB----BB----------- -----------BB----BB----------- ------------BB--BB------------ -----------BBB--BBB----------- ------------BB--BB------------ -------------BBBB------------- ------------------------------ ------------------------------ ------------------------------ ------------------------------ ------------------------------ ------------------------------ ------------------------------ ------------------------------ ------------------------------ ------------------------------ ------------------------------ ------------------------------ ------------------------------ ------------------------------ 
------------------------------ ------------------------------ ---------B----------B--------- ---------B----------B--------- ---------B---BBBB---B--------- ------------B----B------------ ------------B----B------------ -----------BBAAAABB----------- -----------BBAAAABB----------- -----------BBAAAABB----------- ------------BAAAAB------------ ------------BB--BB------------ -------------B--B------------- -------------B--B------------- --------------BB-------------- ------------------------------ ------------------------------ ------------------------------ ------------------------------ ------------------------------ ------------------------------ ------------------------------ ------------------------------ ------------------------------ ------------------------------ ------------------------------ ------------------------------ ------------------------------ ------------------------------ 
---------B----------B--------- ---------B----------B--------- ------------------------------ ------------------------------ -------------BBBB------------- -------------AAAA------------- ------------AAAAAA------------ -----------AAAAAAAA----------- -----------AAAAAAAA----------- -----------AAAAAAAA----------- -----------AAAAAAAA----------- ------------AAAAAA------------ -------------AAAA------------- --------------BB-------------- ------------------------------ ------------------------------ ------------------------------ ------------------------------ ------------------------------ ------------------------------ ------------------------------ ------------------------------ ------------------------------ ------------------------------ ------------------------------ ------------------------------ ------------------------------ ------------------------------ ------------------------------ 
------------------------------ ------------------------------ ------------------------------ ------------------------------ -------------AAAA------------- ------------AAAAAA------------ -----------AAAAAAAA----------- ----------AAAAAAAAAA---------- ----------AAAAAAAAAA---------- ----------AAAAAAAAAA---------- ----------AAAAAAAAAA---------- -----------AAAAAAAA----------- ------------AAAAAA------------ -------------AAAA------------- ------------------------------ ------------------------------ ------------------------------ ------------------------------ ------------------------------ ------------------------------ ------------------------------ ------------------------------ ------------------------------ ------------------------------ ------------------------------ ------------------------------ ------------------------------ ------------------------------ ------------------------------ 
------------------------------ ------------------------------ ------------------------------ ------------------------------ ------------AAAAAA------------ -----------AAAAAAAA----------- ----------AAAAAAAAAA---------- ----------AAAAAAAAAA---------- ----------AAAAAAAAAA---------- ----------AAAAAAAAAA---------- ----------AAAAAAAAAA---------- ----------AAAAAAAAAA---------- -----------AAAAAAAA----------- ------------AAAAAA------------ ------------------------------ ------------------------------ ------------------------------ ------------------------------ ------------------------------ ------------------------------ ------------------------------ ------------------------------ ------------------------------ ------------------------------ ------------------------------ ------------------------------ ------------------------------ ------------------------------ ------------------------------ 
------------------------------ ------------------------------ ------------------------------ -------------AAAA------------- -----------AAAAAAAA----------- ----------AAAAAAAAAA---------- ----------AAAAAAAAAA---------- ---------AAAAAAAAAAAA--------- ---------AAAAAAAAAAAA--------- ---------AAAAAAAAAAAA--------- ---------AAAAAAAAAAAA--------- ----------AAAAAAAAAA---------- ----------AAAAAAAAAA---------- -----------AAAAAAAA----------- -------------AAAA------------- ------------------------------ ------------------------------ ------------------------------ ------------------------------ ------------------------------ ------------------------------ ------------------------------ ------------------------------ ------------------------------ ------------------------------ ------------------------------ ------------------------------ ------------------------------ ------------------------------ 
------------------------------ ------------------------------ ------------------------------ -------------AAAA------------- -----------AAAAAAAA----------- ----------AAAAAAAAAA---------- ----------AAAAAAAAAA---------- ---------AAAAAAAAAAAA--------- ---------AAAAAAAAAAAA--------- ---------AAAAAAAAAAAA--------- ---------AAAAAAAAAAAA--------- ----------AAAAAAAAAA---------- ----------AAAAAAAAAA---------- -----------AAAAAAAA----------- -------------AAAA------------- ------------------------------ ------------------------------ ------------------------------ ------------------------------ ------------------------------ ------------------------------ ------------------------------ ------------------------------ ------------------------------ ------------------------------ ------------------------------ ------------------------------ ------------------------------ ------------------------------ 
------------------------------ ------------------------------ ------------------------------ -------------AAAA------------- -----------AAAAAAAA----------- ----------AAAAAAAAAA---------- ----------AAAAAAAAAA---------- ---------AAAAAAAAAAAA--------- ---------AAAAAAAAAAAA--------- ---------AAAAAAAAAAAA--------- ---------AAAAAAAAAAAA--------- ----------AAAAAAAAAA---------- ----------AAAAAAAAAA---------- -----------AAAAAAAA----------- -------------AAAA------------- ------------------------------ ------------------------------ ------------------------------ ------------------------------ ------------------------------ ------------------------------ ------------------------------ ------------------------------ ------------------------------ ------------------------------ ------------------------------ ------------------------------ ------------------------------ ------------------------------ 
------------------------------ ------------------------------ ------------------------------ -------------AAAA------------- -----------AAAAAAAA----------- ----------AAAAAAAAAA---------- ----------AAAAAAAAAA---------- ---------AAAAAAAAAAAA--------- ---------AAAAAAAAAAAA--------- ---------AAAAAAAAAAAA--------- ---------AAAAAAAAAAAA--------- ----------AAAAAAAAAA---------- ----------AAAAAAAAAA---------- -----------AAAAAAAA----------- -------------AAAA------------- ------------------------------ ------------------------------ ------------------------------ ------------------------------ ------------------------------ ------------------------------ ------------------------------ ------------------------------ ------------------------------ ------------------------------ ------------------------------ ------------------------------ ------------------------------ ------------------------------ 
------------------------------ ------------------------------ ------------------------------ ------------------------------ ------------AAAAAA------------ -----------AAAAAAAA----------- ----------AAAAAAAAAA---------- ----------AAAAAAAAAA---------- ----------AAAAAAAAAA---------- ----------AAAAAAAAAA---------- ----------AAAAAAAAAA---------- ----------AAAAAAAAAA---------- -----------AAAAAAAA----------- ------------AAAAAA------------ ------------------------------ ------------------------------ ------------------------------ ------------------------------ ------------------------------ ------------------------------ ------------------------------ ------------------------------ ------------------------------ ------------------------------ ------------------------------ ------------------------------ ------------------------------ ------------------------------ ------------------------------ 
------------------------------ ------------------------------ ------------------------------ ------------------------------ -------------AAAA------------- ------------AAAAAA------------ -----------AAAAAAAA----------- ----------AAAAAAAAAA---------- ----------AAAAAAAAAA---------- ----------AAAAAAAAAA---------- ----------AAAAAAAAAA---------- -----------AAAAAAAA----------- ------------AAAAAA------------ -------------AAAA------------- ------------------------------ ------------------------------ ------------------------------ ------------------------------ ------------------------------ ------------------------------ ------------------------------ ------------------------------ ------------------------------ ------------------------------ ------------------------------ ------------------------------ ------------------------------ ------------------------------ ------------------------------ 
------------------------------ ------------------------------ ------------------------------ ------------------------------ ------------------------------ -------------AAAA------------- ------------AAAAAA------------ -----------AAAAAAAA----------- -----------AAAAAAAA----------- -----------AAAAAAAA----------- -----------AAAAAAAA----------- ------------AAAAAA------------ -------------AAAA------------- ------------------------------ ------------------------------ ------------------------------ ------------------------------ ------------------------------ ------------------------------ ------------------------------ ------------------------------ ------------------------------ ------------------------------ ------------------------------ ------------------------------ ------------------------------ ------------------------------ ------------------------------ ------------------------------ 
------------------------------ ------------------------------ ------------------------------ ------------------------------ ------------------------------ ------------------------------ ------------------------------ -------------AAAA------------- -------------AAAA------------- -------------AAAA------------- -------------AAAA------------- ------------------------------ ------------------------------ ------------------------------ ------------------------------ ------------------------------ ------------------------------ ------------------------------ ------------------------------ ------------------------------ ------------------------------ ------------------------------ ------------------------------ ------------------------------ ------------------------------ ------------------------------ ------------------------------ ------------------------------ ------------------------------ 
