model
size = 28 26 10, scale = 0.05, origin = -y
material 
  colors = A:#F500F8 B:#8400C0 C:#F57CF8 D:#120051 E:#9D54C0 F:#450082
voxels
---------------------------- ---------------------------- ---------------------------- ---------------------------- ---------------------------- ---------------------------- ---------------------------- --EE--------------------EE-- -BBB--------------------BBB- EEE----------------------EEE BB------------------------BB ---------------------------- ---------------------------- ---------------------------- ---------------------------- ---------------------------- ---------------------------- ---------------------------- ---------------------------- ---------------------------- ---------------------------- ---------------------------- ---------------------------- ---------------------------- ---------------------------- ---------------------------- 
-DDDD---DDDD----DDDD---DDDD- -DDDD---DDDD----DDDD---DDDD- -DDDD---DDDD----DDDD---DDDD- -DDDD---DDDD----DDDD---DDDD- ---------------------------- ---------------------------- ---------------------------- ---------------------------- ---------------------------- ---------------------------- ---------------------------- ---------------------------- ---------------------------- ---------------------------- ---------------------------- ---------------------------- ---------------------------- ---------------------------- ---------------------------- ---------------------------- ---------------------------- ---------------------------- -DDDD---DDDD----DDDD---DDDD- -DDDD---DDDD----DDDD---DDDD- -DDDD---DDDD----DDDD---DDDD- -DDDD---DDDD----DDDD---DDDD- 
---------------------------- --FF-----FF------FF-----FF-- --FF-----FF------FF-----FF-- ---------------------------- ---------------------------- ---------------------------- ---------------------------- ---------------------------- ---------------------------- ---------------------------- ---------------------------- ---------------------------- ---------------------------- ---------------------------- ---------------------------- ---------------------------- ---------------------------- ---------------------------- ---------------------------- ---------------------------- ---------------------------- ---------------------------- ---------------------------- --FF-----FF------FF-----FF-- --FF-----FF------FF-----FF-- ---------------------------- 
---------------------------- --FF-----FF------FF-----FF-- --FF-----FF------FF-----FF-- ---------------------------- ---------------------------- ---------------------------- ---------------------------- ---------------------------- ---------------------------- ---------------------------- ---------------------------- ---------------------------- ---------------------------- ---------------------------- ---------------------------- ---------------------------- ---------------------------- ---------------------------- ---------------------------- ---------------------------- ---------------------------- ---------------------------- ---------------------------- --FF-----FF------FF-----FF-- --FF-----FF------FF-----FF-- ---------------------------- 
---------------------------- --BB-----AA------AA-----BB-- --BB-----CC------CC-----BB-- ---------------------------- ---------------------------- ---------------------------- ---------------------------- ---------------------------- ---------------------------- ---------------------------- ---------------------------- ---------------------------- ---------------------------- ---------------------------- ---------------------------- ---------------------------- ---------------------------- ---------------------------- ---------------------------- ---------------------------- ---------------------------- ---------------------------- ---------------------------- --BB-----CC------CC-----BB-- --BB-----CC------CC-----BB-- ---------------------------- 
---------------------------- --EB-----AA------AA-----BE-- --EB-----CC------CC-----BE-- ---------AA------AA--------- ---------CC------CC--------- --------AAA------AAA-------- --------CC--------CC-------- ---------------------------- ---------------------------- ---------------------------- ---------------------------- ---------------------------- ---------------------------- ---------------------------- ---------------------------- ---------------------------- ---------------------------- ---------------------------- ---------------------------- ---------------------------- ---------------------------- ---------------------------- --EE--------------------EE-- --EE----AAA------AAA----EE-- --EE----AAA------AAA----EE-- ---------------------------- 
---------------------------- --BB--------------------BB-- --BB-----CC------CC-----BB-- ---------AA------AA--------- ---------CC------CC--------- --------AAA------AAA-------- --------CC--------CC-------- --------AAA------AAA-------- ---------CCC----CCC--------- ---------------------------- ---------------------------- ---------------------------- ---------------------------- ---------------------------- ---------------------------- ---------------------------- ---------------------------- ---------------------------- ---------------------------- ---------------------------- ---------------------------- --BB--------------------BB-- --EE--------------------EE-- --BB---CCC--------CCC---BB-- -------CCC--------CCC------- ---------------------------- 
---------------------------- --EB--------------------BE-- --EB--------------------BE-- --BB--------------------BB-- ---------------------------- ---------------------------- --------CC--------CC-------- --------AAA------AAA-------- ---------CCC----CCC--------- ----------AA----AA---------- ---------CAC----CAC--------- BB------AAA------AAA------BB EEE----------------------EEE -BBB--------------------BBB- --EE--------------------EE-- --BB--------------------BB-- --EE--------------------EE-- --BB--------------------BB-- --EE--------------------EE-- --BB--------------------BB-- --EE--------------------EE-- --BB--------------------BB-- --EE--------------------EE-- ------AAA----------AAA------ ------AAA----------AAA------ ---------------------------- 
---------------------------- ---------------------------- --EE--------------------EE-- --BB--------------------BB-- --EE--------------------EE-- --BB--------------------BB-- --EE--------------------EE-- ---------------------------- ---------------------------- BB--------AA----AA--------BB EE-------CCC----CCC-------EE BB------AAA------AAA------BB EEE-----CC--------CC-----EEE -BBB----AA--------AA----BBB- --EE----CC--------CC----EE-- --BB----AA--------AA----BB-- --EE----CC--------CC----EE-- --BB----AA--------AA----BB-- --EE---CCC--------CCC---EE-- --BB--AAA----------AAA--BB-- --EE--CA------------AC--EE-- --BB--AA------------AA--BB-- ------CA------------AC------ ------CC------------CC------ ------CC------------CC------ ---------------------------- 
---------------------------- ---------------------------- ---------------------------- --BB--------------------BB-- --EE--------------------EE-- --BB--------------------BB-- --EE--------------------EE-- -BBB--------------------BBB- EEE----------------------EEE BB------------------------BB EE------------------------EE ---------------------------- --------CC--------CC-------- --------AA--------AA-------- --------CC--------CC-------- --------AA--------AA-------- --------CC--------CC-------- --------AA--------AA-------- -------CCC--------CCC------- ------AAA----------AAA------ ------CC------------CC------ ------AA------------AA------ ------CC------------CC------ ------AA------------AA------ ---------------------------- ---------------------------- 
