model
size = 16 19 16, scale = 0.05, origin = -y
material 
  colors = A:#EEE B:#111 C:#AAA D:#F500F8 E:#8400C0 F:#FF0
voxels
---------------- BBBBBBBBBBBBBBBB BAABAABAABAABAAB BAABAABAABAABAAB BAABAABAABAABAAB BAABBBBBBBBBBAAB BAAAAAAAAAAAAAAB BAAAAAAAAAAAAAAB BAABBBBBBBBBBAAB BABBBBBBBBBBBBAB BABBFBFBBFBFBBAB BABBBFBBBBFBBBAB BABBBBBBBBBBBBAB BABBBBBBBBBBBBAB BAABBBBBBBBBBAAB BAAAAAAAAAAAAAAB BBBBBBBBBBBBBBBB ---------------- ---------------- 
BBBBBBBBBBBBBBBB BAABAABAABAABAAB BAABAABAABAABAAB BAABAABAABAABAAB BAABBBBBBBBBBAAB BAAAAAAAAAAAAAAB BAAAAAAAAAAAAAAB BAABBBBBBBBBBAAB BABBBBBBBBBBBBAB BABBBDBBBBDBBBAB BABBDDDBBDDDBBAB BABBDBDBBDBDBBAB BABBBBBBBBBBBBAB BAABBBBBBBBBBAAB BAAAAAAAAAAAAAAB BBBBBBBBBBBBBBBB ---------------- ---------------- ---------------- 
BAAAAAAAAAAAAAAB AAAAAAAAAAAAAAAA AAAAAAAAAAAAAAAA AAAAAAAAAAAAAAAA AAAAAAAAAAAAAAAA AAAAAAAAAAAAAAAA AAAAAAAAAAAAAAAA AAAAAAAAAAAAAAAA AAAAAAAAAAAAAAAA AAAAAAAAAAAAAAAA AAAAAAAAAAAAAAAA AAAAAAAAAAAAAAAA AAAAAAAAAAAAAAAA AAAAAAAAAAAAAAAA AAAAAAAAAAAAAAAA BAAAAAAAAAAAAAAB ---------------- ---------------- ---------------- 
BAAAAAAAAAAAAAAB AAAAAAAAAAAAAAAA AAAAAAAAAAAAAAAA AAAAAAAAAAAAAAAA AAAAAAAAAAAAAAAA AAAAAAAAAAAAAAAA AAAAAAAAAAAAAAAA BAAAAAAAAAAAAAAA BAAAAAAAAAAAAAAB BAAAAAAAAAAAAAAB BAAAAAAAAAAAAAAB BAAAAAAAAAAAAAAB BAAAAAAAAAAAAAAB AAAAAAAAAAAAAAAA AAAAAAAAAAAAAAAA BAAAAAAAAAAAAAAB ---------------- ---------------- ---------------- 
BAAAAAAAAAAAAAAB BAAAAAAAAAAAAAAB BAAAAAAAAAAAAAAB BAAAAAAAAAAAAAAB BAAAAAAAAAAAAAAB AAAAAAAAAAAAAAAA BAAAAAAAAAAAAAAA BAAAAAAAAAAAAAAB CAAAAAAAAAAAAAAB BAAAAAAAAAAAAAAB BAAAAAAAAAAAAAAB CAAAAAAAAAAAAAAB BAAAAAAAAAAAAAAB BAAAAAAAAAAAAAAB AAAAAAAAAAAAAAAA BAAAAAAAAAAAAAAB ---------------- ---------------- ---------------- 
BAAAAAAAAAAAAAAB AAAAAAAAAAAAAAAA AAAAAAAAAAAAAAAA AAAAAAAAAAAAAAAA BAAAAAAAAAAAAAAB AAAAAAAAAAAAAAAA BAAAAAAAAAAAAAAA BAAAAAAAAAAAAAAB BAAAAAAAAAAAAAAB CAAAAAAAAAAAAAAB CAAAAAAAAAAAAAAB BAAAAAAAAAAAAAAB BAAAAAAAAAAAAAAB BAAAAAAAAAAAAAAB AAAAAAAAAAAAAAAA BAAAAAAAAAAAAAAB ---------------- ---------------- ---------------- 
BAAAAAAAAAAAAAAB AAAAAAAAAAAAAAAA AAAAAAAAAAAAAAAA AAAAAAAAAAAAAAAA BAAAAAAAAAAAAAAB AAAAAAAAAAAAAAAA BAAAAAAAAAAAAAAA BAAAAAAAAAAAAAAB BAAAAAAAAAAAAAAB CAAAAAAAAAAAAAAE CAAAAAAAAAAAAAAE BAAAAAAAAAAAAAAB BAAAAAAAAAAAAAAB BAAAAAAAAAAAAAAB AAAAAAAAAAAAAAAA BAAAAAAAAAAAAAAB ---------------- ---------------- ---------------- 
BAAAAAAAAAAAAAAB BAAAAAAAAAAAAAAB BAAAAAAAAAAAAAAB BAAAAAAAAAAAAAAB BAAAAAAAAAAAAAAB AAAAAAAAAAAAAAAA BAAAAAAAAAAAAAAA BAAAAAAAAAAAAAAB CAAAAAAAAAAAAAAB BAAAAAAAAAAAAAAE BAAAAAAAAAAAAAAE CAAAAAAAAAAAAAAB BAAAAAAAAAAAAAAB BAAAAAAAAAAAAAAB AAAAAAAAAAAAAAAA BAAAAAAAAAAAAAAB ------BAAB------ ------BAAB------ ------BBBB------ 
BAAAAAAAAAAAAAAB AAAAAAAAAAAAAAAA AAAAAAAAAAAAAAAA AAAAAAAAAAAAAAAA BAAAAAAAAAAAAAAB AAAAAAAAAAAAAAAA BAAAAAAAAAAAAAAA BAAAAAAAAAAAAAAB BAAAAAAAAAAAAAAB BAAAAAAAAAAAAAAB BAAAAAAAAAAAAAAB BAAAAAAAAAAAAAAB BAAAAAAAAAAAAAAB BAAAAAAAAAAAAAAB AAAAAAAAAAAAAAAA BAAAAAAAAAAAAAAB ------AAAA------ ------AAAA------ ------BAAB------ 
BAAAAAAAAAAAAAAB AAAAAAAAAAAAAAAA AAAAAAAAAAAAAAAA AAAAAAAAAAAAAAAA BAAAAAAAAAAAAAAB AAAAAAAAAAAAAAAA BAAAAAAAAAAAAAAA BAAAAAAAAAAAAAAB BAAAAAAAAAAAAAAB BAAAAAAAAAAAAAAB BAAAAAAAAAAAAAAB BAAAAAAAAAAAAAAB BAAAAAAAAAAAAAAB BAAAAAAAAAAAAAAB AAAAAAAAAAAAAAAA BAAAAAAAAAAAAAAB ------AAAA------ ------AAAA------ ------BAAB------ 
BAAAAAAAAAAAAAAB BAAAAAAAAAAAAAAB BAAAAAAAAAAAAAAB BAAAAAAAAAAAAAAB BAAAAAAAAAAAAAAB AAAAAAAAAAAAAAAA BAAAAAAAAAAAAAAA BAAAAAAAAAAAAAAB CAAAAAAAAAAAAAAB BAAAAAAAAAAAAAAE BAAAAAAAAAAAAAAE CAAAAAAAAAAAAAAB BAAAAAAAAAAAAAAB BAAAAAAAAAAAAAAB AAAAAAAAAAAAAAAA BAAAAAAAAAAAAAAB ------BAAB------ ------BAAB------ ------BBBB------ 
BAAAAAAAAAAAAAAB AAAAAAAAAAAAAAAA AAAAAAAAAAAAAAAA AAAAAAAAAAAAAAAA BAAAAAAAAAAAAAAB AAAAAAAAAAAAAAAA BAAAAAAAAAAAAAAA BAAAAAAAAAAAAAAB BAAAAAAAAAAAAAAB CAAAAAAAAAAAAAAE CAAAAAAAAAAAAAAE BAAAAAAAAAAAAAAB BAAAAAAAAAAAAAAB BAAAAAAAAAAAAAAB AAAAAAAAAAAAAAAA BAAAAAAAAAAAAAAB ---------------- ---------------- ---------------- 
BAAAAAAAAAAAAAAB AAAAAAAAAAAAAAAA AAAAAAAAAAAAAAAA AAAAAAAAAAAAAAAA BAAAAAAAAAAAAAAB AAAAAAAAAAAAAAAA BAAAAAAAAAAAAAAA BAAAAAAAAAAAAAAB BAAAAAAAAAAAAAAB CAAAAAAAAAAAAAAB CAAAAAAAAAAAAAAB BAAAAAAAAAAAAAAB BAAAAAAAAAAAAAAB BAAAAAAAAAAAAAAB AAAAAAAAAAAAAAAA BAAAAAAAAAAAAAAB ---------------- ---------------- ---------------- 
BAAAAAAAAAAAAAAB BAAAAAAAAAAAAAAB BAAAAAAAAAAAAAAB BAAAAAAAAAAAAAAB BAAAAAAAAAAAAAAB AAAAAAAAAAAAAAAA BAAAAAAAAAAAAAAA BAAAAAAAAAAAAAAB CAAAAAAAAAAAAAAB BAAAAAAAAAAAAAAB BAAAAAAAAAAAAAAB CAAAAAAAAAAAAAAB BAAAAAAAAAAAAAAB BAAAAAAAAAAAAAAB AAAAAAAAAAAAAAAA BAAAAAAAAAAAAAAB ---------------- ---------------- ---------------- 
BAAAAAAAAAAAAAAB AAAAAAAAAAAAAAAA AAAAAAAAAAAAAAAA AAAAAAAAAAAAAAAA AAAAAAAAAAAAAAAA AAAAAAAAAAAAAAAA AAAAAAAAAAAAAAAA BAAAAAAAAAAAAAAA BAAAAAAAAAAAAAAB BAAAAAAAAAAAAAAB BAAAAAAAAAAAAAAB BAAAAAAAAAAAAAAB BAAAAAAAAAAAAAAB AAAAAAAAAAAAAAAA AAAAAAAAAAAAAAAA BAAAAAAAAAAAAAAB ---------------- ---------------- ---------------- 
BBBBBBBBBBBBBBBB AAAAAAAAAAAAAAAA AAAAAAAAAAAAAAAA AAAAAAAAAAAAAAAA AAAAAAAAAAAAAAAA AAAAAAAAAAAAAAAA AAAAAAAAAAAAAAAA AAAAAAAAAAAAAAAA AAAAAAAAAAAAAAAA AAAAAAAAAAAAAAAA AAAAAAAAAAAAAAAA AAAAAAAAAAAAAAAA AAAAAAAAAAAAAAAA AAAAAAAAAAAAAAAA AAAAAAAAAAAAAAAA BAAAAAAAAAAAAAAB ---------------- ---------------- ---------------- 
