model
size = 32 28 24, scale = 0.05, origin = -y
material 
  colors = A:#EEE B:#111
voxels
269-6B24-3B4A3B19-4B8A4B16-B14AB16-2B4A4B4A2B17-2(B12AB18-)2B10A2B19-B10AB20-2B8A2B21-2B6A2B23-B6AB24-2B4A2B25-B4AB26-6B374-2(14B18-B12AB18-)BA3(-2A)-AB15-9(2A-BA3(-2A)-AB-2A12-)2(2A-B12AB-2A12-)2A-14B-2A367-14B2(18-14A)14-5B12A5B10(10-B5A3(B2A)B5AB)4(10-B20AB)11-20B303-14B2(18-14A)15-B18AB11-B20AB12(10-22A)10-B20AB11-B18AB12-2B16A2B271-14B2(18-14A)15-B18AB11-B20AB6(10-22A)5(10-B20AB)10-22A10-B20AB11-B18AB12-B18AB13-2B14A2B240-14B2(18-14A)15-B18AB11-B20AB12(10-22A)10-B20AB11-B18AB12-20A13-B16AB15-16B209-14B2(18-14A)15-B18AB11-B20AB8(10-22A)3(10-B20AB)10-22A10-B20AB11-B18AB12-20A13-18A15-B14AB209-14B2(18-14A)15-B18AB11-B20AB12(10-22A)10-B20AB11-B18AB12-20A13-18A15-BA12BAB208-B14AB16-B14AB14-3B14A3B12-20A11-B20AB12(10-22A)10-B20AB11-B4A10-4AB12-5A10-5A13-4A10-4A15-BAB10-BAB17-3B8-3B137-3B26-4B7-B14AB7-2B2-B4-16A4-B2-2B2-B2-3B14A3B2-B2-5B2-20A2-4B5-B20AB2(10-22A)5-5B22A6B9(3AB22AB3A2B)3AB22AB3AB-5B5A10-5A5B7-5A10-5A13-4A10-4A15-BAB10-BAB16-5B6-5B17-3A8-3A105-3B26-3BA7-B14AB7-2A2-B4-16A4-B2-2A2-B2-3B14A3B2-B2-A4B2-20A2-4B-2B2-B20AB2(2(2-2B)2-22A)2-2B-BA3B22A3BAB320A-B9A10-9AB7-5A10-5A13-4A10-4A15-BAB3-4B3-BAB15-7B4-7B15-5A6-5A48-4A8-4A40-3B26-3BA7-B14AB7-2A2-B4-16A4-B2-2A2-B2-3B14A3B2-B2-ABA2B2-20A2-2BAB-2B2-B20AB2(2(2-2B)2-22A)2-2B-BA3B22A3BAB320A-B9A10-9AB7-5A10-5A13-4A10-4A15-BAB3-4B3-BAB14-8B4-8B13-6A6-6A16-2B10-2B17-4A8-4A17-2B10-2B9-3B6-2B10-2B6-4B7-B14AB7-2B2-B4-16A4-B2-5B2-3B14A3B2-8B2-20A2-4B5-B20AB2(10-22A)5-5B22A5B320A-5B5A10-5A5B7-5A10-5A13-4A10-4A15-BAB3-4B3-BAB14-8B4-8B13-6A6-6A16-2B10-2B17-4A8-4A17-2B10-2B18-2B10-2B17-B14AB16-16A14-B18AB12-20A11-B20AB2(10-22A)5-5B22A6B9(3AB22AB3A2B)3AB22AB3AB-6B4A10-4A6B7-5A10-5A13-4A10-4A15-BAB3-4B3-BAB14-8B4-8B13-5A8-5A16-2B10-2B17-4A8-4A80-B14AB16-16A14-B18AB12-20A11-B20AB12(10-22A)10-B20AB11-B18AB12-5A10-5A13-4A10-4A15-BAB10-BAB14-8B4-8B13-5A8-5A16-2B10-2B113-B14AB16-16A14-B18AB12-20A11-B20AB12(10-22A)10-B20AB11-B18AB12-5A10-5A13-4A10-4A15-BAB10-BAB14-8B4-8B13-6A6-6A143-B14AB16-16A14-B18AB12-20A11-2(B20AB10-22A10-)9(22A10-)B20AB11-B18AB12-20A13-18A15-BA12BAB14-8B4-8B14-5A6-5A144-B14AB16-16A14-B18AB12-20A11-2(B20AB10-22A10-)9(22A10-)B20AB11-B18AB12-20A13-B16AB15-B14AB14-8B4-8B15-4A6-4A145-B14AB16-16A14-B18AB12-20A11-2(B20AB10-22A10-)9(22A10-)B20AB11-B18AB12-B18AB13-2B14A2B15-16B15-7B4-7B175-B14AB16-16A14-B18AB12-20A11-B20AB10-22A3(10-B20AB)8(10-22A)10-B20AB11-B18AB12-2B16A2B18-B6AB56-2B4-2B180-B14AB16-16A14-B18AB12-20A11-B20AB8(10-22A)4(10-B20AB)10-2B18A2B11-B18AB17-2B6A2B275-B14AB16-16A14-B18AB12-20A11-9(B20AB10-)B20AB11-2B16A2B13-2B14A2B15-2B12A2B17-2B10A2B19-2B8A2B306-B14AB16-16A14-B18AB9(12-20A)2(12-B18AB)14-16A17-14A23-4A374-16B16-B14AB14-3B14A3B9(12-B18AB)14-16A20-8A25-6A26-6A27-4A174-
